2024-01-30 16:10:12,605 INFO    StreamThr :1134333 [internal.py:wandb_internal():86] W&B internal server running at pid: 1134333, started at: 2024-01-30 16:10:12.604075
2024-01-30 16:10:12,613 DEBUG   HandlerThread:1134333 [handler.py:handle_request():146] handle_request: status
2024-01-30 16:10:12,615 INFO    WriterThread:1134333 [datastore.py:open_for_write():87] open: /home/yanxindong/mkor/bert/wandb/run-20240130_161012-k02uw2vk/run-k02uw2vk.wandb
2024-01-30 16:10:12,615 DEBUG   SenderThread:1134333 [sender.py:send():382] send: header
2024-01-30 16:10:12,615 DEBUG   SenderThread:1134333 [sender.py:send():382] send: run
2024-01-30 16:10:13,853 DEBUG   HandlerThread:1134333 [handler.py:handle_request():146] handle_request: check_version
2024-01-30 16:10:13,855 INFO    SenderThread:1134333 [dir_watcher.py:__init__():211] watching files in: /home/yanxindong/mkor/bert/wandb/run-20240130_161012-k02uw2vk/files
2024-01-30 16:10:13,855 INFO    SenderThread:1134333 [sender.py:_start_run_threads():1136] run started: k02uw2vk with start time 1706602212.585994
2024-01-30 16:10:13,855 DEBUG   SenderThread:1134333 [sender.py:send_request():409] send_request: check_version
2024-01-30 16:10:14,828 DEBUG   HandlerThread:1134333 [handler.py:handle_request():146] handle_request: run_start
2024-01-30 16:10:14,837 DEBUG   HandlerThread:1134333 [system_info.py:__init__():27] System info init
2024-01-30 16:10:14,837 DEBUG   HandlerThread:1134333 [system_info.py:__init__():42] System info init done
2024-01-30 16:10:14,837 INFO    HandlerThread:1134333 [system_monitor.py:start():194] Starting system monitor
2024-01-30 16:10:14,861 INFO    SystemMonitor:1134333 [system_monitor.py:_start():158] Starting system asset monitoring threads
2024-01-30 16:10:14,862 INFO    HandlerThread:1134333 [system_monitor.py:probe():214] Collecting system info
2024-01-30 16:10:14,909 INFO    SystemMonitor:1134333 [interfaces.py:start():190] Started cpu monitoring
2024-01-30 16:10:14,965 INFO    SystemMonitor:1134333 [interfaces.py:start():190] Started disk monitoring
2024-01-30 16:10:15,001 INFO    SystemMonitor:1134333 [interfaces.py:start():190] Started gpu monitoring
2024-01-30 16:10:15,017 INFO    SystemMonitor:1134333 [interfaces.py:start():190] Started memory monitoring
2024-01-30 16:10:15,033 INFO    SystemMonitor:1134333 [interfaces.py:start():190] Started network monitoring
2024-01-30 16:10:15,071 DEBUG   HandlerThread:1134333 [system_info.py:probe():151] Probing system
2024-01-30 16:10:15,107 DEBUG   HandlerThread:1134333 [system_info.py:_probe_git():136] Probing git
2024-01-30 16:10:15,170 DEBUG   HandlerThread:1134333 [system_info.py:_probe_git():144] Probing git done
2024-01-30 16:10:15,170 DEBUG   HandlerThread:1134333 [system_info.py:probe():199] Probing system done
2024-01-30 16:10:15,170 DEBUG   HandlerThread:1134333 [system_monitor.py:probe():223] {'os': 'Linux-5.15.0-92-generic-x86_64-with-glibc2.17', 'python': '3.8.17', 'heartbeatAt': '2024-01-30T08:10:15.071515', 'startedAt': '2024-01-30T08:10:12.560707', 'docker': None, 'cuda': None, 'args': ('--local_rank=1', '--config_file', 'config/bert_pretraining_phase2_config.json', '--input_dir', '/home/yanxindong/mkor/bert/data/encoded/sequences_lowercase_max_seq_len_512_next_seq_task_true', '--output_dir', 'results/adam', '--weight_decay', '0.01', '--num_steps_per_checkpoint', '200'), 'state': 'running', 'program': 'run_pretraining.py', 'codePathLocal': 'run_pretraining.py', 'codePath': 'bert/run_pretraining.py', 'git': {'remote': 'https://github.com/kkkjj-d/mkor.git', 'commit': 'efe99e84fef5594780cfb1df6d6a1f61da4ebba0'}, 'email': '1262670315@qq.com', 'root': '/home/yanxindong/mkor', 'host': 'a6000-X640-G40', 'username': 'yanxindong', 'executable': '/home/yanxindong/anaconda/envs/eva/bin/python', 'cpu_count': 64, 'cpu_count_logical': 128, 'cpu_freq': {'current': 850.7812265625, 'min': 800.0, 'max': 3400.0}, 'cpu_freq_per_core': [{'current': 3300.0, 'min': 800.0, 'max': 3400.0}, {'current': 900.0, 'min': 800.0, 'max': 3400.0}, {'current': 800.0, 'min': 800.0, 'max': 3400.0}, {'current': 800.0, 'min': 800.0, 'max': 3400.0}, {'current': 800.0, 'min': 800.0, 'max': 3400.0}, {'current': 800.0, 'min': 800.0, 'max': 3400.0}, {'current': 800.0, 'min': 800.0, 'max': 3400.0}, {'current': 800.0, 'min': 800.0, 'max': 3400.0}, {'current': 900.0, 'min': 800.0, 'max': 3400.0}, {'current': 800.0, 'min': 800.0, 'max': 3400.0}, {'current': 800.0, 'min': 800.0, 'max': 3400.0}, {'current': 800.0, 'min': 800.0, 'max': 3400.0}, {'current': 800.0, 'min': 800.0, 'max': 3400.0}, {'current': 800.0, 'min': 800.0, 'max': 3400.0}, {'current': 800.0, 'min': 800.0, 'max': 3400.0}, {'current': 800.0, 'min': 800.0, 'max': 3400.0}, {'current': 800.0, 'min': 800.0, 'max': 3400.0}, {'current': 800.0, 'min': 800.0, 'max': 3400.0}, {'current': 800.0, 'min': 800.0, 'max': 3400.0}, {'current': 800.0, 'min': 800.0, 'max': 3400.0}, {'current': 800.0, 'min': 800.0, 'max': 3400.0}, {'current': 800.0, 'min': 800.0, 'max': 3400.0}, {'current': 800.0, 'min': 800.0, 'max': 3400.0}, {'current': 800.0, 'min': 800.0, 'max': 3400.0}, {'current': 800.0, 'min': 800.0, 'max': 3400.0}, {'current': 800.0, 'min': 800.0, 'max': 3400.0}, {'current': 800.0, 'min': 800.0, 'max': 3400.0}, {'current': 800.0, 'min': 800.0, 'max': 3400.0}, {'current': 800.0, 'min': 800.0, 'max': 3400.0}, {'current': 800.0, 'min': 800.0, 'max': 3400.0}, {'current': 800.0, 'min': 800.0, 'max': 3400.0}, {'current': 800.0, 'min': 800.0, 'max': 3400.0}, {'current': 800.0, 'min': 800.0, 'max': 3400.0}, {'current': 800.0, 'min': 800.0, 'max': 3400.0}, {'current': 1300.0, 'min': 800.0, 'max': 3400.0}, {'current': 800.0, 'min': 800.0, 'max': 3400.0}, {'current': 800.0, 'min': 800.0, 'max': 3400.0}, {'current': 800.0, 'min': 800.0, 'max': 3400.0}, {'current': 800.0, 'min': 800.0, 'max': 3400.0}, {'current': 800.0, 'min': 800.0, 'max': 3400.0}, {'current': 800.0, 'min': 800.0, 'max': 3400.0}, {'current': 800.0, 'min': 800.0, 'max': 3400.0}, {'current': 800.0, 'min': 800.0, 'max': 3400.0}, {'current': 800.0, 'min': 800.0, 'max': 3400.0}, {'current': 800.0, 'min': 800.0, 'max': 3400.0}, {'current': 800.0, 'min': 800.0, 'max': 3400.0}, {'current': 800.0, 'min': 800.0, 'max': 3400.0}, {'current': 800.0, 'min': 800.0, 'max': 3400.0}, {'current': 800.0, 'min': 800.0, 'max': 3400.0}, {'current': 800.0, 'min': 800.0, 'max': 3400.0}, {'current': 800.0, 'min': 800.0, 'max': 3400.0}, {'current': 1000.0, 'min': 800.0, 'max': 3400.0}, {'current': 800.0, 'min': 800.0, 'max': 3400.0}, {'current': 800.0, 'min': 800.0, 'max': 3400.0}, {'current': 800.0, 'min': 800.0, 'max': 3400.0}, {'current': 800.0, 'min': 800.0, 'max': 3400.0}, {'current': 800.0, 'min': 800.0, 'max': 3400.0}, {'current': 800.0, 'min': 800.0, 'max': 3400.0}, {'current': 800.0, 'min': 800.0, 'max': 3400.0}, {'current': 800.0, 'min': 800.0, 'max': 3400.0}, {'current': 800.0, 'min': 800.0, 'max': 3400.0}, {'current': 800.0, 'min': 800.0, 'max': 3400.0}, {'current': 800.0, 'min': 800.0, 'max': 3400.0}, {'current': 800.0, 'min': 800.0, 'max': 3400.0}, {'current': 3300.0, 'min': 800.0, 'max': 3400.0}, {'current': 800.0, 'min': 800.0, 'max': 3400.0}, {'current': 800.0, 'min': 800.0, 'max': 3400.0}, {'current': 800.0, 'min': 800.0, 'max': 3400.0}, {'current': 800.0, 'min': 800.0, 'max': 3400.0}, {'current': 800.0, 'min': 800.0, 'max': 3400.0}, {'current': 800.0, 'min': 800.0, 'max': 3400.0}, {'current': 800.0, 'min': 800.0, 'max': 3400.0}, {'current': 800.0, 'min': 800.0, 'max': 3400.0}, {'current': 800.0, 'min': 800.0, 'max': 3400.0}, {'current': 800.0, 'min': 800.0, 'max': 3400.0}, {'current': 800.0, 'min': 800.0, 'max': 3400.0}, {'current': 800.0, 'min': 800.0, 'max': 3400.0}, {'current': 800.0, 'min': 800.0, 'max': 3400.0}, {'current': 800.0, 'min': 800.0, 'max': 3400.0}, {'current': 800.0, 'min': 800.0, 'max': 3400.0}, {'current': 800.0, 'min': 800.0, 'max': 3400.0}, {'current': 800.0, 'min': 800.0, 'max': 3400.0}, {'current': 800.0, 'min': 800.0, 'max': 3400.0}, {'current': 800.0, 'min': 800.0, 'max': 3400.0}, {'current': 800.0, 'min': 800.0, 'max': 3400.0}, {'current': 800.0, 'min': 800.0, 'max': 3400.0}, {'current': 800.0, 'min': 800.0, 'max': 3400.0}, {'current': 800.0, 'min': 800.0, 'max': 3400.0}, {'current': 800.0, 'min': 800.0, 'max': 3400.0}, {'current': 800.0, 'min': 800.0, 'max': 3400.0}, {'current': 800.0, 'min': 800.0, 'max': 3400.0}, {'current': 800.0, 'min': 800.0, 'max': 3400.0}, {'current': 800.0, 'min': 800.0, 'max': 3400.0}, {'current': 800.0, 'min': 800.0, 'max': 3400.0}, {'current': 800.0, 'min': 800.0, 'max': 3400.0}, {'current': 800.0, 'min': 800.0, 'max': 3400.0}, {'current': 800.0, 'min': 800.0, 'max': 3400.0}, {'current': 800.0, 'min': 800.0, 'max': 3400.0}, {'current': 800.0, 'min': 800.0, 'max': 3400.0}, {'current': 800.0, 'min': 800.0, 'max': 3400.0}, {'current': 800.0, 'min': 800.0, 'max': 3400.0}, {'current': 800.0, 'min': 800.0, 'max': 3400.0}, {'current': 800.0, 'min': 800.0, 'max': 3400.0}, {'current': 800.0, 'min': 800.0, 'max': 3400.0}, {'current': 800.0, 'min': 800.0, 'max': 3400.0}, {'current': 800.0, 'min': 800.0, 'max': 3400.0}, {'current': 800.0, 'min': 800.0, 'max': 3400.0}, {'current': 800.0, 'min': 800.0, 'max': 3400.0}, {'current': 800.0, 'min': 800.0, 'max': 3400.0}, {'current': 800.0, 'min': 800.0, 'max': 3400.0}, {'current': 900.0, 'min': 800.0, 'max': 3400.0}, {'current': 800.0, 'min': 800.0, 'max': 3400.0}, {'current': 800.0, 'min': 800.0, 'max': 3400.0}, {'current': 800.0, 'min': 800.0, 'max': 3400.0}, {'current': 800.0, 'min': 800.0, 'max': 3400.0}, {'current': 800.0, 'min': 800.0, 'max': 3400.0}, {'current': 800.0, 'min': 800.0, 'max': 3400.0}, {'current': 800.0, 'min': 800.0, 'max': 3400.0}, {'current': 800.0, 'min': 800.0, 'max': 3400.0}, {'current': 800.0, 'min': 800.0, 'max': 3400.0}, {'current': 800.0, 'min': 800.0, 'max': 3400.0}, {'current': 800.0, 'min': 800.0, 'max': 3400.0}, {'current': 800.0, 'min': 800.0, 'max': 3400.0}, {'current': 800.0, 'min': 800.0, 'max': 3400.0}, {'current': 800.0, 'min': 800.0, 'max': 3400.0}, {'current': 800.0, 'min': 800.0, 'max': 3400.0}, {'current': 800.0, 'min': 800.0, 'max': 3400.0}, {'current': 800.0, 'min': 800.0, 'max': 3400.0}], 'disk': {'/': {'total': 438.05088806152344, 'used': 30.817367553710938}}, 'gpu': 'NVIDIA RTX A6000', 'gpu_count': 8, 'gpu_devices': [{'name': 'NVIDIA RTX A6000', 'memory_total': 51527024640}, {'name': 'NVIDIA RTX A6000', 'memory_total': 51527024640}, {'name': 'NVIDIA RTX A6000', 'memory_total': 51527024640}, {'name': 'NVIDIA RTX A6000', 'memory_total': 51527024640}, {'name': 'NVIDIA RTX A6000', 'memory_total': 51527024640}, {'name': 'NVIDIA RTX A6000', 'memory_total': 51527024640}, {'name': 'NVIDIA RTX A6000', 'memory_total': 51527024640}, {'name': 'NVIDIA RTX A6000', 'memory_total': 51527024640}], 'memory': {'total': 503.51252365112305}}
2024-01-30 16:10:15,171 INFO    HandlerThread:1134333 [system_monitor.py:probe():224] Finished collecting system info
2024-01-30 16:10:15,171 INFO    HandlerThread:1134333 [system_monitor.py:probe():227] Publishing system info
2024-01-30 16:10:15,171 DEBUG   HandlerThread:1134333 [system_info.py:_save_conda():208] Saving list of conda packages installed into the current environment
2024-01-30 16:10:15,856 INFO    Thread-12 :1134333 [dir_watcher.py:_on_file_created():271] file/dir created: /home/yanxindong/mkor/bert/wandb/run-20240130_161012-k02uw2vk/files/conda-environment.yaml
2024-01-30 16:10:35,858 INFO    Thread-12 :1134333 [dir_watcher.py:_on_file_modified():288] file/dir modified: /home/yanxindong/mkor/bert/wandb/run-20240130_161012-k02uw2vk/files/conda-environment.yaml
2024-01-30 16:10:36,186 DEBUG   HandlerThread:1134333 [system_info.py:_save_conda():220] Saving conda packages done
2024-01-30 16:10:36,188 INFO    HandlerThread:1134333 [system_monitor.py:probe():229] Finished publishing system info
2024-01-30 16:10:36,193 DEBUG   HandlerThread:1134333 [handler.py:handle_request():146] handle_request: status_report
2024-01-30 16:10:36,202 DEBUG   HandlerThread:1134333 [handler.py:handle_request():146] handle_request: keepalive
2024-01-30 16:10:36,202 DEBUG   HandlerThread:1134333 [handler.py:handle_request():146] handle_request: status_report
2024-01-30 16:10:36,202 DEBUG   HandlerThread:1134333 [handler.py:handle_request():146] handle_request: keepalive
2024-01-30 16:10:36,203 DEBUG   HandlerThread:1134333 [handler.py:handle_request():146] handle_request: status_report
2024-01-30 16:10:36,203 DEBUG   HandlerThread:1134333 [handler.py:handle_request():146] handle_request: keepalive
2024-01-30 16:10:36,203 DEBUG   HandlerThread:1134333 [handler.py:handle_request():146] handle_request: status_report
2024-01-30 16:10:36,203 DEBUG   HandlerThread:1134333 [handler.py:handle_request():146] handle_request: keepalive
2024-01-30 16:10:36,203 DEBUG   HandlerThread:1134333 [handler.py:handle_request():146] handle_request: python_packages
2024-01-30 16:10:36,203 DEBUG   SenderThread:1134333 [sender.py:send():382] send: files
2024-01-30 16:10:36,203 INFO    SenderThread:1134333 [sender.py:_save_file():1403] saving file wandb-metadata.json with policy now
2024-01-30 16:10:36,204 DEBUG   SenderThread:1134333 [sender.py:send_request():409] send_request: python_packages
2024-01-30 16:10:36,222 DEBUG   HandlerThread:1134333 [handler.py:handle_request():146] handle_request: stop_status
2024-01-30 16:10:36,241 DEBUG   SenderThread:1134333 [sender.py:send_request():409] send_request: stop_status
2024-01-30 16:10:36,273 DEBUG   HandlerThread:1134333 [handler.py:handle_request():146] handle_request: internal_messages
2024-01-30 16:10:36,580 DEBUG   SenderThread:1134333 [sender.py:send():382] send: telemetry
2024-01-30 16:10:36,858 INFO    Thread-12 :1134333 [dir_watcher.py:_on_file_created():271] file/dir created: /home/yanxindong/mkor/bert/wandb/run-20240130_161012-k02uw2vk/files/wandb-metadata.json
2024-01-30 16:10:36,859 INFO    Thread-12 :1134333 [dir_watcher.py:_on_file_created():271] file/dir created: /home/yanxindong/mkor/bert/wandb/run-20240130_161012-k02uw2vk/files/requirements.txt
2024-01-30 16:10:36,940 ERROR   wandb-upload_0:1134333 [internal_api.py:upload_file():2765] upload_file exception https://storage.googleapis.com/wandb-production.appspot.com/dynamic_x/bert_pytorch/k02uw2vk/wandb-metadata.json?Expires=1706688636&GoogleAccessId=gorilla-files-url-signer-man%40wandb-production.iam.gserviceaccount.com&Signature=O5gfF6B4ppD%2Bi%2BHqYp9rSofCCWc6atzI%2FJ4kGH8QCvKU9TkLSWBd4L%2F0Y8wy4VYiO5uN8bfoYhQ7nit1eT%2FGIpv06LqT3QKE9ClIuiKmeXxqMcA%2BVYrF5dRiXdyC%2Ba6nTwG5qncoYioJQ%2BdHwrNWRGwrgboVjc2r3ZqfVaZTtzHCjJq3tENgZPG5JBeN2mA1r1OaXz7PJ9NZOONnTc5%2BkP%2Feos3GUefnLmb%2BOM2gHS4HWB%2FTQUzghpD6VD%2FR5587T4eupp1Cm1BaxsoMs2u7AaSK5VMhsX87cKcyp8N%2BZLNgpeN%2BzmofSok1yArLSWqjOJvzAkDzvX9Lm4cRbJzDEw%3D%3D: HTTPSConnectionPool(host='storage.googleapis.com', port=443): Max retries exceeded with url: /wandb-production.appspot.com/dynamic_x/bert_pytorch/k02uw2vk/wandb-metadata.json?Expires=1706688636&GoogleAccessId=gorilla-files-url-signer-man%40wandb-production.iam.gserviceaccount.com&Signature=O5gfF6B4ppD%2Bi%2BHqYp9rSofCCWc6atzI%2FJ4kGH8QCvKU9TkLSWBd4L%2F0Y8wy4VYiO5uN8bfoYhQ7nit1eT%2FGIpv06LqT3QKE9ClIuiKmeXxqMcA%2BVYrF5dRiXdyC%2Ba6nTwG5qncoYioJQ%2BdHwrNWRGwrgboVjc2r3ZqfVaZTtzHCjJq3tENgZPG5JBeN2mA1r1OaXz7PJ9NZOONnTc5%2BkP%2Feos3GUefnLmb%2BOM2gHS4HWB%2FTQUzghpD6VD%2FR5587T4eupp1Cm1BaxsoMs2u7AaSK5VMhsX87cKcyp8N%2BZLNgpeN%2BzmofSok1yArLSWqjOJvzAkDzvX9Lm4cRbJzDEw%3D%3D (Caused by NewConnectionError('<urllib3.connection.HTTPSConnection object at 0x7ff074ed91c0>: Failed to establish a new connection: [Errno 111] Connection refused'))
2024-01-30 16:10:36,940 ERROR   wandb-upload_0:1134333 [internal_api.py:upload_file():2767] upload_file request headers: {'User-Agent': 'python-requests/2.23.0', 'Accept-Encoding': 'gzip, deflate', 'Accept': '*/*', 'Connection': 'keep-alive', 'Content-Length': '15547'}
2024-01-30 16:10:36,940 ERROR   wandb-upload_0:1134333 [internal_api.py:upload_file():2769] upload_file response body: 
2024-01-30 16:10:38,130 ERROR   wandb-upload_0:1134333 [internal_api.py:upload_file():2765] upload_file exception https://storage.googleapis.com/wandb-production.appspot.com/dynamic_x/bert_pytorch/k02uw2vk/wandb-metadata.json?Expires=1706688636&GoogleAccessId=gorilla-files-url-signer-man%40wandb-production.iam.gserviceaccount.com&Signature=O5gfF6B4ppD%2Bi%2BHqYp9rSofCCWc6atzI%2FJ4kGH8QCvKU9TkLSWBd4L%2F0Y8wy4VYiO5uN8bfoYhQ7nit1eT%2FGIpv06LqT3QKE9ClIuiKmeXxqMcA%2BVYrF5dRiXdyC%2Ba6nTwG5qncoYioJQ%2BdHwrNWRGwrgboVjc2r3ZqfVaZTtzHCjJq3tENgZPG5JBeN2mA1r1OaXz7PJ9NZOONnTc5%2BkP%2Feos3GUefnLmb%2BOM2gHS4HWB%2FTQUzghpD6VD%2FR5587T4eupp1Cm1BaxsoMs2u7AaSK5VMhsX87cKcyp8N%2BZLNgpeN%2BzmofSok1yArLSWqjOJvzAkDzvX9Lm4cRbJzDEw%3D%3D: HTTPSConnectionPool(host='storage.googleapis.com', port=443): Max retries exceeded with url: /wandb-production.appspot.com/dynamic_x/bert_pytorch/k02uw2vk/wandb-metadata.json?Expires=1706688636&GoogleAccessId=gorilla-files-url-signer-man%40wandb-production.iam.gserviceaccount.com&Signature=O5gfF6B4ppD%2Bi%2BHqYp9rSofCCWc6atzI%2FJ4kGH8QCvKU9TkLSWBd4L%2F0Y8wy4VYiO5uN8bfoYhQ7nit1eT%2FGIpv06LqT3QKE9ClIuiKmeXxqMcA%2BVYrF5dRiXdyC%2Ba6nTwG5qncoYioJQ%2BdHwrNWRGwrgboVjc2r3ZqfVaZTtzHCjJq3tENgZPG5JBeN2mA1r1OaXz7PJ9NZOONnTc5%2BkP%2Feos3GUefnLmb%2BOM2gHS4HWB%2FTQUzghpD6VD%2FR5587T4eupp1Cm1BaxsoMs2u7AaSK5VMhsX87cKcyp8N%2BZLNgpeN%2BzmofSok1yArLSWqjOJvzAkDzvX9Lm4cRbJzDEw%3D%3D (Caused by NewConnectionError('<urllib3.connection.HTTPSConnection object at 0x7ff074ed95e0>: Failed to establish a new connection: [Errno 111] Connection refused'))
2024-01-30 16:10:38,131 ERROR   wandb-upload_0:1134333 [internal_api.py:upload_file():2767] upload_file request headers: {'User-Agent': 'python-requests/2.23.0', 'Accept-Encoding': 'gzip, deflate', 'Accept': '*/*', 'Connection': 'keep-alive', 'Content-Length': '15547'}
2024-01-30 16:10:38,131 ERROR   wandb-upload_0:1134333 [internal_api.py:upload_file():2769] upload_file response body: 
2024-01-30 16:10:38,581 DEBUG   HandlerThread:1134333 [handler.py:handle_request():146] handle_request: status_report
2024-01-30 16:10:40,277 ERROR   wandb-upload_0:1134333 [internal_api.py:upload_file():2765] upload_file exception https://storage.googleapis.com/wandb-production.appspot.com/dynamic_x/bert_pytorch/k02uw2vk/wandb-metadata.json?Expires=1706688636&GoogleAccessId=gorilla-files-url-signer-man%40wandb-production.iam.gserviceaccount.com&Signature=O5gfF6B4ppD%2Bi%2BHqYp9rSofCCWc6atzI%2FJ4kGH8QCvKU9TkLSWBd4L%2F0Y8wy4VYiO5uN8bfoYhQ7nit1eT%2FGIpv06LqT3QKE9ClIuiKmeXxqMcA%2BVYrF5dRiXdyC%2Ba6nTwG5qncoYioJQ%2BdHwrNWRGwrgboVjc2r3ZqfVaZTtzHCjJq3tENgZPG5JBeN2mA1r1OaXz7PJ9NZOONnTc5%2BkP%2Feos3GUefnLmb%2BOM2gHS4HWB%2FTQUzghpD6VD%2FR5587T4eupp1Cm1BaxsoMs2u7AaSK5VMhsX87cKcyp8N%2BZLNgpeN%2BzmofSok1yArLSWqjOJvzAkDzvX9Lm4cRbJzDEw%3D%3D: HTTPSConnectionPool(host='storage.googleapis.com', port=443): Max retries exceeded with url: /wandb-production.appspot.com/dynamic_x/bert_pytorch/k02uw2vk/wandb-metadata.json?Expires=1706688636&GoogleAccessId=gorilla-files-url-signer-man%40wandb-production.iam.gserviceaccount.com&Signature=O5gfF6B4ppD%2Bi%2BHqYp9rSofCCWc6atzI%2FJ4kGH8QCvKU9TkLSWBd4L%2F0Y8wy4VYiO5uN8bfoYhQ7nit1eT%2FGIpv06LqT3QKE9ClIuiKmeXxqMcA%2BVYrF5dRiXdyC%2Ba6nTwG5qncoYioJQ%2BdHwrNWRGwrgboVjc2r3ZqfVaZTtzHCjJq3tENgZPG5JBeN2mA1r1OaXz7PJ9NZOONnTc5%2BkP%2Feos3GUefnLmb%2BOM2gHS4HWB%2FTQUzghpD6VD%2FR5587T4eupp1Cm1BaxsoMs2u7AaSK5VMhsX87cKcyp8N%2BZLNgpeN%2BzmofSok1yArLSWqjOJvzAkDzvX9Lm4cRbJzDEw%3D%3D (Caused by NewConnectionError('<urllib3.connection.HTTPSConnection object at 0x7ff074eee190>: Failed to establish a new connection: [Errno 111] Connection refused'))
2024-01-30 16:10:40,278 ERROR   wandb-upload_0:1134333 [internal_api.py:upload_file():2767] upload_file request headers: {'User-Agent': 'python-requests/2.23.0', 'Accept-Encoding': 'gzip, deflate', 'Accept': '*/*', 'Connection': 'keep-alive', 'Content-Length': '15547'}
2024-01-30 16:10:40,278 ERROR   wandb-upload_0:1134333 [internal_api.py:upload_file():2769] upload_file response body: 
2024-01-30 16:10:40,278 INFO    wandb-upload_0:1134333 [retry.py:__call__():172] Retry attempt failed:
Traceback (most recent call last):
  File "/home/yanxindong/anaconda/envs/eva/lib/python3.8/site-packages/urllib3/connection.py", line 159, in _new_conn
    conn = connection.create_connection(
  File "/home/yanxindong/anaconda/envs/eva/lib/python3.8/site-packages/urllib3/util/connection.py", line 84, in create_connection
    raise err
  File "/home/yanxindong/anaconda/envs/eva/lib/python3.8/site-packages/urllib3/util/connection.py", line 74, in create_connection
    sock.connect(sa)
ConnectionRefusedError: [Errno 111] Connection refused

During handling of the above exception, another exception occurred:

Traceback (most recent call last):
  File "/home/yanxindong/anaconda/envs/eva/lib/python3.8/site-packages/urllib3/connectionpool.py", line 670, in urlopen
    httplib_response = self._make_request(
  File "/home/yanxindong/anaconda/envs/eva/lib/python3.8/site-packages/urllib3/connectionpool.py", line 381, in _make_request
    self._validate_conn(conn)
  File "/home/yanxindong/anaconda/envs/eva/lib/python3.8/site-packages/urllib3/connectionpool.py", line 978, in _validate_conn
    conn.connect()
  File "/home/yanxindong/anaconda/envs/eva/lib/python3.8/site-packages/urllib3/connection.py", line 309, in connect
    conn = self._new_conn()
  File "/home/yanxindong/anaconda/envs/eva/lib/python3.8/site-packages/urllib3/connection.py", line 171, in _new_conn
    raise NewConnectionError(
urllib3.exceptions.NewConnectionError: <urllib3.connection.HTTPSConnection object at 0x7ff074eee190>: Failed to establish a new connection: [Errno 111] Connection refused

During handling of the above exception, another exception occurred:

Traceback (most recent call last):
  File "/home/yanxindong/anaconda/envs/eva/lib/python3.8/site-packages/requests/adapters.py", line 439, in send
    resp = conn.urlopen(
  File "/home/yanxindong/anaconda/envs/eva/lib/python3.8/site-packages/urllib3/connectionpool.py", line 726, in urlopen
    retries = retries.increment(
  File "/home/yanxindong/anaconda/envs/eva/lib/python3.8/site-packages/urllib3/util/retry.py", line 446, in increment
    raise MaxRetryError(_pool, url, error or ResponseError(cause))
urllib3.exceptions.MaxRetryError: HTTPSConnectionPool(host='storage.googleapis.com', port=443): Max retries exceeded with url: /wandb-production.appspot.com/dynamic_x/bert_pytorch/k02uw2vk/wandb-metadata.json?Expires=1706688636&GoogleAccessId=gorilla-files-url-signer-man%40wandb-production.iam.gserviceaccount.com&Signature=O5gfF6B4ppD%2Bi%2BHqYp9rSofCCWc6atzI%2FJ4kGH8QCvKU9TkLSWBd4L%2F0Y8wy4VYiO5uN8bfoYhQ7nit1eT%2FGIpv06LqT3QKE9ClIuiKmeXxqMcA%2BVYrF5dRiXdyC%2Ba6nTwG5qncoYioJQ%2BdHwrNWRGwrgboVjc2r3ZqfVaZTtzHCjJq3tENgZPG5JBeN2mA1r1OaXz7PJ9NZOONnTc5%2BkP%2Feos3GUefnLmb%2BOM2gHS4HWB%2FTQUzghpD6VD%2FR5587T4eupp1Cm1BaxsoMs2u7AaSK5VMhsX87cKcyp8N%2BZLNgpeN%2BzmofSok1yArLSWqjOJvzAkDzvX9Lm4cRbJzDEw%3D%3D (Caused by NewConnectionError('<urllib3.connection.HTTPSConnection object at 0x7ff074eee190>: Failed to establish a new connection: [Errno 111] Connection refused'))

During handling of the above exception, another exception occurred:

Traceback (most recent call last):
  File "/home/yanxindong/anaconda/envs/eva/lib/python3.8/site-packages/wandb/sdk/internal/internal_api.py", line 2758, in upload_file
    response = self._upload_file_session.put(
  File "/home/yanxindong/anaconda/envs/eva/lib/python3.8/site-packages/requests/sessions.py", line 590, in put
    return self.request('PUT', url, data=data, **kwargs)
  File "/home/yanxindong/anaconda/envs/eva/lib/python3.8/site-packages/requests/sessions.py", line 530, in request
    resp = self.send(prep, **send_kwargs)
  File "/home/yanxindong/anaconda/envs/eva/lib/python3.8/site-packages/requests/sessions.py", line 643, in send
    r = adapter.send(request, **kwargs)
  File "/home/yanxindong/anaconda/envs/eva/lib/python3.8/site-packages/requests/adapters.py", line 516, in send
    raise ConnectionError(e, request=request)
requests.exceptions.ConnectionError: HTTPSConnectionPool(host='storage.googleapis.com', port=443): Max retries exceeded with url: /wandb-production.appspot.com/dynamic_x/bert_pytorch/k02uw2vk/wandb-metadata.json?Expires=1706688636&GoogleAccessId=gorilla-files-url-signer-man%40wandb-production.iam.gserviceaccount.com&Signature=O5gfF6B4ppD%2Bi%2BHqYp9rSofCCWc6atzI%2FJ4kGH8QCvKU9TkLSWBd4L%2F0Y8wy4VYiO5uN8bfoYhQ7nit1eT%2FGIpv06LqT3QKE9ClIuiKmeXxqMcA%2BVYrF5dRiXdyC%2Ba6nTwG5qncoYioJQ%2BdHwrNWRGwrgboVjc2r3ZqfVaZTtzHCjJq3tENgZPG5JBeN2mA1r1OaXz7PJ9NZOONnTc5%2BkP%2Feos3GUefnLmb%2BOM2gHS4HWB%2FTQUzghpD6VD%2FR5587T4eupp1Cm1BaxsoMs2u7AaSK5VMhsX87cKcyp8N%2BZLNgpeN%2BzmofSok1yArLSWqjOJvzAkDzvX9Lm4cRbJzDEw%3D%3D (Caused by NewConnectionError('<urllib3.connection.HTTPSConnection object at 0x7ff074eee190>: Failed to establish a new connection: [Errno 111] Connection refused'))

During handling of the above exception, another exception occurred:

Traceback (most recent call last):
  File "/home/yanxindong/anaconda/envs/eva/lib/python3.8/site-packages/wandb/sdk/lib/retry.py", line 131, in __call__
    result = self._call_fn(*args, **kwargs)
  File "/home/yanxindong/anaconda/envs/eva/lib/python3.8/site-packages/wandb/sdk/internal/internal_api.py", line 2789, in upload_file
    raise _e.with_traceback(sys.exc_info()[2])
  File "/home/yanxindong/anaconda/envs/eva/lib/python3.8/site-packages/wandb/sdk/internal/internal_api.py", line 2758, in upload_file
    response = self._upload_file_session.put(
  File "/home/yanxindong/anaconda/envs/eva/lib/python3.8/site-packages/requests/sessions.py", line 590, in put
    return self.request('PUT', url, data=data, **kwargs)
  File "/home/yanxindong/anaconda/envs/eva/lib/python3.8/site-packages/requests/sessions.py", line 530, in request
    resp = self.send(prep, **send_kwargs)
  File "/home/yanxindong/anaconda/envs/eva/lib/python3.8/site-packages/requests/sessions.py", line 643, in send
    r = adapter.send(request, **kwargs)
  File "/home/yanxindong/anaconda/envs/eva/lib/python3.8/site-packages/requests/adapters.py", line 516, in send
    raise ConnectionError(e, request=request)
wandb.sdk.lib.retry.TransientError: None
2024-01-30 16:10:43,586 DEBUG   HandlerThread:1134333 [handler.py:handle_request():146] handle_request: status_report
2024-01-30 16:10:44,618 ERROR   wandb-upload_0:1134333 [internal_api.py:upload_file():2765] upload_file exception https://storage.googleapis.com/wandb-production.appspot.com/dynamic_x/bert_pytorch/k02uw2vk/wandb-metadata.json?Expires=1706688636&GoogleAccessId=gorilla-files-url-signer-man%40wandb-production.iam.gserviceaccount.com&Signature=O5gfF6B4ppD%2Bi%2BHqYp9rSofCCWc6atzI%2FJ4kGH8QCvKU9TkLSWBd4L%2F0Y8wy4VYiO5uN8bfoYhQ7nit1eT%2FGIpv06LqT3QKE9ClIuiKmeXxqMcA%2BVYrF5dRiXdyC%2Ba6nTwG5qncoYioJQ%2BdHwrNWRGwrgboVjc2r3ZqfVaZTtzHCjJq3tENgZPG5JBeN2mA1r1OaXz7PJ9NZOONnTc5%2BkP%2Feos3GUefnLmb%2BOM2gHS4HWB%2FTQUzghpD6VD%2FR5587T4eupp1Cm1BaxsoMs2u7AaSK5VMhsX87cKcyp8N%2BZLNgpeN%2BzmofSok1yArLSWqjOJvzAkDzvX9Lm4cRbJzDEw%3D%3D: HTTPSConnectionPool(host='storage.googleapis.com', port=443): Max retries exceeded with url: /wandb-production.appspot.com/dynamic_x/bert_pytorch/k02uw2vk/wandb-metadata.json?Expires=1706688636&GoogleAccessId=gorilla-files-url-signer-man%40wandb-production.iam.gserviceaccount.com&Signature=O5gfF6B4ppD%2Bi%2BHqYp9rSofCCWc6atzI%2FJ4kGH8QCvKU9TkLSWBd4L%2F0Y8wy4VYiO5uN8bfoYhQ7nit1eT%2FGIpv06LqT3QKE9ClIuiKmeXxqMcA%2BVYrF5dRiXdyC%2Ba6nTwG5qncoYioJQ%2BdHwrNWRGwrgboVjc2r3ZqfVaZTtzHCjJq3tENgZPG5JBeN2mA1r1OaXz7PJ9NZOONnTc5%2BkP%2Feos3GUefnLmb%2BOM2gHS4HWB%2FTQUzghpD6VD%2FR5587T4eupp1Cm1BaxsoMs2u7AaSK5VMhsX87cKcyp8N%2BZLNgpeN%2BzmofSok1yArLSWqjOJvzAkDzvX9Lm4cRbJzDEw%3D%3D (Caused by NewConnectionError('<urllib3.connection.HTTPSConnection object at 0x7ff075f0f520>: Failed to establish a new connection: [Errno 111] Connection refused'))
2024-01-30 16:10:44,618 ERROR   wandb-upload_0:1134333 [internal_api.py:upload_file():2767] upload_file request headers: {'User-Agent': 'python-requests/2.23.0', 'Accept-Encoding': 'gzip, deflate', 'Accept': '*/*', 'Connection': 'keep-alive', 'Content-Length': '15547'}
2024-01-30 16:10:44,618 ERROR   wandb-upload_0:1134333 [internal_api.py:upload_file():2769] upload_file response body: 
2024-01-30 16:10:44,860 INFO    Thread-12 :1134333 [dir_watcher.py:_on_file_modified():288] file/dir modified: /home/yanxindong/mkor/bert/wandb/run-20240130_161012-k02uw2vk/files/config.yaml
2024-01-30 16:10:49,401 DEBUG   HandlerThread:1134333 [handler.py:handle_request():146] handle_request: status_report
2024-01-30 16:10:51,225 DEBUG   HandlerThread:1134333 [handler.py:handle_request():146] handle_request: stop_status
2024-01-30 16:10:51,226 DEBUG   SenderThread:1134333 [sender.py:send_request():409] send_request: stop_status
2024-01-30 16:10:51,265 DEBUG   HandlerThread:1134333 [handler.py:handle_request():146] handle_request: internal_messages
2024-01-30 16:10:53,956 ERROR   wandb-upload_0:1134333 [internal_api.py:upload_file():2765] upload_file exception https://storage.googleapis.com/wandb-production.appspot.com/dynamic_x/bert_pytorch/k02uw2vk/wandb-metadata.json?Expires=1706688636&GoogleAccessId=gorilla-files-url-signer-man%40wandb-production.iam.gserviceaccount.com&Signature=O5gfF6B4ppD%2Bi%2BHqYp9rSofCCWc6atzI%2FJ4kGH8QCvKU9TkLSWBd4L%2F0Y8wy4VYiO5uN8bfoYhQ7nit1eT%2FGIpv06LqT3QKE9ClIuiKmeXxqMcA%2BVYrF5dRiXdyC%2Ba6nTwG5qncoYioJQ%2BdHwrNWRGwrgboVjc2r3ZqfVaZTtzHCjJq3tENgZPG5JBeN2mA1r1OaXz7PJ9NZOONnTc5%2BkP%2Feos3GUefnLmb%2BOM2gHS4HWB%2FTQUzghpD6VD%2FR5587T4eupp1Cm1BaxsoMs2u7AaSK5VMhsX87cKcyp8N%2BZLNgpeN%2BzmofSok1yArLSWqjOJvzAkDzvX9Lm4cRbJzDEw%3D%3D: HTTPSConnectionPool(host='storage.googleapis.com', port=443): Max retries exceeded with url: /wandb-production.appspot.com/dynamic_x/bert_pytorch/k02uw2vk/wandb-metadata.json?Expires=1706688636&GoogleAccessId=gorilla-files-url-signer-man%40wandb-production.iam.gserviceaccount.com&Signature=O5gfF6B4ppD%2Bi%2BHqYp9rSofCCWc6atzI%2FJ4kGH8QCvKU9TkLSWBd4L%2F0Y8wy4VYiO5uN8bfoYhQ7nit1eT%2FGIpv06LqT3QKE9ClIuiKmeXxqMcA%2BVYrF5dRiXdyC%2Ba6nTwG5qncoYioJQ%2BdHwrNWRGwrgboVjc2r3ZqfVaZTtzHCjJq3tENgZPG5JBeN2mA1r1OaXz7PJ9NZOONnTc5%2BkP%2Feos3GUefnLmb%2BOM2gHS4HWB%2FTQUzghpD6VD%2FR5587T4eupp1Cm1BaxsoMs2u7AaSK5VMhsX87cKcyp8N%2BZLNgpeN%2BzmofSok1yArLSWqjOJvzAkDzvX9Lm4cRbJzDEw%3D%3D (Caused by NewConnectionError('<urllib3.connection.HTTPSConnection object at 0x7ff074eeefa0>: Failed to establish a new connection: [Errno 111] Connection refused'))
2024-01-30 16:10:53,956 ERROR   wandb-upload_0:1134333 [internal_api.py:upload_file():2767] upload_file request headers: {'User-Agent': 'python-requests/2.23.0', 'Accept-Encoding': 'gzip, deflate', 'Accept': '*/*', 'Connection': 'keep-alive', 'Content-Length': '15547'}
2024-01-30 16:10:53,956 ERROR   wandb-upload_0:1134333 [internal_api.py:upload_file():2769] upload_file response body: 
2024-01-30 16:10:54,606 DEBUG   HandlerThread:1134333 [handler.py:handle_request():146] handle_request: status_report
2024-01-30 16:10:59,606 DEBUG   HandlerThread:1134333 [handler.py:handle_request():146] handle_request: status_report
2024-01-30 16:11:04,607 DEBUG   HandlerThread:1134333 [handler.py:handle_request():146] handle_request: status_report
2024-01-30 16:11:06,222 DEBUG   HandlerThread:1134333 [handler.py:handle_request():146] handle_request: stop_status
2024-01-30 16:11:06,222 DEBUG   SenderThread:1134333 [sender.py:send_request():409] send_request: stop_status
2024-01-30 16:11:06,265 DEBUG   HandlerThread:1134333 [handler.py:handle_request():146] handle_request: internal_messages
2024-01-30 16:11:10,579 DEBUG   HandlerThread:1134333 [handler.py:handle_request():146] handle_request: status_report
2024-01-30 16:11:12,579 ERROR   wandb-upload_0:1134333 [internal_api.py:upload_file():2765] upload_file exception https://storage.googleapis.com/wandb-production.appspot.com/dynamic_x/bert_pytorch/k02uw2vk/wandb-metadata.json?Expires=1706688636&GoogleAccessId=gorilla-files-url-signer-man%40wandb-production.iam.gserviceaccount.com&Signature=O5gfF6B4ppD%2Bi%2BHqYp9rSofCCWc6atzI%2FJ4kGH8QCvKU9TkLSWBd4L%2F0Y8wy4VYiO5uN8bfoYhQ7nit1eT%2FGIpv06LqT3QKE9ClIuiKmeXxqMcA%2BVYrF5dRiXdyC%2Ba6nTwG5qncoYioJQ%2BdHwrNWRGwrgboVjc2r3ZqfVaZTtzHCjJq3tENgZPG5JBeN2mA1r1OaXz7PJ9NZOONnTc5%2BkP%2Feos3GUefnLmb%2BOM2gHS4HWB%2FTQUzghpD6VD%2FR5587T4eupp1Cm1BaxsoMs2u7AaSK5VMhsX87cKcyp8N%2BZLNgpeN%2BzmofSok1yArLSWqjOJvzAkDzvX9Lm4cRbJzDEw%3D%3D: HTTPSConnectionPool(host='storage.googleapis.com', port=443): Max retries exceeded with url: /wandb-production.appspot.com/dynamic_x/bert_pytorch/k02uw2vk/wandb-metadata.json?Expires=1706688636&GoogleAccessId=gorilla-files-url-signer-man%40wandb-production.iam.gserviceaccount.com&Signature=O5gfF6B4ppD%2Bi%2BHqYp9rSofCCWc6atzI%2FJ4kGH8QCvKU9TkLSWBd4L%2F0Y8wy4VYiO5uN8bfoYhQ7nit1eT%2FGIpv06LqT3QKE9ClIuiKmeXxqMcA%2BVYrF5dRiXdyC%2Ba6nTwG5qncoYioJQ%2BdHwrNWRGwrgboVjc2r3ZqfVaZTtzHCjJq3tENgZPG5JBeN2mA1r1OaXz7PJ9NZOONnTc5%2BkP%2Feos3GUefnLmb%2BOM2gHS4HWB%2FTQUzghpD6VD%2FR5587T4eupp1Cm1BaxsoMs2u7AaSK5VMhsX87cKcyp8N%2BZLNgpeN%2BzmofSok1yArLSWqjOJvzAkDzvX9Lm4cRbJzDEw%3D%3D (Caused by NewConnectionError('<urllib3.connection.HTTPSConnection object at 0x7ff074e1c3a0>: Failed to establish a new connection: [Errno 111] Connection refused'))
2024-01-30 16:11:12,579 ERROR   wandb-upload_0:1134333 [internal_api.py:upload_file():2767] upload_file request headers: {'User-Agent': 'python-requests/2.23.0', 'Accept-Encoding': 'gzip, deflate', 'Accept': '*/*', 'Connection': 'keep-alive', 'Content-Length': '15547'}
2024-01-30 16:11:12,579 ERROR   wandb-upload_0:1134333 [internal_api.py:upload_file():2769] upload_file response body: 
2024-01-30 16:11:15,033 DEBUG   SystemMonitor:1134333 [system_monitor.py:_start():172] Starting system metrics aggregation loop
2024-01-30 16:11:15,039 DEBUG   SenderThread:1134333 [sender.py:send():382] send: stats
2024-01-30 16:11:16,041 DEBUG   HandlerThread:1134333 [handler.py:handle_request():146] handle_request: status_report
2024-01-30 16:11:21,043 DEBUG   HandlerThread:1134333 [handler.py:handle_request():146] handle_request: status_report
2024-01-30 16:11:21,222 DEBUG   HandlerThread:1134333 [handler.py:handle_request():146] handle_request: stop_status
2024-01-30 16:11:21,223 DEBUG   SenderThread:1134333 [sender.py:send_request():409] send_request: stop_status
2024-01-30 16:11:21,265 DEBUG   HandlerThread:1134333 [handler.py:handle_request():146] handle_request: internal_messages
2024-01-30 16:11:26,537 DEBUG   HandlerThread:1134333 [handler.py:handle_request():146] handle_request: status_report
2024-01-30 16:11:31,558 DEBUG   HandlerThread:1134333 [handler.py:handle_request():146] handle_request: status_report
2024-01-30 16:11:36,229 DEBUG   HandlerThread:1134333 [handler.py:handle_request():146] handle_request: stop_status
2024-01-30 16:11:36,230 DEBUG   SenderThread:1134333 [sender.py:send_request():409] send_request: stop_status
2024-01-30 16:11:36,265 DEBUG   HandlerThread:1134333 [handler.py:handle_request():146] handle_request: internal_messages
2024-01-30 16:11:37,505 DEBUG   HandlerThread:1134333 [handler.py:handle_request():146] handle_request: status_report
2024-01-30 16:11:42,506 DEBUG   HandlerThread:1134333 [handler.py:handle_request():146] handle_request: status_report
2024-01-30 16:11:45,038 DEBUG   SenderThread:1134333 [sender.py:send():382] send: stats
2024-01-30 16:11:45,135 ERROR   wandb-upload_0:1134333 [internal_api.py:upload_file():2765] upload_file exception https://storage.googleapis.com/wandb-production.appspot.com/dynamic_x/bert_pytorch/k02uw2vk/wandb-metadata.json?Expires=1706688636&GoogleAccessId=gorilla-files-url-signer-man%40wandb-production.iam.gserviceaccount.com&Signature=O5gfF6B4ppD%2Bi%2BHqYp9rSofCCWc6atzI%2FJ4kGH8QCvKU9TkLSWBd4L%2F0Y8wy4VYiO5uN8bfoYhQ7nit1eT%2FGIpv06LqT3QKE9ClIuiKmeXxqMcA%2BVYrF5dRiXdyC%2Ba6nTwG5qncoYioJQ%2BdHwrNWRGwrgboVjc2r3ZqfVaZTtzHCjJq3tENgZPG5JBeN2mA1r1OaXz7PJ9NZOONnTc5%2BkP%2Feos3GUefnLmb%2BOM2gHS4HWB%2FTQUzghpD6VD%2FR5587T4eupp1Cm1BaxsoMs2u7AaSK5VMhsX87cKcyp8N%2BZLNgpeN%2BzmofSok1yArLSWqjOJvzAkDzvX9Lm4cRbJzDEw%3D%3D: HTTPSConnectionPool(host='storage.googleapis.com', port=443): Max retries exceeded with url: /wandb-production.appspot.com/dynamic_x/bert_pytorch/k02uw2vk/wandb-metadata.json?Expires=1706688636&GoogleAccessId=gorilla-files-url-signer-man%40wandb-production.iam.gserviceaccount.com&Signature=O5gfF6B4ppD%2Bi%2BHqYp9rSofCCWc6atzI%2FJ4kGH8QCvKU9TkLSWBd4L%2F0Y8wy4VYiO5uN8bfoYhQ7nit1eT%2FGIpv06LqT3QKE9ClIuiKmeXxqMcA%2BVYrF5dRiXdyC%2Ba6nTwG5qncoYioJQ%2BdHwrNWRGwrgboVjc2r3ZqfVaZTtzHCjJq3tENgZPG5JBeN2mA1r1OaXz7PJ9NZOONnTc5%2BkP%2Feos3GUefnLmb%2BOM2gHS4HWB%2FTQUzghpD6VD%2FR5587T4eupp1Cm1BaxsoMs2u7AaSK5VMhsX87cKcyp8N%2BZLNgpeN%2BzmofSok1yArLSWqjOJvzAkDzvX9Lm4cRbJzDEw%3D%3D (Caused by NewConnectionError('<urllib3.connection.HTTPSConnection object at 0x7ff074e1c9d0>: Failed to establish a new connection: [Errno 101] Network is unreachable'))
2024-01-30 16:11:45,135 ERROR   wandb-upload_0:1134333 [internal_api.py:upload_file():2767] upload_file request headers: {'User-Agent': 'python-requests/2.23.0', 'Accept-Encoding': 'gzip, deflate', 'Accept': '*/*', 'Connection': 'keep-alive', 'Content-Length': '15547'}
2024-01-30 16:11:45,135 ERROR   wandb-upload_0:1134333 [internal_api.py:upload_file():2769] upload_file response body: 
2024-01-30 16:11:48,039 DEBUG   HandlerThread:1134333 [handler.py:handle_request():146] handle_request: status_report
2024-01-30 16:11:51,222 DEBUG   HandlerThread:1134333 [handler.py:handle_request():146] handle_request: stop_status
2024-01-30 16:11:51,223 DEBUG   SenderThread:1134333 [sender.py:send_request():409] send_request: stop_status
2024-01-30 16:11:51,265 DEBUG   HandlerThread:1134333 [handler.py:handle_request():146] handle_request: internal_messages
2024-01-30 16:11:53,571 DEBUG   HandlerThread:1134333 [handler.py:handle_request():146] handle_request: status_report
2024-01-30 16:11:55,154 INFO    Thread-12 :1134333 [dir_watcher.py:_on_file_created():271] file/dir created: /home/yanxindong/mkor/bert/wandb/run-20240130_161012-k02uw2vk/files/output.log
2024-01-30 16:11:58,155 INFO    Thread-12 :1134333 [dir_watcher.py:_on_file_modified():288] file/dir modified: /home/yanxindong/mkor/bert/wandb/run-20240130_161012-k02uw2vk/files/output.log
2024-01-30 16:11:59,186 DEBUG   HandlerThread:1134333 [handler.py:handle_request():146] handle_request: status_report
2024-01-30 16:12:04,187 DEBUG   HandlerThread:1134333 [handler.py:handle_request():146] handle_request: status_report
2024-01-30 16:12:06,404 DEBUG   HandlerThread:1134333 [handler.py:handle_request():146] handle_request: internal_messages
2024-01-30 16:12:06,406 DEBUG   HandlerThread:1134333 [handler.py:handle_request():146] handle_request: stop_status
2024-01-30 16:12:06,406 DEBUG   SenderThread:1134333 [sender.py:send_request():409] send_request: stop_status
2024-01-30 16:12:09,705 DEBUG   HandlerThread:1134333 [handler.py:handle_request():146] handle_request: status_report
2024-01-30 16:12:15,042 DEBUG   SenderThread:1134333 [sender.py:send():382] send: stats
2024-01-30 16:12:15,050 DEBUG   HandlerThread:1134333 [handler.py:handle_request():146] handle_request: status_report
2024-01-30 16:12:20,072 DEBUG   HandlerThread:1134333 [handler.py:handle_request():146] handle_request: status_report
2024-01-30 16:12:21,404 DEBUG   HandlerThread:1134333 [handler.py:handle_request():146] handle_request: stop_status
2024-01-30 16:12:21,405 DEBUG   HandlerThread:1134333 [handler.py:handle_request():146] handle_request: internal_messages
2024-01-30 16:12:21,405 DEBUG   SenderThread:1134333 [sender.py:send_request():409] send_request: stop_status
2024-01-30 16:12:25,858 DEBUG   HandlerThread:1134333 [handler.py:handle_request():146] handle_request: status_report
2024-01-30 16:12:31,037 DEBUG   HandlerThread:1134333 [handler.py:handle_request():146] handle_request: status_report
2024-01-30 16:12:36,158 DEBUG   HandlerThread:1134333 [handler.py:handle_request():146] handle_request: status_report
2024-01-30 16:12:36,404 DEBUG   HandlerThread:1134333 [handler.py:handle_request():146] handle_request: stop_status
2024-01-30 16:12:36,405 DEBUG   SenderThread:1134333 [sender.py:send_request():409] send_request: stop_status
2024-01-30 16:12:36,445 DEBUG   HandlerThread:1134333 [handler.py:handle_request():146] handle_request: internal_messages
2024-01-30 16:12:41,858 DEBUG   HandlerThread:1134333 [handler.py:handle_request():146] handle_request: status_report
2024-01-30 16:12:45,044 DEBUG   SenderThread:1134333 [sender.py:send():382] send: stats
2024-01-30 16:12:47,045 DEBUG   HandlerThread:1134333 [handler.py:handle_request():146] handle_request: status_report
2024-01-30 16:12:51,404 DEBUG   HandlerThread:1134333 [handler.py:handle_request():146] handle_request: stop_status
2024-01-30 16:12:51,405 DEBUG   SenderThread:1134333 [sender.py:send_request():409] send_request: stop_status
2024-01-30 16:12:51,445 DEBUG   HandlerThread:1134333 [handler.py:handle_request():146] handle_request: internal_messages
2024-01-30 16:12:52,707 DEBUG   HandlerThread:1134333 [handler.py:handle_request():146] handle_request: status_report
2024-01-30 16:12:57,708 DEBUG   HandlerThread:1134333 [handler.py:handle_request():146] handle_request: status_report
2024-01-30 16:13:01,218 ERROR   wandb-upload_0:1134333 [internal_api.py:upload_file():2765] upload_file exception https://storage.googleapis.com/wandb-production.appspot.com/dynamic_x/bert_pytorch/k02uw2vk/wandb-metadata.json?Expires=1706688636&GoogleAccessId=gorilla-files-url-signer-man%40wandb-production.iam.gserviceaccount.com&Signature=O5gfF6B4ppD%2Bi%2BHqYp9rSofCCWc6atzI%2FJ4kGH8QCvKU9TkLSWBd4L%2F0Y8wy4VYiO5uN8bfoYhQ7nit1eT%2FGIpv06LqT3QKE9ClIuiKmeXxqMcA%2BVYrF5dRiXdyC%2Ba6nTwG5qncoYioJQ%2BdHwrNWRGwrgboVjc2r3ZqfVaZTtzHCjJq3tENgZPG5JBeN2mA1r1OaXz7PJ9NZOONnTc5%2BkP%2Feos3GUefnLmb%2BOM2gHS4HWB%2FTQUzghpD6VD%2FR5587T4eupp1Cm1BaxsoMs2u7AaSK5VMhsX87cKcyp8N%2BZLNgpeN%2BzmofSok1yArLSWqjOJvzAkDzvX9Lm4cRbJzDEw%3D%3D: HTTPSConnectionPool(host='storage.googleapis.com', port=443): Max retries exceeded with url: /wandb-production.appspot.com/dynamic_x/bert_pytorch/k02uw2vk/wandb-metadata.json?Expires=1706688636&GoogleAccessId=gorilla-files-url-signer-man%40wandb-production.iam.gserviceaccount.com&Signature=O5gfF6B4ppD%2Bi%2BHqYp9rSofCCWc6atzI%2FJ4kGH8QCvKU9TkLSWBd4L%2F0Y8wy4VYiO5uN8bfoYhQ7nit1eT%2FGIpv06LqT3QKE9ClIuiKmeXxqMcA%2BVYrF5dRiXdyC%2Ba6nTwG5qncoYioJQ%2BdHwrNWRGwrgboVjc2r3ZqfVaZTtzHCjJq3tENgZPG5JBeN2mA1r1OaXz7PJ9NZOONnTc5%2BkP%2Feos3GUefnLmb%2BOM2gHS4HWB%2FTQUzghpD6VD%2FR5587T4eupp1Cm1BaxsoMs2u7AaSK5VMhsX87cKcyp8N%2BZLNgpeN%2BzmofSok1yArLSWqjOJvzAkDzvX9Lm4cRbJzDEw%3D%3D (Caused by NewConnectionError('<urllib3.connection.HTTPSConnection object at 0x7ff074eee4f0>: Failed to establish a new connection: [Errno 101] Network is unreachable'))
2024-01-30 16:13:01,218 ERROR   wandb-upload_0:1134333 [internal_api.py:upload_file():2767] upload_file request headers: {'User-Agent': 'python-requests/2.23.0', 'Accept-Encoding': 'gzip, deflate', 'Accept': '*/*', 'Connection': 'keep-alive', 'Content-Length': '15547'}
2024-01-30 16:13:01,218 ERROR   wandb-upload_0:1134333 [internal_api.py:upload_file():2769] upload_file response body: 
2024-01-30 16:13:02,708 DEBUG   HandlerThread:1134333 [handler.py:handle_request():146] handle_request: status_report
2024-01-30 16:13:06,404 DEBUG   HandlerThread:1134333 [handler.py:handle_request():146] handle_request: stop_status
2024-01-30 16:13:06,405 DEBUG   SenderThread:1134333 [sender.py:send_request():409] send_request: stop_status
2024-01-30 16:13:06,445 DEBUG   HandlerThread:1134333 [handler.py:handle_request():146] handle_request: internal_messages
2024-01-30 16:13:07,761 DEBUG   HandlerThread:1134333 [handler.py:handle_request():146] handle_request: status_report
2024-01-30 16:13:12,762 DEBUG   HandlerThread:1134333 [handler.py:handle_request():146] handle_request: status_report
2024-01-30 16:13:15,046 DEBUG   SenderThread:1134333 [sender.py:send():382] send: stats
2024-01-30 16:13:18,047 DEBUG   HandlerThread:1134333 [handler.py:handle_request():146] handle_request: status_report
2024-01-30 16:13:21,425 DEBUG   HandlerThread:1134333 [handler.py:handle_request():146] handle_request: stop_status
2024-01-30 16:13:21,426 DEBUG   SenderThread:1134333 [sender.py:send_request():409] send_request: stop_status
2024-01-30 16:13:21,449 DEBUG   HandlerThread:1134333 [handler.py:handle_request():146] handle_request: internal_messages
2024-01-30 16:13:23,717 DEBUG   HandlerThread:1134333 [handler.py:handle_request():146] handle_request: status_report
2024-01-30 16:13:28,741 DEBUG   HandlerThread:1134333 [handler.py:handle_request():146] handle_request: status_report
2024-01-30 16:13:33,818 DEBUG   HandlerThread:1134333 [handler.py:handle_request():146] handle_request: status_report
2024-01-30 16:13:36,516 DEBUG   HandlerThread:1134333 [handler.py:handle_request():146] handle_request: stop_status
2024-01-30 16:13:36,516 DEBUG   HandlerThread:1134333 [handler.py:handle_request():146] handle_request: internal_messages
2024-01-30 16:13:36,517 DEBUG   SenderThread:1134333 [sender.py:send_request():409] send_request: stop_status
2024-01-30 16:13:38,960 DEBUG   HandlerThread:1134333 [handler.py:handle_request():146] handle_request: status_report
2024-01-30 16:13:43,961 DEBUG   HandlerThread:1134333 [handler.py:handle_request():146] handle_request: status_report
2024-01-30 16:13:45,049 DEBUG   SenderThread:1134333 [sender.py:send():382] send: stats
2024-01-30 16:13:49,050 DEBUG   HandlerThread:1134333 [handler.py:handle_request():146] handle_request: status_report
2024-01-30 16:13:51,405 DEBUG   HandlerThread:1134333 [handler.py:handle_request():146] handle_request: stop_status
2024-01-30 16:13:51,405 DEBUG   SenderThread:1134333 [sender.py:send_request():409] send_request: stop_status
2024-01-30 16:13:51,408 DEBUG   HandlerThread:1134333 [handler.py:handle_request():146] handle_request: internal_messages
2024-01-30 16:13:54,733 DEBUG   HandlerThread:1134333 [handler.py:handle_request():146] handle_request: status_report
2024-01-30 16:13:59,734 DEBUG   HandlerThread:1134333 [handler.py:handle_request():146] handle_request: status_report
2024-01-30 16:14:04,734 DEBUG   HandlerThread:1134333 [handler.py:handle_request():146] handle_request: status_report
2024-01-30 16:14:06,405 DEBUG   HandlerThread:1134333 [handler.py:handle_request():146] handle_request: stop_status
2024-01-30 16:14:06,405 DEBUG   SenderThread:1134333 [sender.py:send_request():409] send_request: stop_status
2024-01-30 16:14:06,445 DEBUG   HandlerThread:1134333 [handler.py:handle_request():146] handle_request: internal_messages
2024-01-30 16:14:10,723 DEBUG   HandlerThread:1134333 [handler.py:handle_request():146] handle_request: status_report
2024-01-30 16:14:15,050 DEBUG   SenderThread:1134333 [sender.py:send():382] send: stats
2024-01-30 16:14:16,052 DEBUG   HandlerThread:1134333 [handler.py:handle_request():146] handle_request: status_report
2024-01-30 16:14:21,052 DEBUG   HandlerThread:1134333 [handler.py:handle_request():146] handle_request: status_report
2024-01-30 16:14:21,405 DEBUG   HandlerThread:1134333 [handler.py:handle_request():146] handle_request: stop_status
2024-01-30 16:14:21,405 DEBUG   SenderThread:1134333 [sender.py:send_request():409] send_request: stop_status
2024-01-30 16:14:21,445 DEBUG   HandlerThread:1134333 [handler.py:handle_request():146] handle_request: internal_messages
2024-01-30 16:14:26,974 DEBUG   HandlerThread:1134333 [handler.py:handle_request():146] handle_request: status_report
2024-01-30 16:14:31,978 DEBUG   HandlerThread:1134333 [handler.py:handle_request():146] handle_request: status_report
2024-01-30 16:14:36,405 DEBUG   HandlerThread:1134333 [handler.py:handle_request():146] handle_request: stop_status
2024-01-30 16:14:36,405 DEBUG   SenderThread:1134333 [sender.py:send_request():409] send_request: stop_status
2024-01-30 16:14:36,445 DEBUG   HandlerThread:1134333 [handler.py:handle_request():146] handle_request: internal_messages
2024-01-30 16:14:37,751 DEBUG   HandlerThread:1134333 [handler.py:handle_request():146] handle_request: status_report
2024-01-30 16:14:42,882 DEBUG   HandlerThread:1134333 [handler.py:handle_request():146] handle_request: status_report
2024-01-30 16:14:45,053 DEBUG   SenderThread:1134333 [sender.py:send():382] send: stats
2024-01-30 16:14:48,054 DEBUG   HandlerThread:1134333 [handler.py:handle_request():146] handle_request: status_report
2024-01-30 16:14:51,405 DEBUG   HandlerThread:1134333 [handler.py:handle_request():146] handle_request: stop_status
2024-01-30 16:14:51,405 DEBUG   SenderThread:1134333 [sender.py:send_request():409] send_request: stop_status
2024-01-30 16:14:51,445 DEBUG   HandlerThread:1134333 [handler.py:handle_request():146] handle_request: internal_messages
2024-01-30 16:14:53,698 DEBUG   HandlerThread:1134333 [handler.py:handle_request():146] handle_request: status_report
2024-01-30 16:14:58,699 DEBUG   HandlerThread:1134333 [handler.py:handle_request():146] handle_request: status_report
2024-01-30 16:15:03,699 DEBUG   HandlerThread:1134333 [handler.py:handle_request():146] handle_request: status_report
2024-01-30 16:15:06,405 DEBUG   HandlerThread:1134333 [handler.py:handle_request():146] handle_request: stop_status
2024-01-30 16:15:06,405 DEBUG   SenderThread:1134333 [sender.py:send_request():409] send_request: stop_status
2024-01-30 16:15:06,445 DEBUG   HandlerThread:1134333 [handler.py:handle_request():146] handle_request: internal_messages
2024-01-30 16:15:09,694 DEBUG   HandlerThread:1134333 [handler.py:handle_request():146] handle_request: status_report
2024-01-30 16:15:14,694 DEBUG   HandlerThread:1134333 [handler.py:handle_request():146] handle_request: status_report
2024-01-30 16:15:15,055 DEBUG   SenderThread:1134333 [sender.py:send():382] send: stats
2024-01-30 16:15:18,422 ERROR   wandb-upload_0:1134333 [internal_api.py:upload_file():2765] upload_file exception https://storage.googleapis.com/wandb-production.appspot.com/dynamic_x/bert_pytorch/k02uw2vk/wandb-metadata.json?Expires=1706688636&GoogleAccessId=gorilla-files-url-signer-man%40wandb-production.iam.gserviceaccount.com&Signature=O5gfF6B4ppD%2Bi%2BHqYp9rSofCCWc6atzI%2FJ4kGH8QCvKU9TkLSWBd4L%2F0Y8wy4VYiO5uN8bfoYhQ7nit1eT%2FGIpv06LqT3QKE9ClIuiKmeXxqMcA%2BVYrF5dRiXdyC%2Ba6nTwG5qncoYioJQ%2BdHwrNWRGwrgboVjc2r3ZqfVaZTtzHCjJq3tENgZPG5JBeN2mA1r1OaXz7PJ9NZOONnTc5%2BkP%2Feos3GUefnLmb%2BOM2gHS4HWB%2FTQUzghpD6VD%2FR5587T4eupp1Cm1BaxsoMs2u7AaSK5VMhsX87cKcyp8N%2BZLNgpeN%2BzmofSok1yArLSWqjOJvzAkDzvX9Lm4cRbJzDEw%3D%3D: HTTPSConnectionPool(host='storage.googleapis.com', port=443): Max retries exceeded with url: /wandb-production.appspot.com/dynamic_x/bert_pytorch/k02uw2vk/wandb-metadata.json?Expires=1706688636&GoogleAccessId=gorilla-files-url-signer-man%40wandb-production.iam.gserviceaccount.com&Signature=O5gfF6B4ppD%2Bi%2BHqYp9rSofCCWc6atzI%2FJ4kGH8QCvKU9TkLSWBd4L%2F0Y8wy4VYiO5uN8bfoYhQ7nit1eT%2FGIpv06LqT3QKE9ClIuiKmeXxqMcA%2BVYrF5dRiXdyC%2Ba6nTwG5qncoYioJQ%2BdHwrNWRGwrgboVjc2r3ZqfVaZTtzHCjJq3tENgZPG5JBeN2mA1r1OaXz7PJ9NZOONnTc5%2BkP%2Feos3GUefnLmb%2BOM2gHS4HWB%2FTQUzghpD6VD%2FR5587T4eupp1Cm1BaxsoMs2u7AaSK5VMhsX87cKcyp8N%2BZLNgpeN%2BzmofSok1yArLSWqjOJvzAkDzvX9Lm4cRbJzDEw%3D%3D (Caused by NewConnectionError('<urllib3.connection.HTTPSConnection object at 0x7ff074eee910>: Failed to establish a new connection: [Errno 101] Network is unreachable'))
2024-01-30 16:15:18,423 ERROR   wandb-upload_0:1134333 [internal_api.py:upload_file():2767] upload_file request headers: {'User-Agent': 'python-requests/2.23.0', 'Accept-Encoding': 'gzip, deflate', 'Accept': '*/*', 'Connection': 'keep-alive', 'Content-Length': '15547'}
2024-01-30 16:15:18,423 ERROR   wandb-upload_0:1134333 [internal_api.py:upload_file():2769] upload_file response body: 
2024-01-30 16:15:20,184 DEBUG   HandlerThread:1134333 [handler.py:handle_request():146] handle_request: status_report
2024-01-30 16:15:21,405 DEBUG   HandlerThread:1134333 [handler.py:handle_request():146] handle_request: stop_status
2024-01-30 16:15:21,406 DEBUG   SenderThread:1134333 [sender.py:send_request():409] send_request: stop_status
2024-01-30 16:15:21,446 DEBUG   HandlerThread:1134333 [handler.py:handle_request():146] handle_request: internal_messages
2024-01-30 16:15:25,829 DEBUG   HandlerThread:1134333 [handler.py:handle_request():146] handle_request: status_report
2024-01-30 16:15:30,986 DEBUG   HandlerThread:1134333 [handler.py:handle_request():146] handle_request: status_report
2024-01-30 16:15:36,026 DEBUG   HandlerThread:1134333 [handler.py:handle_request():146] handle_request: status_report
2024-01-30 16:15:36,426 DEBUG   HandlerThread:1134333 [handler.py:handle_request():146] handle_request: stop_status
2024-01-30 16:15:36,426 DEBUG   SenderThread:1134333 [sender.py:send_request():409] send_request: stop_status
2024-01-30 16:15:36,445 DEBUG   HandlerThread:1134333 [handler.py:handle_request():146] handle_request: internal_messages
2024-01-30 16:15:41,747 DEBUG   HandlerThread:1134333 [handler.py:handle_request():146] handle_request: status_report
2024-01-30 16:15:45,057 DEBUG   SenderThread:1134333 [sender.py:send():382] send: stats
2024-01-30 16:15:47,058 DEBUG   HandlerThread:1134333 [handler.py:handle_request():146] handle_request: status_report
2024-01-30 16:15:51,405 DEBUG   HandlerThread:1134333 [handler.py:handle_request():146] handle_request: stop_status
2024-01-30 16:15:51,406 DEBUG   SenderThread:1134333 [sender.py:send_request():409] send_request: stop_status
2024-01-30 16:15:51,449 DEBUG   HandlerThread:1134333 [handler.py:handle_request():146] handle_request: internal_messages
2024-01-30 16:15:52,692 DEBUG   HandlerThread:1134333 [handler.py:handle_request():146] handle_request: status_report
2024-01-30 16:15:57,692 DEBUG   HandlerThread:1134333 [handler.py:handle_request():146] handle_request: status_report
2024-01-30 16:16:01,166 DEBUG   SenderThread:1134333 [sender.py:send():382] send: exit
2024-01-30 16:16:01,166 INFO    SenderThread:1134333 [sender.py:send_exit():589] handling exit code: 1
2024-01-30 16:16:01,167 INFO    SenderThread:1134333 [sender.py:send_exit():591] handling runtime: 346
2024-01-30 16:16:01,167 INFO    SenderThread:1134333 [sender.py:_save_file():1403] saving file wandb-summary.json with policy end
2024-01-30 16:16:01,167 INFO    SenderThread:1134333 [sender.py:send_exit():597] send defer
2024-01-30 16:16:01,167 DEBUG   HandlerThread:1134333 [handler.py:handle_request():146] handle_request: defer
2024-01-30 16:16:01,167 INFO    HandlerThread:1134333 [handler.py:handle_request_defer():172] handle defer: 0
2024-01-30 16:16:01,168 DEBUG   SenderThread:1134333 [sender.py:send_request():409] send_request: defer
2024-01-30 16:16:01,168 INFO    SenderThread:1134333 [sender.py:send_request_defer():613] handle sender defer: 0
2024-01-30 16:16:01,168 INFO    SenderThread:1134333 [sender.py:transition_state():617] send defer: 1
2024-01-30 16:16:01,168 DEBUG   HandlerThread:1134333 [handler.py:handle_request():146] handle_request: defer
2024-01-30 16:16:01,168 INFO    HandlerThread:1134333 [handler.py:handle_request_defer():172] handle defer: 1
2024-01-30 16:16:01,168 DEBUG   SenderThread:1134333 [sender.py:send_request():409] send_request: defer
2024-01-30 16:16:01,168 INFO    SenderThread:1134333 [sender.py:send_request_defer():613] handle sender defer: 1
2024-01-30 16:16:01,168 INFO    SenderThread:1134333 [sender.py:transition_state():617] send defer: 2
2024-01-30 16:16:01,168 DEBUG   HandlerThread:1134333 [handler.py:handle_request():146] handle_request: defer
2024-01-30 16:16:01,168 INFO    HandlerThread:1134333 [handler.py:handle_request_defer():172] handle defer: 2
2024-01-30 16:16:01,168 INFO    HandlerThread:1134333 [system_monitor.py:finish():203] Stopping system monitor
2024-01-30 16:16:01,169 INFO    HandlerThread:1134333 [interfaces.py:finish():202] Joined cpu monitor
2024-01-30 16:16:01,169 INFO    HandlerThread:1134333 [interfaces.py:finish():202] Joined disk monitor
2024-01-30 16:16:01,169 DEBUG   SystemMonitor:1134333 [system_monitor.py:_start():179] Finished system metrics aggregation loop
2024-01-30 16:16:01,169 DEBUG   SystemMonitor:1134333 [system_monitor.py:_start():183] Publishing last batch of metrics
2024-01-30 16:16:02,094 INFO    Thread-12 :1134333 [dir_watcher.py:_on_file_created():271] file/dir created: /home/yanxindong/mkor/bert/wandb/run-20240130_161012-k02uw2vk/files/wandb-summary.json
2024-01-30 16:16:03,095 INFO    Thread-12 :1134333 [dir_watcher.py:_on_file_modified():288] file/dir modified: /home/yanxindong/mkor/bert/wandb/run-20240130_161012-k02uw2vk/files/output.log
2024-01-30 16:16:13,199 INFO    HandlerThread:1134333 [interfaces.py:finish():202] Joined gpu monitor
2024-01-30 16:16:13,200 INFO    HandlerThread:1134333 [interfaces.py:finish():202] Joined memory monitor
2024-01-30 16:16:13,200 INFO    HandlerThread:1134333 [interfaces.py:finish():202] Joined network monitor
2024-01-30 16:16:13,200 DEBUG   HandlerThread:1134333 [handler.py:handle_request():146] handle_request: poll_exit
2024-01-30 16:16:13,200 DEBUG   HandlerThread:1134333 [handler.py:handle_request():146] handle_request: status_report
2024-01-30 16:16:13,200 DEBUG   HandlerThread:1134333 [handler.py:handle_request():146] handle_request: keepalive
2024-01-30 16:16:13,200 DEBUG   HandlerThread:1134333 [handler.py:handle_request():146] handle_request: status_report
2024-01-30 16:16:13,200 DEBUG   HandlerThread:1134333 [handler.py:handle_request():146] handle_request: keepalive
2024-01-30 16:16:13,201 DEBUG   SenderThread:1134333 [sender.py:send_request():409] send_request: defer
2024-01-30 16:16:13,201 INFO    SenderThread:1134333 [sender.py:send_request_defer():613] handle sender defer: 2
2024-01-30 16:16:13,201 INFO    SenderThread:1134333 [sender.py:transition_state():617] send defer: 3
2024-01-30 16:16:13,201 DEBUG   SenderThread:1134333 [sender.py:send():382] send: stats
2024-01-30 16:16:13,202 DEBUG   SenderThread:1134333 [sender.py:send_request():409] send_request: poll_exit
2024-01-30 16:16:13,203 DEBUG   HandlerThread:1134333 [handler.py:handle_request():146] handle_request: defer
2024-01-30 16:16:13,203 INFO    HandlerThread:1134333 [handler.py:handle_request_defer():172] handle defer: 3
2024-01-30 16:16:13,203 DEBUG   SenderThread:1134333 [sender.py:send_request():409] send_request: defer
2024-01-30 16:16:13,203 INFO    SenderThread:1134333 [sender.py:send_request_defer():613] handle sender defer: 3
2024-01-30 16:16:13,203 INFO    SenderThread:1134333 [sender.py:transition_state():617] send defer: 4
2024-01-30 16:16:13,203 DEBUG   HandlerThread:1134333 [handler.py:handle_request():146] handle_request: defer
2024-01-30 16:16:13,203 INFO    HandlerThread:1134333 [handler.py:handle_request_defer():172] handle defer: 4
2024-01-30 16:16:13,203 DEBUG   SenderThread:1134333 [sender.py:send_request():409] send_request: defer
2024-01-30 16:16:13,203 INFO    SenderThread:1134333 [sender.py:send_request_defer():613] handle sender defer: 4
2024-01-30 16:16:13,203 INFO    SenderThread:1134333 [sender.py:transition_state():617] send defer: 5
2024-01-30 16:16:13,203 DEBUG   HandlerThread:1134333 [handler.py:handle_request():146] handle_request: defer
2024-01-30 16:16:13,203 INFO    HandlerThread:1134333 [handler.py:handle_request_defer():172] handle defer: 5
2024-01-30 16:16:13,204 DEBUG   SenderThread:1134333 [sender.py:send():382] send: summary
2024-01-30 16:16:13,204 INFO    SenderThread:1134333 [sender.py:_save_file():1403] saving file wandb-summary.json with policy end
2024-01-30 16:16:13,204 DEBUG   SenderThread:1134333 [sender.py:send_request():409] send_request: defer
2024-01-30 16:16:13,204 INFO    SenderThread:1134333 [sender.py:send_request_defer():613] handle sender defer: 5
2024-01-30 16:16:13,204 INFO    SenderThread:1134333 [sender.py:transition_state():617] send defer: 6
2024-01-30 16:16:13,204 DEBUG   HandlerThread:1134333 [handler.py:handle_request():146] handle_request: defer
2024-01-30 16:16:13,204 INFO    HandlerThread:1134333 [handler.py:handle_request_defer():172] handle defer: 6
2024-01-30 16:16:13,204 DEBUG   SenderThread:1134333 [sender.py:send_request():409] send_request: defer
2024-01-30 16:16:13,204 INFO    SenderThread:1134333 [sender.py:send_request_defer():613] handle sender defer: 6
2024-01-30 16:16:13,204 INFO    SenderThread:1134333 [sender.py:transition_state():617] send defer: 7
2024-01-30 16:16:13,205 DEBUG   HandlerThread:1134333 [handler.py:handle_request():146] handle_request: status_report
2024-01-30 16:16:13,205 DEBUG   HandlerThread:1134333 [handler.py:handle_request():146] handle_request: defer
2024-01-30 16:16:13,205 INFO    HandlerThread:1134333 [handler.py:handle_request_defer():172] handle defer: 7
2024-01-30 16:16:13,205 DEBUG   SenderThread:1134333 [sender.py:send_request():409] send_request: defer
2024-01-30 16:16:13,205 INFO    SenderThread:1134333 [sender.py:send_request_defer():613] handle sender defer: 7
2024-01-30 16:16:13,230 DEBUG   HandlerThread:1134333 [handler.py:handle_request():146] handle_request: poll_exit
2024-01-30 16:16:14,136 INFO    Thread-12 :1134333 [dir_watcher.py:_on_file_modified():288] file/dir modified: /home/yanxindong/mkor/bert/wandb/run-20240130_161012-k02uw2vk/files/wandb-summary.json
2024-01-30 16:16:14,743 INFO    SenderThread:1134333 [sender.py:transition_state():617] send defer: 8
2024-01-30 16:16:14,743 DEBUG   SenderThread:1134333 [sender.py:send_request():409] send_request: poll_exit
2024-01-30 16:16:14,743 DEBUG   HandlerThread:1134333 [handler.py:handle_request():146] handle_request: defer
2024-01-30 16:16:14,743 INFO    HandlerThread:1134333 [handler.py:handle_request_defer():172] handle defer: 8
2024-01-30 16:16:14,743 DEBUG   SenderThread:1134333 [sender.py:send_request():409] send_request: defer
2024-01-30 16:16:14,743 INFO    SenderThread:1134333 [sender.py:send_request_defer():613] handle sender defer: 8
2024-01-30 16:16:14,744 INFO    SenderThread:1134333 [job_builder.py:build():296] Attempting to build job artifact
2024-01-30 16:16:14,744 INFO    SenderThread:1134333 [job_builder.py:_get_source_type():426] is repo sourced job
2024-01-30 16:16:14,907 INFO    SenderThread:1134333 [job_builder.py:build():402] adding wandb-job metadata file
2024-01-30 16:16:14,910 INFO    SenderThread:1134333 [sender.py:transition_state():617] send defer: 9
2024-01-30 16:16:14,910 DEBUG   HandlerThread:1134333 [handler.py:handle_request():146] handle_request: defer
2024-01-30 16:16:14,910 INFO    HandlerThread:1134333 [handler.py:handle_request_defer():172] handle defer: 9
2024-01-30 16:16:14,910 DEBUG   SenderThread:1134333 [sender.py:send():382] send: artifact
2024-01-30 16:16:15,136 INFO    Thread-12 :1134333 [dir_watcher.py:_on_file_modified():288] file/dir modified: /home/yanxindong/mkor/bert/wandb/run-20240130_161012-k02uw2vk/files/output.log
2024-01-30 16:16:15,231 DEBUG   HandlerThread:1134333 [handler.py:handle_request():146] handle_request: poll_exit
2024-01-30 16:16:16,864 ERROR   wandb-upload_1:1134333 [internal_api.py:upload_file():2765] upload_file exception https://storage.googleapis.com/wandb-artifacts-prod/wandb_artifacts/133981200/707680441/174a3d9bc61fec126cc7d5bdff5c6c5a?Expires=1706688976&GoogleAccessId=gorilla-files-url-signer-man%40wandb-production.iam.gserviceaccount.com&Signature=uIbfStEO5cczURRkS4SpZN1KkOF1nNcaFcdRGat7PQLC9Tggo%2BUgYtftkZei%2BxbqK8nyTsqGnJst%2BoaNPYUckSZg0CJDQFyNY%2BXc4SK3OdCAZ6QF7abYQ7mXMJgzBCTkt1OfRFdc3r%2BjOu67iXZeYVHKHEH69S6pAkgIMCIdREHjeQ2O7IcYtfszxeByToc8Otd72VkwVhWvP%2BgAs2vXLIy2bWdRBO%2BcbPM5ejas4MQH%2B7Z0E9qA8ag51zhEkIbqJAmeI8n5dxiJy3Bvgfm%2BMpQtb6LxXCCfQkVOISE6CZ6r3xokc3PPr5dhq6xtQCoawqO%2ByDNeu3A4NzF9S3az6w%3D%3D: HTTPSConnectionPool(host='storage.googleapis.com', port=443): Max retries exceeded with url: /wandb-artifacts-prod/wandb_artifacts/133981200/707680441/174a3d9bc61fec126cc7d5bdff5c6c5a?Expires=1706688976&GoogleAccessId=gorilla-files-url-signer-man%40wandb-production.iam.gserviceaccount.com&Signature=uIbfStEO5cczURRkS4SpZN1KkOF1nNcaFcdRGat7PQLC9Tggo%2BUgYtftkZei%2BxbqK8nyTsqGnJst%2BoaNPYUckSZg0CJDQFyNY%2BXc4SK3OdCAZ6QF7abYQ7mXMJgzBCTkt1OfRFdc3r%2BjOu67iXZeYVHKHEH69S6pAkgIMCIdREHjeQ2O7IcYtfszxeByToc8Otd72VkwVhWvP%2BgAs2vXLIy2bWdRBO%2BcbPM5ejas4MQH%2B7Z0E9qA8ag51zhEkIbqJAmeI8n5dxiJy3Bvgfm%2BMpQtb6LxXCCfQkVOISE6CZ6r3xokc3PPr5dhq6xtQCoawqO%2ByDNeu3A4NzF9S3az6w%3D%3D (Caused by NewConnectionError('<urllib3.connection.HTTPSConnection object at 0x7ff075f06e20>: Failed to establish a new connection: [Errno 101] Network is unreachable'))
2024-01-30 16:16:16,864 ERROR   wandb-upload_1:1134333 [internal_api.py:upload_file():2767] upload_file request headers: {'User-Agent': 'python-requests/2.23.0', 'Accept-Encoding': 'gzip, deflate', 'Accept': '*/*', 'Connection': 'keep-alive', 'Content-MD5': 'F0o9m8Yf7BJsx9W9/1xsWg==', 'Content-Type': 'text/plain; charset=utf-8', 'Content-Length': '2179'}
2024-01-30 16:16:16,864 ERROR   wandb-upload_1:1134333 [internal_api.py:upload_file():2769] upload_file response body: 
2024-01-30 16:16:17,452 ERROR   wandb-upload_2:1134333 [internal_api.py:upload_file():2765] upload_file exception https://storage.googleapis.com/wandb-artifacts-prod/wandb_artifacts/133981200/707680441/6873c23a2381d1524249eb1a948a45a5?Expires=1706688977&GoogleAccessId=gorilla-files-url-signer-man%40wandb-production.iam.gserviceaccount.com&Signature=qIJkPWvML5xinRceuHOzA0bUaw3Do9%2F91nWMxuxxepOVZJnxcZAb%2FvWPuaHz%2BgN%2FpMtlTLUXpb61voC%2Btv0PuVKFX1JYa4wzyYH9JGNauViHKrnTWzhOE2Y%2FUN%2FSjAS8vRKa2evko8P8FXApaLaBiuKPxkEJTiUDsjWR0C4JNp8M6LhslScdVqaq1EzjjBf7lF6GHjKSCdIcLc4MQtW5htoqnJCYQiEeokqd5H6kZH1%2BMgmEI6wMFyH6tMEt1c%2FZx0u2NJsKqXgcZLsf%2FcCERAg8fgoDojG59bTu5L2ioIfAUOwTrbm75KUZ6Mhiz9mbXbjiC0Ek65fb6CwqmWvW%2Bw%3D%3D: HTTPSConnectionPool(host='storage.googleapis.com', port=443): Max retries exceeded with url: /wandb-artifacts-prod/wandb_artifacts/133981200/707680441/6873c23a2381d1524249eb1a948a45a5?Expires=1706688977&GoogleAccessId=gorilla-files-url-signer-man%40wandb-production.iam.gserviceaccount.com&Signature=qIJkPWvML5xinRceuHOzA0bUaw3Do9%2F91nWMxuxxepOVZJnxcZAb%2FvWPuaHz%2BgN%2FpMtlTLUXpb61voC%2Btv0PuVKFX1JYa4wzyYH9JGNauViHKrnTWzhOE2Y%2FUN%2FSjAS8vRKa2evko8P8FXApaLaBiuKPxkEJTiUDsjWR0C4JNp8M6LhslScdVqaq1EzjjBf7lF6GHjKSCdIcLc4MQtW5htoqnJCYQiEeokqd5H6kZH1%2BMgmEI6wMFyH6tMEt1c%2FZx0u2NJsKqXgcZLsf%2FcCERAg8fgoDojG59bTu5L2ioIfAUOwTrbm75KUZ6Mhiz9mbXbjiC0Ek65fb6CwqmWvW%2Bw%3D%3D (Caused by NewConnectionError('<urllib3.connection.HTTPSConnection object at 0x7ff074e1c1c0>: Failed to establish a new connection: [Errno 101] Network is unreachable'))
2024-01-30 16:16:17,452 ERROR   wandb-upload_2:1134333 [internal_api.py:upload_file():2767] upload_file request headers: {'User-Agent': 'python-requests/2.23.0', 'Accept-Encoding': 'gzip, deflate', 'Accept': '*/*', 'Connection': 'keep-alive', 'Content-MD5': 'aHPCOiOB0VJCSesalIpFpQ==', 'Content-Type': 'application/json', 'Content-Length': '609'}
2024-01-30 16:16:17,452 ERROR   wandb-upload_2:1134333 [internal_api.py:upload_file():2769] upload_file response body: 
2024-01-30 16:16:17,899 ERROR   wandb-upload_1:1134333 [internal_api.py:upload_file():2765] upload_file exception https://storage.googleapis.com/wandb-artifacts-prod/wandb_artifacts/133981200/707680441/174a3d9bc61fec126cc7d5bdff5c6c5a?Expires=1706688976&GoogleAccessId=gorilla-files-url-signer-man%40wandb-production.iam.gserviceaccount.com&Signature=uIbfStEO5cczURRkS4SpZN1KkOF1nNcaFcdRGat7PQLC9Tggo%2BUgYtftkZei%2BxbqK8nyTsqGnJst%2BoaNPYUckSZg0CJDQFyNY%2BXc4SK3OdCAZ6QF7abYQ7mXMJgzBCTkt1OfRFdc3r%2BjOu67iXZeYVHKHEH69S6pAkgIMCIdREHjeQ2O7IcYtfszxeByToc8Otd72VkwVhWvP%2BgAs2vXLIy2bWdRBO%2BcbPM5ejas4MQH%2B7Z0E9qA8ag51zhEkIbqJAmeI8n5dxiJy3Bvgfm%2BMpQtb6LxXCCfQkVOISE6CZ6r3xokc3PPr5dhq6xtQCoawqO%2ByDNeu3A4NzF9S3az6w%3D%3D: HTTPSConnectionPool(host='storage.googleapis.com', port=443): Max retries exceeded with url: /wandb-artifacts-prod/wandb_artifacts/133981200/707680441/174a3d9bc61fec126cc7d5bdff5c6c5a?Expires=1706688976&GoogleAccessId=gorilla-files-url-signer-man%40wandb-production.iam.gserviceaccount.com&Signature=uIbfStEO5cczURRkS4SpZN1KkOF1nNcaFcdRGat7PQLC9Tggo%2BUgYtftkZei%2BxbqK8nyTsqGnJst%2BoaNPYUckSZg0CJDQFyNY%2BXc4SK3OdCAZ6QF7abYQ7mXMJgzBCTkt1OfRFdc3r%2BjOu67iXZeYVHKHEH69S6pAkgIMCIdREHjeQ2O7IcYtfszxeByToc8Otd72VkwVhWvP%2BgAs2vXLIy2bWdRBO%2BcbPM5ejas4MQH%2B7Z0E9qA8ag51zhEkIbqJAmeI8n5dxiJy3Bvgfm%2BMpQtb6LxXCCfQkVOISE6CZ6r3xokc3PPr5dhq6xtQCoawqO%2ByDNeu3A4NzF9S3az6w%3D%3D (Caused by NewConnectionError('<urllib3.connection.HTTPSConnection object at 0x7ff074e1cdf0>: Failed to establish a new connection: [Errno 101] Network is unreachable'))
2024-01-30 16:16:17,900 ERROR   wandb-upload_1:1134333 [internal_api.py:upload_file():2767] upload_file request headers: {'User-Agent': 'python-requests/2.23.0', 'Accept-Encoding': 'gzip, deflate', 'Accept': '*/*', 'Connection': 'keep-alive', 'Content-MD5': 'F0o9m8Yf7BJsx9W9/1xsWg==', 'Content-Type': 'text/plain; charset=utf-8', 'Content-Length': '2179'}
2024-01-30 16:16:17,900 ERROR   wandb-upload_1:1134333 [internal_api.py:upload_file():2769] upload_file response body: 
2024-01-30 16:16:18,540 ERROR   wandb-upload_2:1134333 [internal_api.py:upload_file():2765] upload_file exception https://storage.googleapis.com/wandb-artifacts-prod/wandb_artifacts/133981200/707680441/6873c23a2381d1524249eb1a948a45a5?Expires=1706688977&GoogleAccessId=gorilla-files-url-signer-man%40wandb-production.iam.gserviceaccount.com&Signature=qIJkPWvML5xinRceuHOzA0bUaw3Do9%2F91nWMxuxxepOVZJnxcZAb%2FvWPuaHz%2BgN%2FpMtlTLUXpb61voC%2Btv0PuVKFX1JYa4wzyYH9JGNauViHKrnTWzhOE2Y%2FUN%2FSjAS8vRKa2evko8P8FXApaLaBiuKPxkEJTiUDsjWR0C4JNp8M6LhslScdVqaq1EzjjBf7lF6GHjKSCdIcLc4MQtW5htoqnJCYQiEeokqd5H6kZH1%2BMgmEI6wMFyH6tMEt1c%2FZx0u2NJsKqXgcZLsf%2FcCERAg8fgoDojG59bTu5L2ioIfAUOwTrbm75KUZ6Mhiz9mbXbjiC0Ek65fb6CwqmWvW%2Bw%3D%3D: HTTPSConnectionPool(host='storage.googleapis.com', port=443): Max retries exceeded with url: /wandb-artifacts-prod/wandb_artifacts/133981200/707680441/6873c23a2381d1524249eb1a948a45a5?Expires=1706688977&GoogleAccessId=gorilla-files-url-signer-man%40wandb-production.iam.gserviceaccount.com&Signature=qIJkPWvML5xinRceuHOzA0bUaw3Do9%2F91nWMxuxxepOVZJnxcZAb%2FvWPuaHz%2BgN%2FpMtlTLUXpb61voC%2Btv0PuVKFX1JYa4wzyYH9JGNauViHKrnTWzhOE2Y%2FUN%2FSjAS8vRKa2evko8P8FXApaLaBiuKPxkEJTiUDsjWR0C4JNp8M6LhslScdVqaq1EzjjBf7lF6GHjKSCdIcLc4MQtW5htoqnJCYQiEeokqd5H6kZH1%2BMgmEI6wMFyH6tMEt1c%2FZx0u2NJsKqXgcZLsf%2FcCERAg8fgoDojG59bTu5L2ioIfAUOwTrbm75KUZ6Mhiz9mbXbjiC0Ek65fb6CwqmWvW%2Bw%3D%3D (Caused by NewConnectionError('<urllib3.connection.HTTPSConnection object at 0x7ff074e36550>: Failed to establish a new connection: [Errno 101] Network is unreachable'))
2024-01-30 16:16:18,540 ERROR   wandb-upload_2:1134333 [internal_api.py:upload_file():2767] upload_file request headers: {'User-Agent': 'python-requests/2.23.0', 'Accept-Encoding': 'gzip, deflate', 'Accept': '*/*', 'Connection': 'keep-alive', 'Content-MD5': 'aHPCOiOB0VJCSesalIpFpQ==', 'Content-Type': 'application/json', 'Content-Length': '609'}
2024-01-30 16:16:18,540 ERROR   wandb-upload_2:1134333 [internal_api.py:upload_file():2769] upload_file response body: 
2024-01-30 16:16:18,540 INFO    wandb-upload_2:1134333 [retry.py:__call__():172] Retry attempt failed:
Traceback (most recent call last):
  File "/home/yanxindong/anaconda/envs/eva/lib/python3.8/site-packages/urllib3/connection.py", line 159, in _new_conn
    conn = connection.create_connection(
  File "/home/yanxindong/anaconda/envs/eva/lib/python3.8/site-packages/urllib3/util/connection.py", line 84, in create_connection
    raise err
  File "/home/yanxindong/anaconda/envs/eva/lib/python3.8/site-packages/urllib3/util/connection.py", line 74, in create_connection
    sock.connect(sa)
OSError: [Errno 101] Network is unreachable

During handling of the above exception, another exception occurred:

Traceback (most recent call last):
  File "/home/yanxindong/anaconda/envs/eva/lib/python3.8/site-packages/urllib3/connectionpool.py", line 670, in urlopen
    httplib_response = self._make_request(
  File "/home/yanxindong/anaconda/envs/eva/lib/python3.8/site-packages/urllib3/connectionpool.py", line 381, in _make_request
    self._validate_conn(conn)
  File "/home/yanxindong/anaconda/envs/eva/lib/python3.8/site-packages/urllib3/connectionpool.py", line 978, in _validate_conn
    conn.connect()
  File "/home/yanxindong/anaconda/envs/eva/lib/python3.8/site-packages/urllib3/connection.py", line 309, in connect
    conn = self._new_conn()
  File "/home/yanxindong/anaconda/envs/eva/lib/python3.8/site-packages/urllib3/connection.py", line 171, in _new_conn
    raise NewConnectionError(
urllib3.exceptions.NewConnectionError: <urllib3.connection.HTTPSConnection object at 0x7ff074e36550>: Failed to establish a new connection: [Errno 101] Network is unreachable

During handling of the above exception, another exception occurred:

Traceback (most recent call last):
  File "/home/yanxindong/anaconda/envs/eva/lib/python3.8/site-packages/requests/adapters.py", line 439, in send
    resp = conn.urlopen(
  File "/home/yanxindong/anaconda/envs/eva/lib/python3.8/site-packages/urllib3/connectionpool.py", line 726, in urlopen
    retries = retries.increment(
  File "/home/yanxindong/anaconda/envs/eva/lib/python3.8/site-packages/urllib3/util/retry.py", line 446, in increment
    raise MaxRetryError(_pool, url, error or ResponseError(cause))
urllib3.exceptions.MaxRetryError: HTTPSConnectionPool(host='storage.googleapis.com', port=443): Max retries exceeded with url: /wandb-artifacts-prod/wandb_artifacts/133981200/707680441/6873c23a2381d1524249eb1a948a45a5?Expires=1706688977&GoogleAccessId=gorilla-files-url-signer-man%40wandb-production.iam.gserviceaccount.com&Signature=qIJkPWvML5xinRceuHOzA0bUaw3Do9%2F91nWMxuxxepOVZJnxcZAb%2FvWPuaHz%2BgN%2FpMtlTLUXpb61voC%2Btv0PuVKFX1JYa4wzyYH9JGNauViHKrnTWzhOE2Y%2FUN%2FSjAS8vRKa2evko8P8FXApaLaBiuKPxkEJTiUDsjWR0C4JNp8M6LhslScdVqaq1EzjjBf7lF6GHjKSCdIcLc4MQtW5htoqnJCYQiEeokqd5H6kZH1%2BMgmEI6wMFyH6tMEt1c%2FZx0u2NJsKqXgcZLsf%2FcCERAg8fgoDojG59bTu5L2ioIfAUOwTrbm75KUZ6Mhiz9mbXbjiC0Ek65fb6CwqmWvW%2Bw%3D%3D (Caused by NewConnectionError('<urllib3.connection.HTTPSConnection object at 0x7ff074e36550>: Failed to establish a new connection: [Errno 101] Network is unreachable'))

During handling of the above exception, another exception occurred:

Traceback (most recent call last):
  File "/home/yanxindong/anaconda/envs/eva/lib/python3.8/site-packages/wandb/sdk/internal/internal_api.py", line 2758, in upload_file
    response = self._upload_file_session.put(
  File "/home/yanxindong/anaconda/envs/eva/lib/python3.8/site-packages/requests/sessions.py", line 590, in put
    return self.request('PUT', url, data=data, **kwargs)
  File "/home/yanxindong/anaconda/envs/eva/lib/python3.8/site-packages/requests/sessions.py", line 530, in request
    resp = self.send(prep, **send_kwargs)
  File "/home/yanxindong/anaconda/envs/eva/lib/python3.8/site-packages/requests/sessions.py", line 643, in send
    r = adapter.send(request, **kwargs)
  File "/home/yanxindong/anaconda/envs/eva/lib/python3.8/site-packages/requests/adapters.py", line 516, in send
    raise ConnectionError(e, request=request)
requests.exceptions.ConnectionError: HTTPSConnectionPool(host='storage.googleapis.com', port=443): Max retries exceeded with url: /wandb-artifacts-prod/wandb_artifacts/133981200/707680441/6873c23a2381d1524249eb1a948a45a5?Expires=1706688977&GoogleAccessId=gorilla-files-url-signer-man%40wandb-production.iam.gserviceaccount.com&Signature=qIJkPWvML5xinRceuHOzA0bUaw3Do9%2F91nWMxuxxepOVZJnxcZAb%2FvWPuaHz%2BgN%2FpMtlTLUXpb61voC%2Btv0PuVKFX1JYa4wzyYH9JGNauViHKrnTWzhOE2Y%2FUN%2FSjAS8vRKa2evko8P8FXApaLaBiuKPxkEJTiUDsjWR0C4JNp8M6LhslScdVqaq1EzjjBf7lF6GHjKSCdIcLc4MQtW5htoqnJCYQiEeokqd5H6kZH1%2BMgmEI6wMFyH6tMEt1c%2FZx0u2NJsKqXgcZLsf%2FcCERAg8fgoDojG59bTu5L2ioIfAUOwTrbm75KUZ6Mhiz9mbXbjiC0Ek65fb6CwqmWvW%2Bw%3D%3D (Caused by NewConnectionError('<urllib3.connection.HTTPSConnection object at 0x7ff074e36550>: Failed to establish a new connection: [Errno 101] Network is unreachable'))

During handling of the above exception, another exception occurred:

Traceback (most recent call last):
  File "/home/yanxindong/anaconda/envs/eva/lib/python3.8/site-packages/wandb/sdk/lib/retry.py", line 131, in __call__
    result = self._call_fn(*args, **kwargs)
  File "/home/yanxindong/anaconda/envs/eva/lib/python3.8/site-packages/wandb/sdk/internal/internal_api.py", line 2789, in upload_file
    raise _e.with_traceback(sys.exc_info()[2])
  File "/home/yanxindong/anaconda/envs/eva/lib/python3.8/site-packages/wandb/sdk/internal/internal_api.py", line 2758, in upload_file
    response = self._upload_file_session.put(
  File "/home/yanxindong/anaconda/envs/eva/lib/python3.8/site-packages/requests/sessions.py", line 590, in put
    return self.request('PUT', url, data=data, **kwargs)
  File "/home/yanxindong/anaconda/envs/eva/lib/python3.8/site-packages/requests/sessions.py", line 530, in request
    resp = self.send(prep, **send_kwargs)
  File "/home/yanxindong/anaconda/envs/eva/lib/python3.8/site-packages/requests/sessions.py", line 643, in send
    r = adapter.send(request, **kwargs)
  File "/home/yanxindong/anaconda/envs/eva/lib/python3.8/site-packages/requests/adapters.py", line 516, in send
    raise ConnectionError(e, request=request)
wandb.sdk.lib.retry.TransientError: None
2024-01-30 16:16:19,986 ERROR   wandb-upload_1:1134333 [internal_api.py:upload_file():2765] upload_file exception https://storage.googleapis.com/wandb-artifacts-prod/wandb_artifacts/133981200/707680441/174a3d9bc61fec126cc7d5bdff5c6c5a?Expires=1706688976&GoogleAccessId=gorilla-files-url-signer-man%40wandb-production.iam.gserviceaccount.com&Signature=uIbfStEO5cczURRkS4SpZN1KkOF1nNcaFcdRGat7PQLC9Tggo%2BUgYtftkZei%2BxbqK8nyTsqGnJst%2BoaNPYUckSZg0CJDQFyNY%2BXc4SK3OdCAZ6QF7abYQ7mXMJgzBCTkt1OfRFdc3r%2BjOu67iXZeYVHKHEH69S6pAkgIMCIdREHjeQ2O7IcYtfszxeByToc8Otd72VkwVhWvP%2BgAs2vXLIy2bWdRBO%2BcbPM5ejas4MQH%2B7Z0E9qA8ag51zhEkIbqJAmeI8n5dxiJy3Bvgfm%2BMpQtb6LxXCCfQkVOISE6CZ6r3xokc3PPr5dhq6xtQCoawqO%2ByDNeu3A4NzF9S3az6w%3D%3D: HTTPSConnectionPool(host='storage.googleapis.com', port=443): Max retries exceeded with url: /wandb-artifacts-prod/wandb_artifacts/133981200/707680441/174a3d9bc61fec126cc7d5bdff5c6c5a?Expires=1706688976&GoogleAccessId=gorilla-files-url-signer-man%40wandb-production.iam.gserviceaccount.com&Signature=uIbfStEO5cczURRkS4SpZN1KkOF1nNcaFcdRGat7PQLC9Tggo%2BUgYtftkZei%2BxbqK8nyTsqGnJst%2BoaNPYUckSZg0CJDQFyNY%2BXc4SK3OdCAZ6QF7abYQ7mXMJgzBCTkt1OfRFdc3r%2BjOu67iXZeYVHKHEH69S6pAkgIMCIdREHjeQ2O7IcYtfszxeByToc8Otd72VkwVhWvP%2BgAs2vXLIy2bWdRBO%2BcbPM5ejas4MQH%2B7Z0E9qA8ag51zhEkIbqJAmeI8n5dxiJy3Bvgfm%2BMpQtb6LxXCCfQkVOISE6CZ6r3xokc3PPr5dhq6xtQCoawqO%2ByDNeu3A4NzF9S3az6w%3D%3D (Caused by NewConnectionError('<urllib3.connection.HTTPSConnection object at 0x7ff074e36820>: Failed to establish a new connection: [Errno 101] Network is unreachable'))
2024-01-30 16:16:19,986 ERROR   wandb-upload_1:1134333 [internal_api.py:upload_file():2767] upload_file request headers: {'User-Agent': 'python-requests/2.23.0', 'Accept-Encoding': 'gzip, deflate', 'Accept': '*/*', 'Connection': 'keep-alive', 'Content-MD5': 'F0o9m8Yf7BJsx9W9/1xsWg==', 'Content-Type': 'text/plain; charset=utf-8', 'Content-Length': '2179'}
2024-01-30 16:16:19,986 ERROR   wandb-upload_1:1134333 [internal_api.py:upload_file():2769] upload_file response body: 
2024-01-30 16:16:20,233 DEBUG   HandlerThread:1134333 [handler.py:handle_request():146] handle_request: keepalive
2024-01-30 16:16:20,606 ERROR   wandb-upload_2:1134333 [internal_api.py:upload_file():2765] upload_file exception https://storage.googleapis.com/wandb-artifacts-prod/wandb_artifacts/133981200/707680441/6873c23a2381d1524249eb1a948a45a5?Expires=1706688977&GoogleAccessId=gorilla-files-url-signer-man%40wandb-production.iam.gserviceaccount.com&Signature=qIJkPWvML5xinRceuHOzA0bUaw3Do9%2F91nWMxuxxepOVZJnxcZAb%2FvWPuaHz%2BgN%2FpMtlTLUXpb61voC%2Btv0PuVKFX1JYa4wzyYH9JGNauViHKrnTWzhOE2Y%2FUN%2FSjAS8vRKa2evko8P8FXApaLaBiuKPxkEJTiUDsjWR0C4JNp8M6LhslScdVqaq1EzjjBf7lF6GHjKSCdIcLc4MQtW5htoqnJCYQiEeokqd5H6kZH1%2BMgmEI6wMFyH6tMEt1c%2FZx0u2NJsKqXgcZLsf%2FcCERAg8fgoDojG59bTu5L2ioIfAUOwTrbm75KUZ6Mhiz9mbXbjiC0Ek65fb6CwqmWvW%2Bw%3D%3D: HTTPSConnectionPool(host='storage.googleapis.com', port=443): Max retries exceeded with url: /wandb-artifacts-prod/wandb_artifacts/133981200/707680441/6873c23a2381d1524249eb1a948a45a5?Expires=1706688977&GoogleAccessId=gorilla-files-url-signer-man%40wandb-production.iam.gserviceaccount.com&Signature=qIJkPWvML5xinRceuHOzA0bUaw3Do9%2F91nWMxuxxepOVZJnxcZAb%2FvWPuaHz%2BgN%2FpMtlTLUXpb61voC%2Btv0PuVKFX1JYa4wzyYH9JGNauViHKrnTWzhOE2Y%2FUN%2FSjAS8vRKa2evko8P8FXApaLaBiuKPxkEJTiUDsjWR0C4JNp8M6LhslScdVqaq1EzjjBf7lF6GHjKSCdIcLc4MQtW5htoqnJCYQiEeokqd5H6kZH1%2BMgmEI6wMFyH6tMEt1c%2FZx0u2NJsKqXgcZLsf%2FcCERAg8fgoDojG59bTu5L2ioIfAUOwTrbm75KUZ6Mhiz9mbXbjiC0Ek65fb6CwqmWvW%2Bw%3D%3D (Caused by NewConnectionError('<urllib3.connection.HTTPSConnection object at 0x7ff074e362e0>: Failed to establish a new connection: [Errno 101] Network is unreachable'))
2024-01-30 16:16:20,606 ERROR   wandb-upload_2:1134333 [internal_api.py:upload_file():2767] upload_file request headers: {'User-Agent': 'python-requests/2.23.0', 'Accept-Encoding': 'gzip, deflate', 'Accept': '*/*', 'Connection': 'keep-alive', 'Content-MD5': 'aHPCOiOB0VJCSesalIpFpQ==', 'Content-Type': 'application/json', 'Content-Length': '609'}
2024-01-30 16:16:20,607 ERROR   wandb-upload_2:1134333 [internal_api.py:upload_file():2769] upload_file response body: 
2024-01-30 16:16:24,686 ERROR   wandb-upload_2:1134333 [internal_api.py:upload_file():2765] upload_file exception https://storage.googleapis.com/wandb-artifacts-prod/wandb_artifacts/133981200/707680441/6873c23a2381d1524249eb1a948a45a5?Expires=1706688977&GoogleAccessId=gorilla-files-url-signer-man%40wandb-production.iam.gserviceaccount.com&Signature=qIJkPWvML5xinRceuHOzA0bUaw3Do9%2F91nWMxuxxepOVZJnxcZAb%2FvWPuaHz%2BgN%2FpMtlTLUXpb61voC%2Btv0PuVKFX1JYa4wzyYH9JGNauViHKrnTWzhOE2Y%2FUN%2FSjAS8vRKa2evko8P8FXApaLaBiuKPxkEJTiUDsjWR0C4JNp8M6LhslScdVqaq1EzjjBf7lF6GHjKSCdIcLc4MQtW5htoqnJCYQiEeokqd5H6kZH1%2BMgmEI6wMFyH6tMEt1c%2FZx0u2NJsKqXgcZLsf%2FcCERAg8fgoDojG59bTu5L2ioIfAUOwTrbm75KUZ6Mhiz9mbXbjiC0Ek65fb6CwqmWvW%2Bw%3D%3D: HTTPSConnectionPool(host='storage.googleapis.com', port=443): Max retries exceeded with url: /wandb-artifacts-prod/wandb_artifacts/133981200/707680441/6873c23a2381d1524249eb1a948a45a5?Expires=1706688977&GoogleAccessId=gorilla-files-url-signer-man%40wandb-production.iam.gserviceaccount.com&Signature=qIJkPWvML5xinRceuHOzA0bUaw3Do9%2F91nWMxuxxepOVZJnxcZAb%2FvWPuaHz%2BgN%2FpMtlTLUXpb61voC%2Btv0PuVKFX1JYa4wzyYH9JGNauViHKrnTWzhOE2Y%2FUN%2FSjAS8vRKa2evko8P8FXApaLaBiuKPxkEJTiUDsjWR0C4JNp8M6LhslScdVqaq1EzjjBf7lF6GHjKSCdIcLc4MQtW5htoqnJCYQiEeokqd5H6kZH1%2BMgmEI6wMFyH6tMEt1c%2FZx0u2NJsKqXgcZLsf%2FcCERAg8fgoDojG59bTu5L2ioIfAUOwTrbm75KUZ6Mhiz9mbXbjiC0Ek65fb6CwqmWvW%2Bw%3D%3D (Caused by NewConnectionError('<urllib3.connection.HTTPSConnection object at 0x7ff074e1c190>: Failed to establish a new connection: [Errno 101] Network is unreachable'))
2024-01-30 16:16:24,686 ERROR   wandb-upload_2:1134333 [internal_api.py:upload_file():2767] upload_file request headers: {'User-Agent': 'python-requests/2.23.0', 'Accept-Encoding': 'gzip, deflate', 'Accept': '*/*', 'Connection': 'keep-alive', 'Content-MD5': 'aHPCOiOB0VJCSesalIpFpQ==', 'Content-Type': 'application/json', 'Content-Length': '609'}
2024-01-30 16:16:24,686 ERROR   wandb-upload_2:1134333 [internal_api.py:upload_file():2769] upload_file response body: 
2024-01-30 16:16:24,709 ERROR   wandb-upload_1:1134333 [internal_api.py:upload_file():2765] upload_file exception https://storage.googleapis.com/wandb-artifacts-prod/wandb_artifacts/133981200/707680441/174a3d9bc61fec126cc7d5bdff5c6c5a?Expires=1706688976&GoogleAccessId=gorilla-files-url-signer-man%40wandb-production.iam.gserviceaccount.com&Signature=uIbfStEO5cczURRkS4SpZN1KkOF1nNcaFcdRGat7PQLC9Tggo%2BUgYtftkZei%2BxbqK8nyTsqGnJst%2BoaNPYUckSZg0CJDQFyNY%2BXc4SK3OdCAZ6QF7abYQ7mXMJgzBCTkt1OfRFdc3r%2BjOu67iXZeYVHKHEH69S6pAkgIMCIdREHjeQ2O7IcYtfszxeByToc8Otd72VkwVhWvP%2BgAs2vXLIy2bWdRBO%2BcbPM5ejas4MQH%2B7Z0E9qA8ag51zhEkIbqJAmeI8n5dxiJy3Bvgfm%2BMpQtb6LxXCCfQkVOISE6CZ6r3xokc3PPr5dhq6xtQCoawqO%2ByDNeu3A4NzF9S3az6w%3D%3D: HTTPSConnectionPool(host='storage.googleapis.com', port=443): Max retries exceeded with url: /wandb-artifacts-prod/wandb_artifacts/133981200/707680441/174a3d9bc61fec126cc7d5bdff5c6c5a?Expires=1706688976&GoogleAccessId=gorilla-files-url-signer-man%40wandb-production.iam.gserviceaccount.com&Signature=uIbfStEO5cczURRkS4SpZN1KkOF1nNcaFcdRGat7PQLC9Tggo%2BUgYtftkZei%2BxbqK8nyTsqGnJst%2BoaNPYUckSZg0CJDQFyNY%2BXc4SK3OdCAZ6QF7abYQ7mXMJgzBCTkt1OfRFdc3r%2BjOu67iXZeYVHKHEH69S6pAkgIMCIdREHjeQ2O7IcYtfszxeByToc8Otd72VkwVhWvP%2BgAs2vXLIy2bWdRBO%2BcbPM5ejas4MQH%2B7Z0E9qA8ag51zhEkIbqJAmeI8n5dxiJy3Bvgfm%2BMpQtb6LxXCCfQkVOISE6CZ6r3xokc3PPr5dhq6xtQCoawqO%2ByDNeu3A4NzF9S3az6w%3D%3D (Caused by NewConnectionError('<urllib3.connection.HTTPSConnection object at 0x7ff074e361f0>: Failed to establish a new connection: [Errno 101] Network is unreachable'))
2024-01-30 16:16:24,709 ERROR   wandb-upload_1:1134333 [internal_api.py:upload_file():2767] upload_file request headers: {'User-Agent': 'python-requests/2.23.0', 'Accept-Encoding': 'gzip, deflate', 'Accept': '*/*', 'Connection': 'keep-alive', 'Content-MD5': 'F0o9m8Yf7BJsx9W9/1xsWg==', 'Content-Type': 'text/plain; charset=utf-8', 'Content-Length': '2179'}
2024-01-30 16:16:24,709 ERROR   wandb-upload_1:1134333 [internal_api.py:upload_file():2769] upload_file response body: 
2024-01-30 16:16:25,235 DEBUG   HandlerThread:1134333 [handler.py:handle_request():146] handle_request: keepalive
2024-01-30 16:16:30,237 DEBUG   HandlerThread:1134333 [handler.py:handle_request():146] handle_request: keepalive
2024-01-30 16:16:32,842 ERROR   wandb-upload_1:1134333 [internal_api.py:upload_file():2765] upload_file exception https://storage.googleapis.com/wandb-artifacts-prod/wandb_artifacts/133981200/707680441/174a3d9bc61fec126cc7d5bdff5c6c5a?Expires=1706688976&GoogleAccessId=gorilla-files-url-signer-man%40wandb-production.iam.gserviceaccount.com&Signature=uIbfStEO5cczURRkS4SpZN1KkOF1nNcaFcdRGat7PQLC9Tggo%2BUgYtftkZei%2BxbqK8nyTsqGnJst%2BoaNPYUckSZg0CJDQFyNY%2BXc4SK3OdCAZ6QF7abYQ7mXMJgzBCTkt1OfRFdc3r%2BjOu67iXZeYVHKHEH69S6pAkgIMCIdREHjeQ2O7IcYtfszxeByToc8Otd72VkwVhWvP%2BgAs2vXLIy2bWdRBO%2BcbPM5ejas4MQH%2B7Z0E9qA8ag51zhEkIbqJAmeI8n5dxiJy3Bvgfm%2BMpQtb6LxXCCfQkVOISE6CZ6r3xokc3PPr5dhq6xtQCoawqO%2ByDNeu3A4NzF9S3az6w%3D%3D: HTTPSConnectionPool(host='storage.googleapis.com', port=443): Max retries exceeded with url: /wandb-artifacts-prod/wandb_artifacts/133981200/707680441/174a3d9bc61fec126cc7d5bdff5c6c5a?Expires=1706688976&GoogleAccessId=gorilla-files-url-signer-man%40wandb-production.iam.gserviceaccount.com&Signature=uIbfStEO5cczURRkS4SpZN1KkOF1nNcaFcdRGat7PQLC9Tggo%2BUgYtftkZei%2BxbqK8nyTsqGnJst%2BoaNPYUckSZg0CJDQFyNY%2BXc4SK3OdCAZ6QF7abYQ7mXMJgzBCTkt1OfRFdc3r%2BjOu67iXZeYVHKHEH69S6pAkgIMCIdREHjeQ2O7IcYtfszxeByToc8Otd72VkwVhWvP%2BgAs2vXLIy2bWdRBO%2BcbPM5ejas4MQH%2B7Z0E9qA8ag51zhEkIbqJAmeI8n5dxiJy3Bvgfm%2BMpQtb6LxXCCfQkVOISE6CZ6r3xokc3PPr5dhq6xtQCoawqO%2ByDNeu3A4NzF9S3az6w%3D%3D (Caused by NewConnectionError('<urllib3.connection.HTTPSConnection object at 0x7ff074e36af0>: Failed to establish a new connection: [Errno 101] Network is unreachable'))
2024-01-30 16:16:32,842 ERROR   wandb-upload_1:1134333 [internal_api.py:upload_file():2767] upload_file request headers: {'User-Agent': 'python-requests/2.23.0', 'Accept-Encoding': 'gzip, deflate', 'Accept': '*/*', 'Connection': 'keep-alive', 'Content-MD5': 'F0o9m8Yf7BJsx9W9/1xsWg==', 'Content-Type': 'text/plain; charset=utf-8', 'Content-Length': '2179'}
2024-01-30 16:16:32,842 ERROR   wandb-upload_1:1134333 [internal_api.py:upload_file():2769] upload_file response body: 
2024-01-30 16:16:33,743 ERROR   wandb-upload_2:1134333 [internal_api.py:upload_file():2765] upload_file exception https://storage.googleapis.com/wandb-artifacts-prod/wandb_artifacts/133981200/707680441/6873c23a2381d1524249eb1a948a45a5?Expires=1706688977&GoogleAccessId=gorilla-files-url-signer-man%40wandb-production.iam.gserviceaccount.com&Signature=qIJkPWvML5xinRceuHOzA0bUaw3Do9%2F91nWMxuxxepOVZJnxcZAb%2FvWPuaHz%2BgN%2FpMtlTLUXpb61voC%2Btv0PuVKFX1JYa4wzyYH9JGNauViHKrnTWzhOE2Y%2FUN%2FSjAS8vRKa2evko8P8FXApaLaBiuKPxkEJTiUDsjWR0C4JNp8M6LhslScdVqaq1EzjjBf7lF6GHjKSCdIcLc4MQtW5htoqnJCYQiEeokqd5H6kZH1%2BMgmEI6wMFyH6tMEt1c%2FZx0u2NJsKqXgcZLsf%2FcCERAg8fgoDojG59bTu5L2ioIfAUOwTrbm75KUZ6Mhiz9mbXbjiC0Ek65fb6CwqmWvW%2Bw%3D%3D: HTTPSConnectionPool(host='storage.googleapis.com', port=443): Max retries exceeded with url: /wandb-artifacts-prod/wandb_artifacts/133981200/707680441/6873c23a2381d1524249eb1a948a45a5?Expires=1706688977&GoogleAccessId=gorilla-files-url-signer-man%40wandb-production.iam.gserviceaccount.com&Signature=qIJkPWvML5xinRceuHOzA0bUaw3Do9%2F91nWMxuxxepOVZJnxcZAb%2FvWPuaHz%2BgN%2FpMtlTLUXpb61voC%2Btv0PuVKFX1JYa4wzyYH9JGNauViHKrnTWzhOE2Y%2FUN%2FSjAS8vRKa2evko8P8FXApaLaBiuKPxkEJTiUDsjWR0C4JNp8M6LhslScdVqaq1EzjjBf7lF6GHjKSCdIcLc4MQtW5htoqnJCYQiEeokqd5H6kZH1%2BMgmEI6wMFyH6tMEt1c%2FZx0u2NJsKqXgcZLsf%2FcCERAg8fgoDojG59bTu5L2ioIfAUOwTrbm75KUZ6Mhiz9mbXbjiC0Ek65fb6CwqmWvW%2Bw%3D%3D (Caused by NewConnectionError('<urllib3.connection.HTTPSConnection object at 0x7ff07456c430>: Failed to establish a new connection: [Errno 101] Network is unreachable'))
2024-01-30 16:16:33,743 ERROR   wandb-upload_2:1134333 [internal_api.py:upload_file():2767] upload_file request headers: {'User-Agent': 'python-requests/2.23.0', 'Accept-Encoding': 'gzip, deflate', 'Accept': '*/*', 'Connection': 'keep-alive', 'Content-MD5': 'aHPCOiOB0VJCSesalIpFpQ==', 'Content-Type': 'application/json', 'Content-Length': '609'}
2024-01-30 16:16:33,743 ERROR   wandb-upload_2:1134333 [internal_api.py:upload_file():2769] upload_file response body: 
2024-01-30 16:16:35,240 DEBUG   HandlerThread:1134333 [handler.py:handle_request():146] handle_request: keepalive
2024-01-30 16:16:40,241 DEBUG   HandlerThread:1134333 [handler.py:handle_request():146] handle_request: keepalive
2024-01-30 16:16:45,244 DEBUG   HandlerThread:1134333 [handler.py:handle_request():146] handle_request: keepalive
2024-01-30 16:16:49,848 ERROR   wandb-upload_1:1134333 [internal_api.py:upload_file():2765] upload_file exception https://storage.googleapis.com/wandb-artifacts-prod/wandb_artifacts/133981200/707680441/174a3d9bc61fec126cc7d5bdff5c6c5a?Expires=1706688976&GoogleAccessId=gorilla-files-url-signer-man%40wandb-production.iam.gserviceaccount.com&Signature=uIbfStEO5cczURRkS4SpZN1KkOF1nNcaFcdRGat7PQLC9Tggo%2BUgYtftkZei%2BxbqK8nyTsqGnJst%2BoaNPYUckSZg0CJDQFyNY%2BXc4SK3OdCAZ6QF7abYQ7mXMJgzBCTkt1OfRFdc3r%2BjOu67iXZeYVHKHEH69S6pAkgIMCIdREHjeQ2O7IcYtfszxeByToc8Otd72VkwVhWvP%2BgAs2vXLIy2bWdRBO%2BcbPM5ejas4MQH%2B7Z0E9qA8ag51zhEkIbqJAmeI8n5dxiJy3Bvgfm%2BMpQtb6LxXCCfQkVOISE6CZ6r3xokc3PPr5dhq6xtQCoawqO%2ByDNeu3A4NzF9S3az6w%3D%3D: HTTPSConnectionPool(host='storage.googleapis.com', port=443): Max retries exceeded with url: /wandb-artifacts-prod/wandb_artifacts/133981200/707680441/174a3d9bc61fec126cc7d5bdff5c6c5a?Expires=1706688976&GoogleAccessId=gorilla-files-url-signer-man%40wandb-production.iam.gserviceaccount.com&Signature=uIbfStEO5cczURRkS4SpZN1KkOF1nNcaFcdRGat7PQLC9Tggo%2BUgYtftkZei%2BxbqK8nyTsqGnJst%2BoaNPYUckSZg0CJDQFyNY%2BXc4SK3OdCAZ6QF7abYQ7mXMJgzBCTkt1OfRFdc3r%2BjOu67iXZeYVHKHEH69S6pAkgIMCIdREHjeQ2O7IcYtfszxeByToc8Otd72VkwVhWvP%2BgAs2vXLIy2bWdRBO%2BcbPM5ejas4MQH%2B7Z0E9qA8ag51zhEkIbqJAmeI8n5dxiJy3Bvgfm%2BMpQtb6LxXCCfQkVOISE6CZ6r3xokc3PPr5dhq6xtQCoawqO%2ByDNeu3A4NzF9S3az6w%3D%3D (Caused by NewConnectionError('<urllib3.connection.HTTPSConnection object at 0x7ff0744c8370>: Failed to establish a new connection: [Errno 101] Network is unreachable'))
2024-01-30 16:16:49,848 ERROR   wandb-upload_1:1134333 [internal_api.py:upload_file():2767] upload_file request headers: {'User-Agent': 'python-requests/2.23.0', 'Accept-Encoding': 'gzip, deflate', 'Accept': '*/*', 'Connection': 'keep-alive', 'Content-MD5': 'F0o9m8Yf7BJsx9W9/1xsWg==', 'Content-Type': 'text/plain; charset=utf-8', 'Content-Length': '2179'}
2024-01-30 16:16:49,848 ERROR   wandb-upload_1:1134333 [internal_api.py:upload_file():2769] upload_file response body: 
2024-01-30 16:16:50,246 DEBUG   HandlerThread:1134333 [handler.py:handle_request():146] handle_request: keepalive
2024-01-30 16:16:52,716 ERROR   wandb-upload_2:1134333 [internal_api.py:upload_file():2765] upload_file exception https://storage.googleapis.com/wandb-artifacts-prod/wandb_artifacts/133981200/707680441/6873c23a2381d1524249eb1a948a45a5?Expires=1706688977&GoogleAccessId=gorilla-files-url-signer-man%40wandb-production.iam.gserviceaccount.com&Signature=qIJkPWvML5xinRceuHOzA0bUaw3Do9%2F91nWMxuxxepOVZJnxcZAb%2FvWPuaHz%2BgN%2FpMtlTLUXpb61voC%2Btv0PuVKFX1JYa4wzyYH9JGNauViHKrnTWzhOE2Y%2FUN%2FSjAS8vRKa2evko8P8FXApaLaBiuKPxkEJTiUDsjWR0C4JNp8M6LhslScdVqaq1EzjjBf7lF6GHjKSCdIcLc4MQtW5htoqnJCYQiEeokqd5H6kZH1%2BMgmEI6wMFyH6tMEt1c%2FZx0u2NJsKqXgcZLsf%2FcCERAg8fgoDojG59bTu5L2ioIfAUOwTrbm75KUZ6Mhiz9mbXbjiC0Ek65fb6CwqmWvW%2Bw%3D%3D: HTTPSConnectionPool(host='storage.googleapis.com', port=443): Max retries exceeded with url: /wandb-artifacts-prod/wandb_artifacts/133981200/707680441/6873c23a2381d1524249eb1a948a45a5?Expires=1706688977&GoogleAccessId=gorilla-files-url-signer-man%40wandb-production.iam.gserviceaccount.com&Signature=qIJkPWvML5xinRceuHOzA0bUaw3Do9%2F91nWMxuxxepOVZJnxcZAb%2FvWPuaHz%2BgN%2FpMtlTLUXpb61voC%2Btv0PuVKFX1JYa4wzyYH9JGNauViHKrnTWzhOE2Y%2FUN%2FSjAS8vRKa2evko8P8FXApaLaBiuKPxkEJTiUDsjWR0C4JNp8M6LhslScdVqaq1EzjjBf7lF6GHjKSCdIcLc4MQtW5htoqnJCYQiEeokqd5H6kZH1%2BMgmEI6wMFyH6tMEt1c%2FZx0u2NJsKqXgcZLsf%2FcCERAg8fgoDojG59bTu5L2ioIfAUOwTrbm75KUZ6Mhiz9mbXbjiC0Ek65fb6CwqmWvW%2Bw%3D%3D (Caused by NewConnectionError('<urllib3.connection.HTTPSConnection object at 0x7ff0744c8310>: Failed to establish a new connection: [Errno 101] Network is unreachable'))
2024-01-30 16:16:52,716 ERROR   wandb-upload_2:1134333 [internal_api.py:upload_file():2767] upload_file request headers: {'User-Agent': 'python-requests/2.23.0', 'Accept-Encoding': 'gzip, deflate', 'Accept': '*/*', 'Connection': 'keep-alive', 'Content-MD5': 'aHPCOiOB0VJCSesalIpFpQ==', 'Content-Type': 'application/json', 'Content-Length': '609'}
2024-01-30 16:16:52,716 ERROR   wandb-upload_2:1134333 [internal_api.py:upload_file():2769] upload_file response body: 
2024-01-30 16:16:55,248 DEBUG   HandlerThread:1134333 [handler.py:handle_request():146] handle_request: keepalive
2024-01-30 16:17:00,250 DEBUG   HandlerThread:1134333 [handler.py:handle_request():146] handle_request: keepalive
2024-01-30 16:17:05,253 DEBUG   HandlerThread:1134333 [handler.py:handle_request():146] handle_request: keepalive
2024-01-30 16:17:10,255 DEBUG   HandlerThread:1134333 [handler.py:handle_request():146] handle_request: keepalive
2024-01-30 16:17:15,257 DEBUG   HandlerThread:1134333 [handler.py:handle_request():146] handle_request: keepalive
2024-01-30 16:17:20,259 DEBUG   HandlerThread:1134333 [handler.py:handle_request():146] handle_request: keepalive
2024-01-30 16:17:25,262 DEBUG   HandlerThread:1134333 [handler.py:handle_request():146] handle_request: keepalive
2024-01-30 16:17:28,413 ERROR   wandb-upload_1:1134333 [internal_api.py:upload_file():2765] upload_file exception https://storage.googleapis.com/wandb-artifacts-prod/wandb_artifacts/133981200/707680441/174a3d9bc61fec126cc7d5bdff5c6c5a?Expires=1706688976&GoogleAccessId=gorilla-files-url-signer-man%40wandb-production.iam.gserviceaccount.com&Signature=uIbfStEO5cczURRkS4SpZN1KkOF1nNcaFcdRGat7PQLC9Tggo%2BUgYtftkZei%2BxbqK8nyTsqGnJst%2BoaNPYUckSZg0CJDQFyNY%2BXc4SK3OdCAZ6QF7abYQ7mXMJgzBCTkt1OfRFdc3r%2BjOu67iXZeYVHKHEH69S6pAkgIMCIdREHjeQ2O7IcYtfszxeByToc8Otd72VkwVhWvP%2BgAs2vXLIy2bWdRBO%2BcbPM5ejas4MQH%2B7Z0E9qA8ag51zhEkIbqJAmeI8n5dxiJy3Bvgfm%2BMpQtb6LxXCCfQkVOISE6CZ6r3xokc3PPr5dhq6xtQCoawqO%2ByDNeu3A4NzF9S3az6w%3D%3D: HTTPSConnectionPool(host='storage.googleapis.com', port=443): Max retries exceeded with url: /wandb-artifacts-prod/wandb_artifacts/133981200/707680441/174a3d9bc61fec126cc7d5bdff5c6c5a?Expires=1706688976&GoogleAccessId=gorilla-files-url-signer-man%40wandb-production.iam.gserviceaccount.com&Signature=uIbfStEO5cczURRkS4SpZN1KkOF1nNcaFcdRGat7PQLC9Tggo%2BUgYtftkZei%2BxbqK8nyTsqGnJst%2BoaNPYUckSZg0CJDQFyNY%2BXc4SK3OdCAZ6QF7abYQ7mXMJgzBCTkt1OfRFdc3r%2BjOu67iXZeYVHKHEH69S6pAkgIMCIdREHjeQ2O7IcYtfszxeByToc8Otd72VkwVhWvP%2BgAs2vXLIy2bWdRBO%2BcbPM5ejas4MQH%2B7Z0E9qA8ag51zhEkIbqJAmeI8n5dxiJy3Bvgfm%2BMpQtb6LxXCCfQkVOISE6CZ6r3xokc3PPr5dhq6xtQCoawqO%2ByDNeu3A4NzF9S3az6w%3D%3D (Caused by NewConnectionError('<urllib3.connection.HTTPSConnection object at 0x7ff07456c7f0>: Failed to establish a new connection: [Errno 101] Network is unreachable'))
2024-01-30 16:17:28,413 ERROR   wandb-upload_1:1134333 [internal_api.py:upload_file():2767] upload_file request headers: {'User-Agent': 'python-requests/2.23.0', 'Accept-Encoding': 'gzip, deflate', 'Accept': '*/*', 'Connection': 'keep-alive', 'Content-MD5': 'F0o9m8Yf7BJsx9W9/1xsWg==', 'Content-Type': 'text/plain; charset=utf-8', 'Content-Length': '2179'}
2024-01-30 16:17:28,413 ERROR   wandb-upload_1:1134333 [internal_api.py:upload_file():2769] upload_file response body: 
2024-01-30 16:17:30,263 DEBUG   HandlerThread:1134333 [handler.py:handle_request():146] handle_request: keepalive
2024-01-30 16:17:31,220 ERROR   wandb-upload_2:1134333 [internal_api.py:upload_file():2765] upload_file exception https://storage.googleapis.com/wandb-artifacts-prod/wandb_artifacts/133981200/707680441/6873c23a2381d1524249eb1a948a45a5?Expires=1706688977&GoogleAccessId=gorilla-files-url-signer-man%40wandb-production.iam.gserviceaccount.com&Signature=qIJkPWvML5xinRceuHOzA0bUaw3Do9%2F91nWMxuxxepOVZJnxcZAb%2FvWPuaHz%2BgN%2FpMtlTLUXpb61voC%2Btv0PuVKFX1JYa4wzyYH9JGNauViHKrnTWzhOE2Y%2FUN%2FSjAS8vRKa2evko8P8FXApaLaBiuKPxkEJTiUDsjWR0C4JNp8M6LhslScdVqaq1EzjjBf7lF6GHjKSCdIcLc4MQtW5htoqnJCYQiEeokqd5H6kZH1%2BMgmEI6wMFyH6tMEt1c%2FZx0u2NJsKqXgcZLsf%2FcCERAg8fgoDojG59bTu5L2ioIfAUOwTrbm75KUZ6Mhiz9mbXbjiC0Ek65fb6CwqmWvW%2Bw%3D%3D: HTTPSConnectionPool(host='storage.googleapis.com', port=443): Max retries exceeded with url: /wandb-artifacts-prod/wandb_artifacts/133981200/707680441/6873c23a2381d1524249eb1a948a45a5?Expires=1706688977&GoogleAccessId=gorilla-files-url-signer-man%40wandb-production.iam.gserviceaccount.com&Signature=qIJkPWvML5xinRceuHOzA0bUaw3Do9%2F91nWMxuxxepOVZJnxcZAb%2FvWPuaHz%2BgN%2FpMtlTLUXpb61voC%2Btv0PuVKFX1JYa4wzyYH9JGNauViHKrnTWzhOE2Y%2FUN%2FSjAS8vRKa2evko8P8FXApaLaBiuKPxkEJTiUDsjWR0C4JNp8M6LhslScdVqaq1EzjjBf7lF6GHjKSCdIcLc4MQtW5htoqnJCYQiEeokqd5H6kZH1%2BMgmEI6wMFyH6tMEt1c%2FZx0u2NJsKqXgcZLsf%2FcCERAg8fgoDojG59bTu5L2ioIfAUOwTrbm75KUZ6Mhiz9mbXbjiC0Ek65fb6CwqmWvW%2Bw%3D%3D (Caused by NewConnectionError('<urllib3.connection.HTTPSConnection object at 0x7ff07456cd90>: Failed to establish a new connection: [Errno 101] Network is unreachable'))
2024-01-30 16:17:31,220 ERROR   wandb-upload_2:1134333 [internal_api.py:upload_file():2767] upload_file request headers: {'User-Agent': 'python-requests/2.23.0', 'Accept-Encoding': 'gzip, deflate', 'Accept': '*/*', 'Connection': 'keep-alive', 'Content-MD5': 'aHPCOiOB0VJCSesalIpFpQ==', 'Content-Type': 'application/json', 'Content-Length': '609'}
2024-01-30 16:17:31,220 ERROR   wandb-upload_2:1134333 [internal_api.py:upload_file():2769] upload_file response body: 
2024-01-30 16:17:35,266 DEBUG   HandlerThread:1134333 [handler.py:handle_request():146] handle_request: keepalive
2024-01-30 16:17:40,268 DEBUG   HandlerThread:1134333 [handler.py:handle_request():146] handle_request: keepalive
2024-01-30 16:17:45,270 DEBUG   HandlerThread:1134333 [handler.py:handle_request():146] handle_request: keepalive
2024-01-30 16:17:50,272 DEBUG   HandlerThread:1134333 [handler.py:handle_request():146] handle_request: keepalive
2024-01-30 16:17:55,275 DEBUG   HandlerThread:1134333 [handler.py:handle_request():146] handle_request: keepalive
2024-01-30 16:20:21,779 ERROR   wandb-upload_0:1134333 [internal_api.py:upload_file():2765] upload_file exception https://storage.googleapis.com/wandb-production.appspot.com/dynamic_x/bert_pytorch/k02uw2vk/wandb-metadata.json?Expires=1706688636&GoogleAccessId=gorilla-files-url-signer-man%40wandb-production.iam.gserviceaccount.com&Signature=O5gfF6B4ppD%2Bi%2BHqYp9rSofCCWc6atzI%2FJ4kGH8QCvKU9TkLSWBd4L%2F0Y8wy4VYiO5uN8bfoYhQ7nit1eT%2FGIpv06LqT3QKE9ClIuiKmeXxqMcA%2BVYrF5dRiXdyC%2Ba6nTwG5qncoYioJQ%2BdHwrNWRGwrgboVjc2r3ZqfVaZTtzHCjJq3tENgZPG5JBeN2mA1r1OaXz7PJ9NZOONnTc5%2BkP%2Feos3GUefnLmb%2BOM2gHS4HWB%2FTQUzghpD6VD%2FR5587T4eupp1Cm1BaxsoMs2u7AaSK5VMhsX87cKcyp8N%2BZLNgpeN%2BzmofSok1yArLSWqjOJvzAkDzvX9Lm4cRbJzDEw%3D%3D: HTTPSConnectionPool(host='storage.googleapis.com', port=443): Max retries exceeded with url: /wandb-production.appspot.com/dynamic_x/bert_pytorch/k02uw2vk/wandb-metadata.json?Expires=1706688636&GoogleAccessId=gorilla-files-url-signer-man%40wandb-production.iam.gserviceaccount.com&Signature=O5gfF6B4ppD%2Bi%2BHqYp9rSofCCWc6atzI%2FJ4kGH8QCvKU9TkLSWBd4L%2F0Y8wy4VYiO5uN8bfoYhQ7nit1eT%2FGIpv06LqT3QKE9ClIuiKmeXxqMcA%2BVYrF5dRiXdyC%2Ba6nTwG5qncoYioJQ%2BdHwrNWRGwrgboVjc2r3ZqfVaZTtzHCjJq3tENgZPG5JBeN2mA1r1OaXz7PJ9NZOONnTc5%2BkP%2Feos3GUefnLmb%2BOM2gHS4HWB%2FTQUzghpD6VD%2FR5587T4eupp1Cm1BaxsoMs2u7AaSK5VMhsX87cKcyp8N%2BZLNgpeN%2BzmofSok1yArLSWqjOJvzAkDzvX9Lm4cRbJzDEw%3D%3D (Caused by NewConnectionError('<urllib3.connection.HTTPSConnection object at 0x7ff07456cbe0>: Failed to establish a new connection: [Errno 111] Connection refused'))
2024-01-30 16:20:21,779 ERROR   wandb-upload_0:1134333 [internal_api.py:upload_file():2767] upload_file request headers: {'User-Agent': 'python-requests/2.23.0', 'Accept-Encoding': 'gzip, deflate', 'Accept': '*/*', 'Connection': 'keep-alive', 'Content-Length': '15547'}
2024-01-30 16:20:21,779 ERROR   wandb-upload_0:1134333 [internal_api.py:upload_file():2769] upload_file response body: 
2024-01-30 16:25:29,775 ERROR   wandb-upload_0:1134333 [internal_api.py:upload_file():2765] upload_file exception https://storage.googleapis.com/wandb-production.appspot.com/dynamic_x/bert_pytorch/k02uw2vk/wandb-metadata.json?Expires=1706688636&GoogleAccessId=gorilla-files-url-signer-man%40wandb-production.iam.gserviceaccount.com&Signature=O5gfF6B4ppD%2Bi%2BHqYp9rSofCCWc6atzI%2FJ4kGH8QCvKU9TkLSWBd4L%2F0Y8wy4VYiO5uN8bfoYhQ7nit1eT%2FGIpv06LqT3QKE9ClIuiKmeXxqMcA%2BVYrF5dRiXdyC%2Ba6nTwG5qncoYioJQ%2BdHwrNWRGwrgboVjc2r3ZqfVaZTtzHCjJq3tENgZPG5JBeN2mA1r1OaXz7PJ9NZOONnTc5%2BkP%2Feos3GUefnLmb%2BOM2gHS4HWB%2FTQUzghpD6VD%2FR5587T4eupp1Cm1BaxsoMs2u7AaSK5VMhsX87cKcyp8N%2BZLNgpeN%2BzmofSok1yArLSWqjOJvzAkDzvX9Lm4cRbJzDEw%3D%3D: HTTPSConnectionPool(host='storage.googleapis.com', port=443): Max retries exceeded with url: /wandb-production.appspot.com/dynamic_x/bert_pytorch/k02uw2vk/wandb-metadata.json?Expires=1706688636&GoogleAccessId=gorilla-files-url-signer-man%40wandb-production.iam.gserviceaccount.com&Signature=O5gfF6B4ppD%2Bi%2BHqYp9rSofCCWc6atzI%2FJ4kGH8QCvKU9TkLSWBd4L%2F0Y8wy4VYiO5uN8bfoYhQ7nit1eT%2FGIpv06LqT3QKE9ClIuiKmeXxqMcA%2BVYrF5dRiXdyC%2Ba6nTwG5qncoYioJQ%2BdHwrNWRGwrgboVjc2r3ZqfVaZTtzHCjJq3tENgZPG5JBeN2mA1r1OaXz7PJ9NZOONnTc5%2BkP%2Feos3GUefnLmb%2BOM2gHS4HWB%2FTQUzghpD6VD%2FR5587T4eupp1Cm1BaxsoMs2u7AaSK5VMhsX87cKcyp8N%2BZLNgpeN%2BzmofSok1yArLSWqjOJvzAkDzvX9Lm4cRbJzDEw%3D%3D (Caused by NewConnectionError('<urllib3.connection.HTTPSConnection object at 0x7ff0744d0610>: Failed to establish a new connection: [Errno 111] Connection refused'))
2024-01-30 16:25:29,775 ERROR   wandb-upload_0:1134333 [internal_api.py:upload_file():2767] upload_file request headers: {'User-Agent': 'python-requests/2.23.0', 'Accept-Encoding': 'gzip, deflate', 'Accept': '*/*', 'Connection': 'keep-alive', 'Content-Length': '15547'}
2024-01-30 16:25:29,775 ERROR   wandb-upload_0:1134333 [internal_api.py:upload_file():2769] upload_file response body: 
2024-01-30 16:31:32,938 ERROR   wandb-upload_0:1134333 [internal_api.py:upload_file():2765] upload_file exception https://storage.googleapis.com/wandb-production.appspot.com/dynamic_x/bert_pytorch/k02uw2vk/wandb-metadata.json?Expires=1706688636&GoogleAccessId=gorilla-files-url-signer-man%40wandb-production.iam.gserviceaccount.com&Signature=O5gfF6B4ppD%2Bi%2BHqYp9rSofCCWc6atzI%2FJ4kGH8QCvKU9TkLSWBd4L%2F0Y8wy4VYiO5uN8bfoYhQ7nit1eT%2FGIpv06LqT3QKE9ClIuiKmeXxqMcA%2BVYrF5dRiXdyC%2Ba6nTwG5qncoYioJQ%2BdHwrNWRGwrgboVjc2r3ZqfVaZTtzHCjJq3tENgZPG5JBeN2mA1r1OaXz7PJ9NZOONnTc5%2BkP%2Feos3GUefnLmb%2BOM2gHS4HWB%2FTQUzghpD6VD%2FR5587T4eupp1Cm1BaxsoMs2u7AaSK5VMhsX87cKcyp8N%2BZLNgpeN%2BzmofSok1yArLSWqjOJvzAkDzvX9Lm4cRbJzDEw%3D%3D: HTTPSConnectionPool(host='storage.googleapis.com', port=443): Max retries exceeded with url: /wandb-production.appspot.com/dynamic_x/bert_pytorch/k02uw2vk/wandb-metadata.json?Expires=1706688636&GoogleAccessId=gorilla-files-url-signer-man%40wandb-production.iam.gserviceaccount.com&Signature=O5gfF6B4ppD%2Bi%2BHqYp9rSofCCWc6atzI%2FJ4kGH8QCvKU9TkLSWBd4L%2F0Y8wy4VYiO5uN8bfoYhQ7nit1eT%2FGIpv06LqT3QKE9ClIuiKmeXxqMcA%2BVYrF5dRiXdyC%2Ba6nTwG5qncoYioJQ%2BdHwrNWRGwrgboVjc2r3ZqfVaZTtzHCjJq3tENgZPG5JBeN2mA1r1OaXz7PJ9NZOONnTc5%2BkP%2Feos3GUefnLmb%2BOM2gHS4HWB%2FTQUzghpD6VD%2FR5587T4eupp1Cm1BaxsoMs2u7AaSK5VMhsX87cKcyp8N%2BZLNgpeN%2BzmofSok1yArLSWqjOJvzAkDzvX9Lm4cRbJzDEw%3D%3D (Caused by NewConnectionError('<urllib3.connection.HTTPSConnection object at 0x7ff0744c5610>: Failed to establish a new connection: [Errno 111] Connection refused'))
2024-01-30 16:31:32,939 ERROR   wandb-upload_0:1134333 [internal_api.py:upload_file():2767] upload_file request headers: {'User-Agent': 'python-requests/2.23.0', 'Accept-Encoding': 'gzip, deflate', 'Accept': '*/*', 'Connection': 'keep-alive', 'Content-Length': '15547'}
2024-01-30 16:31:32,939 ERROR   wandb-upload_0:1134333 [internal_api.py:upload_file():2769] upload_file response body: 
2024-01-30 16:37:19,117 ERROR   wandb-upload_0:1134333 [internal_api.py:upload_file():2765] upload_file exception https://storage.googleapis.com/wandb-production.appspot.com/dynamic_x/bert_pytorch/k02uw2vk/wandb-metadata.json?Expires=1706688636&GoogleAccessId=gorilla-files-url-signer-man%40wandb-production.iam.gserviceaccount.com&Signature=O5gfF6B4ppD%2Bi%2BHqYp9rSofCCWc6atzI%2FJ4kGH8QCvKU9TkLSWBd4L%2F0Y8wy4VYiO5uN8bfoYhQ7nit1eT%2FGIpv06LqT3QKE9ClIuiKmeXxqMcA%2BVYrF5dRiXdyC%2Ba6nTwG5qncoYioJQ%2BdHwrNWRGwrgboVjc2r3ZqfVaZTtzHCjJq3tENgZPG5JBeN2mA1r1OaXz7PJ9NZOONnTc5%2BkP%2Feos3GUefnLmb%2BOM2gHS4HWB%2FTQUzghpD6VD%2FR5587T4eupp1Cm1BaxsoMs2u7AaSK5VMhsX87cKcyp8N%2BZLNgpeN%2BzmofSok1yArLSWqjOJvzAkDzvX9Lm4cRbJzDEw%3D%3D: HTTPSConnectionPool(host='storage.googleapis.com', port=443): Max retries exceeded with url: /wandb-production.appspot.com/dynamic_x/bert_pytorch/k02uw2vk/wandb-metadata.json?Expires=1706688636&GoogleAccessId=gorilla-files-url-signer-man%40wandb-production.iam.gserviceaccount.com&Signature=O5gfF6B4ppD%2Bi%2BHqYp9rSofCCWc6atzI%2FJ4kGH8QCvKU9TkLSWBd4L%2F0Y8wy4VYiO5uN8bfoYhQ7nit1eT%2FGIpv06LqT3QKE9ClIuiKmeXxqMcA%2BVYrF5dRiXdyC%2Ba6nTwG5qncoYioJQ%2BdHwrNWRGwrgboVjc2r3ZqfVaZTtzHCjJq3tENgZPG5JBeN2mA1r1OaXz7PJ9NZOONnTc5%2BkP%2Feos3GUefnLmb%2BOM2gHS4HWB%2FTQUzghpD6VD%2FR5587T4eupp1Cm1BaxsoMs2u7AaSK5VMhsX87cKcyp8N%2BZLNgpeN%2BzmofSok1yArLSWqjOJvzAkDzvX9Lm4cRbJzDEw%3D%3D (Caused by NewConnectionError('<urllib3.connection.HTTPSConnection object at 0x7ff0744c5490>: Failed to establish a new connection: [Errno 111] Connection refused'))
2024-01-30 16:37:19,117 ERROR   wandb-upload_0:1134333 [internal_api.py:upload_file():2767] upload_file request headers: {'User-Agent': 'python-requests/2.23.0', 'Accept-Encoding': 'gzip, deflate', 'Accept': '*/*', 'Connection': 'keep-alive', 'Content-Length': '15547'}
2024-01-30 16:37:19,117 ERROR   wandb-upload_0:1134333 [internal_api.py:upload_file():2769] upload_file response body: 
2024-01-30 16:37:46,448 WARNING StreamThr :1134333 [internal.py:is_dead():414] Internal process exiting, parent pid 1134040 disappeared
2024-01-30 16:37:46,448 ERROR   StreamThr :1134333 [internal.py:wandb_internal():152] Internal process shutdown.
2024-01-30 16:37:47,349 INFO    WriterThread:1134333 [datastore.py:close():296] close: /home/yanxindong/mkor/bert/wandb/run-20240130_161012-k02uw2vk/run-k02uw2vk.wandb
2024-01-30 16:37:47,376 INFO    HandlerThread:1134333 [handler.py:finish():869] shutting down handler
2024-01-30 16:40:35,574 ERROR   wandb-upload_1:1134333 [internal_api.py:upload_file():2765] upload_file exception https://storage.googleapis.com/wandb-artifacts-prod/wandb_artifacts/133981200/707680441/174a3d9bc61fec126cc7d5bdff5c6c5a?Expires=1706688976&GoogleAccessId=gorilla-files-url-signer-man%40wandb-production.iam.gserviceaccount.com&Signature=uIbfStEO5cczURRkS4SpZN1KkOF1nNcaFcdRGat7PQLC9Tggo%2BUgYtftkZei%2BxbqK8nyTsqGnJst%2BoaNPYUckSZg0CJDQFyNY%2BXc4SK3OdCAZ6QF7abYQ7mXMJgzBCTkt1OfRFdc3r%2BjOu67iXZeYVHKHEH69S6pAkgIMCIdREHjeQ2O7IcYtfszxeByToc8Otd72VkwVhWvP%2BgAs2vXLIy2bWdRBO%2BcbPM5ejas4MQH%2B7Z0E9qA8ag51zhEkIbqJAmeI8n5dxiJy3Bvgfm%2BMpQtb6LxXCCfQkVOISE6CZ6r3xokc3PPr5dhq6xtQCoawqO%2ByDNeu3A4NzF9S3az6w%3D%3D: HTTPSConnectionPool(host='storage.googleapis.com', port=443): Max retries exceeded with url: /wandb-artifacts-prod/wandb_artifacts/133981200/707680441/174a3d9bc61fec126cc7d5bdff5c6c5a?Expires=1706688976&GoogleAccessId=gorilla-files-url-signer-man%40wandb-production.iam.gserviceaccount.com&Signature=uIbfStEO5cczURRkS4SpZN1KkOF1nNcaFcdRGat7PQLC9Tggo%2BUgYtftkZei%2BxbqK8nyTsqGnJst%2BoaNPYUckSZg0CJDQFyNY%2BXc4SK3OdCAZ6QF7abYQ7mXMJgzBCTkt1OfRFdc3r%2BjOu67iXZeYVHKHEH69S6pAkgIMCIdREHjeQ2O7IcYtfszxeByToc8Otd72VkwVhWvP%2BgAs2vXLIy2bWdRBO%2BcbPM5ejas4MQH%2B7Z0E9qA8ag51zhEkIbqJAmeI8n5dxiJy3Bvgfm%2BMpQtb6LxXCCfQkVOISE6CZ6r3xokc3PPr5dhq6xtQCoawqO%2ByDNeu3A4NzF9S3az6w%3D%3D (Caused by NewConnectionError('<urllib3.connection.HTTPSConnection object at 0x7ff0744c7220>: Failed to establish a new connection: [Errno 101] Network is unreachable'))
2024-01-30 16:40:35,574 ERROR   wandb-upload_1:1134333 [internal_api.py:upload_file():2767] upload_file request headers: {'User-Agent': 'python-requests/2.23.0', 'Accept-Encoding': 'gzip, deflate', 'Accept': '*/*', 'Connection': 'keep-alive', 'Content-MD5': 'F0o9m8Yf7BJsx9W9/1xsWg==', 'Content-Type': 'text/plain; charset=utf-8', 'Content-Length': '2179'}
2024-01-30 16:40:35,574 ERROR   wandb-upload_1:1134333 [internal_api.py:upload_file():2769] upload_file response body: 
2024-01-30 16:40:39,671 ERROR   wandb-upload_2:1134333 [internal_api.py:upload_file():2765] upload_file exception https://storage.googleapis.com/wandb-artifacts-prod/wandb_artifacts/133981200/707680441/6873c23a2381d1524249eb1a948a45a5?Expires=1706688977&GoogleAccessId=gorilla-files-url-signer-man%40wandb-production.iam.gserviceaccount.com&Signature=qIJkPWvML5xinRceuHOzA0bUaw3Do9%2F91nWMxuxxepOVZJnxcZAb%2FvWPuaHz%2BgN%2FpMtlTLUXpb61voC%2Btv0PuVKFX1JYa4wzyYH9JGNauViHKrnTWzhOE2Y%2FUN%2FSjAS8vRKa2evko8P8FXApaLaBiuKPxkEJTiUDsjWR0C4JNp8M6LhslScdVqaq1EzjjBf7lF6GHjKSCdIcLc4MQtW5htoqnJCYQiEeokqd5H6kZH1%2BMgmEI6wMFyH6tMEt1c%2FZx0u2NJsKqXgcZLsf%2FcCERAg8fgoDojG59bTu5L2ioIfAUOwTrbm75KUZ6Mhiz9mbXbjiC0Ek65fb6CwqmWvW%2Bw%3D%3D: HTTPSConnectionPool(host='storage.googleapis.com', port=443): Max retries exceeded with url: /wandb-artifacts-prod/wandb_artifacts/133981200/707680441/6873c23a2381d1524249eb1a948a45a5?Expires=1706688977&GoogleAccessId=gorilla-files-url-signer-man%40wandb-production.iam.gserviceaccount.com&Signature=qIJkPWvML5xinRceuHOzA0bUaw3Do9%2F91nWMxuxxepOVZJnxcZAb%2FvWPuaHz%2BgN%2FpMtlTLUXpb61voC%2Btv0PuVKFX1JYa4wzyYH9JGNauViHKrnTWzhOE2Y%2FUN%2FSjAS8vRKa2evko8P8FXApaLaBiuKPxkEJTiUDsjWR0C4JNp8M6LhslScdVqaq1EzjjBf7lF6GHjKSCdIcLc4MQtW5htoqnJCYQiEeokqd5H6kZH1%2BMgmEI6wMFyH6tMEt1c%2FZx0u2NJsKqXgcZLsf%2FcCERAg8fgoDojG59bTu5L2ioIfAUOwTrbm75KUZ6Mhiz9mbXbjiC0Ek65fb6CwqmWvW%2Bw%3D%3D (Caused by NewConnectionError('<urllib3.connection.HTTPSConnection object at 0x7ff0744c7bb0>: Failed to establish a new connection: [Errno 101] Network is unreachable'))
2024-01-30 16:40:39,672 ERROR   wandb-upload_2:1134333 [internal_api.py:upload_file():2767] upload_file request headers: {'User-Agent': 'python-requests/2.23.0', 'Accept-Encoding': 'gzip, deflate', 'Accept': '*/*', 'Connection': 'keep-alive', 'Content-MD5': 'aHPCOiOB0VJCSesalIpFpQ==', 'Content-Type': 'application/json', 'Content-Length': '609'}
2024-01-30 16:40:39,672 ERROR   wandb-upload_2:1134333 [internal_api.py:upload_file():2769] upload_file response body: 
2024-01-30 16:42:55,367 ERROR   wandb-upload_1:1134333 [internal_api.py:upload_file():2765] upload_file exception https://storage.googleapis.com/wandb-artifacts-prod/wandb_artifacts/133981200/707680441/174a3d9bc61fec126cc7d5bdff5c6c5a?Expires=1706688976&GoogleAccessId=gorilla-files-url-signer-man%40wandb-production.iam.gserviceaccount.com&Signature=uIbfStEO5cczURRkS4SpZN1KkOF1nNcaFcdRGat7PQLC9Tggo%2BUgYtftkZei%2BxbqK8nyTsqGnJst%2BoaNPYUckSZg0CJDQFyNY%2BXc4SK3OdCAZ6QF7abYQ7mXMJgzBCTkt1OfRFdc3r%2BjOu67iXZeYVHKHEH69S6pAkgIMCIdREHjeQ2O7IcYtfszxeByToc8Otd72VkwVhWvP%2BgAs2vXLIy2bWdRBO%2BcbPM5ejas4MQH%2B7Z0E9qA8ag51zhEkIbqJAmeI8n5dxiJy3Bvgfm%2BMpQtb6LxXCCfQkVOISE6CZ6r3xokc3PPr5dhq6xtQCoawqO%2ByDNeu3A4NzF9S3az6w%3D%3D: HTTPSConnectionPool(host='storage.googleapis.com', port=443): Max retries exceeded with url: /wandb-artifacts-prod/wandb_artifacts/133981200/707680441/174a3d9bc61fec126cc7d5bdff5c6c5a?Expires=1706688976&GoogleAccessId=gorilla-files-url-signer-man%40wandb-production.iam.gserviceaccount.com&Signature=uIbfStEO5cczURRkS4SpZN1KkOF1nNcaFcdRGat7PQLC9Tggo%2BUgYtftkZei%2BxbqK8nyTsqGnJst%2BoaNPYUckSZg0CJDQFyNY%2BXc4SK3OdCAZ6QF7abYQ7mXMJgzBCTkt1OfRFdc3r%2BjOu67iXZeYVHKHEH69S6pAkgIMCIdREHjeQ2O7IcYtfszxeByToc8Otd72VkwVhWvP%2BgAs2vXLIy2bWdRBO%2BcbPM5ejas4MQH%2B7Z0E9qA8ag51zhEkIbqJAmeI8n5dxiJy3Bvgfm%2BMpQtb6LxXCCfQkVOISE6CZ6r3xokc3PPr5dhq6xtQCoawqO%2ByDNeu3A4NzF9S3az6w%3D%3D (Caused by NewConnectionError('<urllib3.connection.HTTPSConnection object at 0x7ff0744c83d0>: Failed to establish a new connection: [Errno 101] Network is unreachable'))
2024-01-30 16:42:55,367 ERROR   wandb-upload_1:1134333 [internal_api.py:upload_file():2767] upload_file request headers: {'User-Agent': 'python-requests/2.23.0', 'Accept-Encoding': 'gzip, deflate', 'Accept': '*/*', 'Connection': 'keep-alive', 'Content-MD5': 'F0o9m8Yf7BJsx9W9/1xsWg==', 'Content-Type': 'text/plain; charset=utf-8', 'Content-Length': '2179'}
2024-01-30 16:42:55,367 ERROR   wandb-upload_1:1134333 [internal_api.py:upload_file():2769] upload_file response body: 
2024-01-30 16:43:11,135 ERROR   wandb-upload_0:1134333 [internal_api.py:upload_file():2765] upload_file exception https://storage.googleapis.com/wandb-production.appspot.com/dynamic_x/bert_pytorch/k02uw2vk/wandb-metadata.json?Expires=1706688636&GoogleAccessId=gorilla-files-url-signer-man%40wandb-production.iam.gserviceaccount.com&Signature=O5gfF6B4ppD%2Bi%2BHqYp9rSofCCWc6atzI%2FJ4kGH8QCvKU9TkLSWBd4L%2F0Y8wy4VYiO5uN8bfoYhQ7nit1eT%2FGIpv06LqT3QKE9ClIuiKmeXxqMcA%2BVYrF5dRiXdyC%2Ba6nTwG5qncoYioJQ%2BdHwrNWRGwrgboVjc2r3ZqfVaZTtzHCjJq3tENgZPG5JBeN2mA1r1OaXz7PJ9NZOONnTc5%2BkP%2Feos3GUefnLmb%2BOM2gHS4HWB%2FTQUzghpD6VD%2FR5587T4eupp1Cm1BaxsoMs2u7AaSK5VMhsX87cKcyp8N%2BZLNgpeN%2BzmofSok1yArLSWqjOJvzAkDzvX9Lm4cRbJzDEw%3D%3D: HTTPSConnectionPool(host='storage.googleapis.com', port=443): Max retries exceeded with url: /wandb-production.appspot.com/dynamic_x/bert_pytorch/k02uw2vk/wandb-metadata.json?Expires=1706688636&GoogleAccessId=gorilla-files-url-signer-man%40wandb-production.iam.gserviceaccount.com&Signature=O5gfF6B4ppD%2Bi%2BHqYp9rSofCCWc6atzI%2FJ4kGH8QCvKU9TkLSWBd4L%2F0Y8wy4VYiO5uN8bfoYhQ7nit1eT%2FGIpv06LqT3QKE9ClIuiKmeXxqMcA%2BVYrF5dRiXdyC%2Ba6nTwG5qncoYioJQ%2BdHwrNWRGwrgboVjc2r3ZqfVaZTtzHCjJq3tENgZPG5JBeN2mA1r1OaXz7PJ9NZOONnTc5%2BkP%2Feos3GUefnLmb%2BOM2gHS4HWB%2FTQUzghpD6VD%2FR5587T4eupp1Cm1BaxsoMs2u7AaSK5VMhsX87cKcyp8N%2BZLNgpeN%2BzmofSok1yArLSWqjOJvzAkDzvX9Lm4cRbJzDEw%3D%3D (Caused by NewConnectionError('<urllib3.connection.HTTPSConnection object at 0x7ff074e1c310>: Failed to establish a new connection: [Errno 101] Network is unreachable'))
2024-01-30 16:43:11,136 ERROR   wandb-upload_0:1134333 [internal_api.py:upload_file():2767] upload_file request headers: {'User-Agent': 'python-requests/2.23.0', 'Accept-Encoding': 'gzip, deflate', 'Accept': '*/*', 'Connection': 'keep-alive', 'Content-Length': '15547'}
2024-01-30 16:43:11,136 ERROR   wandb-upload_0:1134333 [internal_api.py:upload_file():2769] upload_file response body: 
2024-01-30 16:43:16,492 ERROR   wandb-upload_2:1134333 [internal_api.py:upload_file():2765] upload_file exception https://storage.googleapis.com/wandb-artifacts-prod/wandb_artifacts/133981200/707680441/6873c23a2381d1524249eb1a948a45a5?Expires=1706688977&GoogleAccessId=gorilla-files-url-signer-man%40wandb-production.iam.gserviceaccount.com&Signature=qIJkPWvML5xinRceuHOzA0bUaw3Do9%2F91nWMxuxxepOVZJnxcZAb%2FvWPuaHz%2BgN%2FpMtlTLUXpb61voC%2Btv0PuVKFX1JYa4wzyYH9JGNauViHKrnTWzhOE2Y%2FUN%2FSjAS8vRKa2evko8P8FXApaLaBiuKPxkEJTiUDsjWR0C4JNp8M6LhslScdVqaq1EzjjBf7lF6GHjKSCdIcLc4MQtW5htoqnJCYQiEeokqd5H6kZH1%2BMgmEI6wMFyH6tMEt1c%2FZx0u2NJsKqXgcZLsf%2FcCERAg8fgoDojG59bTu5L2ioIfAUOwTrbm75KUZ6Mhiz9mbXbjiC0Ek65fb6CwqmWvW%2Bw%3D%3D: HTTPSConnectionPool(host='storage.googleapis.com', port=443): Max retries exceeded with url: /wandb-artifacts-prod/wandb_artifacts/133981200/707680441/6873c23a2381d1524249eb1a948a45a5?Expires=1706688977&GoogleAccessId=gorilla-files-url-signer-man%40wandb-production.iam.gserviceaccount.com&Signature=qIJkPWvML5xinRceuHOzA0bUaw3Do9%2F91nWMxuxxepOVZJnxcZAb%2FvWPuaHz%2BgN%2FpMtlTLUXpb61voC%2Btv0PuVKFX1JYa4wzyYH9JGNauViHKrnTWzhOE2Y%2FUN%2FSjAS8vRKa2evko8P8FXApaLaBiuKPxkEJTiUDsjWR0C4JNp8M6LhslScdVqaq1EzjjBf7lF6GHjKSCdIcLc4MQtW5htoqnJCYQiEeokqd5H6kZH1%2BMgmEI6wMFyH6tMEt1c%2FZx0u2NJsKqXgcZLsf%2FcCERAg8fgoDojG59bTu5L2ioIfAUOwTrbm75KUZ6Mhiz9mbXbjiC0Ek65fb6CwqmWvW%2Bw%3D%3D (Caused by NewConnectionError('<urllib3.connection.HTTPSConnection object at 0x7ff074e36c40>: Failed to establish a new connection: [Errno 101] Network is unreachable'))
2024-01-30 16:43:16,492 ERROR   wandb-upload_2:1134333 [internal_api.py:upload_file():2767] upload_file request headers: {'User-Agent': 'python-requests/2.23.0', 'Accept-Encoding': 'gzip, deflate', 'Accept': '*/*', 'Connection': 'keep-alive', 'Content-MD5': 'aHPCOiOB0VJCSesalIpFpQ==', 'Content-Type': 'application/json', 'Content-Length': '609'}
2024-01-30 16:43:16,492 ERROR   wandb-upload_2:1134333 [internal_api.py:upload_file():2769] upload_file response body: 
2024-01-30 17:12:12,022 ERROR   wandb-upload_1:1134333 [internal_api.py:upload_file():2765] upload_file exception https://storage.googleapis.com/wandb-artifacts-prod/wandb_artifacts/133981200/707680441/174a3d9bc61fec126cc7d5bdff5c6c5a?Expires=1706688976&GoogleAccessId=gorilla-files-url-signer-man%40wandb-production.iam.gserviceaccount.com&Signature=uIbfStEO5cczURRkS4SpZN1KkOF1nNcaFcdRGat7PQLC9Tggo%2BUgYtftkZei%2BxbqK8nyTsqGnJst%2BoaNPYUckSZg0CJDQFyNY%2BXc4SK3OdCAZ6QF7abYQ7mXMJgzBCTkt1OfRFdc3r%2BjOu67iXZeYVHKHEH69S6pAkgIMCIdREHjeQ2O7IcYtfszxeByToc8Otd72VkwVhWvP%2BgAs2vXLIy2bWdRBO%2BcbPM5ejas4MQH%2B7Z0E9qA8ag51zhEkIbqJAmeI8n5dxiJy3Bvgfm%2BMpQtb6LxXCCfQkVOISE6CZ6r3xokc3PPr5dhq6xtQCoawqO%2ByDNeu3A4NzF9S3az6w%3D%3D: HTTPSConnectionPool(host='storage.googleapis.com', port=443): Max retries exceeded with url: /wandb-artifacts-prod/wandb_artifacts/133981200/707680441/174a3d9bc61fec126cc7d5bdff5c6c5a?Expires=1706688976&GoogleAccessId=gorilla-files-url-signer-man%40wandb-production.iam.gserviceaccount.com&Signature=uIbfStEO5cczURRkS4SpZN1KkOF1nNcaFcdRGat7PQLC9Tggo%2BUgYtftkZei%2BxbqK8nyTsqGnJst%2BoaNPYUckSZg0CJDQFyNY%2BXc4SK3OdCAZ6QF7abYQ7mXMJgzBCTkt1OfRFdc3r%2BjOu67iXZeYVHKHEH69S6pAkgIMCIdREHjeQ2O7IcYtfszxeByToc8Otd72VkwVhWvP%2BgAs2vXLIy2bWdRBO%2BcbPM5ejas4MQH%2B7Z0E9qA8ag51zhEkIbqJAmeI8n5dxiJy3Bvgfm%2BMpQtb6LxXCCfQkVOISE6CZ6r3xokc3PPr5dhq6xtQCoawqO%2ByDNeu3A4NzF9S3az6w%3D%3D (Caused by NewConnectionError('<urllib3.connection.HTTPSConnection object at 0x7ff0744c7190>: Failed to establish a new connection: [Errno 110] Connection timed out'))
2024-01-30 17:12:12,022 ERROR   wandb-upload_1:1134333 [internal_api.py:upload_file():2767] upload_file request headers: {'User-Agent': 'python-requests/2.23.0', 'Accept-Encoding': 'gzip, deflate', 'Accept': '*/*', 'Connection': 'keep-alive', 'Content-MD5': 'F0o9m8Yf7BJsx9W9/1xsWg==', 'Content-Type': 'text/plain; charset=utf-8', 'Content-Length': '2179'}
2024-01-30 17:12:12,022 ERROR   wandb-upload_1:1134333 [internal_api.py:upload_file():2769] upload_file response body: 
2024-01-30 17:12:14,070 ERROR   wandb-upload_2:1134333 [internal_api.py:upload_file():2765] upload_file exception https://storage.googleapis.com/wandb-artifacts-prod/wandb_artifacts/133981200/707680441/6873c23a2381d1524249eb1a948a45a5?Expires=1706688977&GoogleAccessId=gorilla-files-url-signer-man%40wandb-production.iam.gserviceaccount.com&Signature=qIJkPWvML5xinRceuHOzA0bUaw3Do9%2F91nWMxuxxepOVZJnxcZAb%2FvWPuaHz%2BgN%2FpMtlTLUXpb61voC%2Btv0PuVKFX1JYa4wzyYH9JGNauViHKrnTWzhOE2Y%2FUN%2FSjAS8vRKa2evko8P8FXApaLaBiuKPxkEJTiUDsjWR0C4JNp8M6LhslScdVqaq1EzjjBf7lF6GHjKSCdIcLc4MQtW5htoqnJCYQiEeokqd5H6kZH1%2BMgmEI6wMFyH6tMEt1c%2FZx0u2NJsKqXgcZLsf%2FcCERAg8fgoDojG59bTu5L2ioIfAUOwTrbm75KUZ6Mhiz9mbXbjiC0Ek65fb6CwqmWvW%2Bw%3D%3D: HTTPSConnectionPool(host='storage.googleapis.com', port=443): Max retries exceeded with url: /wandb-artifacts-prod/wandb_artifacts/133981200/707680441/6873c23a2381d1524249eb1a948a45a5?Expires=1706688977&GoogleAccessId=gorilla-files-url-signer-man%40wandb-production.iam.gserviceaccount.com&Signature=qIJkPWvML5xinRceuHOzA0bUaw3Do9%2F91nWMxuxxepOVZJnxcZAb%2FvWPuaHz%2BgN%2FpMtlTLUXpb61voC%2Btv0PuVKFX1JYa4wzyYH9JGNauViHKrnTWzhOE2Y%2FUN%2FSjAS8vRKa2evko8P8FXApaLaBiuKPxkEJTiUDsjWR0C4JNp8M6LhslScdVqaq1EzjjBf7lF6GHjKSCdIcLc4MQtW5htoqnJCYQiEeokqd5H6kZH1%2BMgmEI6wMFyH6tMEt1c%2FZx0u2NJsKqXgcZLsf%2FcCERAg8fgoDojG59bTu5L2ioIfAUOwTrbm75KUZ6Mhiz9mbXbjiC0Ek65fb6CwqmWvW%2Bw%3D%3D (Caused by NewConnectionError('<urllib3.connection.HTTPSConnection object at 0x7ff0744c7b20>: Failed to establish a new connection: [Errno 110] Connection timed out'))
2024-01-30 17:12:14,070 ERROR   wandb-upload_2:1134333 [internal_api.py:upload_file():2767] upload_file request headers: {'User-Agent': 'python-requests/2.23.0', 'Accept-Encoding': 'gzip, deflate', 'Accept': '*/*', 'Connection': 'keep-alive', 'Content-MD5': 'aHPCOiOB0VJCSesalIpFpQ==', 'Content-Type': 'application/json', 'Content-Length': '609'}
2024-01-30 17:12:14,070 ERROR   wandb-upload_2:1134333 [internal_api.py:upload_file():2769] upload_file response body: 
2024-01-30 17:12:18,166 ERROR   wandb-upload_0:1134333 [internal_api.py:upload_file():2765] upload_file exception https://storage.googleapis.com/wandb-production.appspot.com/dynamic_x/bert_pytorch/k02uw2vk/wandb-metadata.json?Expires=1706688636&GoogleAccessId=gorilla-files-url-signer-man%40wandb-production.iam.gserviceaccount.com&Signature=O5gfF6B4ppD%2Bi%2BHqYp9rSofCCWc6atzI%2FJ4kGH8QCvKU9TkLSWBd4L%2F0Y8wy4VYiO5uN8bfoYhQ7nit1eT%2FGIpv06LqT3QKE9ClIuiKmeXxqMcA%2BVYrF5dRiXdyC%2Ba6nTwG5qncoYioJQ%2BdHwrNWRGwrgboVjc2r3ZqfVaZTtzHCjJq3tENgZPG5JBeN2mA1r1OaXz7PJ9NZOONnTc5%2BkP%2Feos3GUefnLmb%2BOM2gHS4HWB%2FTQUzghpD6VD%2FR5587T4eupp1Cm1BaxsoMs2u7AaSK5VMhsX87cKcyp8N%2BZLNgpeN%2BzmofSok1yArLSWqjOJvzAkDzvX9Lm4cRbJzDEw%3D%3D: HTTPSConnectionPool(host='storage.googleapis.com', port=443): Max retries exceeded with url: /wandb-production.appspot.com/dynamic_x/bert_pytorch/k02uw2vk/wandb-metadata.json?Expires=1706688636&GoogleAccessId=gorilla-files-url-signer-man%40wandb-production.iam.gserviceaccount.com&Signature=O5gfF6B4ppD%2Bi%2BHqYp9rSofCCWc6atzI%2FJ4kGH8QCvKU9TkLSWBd4L%2F0Y8wy4VYiO5uN8bfoYhQ7nit1eT%2FGIpv06LqT3QKE9ClIuiKmeXxqMcA%2BVYrF5dRiXdyC%2Ba6nTwG5qncoYioJQ%2BdHwrNWRGwrgboVjc2r3ZqfVaZTtzHCjJq3tENgZPG5JBeN2mA1r1OaXz7PJ9NZOONnTc5%2BkP%2Feos3GUefnLmb%2BOM2gHS4HWB%2FTQUzghpD6VD%2FR5587T4eupp1Cm1BaxsoMs2u7AaSK5VMhsX87cKcyp8N%2BZLNgpeN%2BzmofSok1yArLSWqjOJvzAkDzvX9Lm4cRbJzDEw%3D%3D (Caused by NewConnectionError('<urllib3.connection.HTTPSConnection object at 0x7ff0744c7e20>: Failed to establish a new connection: [Errno 110] Connection timed out'))
2024-01-30 17:12:18,166 ERROR   wandb-upload_0:1134333 [internal_api.py:upload_file():2767] upload_file request headers: {'User-Agent': 'python-requests/2.23.0', 'Accept-Encoding': 'gzip, deflate', 'Accept': '*/*', 'Connection': 'keep-alive', 'Content-Length': '15547'}
2024-01-30 17:12:18,166 ERROR   wandb-upload_0:1134333 [internal_api.py:upload_file():2769] upload_file response body: 
2024-01-30 17:17:24,733 ERROR   wandb-upload_2:1134333 [internal_api.py:upload_file():2765] upload_file exception https://storage.googleapis.com/wandb-artifacts-prod/wandb_artifacts/133981200/707680441/6873c23a2381d1524249eb1a948a45a5?Expires=1706688977&GoogleAccessId=gorilla-files-url-signer-man%40wandb-production.iam.gserviceaccount.com&Signature=qIJkPWvML5xinRceuHOzA0bUaw3Do9%2F91nWMxuxxepOVZJnxcZAb%2FvWPuaHz%2BgN%2FpMtlTLUXpb61voC%2Btv0PuVKFX1JYa4wzyYH9JGNauViHKrnTWzhOE2Y%2FUN%2FSjAS8vRKa2evko8P8FXApaLaBiuKPxkEJTiUDsjWR0C4JNp8M6LhslScdVqaq1EzjjBf7lF6GHjKSCdIcLc4MQtW5htoqnJCYQiEeokqd5H6kZH1%2BMgmEI6wMFyH6tMEt1c%2FZx0u2NJsKqXgcZLsf%2FcCERAg8fgoDojG59bTu5L2ioIfAUOwTrbm75KUZ6Mhiz9mbXbjiC0Ek65fb6CwqmWvW%2Bw%3D%3D: HTTPSConnectionPool(host='storage.googleapis.com', port=443): Max retries exceeded with url: /wandb-artifacts-prod/wandb_artifacts/133981200/707680441/6873c23a2381d1524249eb1a948a45a5?Expires=1706688977&GoogleAccessId=gorilla-files-url-signer-man%40wandb-production.iam.gserviceaccount.com&Signature=qIJkPWvML5xinRceuHOzA0bUaw3Do9%2F91nWMxuxxepOVZJnxcZAb%2FvWPuaHz%2BgN%2FpMtlTLUXpb61voC%2Btv0PuVKFX1JYa4wzyYH9JGNauViHKrnTWzhOE2Y%2FUN%2FSjAS8vRKa2evko8P8FXApaLaBiuKPxkEJTiUDsjWR0C4JNp8M6LhslScdVqaq1EzjjBf7lF6GHjKSCdIcLc4MQtW5htoqnJCYQiEeokqd5H6kZH1%2BMgmEI6wMFyH6tMEt1c%2FZx0u2NJsKqXgcZLsf%2FcCERAg8fgoDojG59bTu5L2ioIfAUOwTrbm75KUZ6Mhiz9mbXbjiC0Ek65fb6CwqmWvW%2Bw%3D%3D (Caused by NewConnectionError('<urllib3.connection.HTTPSConnection object at 0x7ff074e1cbb0>: Failed to establish a new connection: [Errno 101] Network is unreachable'))
2024-01-30 17:17:24,734 ERROR   wandb-upload_2:1134333 [internal_api.py:upload_file():2767] upload_file request headers: {'User-Agent': 'python-requests/2.23.0', 'Accept-Encoding': 'gzip, deflate', 'Accept': '*/*', 'Connection': 'keep-alive', 'Content-MD5': 'aHPCOiOB0VJCSesalIpFpQ==', 'Content-Type': 'application/json', 'Content-Length': '609'}
2024-01-30 17:17:24,734 ERROR   wandb-upload_2:1134333 [internal_api.py:upload_file():2769] upload_file response body: 
2024-01-30 17:18:09,912 ERROR   wandb-upload_0:1134333 [internal_api.py:upload_file():2765] upload_file exception https://storage.googleapis.com/wandb-production.appspot.com/dynamic_x/bert_pytorch/k02uw2vk/wandb-metadata.json?Expires=1706688636&GoogleAccessId=gorilla-files-url-signer-man%40wandb-production.iam.gserviceaccount.com&Signature=O5gfF6B4ppD%2Bi%2BHqYp9rSofCCWc6atzI%2FJ4kGH8QCvKU9TkLSWBd4L%2F0Y8wy4VYiO5uN8bfoYhQ7nit1eT%2FGIpv06LqT3QKE9ClIuiKmeXxqMcA%2BVYrF5dRiXdyC%2Ba6nTwG5qncoYioJQ%2BdHwrNWRGwrgboVjc2r3ZqfVaZTtzHCjJq3tENgZPG5JBeN2mA1r1OaXz7PJ9NZOONnTc5%2BkP%2Feos3GUefnLmb%2BOM2gHS4HWB%2FTQUzghpD6VD%2FR5587T4eupp1Cm1BaxsoMs2u7AaSK5VMhsX87cKcyp8N%2BZLNgpeN%2BzmofSok1yArLSWqjOJvzAkDzvX9Lm4cRbJzDEw%3D%3D: HTTPSConnectionPool(host='storage.googleapis.com', port=443): Max retries exceeded with url: /wandb-production.appspot.com/dynamic_x/bert_pytorch/k02uw2vk/wandb-metadata.json?Expires=1706688636&GoogleAccessId=gorilla-files-url-signer-man%40wandb-production.iam.gserviceaccount.com&Signature=O5gfF6B4ppD%2Bi%2BHqYp9rSofCCWc6atzI%2FJ4kGH8QCvKU9TkLSWBd4L%2F0Y8wy4VYiO5uN8bfoYhQ7nit1eT%2FGIpv06LqT3QKE9ClIuiKmeXxqMcA%2BVYrF5dRiXdyC%2Ba6nTwG5qncoYioJQ%2BdHwrNWRGwrgboVjc2r3ZqfVaZTtzHCjJq3tENgZPG5JBeN2mA1r1OaXz7PJ9NZOONnTc5%2BkP%2Feos3GUefnLmb%2BOM2gHS4HWB%2FTQUzghpD6VD%2FR5587T4eupp1Cm1BaxsoMs2u7AaSK5VMhsX87cKcyp8N%2BZLNgpeN%2BzmofSok1yArLSWqjOJvzAkDzvX9Lm4cRbJzDEw%3D%3D (Caused by NewConnectionError('<urllib3.connection.HTTPSConnection object at 0x7ff0744c70a0>: Failed to establish a new connection: [Errno 101] Network is unreachable'))
2024-01-30 17:18:09,912 ERROR   wandb-upload_0:1134333 [internal_api.py:upload_file():2767] upload_file request headers: {'User-Agent': 'python-requests/2.23.0', 'Accept-Encoding': 'gzip, deflate', 'Accept': '*/*', 'Connection': 'keep-alive', 'Content-Length': '15547'}
2024-01-30 17:18:09,912 ERROR   wandb-upload_0:1134333 [internal_api.py:upload_file():2769] upload_file response body: 
2024-01-30 17:18:17,570 ERROR   wandb-upload_1:1134333 [internal_api.py:upload_file():2765] upload_file exception https://storage.googleapis.com/wandb-artifacts-prod/wandb_artifacts/133981200/707680441/174a3d9bc61fec126cc7d5bdff5c6c5a?Expires=1706688976&GoogleAccessId=gorilla-files-url-signer-man%40wandb-production.iam.gserviceaccount.com&Signature=uIbfStEO5cczURRkS4SpZN1KkOF1nNcaFcdRGat7PQLC9Tggo%2BUgYtftkZei%2BxbqK8nyTsqGnJst%2BoaNPYUckSZg0CJDQFyNY%2BXc4SK3OdCAZ6QF7abYQ7mXMJgzBCTkt1OfRFdc3r%2BjOu67iXZeYVHKHEH69S6pAkgIMCIdREHjeQ2O7IcYtfszxeByToc8Otd72VkwVhWvP%2BgAs2vXLIy2bWdRBO%2BcbPM5ejas4MQH%2B7Z0E9qA8ag51zhEkIbqJAmeI8n5dxiJy3Bvgfm%2BMpQtb6LxXCCfQkVOISE6CZ6r3xokc3PPr5dhq6xtQCoawqO%2ByDNeu3A4NzF9S3az6w%3D%3D: HTTPSConnectionPool(host='storage.googleapis.com', port=443): Max retries exceeded with url: /wandb-artifacts-prod/wandb_artifacts/133981200/707680441/174a3d9bc61fec126cc7d5bdff5c6c5a?Expires=1706688976&GoogleAccessId=gorilla-files-url-signer-man%40wandb-production.iam.gserviceaccount.com&Signature=uIbfStEO5cczURRkS4SpZN1KkOF1nNcaFcdRGat7PQLC9Tggo%2BUgYtftkZei%2BxbqK8nyTsqGnJst%2BoaNPYUckSZg0CJDQFyNY%2BXc4SK3OdCAZ6QF7abYQ7mXMJgzBCTkt1OfRFdc3r%2BjOu67iXZeYVHKHEH69S6pAkgIMCIdREHjeQ2O7IcYtfszxeByToc8Otd72VkwVhWvP%2BgAs2vXLIy2bWdRBO%2BcbPM5ejas4MQH%2B7Z0E9qA8ag51zhEkIbqJAmeI8n5dxiJy3Bvgfm%2BMpQtb6LxXCCfQkVOISE6CZ6r3xokc3PPr5dhq6xtQCoawqO%2ByDNeu3A4NzF9S3az6w%3D%3D (Caused by NewConnectionError('<urllib3.connection.HTTPSConnection object at 0x7ff0744c7e20>: Failed to establish a new connection: [Errno 101] Network is unreachable'))
2024-01-30 17:18:17,570 ERROR   wandb-upload_1:1134333 [internal_api.py:upload_file():2767] upload_file request headers: {'User-Agent': 'python-requests/2.23.0', 'Accept-Encoding': 'gzip, deflate', 'Accept': '*/*', 'Connection': 'keep-alive', 'Content-MD5': 'F0o9m8Yf7BJsx9W9/1xsWg==', 'Content-Type': 'text/plain; charset=utf-8', 'Content-Length': '2179'}
2024-01-30 17:18:17,570 ERROR   wandb-upload_1:1134333 [internal_api.py:upload_file():2769] upload_file response body: 
2024-01-30 17:23:07,634 INFO    wandb-upload_2:1134333 [upload_job.py:push():89] Uploaded file /home/yanxindong/.local/share/wandb/artifacts/staging/tmpx538_y9c
2024-01-30 17:24:13,021 INFO    wandb-upload_0:1134333 [upload_job.py:push():131] Uploaded file /tmp/tmp6u8yns0pwandb/d0o5hh2w-wandb-metadata.json
2024-01-30 17:24:17,252 INFO    wandb-upload_1:1134333 [upload_job.py:push():89] Uploaded file /home/yanxindong/.local/share/wandb/artifacts/staging/tmp7jpts24f
2024-01-30 17:24:20,349 INFO    SenderThread:1134333 [sender.py:send_artifact():1494] sent artifact job-https___github.com_kkkjj-d_mkor.git_bert_run_pretraining.py - {'id': 'QXJ0aWZhY3Q6NzA3NjgwNDQx', 'state': 'PENDING', 'artifactSequence': {'id': 'QXJ0aWZhY3RDb2xsZWN0aW9uOjEzMzk4MTIwMA==', 'latestArtifact': {'id': 'QXJ0aWZhY3Q6NzAzOTc3Mjk3', 'versionIndex': 8}}}
2024-01-30 17:24:20,349 INFO    SenderThread:1134333 [sender.py:finish():1572] shutting down sender
2024-01-30 17:24:20,350 INFO    SenderThread:1134333 [dir_watcher.py:finish():358] shutting down directory watcher
2024-01-30 17:24:20,607 INFO    SenderThread:1134333 [dir_watcher.py:finish():388] scan: /home/yanxindong/mkor/bert/wandb/run-20240130_161012-k02uw2vk/files
2024-01-30 17:24:20,608 INFO    SenderThread:1134333 [dir_watcher.py:finish():402] scan save: /home/yanxindong/mkor/bert/wandb/run-20240130_161012-k02uw2vk/files/wandb-summary.json wandb-summary.json
2024-01-30 17:24:20,608 INFO    SenderThread:1134333 [dir_watcher.py:finish():402] scan save: /home/yanxindong/mkor/bert/wandb/run-20240130_161012-k02uw2vk/files/conda-environment.yaml conda-environment.yaml
2024-01-30 17:24:20,608 INFO    SenderThread:1134333 [dir_watcher.py:finish():402] scan save: /home/yanxindong/mkor/bert/wandb/run-20240130_161012-k02uw2vk/files/wandb-metadata.json wandb-metadata.json
2024-01-30 17:24:20,608 INFO    SenderThread:1134333 [dir_watcher.py:finish():402] scan save: /home/yanxindong/mkor/bert/wandb/run-20240130_161012-k02uw2vk/files/output.log output.log
2024-01-30 17:24:20,609 INFO    SenderThread:1134333 [dir_watcher.py:finish():402] scan save: /home/yanxindong/mkor/bert/wandb/run-20240130_161012-k02uw2vk/files/requirements.txt requirements.txt
2024-01-30 17:24:20,609 INFO    SenderThread:1134333 [dir_watcher.py:finish():402] scan save: /home/yanxindong/mkor/bert/wandb/run-20240130_161012-k02uw2vk/files/config.yaml config.yaml
2024-01-30 17:24:20,617 INFO    SenderThread:1134333 [file_pusher.py:finish():175] shutting down file pusher
2024-01-30 17:24:20,623 INFO    SenderThread:1134333 [file_pusher.py:join():181] waiting for file pusher
2024-01-30 17:24:21,232 INFO    wandb-upload_2:1134333 [upload_job.py:push():131] Uploaded file /home/yanxindong/mkor/bert/wandb/run-20240130_161012-k02uw2vk/files/conda-environment.yaml
2024-01-30 17:24:21,607 INFO    wandb-upload_1:1134333 [upload_job.py:push():131] Uploaded file /home/yanxindong/mkor/bert/wandb/run-20240130_161012-k02uw2vk/files/requirements.txt
2024-01-30 17:24:21,627 INFO    wandb-upload_4:1134333 [upload_job.py:push():131] Uploaded file /home/yanxindong/mkor/bert/wandb/run-20240130_161012-k02uw2vk/files/config.yaml
2024-01-30 17:24:21,631 INFO    wandb-upload_0:1134333 [upload_job.py:push():131] Uploaded file /home/yanxindong/mkor/bert/wandb/run-20240130_161012-k02uw2vk/files/output.log
2024-01-30 17:24:22,503 INFO    wandb-upload_3:1134333 [upload_job.py:push():131] Uploaded file /home/yanxindong/mkor/bert/wandb/run-20240130_161012-k02uw2vk/files/wandb-summary.json
2024-01-30 17:24:23,126 INFO    SenderThread:1134333 [file_stream.py:finish():595] file stream finish called
2024-01-30 17:24:23,396 INFO    SenderThread:1134333 [file_stream.py:finish():599] file stream finish is done
