2024-01-30 16:10:12,572 INFO    StreamThr :1134335 [internal.py:wandb_internal():86] W&B internal server running at pid: 1134335, started at: 2024-01-30 16:10:12.571572
2024-01-30 16:10:12,603 DEBUG   HandlerThread:1134335 [handler.py:handle_request():146] handle_request: status
2024-01-30 16:10:12,609 INFO    WriterThread:1134335 [datastore.py:open_for_write():87] open: /home/yanxindong/mkor/bert/wandb/run-20240130_161012-jomc1iuf/run-jomc1iuf.wandb
2024-01-30 16:10:12,609 DEBUG   SenderThread:1134335 [sender.py:send():382] send: header
2024-01-30 16:10:12,609 DEBUG   SenderThread:1134335 [sender.py:send():382] send: run
2024-01-30 16:10:13,855 DEBUG   HandlerThread:1134335 [handler.py:handle_request():146] handle_request: check_version
2024-01-30 16:10:13,855 INFO    SenderThread:1134335 [dir_watcher.py:__init__():211] watching files in: /home/yanxindong/mkor/bert/wandb/run-20240130_161012-jomc1iuf/files
2024-01-30 16:10:13,856 INFO    SenderThread:1134335 [sender.py:_start_run_threads():1136] run started: jomc1iuf with start time 1706602212.535899
2024-01-30 16:10:13,856 DEBUG   SenderThread:1134335 [sender.py:send_request():409] send_request: check_version
2024-01-30 16:10:14,797 DEBUG   HandlerThread:1134335 [handler.py:handle_request():146] handle_request: run_start
2024-01-30 16:10:14,822 DEBUG   HandlerThread:1134335 [system_info.py:__init__():27] System info init
2024-01-30 16:10:14,822 DEBUG   HandlerThread:1134335 [system_info.py:__init__():42] System info init done
2024-01-30 16:10:14,822 INFO    HandlerThread:1134335 [system_monitor.py:start():194] Starting system monitor
2024-01-30 16:10:14,856 INFO    SystemMonitor:1134335 [system_monitor.py:_start():158] Starting system asset monitoring threads
2024-01-30 16:10:14,856 INFO    HandlerThread:1134335 [system_monitor.py:probe():214] Collecting system info
2024-01-30 16:10:14,925 INFO    SystemMonitor:1134335 [interfaces.py:start():190] Started cpu monitoring
2024-01-30 16:10:14,957 INFO    SystemMonitor:1134335 [interfaces.py:start():190] Started disk monitoring
2024-01-30 16:10:14,990 INFO    SystemMonitor:1134335 [interfaces.py:start():190] Started gpu monitoring
2024-01-30 16:10:15,026 INFO    SystemMonitor:1134335 [interfaces.py:start():190] Started memory monitoring
2024-01-30 16:10:15,037 INFO    SystemMonitor:1134335 [interfaces.py:start():190] Started network monitoring
2024-01-30 16:10:15,079 DEBUG   HandlerThread:1134335 [system_info.py:probe():151] Probing system
2024-01-30 16:10:15,115 DEBUG   HandlerThread:1134335 [system_info.py:_probe_git():136] Probing git
2024-01-30 16:10:15,164 DEBUG   HandlerThread:1134335 [system_info.py:_probe_git():144] Probing git done
2024-01-30 16:10:15,164 DEBUG   HandlerThread:1134335 [system_info.py:probe():199] Probing system done
2024-01-30 16:10:15,164 DEBUG   HandlerThread:1134335 [system_monitor.py:probe():223] {'os': 'Linux-5.15.0-92-generic-x86_64-with-glibc2.17', 'python': '3.8.17', 'heartbeatAt': '2024-01-30T08:10:15.080045', 'startedAt': '2024-01-30T08:10:12.528151', 'docker': None, 'cuda': None, 'args': ('--local_rank=6', '--config_file', 'config/bert_pretraining_phase2_config.json', '--input_dir', '/home/yanxindong/mkor/bert/data/encoded/sequences_lowercase_max_seq_len_512_next_seq_task_true', '--output_dir', 'results/adam', '--weight_decay', '0.01', '--num_steps_per_checkpoint', '200'), 'state': 'running', 'program': 'run_pretraining.py', 'codePathLocal': 'run_pretraining.py', 'codePath': 'bert/run_pretraining.py', 'git': {'remote': 'https://github.com/kkkjj-d/mkor.git', 'commit': 'efe99e84fef5594780cfb1df6d6a1f61da4ebba0'}, 'email': '1262670315@qq.com', 'root': '/home/yanxindong/mkor', 'host': 'a6000-X640-G40', 'username': 'yanxindong', 'executable': '/home/yanxindong/anaconda/envs/eva/bin/python', 'cpu_count': 64, 'cpu_count_logical': 128, 'cpu_freq': {'current': 850.781203125, 'min': 800.0, 'max': 3400.0}, 'cpu_freq_per_core': [{'current': 3299.997, 'min': 800.0, 'max': 3400.0}, {'current': 900.0, 'min': 800.0, 'max': 3400.0}, {'current': 800.0, 'min': 800.0, 'max': 3400.0}, {'current': 800.0, 'min': 800.0, 'max': 3400.0}, {'current': 800.0, 'min': 800.0, 'max': 3400.0}, {'current': 800.0, 'min': 800.0, 'max': 3400.0}, {'current': 800.0, 'min': 800.0, 'max': 3400.0}, {'current': 800.0, 'min': 800.0, 'max': 3400.0}, {'current': 900.0, 'min': 800.0, 'max': 3400.0}, {'current': 800.0, 'min': 800.0, 'max': 3400.0}, {'current': 800.0, 'min': 800.0, 'max': 3400.0}, {'current': 800.0, 'min': 800.0, 'max': 3400.0}, {'current': 800.0, 'min': 800.0, 'max': 3400.0}, {'current': 800.0, 'min': 800.0, 'max': 3400.0}, {'current': 800.0, 'min': 800.0, 'max': 3400.0}, {'current': 800.0, 'min': 800.0, 'max': 3400.0}, {'current': 800.0, 'min': 800.0, 'max': 3400.0}, {'current': 800.0, 'min': 800.0, 'max': 3400.0}, {'current': 800.0, 'min': 800.0, 'max': 3400.0}, {'current': 800.0, 'min': 800.0, 'max': 3400.0}, {'current': 800.0, 'min': 800.0, 'max': 3400.0}, {'current': 800.0, 'min': 800.0, 'max': 3400.0}, {'current': 800.0, 'min': 800.0, 'max': 3400.0}, {'current': 800.0, 'min': 800.0, 'max': 3400.0}, {'current': 800.0, 'min': 800.0, 'max': 3400.0}, {'current': 800.0, 'min': 800.0, 'max': 3400.0}, {'current': 800.0, 'min': 800.0, 'max': 3400.0}, {'current': 800.0, 'min': 800.0, 'max': 3400.0}, {'current': 800.0, 'min': 800.0, 'max': 3400.0}, {'current': 800.0, 'min': 800.0, 'max': 3400.0}, {'current': 800.0, 'min': 800.0, 'max': 3400.0}, {'current': 800.0, 'min': 800.0, 'max': 3400.0}, {'current': 800.0, 'min': 800.0, 'max': 3400.0}, {'current': 800.0, 'min': 800.0, 'max': 3400.0}, {'current': 1300.0, 'min': 800.0, 'max': 3400.0}, {'current': 800.0, 'min': 800.0, 'max': 3400.0}, {'current': 800.0, 'min': 800.0, 'max': 3400.0}, {'current': 800.0, 'min': 800.0, 'max': 3400.0}, {'current': 800.0, 'min': 800.0, 'max': 3400.0}, {'current': 800.0, 'min': 800.0, 'max': 3400.0}, {'current': 800.0, 'min': 800.0, 'max': 3400.0}, {'current': 800.0, 'min': 800.0, 'max': 3400.0}, {'current': 800.0, 'min': 800.0, 'max': 3400.0}, {'current': 800.0, 'min': 800.0, 'max': 3400.0}, {'current': 800.0, 'min': 800.0, 'max': 3400.0}, {'current': 800.0, 'min': 800.0, 'max': 3400.0}, {'current': 800.0, 'min': 800.0, 'max': 3400.0}, {'current': 800.0, 'min': 800.0, 'max': 3400.0}, {'current': 800.0, 'min': 800.0, 'max': 3400.0}, {'current': 800.0, 'min': 800.0, 'max': 3400.0}, {'current': 800.0, 'min': 800.0, 'max': 3400.0}, {'current': 1000.0, 'min': 800.0, 'max': 3400.0}, {'current': 800.0, 'min': 800.0, 'max': 3400.0}, {'current': 800.0, 'min': 800.0, 'max': 3400.0}, {'current': 800.0, 'min': 800.0, 'max': 3400.0}, {'current': 800.0, 'min': 800.0, 'max': 3400.0}, {'current': 800.0, 'min': 800.0, 'max': 3400.0}, {'current': 800.0, 'min': 800.0, 'max': 3400.0}, {'current': 800.0, 'min': 800.0, 'max': 3400.0}, {'current': 800.0, 'min': 800.0, 'max': 3400.0}, {'current': 800.0, 'min': 800.0, 'max': 3400.0}, {'current': 800.0, 'min': 800.0, 'max': 3400.0}, {'current': 800.0, 'min': 800.0, 'max': 3400.0}, {'current': 800.0, 'min': 800.0, 'max': 3400.0}, {'current': 3300.0, 'min': 800.0, 'max': 3400.0}, {'current': 800.0, 'min': 800.0, 'max': 3400.0}, {'current': 800.0, 'min': 800.0, 'max': 3400.0}, {'current': 800.0, 'min': 800.0, 'max': 3400.0}, {'current': 800.0, 'min': 800.0, 'max': 3400.0}, {'current': 800.0, 'min': 800.0, 'max': 3400.0}, {'current': 800.0, 'min': 800.0, 'max': 3400.0}, {'current': 800.0, 'min': 800.0, 'max': 3400.0}, {'current': 800.0, 'min': 800.0, 'max': 3400.0}, {'current': 800.0, 'min': 800.0, 'max': 3400.0}, {'current': 800.0, 'min': 800.0, 'max': 3400.0}, {'current': 800.0, 'min': 800.0, 'max': 3400.0}, {'current': 800.0, 'min': 800.0, 'max': 3400.0}, {'current': 800.0, 'min': 800.0, 'max': 3400.0}, {'current': 800.0, 'min': 800.0, 'max': 3400.0}, {'current': 800.0, 'min': 800.0, 'max': 3400.0}, {'current': 800.0, 'min': 800.0, 'max': 3400.0}, {'current': 800.0, 'min': 800.0, 'max': 3400.0}, {'current': 800.0, 'min': 800.0, 'max': 3400.0}, {'current': 800.0, 'min': 800.0, 'max': 3400.0}, {'current': 800.0, 'min': 800.0, 'max': 3400.0}, {'current': 800.0, 'min': 800.0, 'max': 3400.0}, {'current': 800.0, 'min': 800.0, 'max': 3400.0}, {'current': 800.0, 'min': 800.0, 'max': 3400.0}, {'current': 800.0, 'min': 800.0, 'max': 3400.0}, {'current': 800.0, 'min': 800.0, 'max': 3400.0}, {'current': 800.0, 'min': 800.0, 'max': 3400.0}, {'current': 800.0, 'min': 800.0, 'max': 3400.0}, {'current': 800.0, 'min': 800.0, 'max': 3400.0}, {'current': 800.0, 'min': 800.0, 'max': 3400.0}, {'current': 800.0, 'min': 800.0, 'max': 3400.0}, {'current': 800.0, 'min': 800.0, 'max': 3400.0}, {'current': 800.0, 'min': 800.0, 'max': 3400.0}, {'current': 800.0, 'min': 800.0, 'max': 3400.0}, {'current': 800.0, 'min': 800.0, 'max': 3400.0}, {'current': 800.0, 'min': 800.0, 'max': 3400.0}, {'current': 800.0, 'min': 800.0, 'max': 3400.0}, {'current': 800.0, 'min': 800.0, 'max': 3400.0}, {'current': 800.0, 'min': 800.0, 'max': 3400.0}, {'current': 800.0, 'min': 800.0, 'max': 3400.0}, {'current': 800.0, 'min': 800.0, 'max': 3400.0}, {'current': 800.0, 'min': 800.0, 'max': 3400.0}, {'current': 800.0, 'min': 800.0, 'max': 3400.0}, {'current': 800.0, 'min': 800.0, 'max': 3400.0}, {'current': 800.0, 'min': 800.0, 'max': 3400.0}, {'current': 800.0, 'min': 800.0, 'max': 3400.0}, {'current': 900.0, 'min': 800.0, 'max': 3400.0}, {'current': 800.0, 'min': 800.0, 'max': 3400.0}, {'current': 800.0, 'min': 800.0, 'max': 3400.0}, {'current': 800.0, 'min': 800.0, 'max': 3400.0}, {'current': 800.0, 'min': 800.0, 'max': 3400.0}, {'current': 800.0, 'min': 800.0, 'max': 3400.0}, {'current': 800.0, 'min': 800.0, 'max': 3400.0}, {'current': 800.0, 'min': 800.0, 'max': 3400.0}, {'current': 800.0, 'min': 800.0, 'max': 3400.0}, {'current': 800.0, 'min': 800.0, 'max': 3400.0}, {'current': 800.0, 'min': 800.0, 'max': 3400.0}, {'current': 800.0, 'min': 800.0, 'max': 3400.0}, {'current': 800.0, 'min': 800.0, 'max': 3400.0}, {'current': 800.0, 'min': 800.0, 'max': 3400.0}, {'current': 800.0, 'min': 800.0, 'max': 3400.0}, {'current': 800.0, 'min': 800.0, 'max': 3400.0}, {'current': 800.0, 'min': 800.0, 'max': 3400.0}, {'current': 800.0, 'min': 800.0, 'max': 3400.0}], 'disk': {'/': {'total': 438.05088806152344, 'used': 30.817367553710938}}, 'gpu': 'NVIDIA RTX A6000', 'gpu_count': 8, 'gpu_devices': [{'name': 'NVIDIA RTX A6000', 'memory_total': 51527024640}, {'name': 'NVIDIA RTX A6000', 'memory_total': 51527024640}, {'name': 'NVIDIA RTX A6000', 'memory_total': 51527024640}, {'name': 'NVIDIA RTX A6000', 'memory_total': 51527024640}, {'name': 'NVIDIA RTX A6000', 'memory_total': 51527024640}, {'name': 'NVIDIA RTX A6000', 'memory_total': 51527024640}, {'name': 'NVIDIA RTX A6000', 'memory_total': 51527024640}, {'name': 'NVIDIA RTX A6000', 'memory_total': 51527024640}], 'memory': {'total': 503.51252365112305}}
2024-01-30 16:10:15,164 INFO    HandlerThread:1134335 [system_monitor.py:probe():224] Finished collecting system info
2024-01-30 16:10:15,164 INFO    HandlerThread:1134335 [system_monitor.py:probe():227] Publishing system info
2024-01-30 16:10:15,164 DEBUG   HandlerThread:1134335 [system_info.py:_save_conda():208] Saving list of conda packages installed into the current environment
2024-01-30 16:10:15,858 INFO    Thread-12 :1134335 [dir_watcher.py:_on_file_created():271] file/dir created: /home/yanxindong/mkor/bert/wandb/run-20240130_161012-jomc1iuf/files/conda-environment.yaml
2024-01-30 16:10:35,861 INFO    Thread-12 :1134335 [dir_watcher.py:_on_file_modified():288] file/dir modified: /home/yanxindong/mkor/bert/wandb/run-20240130_161012-jomc1iuf/files/conda-environment.yaml
2024-01-30 16:10:35,975 DEBUG   HandlerThread:1134335 [system_info.py:_save_conda():220] Saving conda packages done
2024-01-30 16:10:35,976 INFO    HandlerThread:1134335 [system_monitor.py:probe():229] Finished publishing system info
2024-01-30 16:10:35,981 DEBUG   HandlerThread:1134335 [handler.py:handle_request():146] handle_request: status_report
2024-01-30 16:10:35,987 DEBUG   HandlerThread:1134335 [handler.py:handle_request():146] handle_request: keepalive
2024-01-30 16:10:35,987 DEBUG   HandlerThread:1134335 [handler.py:handle_request():146] handle_request: status_report
2024-01-30 16:10:35,987 DEBUG   HandlerThread:1134335 [handler.py:handle_request():146] handle_request: keepalive
2024-01-30 16:10:35,987 DEBUG   HandlerThread:1134335 [handler.py:handle_request():146] handle_request: status_report
2024-01-30 16:10:35,987 DEBUG   HandlerThread:1134335 [handler.py:handle_request():146] handle_request: keepalive
2024-01-30 16:10:35,988 DEBUG   HandlerThread:1134335 [handler.py:handle_request():146] handle_request: status_report
2024-01-30 16:10:35,988 DEBUG   HandlerThread:1134335 [handler.py:handle_request():146] handle_request: keepalive
2024-01-30 16:10:35,988 DEBUG   HandlerThread:1134335 [handler.py:handle_request():146] handle_request: python_packages
2024-01-30 16:10:35,988 DEBUG   SenderThread:1134335 [sender.py:send():382] send: files
2024-01-30 16:10:35,988 INFO    SenderThread:1134335 [sender.py:_save_file():1403] saving file wandb-metadata.json with policy now
2024-01-30 16:10:35,989 DEBUG   SenderThread:1134335 [sender.py:send_request():409] send_request: python_packages
2024-01-30 16:10:36,005 DEBUG   HandlerThread:1134335 [handler.py:handle_request():146] handle_request: stop_status
2024-01-30 16:10:36,006 DEBUG   SenderThread:1134335 [sender.py:send_request():409] send_request: stop_status
2024-01-30 16:10:36,047 DEBUG   HandlerThread:1134335 [handler.py:handle_request():146] handle_request: internal_messages
2024-01-30 16:10:36,297 DEBUG   SenderThread:1134335 [sender.py:send():382] send: telemetry
2024-01-30 16:10:36,701 ERROR   wandb-upload_0:1134335 [internal_api.py:upload_file():2765] upload_file exception https://storage.googleapis.com/wandb-production.appspot.com/dynamic_x/bert_pytorch/jomc1iuf/wandb-metadata.json?Expires=1706688636&GoogleAccessId=gorilla-files-url-signer-man%40wandb-production.iam.gserviceaccount.com&Signature=vqMRnHJotxH%2BLQdQMnF%2FUEG8Q6OLuZGZfMxalY%2FUnvEM%2Be8ZyMBnFDWuHSTfqOP7Pc69TyNGv0JgkpsClhvPAOakvmdu3qmO%2FdMTYx7MsVtQXm1uaTgAUHKXfGVYRGzX9azkKZ0%2BKwudrkvH7EdBXfilA6u8o670q%2FJ1FhvzKDDw%2FoXnoX36K76PI7uhlnPHE8WjKkYY%2FyGiq7WsA%2BStW4O6FJKFdx47Ho0dU6x5DJjnJKGZY3RjFc3njJGPCbv5ihnK9fMa%2ByElS0PvXjOCVqNBXK5eyNZsuN5E3cnvHSA9ov2kAxBLJ%2F0H%2BX0cOb714VK5eTKeQXMrGebJPG%2B3ow%3D%3D: HTTPSConnectionPool(host='storage.googleapis.com', port=443): Max retries exceeded with url: /wandb-production.appspot.com/dynamic_x/bert_pytorch/jomc1iuf/wandb-metadata.json?Expires=1706688636&GoogleAccessId=gorilla-files-url-signer-man%40wandb-production.iam.gserviceaccount.com&Signature=vqMRnHJotxH%2BLQdQMnF%2FUEG8Q6OLuZGZfMxalY%2FUnvEM%2Be8ZyMBnFDWuHSTfqOP7Pc69TyNGv0JgkpsClhvPAOakvmdu3qmO%2FdMTYx7MsVtQXm1uaTgAUHKXfGVYRGzX9azkKZ0%2BKwudrkvH7EdBXfilA6u8o670q%2FJ1FhvzKDDw%2FoXnoX36K76PI7uhlnPHE8WjKkYY%2FyGiq7WsA%2BStW4O6FJKFdx47Ho0dU6x5DJjnJKGZY3RjFc3njJGPCbv5ihnK9fMa%2ByElS0PvXjOCVqNBXK5eyNZsuN5E3cnvHSA9ov2kAxBLJ%2F0H%2BX0cOb714VK5eTKeQXMrGebJPG%2B3ow%3D%3D (Caused by NewConnectionError('<urllib3.connection.HTTPSConnection object at 0x7f4a1c486df0>: Failed to establish a new connection: [Errno 111] Connection refused'))
2024-01-30 16:10:36,701 ERROR   wandb-upload_0:1134335 [internal_api.py:upload_file():2767] upload_file request headers: {'User-Agent': 'python-requests/2.23.0', 'Accept-Encoding': 'gzip, deflate', 'Accept': '*/*', 'Connection': 'keep-alive', 'Content-Length': '15548'}
2024-01-30 16:10:36,701 ERROR   wandb-upload_0:1134335 [internal_api.py:upload_file():2769] upload_file response body: 
2024-01-30 16:10:36,861 INFO    Thread-12 :1134335 [dir_watcher.py:_on_file_created():271] file/dir created: /home/yanxindong/mkor/bert/wandb/run-20240130_161012-jomc1iuf/files/requirements.txt
2024-01-30 16:10:36,861 INFO    Thread-12 :1134335 [dir_watcher.py:_on_file_created():271] file/dir created: /home/yanxindong/mkor/bert/wandb/run-20240130_161012-jomc1iuf/files/wandb-metadata.json
2024-01-30 16:10:37,902 ERROR   wandb-upload_0:1134335 [internal_api.py:upload_file():2765] upload_file exception https://storage.googleapis.com/wandb-production.appspot.com/dynamic_x/bert_pytorch/jomc1iuf/wandb-metadata.json?Expires=1706688636&GoogleAccessId=gorilla-files-url-signer-man%40wandb-production.iam.gserviceaccount.com&Signature=vqMRnHJotxH%2BLQdQMnF%2FUEG8Q6OLuZGZfMxalY%2FUnvEM%2Be8ZyMBnFDWuHSTfqOP7Pc69TyNGv0JgkpsClhvPAOakvmdu3qmO%2FdMTYx7MsVtQXm1uaTgAUHKXfGVYRGzX9azkKZ0%2BKwudrkvH7EdBXfilA6u8o670q%2FJ1FhvzKDDw%2FoXnoX36K76PI7uhlnPHE8WjKkYY%2FyGiq7WsA%2BStW4O6FJKFdx47Ho0dU6x5DJjnJKGZY3RjFc3njJGPCbv5ihnK9fMa%2ByElS0PvXjOCVqNBXK5eyNZsuN5E3cnvHSA9ov2kAxBLJ%2F0H%2BX0cOb714VK5eTKeQXMrGebJPG%2B3ow%3D%3D: HTTPSConnectionPool(host='storage.googleapis.com', port=443): Max retries exceeded with url: /wandb-production.appspot.com/dynamic_x/bert_pytorch/jomc1iuf/wandb-metadata.json?Expires=1706688636&GoogleAccessId=gorilla-files-url-signer-man%40wandb-production.iam.gserviceaccount.com&Signature=vqMRnHJotxH%2BLQdQMnF%2FUEG8Q6OLuZGZfMxalY%2FUnvEM%2Be8ZyMBnFDWuHSTfqOP7Pc69TyNGv0JgkpsClhvPAOakvmdu3qmO%2FdMTYx7MsVtQXm1uaTgAUHKXfGVYRGzX9azkKZ0%2BKwudrkvH7EdBXfilA6u8o670q%2FJ1FhvzKDDw%2FoXnoX36K76PI7uhlnPHE8WjKkYY%2FyGiq7WsA%2BStW4O6FJKFdx47Ho0dU6x5DJjnJKGZY3RjFc3njJGPCbv5ihnK9fMa%2ByElS0PvXjOCVqNBXK5eyNZsuN5E3cnvHSA9ov2kAxBLJ%2F0H%2BX0cOb714VK5eTKeQXMrGebJPG%2B3ow%3D%3D (Caused by NewConnectionError('<urllib3.connection.HTTPSConnection object at 0x7f4a1c4867c0>: Failed to establish a new connection: [Errno 111] Connection refused'))
2024-01-30 16:10:37,902 ERROR   wandb-upload_0:1134335 [internal_api.py:upload_file():2767] upload_file request headers: {'User-Agent': 'python-requests/2.23.0', 'Accept-Encoding': 'gzip, deflate', 'Accept': '*/*', 'Connection': 'keep-alive', 'Content-Length': '15548'}
2024-01-30 16:10:37,902 ERROR   wandb-upload_0:1134335 [internal_api.py:upload_file():2769] upload_file response body: 
2024-01-30 16:10:38,297 DEBUG   HandlerThread:1134335 [handler.py:handle_request():146] handle_request: status_report
2024-01-30 16:10:40,086 ERROR   wandb-upload_0:1134335 [internal_api.py:upload_file():2765] upload_file exception https://storage.googleapis.com/wandb-production.appspot.com/dynamic_x/bert_pytorch/jomc1iuf/wandb-metadata.json?Expires=1706688636&GoogleAccessId=gorilla-files-url-signer-man%40wandb-production.iam.gserviceaccount.com&Signature=vqMRnHJotxH%2BLQdQMnF%2FUEG8Q6OLuZGZfMxalY%2FUnvEM%2Be8ZyMBnFDWuHSTfqOP7Pc69TyNGv0JgkpsClhvPAOakvmdu3qmO%2FdMTYx7MsVtQXm1uaTgAUHKXfGVYRGzX9azkKZ0%2BKwudrkvH7EdBXfilA6u8o670q%2FJ1FhvzKDDw%2FoXnoX36K76PI7uhlnPHE8WjKkYY%2FyGiq7WsA%2BStW4O6FJKFdx47Ho0dU6x5DJjnJKGZY3RjFc3njJGPCbv5ihnK9fMa%2ByElS0PvXjOCVqNBXK5eyNZsuN5E3cnvHSA9ov2kAxBLJ%2F0H%2BX0cOb714VK5eTKeQXMrGebJPG%2B3ow%3D%3D: HTTPSConnectionPool(host='storage.googleapis.com', port=443): Max retries exceeded with url: /wandb-production.appspot.com/dynamic_x/bert_pytorch/jomc1iuf/wandb-metadata.json?Expires=1706688636&GoogleAccessId=gorilla-files-url-signer-man%40wandb-production.iam.gserviceaccount.com&Signature=vqMRnHJotxH%2BLQdQMnF%2FUEG8Q6OLuZGZfMxalY%2FUnvEM%2Be8ZyMBnFDWuHSTfqOP7Pc69TyNGv0JgkpsClhvPAOakvmdu3qmO%2FdMTYx7MsVtQXm1uaTgAUHKXfGVYRGzX9azkKZ0%2BKwudrkvH7EdBXfilA6u8o670q%2FJ1FhvzKDDw%2FoXnoX36K76PI7uhlnPHE8WjKkYY%2FyGiq7WsA%2BStW4O6FJKFdx47Ho0dU6x5DJjnJKGZY3RjFc3njJGPCbv5ihnK9fMa%2ByElS0PvXjOCVqNBXK5eyNZsuN5E3cnvHSA9ov2kAxBLJ%2F0H%2BX0cOb714VK5eTKeQXMrGebJPG%2B3ow%3D%3D (Caused by NewConnectionError('<urllib3.connection.HTTPSConnection object at 0x7f4a1c486fd0>: Failed to establish a new connection: [Errno 111] Connection refused'))
2024-01-30 16:10:40,087 ERROR   wandb-upload_0:1134335 [internal_api.py:upload_file():2767] upload_file request headers: {'User-Agent': 'python-requests/2.23.0', 'Accept-Encoding': 'gzip, deflate', 'Accept': '*/*', 'Connection': 'keep-alive', 'Content-Length': '15548'}
2024-01-30 16:10:40,087 ERROR   wandb-upload_0:1134335 [internal_api.py:upload_file():2769] upload_file response body: 
2024-01-30 16:10:40,087 INFO    wandb-upload_0:1134335 [retry.py:__call__():172] Retry attempt failed:
Traceback (most recent call last):
  File "/home/yanxindong/anaconda/envs/eva/lib/python3.8/site-packages/urllib3/connection.py", line 159, in _new_conn
    conn = connection.create_connection(
  File "/home/yanxindong/anaconda/envs/eva/lib/python3.8/site-packages/urllib3/util/connection.py", line 84, in create_connection
    raise err
  File "/home/yanxindong/anaconda/envs/eva/lib/python3.8/site-packages/urllib3/util/connection.py", line 74, in create_connection
    sock.connect(sa)
ConnectionRefusedError: [Errno 111] Connection refused

During handling of the above exception, another exception occurred:

Traceback (most recent call last):
  File "/home/yanxindong/anaconda/envs/eva/lib/python3.8/site-packages/urllib3/connectionpool.py", line 670, in urlopen
    httplib_response = self._make_request(
  File "/home/yanxindong/anaconda/envs/eva/lib/python3.8/site-packages/urllib3/connectionpool.py", line 381, in _make_request
    self._validate_conn(conn)
  File "/home/yanxindong/anaconda/envs/eva/lib/python3.8/site-packages/urllib3/connectionpool.py", line 978, in _validate_conn
    conn.connect()
  File "/home/yanxindong/anaconda/envs/eva/lib/python3.8/site-packages/urllib3/connection.py", line 309, in connect
    conn = self._new_conn()
  File "/home/yanxindong/anaconda/envs/eva/lib/python3.8/site-packages/urllib3/connection.py", line 171, in _new_conn
    raise NewConnectionError(
urllib3.exceptions.NewConnectionError: <urllib3.connection.HTTPSConnection object at 0x7f4a1c486fd0>: Failed to establish a new connection: [Errno 111] Connection refused

During handling of the above exception, another exception occurred:

Traceback (most recent call last):
  File "/home/yanxindong/anaconda/envs/eva/lib/python3.8/site-packages/requests/adapters.py", line 439, in send
    resp = conn.urlopen(
  File "/home/yanxindong/anaconda/envs/eva/lib/python3.8/site-packages/urllib3/connectionpool.py", line 726, in urlopen
    retries = retries.increment(
  File "/home/yanxindong/anaconda/envs/eva/lib/python3.8/site-packages/urllib3/util/retry.py", line 446, in increment
    raise MaxRetryError(_pool, url, error or ResponseError(cause))
urllib3.exceptions.MaxRetryError: HTTPSConnectionPool(host='storage.googleapis.com', port=443): Max retries exceeded with url: /wandb-production.appspot.com/dynamic_x/bert_pytorch/jomc1iuf/wandb-metadata.json?Expires=1706688636&GoogleAccessId=gorilla-files-url-signer-man%40wandb-production.iam.gserviceaccount.com&Signature=vqMRnHJotxH%2BLQdQMnF%2FUEG8Q6OLuZGZfMxalY%2FUnvEM%2Be8ZyMBnFDWuHSTfqOP7Pc69TyNGv0JgkpsClhvPAOakvmdu3qmO%2FdMTYx7MsVtQXm1uaTgAUHKXfGVYRGzX9azkKZ0%2BKwudrkvH7EdBXfilA6u8o670q%2FJ1FhvzKDDw%2FoXnoX36K76PI7uhlnPHE8WjKkYY%2FyGiq7WsA%2BStW4O6FJKFdx47Ho0dU6x5DJjnJKGZY3RjFc3njJGPCbv5ihnK9fMa%2ByElS0PvXjOCVqNBXK5eyNZsuN5E3cnvHSA9ov2kAxBLJ%2F0H%2BX0cOb714VK5eTKeQXMrGebJPG%2B3ow%3D%3D (Caused by NewConnectionError('<urllib3.connection.HTTPSConnection object at 0x7f4a1c486fd0>: Failed to establish a new connection: [Errno 111] Connection refused'))

During handling of the above exception, another exception occurred:

Traceback (most recent call last):
  File "/home/yanxindong/anaconda/envs/eva/lib/python3.8/site-packages/wandb/sdk/internal/internal_api.py", line 2758, in upload_file
    response = self._upload_file_session.put(
  File "/home/yanxindong/anaconda/envs/eva/lib/python3.8/site-packages/requests/sessions.py", line 590, in put
    return self.request('PUT', url, data=data, **kwargs)
  File "/home/yanxindong/anaconda/envs/eva/lib/python3.8/site-packages/requests/sessions.py", line 530, in request
    resp = self.send(prep, **send_kwargs)
  File "/home/yanxindong/anaconda/envs/eva/lib/python3.8/site-packages/requests/sessions.py", line 643, in send
    r = adapter.send(request, **kwargs)
  File "/home/yanxindong/anaconda/envs/eva/lib/python3.8/site-packages/requests/adapters.py", line 516, in send
    raise ConnectionError(e, request=request)
requests.exceptions.ConnectionError: HTTPSConnectionPool(host='storage.googleapis.com', port=443): Max retries exceeded with url: /wandb-production.appspot.com/dynamic_x/bert_pytorch/jomc1iuf/wandb-metadata.json?Expires=1706688636&GoogleAccessId=gorilla-files-url-signer-man%40wandb-production.iam.gserviceaccount.com&Signature=vqMRnHJotxH%2BLQdQMnF%2FUEG8Q6OLuZGZfMxalY%2FUnvEM%2Be8ZyMBnFDWuHSTfqOP7Pc69TyNGv0JgkpsClhvPAOakvmdu3qmO%2FdMTYx7MsVtQXm1uaTgAUHKXfGVYRGzX9azkKZ0%2BKwudrkvH7EdBXfilA6u8o670q%2FJ1FhvzKDDw%2FoXnoX36K76PI7uhlnPHE8WjKkYY%2FyGiq7WsA%2BStW4O6FJKFdx47Ho0dU6x5DJjnJKGZY3RjFc3njJGPCbv5ihnK9fMa%2ByElS0PvXjOCVqNBXK5eyNZsuN5E3cnvHSA9ov2kAxBLJ%2F0H%2BX0cOb714VK5eTKeQXMrGebJPG%2B3ow%3D%3D (Caused by NewConnectionError('<urllib3.connection.HTTPSConnection object at 0x7f4a1c486fd0>: Failed to establish a new connection: [Errno 111] Connection refused'))

During handling of the above exception, another exception occurred:

Traceback (most recent call last):
  File "/home/yanxindong/anaconda/envs/eva/lib/python3.8/site-packages/wandb/sdk/lib/retry.py", line 131, in __call__
    result = self._call_fn(*args, **kwargs)
  File "/home/yanxindong/anaconda/envs/eva/lib/python3.8/site-packages/wandb/sdk/internal/internal_api.py", line 2789, in upload_file
    raise _e.with_traceback(sys.exc_info()[2])
  File "/home/yanxindong/anaconda/envs/eva/lib/python3.8/site-packages/wandb/sdk/internal/internal_api.py", line 2758, in upload_file
    response = self._upload_file_session.put(
  File "/home/yanxindong/anaconda/envs/eva/lib/python3.8/site-packages/requests/sessions.py", line 590, in put
    return self.request('PUT', url, data=data, **kwargs)
  File "/home/yanxindong/anaconda/envs/eva/lib/python3.8/site-packages/requests/sessions.py", line 530, in request
    resp = self.send(prep, **send_kwargs)
  File "/home/yanxindong/anaconda/envs/eva/lib/python3.8/site-packages/requests/sessions.py", line 643, in send
    r = adapter.send(request, **kwargs)
  File "/home/yanxindong/anaconda/envs/eva/lib/python3.8/site-packages/requests/adapters.py", line 516, in send
    raise ConnectionError(e, request=request)
wandb.sdk.lib.retry.TransientError: None
2024-01-30 16:10:43,317 DEBUG   HandlerThread:1134335 [handler.py:handle_request():146] handle_request: status_report
2024-01-30 16:10:44,250 ERROR   wandb-upload_0:1134335 [internal_api.py:upload_file():2765] upload_file exception https://storage.googleapis.com/wandb-production.appspot.com/dynamic_x/bert_pytorch/jomc1iuf/wandb-metadata.json?Expires=1706688636&GoogleAccessId=gorilla-files-url-signer-man%40wandb-production.iam.gserviceaccount.com&Signature=vqMRnHJotxH%2BLQdQMnF%2FUEG8Q6OLuZGZfMxalY%2FUnvEM%2Be8ZyMBnFDWuHSTfqOP7Pc69TyNGv0JgkpsClhvPAOakvmdu3qmO%2FdMTYx7MsVtQXm1uaTgAUHKXfGVYRGzX9azkKZ0%2BKwudrkvH7EdBXfilA6u8o670q%2FJ1FhvzKDDw%2FoXnoX36K76PI7uhlnPHE8WjKkYY%2FyGiq7WsA%2BStW4O6FJKFdx47Ho0dU6x5DJjnJKGZY3RjFc3njJGPCbv5ihnK9fMa%2ByElS0PvXjOCVqNBXK5eyNZsuN5E3cnvHSA9ov2kAxBLJ%2F0H%2BX0cOb714VK5eTKeQXMrGebJPG%2B3ow%3D%3D: HTTPSConnectionPool(host='storage.googleapis.com', port=443): Max retries exceeded with url: /wandb-production.appspot.com/dynamic_x/bert_pytorch/jomc1iuf/wandb-metadata.json?Expires=1706688636&GoogleAccessId=gorilla-files-url-signer-man%40wandb-production.iam.gserviceaccount.com&Signature=vqMRnHJotxH%2BLQdQMnF%2FUEG8Q6OLuZGZfMxalY%2FUnvEM%2Be8ZyMBnFDWuHSTfqOP7Pc69TyNGv0JgkpsClhvPAOakvmdu3qmO%2FdMTYx7MsVtQXm1uaTgAUHKXfGVYRGzX9azkKZ0%2BKwudrkvH7EdBXfilA6u8o670q%2FJ1FhvzKDDw%2FoXnoX36K76PI7uhlnPHE8WjKkYY%2FyGiq7WsA%2BStW4O6FJKFdx47Ho0dU6x5DJjnJKGZY3RjFc3njJGPCbv5ihnK9fMa%2ByElS0PvXjOCVqNBXK5eyNZsuN5E3cnvHSA9ov2kAxBLJ%2F0H%2BX0cOb714VK5eTKeQXMrGebJPG%2B3ow%3D%3D (Caused by NewConnectionError('<urllib3.connection.HTTPSConnection object at 0x7f4a1c49c3d0>: Failed to establish a new connection: [Errno 111] Connection refused'))
2024-01-30 16:10:44,250 ERROR   wandb-upload_0:1134335 [internal_api.py:upload_file():2767] upload_file request headers: {'User-Agent': 'python-requests/2.23.0', 'Accept-Encoding': 'gzip, deflate', 'Accept': '*/*', 'Connection': 'keep-alive', 'Content-Length': '15548'}
2024-01-30 16:10:44,250 ERROR   wandb-upload_0:1134335 [internal_api.py:upload_file():2769] upload_file response body: 
2024-01-30 16:10:44,863 INFO    Thread-12 :1134335 [dir_watcher.py:_on_file_modified():288] file/dir modified: /home/yanxindong/mkor/bert/wandb/run-20240130_161012-jomc1iuf/files/config.yaml
2024-01-30 16:10:49,753 DEBUG   HandlerThread:1134335 [handler.py:handle_request():146] handle_request: status_report
2024-01-30 16:10:51,003 DEBUG   HandlerThread:1134335 [handler.py:handle_request():146] handle_request: stop_status
2024-01-30 16:10:51,003 DEBUG   SenderThread:1134335 [sender.py:send_request():409] send_request: stop_status
2024-01-30 16:10:51,045 DEBUG   HandlerThread:1134335 [handler.py:handle_request():146] handle_request: internal_messages
2024-01-30 16:10:52,412 ERROR   wandb-upload_0:1134335 [internal_api.py:upload_file():2765] upload_file exception https://storage.googleapis.com/wandb-production.appspot.com/dynamic_x/bert_pytorch/jomc1iuf/wandb-metadata.json?Expires=1706688636&GoogleAccessId=gorilla-files-url-signer-man%40wandb-production.iam.gserviceaccount.com&Signature=vqMRnHJotxH%2BLQdQMnF%2FUEG8Q6OLuZGZfMxalY%2FUnvEM%2Be8ZyMBnFDWuHSTfqOP7Pc69TyNGv0JgkpsClhvPAOakvmdu3qmO%2FdMTYx7MsVtQXm1uaTgAUHKXfGVYRGzX9azkKZ0%2BKwudrkvH7EdBXfilA6u8o670q%2FJ1FhvzKDDw%2FoXnoX36K76PI7uhlnPHE8WjKkYY%2FyGiq7WsA%2BStW4O6FJKFdx47Ho0dU6x5DJjnJKGZY3RjFc3njJGPCbv5ihnK9fMa%2ByElS0PvXjOCVqNBXK5eyNZsuN5E3cnvHSA9ov2kAxBLJ%2F0H%2BX0cOb714VK5eTKeQXMrGebJPG%2B3ow%3D%3D: HTTPSConnectionPool(host='storage.googleapis.com', port=443): Max retries exceeded with url: /wandb-production.appspot.com/dynamic_x/bert_pytorch/jomc1iuf/wandb-metadata.json?Expires=1706688636&GoogleAccessId=gorilla-files-url-signer-man%40wandb-production.iam.gserviceaccount.com&Signature=vqMRnHJotxH%2BLQdQMnF%2FUEG8Q6OLuZGZfMxalY%2FUnvEM%2Be8ZyMBnFDWuHSTfqOP7Pc69TyNGv0JgkpsClhvPAOakvmdu3qmO%2FdMTYx7MsVtQXm1uaTgAUHKXfGVYRGzX9azkKZ0%2BKwudrkvH7EdBXfilA6u8o670q%2FJ1FhvzKDDw%2FoXnoX36K76PI7uhlnPHE8WjKkYY%2FyGiq7WsA%2BStW4O6FJKFdx47Ho0dU6x5DJjnJKGZY3RjFc3njJGPCbv5ihnK9fMa%2ByElS0PvXjOCVqNBXK5eyNZsuN5E3cnvHSA9ov2kAxBLJ%2F0H%2BX0cOb714VK5eTKeQXMrGebJPG%2B3ow%3D%3D (Caused by NewConnectionError('<urllib3.connection.HTTPSConnection object at 0x7f4a1c49c970>: Failed to establish a new connection: [Errno 111] Connection refused'))
2024-01-30 16:10:52,412 ERROR   wandb-upload_0:1134335 [internal_api.py:upload_file():2767] upload_file request headers: {'User-Agent': 'python-requests/2.23.0', 'Accept-Encoding': 'gzip, deflate', 'Accept': '*/*', 'Connection': 'keep-alive', 'Content-Length': '15548'}
2024-01-30 16:10:52,412 ERROR   wandb-upload_0:1134335 [internal_api.py:upload_file():2769] upload_file response body: 
2024-01-30 16:10:55,502 DEBUG   HandlerThread:1134335 [handler.py:handle_request():146] handle_request: status_report
2024-01-30 16:11:00,502 DEBUG   HandlerThread:1134335 [handler.py:handle_request():146] handle_request: status_report
2024-01-30 16:11:05,502 DEBUG   HandlerThread:1134335 [handler.py:handle_request():146] handle_request: status_report
2024-01-30 16:11:06,001 DEBUG   HandlerThread:1134335 [handler.py:handle_request():146] handle_request: stop_status
2024-01-30 16:11:06,002 DEBUG   SenderThread:1134335 [sender.py:send_request():409] send_request: stop_status
2024-01-30 16:11:06,045 DEBUG   HandlerThread:1134335 [handler.py:handle_request():146] handle_request: internal_messages
2024-01-30 16:11:11,284 DEBUG   HandlerThread:1134335 [handler.py:handle_request():146] handle_request: status_report
2024-01-30 16:11:11,579 ERROR   wandb-upload_0:1134335 [internal_api.py:upload_file():2765] upload_file exception https://storage.googleapis.com/wandb-production.appspot.com/dynamic_x/bert_pytorch/jomc1iuf/wandb-metadata.json?Expires=1706688636&GoogleAccessId=gorilla-files-url-signer-man%40wandb-production.iam.gserviceaccount.com&Signature=vqMRnHJotxH%2BLQdQMnF%2FUEG8Q6OLuZGZfMxalY%2FUnvEM%2Be8ZyMBnFDWuHSTfqOP7Pc69TyNGv0JgkpsClhvPAOakvmdu3qmO%2FdMTYx7MsVtQXm1uaTgAUHKXfGVYRGzX9azkKZ0%2BKwudrkvH7EdBXfilA6u8o670q%2FJ1FhvzKDDw%2FoXnoX36K76PI7uhlnPHE8WjKkYY%2FyGiq7WsA%2BStW4O6FJKFdx47Ho0dU6x5DJjnJKGZY3RjFc3njJGPCbv5ihnK9fMa%2ByElS0PvXjOCVqNBXK5eyNZsuN5E3cnvHSA9ov2kAxBLJ%2F0H%2BX0cOb714VK5eTKeQXMrGebJPG%2B3ow%3D%3D: HTTPSConnectionPool(host='storage.googleapis.com', port=443): Max retries exceeded with url: /wandb-production.appspot.com/dynamic_x/bert_pytorch/jomc1iuf/wandb-metadata.json?Expires=1706688636&GoogleAccessId=gorilla-files-url-signer-man%40wandb-production.iam.gserviceaccount.com&Signature=vqMRnHJotxH%2BLQdQMnF%2FUEG8Q6OLuZGZfMxalY%2FUnvEM%2Be8ZyMBnFDWuHSTfqOP7Pc69TyNGv0JgkpsClhvPAOakvmdu3qmO%2FdMTYx7MsVtQXm1uaTgAUHKXfGVYRGzX9azkKZ0%2BKwudrkvH7EdBXfilA6u8o670q%2FJ1FhvzKDDw%2FoXnoX36K76PI7uhlnPHE8WjKkYY%2FyGiq7WsA%2BStW4O6FJKFdx47Ho0dU6x5DJjnJKGZY3RjFc3njJGPCbv5ihnK9fMa%2ByElS0PvXjOCVqNBXK5eyNZsuN5E3cnvHSA9ov2kAxBLJ%2F0H%2BX0cOb714VK5eTKeQXMrGebJPG%2B3ow%3D%3D (Caused by NewConnectionError('<urllib3.connection.HTTPSConnection object at 0x7f4a1c3cea30>: Failed to establish a new connection: [Errno 111] Connection refused'))
2024-01-30 16:11:11,579 ERROR   wandb-upload_0:1134335 [internal_api.py:upload_file():2767] upload_file request headers: {'User-Agent': 'python-requests/2.23.0', 'Accept-Encoding': 'gzip, deflate', 'Accept': '*/*', 'Connection': 'keep-alive', 'Content-Length': '15548'}
2024-01-30 16:11:11,579 ERROR   wandb-upload_0:1134335 [internal_api.py:upload_file():2769] upload_file response body: 
2024-01-30 16:11:15,039 DEBUG   SystemMonitor:1134335 [system_monitor.py:_start():172] Starting system metrics aggregation loop
2024-01-30 16:11:15,043 DEBUG   SenderThread:1134335 [sender.py:send():382] send: stats
2024-01-30 16:11:17,044 DEBUG   HandlerThread:1134335 [handler.py:handle_request():146] handle_request: status_report
2024-01-30 16:11:21,002 DEBUG   HandlerThread:1134335 [handler.py:handle_request():146] handle_request: stop_status
2024-01-30 16:11:21,002 DEBUG   SenderThread:1134335 [sender.py:send_request():409] send_request: stop_status
2024-01-30 16:11:21,065 DEBUG   HandlerThread:1134335 [handler.py:handle_request():146] handle_request: internal_messages
2024-01-30 16:11:22,330 DEBUG   HandlerThread:1134335 [handler.py:handle_request():146] handle_request: status_report
2024-01-30 16:11:27,338 DEBUG   HandlerThread:1134335 [handler.py:handle_request():146] handle_request: status_report
2024-01-30 16:11:32,409 DEBUG   HandlerThread:1134335 [handler.py:handle_request():146] handle_request: status_report
2024-01-30 16:11:36,002 DEBUG   HandlerThread:1134335 [handler.py:handle_request():146] handle_request: stop_status
2024-01-30 16:11:36,002 DEBUG   SenderThread:1134335 [sender.py:send_request():409] send_request: stop_status
2024-01-30 16:11:36,045 DEBUG   HandlerThread:1134335 [handler.py:handle_request():146] handle_request: internal_messages
2024-01-30 16:11:38,286 DEBUG   HandlerThread:1134335 [handler.py:handle_request():146] handle_request: status_report
2024-01-30 16:11:43,287 DEBUG   HandlerThread:1134335 [handler.py:handle_request():146] handle_request: status_report
2024-01-30 16:11:44,172 ERROR   wandb-upload_0:1134335 [internal_api.py:upload_file():2765] upload_file exception https://storage.googleapis.com/wandb-production.appspot.com/dynamic_x/bert_pytorch/jomc1iuf/wandb-metadata.json?Expires=1706688636&GoogleAccessId=gorilla-files-url-signer-man%40wandb-production.iam.gserviceaccount.com&Signature=vqMRnHJotxH%2BLQdQMnF%2FUEG8Q6OLuZGZfMxalY%2FUnvEM%2Be8ZyMBnFDWuHSTfqOP7Pc69TyNGv0JgkpsClhvPAOakvmdu3qmO%2FdMTYx7MsVtQXm1uaTgAUHKXfGVYRGzX9azkKZ0%2BKwudrkvH7EdBXfilA6u8o670q%2FJ1FhvzKDDw%2FoXnoX36K76PI7uhlnPHE8WjKkYY%2FyGiq7WsA%2BStW4O6FJKFdx47Ho0dU6x5DJjnJKGZY3RjFc3njJGPCbv5ihnK9fMa%2ByElS0PvXjOCVqNBXK5eyNZsuN5E3cnvHSA9ov2kAxBLJ%2F0H%2BX0cOb714VK5eTKeQXMrGebJPG%2B3ow%3D%3D: HTTPSConnectionPool(host='storage.googleapis.com', port=443): Max retries exceeded with url: /wandb-production.appspot.com/dynamic_x/bert_pytorch/jomc1iuf/wandb-metadata.json?Expires=1706688636&GoogleAccessId=gorilla-files-url-signer-man%40wandb-production.iam.gserviceaccount.com&Signature=vqMRnHJotxH%2BLQdQMnF%2FUEG8Q6OLuZGZfMxalY%2FUnvEM%2Be8ZyMBnFDWuHSTfqOP7Pc69TyNGv0JgkpsClhvPAOakvmdu3qmO%2FdMTYx7MsVtQXm1uaTgAUHKXfGVYRGzX9azkKZ0%2BKwudrkvH7EdBXfilA6u8o670q%2FJ1FhvzKDDw%2FoXnoX36K76PI7uhlnPHE8WjKkYY%2FyGiq7WsA%2BStW4O6FJKFdx47Ho0dU6x5DJjnJKGZY3RjFc3njJGPCbv5ihnK9fMa%2ByElS0PvXjOCVqNBXK5eyNZsuN5E3cnvHSA9ov2kAxBLJ%2F0H%2BX0cOb714VK5eTKeQXMrGebJPG%2B3ow%3D%3D (Caused by NewConnectionError('<urllib3.connection.HTTPSConnection object at 0x7f4a1c3cedc0>: Failed to establish a new connection: [Errno 101] Network is unreachable'))
2024-01-30 16:11:44,173 ERROR   wandb-upload_0:1134335 [internal_api.py:upload_file():2767] upload_file request headers: {'User-Agent': 'python-requests/2.23.0', 'Accept-Encoding': 'gzip, deflate', 'Accept': '*/*', 'Connection': 'keep-alive', 'Content-Length': '15548'}
2024-01-30 16:11:44,173 ERROR   wandb-upload_0:1134335 [internal_api.py:upload_file():2769] upload_file response body: 
2024-01-30 16:11:45,046 DEBUG   SenderThread:1134335 [sender.py:send():382] send: stats
2024-01-30 16:11:49,048 DEBUG   HandlerThread:1134335 [handler.py:handle_request():146] handle_request: status_report
2024-01-30 16:11:51,002 DEBUG   HandlerThread:1134335 [handler.py:handle_request():146] handle_request: stop_status
2024-01-30 16:11:51,002 DEBUG   SenderThread:1134335 [sender.py:send_request():409] send_request: stop_status
2024-01-30 16:11:51,045 DEBUG   HandlerThread:1134335 [handler.py:handle_request():146] handle_request: internal_messages
2024-01-30 16:11:54,373 DEBUG   HandlerThread:1134335 [handler.py:handle_request():146] handle_request: status_report
2024-01-30 16:11:55,997 INFO    Thread-12 :1134335 [dir_watcher.py:_on_file_created():271] file/dir created: /home/yanxindong/mkor/bert/wandb/run-20240130_161012-jomc1iuf/files/output.log
2024-01-30 16:11:57,997 INFO    Thread-12 :1134335 [dir_watcher.py:_on_file_modified():288] file/dir modified: /home/yanxindong/mkor/bert/wandb/run-20240130_161012-jomc1iuf/files/output.log
2024-01-30 16:12:00,242 DEBUG   HandlerThread:1134335 [handler.py:handle_request():146] handle_request: status_report
2024-01-30 16:12:05,242 DEBUG   HandlerThread:1134335 [handler.py:handle_request():146] handle_request: status_report
2024-01-30 16:12:07,240 DEBUG   HandlerThread:1134335 [handler.py:handle_request():146] handle_request: stop_status
2024-01-30 16:12:07,240 DEBUG   SenderThread:1134335 [sender.py:send_request():409] send_request: stop_status
2024-01-30 16:12:07,243 DEBUG   HandlerThread:1134335 [handler.py:handle_request():146] handle_request: internal_messages
2024-01-30 16:12:10,578 DEBUG   HandlerThread:1134335 [handler.py:handle_request():146] handle_request: status_report
2024-01-30 16:12:15,049 DEBUG   SenderThread:1134335 [sender.py:send():382] send: stats
2024-01-30 16:12:16,050 DEBUG   HandlerThread:1134335 [handler.py:handle_request():146] handle_request: status_report
2024-01-30 16:12:21,170 DEBUG   HandlerThread:1134335 [handler.py:handle_request():146] handle_request: status_report
2024-01-30 16:12:22,239 DEBUG   HandlerThread:1134335 [handler.py:handle_request():146] handle_request: stop_status
2024-01-30 16:12:22,240 DEBUG   SenderThread:1134335 [sender.py:send_request():409] send_request: stop_status
2024-01-30 16:12:26,725 DEBUG   HandlerThread:1134335 [handler.py:handle_request():146] handle_request: status_report
2024-01-30 16:12:31,812 DEBUG   HandlerThread:1134335 [handler.py:handle_request():146] handle_request: status_report
2024-01-30 16:12:36,906 DEBUG   HandlerThread:1134335 [handler.py:handle_request():146] handle_request: status_report
2024-01-30 16:12:37,240 DEBUG   HandlerThread:1134335 [handler.py:handle_request():146] handle_request: stop_status
2024-01-30 16:12:37,240 DEBUG   SenderThread:1134335 [sender.py:send_request():409] send_request: stop_status
2024-01-30 16:12:37,243 DEBUG   HandlerThread:1134335 [handler.py:handle_request():146] handle_request: internal_messages
2024-01-30 16:12:42,617 DEBUG   HandlerThread:1134335 [handler.py:handle_request():146] handle_request: status_report
2024-01-30 16:12:45,052 DEBUG   SenderThread:1134335 [sender.py:send():382] send: stats
2024-01-30 16:12:48,053 DEBUG   HandlerThread:1134335 [handler.py:handle_request():146] handle_request: status_report
2024-01-30 16:12:52,241 DEBUG   HandlerThread:1134335 [handler.py:handle_request():146] handle_request: stop_status
2024-01-30 16:12:52,242 DEBUG   SenderThread:1134335 [sender.py:send_request():409] send_request: stop_status
2024-01-30 16:12:52,281 DEBUG   HandlerThread:1134335 [handler.py:handle_request():146] handle_request: internal_messages
2024-01-30 16:12:53,614 DEBUG   HandlerThread:1134335 [handler.py:handle_request():146] handle_request: status_report
2024-01-30 16:12:54,732 ERROR   wandb-upload_0:1134335 [internal_api.py:upload_file():2765] upload_file exception https://storage.googleapis.com/wandb-production.appspot.com/dynamic_x/bert_pytorch/jomc1iuf/wandb-metadata.json?Expires=1706688636&GoogleAccessId=gorilla-files-url-signer-man%40wandb-production.iam.gserviceaccount.com&Signature=vqMRnHJotxH%2BLQdQMnF%2FUEG8Q6OLuZGZfMxalY%2FUnvEM%2Be8ZyMBnFDWuHSTfqOP7Pc69TyNGv0JgkpsClhvPAOakvmdu3qmO%2FdMTYx7MsVtQXm1uaTgAUHKXfGVYRGzX9azkKZ0%2BKwudrkvH7EdBXfilA6u8o670q%2FJ1FhvzKDDw%2FoXnoX36K76PI7uhlnPHE8WjKkYY%2FyGiq7WsA%2BStW4O6FJKFdx47Ho0dU6x5DJjnJKGZY3RjFc3njJGPCbv5ihnK9fMa%2ByElS0PvXjOCVqNBXK5eyNZsuN5E3cnvHSA9ov2kAxBLJ%2F0H%2BX0cOb714VK5eTKeQXMrGebJPG%2B3ow%3D%3D: HTTPSConnectionPool(host='storage.googleapis.com', port=443): Max retries exceeded with url: /wandb-production.appspot.com/dynamic_x/bert_pytorch/jomc1iuf/wandb-metadata.json?Expires=1706688636&GoogleAccessId=gorilla-files-url-signer-man%40wandb-production.iam.gserviceaccount.com&Signature=vqMRnHJotxH%2BLQdQMnF%2FUEG8Q6OLuZGZfMxalY%2FUnvEM%2Be8ZyMBnFDWuHSTfqOP7Pc69TyNGv0JgkpsClhvPAOakvmdu3qmO%2FdMTYx7MsVtQXm1uaTgAUHKXfGVYRGzX9azkKZ0%2BKwudrkvH7EdBXfilA6u8o670q%2FJ1FhvzKDDw%2FoXnoX36K76PI7uhlnPHE8WjKkYY%2FyGiq7WsA%2BStW4O6FJKFdx47Ho0dU6x5DJjnJKGZY3RjFc3njJGPCbv5ihnK9fMa%2ByElS0PvXjOCVqNBXK5eyNZsuN5E3cnvHSA9ov2kAxBLJ%2F0H%2BX0cOb714VK5eTKeQXMrGebJPG%2B3ow%3D%3D (Caused by NewConnectionError('<urllib3.connection.HTTPSConnection object at 0x7f4a1c3c46a0>: Failed to establish a new connection: [Errno 101] Network is unreachable'))
2024-01-30 16:12:54,732 ERROR   wandb-upload_0:1134335 [internal_api.py:upload_file():2767] upload_file request headers: {'User-Agent': 'python-requests/2.23.0', 'Accept-Encoding': 'gzip, deflate', 'Accept': '*/*', 'Connection': 'keep-alive', 'Content-Length': '15548'}
2024-01-30 16:12:54,733 ERROR   wandb-upload_0:1134335 [internal_api.py:upload_file():2769] upload_file response body: 
2024-01-30 16:12:58,616 DEBUG   HandlerThread:1134335 [handler.py:handle_request():146] handle_request: status_report
2024-01-30 16:13:03,623 DEBUG   HandlerThread:1134335 [handler.py:handle_request():146] handle_request: status_report
2024-01-30 16:13:07,241 DEBUG   HandlerThread:1134335 [handler.py:handle_request():146] handle_request: stop_status
2024-01-30 16:13:07,242 DEBUG   SenderThread:1134335 [sender.py:send_request():409] send_request: stop_status
2024-01-30 16:13:07,285 DEBUG   HandlerThread:1134335 [handler.py:handle_request():146] handle_request: internal_messages
2024-01-30 16:13:09,532 DEBUG   HandlerThread:1134335 [handler.py:handle_request():146] handle_request: status_report
2024-01-30 16:13:14,533 DEBUG   HandlerThread:1134335 [handler.py:handle_request():146] handle_request: status_report
2024-01-30 16:13:15,054 DEBUG   SenderThread:1134335 [sender.py:send():382] send: stats
2024-01-30 16:13:20,149 DEBUG   HandlerThread:1134335 [handler.py:handle_request():146] handle_request: status_report
2024-01-30 16:13:22,242 DEBUG   HandlerThread:1134335 [handler.py:handle_request():146] handle_request: stop_status
2024-01-30 16:13:22,242 DEBUG   SenderThread:1134335 [sender.py:send_request():409] send_request: stop_status
2024-01-30 16:13:22,285 DEBUG   HandlerThread:1134335 [handler.py:handle_request():146] handle_request: internal_messages
2024-01-30 16:13:25,547 DEBUG   HandlerThread:1134335 [handler.py:handle_request():146] handle_request: status_report
2024-01-30 16:13:30,750 DEBUG   HandlerThread:1134335 [handler.py:handle_request():146] handle_request: status_report
2024-01-30 16:13:35,920 DEBUG   HandlerThread:1134335 [handler.py:handle_request():146] handle_request: status_report
2024-01-30 16:13:37,295 DEBUG   HandlerThread:1134335 [handler.py:handle_request():146] handle_request: stop_status
2024-01-30 16:13:37,295 DEBUG   HandlerThread:1134335 [handler.py:handle_request():146] handle_request: internal_messages
2024-01-30 16:13:37,296 DEBUG   SenderThread:1134335 [sender.py:send_request():409] send_request: stop_status
2024-01-30 16:13:41,639 DEBUG   HandlerThread:1134335 [handler.py:handle_request():146] handle_request: status_report
2024-01-30 16:13:45,056 DEBUG   SenderThread:1134335 [sender.py:send():382] send: stats
2024-01-30 16:13:47,058 DEBUG   HandlerThread:1134335 [handler.py:handle_request():146] handle_request: status_report
2024-01-30 16:13:52,065 DEBUG   HandlerThread:1134335 [handler.py:handle_request():146] handle_request: status_report
2024-01-30 16:13:52,242 DEBUG   HandlerThread:1134335 [handler.py:handle_request():146] handle_request: stop_status
2024-01-30 16:13:52,243 DEBUG   SenderThread:1134335 [sender.py:send_request():409] send_request: stop_status
2024-01-30 16:13:52,285 DEBUG   HandlerThread:1134335 [handler.py:handle_request():146] handle_request: internal_messages
2024-01-30 16:13:57,581 DEBUG   HandlerThread:1134335 [handler.py:handle_request():146] handle_request: status_report
2024-01-30 16:14:02,582 DEBUG   HandlerThread:1134335 [handler.py:handle_request():146] handle_request: status_report
2024-01-30 16:14:07,242 DEBUG   HandlerThread:1134335 [handler.py:handle_request():146] handle_request: stop_status
2024-01-30 16:14:07,243 DEBUG   SenderThread:1134335 [sender.py:send_request():409] send_request: stop_status
2024-01-30 16:14:07,285 DEBUG   HandlerThread:1134335 [handler.py:handle_request():146] handle_request: internal_messages
2024-01-30 16:14:08,573 DEBUG   HandlerThread:1134335 [handler.py:handle_request():146] handle_request: status_report
2024-01-30 16:14:13,574 DEBUG   HandlerThread:1134335 [handler.py:handle_request():146] handle_request: status_report
2024-01-30 16:14:15,058 DEBUG   SenderThread:1134335 [sender.py:send():382] send: stats
2024-01-30 16:14:19,060 DEBUG   HandlerThread:1134335 [handler.py:handle_request():146] handle_request: status_report
2024-01-30 16:14:22,242 DEBUG   HandlerThread:1134335 [handler.py:handle_request():146] handle_request: stop_status
2024-01-30 16:14:22,243 DEBUG   SenderThread:1134335 [sender.py:send_request():409] send_request: stop_status
2024-01-30 16:14:22,349 DEBUG   HandlerThread:1134335 [handler.py:handle_request():146] handle_request: internal_messages
2024-01-30 16:14:24,652 DEBUG   HandlerThread:1134335 [handler.py:handle_request():146] handle_request: status_report
2024-01-30 16:14:29,753 DEBUG   HandlerThread:1134335 [handler.py:handle_request():146] handle_request: status_report
2024-01-30 16:14:34,774 DEBUG   HandlerThread:1134335 [handler.py:handle_request():146] handle_request: status_report
2024-01-30 16:14:37,243 DEBUG   HandlerThread:1134335 [handler.py:handle_request():146] handle_request: stop_status
2024-01-30 16:14:37,244 DEBUG   SenderThread:1134335 [sender.py:send_request():409] send_request: stop_status
2024-01-30 16:14:37,247 DEBUG   HandlerThread:1134335 [handler.py:handle_request():146] handle_request: internal_messages
2024-01-30 16:14:40,695 DEBUG   HandlerThread:1134335 [handler.py:handle_request():146] handle_request: status_report
2024-01-30 16:14:45,060 DEBUG   SenderThread:1134335 [sender.py:send():382] send: stats
2024-01-30 16:14:46,061 DEBUG   HandlerThread:1134335 [handler.py:handle_request():146] handle_request: status_report
2024-01-30 16:14:51,062 DEBUG   HandlerThread:1134335 [handler.py:handle_request():146] handle_request: status_report
2024-01-30 16:14:52,243 DEBUG   HandlerThread:1134335 [handler.py:handle_request():146] handle_request: stop_status
2024-01-30 16:14:52,244 DEBUG   SenderThread:1134335 [sender.py:send_request():409] send_request: stop_status
2024-01-30 16:14:52,285 DEBUG   HandlerThread:1134335 [handler.py:handle_request():146] handle_request: internal_messages
2024-01-30 16:14:56,539 DEBUG   HandlerThread:1134335 [handler.py:handle_request():146] handle_request: status_report
2024-01-30 16:15:01,539 DEBUG   HandlerThread:1134335 [handler.py:handle_request():146] handle_request: status_report
2024-01-30 16:15:06,540 DEBUG   HandlerThread:1134335 [handler.py:handle_request():146] handle_request: status_report
2024-01-30 16:15:07,243 DEBUG   HandlerThread:1134335 [handler.py:handle_request():146] handle_request: stop_status
2024-01-30 16:15:07,244 DEBUG   SenderThread:1134335 [sender.py:send_request():409] send_request: stop_status
2024-01-30 16:15:07,285 DEBUG   HandlerThread:1134335 [handler.py:handle_request():146] handle_request: internal_messages
2024-01-30 16:15:12,505 DEBUG   HandlerThread:1134335 [handler.py:handle_request():146] handle_request: status_report
2024-01-30 16:15:15,063 DEBUG   SenderThread:1134335 [sender.py:send():382] send: stats
2024-01-30 16:15:18,064 DEBUG   HandlerThread:1134335 [handler.py:handle_request():146] handle_request: status_report
2024-01-30 16:15:20,452 ERROR   wandb-upload_0:1134335 [internal_api.py:upload_file():2765] upload_file exception https://storage.googleapis.com/wandb-production.appspot.com/dynamic_x/bert_pytorch/jomc1iuf/wandb-metadata.json?Expires=1706688636&GoogleAccessId=gorilla-files-url-signer-man%40wandb-production.iam.gserviceaccount.com&Signature=vqMRnHJotxH%2BLQdQMnF%2FUEG8Q6OLuZGZfMxalY%2FUnvEM%2Be8ZyMBnFDWuHSTfqOP7Pc69TyNGv0JgkpsClhvPAOakvmdu3qmO%2FdMTYx7MsVtQXm1uaTgAUHKXfGVYRGzX9azkKZ0%2BKwudrkvH7EdBXfilA6u8o670q%2FJ1FhvzKDDw%2FoXnoX36K76PI7uhlnPHE8WjKkYY%2FyGiq7WsA%2BStW4O6FJKFdx47Ho0dU6x5DJjnJKGZY3RjFc3njJGPCbv5ihnK9fMa%2ByElS0PvXjOCVqNBXK5eyNZsuN5E3cnvHSA9ov2kAxBLJ%2F0H%2BX0cOb714VK5eTKeQXMrGebJPG%2B3ow%3D%3D: HTTPSConnectionPool(host='storage.googleapis.com', port=443): Max retries exceeded with url: /wandb-production.appspot.com/dynamic_x/bert_pytorch/jomc1iuf/wandb-metadata.json?Expires=1706688636&GoogleAccessId=gorilla-files-url-signer-man%40wandb-production.iam.gserviceaccount.com&Signature=vqMRnHJotxH%2BLQdQMnF%2FUEG8Q6OLuZGZfMxalY%2FUnvEM%2Be8ZyMBnFDWuHSTfqOP7Pc69TyNGv0JgkpsClhvPAOakvmdu3qmO%2FdMTYx7MsVtQXm1uaTgAUHKXfGVYRGzX9azkKZ0%2BKwudrkvH7EdBXfilA6u8o670q%2FJ1FhvzKDDw%2FoXnoX36K76PI7uhlnPHE8WjKkYY%2FyGiq7WsA%2BStW4O6FJKFdx47Ho0dU6x5DJjnJKGZY3RjFc3njJGPCbv5ihnK9fMa%2ByElS0PvXjOCVqNBXK5eyNZsuN5E3cnvHSA9ov2kAxBLJ%2F0H%2BX0cOb714VK5eTKeQXMrGebJPG%2B3ow%3D%3D (Caused by NewConnectionError('<urllib3.connection.HTTPSConnection object at 0x7f4a1c49c2b0>: Failed to establish a new connection: [Errno 101] Network is unreachable'))
2024-01-30 16:15:20,452 ERROR   wandb-upload_0:1134335 [internal_api.py:upload_file():2767] upload_file request headers: {'User-Agent': 'python-requests/2.23.0', 'Accept-Encoding': 'gzip, deflate', 'Accept': '*/*', 'Connection': 'keep-alive', 'Content-Length': '15548'}
2024-01-30 16:15:20,452 ERROR   wandb-upload_0:1134335 [internal_api.py:upload_file():2769] upload_file response body: 
2024-01-30 16:15:22,243 DEBUG   HandlerThread:1134335 [handler.py:handle_request():146] handle_request: stop_status
2024-01-30 16:15:22,244 DEBUG   SenderThread:1134335 [sender.py:send_request():409] send_request: stop_status
2024-01-30 16:15:22,285 DEBUG   HandlerThread:1134335 [handler.py:handle_request():146] handle_request: internal_messages
2024-01-30 16:15:23,629 DEBUG   HandlerThread:1134335 [handler.py:handle_request():146] handle_request: status_report
2024-01-30 16:15:28,717 DEBUG   HandlerThread:1134335 [handler.py:handle_request():146] handle_request: status_report
2024-01-30 16:15:33,789 DEBUG   HandlerThread:1134335 [handler.py:handle_request():146] handle_request: status_report
2024-01-30 16:15:37,244 DEBUG   HandlerThread:1134335 [handler.py:handle_request():146] handle_request: stop_status
2024-01-30 16:15:37,244 DEBUG   SenderThread:1134335 [sender.py:send_request():409] send_request: stop_status
2024-01-30 16:15:37,285 DEBUG   HandlerThread:1134335 [handler.py:handle_request():146] handle_request: internal_messages
2024-01-30 16:15:39,516 DEBUG   HandlerThread:1134335 [handler.py:handle_request():146] handle_request: status_report
2024-01-30 16:15:44,596 DEBUG   HandlerThread:1134335 [handler.py:handle_request():146] handle_request: status_report
2024-01-30 16:15:45,108 DEBUG   SenderThread:1134335 [sender.py:send():382] send: stats
2024-01-30 16:15:50,109 DEBUG   HandlerThread:1134335 [handler.py:handle_request():146] handle_request: status_report
2024-01-30 16:15:50,786 DEBUG   SenderThread:1134335 [sender.py:send():382] send: exit
2024-01-30 16:15:50,786 INFO    SenderThread:1134335 [sender.py:send_exit():589] handling exit code: 1
2024-01-30 16:15:50,786 INFO    SenderThread:1134335 [sender.py:send_exit():591] handling runtime: 335
2024-01-30 16:15:50,787 INFO    SenderThread:1134335 [sender.py:_save_file():1403] saving file wandb-summary.json with policy end
2024-01-30 16:15:50,787 INFO    SenderThread:1134335 [sender.py:send_exit():597] send defer
2024-01-30 16:15:50,787 DEBUG   HandlerThread:1134335 [handler.py:handle_request():146] handle_request: defer
2024-01-30 16:15:50,787 INFO    HandlerThread:1134335 [handler.py:handle_request_defer():172] handle defer: 0
2024-01-30 16:15:50,787 DEBUG   SenderThread:1134335 [sender.py:send_request():409] send_request: defer
2024-01-30 16:15:50,787 INFO    SenderThread:1134335 [sender.py:send_request_defer():613] handle sender defer: 0
2024-01-30 16:15:50,787 INFO    SenderThread:1134335 [sender.py:transition_state():617] send defer: 1
2024-01-30 16:15:50,787 DEBUG   HandlerThread:1134335 [handler.py:handle_request():146] handle_request: defer
2024-01-30 16:15:50,787 INFO    HandlerThread:1134335 [handler.py:handle_request_defer():172] handle defer: 1
2024-01-30 16:15:50,788 DEBUG   SenderThread:1134335 [sender.py:send_request():409] send_request: defer
2024-01-30 16:15:50,788 INFO    SenderThread:1134335 [sender.py:send_request_defer():613] handle sender defer: 1
2024-01-30 16:15:50,788 INFO    SenderThread:1134335 [sender.py:transition_state():617] send defer: 2
2024-01-30 16:15:50,788 DEBUG   HandlerThread:1134335 [handler.py:handle_request():146] handle_request: defer
2024-01-30 16:15:50,788 INFO    HandlerThread:1134335 [handler.py:handle_request_defer():172] handle defer: 2
2024-01-30 16:15:50,788 INFO    HandlerThread:1134335 [system_monitor.py:finish():203] Stopping system monitor
2024-01-30 16:15:50,788 DEBUG   SystemMonitor:1134335 [system_monitor.py:_start():179] Finished system metrics aggregation loop
2024-01-30 16:15:50,788 DEBUG   SystemMonitor:1134335 [system_monitor.py:_start():183] Publishing last batch of metrics
2024-01-30 16:15:50,798 INFO    HandlerThread:1134335 [interfaces.py:finish():202] Joined cpu monitor
2024-01-30 16:15:50,798 INFO    HandlerThread:1134335 [interfaces.py:finish():202] Joined disk monitor
2024-01-30 16:15:51,212 INFO    Thread-12 :1134335 [dir_watcher.py:_on_file_created():271] file/dir created: /home/yanxindong/mkor/bert/wandb/run-20240130_161012-jomc1iuf/files/wandb-summary.json
2024-01-30 16:15:53,218 INFO    Thread-12 :1134335 [dir_watcher.py:_on_file_modified():288] file/dir modified: /home/yanxindong/mkor/bert/wandb/run-20240130_161012-jomc1iuf/files/output.log
2024-01-30 16:16:08,264 INFO    HandlerThread:1134335 [interfaces.py:finish():202] Joined gpu monitor
2024-01-30 16:16:08,264 INFO    HandlerThread:1134335 [interfaces.py:finish():202] Joined memory monitor
2024-01-30 16:16:08,265 INFO    HandlerThread:1134335 [interfaces.py:finish():202] Joined network monitor
2024-01-30 16:16:08,265 DEBUG   HandlerThread:1134335 [handler.py:handle_request():146] handle_request: poll_exit
2024-01-30 16:16:08,265 DEBUG   HandlerThread:1134335 [handler.py:handle_request():146] handle_request: status_report
2024-01-30 16:16:08,265 DEBUG   HandlerThread:1134335 [handler.py:handle_request():146] handle_request: keepalive
2024-01-30 16:16:08,265 DEBUG   HandlerThread:1134335 [handler.py:handle_request():146] handle_request: status_report
2024-01-30 16:16:08,265 DEBUG   HandlerThread:1134335 [handler.py:handle_request():146] handle_request: keepalive
2024-01-30 16:16:08,265 DEBUG   HandlerThread:1134335 [handler.py:handle_request():146] handle_request: status_report
2024-01-30 16:16:08,265 DEBUG   HandlerThread:1134335 [handler.py:handle_request():146] handle_request: keepalive
2024-01-30 16:16:08,266 DEBUG   SenderThread:1134335 [sender.py:send_request():409] send_request: defer
2024-01-30 16:16:08,266 INFO    SenderThread:1134335 [sender.py:send_request_defer():613] handle sender defer: 2
2024-01-30 16:16:08,266 INFO    SenderThread:1134335 [sender.py:transition_state():617] send defer: 3
2024-01-30 16:16:08,266 DEBUG   SenderThread:1134335 [sender.py:send():382] send: stats
2024-01-30 16:16:08,267 DEBUG   SenderThread:1134335 [sender.py:send_request():409] send_request: poll_exit
2024-01-30 16:16:08,268 DEBUG   HandlerThread:1134335 [handler.py:handle_request():146] handle_request: defer
2024-01-30 16:16:08,268 INFO    HandlerThread:1134335 [handler.py:handle_request_defer():172] handle defer: 3
2024-01-30 16:16:08,268 DEBUG   SenderThread:1134335 [sender.py:send_request():409] send_request: defer
2024-01-30 16:16:08,268 INFO    SenderThread:1134335 [sender.py:send_request_defer():613] handle sender defer: 3
2024-01-30 16:16:08,268 INFO    SenderThread:1134335 [sender.py:transition_state():617] send defer: 4
2024-01-30 16:16:08,268 DEBUG   HandlerThread:1134335 [handler.py:handle_request():146] handle_request: defer
2024-01-30 16:16:08,268 INFO    HandlerThread:1134335 [handler.py:handle_request_defer():172] handle defer: 4
2024-01-30 16:16:08,268 DEBUG   SenderThread:1134335 [sender.py:send_request():409] send_request: defer
2024-01-30 16:16:08,268 INFO    SenderThread:1134335 [sender.py:send_request_defer():613] handle sender defer: 4
2024-01-30 16:16:08,268 INFO    SenderThread:1134335 [sender.py:transition_state():617] send defer: 5
2024-01-30 16:16:08,268 DEBUG   HandlerThread:1134335 [handler.py:handle_request():146] handle_request: defer
2024-01-30 16:16:08,268 INFO    HandlerThread:1134335 [handler.py:handle_request_defer():172] handle defer: 5
2024-01-30 16:16:08,269 DEBUG   SenderThread:1134335 [sender.py:send():382] send: summary
2024-01-30 16:16:08,269 INFO    SenderThread:1134335 [sender.py:_save_file():1403] saving file wandb-summary.json with policy end
2024-01-30 16:16:08,269 DEBUG   SenderThread:1134335 [sender.py:send_request():409] send_request: defer
2024-01-30 16:16:08,269 INFO    SenderThread:1134335 [sender.py:send_request_defer():613] handle sender defer: 5
2024-01-30 16:16:08,269 INFO    SenderThread:1134335 [sender.py:transition_state():617] send defer: 6
2024-01-30 16:16:08,269 DEBUG   HandlerThread:1134335 [handler.py:handle_request():146] handle_request: defer
2024-01-30 16:16:08,269 INFO    HandlerThread:1134335 [handler.py:handle_request_defer():172] handle defer: 6
2024-01-30 16:16:08,270 DEBUG   SenderThread:1134335 [sender.py:send_request():409] send_request: defer
2024-01-30 16:16:08,270 INFO    SenderThread:1134335 [sender.py:send_request_defer():613] handle sender defer: 6
2024-01-30 16:16:08,270 INFO    SenderThread:1134335 [sender.py:transition_state():617] send defer: 7
2024-01-30 16:16:08,270 DEBUG   HandlerThread:1134335 [handler.py:handle_request():146] handle_request: status_report
2024-01-30 16:16:08,270 DEBUG   HandlerThread:1134335 [handler.py:handle_request():146] handle_request: defer
2024-01-30 16:16:08,270 INFO    HandlerThread:1134335 [handler.py:handle_request_defer():172] handle defer: 7
2024-01-30 16:16:08,270 DEBUG   SenderThread:1134335 [sender.py:send_request():409] send_request: defer
2024-01-30 16:16:08,270 INFO    SenderThread:1134335 [sender.py:send_request_defer():613] handle sender defer: 7
2024-01-30 16:16:08,706 INFO    SenderThread:1134335 [sender.py:transition_state():617] send defer: 8
2024-01-30 16:16:08,706 DEBUG   HandlerThread:1134335 [handler.py:handle_request():146] handle_request: defer
2024-01-30 16:16:08,706 INFO    HandlerThread:1134335 [handler.py:handle_request_defer():172] handle defer: 8
2024-01-30 16:16:08,706 DEBUG   SenderThread:1134335 [sender.py:send_request():409] send_request: defer
2024-01-30 16:16:08,706 INFO    SenderThread:1134335 [sender.py:send_request_defer():613] handle sender defer: 8
2024-01-30 16:16:08,706 INFO    SenderThread:1134335 [job_builder.py:build():296] Attempting to build job artifact
2024-01-30 16:16:08,707 INFO    SenderThread:1134335 [job_builder.py:_get_source_type():426] is repo sourced job
2024-01-30 16:16:08,868 DEBUG   HandlerThread:1134335 [handler.py:handle_request():146] handle_request: poll_exit
2024-01-30 16:16:08,871 INFO    SenderThread:1134335 [job_builder.py:build():402] adding wandb-job metadata file
2024-01-30 16:16:08,874 INFO    SenderThread:1134335 [sender.py:transition_state():617] send defer: 9
2024-01-30 16:16:08,875 DEBUG   SenderThread:1134335 [sender.py:send_request():409] send_request: poll_exit
2024-01-30 16:16:08,875 DEBUG   HandlerThread:1134335 [handler.py:handle_request():146] handle_request: defer
2024-01-30 16:16:08,875 INFO    HandlerThread:1134335 [handler.py:handle_request_defer():172] handle defer: 9
2024-01-30 16:16:08,875 DEBUG   SenderThread:1134335 [sender.py:send():382] send: artifact
2024-01-30 16:16:09,259 INFO    Thread-12 :1134335 [dir_watcher.py:_on_file_modified():288] file/dir modified: /home/yanxindong/mkor/bert/wandb/run-20240130_161012-jomc1iuf/files/output.log
2024-01-30 16:16:09,259 INFO    Thread-12 :1134335 [dir_watcher.py:_on_file_modified():288] file/dir modified: /home/yanxindong/mkor/bert/wandb/run-20240130_161012-jomc1iuf/files/wandb-summary.json
2024-01-30 16:16:09,868 DEBUG   HandlerThread:1134335 [handler.py:handle_request():146] handle_request: poll_exit
2024-01-30 16:16:10,899 ERROR   wandb-upload_1:1134335 [internal_api.py:upload_file():2765] upload_file exception https://storage.googleapis.com/wandb-artifacts-prod/wandb_artifacts/133981200/707680297/174a3d9bc61fec126cc7d5bdff5c6c5a?Expires=1706688970&GoogleAccessId=gorilla-files-url-signer-man%40wandb-production.iam.gserviceaccount.com&Signature=kuQL2vv4ZrJMNP8ScZYD%2F1hqehOOYHiCOdMHRR5RG2VDIeKWuqBNncAZbu8meTCvhMbIyz%2By%2FfAi0KXcah6iDUufB9mhZM0EFeR0V9vd3TpvG8s4dqIKBnhH%2FsCMXzfjuAgl3NWESXKwEFwTIi3EFmM27dEG8pzlQcFpMFGvs4IZiymQ%2FTmzqRn2mmEYZOdIMi35AR4nus1RoSMUq8dkKgHL49QckDgc5SUde4L4jsjg1o66To4vq4gyoFUzq3Vh74gLAALPE%2BH%2FPdT86TdHsW7rrwaR8YTveQi9%2F5h5aWu4b1a1qbU524NGBSKS9NVRItwl2fxaL88%2FT6EHKlKllg%3D%3D: HTTPSConnectionPool(host='storage.googleapis.com', port=443): Max retries exceeded with url: /wandb-artifacts-prod/wandb_artifacts/133981200/707680297/174a3d9bc61fec126cc7d5bdff5c6c5a?Expires=1706688970&GoogleAccessId=gorilla-files-url-signer-man%40wandb-production.iam.gserviceaccount.com&Signature=kuQL2vv4ZrJMNP8ScZYD%2F1hqehOOYHiCOdMHRR5RG2VDIeKWuqBNncAZbu8meTCvhMbIyz%2By%2FfAi0KXcah6iDUufB9mhZM0EFeR0V9vd3TpvG8s4dqIKBnhH%2FsCMXzfjuAgl3NWESXKwEFwTIi3EFmM27dEG8pzlQcFpMFGvs4IZiymQ%2FTmzqRn2mmEYZOdIMi35AR4nus1RoSMUq8dkKgHL49QckDgc5SUde4L4jsjg1o66To4vq4gyoFUzq3Vh74gLAALPE%2BH%2FPdT86TdHsW7rrwaR8YTveQi9%2F5h5aWu4b1a1qbU524NGBSKS9NVRItwl2fxaL88%2FT6EHKlKllg%3D%3D (Caused by NewConnectionError('<urllib3.connection.HTTPSConnection object at 0x7f4a1c3c4b50>: Failed to establish a new connection: [Errno 101] Network is unreachable'))
2024-01-30 16:16:10,900 ERROR   wandb-upload_1:1134335 [internal_api.py:upload_file():2767] upload_file request headers: {'User-Agent': 'python-requests/2.23.0', 'Accept-Encoding': 'gzip, deflate', 'Accept': '*/*', 'Connection': 'keep-alive', 'Content-MD5': 'F0o9m8Yf7BJsx9W9/1xsWg==', 'Content-Type': 'text/plain; charset=utf-8', 'Content-Length': '2179'}
2024-01-30 16:16:10,900 ERROR   wandb-upload_1:1134335 [internal_api.py:upload_file():2769] upload_file response body: 
2024-01-30 16:16:11,478 ERROR   wandb-upload_2:1134335 [internal_api.py:upload_file():2765] upload_file exception https://storage.googleapis.com/wandb-artifacts-prod/wandb_artifacts/133981200/707680297/6873c23a2381d1524249eb1a948a45a5?Expires=1706688971&GoogleAccessId=gorilla-files-url-signer-man%40wandb-production.iam.gserviceaccount.com&Signature=BaxYtObKuOKiS%2BvcMZU2Bezuyv9eS0Y2vXMmMFcDMFcl4y2oCR0lR9wGzAwOVoKLOd5hG0z1Mmmx7Rp3upmhGpwWr%2FXkHRKmwv%2FHZIPSEVOcWkI2g7C8aEaTdEYNC1N20ZkAnvj8JZKAIR8KMaK3YkCZAJivQjoKpHlXHjfCA8hUxBTQonlTiX0PFoiE%2BxauwWDyPN1jVf%2FK7GIhtcupjAHERrhBuO%2FN7djnw%2BgnY65zmfi0wv2y98ZwB5unjBxHRxpNo%2BrIuF9KM9Bu6xxjFDL%2FAUNoXlr3LuFr5xzvAWPILjDUZItXiiFWKZyqs1Liv%2BiGTgavm%2Foca%2B5QRSWhtQ%3D%3D: HTTPSConnectionPool(host='storage.googleapis.com', port=443): Max retries exceeded with url: /wandb-artifacts-prod/wandb_artifacts/133981200/707680297/6873c23a2381d1524249eb1a948a45a5?Expires=1706688971&GoogleAccessId=gorilla-files-url-signer-man%40wandb-production.iam.gserviceaccount.com&Signature=BaxYtObKuOKiS%2BvcMZU2Bezuyv9eS0Y2vXMmMFcDMFcl4y2oCR0lR9wGzAwOVoKLOd5hG0z1Mmmx7Rp3upmhGpwWr%2FXkHRKmwv%2FHZIPSEVOcWkI2g7C8aEaTdEYNC1N20ZkAnvj8JZKAIR8KMaK3YkCZAJivQjoKpHlXHjfCA8hUxBTQonlTiX0PFoiE%2BxauwWDyPN1jVf%2FK7GIhtcupjAHERrhBuO%2FN7djnw%2BgnY65zmfi0wv2y98ZwB5unjBxHRxpNo%2BrIuF9KM9Bu6xxjFDL%2FAUNoXlr3LuFr5xzvAWPILjDUZItXiiFWKZyqs1Liv%2BiGTgavm%2Foca%2B5QRSWhtQ%3D%3D (Caused by NewConnectionError('<urllib3.connection.HTTPSConnection object at 0x7f4a1c4865e0>: Failed to establish a new connection: [Errno 101] Network is unreachable'))
2024-01-30 16:16:11,478 ERROR   wandb-upload_2:1134335 [internal_api.py:upload_file():2767] upload_file request headers: {'User-Agent': 'python-requests/2.23.0', 'Accept-Encoding': 'gzip, deflate', 'Accept': '*/*', 'Connection': 'keep-alive', 'Content-MD5': 'aHPCOiOB0VJCSesalIpFpQ==', 'Content-Type': 'application/json', 'Content-Length': '609'}
2024-01-30 16:16:11,478 ERROR   wandb-upload_2:1134335 [internal_api.py:upload_file():2769] upload_file response body: 
2024-01-30 16:16:12,137 ERROR   wandb-upload_1:1134335 [internal_api.py:upload_file():2765] upload_file exception https://storage.googleapis.com/wandb-artifacts-prod/wandb_artifacts/133981200/707680297/174a3d9bc61fec126cc7d5bdff5c6c5a?Expires=1706688970&GoogleAccessId=gorilla-files-url-signer-man%40wandb-production.iam.gserviceaccount.com&Signature=kuQL2vv4ZrJMNP8ScZYD%2F1hqehOOYHiCOdMHRR5RG2VDIeKWuqBNncAZbu8meTCvhMbIyz%2By%2FfAi0KXcah6iDUufB9mhZM0EFeR0V9vd3TpvG8s4dqIKBnhH%2FsCMXzfjuAgl3NWESXKwEFwTIi3EFmM27dEG8pzlQcFpMFGvs4IZiymQ%2FTmzqRn2mmEYZOdIMi35AR4nus1RoSMUq8dkKgHL49QckDgc5SUde4L4jsjg1o66To4vq4gyoFUzq3Vh74gLAALPE%2BH%2FPdT86TdHsW7rrwaR8YTveQi9%2F5h5aWu4b1a1qbU524NGBSKS9NVRItwl2fxaL88%2FT6EHKlKllg%3D%3D: HTTPSConnectionPool(host='storage.googleapis.com', port=443): Max retries exceeded with url: /wandb-artifacts-prod/wandb_artifacts/133981200/707680297/174a3d9bc61fec126cc7d5bdff5c6c5a?Expires=1706688970&GoogleAccessId=gorilla-files-url-signer-man%40wandb-production.iam.gserviceaccount.com&Signature=kuQL2vv4ZrJMNP8ScZYD%2F1hqehOOYHiCOdMHRR5RG2VDIeKWuqBNncAZbu8meTCvhMbIyz%2By%2FfAi0KXcah6iDUufB9mhZM0EFeR0V9vd3TpvG8s4dqIKBnhH%2FsCMXzfjuAgl3NWESXKwEFwTIi3EFmM27dEG8pzlQcFpMFGvs4IZiymQ%2FTmzqRn2mmEYZOdIMi35AR4nus1RoSMUq8dkKgHL49QckDgc5SUde4L4jsjg1o66To4vq4gyoFUzq3Vh74gLAALPE%2BH%2FPdT86TdHsW7rrwaR8YTveQi9%2F5h5aWu4b1a1qbU524NGBSKS9NVRItwl2fxaL88%2FT6EHKlKllg%3D%3D (Caused by NewConnectionError('<urllib3.connection.HTTPSConnection object at 0x7f4a1c3ce370>: Failed to establish a new connection: [Errno 101] Network is unreachable'))
2024-01-30 16:16:12,137 ERROR   wandb-upload_1:1134335 [internal_api.py:upload_file():2767] upload_file request headers: {'User-Agent': 'python-requests/2.23.0', 'Accept-Encoding': 'gzip, deflate', 'Accept': '*/*', 'Connection': 'keep-alive', 'Content-MD5': 'F0o9m8Yf7BJsx9W9/1xsWg==', 'Content-Type': 'text/plain; charset=utf-8', 'Content-Length': '2179'}
2024-01-30 16:16:12,137 ERROR   wandb-upload_1:1134335 [internal_api.py:upload_file():2769] upload_file response body: 
2024-01-30 16:16:12,692 ERROR   wandb-upload_2:1134335 [internal_api.py:upload_file():2765] upload_file exception https://storage.googleapis.com/wandb-artifacts-prod/wandb_artifacts/133981200/707680297/6873c23a2381d1524249eb1a948a45a5?Expires=1706688971&GoogleAccessId=gorilla-files-url-signer-man%40wandb-production.iam.gserviceaccount.com&Signature=BaxYtObKuOKiS%2BvcMZU2Bezuyv9eS0Y2vXMmMFcDMFcl4y2oCR0lR9wGzAwOVoKLOd5hG0z1Mmmx7Rp3upmhGpwWr%2FXkHRKmwv%2FHZIPSEVOcWkI2g7C8aEaTdEYNC1N20ZkAnvj8JZKAIR8KMaK3YkCZAJivQjoKpHlXHjfCA8hUxBTQonlTiX0PFoiE%2BxauwWDyPN1jVf%2FK7GIhtcupjAHERrhBuO%2FN7djnw%2BgnY65zmfi0wv2y98ZwB5unjBxHRxpNo%2BrIuF9KM9Bu6xxjFDL%2FAUNoXlr3LuFr5xzvAWPILjDUZItXiiFWKZyqs1Liv%2BiGTgavm%2Foca%2B5QRSWhtQ%3D%3D: HTTPSConnectionPool(host='storage.googleapis.com', port=443): Max retries exceeded with url: /wandb-artifacts-prod/wandb_artifacts/133981200/707680297/6873c23a2381d1524249eb1a948a45a5?Expires=1706688971&GoogleAccessId=gorilla-files-url-signer-man%40wandb-production.iam.gserviceaccount.com&Signature=BaxYtObKuOKiS%2BvcMZU2Bezuyv9eS0Y2vXMmMFcDMFcl4y2oCR0lR9wGzAwOVoKLOd5hG0z1Mmmx7Rp3upmhGpwWr%2FXkHRKmwv%2FHZIPSEVOcWkI2g7C8aEaTdEYNC1N20ZkAnvj8JZKAIR8KMaK3YkCZAJivQjoKpHlXHjfCA8hUxBTQonlTiX0PFoiE%2BxauwWDyPN1jVf%2FK7GIhtcupjAHERrhBuO%2FN7djnw%2BgnY65zmfi0wv2y98ZwB5unjBxHRxpNo%2BrIuF9KM9Bu6xxjFDL%2FAUNoXlr3LuFr5xzvAWPILjDUZItXiiFWKZyqs1Liv%2BiGTgavm%2Foca%2B5QRSWhtQ%3D%3D (Caused by NewConnectionError('<urllib3.connection.HTTPSConnection object at 0x7f4a1c30a970>: Failed to establish a new connection: [Errno 101] Network is unreachable'))
2024-01-30 16:16:12,692 ERROR   wandb-upload_2:1134335 [internal_api.py:upload_file():2767] upload_file request headers: {'User-Agent': 'python-requests/2.23.0', 'Accept-Encoding': 'gzip, deflate', 'Accept': '*/*', 'Connection': 'keep-alive', 'Content-MD5': 'aHPCOiOB0VJCSesalIpFpQ==', 'Content-Type': 'application/json', 'Content-Length': '609'}
2024-01-30 16:16:12,692 ERROR   wandb-upload_2:1134335 [internal_api.py:upload_file():2769] upload_file response body: 
2024-01-30 16:16:12,692 INFO    wandb-upload_2:1134335 [retry.py:__call__():172] Retry attempt failed:
Traceback (most recent call last):
  File "/home/yanxindong/anaconda/envs/eva/lib/python3.8/site-packages/urllib3/connection.py", line 159, in _new_conn
    conn = connection.create_connection(
  File "/home/yanxindong/anaconda/envs/eva/lib/python3.8/site-packages/urllib3/util/connection.py", line 84, in create_connection
    raise err
  File "/home/yanxindong/anaconda/envs/eva/lib/python3.8/site-packages/urllib3/util/connection.py", line 74, in create_connection
    sock.connect(sa)
OSError: [Errno 101] Network is unreachable

During handling of the above exception, another exception occurred:

Traceback (most recent call last):
  File "/home/yanxindong/anaconda/envs/eva/lib/python3.8/site-packages/urllib3/connectionpool.py", line 670, in urlopen
    httplib_response = self._make_request(
  File "/home/yanxindong/anaconda/envs/eva/lib/python3.8/site-packages/urllib3/connectionpool.py", line 381, in _make_request
    self._validate_conn(conn)
  File "/home/yanxindong/anaconda/envs/eva/lib/python3.8/site-packages/urllib3/connectionpool.py", line 978, in _validate_conn
    conn.connect()
  File "/home/yanxindong/anaconda/envs/eva/lib/python3.8/site-packages/urllib3/connection.py", line 309, in connect
    conn = self._new_conn()
  File "/home/yanxindong/anaconda/envs/eva/lib/python3.8/site-packages/urllib3/connection.py", line 171, in _new_conn
    raise NewConnectionError(
urllib3.exceptions.NewConnectionError: <urllib3.connection.HTTPSConnection object at 0x7f4a1c30a970>: Failed to establish a new connection: [Errno 101] Network is unreachable

During handling of the above exception, another exception occurred:

Traceback (most recent call last):
  File "/home/yanxindong/anaconda/envs/eva/lib/python3.8/site-packages/requests/adapters.py", line 439, in send
    resp = conn.urlopen(
  File "/home/yanxindong/anaconda/envs/eva/lib/python3.8/site-packages/urllib3/connectionpool.py", line 726, in urlopen
    retries = retries.increment(
  File "/home/yanxindong/anaconda/envs/eva/lib/python3.8/site-packages/urllib3/util/retry.py", line 446, in increment
    raise MaxRetryError(_pool, url, error or ResponseError(cause))
urllib3.exceptions.MaxRetryError: HTTPSConnectionPool(host='storage.googleapis.com', port=443): Max retries exceeded with url: /wandb-artifacts-prod/wandb_artifacts/133981200/707680297/6873c23a2381d1524249eb1a948a45a5?Expires=1706688971&GoogleAccessId=gorilla-files-url-signer-man%40wandb-production.iam.gserviceaccount.com&Signature=BaxYtObKuOKiS%2BvcMZU2Bezuyv9eS0Y2vXMmMFcDMFcl4y2oCR0lR9wGzAwOVoKLOd5hG0z1Mmmx7Rp3upmhGpwWr%2FXkHRKmwv%2FHZIPSEVOcWkI2g7C8aEaTdEYNC1N20ZkAnvj8JZKAIR8KMaK3YkCZAJivQjoKpHlXHjfCA8hUxBTQonlTiX0PFoiE%2BxauwWDyPN1jVf%2FK7GIhtcupjAHERrhBuO%2FN7djnw%2BgnY65zmfi0wv2y98ZwB5unjBxHRxpNo%2BrIuF9KM9Bu6xxjFDL%2FAUNoXlr3LuFr5xzvAWPILjDUZItXiiFWKZyqs1Liv%2BiGTgavm%2Foca%2B5QRSWhtQ%3D%3D (Caused by NewConnectionError('<urllib3.connection.HTTPSConnection object at 0x7f4a1c30a970>: Failed to establish a new connection: [Errno 101] Network is unreachable'))

During handling of the above exception, another exception occurred:

Traceback (most recent call last):
  File "/home/yanxindong/anaconda/envs/eva/lib/python3.8/site-packages/wandb/sdk/internal/internal_api.py", line 2758, in upload_file
    response = self._upload_file_session.put(
  File "/home/yanxindong/anaconda/envs/eva/lib/python3.8/site-packages/requests/sessions.py", line 590, in put
    return self.request('PUT', url, data=data, **kwargs)
  File "/home/yanxindong/anaconda/envs/eva/lib/python3.8/site-packages/requests/sessions.py", line 530, in request
    resp = self.send(prep, **send_kwargs)
  File "/home/yanxindong/anaconda/envs/eva/lib/python3.8/site-packages/requests/sessions.py", line 643, in send
    r = adapter.send(request, **kwargs)
  File "/home/yanxindong/anaconda/envs/eva/lib/python3.8/site-packages/requests/adapters.py", line 516, in send
    raise ConnectionError(e, request=request)
requests.exceptions.ConnectionError: HTTPSConnectionPool(host='storage.googleapis.com', port=443): Max retries exceeded with url: /wandb-artifacts-prod/wandb_artifacts/133981200/707680297/6873c23a2381d1524249eb1a948a45a5?Expires=1706688971&GoogleAccessId=gorilla-files-url-signer-man%40wandb-production.iam.gserviceaccount.com&Signature=BaxYtObKuOKiS%2BvcMZU2Bezuyv9eS0Y2vXMmMFcDMFcl4y2oCR0lR9wGzAwOVoKLOd5hG0z1Mmmx7Rp3upmhGpwWr%2FXkHRKmwv%2FHZIPSEVOcWkI2g7C8aEaTdEYNC1N20ZkAnvj8JZKAIR8KMaK3YkCZAJivQjoKpHlXHjfCA8hUxBTQonlTiX0PFoiE%2BxauwWDyPN1jVf%2FK7GIhtcupjAHERrhBuO%2FN7djnw%2BgnY65zmfi0wv2y98ZwB5unjBxHRxpNo%2BrIuF9KM9Bu6xxjFDL%2FAUNoXlr3LuFr5xzvAWPILjDUZItXiiFWKZyqs1Liv%2BiGTgavm%2Foca%2B5QRSWhtQ%3D%3D (Caused by NewConnectionError('<urllib3.connection.HTTPSConnection object at 0x7f4a1c30a970>: Failed to establish a new connection: [Errno 101] Network is unreachable'))

During handling of the above exception, another exception occurred:

Traceback (most recent call last):
  File "/home/yanxindong/anaconda/envs/eva/lib/python3.8/site-packages/wandb/sdk/lib/retry.py", line 131, in __call__
    result = self._call_fn(*args, **kwargs)
  File "/home/yanxindong/anaconda/envs/eva/lib/python3.8/site-packages/wandb/sdk/internal/internal_api.py", line 2789, in upload_file
    raise _e.with_traceback(sys.exc_info()[2])
  File "/home/yanxindong/anaconda/envs/eva/lib/python3.8/site-packages/wandb/sdk/internal/internal_api.py", line 2758, in upload_file
    response = self._upload_file_session.put(
  File "/home/yanxindong/anaconda/envs/eva/lib/python3.8/site-packages/requests/sessions.py", line 590, in put
    return self.request('PUT', url, data=data, **kwargs)
  File "/home/yanxindong/anaconda/envs/eva/lib/python3.8/site-packages/requests/sessions.py", line 530, in request
    resp = self.send(prep, **send_kwargs)
  File "/home/yanxindong/anaconda/envs/eva/lib/python3.8/site-packages/requests/sessions.py", line 643, in send
    r = adapter.send(request, **kwargs)
  File "/home/yanxindong/anaconda/envs/eva/lib/python3.8/site-packages/requests/adapters.py", line 516, in send
    raise ConnectionError(e, request=request)
wandb.sdk.lib.retry.TransientError: None
2024-01-30 16:16:14,510 ERROR   wandb-upload_1:1134335 [internal_api.py:upload_file():2765] upload_file exception https://storage.googleapis.com/wandb-artifacts-prod/wandb_artifacts/133981200/707680297/174a3d9bc61fec126cc7d5bdff5c6c5a?Expires=1706688970&GoogleAccessId=gorilla-files-url-signer-man%40wandb-production.iam.gserviceaccount.com&Signature=kuQL2vv4ZrJMNP8ScZYD%2F1hqehOOYHiCOdMHRR5RG2VDIeKWuqBNncAZbu8meTCvhMbIyz%2By%2FfAi0KXcah6iDUufB9mhZM0EFeR0V9vd3TpvG8s4dqIKBnhH%2FsCMXzfjuAgl3NWESXKwEFwTIi3EFmM27dEG8pzlQcFpMFGvs4IZiymQ%2FTmzqRn2mmEYZOdIMi35AR4nus1RoSMUq8dkKgHL49QckDgc5SUde4L4jsjg1o66To4vq4gyoFUzq3Vh74gLAALPE%2BH%2FPdT86TdHsW7rrwaR8YTveQi9%2F5h5aWu4b1a1qbU524NGBSKS9NVRItwl2fxaL88%2FT6EHKlKllg%3D%3D: HTTPSConnectionPool(host='storage.googleapis.com', port=443): Max retries exceeded with url: /wandb-artifacts-prod/wandb_artifacts/133981200/707680297/174a3d9bc61fec126cc7d5bdff5c6c5a?Expires=1706688970&GoogleAccessId=gorilla-files-url-signer-man%40wandb-production.iam.gserviceaccount.com&Signature=kuQL2vv4ZrJMNP8ScZYD%2F1hqehOOYHiCOdMHRR5RG2VDIeKWuqBNncAZbu8meTCvhMbIyz%2By%2FfAi0KXcah6iDUufB9mhZM0EFeR0V9vd3TpvG8s4dqIKBnhH%2FsCMXzfjuAgl3NWESXKwEFwTIi3EFmM27dEG8pzlQcFpMFGvs4IZiymQ%2FTmzqRn2mmEYZOdIMi35AR4nus1RoSMUq8dkKgHL49QckDgc5SUde4L4jsjg1o66To4vq4gyoFUzq3Vh74gLAALPE%2BH%2FPdT86TdHsW7rrwaR8YTveQi9%2F5h5aWu4b1a1qbU524NGBSKS9NVRItwl2fxaL88%2FT6EHKlKllg%3D%3D (Caused by NewConnectionError('<urllib3.connection.HTTPSConnection object at 0x7f4a1c30ac70>: Failed to establish a new connection: [Errno 101] Network is unreachable'))
2024-01-30 16:16:14,510 ERROR   wandb-upload_1:1134335 [internal_api.py:upload_file():2767] upload_file request headers: {'User-Agent': 'python-requests/2.23.0', 'Accept-Encoding': 'gzip, deflate', 'Accept': '*/*', 'Connection': 'keep-alive', 'Content-MD5': 'F0o9m8Yf7BJsx9W9/1xsWg==', 'Content-Type': 'text/plain; charset=utf-8', 'Content-Length': '2179'}
2024-01-30 16:16:14,510 ERROR   wandb-upload_1:1134335 [internal_api.py:upload_file():2769] upload_file response body: 
2024-01-30 16:16:14,870 DEBUG   HandlerThread:1134335 [handler.py:handle_request():146] handle_request: keepalive
2024-01-30 16:16:15,010 ERROR   wandb-upload_2:1134335 [internal_api.py:upload_file():2765] upload_file exception https://storage.googleapis.com/wandb-artifacts-prod/wandb_artifacts/133981200/707680297/6873c23a2381d1524249eb1a948a45a5?Expires=1706688971&GoogleAccessId=gorilla-files-url-signer-man%40wandb-production.iam.gserviceaccount.com&Signature=BaxYtObKuOKiS%2BvcMZU2Bezuyv9eS0Y2vXMmMFcDMFcl4y2oCR0lR9wGzAwOVoKLOd5hG0z1Mmmx7Rp3upmhGpwWr%2FXkHRKmwv%2FHZIPSEVOcWkI2g7C8aEaTdEYNC1N20ZkAnvj8JZKAIR8KMaK3YkCZAJivQjoKpHlXHjfCA8hUxBTQonlTiX0PFoiE%2BxauwWDyPN1jVf%2FK7GIhtcupjAHERrhBuO%2FN7djnw%2BgnY65zmfi0wv2y98ZwB5unjBxHRxpNo%2BrIuF9KM9Bu6xxjFDL%2FAUNoXlr3LuFr5xzvAWPILjDUZItXiiFWKZyqs1Liv%2BiGTgavm%2Foca%2B5QRSWhtQ%3D%3D: HTTPSConnectionPool(host='storage.googleapis.com', port=443): Max retries exceeded with url: /wandb-artifacts-prod/wandb_artifacts/133981200/707680297/6873c23a2381d1524249eb1a948a45a5?Expires=1706688971&GoogleAccessId=gorilla-files-url-signer-man%40wandb-production.iam.gserviceaccount.com&Signature=BaxYtObKuOKiS%2BvcMZU2Bezuyv9eS0Y2vXMmMFcDMFcl4y2oCR0lR9wGzAwOVoKLOd5hG0z1Mmmx7Rp3upmhGpwWr%2FXkHRKmwv%2FHZIPSEVOcWkI2g7C8aEaTdEYNC1N20ZkAnvj8JZKAIR8KMaK3YkCZAJivQjoKpHlXHjfCA8hUxBTQonlTiX0PFoiE%2BxauwWDyPN1jVf%2FK7GIhtcupjAHERrhBuO%2FN7djnw%2BgnY65zmfi0wv2y98ZwB5unjBxHRxpNo%2BrIuF9KM9Bu6xxjFDL%2FAUNoXlr3LuFr5xzvAWPILjDUZItXiiFWKZyqs1Liv%2BiGTgavm%2Foca%2B5QRSWhtQ%3D%3D (Caused by NewConnectionError('<urllib3.connection.HTTPSConnection object at 0x7f4a1c32c4f0>: Failed to establish a new connection: [Errno 101] Network is unreachable'))
2024-01-30 16:16:15,010 ERROR   wandb-upload_2:1134335 [internal_api.py:upload_file():2767] upload_file request headers: {'User-Agent': 'python-requests/2.23.0', 'Accept-Encoding': 'gzip, deflate', 'Accept': '*/*', 'Connection': 'keep-alive', 'Content-MD5': 'aHPCOiOB0VJCSesalIpFpQ==', 'Content-Type': 'application/json', 'Content-Length': '609'}
2024-01-30 16:16:15,011 ERROR   wandb-upload_2:1134335 [internal_api.py:upload_file():2769] upload_file response body: 
2024-01-30 16:16:19,166 ERROR   wandb-upload_1:1134335 [internal_api.py:upload_file():2765] upload_file exception https://storage.googleapis.com/wandb-artifacts-prod/wandb_artifacts/133981200/707680297/174a3d9bc61fec126cc7d5bdff5c6c5a?Expires=1706688970&GoogleAccessId=gorilla-files-url-signer-man%40wandb-production.iam.gserviceaccount.com&Signature=kuQL2vv4ZrJMNP8ScZYD%2F1hqehOOYHiCOdMHRR5RG2VDIeKWuqBNncAZbu8meTCvhMbIyz%2By%2FfAi0KXcah6iDUufB9mhZM0EFeR0V9vd3TpvG8s4dqIKBnhH%2FsCMXzfjuAgl3NWESXKwEFwTIi3EFmM27dEG8pzlQcFpMFGvs4IZiymQ%2FTmzqRn2mmEYZOdIMi35AR4nus1RoSMUq8dkKgHL49QckDgc5SUde4L4jsjg1o66To4vq4gyoFUzq3Vh74gLAALPE%2BH%2FPdT86TdHsW7rrwaR8YTveQi9%2F5h5aWu4b1a1qbU524NGBSKS9NVRItwl2fxaL88%2FT6EHKlKllg%3D%3D: HTTPSConnectionPool(host='storage.googleapis.com', port=443): Max retries exceeded with url: /wandb-artifacts-prod/wandb_artifacts/133981200/707680297/174a3d9bc61fec126cc7d5bdff5c6c5a?Expires=1706688970&GoogleAccessId=gorilla-files-url-signer-man%40wandb-production.iam.gserviceaccount.com&Signature=kuQL2vv4ZrJMNP8ScZYD%2F1hqehOOYHiCOdMHRR5RG2VDIeKWuqBNncAZbu8meTCvhMbIyz%2By%2FfAi0KXcah6iDUufB9mhZM0EFeR0V9vd3TpvG8s4dqIKBnhH%2FsCMXzfjuAgl3NWESXKwEFwTIi3EFmM27dEG8pzlQcFpMFGvs4IZiymQ%2FTmzqRn2mmEYZOdIMi35AR4nus1RoSMUq8dkKgHL49QckDgc5SUde4L4jsjg1o66To4vq4gyoFUzq3Vh74gLAALPE%2BH%2FPdT86TdHsW7rrwaR8YTveQi9%2F5h5aWu4b1a1qbU524NGBSKS9NVRItwl2fxaL88%2FT6EHKlKllg%3D%3D (Caused by NewConnectionError('<urllib3.connection.HTTPSConnection object at 0x7f4a1c3cebb0>: Failed to establish a new connection: [Errno 101] Network is unreachable'))
2024-01-30 16:16:19,166 ERROR   wandb-upload_1:1134335 [internal_api.py:upload_file():2767] upload_file request headers: {'User-Agent': 'python-requests/2.23.0', 'Accept-Encoding': 'gzip, deflate', 'Accept': '*/*', 'Connection': 'keep-alive', 'Content-MD5': 'F0o9m8Yf7BJsx9W9/1xsWg==', 'Content-Type': 'text/plain; charset=utf-8', 'Content-Length': '2179'}
2024-01-30 16:16:19,166 ERROR   wandb-upload_1:1134335 [internal_api.py:upload_file():2769] upload_file response body: 
2024-01-30 16:16:19,822 ERROR   wandb-upload_2:1134335 [internal_api.py:upload_file():2765] upload_file exception https://storage.googleapis.com/wandb-artifacts-prod/wandb_artifacts/133981200/707680297/6873c23a2381d1524249eb1a948a45a5?Expires=1706688971&GoogleAccessId=gorilla-files-url-signer-man%40wandb-production.iam.gserviceaccount.com&Signature=BaxYtObKuOKiS%2BvcMZU2Bezuyv9eS0Y2vXMmMFcDMFcl4y2oCR0lR9wGzAwOVoKLOd5hG0z1Mmmx7Rp3upmhGpwWr%2FXkHRKmwv%2FHZIPSEVOcWkI2g7C8aEaTdEYNC1N20ZkAnvj8JZKAIR8KMaK3YkCZAJivQjoKpHlXHjfCA8hUxBTQonlTiX0PFoiE%2BxauwWDyPN1jVf%2FK7GIhtcupjAHERrhBuO%2FN7djnw%2BgnY65zmfi0wv2y98ZwB5unjBxHRxpNo%2BrIuF9KM9Bu6xxjFDL%2FAUNoXlr3LuFr5xzvAWPILjDUZItXiiFWKZyqs1Liv%2BiGTgavm%2Foca%2B5QRSWhtQ%3D%3D: HTTPSConnectionPool(host='storage.googleapis.com', port=443): Max retries exceeded with url: /wandb-artifacts-prod/wandb_artifacts/133981200/707680297/6873c23a2381d1524249eb1a948a45a5?Expires=1706688971&GoogleAccessId=gorilla-files-url-signer-man%40wandb-production.iam.gserviceaccount.com&Signature=BaxYtObKuOKiS%2BvcMZU2Bezuyv9eS0Y2vXMmMFcDMFcl4y2oCR0lR9wGzAwOVoKLOd5hG0z1Mmmx7Rp3upmhGpwWr%2FXkHRKmwv%2FHZIPSEVOcWkI2g7C8aEaTdEYNC1N20ZkAnvj8JZKAIR8KMaK3YkCZAJivQjoKpHlXHjfCA8hUxBTQonlTiX0PFoiE%2BxauwWDyPN1jVf%2FK7GIhtcupjAHERrhBuO%2FN7djnw%2BgnY65zmfi0wv2y98ZwB5unjBxHRxpNo%2BrIuF9KM9Bu6xxjFDL%2FAUNoXlr3LuFr5xzvAWPILjDUZItXiiFWKZyqs1Liv%2BiGTgavm%2Foca%2B5QRSWhtQ%3D%3D (Caused by NewConnectionError('<urllib3.connection.HTTPSConnection object at 0x7f4a1c30a370>: Failed to establish a new connection: [Errno 101] Network is unreachable'))
2024-01-30 16:16:19,822 ERROR   wandb-upload_2:1134335 [internal_api.py:upload_file():2767] upload_file request headers: {'User-Agent': 'python-requests/2.23.0', 'Accept-Encoding': 'gzip, deflate', 'Accept': '*/*', 'Connection': 'keep-alive', 'Content-MD5': 'aHPCOiOB0VJCSesalIpFpQ==', 'Content-Type': 'application/json', 'Content-Length': '609'}
2024-01-30 16:16:19,822 ERROR   wandb-upload_2:1134335 [internal_api.py:upload_file():2769] upload_file response body: 
2024-01-30 16:16:19,871 DEBUG   HandlerThread:1134335 [handler.py:handle_request():146] handle_request: keepalive
2024-01-30 16:16:24,873 DEBUG   HandlerThread:1134335 [handler.py:handle_request():146] handle_request: keepalive
2024-01-30 16:16:28,456 ERROR   wandb-upload_1:1134335 [internal_api.py:upload_file():2765] upload_file exception https://storage.googleapis.com/wandb-artifacts-prod/wandb_artifacts/133981200/707680297/174a3d9bc61fec126cc7d5bdff5c6c5a?Expires=1706688970&GoogleAccessId=gorilla-files-url-signer-man%40wandb-production.iam.gserviceaccount.com&Signature=kuQL2vv4ZrJMNP8ScZYD%2F1hqehOOYHiCOdMHRR5RG2VDIeKWuqBNncAZbu8meTCvhMbIyz%2By%2FfAi0KXcah6iDUufB9mhZM0EFeR0V9vd3TpvG8s4dqIKBnhH%2FsCMXzfjuAgl3NWESXKwEFwTIi3EFmM27dEG8pzlQcFpMFGvs4IZiymQ%2FTmzqRn2mmEYZOdIMi35AR4nus1RoSMUq8dkKgHL49QckDgc5SUde4L4jsjg1o66To4vq4gyoFUzq3Vh74gLAALPE%2BH%2FPdT86TdHsW7rrwaR8YTveQi9%2F5h5aWu4b1a1qbU524NGBSKS9NVRItwl2fxaL88%2FT6EHKlKllg%3D%3D: HTTPSConnectionPool(host='storage.googleapis.com', port=443): Max retries exceeded with url: /wandb-artifacts-prod/wandb_artifacts/133981200/707680297/174a3d9bc61fec126cc7d5bdff5c6c5a?Expires=1706688970&GoogleAccessId=gorilla-files-url-signer-man%40wandb-production.iam.gserviceaccount.com&Signature=kuQL2vv4ZrJMNP8ScZYD%2F1hqehOOYHiCOdMHRR5RG2VDIeKWuqBNncAZbu8meTCvhMbIyz%2By%2FfAi0KXcah6iDUufB9mhZM0EFeR0V9vd3TpvG8s4dqIKBnhH%2FsCMXzfjuAgl3NWESXKwEFwTIi3EFmM27dEG8pzlQcFpMFGvs4IZiymQ%2FTmzqRn2mmEYZOdIMi35AR4nus1RoSMUq8dkKgHL49QckDgc5SUde4L4jsjg1o66To4vq4gyoFUzq3Vh74gLAALPE%2BH%2FPdT86TdHsW7rrwaR8YTveQi9%2F5h5aWu4b1a1qbU524NGBSKS9NVRItwl2fxaL88%2FT6EHKlKllg%3D%3D (Caused by NewConnectionError('<urllib3.connection.HTTPSConnection object at 0x7f4a1c486250>: Failed to establish a new connection: [Errno 101] Network is unreachable'))
2024-01-30 16:16:28,456 ERROR   wandb-upload_1:1134335 [internal_api.py:upload_file():2767] upload_file request headers: {'User-Agent': 'python-requests/2.23.0', 'Accept-Encoding': 'gzip, deflate', 'Accept': '*/*', 'Connection': 'keep-alive', 'Content-MD5': 'F0o9m8Yf7BJsx9W9/1xsWg==', 'Content-Type': 'text/plain; charset=utf-8', 'Content-Length': '2179'}
2024-01-30 16:16:28,456 ERROR   wandb-upload_1:1134335 [internal_api.py:upload_file():2769] upload_file response body: 
2024-01-30 16:16:29,253 ERROR   wandb-upload_2:1134335 [internal_api.py:upload_file():2765] upload_file exception https://storage.googleapis.com/wandb-artifacts-prod/wandb_artifacts/133981200/707680297/6873c23a2381d1524249eb1a948a45a5?Expires=1706688971&GoogleAccessId=gorilla-files-url-signer-man%40wandb-production.iam.gserviceaccount.com&Signature=BaxYtObKuOKiS%2BvcMZU2Bezuyv9eS0Y2vXMmMFcDMFcl4y2oCR0lR9wGzAwOVoKLOd5hG0z1Mmmx7Rp3upmhGpwWr%2FXkHRKmwv%2FHZIPSEVOcWkI2g7C8aEaTdEYNC1N20ZkAnvj8JZKAIR8KMaK3YkCZAJivQjoKpHlXHjfCA8hUxBTQonlTiX0PFoiE%2BxauwWDyPN1jVf%2FK7GIhtcupjAHERrhBuO%2FN7djnw%2BgnY65zmfi0wv2y98ZwB5unjBxHRxpNo%2BrIuF9KM9Bu6xxjFDL%2FAUNoXlr3LuFr5xzvAWPILjDUZItXiiFWKZyqs1Liv%2BiGTgavm%2Foca%2B5QRSWhtQ%3D%3D: HTTPSConnectionPool(host='storage.googleapis.com', port=443): Max retries exceeded with url: /wandb-artifacts-prod/wandb_artifacts/133981200/707680297/6873c23a2381d1524249eb1a948a45a5?Expires=1706688971&GoogleAccessId=gorilla-files-url-signer-man%40wandb-production.iam.gserviceaccount.com&Signature=BaxYtObKuOKiS%2BvcMZU2Bezuyv9eS0Y2vXMmMFcDMFcl4y2oCR0lR9wGzAwOVoKLOd5hG0z1Mmmx7Rp3upmhGpwWr%2FXkHRKmwv%2FHZIPSEVOcWkI2g7C8aEaTdEYNC1N20ZkAnvj8JZKAIR8KMaK3YkCZAJivQjoKpHlXHjfCA8hUxBTQonlTiX0PFoiE%2BxauwWDyPN1jVf%2FK7GIhtcupjAHERrhBuO%2FN7djnw%2BgnY65zmfi0wv2y98ZwB5unjBxHRxpNo%2BrIuF9KM9Bu6xxjFDL%2FAUNoXlr3LuFr5xzvAWPILjDUZItXiiFWKZyqs1Liv%2BiGTgavm%2Foca%2B5QRSWhtQ%3D%3D (Caused by NewConnectionError('<urllib3.connection.HTTPSConnection object at 0x7f4a1c32c670>: Failed to establish a new connection: [Errno 101] Network is unreachable'))
2024-01-30 16:16:29,254 ERROR   wandb-upload_2:1134335 [internal_api.py:upload_file():2767] upload_file request headers: {'User-Agent': 'python-requests/2.23.0', 'Accept-Encoding': 'gzip, deflate', 'Accept': '*/*', 'Connection': 'keep-alive', 'Content-MD5': 'aHPCOiOB0VJCSesalIpFpQ==', 'Content-Type': 'application/json', 'Content-Length': '609'}
2024-01-30 16:16:29,254 ERROR   wandb-upload_2:1134335 [internal_api.py:upload_file():2769] upload_file response body: 
2024-01-30 16:16:29,875 DEBUG   HandlerThread:1134335 [handler.py:handle_request():146] handle_request: keepalive
2024-01-30 16:16:34,878 DEBUG   HandlerThread:1134335 [handler.py:handle_request():146] handle_request: keepalive
2024-01-30 16:16:39,880 DEBUG   HandlerThread:1134335 [handler.py:handle_request():146] handle_request: keepalive
2024-01-30 16:16:44,882 DEBUG   HandlerThread:1134335 [handler.py:handle_request():146] handle_request: keepalive
2024-01-30 16:16:46,040 ERROR   wandb-upload_2:1134335 [internal_api.py:upload_file():2765] upload_file exception https://storage.googleapis.com/wandb-artifacts-prod/wandb_artifacts/133981200/707680297/6873c23a2381d1524249eb1a948a45a5?Expires=1706688971&GoogleAccessId=gorilla-files-url-signer-man%40wandb-production.iam.gserviceaccount.com&Signature=BaxYtObKuOKiS%2BvcMZU2Bezuyv9eS0Y2vXMmMFcDMFcl4y2oCR0lR9wGzAwOVoKLOd5hG0z1Mmmx7Rp3upmhGpwWr%2FXkHRKmwv%2FHZIPSEVOcWkI2g7C8aEaTdEYNC1N20ZkAnvj8JZKAIR8KMaK3YkCZAJivQjoKpHlXHjfCA8hUxBTQonlTiX0PFoiE%2BxauwWDyPN1jVf%2FK7GIhtcupjAHERrhBuO%2FN7djnw%2BgnY65zmfi0wv2y98ZwB5unjBxHRxpNo%2BrIuF9KM9Bu6xxjFDL%2FAUNoXlr3LuFr5xzvAWPILjDUZItXiiFWKZyqs1Liv%2BiGTgavm%2Foca%2B5QRSWhtQ%3D%3D: HTTPSConnectionPool(host='storage.googleapis.com', port=443): Max retries exceeded with url: /wandb-artifacts-prod/wandb_artifacts/133981200/707680297/6873c23a2381d1524249eb1a948a45a5?Expires=1706688971&GoogleAccessId=gorilla-files-url-signer-man%40wandb-production.iam.gserviceaccount.com&Signature=BaxYtObKuOKiS%2BvcMZU2Bezuyv9eS0Y2vXMmMFcDMFcl4y2oCR0lR9wGzAwOVoKLOd5hG0z1Mmmx7Rp3upmhGpwWr%2FXkHRKmwv%2FHZIPSEVOcWkI2g7C8aEaTdEYNC1N20ZkAnvj8JZKAIR8KMaK3YkCZAJivQjoKpHlXHjfCA8hUxBTQonlTiX0PFoiE%2BxauwWDyPN1jVf%2FK7GIhtcupjAHERrhBuO%2FN7djnw%2BgnY65zmfi0wv2y98ZwB5unjBxHRxpNo%2BrIuF9KM9Bu6xxjFDL%2FAUNoXlr3LuFr5xzvAWPILjDUZItXiiFWKZyqs1Liv%2BiGTgavm%2Foca%2B5QRSWhtQ%3D%3D (Caused by NewConnectionError('<urllib3.connection.HTTPSConnection object at 0x7f4a1c2b1040>: Failed to establish a new connection: [Errno 101] Network is unreachable'))
2024-01-30 16:16:46,040 ERROR   wandb-upload_2:1134335 [internal_api.py:upload_file():2767] upload_file request headers: {'User-Agent': 'python-requests/2.23.0', 'Accept-Encoding': 'gzip, deflate', 'Accept': '*/*', 'Connection': 'keep-alive', 'Content-MD5': 'aHPCOiOB0VJCSesalIpFpQ==', 'Content-Type': 'application/json', 'Content-Length': '609'}
2024-01-30 16:16:46,040 ERROR   wandb-upload_2:1134335 [internal_api.py:upload_file():2769] upload_file response body: 
2024-01-30 16:16:47,756 ERROR   wandb-upload_1:1134335 [internal_api.py:upload_file():2765] upload_file exception https://storage.googleapis.com/wandb-artifacts-prod/wandb_artifacts/133981200/707680297/174a3d9bc61fec126cc7d5bdff5c6c5a?Expires=1706688970&GoogleAccessId=gorilla-files-url-signer-man%40wandb-production.iam.gserviceaccount.com&Signature=kuQL2vv4ZrJMNP8ScZYD%2F1hqehOOYHiCOdMHRR5RG2VDIeKWuqBNncAZbu8meTCvhMbIyz%2By%2FfAi0KXcah6iDUufB9mhZM0EFeR0V9vd3TpvG8s4dqIKBnhH%2FsCMXzfjuAgl3NWESXKwEFwTIi3EFmM27dEG8pzlQcFpMFGvs4IZiymQ%2FTmzqRn2mmEYZOdIMi35AR4nus1RoSMUq8dkKgHL49QckDgc5SUde4L4jsjg1o66To4vq4gyoFUzq3Vh74gLAALPE%2BH%2FPdT86TdHsW7rrwaR8YTveQi9%2F5h5aWu4b1a1qbU524NGBSKS9NVRItwl2fxaL88%2FT6EHKlKllg%3D%3D: HTTPSConnectionPool(host='storage.googleapis.com', port=443): Max retries exceeded with url: /wandb-artifacts-prod/wandb_artifacts/133981200/707680297/174a3d9bc61fec126cc7d5bdff5c6c5a?Expires=1706688970&GoogleAccessId=gorilla-files-url-signer-man%40wandb-production.iam.gserviceaccount.com&Signature=kuQL2vv4ZrJMNP8ScZYD%2F1hqehOOYHiCOdMHRR5RG2VDIeKWuqBNncAZbu8meTCvhMbIyz%2By%2FfAi0KXcah6iDUufB9mhZM0EFeR0V9vd3TpvG8s4dqIKBnhH%2FsCMXzfjuAgl3NWESXKwEFwTIi3EFmM27dEG8pzlQcFpMFGvs4IZiymQ%2FTmzqRn2mmEYZOdIMi35AR4nus1RoSMUq8dkKgHL49QckDgc5SUde4L4jsjg1o66To4vq4gyoFUzq3Vh74gLAALPE%2BH%2FPdT86TdHsW7rrwaR8YTveQi9%2F5h5aWu4b1a1qbU524NGBSKS9NVRItwl2fxaL88%2FT6EHKlKllg%3D%3D (Caused by NewConnectionError('<urllib3.connection.HTTPSConnection object at 0x7f4a1c2b1ca0>: Failed to establish a new connection: [Errno 101] Network is unreachable'))
2024-01-30 16:16:47,756 ERROR   wandb-upload_1:1134335 [internal_api.py:upload_file():2767] upload_file request headers: {'User-Agent': 'python-requests/2.23.0', 'Accept-Encoding': 'gzip, deflate', 'Accept': '*/*', 'Connection': 'keep-alive', 'Content-MD5': 'F0o9m8Yf7BJsx9W9/1xsWg==', 'Content-Type': 'text/plain; charset=utf-8', 'Content-Length': '2179'}
2024-01-30 16:16:47,756 ERROR   wandb-upload_1:1134335 [internal_api.py:upload_file():2769] upload_file response body: 
2024-01-30 16:16:49,884 DEBUG   HandlerThread:1134335 [handler.py:handle_request():146] handle_request: keepalive
2024-01-30 16:16:54,886 DEBUG   HandlerThread:1134335 [handler.py:handle_request():146] handle_request: keepalive
2024-01-30 16:16:59,889 DEBUG   HandlerThread:1134335 [handler.py:handle_request():146] handle_request: keepalive
2024-01-30 16:17:04,891 DEBUG   HandlerThread:1134335 [handler.py:handle_request():146] handle_request: keepalive
2024-01-30 16:17:09,893 DEBUG   HandlerThread:1134335 [handler.py:handle_request():146] handle_request: keepalive
2024-01-30 16:17:14,895 DEBUG   HandlerThread:1134335 [handler.py:handle_request():146] handle_request: keepalive
2024-01-30 16:17:19,898 DEBUG   HandlerThread:1134335 [handler.py:handle_request():146] handle_request: keepalive
2024-01-30 16:17:20,039 ERROR   wandb-upload_1:1134335 [internal_api.py:upload_file():2765] upload_file exception https://storage.googleapis.com/wandb-artifacts-prod/wandb_artifacts/133981200/707680297/174a3d9bc61fec126cc7d5bdff5c6c5a?Expires=1706688970&GoogleAccessId=gorilla-files-url-signer-man%40wandb-production.iam.gserviceaccount.com&Signature=kuQL2vv4ZrJMNP8ScZYD%2F1hqehOOYHiCOdMHRR5RG2VDIeKWuqBNncAZbu8meTCvhMbIyz%2By%2FfAi0KXcah6iDUufB9mhZM0EFeR0V9vd3TpvG8s4dqIKBnhH%2FsCMXzfjuAgl3NWESXKwEFwTIi3EFmM27dEG8pzlQcFpMFGvs4IZiymQ%2FTmzqRn2mmEYZOdIMi35AR4nus1RoSMUq8dkKgHL49QckDgc5SUde4L4jsjg1o66To4vq4gyoFUzq3Vh74gLAALPE%2BH%2FPdT86TdHsW7rrwaR8YTveQi9%2F5h5aWu4b1a1qbU524NGBSKS9NVRItwl2fxaL88%2FT6EHKlKllg%3D%3D: HTTPSConnectionPool(host='storage.googleapis.com', port=443): Max retries exceeded with url: /wandb-artifacts-prod/wandb_artifacts/133981200/707680297/174a3d9bc61fec126cc7d5bdff5c6c5a?Expires=1706688970&GoogleAccessId=gorilla-files-url-signer-man%40wandb-production.iam.gserviceaccount.com&Signature=kuQL2vv4ZrJMNP8ScZYD%2F1hqehOOYHiCOdMHRR5RG2VDIeKWuqBNncAZbu8meTCvhMbIyz%2By%2FfAi0KXcah6iDUufB9mhZM0EFeR0V9vd3TpvG8s4dqIKBnhH%2FsCMXzfjuAgl3NWESXKwEFwTIi3EFmM27dEG8pzlQcFpMFGvs4IZiymQ%2FTmzqRn2mmEYZOdIMi35AR4nus1RoSMUq8dkKgHL49QckDgc5SUde4L4jsjg1o66To4vq4gyoFUzq3Vh74gLAALPE%2BH%2FPdT86TdHsW7rrwaR8YTveQi9%2F5h5aWu4b1a1qbU524NGBSKS9NVRItwl2fxaL88%2FT6EHKlKllg%3D%3D (Caused by NewConnectionError('<urllib3.connection.HTTPSConnection object at 0x7f4a1c2b54c0>: Failed to establish a new connection: [Errno 101] Network is unreachable'))
2024-01-30 16:17:20,039 ERROR   wandb-upload_1:1134335 [internal_api.py:upload_file():2767] upload_file request headers: {'User-Agent': 'python-requests/2.23.0', 'Accept-Encoding': 'gzip, deflate', 'Accept': '*/*', 'Connection': 'keep-alive', 'Content-MD5': 'F0o9m8Yf7BJsx9W9/1xsWg==', 'Content-Type': 'text/plain; charset=utf-8', 'Content-Length': '2179'}
2024-01-30 16:17:20,039 ERROR   wandb-upload_1:1134335 [internal_api.py:upload_file():2769] upload_file response body: 
2024-01-30 16:17:22,659 ERROR   wandb-upload_2:1134335 [internal_api.py:upload_file():2765] upload_file exception https://storage.googleapis.com/wandb-artifacts-prod/wandb_artifacts/133981200/707680297/6873c23a2381d1524249eb1a948a45a5?Expires=1706688971&GoogleAccessId=gorilla-files-url-signer-man%40wandb-production.iam.gserviceaccount.com&Signature=BaxYtObKuOKiS%2BvcMZU2Bezuyv9eS0Y2vXMmMFcDMFcl4y2oCR0lR9wGzAwOVoKLOd5hG0z1Mmmx7Rp3upmhGpwWr%2FXkHRKmwv%2FHZIPSEVOcWkI2g7C8aEaTdEYNC1N20ZkAnvj8JZKAIR8KMaK3YkCZAJivQjoKpHlXHjfCA8hUxBTQonlTiX0PFoiE%2BxauwWDyPN1jVf%2FK7GIhtcupjAHERrhBuO%2FN7djnw%2BgnY65zmfi0wv2y98ZwB5unjBxHRxpNo%2BrIuF9KM9Bu6xxjFDL%2FAUNoXlr3LuFr5xzvAWPILjDUZItXiiFWKZyqs1Liv%2BiGTgavm%2Foca%2B5QRSWhtQ%3D%3D: HTTPSConnectionPool(host='storage.googleapis.com', port=443): Max retries exceeded with url: /wandb-artifacts-prod/wandb_artifacts/133981200/707680297/6873c23a2381d1524249eb1a948a45a5?Expires=1706688971&GoogleAccessId=gorilla-files-url-signer-man%40wandb-production.iam.gserviceaccount.com&Signature=BaxYtObKuOKiS%2BvcMZU2Bezuyv9eS0Y2vXMmMFcDMFcl4y2oCR0lR9wGzAwOVoKLOd5hG0z1Mmmx7Rp3upmhGpwWr%2FXkHRKmwv%2FHZIPSEVOcWkI2g7C8aEaTdEYNC1N20ZkAnvj8JZKAIR8KMaK3YkCZAJivQjoKpHlXHjfCA8hUxBTQonlTiX0PFoiE%2BxauwWDyPN1jVf%2FK7GIhtcupjAHERrhBuO%2FN7djnw%2BgnY65zmfi0wv2y98ZwB5unjBxHRxpNo%2BrIuF9KM9Bu6xxjFDL%2FAUNoXlr3LuFr5xzvAWPILjDUZItXiiFWKZyqs1Liv%2BiGTgavm%2Foca%2B5QRSWhtQ%3D%3D (Caused by NewConnectionError('<urllib3.connection.HTTPSConnection object at 0x7f4a1c2b15e0>: Failed to establish a new connection: [Errno 101] Network is unreachable'))
2024-01-30 16:17:22,659 ERROR   wandb-upload_2:1134335 [internal_api.py:upload_file():2767] upload_file request headers: {'User-Agent': 'python-requests/2.23.0', 'Accept-Encoding': 'gzip, deflate', 'Accept': '*/*', 'Connection': 'keep-alive', 'Content-MD5': 'aHPCOiOB0VJCSesalIpFpQ==', 'Content-Type': 'application/json', 'Content-Length': '609'}
2024-01-30 16:17:22,659 ERROR   wandb-upload_2:1134335 [internal_api.py:upload_file():2769] upload_file response body: 
2024-01-30 16:17:24,900 DEBUG   HandlerThread:1134335 [handler.py:handle_request():146] handle_request: keepalive
2024-01-30 16:17:29,902 DEBUG   HandlerThread:1134335 [handler.py:handle_request():146] handle_request: keepalive
2024-01-30 16:17:34,904 DEBUG   HandlerThread:1134335 [handler.py:handle_request():146] handle_request: keepalive
2024-01-30 16:17:39,907 DEBUG   HandlerThread:1134335 [handler.py:handle_request():146] handle_request: keepalive
2024-01-30 16:17:44,909 DEBUG   HandlerThread:1134335 [handler.py:handle_request():146] handle_request: keepalive
2024-01-30 16:17:49,911 DEBUG   HandlerThread:1134335 [handler.py:handle_request():146] handle_request: keepalive
2024-01-30 16:17:54,913 DEBUG   HandlerThread:1134335 [handler.py:handle_request():146] handle_request: keepalive
2024-01-30 16:18:28,006 ERROR   wandb-upload_1:1134335 [internal_api.py:upload_file():2765] upload_file exception https://storage.googleapis.com/wandb-artifacts-prod/wandb_artifacts/133981200/707680297/174a3d9bc61fec126cc7d5bdff5c6c5a?Expires=1706688970&GoogleAccessId=gorilla-files-url-signer-man%40wandb-production.iam.gserviceaccount.com&Signature=kuQL2vv4ZrJMNP8ScZYD%2F1hqehOOYHiCOdMHRR5RG2VDIeKWuqBNncAZbu8meTCvhMbIyz%2By%2FfAi0KXcah6iDUufB9mhZM0EFeR0V9vd3TpvG8s4dqIKBnhH%2FsCMXzfjuAgl3NWESXKwEFwTIi3EFmM27dEG8pzlQcFpMFGvs4IZiymQ%2FTmzqRn2mmEYZOdIMi35AR4nus1RoSMUq8dkKgHL49QckDgc5SUde4L4jsjg1o66To4vq4gyoFUzq3Vh74gLAALPE%2BH%2FPdT86TdHsW7rrwaR8YTveQi9%2F5h5aWu4b1a1qbU524NGBSKS9NVRItwl2fxaL88%2FT6EHKlKllg%3D%3D: HTTPSConnectionPool(host='storage.googleapis.com', port=443): Max retries exceeded with url: /wandb-artifacts-prod/wandb_artifacts/133981200/707680297/174a3d9bc61fec126cc7d5bdff5c6c5a?Expires=1706688970&GoogleAccessId=gorilla-files-url-signer-man%40wandb-production.iam.gserviceaccount.com&Signature=kuQL2vv4ZrJMNP8ScZYD%2F1hqehOOYHiCOdMHRR5RG2VDIeKWuqBNncAZbu8meTCvhMbIyz%2By%2FfAi0KXcah6iDUufB9mhZM0EFeR0V9vd3TpvG8s4dqIKBnhH%2FsCMXzfjuAgl3NWESXKwEFwTIi3EFmM27dEG8pzlQcFpMFGvs4IZiymQ%2FTmzqRn2mmEYZOdIMi35AR4nus1RoSMUq8dkKgHL49QckDgc5SUde4L4jsjg1o66To4vq4gyoFUzq3Vh74gLAALPE%2BH%2FPdT86TdHsW7rrwaR8YTveQi9%2F5h5aWu4b1a1qbU524NGBSKS9NVRItwl2fxaL88%2FT6EHKlKllg%3D%3D (Caused by NewConnectionError('<urllib3.connection.HTTPSConnection object at 0x7f4a1c3ce400>: Failed to establish a new connection: [Errno 101] Network is unreachable'))
2024-01-30 16:18:28,006 ERROR   wandb-upload_1:1134335 [internal_api.py:upload_file():2767] upload_file request headers: {'User-Agent': 'python-requests/2.23.0', 'Accept-Encoding': 'gzip, deflate', 'Accept': '*/*', 'Connection': 'keep-alive', 'Content-MD5': 'F0o9m8Yf7BJsx9W9/1xsWg==', 'Content-Type': 'text/plain; charset=utf-8', 'Content-Length': '2179'}
2024-01-30 16:18:28,007 ERROR   wandb-upload_1:1134335 [internal_api.py:upload_file():2769] upload_file response body: 
2024-01-30 16:19:37,136 ERROR   wandb-upload_0:1134335 [internal_api.py:upload_file():2765] upload_file exception https://storage.googleapis.com/wandb-production.appspot.com/dynamic_x/bert_pytorch/jomc1iuf/wandb-metadata.json?Expires=1706688636&GoogleAccessId=gorilla-files-url-signer-man%40wandb-production.iam.gserviceaccount.com&Signature=vqMRnHJotxH%2BLQdQMnF%2FUEG8Q6OLuZGZfMxalY%2FUnvEM%2Be8ZyMBnFDWuHSTfqOP7Pc69TyNGv0JgkpsClhvPAOakvmdu3qmO%2FdMTYx7MsVtQXm1uaTgAUHKXfGVYRGzX9azkKZ0%2BKwudrkvH7EdBXfilA6u8o670q%2FJ1FhvzKDDw%2FoXnoX36K76PI7uhlnPHE8WjKkYY%2FyGiq7WsA%2BStW4O6FJKFdx47Ho0dU6x5DJjnJKGZY3RjFc3njJGPCbv5ihnK9fMa%2ByElS0PvXjOCVqNBXK5eyNZsuN5E3cnvHSA9ov2kAxBLJ%2F0H%2BX0cOb714VK5eTKeQXMrGebJPG%2B3ow%3D%3D: HTTPSConnectionPool(host='storage.googleapis.com', port=443): Max retries exceeded with url: /wandb-production.appspot.com/dynamic_x/bert_pytorch/jomc1iuf/wandb-metadata.json?Expires=1706688636&GoogleAccessId=gorilla-files-url-signer-man%40wandb-production.iam.gserviceaccount.com&Signature=vqMRnHJotxH%2BLQdQMnF%2FUEG8Q6OLuZGZfMxalY%2FUnvEM%2Be8ZyMBnFDWuHSTfqOP7Pc69TyNGv0JgkpsClhvPAOakvmdu3qmO%2FdMTYx7MsVtQXm1uaTgAUHKXfGVYRGzX9azkKZ0%2BKwudrkvH7EdBXfilA6u8o670q%2FJ1FhvzKDDw%2FoXnoX36K76PI7uhlnPHE8WjKkYY%2FyGiq7WsA%2BStW4O6FJKFdx47Ho0dU6x5DJjnJKGZY3RjFc3njJGPCbv5ihnK9fMa%2ByElS0PvXjOCVqNBXK5eyNZsuN5E3cnvHSA9ov2kAxBLJ%2F0H%2BX0cOb714VK5eTKeQXMrGebJPG%2B3ow%3D%3D (Caused by NewConnectionError('<urllib3.connection.HTTPSConnection object at 0x7f4a1c30a7c0>: Failed to establish a new connection: [Errno 111] Connection refused'))
2024-01-30 16:19:37,136 ERROR   wandb-upload_0:1134335 [internal_api.py:upload_file():2767] upload_file request headers: {'User-Agent': 'python-requests/2.23.0', 'Accept-Encoding': 'gzip, deflate', 'Accept': '*/*', 'Connection': 'keep-alive', 'Content-Length': '15548'}
2024-01-30 16:19:37,136 ERROR   wandb-upload_0:1134335 [internal_api.py:upload_file():2769] upload_file response body: 
2024-01-30 16:20:53,773 ERROR   wandb-upload_1:1134335 [internal_api.py:upload_file():2765] upload_file exception https://storage.googleapis.com/wandb-artifacts-prod/wandb_artifacts/133981200/707680297/174a3d9bc61fec126cc7d5bdff5c6c5a?Expires=1706688970&GoogleAccessId=gorilla-files-url-signer-man%40wandb-production.iam.gserviceaccount.com&Signature=kuQL2vv4ZrJMNP8ScZYD%2F1hqehOOYHiCOdMHRR5RG2VDIeKWuqBNncAZbu8meTCvhMbIyz%2By%2FfAi0KXcah6iDUufB9mhZM0EFeR0V9vd3TpvG8s4dqIKBnhH%2FsCMXzfjuAgl3NWESXKwEFwTIi3EFmM27dEG8pzlQcFpMFGvs4IZiymQ%2FTmzqRn2mmEYZOdIMi35AR4nus1RoSMUq8dkKgHL49QckDgc5SUde4L4jsjg1o66To4vq4gyoFUzq3Vh74gLAALPE%2BH%2FPdT86TdHsW7rrwaR8YTveQi9%2F5h5aWu4b1a1qbU524NGBSKS9NVRItwl2fxaL88%2FT6EHKlKllg%3D%3D: HTTPSConnectionPool(host='storage.googleapis.com', port=443): Max retries exceeded with url: /wandb-artifacts-prod/wandb_artifacts/133981200/707680297/174a3d9bc61fec126cc7d5bdff5c6c5a?Expires=1706688970&GoogleAccessId=gorilla-files-url-signer-man%40wandb-production.iam.gserviceaccount.com&Signature=kuQL2vv4ZrJMNP8ScZYD%2F1hqehOOYHiCOdMHRR5RG2VDIeKWuqBNncAZbu8meTCvhMbIyz%2By%2FfAi0KXcah6iDUufB9mhZM0EFeR0V9vd3TpvG8s4dqIKBnhH%2FsCMXzfjuAgl3NWESXKwEFwTIi3EFmM27dEG8pzlQcFpMFGvs4IZiymQ%2FTmzqRn2mmEYZOdIMi35AR4nus1RoSMUq8dkKgHL49QckDgc5SUde4L4jsjg1o66To4vq4gyoFUzq3Vh74gLAALPE%2BH%2FPdT86TdHsW7rrwaR8YTveQi9%2F5h5aWu4b1a1qbU524NGBSKS9NVRItwl2fxaL88%2FT6EHKlKllg%3D%3D (Caused by NewConnectionError('<urllib3.connection.HTTPSConnection object at 0x7f4a1c2b45b0>: Failed to establish a new connection: [Errno 101] Network is unreachable'))
2024-01-30 16:20:53,774 ERROR   wandb-upload_1:1134335 [internal_api.py:upload_file():2767] upload_file request headers: {'User-Agent': 'python-requests/2.23.0', 'Accept-Encoding': 'gzip, deflate', 'Accept': '*/*', 'Connection': 'keep-alive', 'Content-MD5': 'F0o9m8Yf7BJsx9W9/1xsWg==', 'Content-Type': 'text/plain; charset=utf-8', 'Content-Length': '2179'}
2024-01-30 16:20:53,774 ERROR   wandb-upload_1:1134335 [internal_api.py:upload_file():2769] upload_file response body: 
2024-01-30 16:25:03,777 ERROR   wandb-upload_0:1134335 [internal_api.py:upload_file():2765] upload_file exception https://storage.googleapis.com/wandb-production.appspot.com/dynamic_x/bert_pytorch/jomc1iuf/wandb-metadata.json?Expires=1706688636&GoogleAccessId=gorilla-files-url-signer-man%40wandb-production.iam.gserviceaccount.com&Signature=vqMRnHJotxH%2BLQdQMnF%2FUEG8Q6OLuZGZfMxalY%2FUnvEM%2Be8ZyMBnFDWuHSTfqOP7Pc69TyNGv0JgkpsClhvPAOakvmdu3qmO%2FdMTYx7MsVtQXm1uaTgAUHKXfGVYRGzX9azkKZ0%2BKwudrkvH7EdBXfilA6u8o670q%2FJ1FhvzKDDw%2FoXnoX36K76PI7uhlnPHE8WjKkYY%2FyGiq7WsA%2BStW4O6FJKFdx47Ho0dU6x5DJjnJKGZY3RjFc3njJGPCbv5ihnK9fMa%2ByElS0PvXjOCVqNBXK5eyNZsuN5E3cnvHSA9ov2kAxBLJ%2F0H%2BX0cOb714VK5eTKeQXMrGebJPG%2B3ow%3D%3D: HTTPSConnectionPool(host='storage.googleapis.com', port=443): Max retries exceeded with url: /wandb-production.appspot.com/dynamic_x/bert_pytorch/jomc1iuf/wandb-metadata.json?Expires=1706688636&GoogleAccessId=gorilla-files-url-signer-man%40wandb-production.iam.gserviceaccount.com&Signature=vqMRnHJotxH%2BLQdQMnF%2FUEG8Q6OLuZGZfMxalY%2FUnvEM%2Be8ZyMBnFDWuHSTfqOP7Pc69TyNGv0JgkpsClhvPAOakvmdu3qmO%2FdMTYx7MsVtQXm1uaTgAUHKXfGVYRGzX9azkKZ0%2BKwudrkvH7EdBXfilA6u8o670q%2FJ1FhvzKDDw%2FoXnoX36K76PI7uhlnPHE8WjKkYY%2FyGiq7WsA%2BStW4O6FJKFdx47Ho0dU6x5DJjnJKGZY3RjFc3njJGPCbv5ihnK9fMa%2ByElS0PvXjOCVqNBXK5eyNZsuN5E3cnvHSA9ov2kAxBLJ%2F0H%2BX0cOb714VK5eTKeQXMrGebJPG%2B3ow%3D%3D (Caused by NewConnectionError('<urllib3.connection.HTTPSConnection object at 0x7f4a1c2b59a0>: Failed to establish a new connection: [Errno 111] Connection refused'))
2024-01-30 16:25:03,777 ERROR   wandb-upload_0:1134335 [internal_api.py:upload_file():2767] upload_file request headers: {'User-Agent': 'python-requests/2.23.0', 'Accept-Encoding': 'gzip, deflate', 'Accept': '*/*', 'Connection': 'keep-alive', 'Content-Length': '15548'}
2024-01-30 16:25:03,777 ERROR   wandb-upload_0:1134335 [internal_api.py:upload_file():2769] upload_file response body: 
2024-01-30 16:25:47,113 ERROR   wandb-upload_1:1134335 [internal_api.py:upload_file():2765] upload_file exception https://storage.googleapis.com/wandb-artifacts-prod/wandb_artifacts/133981200/707680297/174a3d9bc61fec126cc7d5bdff5c6c5a?Expires=1706688970&GoogleAccessId=gorilla-files-url-signer-man%40wandb-production.iam.gserviceaccount.com&Signature=kuQL2vv4ZrJMNP8ScZYD%2F1hqehOOYHiCOdMHRR5RG2VDIeKWuqBNncAZbu8meTCvhMbIyz%2By%2FfAi0KXcah6iDUufB9mhZM0EFeR0V9vd3TpvG8s4dqIKBnhH%2FsCMXzfjuAgl3NWESXKwEFwTIi3EFmM27dEG8pzlQcFpMFGvs4IZiymQ%2FTmzqRn2mmEYZOdIMi35AR4nus1RoSMUq8dkKgHL49QckDgc5SUde4L4jsjg1o66To4vq4gyoFUzq3Vh74gLAALPE%2BH%2FPdT86TdHsW7rrwaR8YTveQi9%2F5h5aWu4b1a1qbU524NGBSKS9NVRItwl2fxaL88%2FT6EHKlKllg%3D%3D: HTTPSConnectionPool(host='storage.googleapis.com', port=443): Max retries exceeded with url: /wandb-artifacts-prod/wandb_artifacts/133981200/707680297/174a3d9bc61fec126cc7d5bdff5c6c5a?Expires=1706688970&GoogleAccessId=gorilla-files-url-signer-man%40wandb-production.iam.gserviceaccount.com&Signature=kuQL2vv4ZrJMNP8ScZYD%2F1hqehOOYHiCOdMHRR5RG2VDIeKWuqBNncAZbu8meTCvhMbIyz%2By%2FfAi0KXcah6iDUufB9mhZM0EFeR0V9vd3TpvG8s4dqIKBnhH%2FsCMXzfjuAgl3NWESXKwEFwTIi3EFmM27dEG8pzlQcFpMFGvs4IZiymQ%2FTmzqRn2mmEYZOdIMi35AR4nus1RoSMUq8dkKgHL49QckDgc5SUde4L4jsjg1o66To4vq4gyoFUzq3Vh74gLAALPE%2BH%2FPdT86TdHsW7rrwaR8YTveQi9%2F5h5aWu4b1a1qbU524NGBSKS9NVRItwl2fxaL88%2FT6EHKlKllg%3D%3D (Caused by NewConnectionError('<urllib3.connection.HTTPSConnection object at 0x7f4a1c2b1400>: Failed to establish a new connection: [Errno 111] Connection refused'))
2024-01-30 16:25:47,113 ERROR   wandb-upload_1:1134335 [internal_api.py:upload_file():2767] upload_file request headers: {'User-Agent': 'python-requests/2.23.0', 'Accept-Encoding': 'gzip, deflate', 'Accept': '*/*', 'Connection': 'keep-alive', 'Content-MD5': 'F0o9m8Yf7BJsx9W9/1xsWg==', 'Content-Type': 'text/plain; charset=utf-8', 'Content-Length': '2179'}
2024-01-30 16:25:47,113 ERROR   wandb-upload_1:1134335 [internal_api.py:upload_file():2769] upload_file response body: 
2024-01-30 16:30:55,374 ERROR   wandb-upload_0:1134335 [internal_api.py:upload_file():2765] upload_file exception https://storage.googleapis.com/wandb-production.appspot.com/dynamic_x/bert_pytorch/jomc1iuf/wandb-metadata.json?Expires=1706688636&GoogleAccessId=gorilla-files-url-signer-man%40wandb-production.iam.gserviceaccount.com&Signature=vqMRnHJotxH%2BLQdQMnF%2FUEG8Q6OLuZGZfMxalY%2FUnvEM%2Be8ZyMBnFDWuHSTfqOP7Pc69TyNGv0JgkpsClhvPAOakvmdu3qmO%2FdMTYx7MsVtQXm1uaTgAUHKXfGVYRGzX9azkKZ0%2BKwudrkvH7EdBXfilA6u8o670q%2FJ1FhvzKDDw%2FoXnoX36K76PI7uhlnPHE8WjKkYY%2FyGiq7WsA%2BStW4O6FJKFdx47Ho0dU6x5DJjnJKGZY3RjFc3njJGPCbv5ihnK9fMa%2ByElS0PvXjOCVqNBXK5eyNZsuN5E3cnvHSA9ov2kAxBLJ%2F0H%2BX0cOb714VK5eTKeQXMrGebJPG%2B3ow%3D%3D: HTTPSConnectionPool(host='storage.googleapis.com', port=443): Max retries exceeded with url: /wandb-production.appspot.com/dynamic_x/bert_pytorch/jomc1iuf/wandb-metadata.json?Expires=1706688636&GoogleAccessId=gorilla-files-url-signer-man%40wandb-production.iam.gserviceaccount.com&Signature=vqMRnHJotxH%2BLQdQMnF%2FUEG8Q6OLuZGZfMxalY%2FUnvEM%2Be8ZyMBnFDWuHSTfqOP7Pc69TyNGv0JgkpsClhvPAOakvmdu3qmO%2FdMTYx7MsVtQXm1uaTgAUHKXfGVYRGzX9azkKZ0%2BKwudrkvH7EdBXfilA6u8o670q%2FJ1FhvzKDDw%2FoXnoX36K76PI7uhlnPHE8WjKkYY%2FyGiq7WsA%2BStW4O6FJKFdx47Ho0dU6x5DJjnJKGZY3RjFc3njJGPCbv5ihnK9fMa%2ByElS0PvXjOCVqNBXK5eyNZsuN5E3cnvHSA9ov2kAxBLJ%2F0H%2BX0cOb714VK5eTKeQXMrGebJPG%2B3ow%3D%3D (Caused by NewConnectionError('<urllib3.connection.HTTPSConnection object at 0x7f4a1c32c0d0>: Failed to establish a new connection: [Errno 111] Connection refused'))
2024-01-30 16:30:55,374 ERROR   wandb-upload_0:1134335 [internal_api.py:upload_file():2767] upload_file request headers: {'User-Agent': 'python-requests/2.23.0', 'Accept-Encoding': 'gzip, deflate', 'Accept': '*/*', 'Connection': 'keep-alive', 'Content-Length': '15548'}
2024-01-30 16:30:55,374 ERROR   wandb-upload_0:1134335 [internal_api.py:upload_file():2769] upload_file response body: 
2024-01-30 16:31:51,307 ERROR   wandb-upload_1:1134335 [internal_api.py:upload_file():2765] upload_file exception https://storage.googleapis.com/wandb-artifacts-prod/wandb_artifacts/133981200/707680297/174a3d9bc61fec126cc7d5bdff5c6c5a?Expires=1706688970&GoogleAccessId=gorilla-files-url-signer-man%40wandb-production.iam.gserviceaccount.com&Signature=kuQL2vv4ZrJMNP8ScZYD%2F1hqehOOYHiCOdMHRR5RG2VDIeKWuqBNncAZbu8meTCvhMbIyz%2By%2FfAi0KXcah6iDUufB9mhZM0EFeR0V9vd3TpvG8s4dqIKBnhH%2FsCMXzfjuAgl3NWESXKwEFwTIi3EFmM27dEG8pzlQcFpMFGvs4IZiymQ%2FTmzqRn2mmEYZOdIMi35AR4nus1RoSMUq8dkKgHL49QckDgc5SUde4L4jsjg1o66To4vq4gyoFUzq3Vh74gLAALPE%2BH%2FPdT86TdHsW7rrwaR8YTveQi9%2F5h5aWu4b1a1qbU524NGBSKS9NVRItwl2fxaL88%2FT6EHKlKllg%3D%3D: HTTPSConnectionPool(host='storage.googleapis.com', port=443): Max retries exceeded with url: /wandb-artifacts-prod/wandb_artifacts/133981200/707680297/174a3d9bc61fec126cc7d5bdff5c6c5a?Expires=1706688970&GoogleAccessId=gorilla-files-url-signer-man%40wandb-production.iam.gserviceaccount.com&Signature=kuQL2vv4ZrJMNP8ScZYD%2F1hqehOOYHiCOdMHRR5RG2VDIeKWuqBNncAZbu8meTCvhMbIyz%2By%2FfAi0KXcah6iDUufB9mhZM0EFeR0V9vd3TpvG8s4dqIKBnhH%2FsCMXzfjuAgl3NWESXKwEFwTIi3EFmM27dEG8pzlQcFpMFGvs4IZiymQ%2FTmzqRn2mmEYZOdIMi35AR4nus1RoSMUq8dkKgHL49QckDgc5SUde4L4jsjg1o66To4vq4gyoFUzq3Vh74gLAALPE%2BH%2FPdT86TdHsW7rrwaR8YTveQi9%2F5h5aWu4b1a1qbU524NGBSKS9NVRItwl2fxaL88%2FT6EHKlKllg%3D%3D (Caused by NewConnectionError('<urllib3.connection.HTTPSConnection object at 0x7f4a1c2b40a0>: Failed to establish a new connection: [Errno 111] Connection refused'))
2024-01-30 16:31:51,307 ERROR   wandb-upload_1:1134335 [internal_api.py:upload_file():2767] upload_file request headers: {'User-Agent': 'python-requests/2.23.0', 'Accept-Encoding': 'gzip, deflate', 'Accept': '*/*', 'Connection': 'keep-alive', 'Content-MD5': 'F0o9m8Yf7BJsx9W9/1xsWg==', 'Content-Type': 'text/plain; charset=utf-8', 'Content-Length': '2179'}
2024-01-30 16:31:51,307 ERROR   wandb-upload_1:1134335 [internal_api.py:upload_file():2769] upload_file response body: 
2024-01-30 16:36:29,503 ERROR   wandb-upload_0:1134335 [internal_api.py:upload_file():2765] upload_file exception https://storage.googleapis.com/wandb-production.appspot.com/dynamic_x/bert_pytorch/jomc1iuf/wandb-metadata.json?Expires=1706688636&GoogleAccessId=gorilla-files-url-signer-man%40wandb-production.iam.gserviceaccount.com&Signature=vqMRnHJotxH%2BLQdQMnF%2FUEG8Q6OLuZGZfMxalY%2FUnvEM%2Be8ZyMBnFDWuHSTfqOP7Pc69TyNGv0JgkpsClhvPAOakvmdu3qmO%2FdMTYx7MsVtQXm1uaTgAUHKXfGVYRGzX9azkKZ0%2BKwudrkvH7EdBXfilA6u8o670q%2FJ1FhvzKDDw%2FoXnoX36K76PI7uhlnPHE8WjKkYY%2FyGiq7WsA%2BStW4O6FJKFdx47Ho0dU6x5DJjnJKGZY3RjFc3njJGPCbv5ihnK9fMa%2ByElS0PvXjOCVqNBXK5eyNZsuN5E3cnvHSA9ov2kAxBLJ%2F0H%2BX0cOb714VK5eTKeQXMrGebJPG%2B3ow%3D%3D: HTTPSConnectionPool(host='storage.googleapis.com', port=443): Max retries exceeded with url: /wandb-production.appspot.com/dynamic_x/bert_pytorch/jomc1iuf/wandb-metadata.json?Expires=1706688636&GoogleAccessId=gorilla-files-url-signer-man%40wandb-production.iam.gserviceaccount.com&Signature=vqMRnHJotxH%2BLQdQMnF%2FUEG8Q6OLuZGZfMxalY%2FUnvEM%2Be8ZyMBnFDWuHSTfqOP7Pc69TyNGv0JgkpsClhvPAOakvmdu3qmO%2FdMTYx7MsVtQXm1uaTgAUHKXfGVYRGzX9azkKZ0%2BKwudrkvH7EdBXfilA6u8o670q%2FJ1FhvzKDDw%2FoXnoX36K76PI7uhlnPHE8WjKkYY%2FyGiq7WsA%2BStW4O6FJKFdx47Ho0dU6x5DJjnJKGZY3RjFc3njJGPCbv5ihnK9fMa%2ByElS0PvXjOCVqNBXK5eyNZsuN5E3cnvHSA9ov2kAxBLJ%2F0H%2BX0cOb714VK5eTKeQXMrGebJPG%2B3ow%3D%3D (Caused by NewConnectionError('<urllib3.connection.HTTPSConnection object at 0x7f4a1c2ba670>: Failed to establish a new connection: [Errno 111] Connection refused'))
2024-01-30 16:36:29,503 ERROR   wandb-upload_0:1134335 [internal_api.py:upload_file():2767] upload_file request headers: {'User-Agent': 'python-requests/2.23.0', 'Accept-Encoding': 'gzip, deflate', 'Accept': '*/*', 'Connection': 'keep-alive', 'Content-Length': '15548'}
2024-01-30 16:36:29,503 ERROR   wandb-upload_0:1134335 [internal_api.py:upload_file():2769] upload_file response body: 
2024-01-30 16:37:24,686 ERROR   wandb-upload_1:1134335 [internal_api.py:upload_file():2765] upload_file exception https://storage.googleapis.com/wandb-artifacts-prod/wandb_artifacts/133981200/707680297/174a3d9bc61fec126cc7d5bdff5c6c5a?Expires=1706688970&GoogleAccessId=gorilla-files-url-signer-man%40wandb-production.iam.gserviceaccount.com&Signature=kuQL2vv4ZrJMNP8ScZYD%2F1hqehOOYHiCOdMHRR5RG2VDIeKWuqBNncAZbu8meTCvhMbIyz%2By%2FfAi0KXcah6iDUufB9mhZM0EFeR0V9vd3TpvG8s4dqIKBnhH%2FsCMXzfjuAgl3NWESXKwEFwTIi3EFmM27dEG8pzlQcFpMFGvs4IZiymQ%2FTmzqRn2mmEYZOdIMi35AR4nus1RoSMUq8dkKgHL49QckDgc5SUde4L4jsjg1o66To4vq4gyoFUzq3Vh74gLAALPE%2BH%2FPdT86TdHsW7rrwaR8YTveQi9%2F5h5aWu4b1a1qbU524NGBSKS9NVRItwl2fxaL88%2FT6EHKlKllg%3D%3D: HTTPSConnectionPool(host='storage.googleapis.com', port=443): Max retries exceeded with url: /wandb-artifacts-prod/wandb_artifacts/133981200/707680297/174a3d9bc61fec126cc7d5bdff5c6c5a?Expires=1706688970&GoogleAccessId=gorilla-files-url-signer-man%40wandb-production.iam.gserviceaccount.com&Signature=kuQL2vv4ZrJMNP8ScZYD%2F1hqehOOYHiCOdMHRR5RG2VDIeKWuqBNncAZbu8meTCvhMbIyz%2By%2FfAi0KXcah6iDUufB9mhZM0EFeR0V9vd3TpvG8s4dqIKBnhH%2FsCMXzfjuAgl3NWESXKwEFwTIi3EFmM27dEG8pzlQcFpMFGvs4IZiymQ%2FTmzqRn2mmEYZOdIMi35AR4nus1RoSMUq8dkKgHL49QckDgc5SUde4L4jsjg1o66To4vq4gyoFUzq3Vh74gLAALPE%2BH%2FPdT86TdHsW7rrwaR8YTveQi9%2F5h5aWu4b1a1qbU524NGBSKS9NVRItwl2fxaL88%2FT6EHKlKllg%3D%3D (Caused by NewConnectionError('<urllib3.connection.HTTPSConnection object at 0x7f4a1c2b1130>: Failed to establish a new connection: [Errno 111] Connection refused'))
2024-01-30 16:37:24,687 ERROR   wandb-upload_1:1134335 [internal_api.py:upload_file():2767] upload_file request headers: {'User-Agent': 'python-requests/2.23.0', 'Accept-Encoding': 'gzip, deflate', 'Accept': '*/*', 'Connection': 'keep-alive', 'Content-MD5': 'F0o9m8Yf7BJsx9W9/1xsWg==', 'Content-Type': 'text/plain; charset=utf-8', 'Content-Length': '2179'}
2024-01-30 16:37:24,687 ERROR   wandb-upload_1:1134335 [internal_api.py:upload_file():2769] upload_file response body: 
2024-01-30 16:37:45,447 WARNING StreamThr :1134335 [internal.py:is_dead():414] Internal process exiting, parent pid 1134045 disappeared
2024-01-30 16:37:45,447 ERROR   StreamThr :1134335 [internal.py:wandb_internal():152] Internal process shutdown.
2024-01-30 16:37:45,991 INFO    WriterThread:1134335 [datastore.py:close():296] close: /home/yanxindong/mkor/bert/wandb/run-20240130_161012-jomc1iuf/run-jomc1iuf.wandb
2024-01-30 16:37:46,013 INFO    HandlerThread:1134335 [handler.py:finish():869] shutting down handler
2024-01-30 16:40:29,430 ERROR   wandb-upload_2:1134335 [internal_api.py:upload_file():2765] upload_file exception https://storage.googleapis.com/wandb-artifacts-prod/wandb_artifacts/133981200/707680297/6873c23a2381d1524249eb1a948a45a5?Expires=1706688971&GoogleAccessId=gorilla-files-url-signer-man%40wandb-production.iam.gserviceaccount.com&Signature=BaxYtObKuOKiS%2BvcMZU2Bezuyv9eS0Y2vXMmMFcDMFcl4y2oCR0lR9wGzAwOVoKLOd5hG0z1Mmmx7Rp3upmhGpwWr%2FXkHRKmwv%2FHZIPSEVOcWkI2g7C8aEaTdEYNC1N20ZkAnvj8JZKAIR8KMaK3YkCZAJivQjoKpHlXHjfCA8hUxBTQonlTiX0PFoiE%2BxauwWDyPN1jVf%2FK7GIhtcupjAHERrhBuO%2FN7djnw%2BgnY65zmfi0wv2y98ZwB5unjBxHRxpNo%2BrIuF9KM9Bu6xxjFDL%2FAUNoXlr3LuFr5xzvAWPILjDUZItXiiFWKZyqs1Liv%2BiGTgavm%2Foca%2B5QRSWhtQ%3D%3D: HTTPSConnectionPool(host='storage.googleapis.com', port=443): Max retries exceeded with url: /wandb-artifacts-prod/wandb_artifacts/133981200/707680297/6873c23a2381d1524249eb1a948a45a5?Expires=1706688971&GoogleAccessId=gorilla-files-url-signer-man%40wandb-production.iam.gserviceaccount.com&Signature=BaxYtObKuOKiS%2BvcMZU2Bezuyv9eS0Y2vXMmMFcDMFcl4y2oCR0lR9wGzAwOVoKLOd5hG0z1Mmmx7Rp3upmhGpwWr%2FXkHRKmwv%2FHZIPSEVOcWkI2g7C8aEaTdEYNC1N20ZkAnvj8JZKAIR8KMaK3YkCZAJivQjoKpHlXHjfCA8hUxBTQonlTiX0PFoiE%2BxauwWDyPN1jVf%2FK7GIhtcupjAHERrhBuO%2FN7djnw%2BgnY65zmfi0wv2y98ZwB5unjBxHRxpNo%2BrIuF9KM9Bu6xxjFDL%2FAUNoXlr3LuFr5xzvAWPILjDUZItXiiFWKZyqs1Liv%2BiGTgavm%2Foca%2B5QRSWhtQ%3D%3D (Caused by NewConnectionError('<urllib3.connection.HTTPSConnection object at 0x7f4a1c2ba8e0>: Failed to establish a new connection: [Errno 101] Network is unreachable'))
2024-01-30 16:40:29,430 ERROR   wandb-upload_2:1134335 [internal_api.py:upload_file():2767] upload_file request headers: {'User-Agent': 'python-requests/2.23.0', 'Accept-Encoding': 'gzip, deflate', 'Accept': '*/*', 'Connection': 'keep-alive', 'Content-MD5': 'aHPCOiOB0VJCSesalIpFpQ==', 'Content-Type': 'application/json', 'Content-Length': '609'}
2024-01-30 16:40:29,430 ERROR   wandb-upload_2:1134335 [internal_api.py:upload_file():2769] upload_file response body: 
2024-01-30 16:42:13,911 ERROR   wandb-upload_0:1134335 [internal_api.py:upload_file():2765] upload_file exception https://storage.googleapis.com/wandb-production.appspot.com/dynamic_x/bert_pytorch/jomc1iuf/wandb-metadata.json?Expires=1706688636&GoogleAccessId=gorilla-files-url-signer-man%40wandb-production.iam.gserviceaccount.com&Signature=vqMRnHJotxH%2BLQdQMnF%2FUEG8Q6OLuZGZfMxalY%2FUnvEM%2Be8ZyMBnFDWuHSTfqOP7Pc69TyNGv0JgkpsClhvPAOakvmdu3qmO%2FdMTYx7MsVtQXm1uaTgAUHKXfGVYRGzX9azkKZ0%2BKwudrkvH7EdBXfilA6u8o670q%2FJ1FhvzKDDw%2FoXnoX36K76PI7uhlnPHE8WjKkYY%2FyGiq7WsA%2BStW4O6FJKFdx47Ho0dU6x5DJjnJKGZY3RjFc3njJGPCbv5ihnK9fMa%2ByElS0PvXjOCVqNBXK5eyNZsuN5E3cnvHSA9ov2kAxBLJ%2F0H%2BX0cOb714VK5eTKeQXMrGebJPG%2B3ow%3D%3D: HTTPSConnectionPool(host='storage.googleapis.com', port=443): Max retries exceeded with url: /wandb-production.appspot.com/dynamic_x/bert_pytorch/jomc1iuf/wandb-metadata.json?Expires=1706688636&GoogleAccessId=gorilla-files-url-signer-man%40wandb-production.iam.gserviceaccount.com&Signature=vqMRnHJotxH%2BLQdQMnF%2FUEG8Q6OLuZGZfMxalY%2FUnvEM%2Be8ZyMBnFDWuHSTfqOP7Pc69TyNGv0JgkpsClhvPAOakvmdu3qmO%2FdMTYx7MsVtQXm1uaTgAUHKXfGVYRGzX9azkKZ0%2BKwudrkvH7EdBXfilA6u8o670q%2FJ1FhvzKDDw%2FoXnoX36K76PI7uhlnPHE8WjKkYY%2FyGiq7WsA%2BStW4O6FJKFdx47Ho0dU6x5DJjnJKGZY3RjFc3njJGPCbv5ihnK9fMa%2ByElS0PvXjOCVqNBXK5eyNZsuN5E3cnvHSA9ov2kAxBLJ%2F0H%2BX0cOb714VK5eTKeQXMrGebJPG%2B3ow%3D%3D (Caused by NewConnectionError('<urllib3.connection.HTTPSConnection object at 0x7f4a1c2b16d0>: Failed to establish a new connection: [Errno 101] Network is unreachable'))
2024-01-30 16:42:13,911 ERROR   wandb-upload_0:1134335 [internal_api.py:upload_file():2767] upload_file request headers: {'User-Agent': 'python-requests/2.23.0', 'Accept-Encoding': 'gzip, deflate', 'Accept': '*/*', 'Connection': 'keep-alive', 'Content-Length': '15548'}
2024-01-30 16:42:13,911 ERROR   wandb-upload_0:1134335 [internal_api.py:upload_file():2769] upload_file response body: 
2024-01-30 16:42:36,944 ERROR   wandb-upload_1:1134335 [internal_api.py:upload_file():2765] upload_file exception https://storage.googleapis.com/wandb-artifacts-prod/wandb_artifacts/133981200/707680297/174a3d9bc61fec126cc7d5bdff5c6c5a?Expires=1706688970&GoogleAccessId=gorilla-files-url-signer-man%40wandb-production.iam.gserviceaccount.com&Signature=kuQL2vv4ZrJMNP8ScZYD%2F1hqehOOYHiCOdMHRR5RG2VDIeKWuqBNncAZbu8meTCvhMbIyz%2By%2FfAi0KXcah6iDUufB9mhZM0EFeR0V9vd3TpvG8s4dqIKBnhH%2FsCMXzfjuAgl3NWESXKwEFwTIi3EFmM27dEG8pzlQcFpMFGvs4IZiymQ%2FTmzqRn2mmEYZOdIMi35AR4nus1RoSMUq8dkKgHL49QckDgc5SUde4L4jsjg1o66To4vq4gyoFUzq3Vh74gLAALPE%2BH%2FPdT86TdHsW7rrwaR8YTveQi9%2F5h5aWu4b1a1qbU524NGBSKS9NVRItwl2fxaL88%2FT6EHKlKllg%3D%3D: HTTPSConnectionPool(host='storage.googleapis.com', port=443): Max retries exceeded with url: /wandb-artifacts-prod/wandb_artifacts/133981200/707680297/174a3d9bc61fec126cc7d5bdff5c6c5a?Expires=1706688970&GoogleAccessId=gorilla-files-url-signer-man%40wandb-production.iam.gserviceaccount.com&Signature=kuQL2vv4ZrJMNP8ScZYD%2F1hqehOOYHiCOdMHRR5RG2VDIeKWuqBNncAZbu8meTCvhMbIyz%2By%2FfAi0KXcah6iDUufB9mhZM0EFeR0V9vd3TpvG8s4dqIKBnhH%2FsCMXzfjuAgl3NWESXKwEFwTIi3EFmM27dEG8pzlQcFpMFGvs4IZiymQ%2FTmzqRn2mmEYZOdIMi35AR4nus1RoSMUq8dkKgHL49QckDgc5SUde4L4jsjg1o66To4vq4gyoFUzq3Vh74gLAALPE%2BH%2FPdT86TdHsW7rrwaR8YTveQi9%2F5h5aWu4b1a1qbU524NGBSKS9NVRItwl2fxaL88%2FT6EHKlKllg%3D%3D (Caused by NewConnectionError('<urllib3.connection.HTTPSConnection object at 0x7f4a1c30a3a0>: Failed to establish a new connection: [Errno 101] Network is unreachable'))
2024-01-30 16:42:36,944 ERROR   wandb-upload_1:1134335 [internal_api.py:upload_file():2767] upload_file request headers: {'User-Agent': 'python-requests/2.23.0', 'Accept-Encoding': 'gzip, deflate', 'Accept': '*/*', 'Connection': 'keep-alive', 'Content-MD5': 'F0o9m8Yf7BJsx9W9/1xsWg==', 'Content-Type': 'text/plain; charset=utf-8', 'Content-Length': '2179'}
2024-01-30 16:42:36,944 ERROR   wandb-upload_1:1134335 [internal_api.py:upload_file():2769] upload_file response body: 
2024-01-30 16:43:08,989 ERROR   wandb-upload_2:1134335 [internal_api.py:upload_file():2765] upload_file exception https://storage.googleapis.com/wandb-artifacts-prod/wandb_artifacts/133981200/707680297/6873c23a2381d1524249eb1a948a45a5?Expires=1706688971&GoogleAccessId=gorilla-files-url-signer-man%40wandb-production.iam.gserviceaccount.com&Signature=BaxYtObKuOKiS%2BvcMZU2Bezuyv9eS0Y2vXMmMFcDMFcl4y2oCR0lR9wGzAwOVoKLOd5hG0z1Mmmx7Rp3upmhGpwWr%2FXkHRKmwv%2FHZIPSEVOcWkI2g7C8aEaTdEYNC1N20ZkAnvj8JZKAIR8KMaK3YkCZAJivQjoKpHlXHjfCA8hUxBTQonlTiX0PFoiE%2BxauwWDyPN1jVf%2FK7GIhtcupjAHERrhBuO%2FN7djnw%2BgnY65zmfi0wv2y98ZwB5unjBxHRxpNo%2BrIuF9KM9Bu6xxjFDL%2FAUNoXlr3LuFr5xzvAWPILjDUZItXiiFWKZyqs1Liv%2BiGTgavm%2Foca%2B5QRSWhtQ%3D%3D: HTTPSConnectionPool(host='storage.googleapis.com', port=443): Max retries exceeded with url: /wandb-artifacts-prod/wandb_artifacts/133981200/707680297/6873c23a2381d1524249eb1a948a45a5?Expires=1706688971&GoogleAccessId=gorilla-files-url-signer-man%40wandb-production.iam.gserviceaccount.com&Signature=BaxYtObKuOKiS%2BvcMZU2Bezuyv9eS0Y2vXMmMFcDMFcl4y2oCR0lR9wGzAwOVoKLOd5hG0z1Mmmx7Rp3upmhGpwWr%2FXkHRKmwv%2FHZIPSEVOcWkI2g7C8aEaTdEYNC1N20ZkAnvj8JZKAIR8KMaK3YkCZAJivQjoKpHlXHjfCA8hUxBTQonlTiX0PFoiE%2BxauwWDyPN1jVf%2FK7GIhtcupjAHERrhBuO%2FN7djnw%2BgnY65zmfi0wv2y98ZwB5unjBxHRxpNo%2BrIuF9KM9Bu6xxjFDL%2FAUNoXlr3LuFr5xzvAWPILjDUZItXiiFWKZyqs1Liv%2BiGTgavm%2Foca%2B5QRSWhtQ%3D%3D (Caused by NewConnectionError('<urllib3.connection.HTTPSConnection object at 0x7f4a1c32cf40>: Failed to establish a new connection: [Errno 101] Network is unreachable'))
2024-01-30 16:43:08,989 ERROR   wandb-upload_2:1134335 [internal_api.py:upload_file():2767] upload_file request headers: {'User-Agent': 'python-requests/2.23.0', 'Accept-Encoding': 'gzip, deflate', 'Accept': '*/*', 'Connection': 'keep-alive', 'Content-MD5': 'aHPCOiOB0VJCSesalIpFpQ==', 'Content-Type': 'application/json', 'Content-Length': '609'}
2024-01-30 16:43:08,989 ERROR   wandb-upload_2:1134335 [internal_api.py:upload_file():2769] upload_file response body: 
2024-01-30 17:11:59,734 ERROR   wandb-upload_2:1134335 [internal_api.py:upload_file():2765] upload_file exception https://storage.googleapis.com/wandb-artifacts-prod/wandb_artifacts/133981200/707680297/6873c23a2381d1524249eb1a948a45a5?Expires=1706688971&GoogleAccessId=gorilla-files-url-signer-man%40wandb-production.iam.gserviceaccount.com&Signature=BaxYtObKuOKiS%2BvcMZU2Bezuyv9eS0Y2vXMmMFcDMFcl4y2oCR0lR9wGzAwOVoKLOd5hG0z1Mmmx7Rp3upmhGpwWr%2FXkHRKmwv%2FHZIPSEVOcWkI2g7C8aEaTdEYNC1N20ZkAnvj8JZKAIR8KMaK3YkCZAJivQjoKpHlXHjfCA8hUxBTQonlTiX0PFoiE%2BxauwWDyPN1jVf%2FK7GIhtcupjAHERrhBuO%2FN7djnw%2BgnY65zmfi0wv2y98ZwB5unjBxHRxpNo%2BrIuF9KM9Bu6xxjFDL%2FAUNoXlr3LuFr5xzvAWPILjDUZItXiiFWKZyqs1Liv%2BiGTgavm%2Foca%2B5QRSWhtQ%3D%3D: HTTPSConnectionPool(host='storage.googleapis.com', port=443): Max retries exceeded with url: /wandb-artifacts-prod/wandb_artifacts/133981200/707680297/6873c23a2381d1524249eb1a948a45a5?Expires=1706688971&GoogleAccessId=gorilla-files-url-signer-man%40wandb-production.iam.gserviceaccount.com&Signature=BaxYtObKuOKiS%2BvcMZU2Bezuyv9eS0Y2vXMmMFcDMFcl4y2oCR0lR9wGzAwOVoKLOd5hG0z1Mmmx7Rp3upmhGpwWr%2FXkHRKmwv%2FHZIPSEVOcWkI2g7C8aEaTdEYNC1N20ZkAnvj8JZKAIR8KMaK3YkCZAJivQjoKpHlXHjfCA8hUxBTQonlTiX0PFoiE%2BxauwWDyPN1jVf%2FK7GIhtcupjAHERrhBuO%2FN7djnw%2BgnY65zmfi0wv2y98ZwB5unjBxHRxpNo%2BrIuF9KM9Bu6xxjFDL%2FAUNoXlr3LuFr5xzvAWPILjDUZItXiiFWKZyqs1Liv%2BiGTgavm%2Foca%2B5QRSWhtQ%3D%3D (Caused by NewConnectionError('<urllib3.connection.HTTPSConnection object at 0x7f4a1c2b8460>: Failed to establish a new connection: [Errno 110] Connection timed out'))
2024-01-30 17:11:59,734 ERROR   wandb-upload_2:1134335 [internal_api.py:upload_file():2767] upload_file request headers: {'User-Agent': 'python-requests/2.23.0', 'Accept-Encoding': 'gzip, deflate', 'Accept': '*/*', 'Connection': 'keep-alive', 'Content-MD5': 'aHPCOiOB0VJCSesalIpFpQ==', 'Content-Type': 'application/json', 'Content-Length': '609'}
2024-01-30 17:11:59,734 ERROR   wandb-upload_2:1134335 [internal_api.py:upload_file():2769] upload_file response body: 
2024-01-30 17:12:05,878 ERROR   wandb-upload_1:1134335 [internal_api.py:upload_file():2765] upload_file exception https://storage.googleapis.com/wandb-artifacts-prod/wandb_artifacts/133981200/707680297/174a3d9bc61fec126cc7d5bdff5c6c5a?Expires=1706688970&GoogleAccessId=gorilla-files-url-signer-man%40wandb-production.iam.gserviceaccount.com&Signature=kuQL2vv4ZrJMNP8ScZYD%2F1hqehOOYHiCOdMHRR5RG2VDIeKWuqBNncAZbu8meTCvhMbIyz%2By%2FfAi0KXcah6iDUufB9mhZM0EFeR0V9vd3TpvG8s4dqIKBnhH%2FsCMXzfjuAgl3NWESXKwEFwTIi3EFmM27dEG8pzlQcFpMFGvs4IZiymQ%2FTmzqRn2mmEYZOdIMi35AR4nus1RoSMUq8dkKgHL49QckDgc5SUde4L4jsjg1o66To4vq4gyoFUzq3Vh74gLAALPE%2BH%2FPdT86TdHsW7rrwaR8YTveQi9%2F5h5aWu4b1a1qbU524NGBSKS9NVRItwl2fxaL88%2FT6EHKlKllg%3D%3D: HTTPSConnectionPool(host='storage.googleapis.com', port=443): Max retries exceeded with url: /wandb-artifacts-prod/wandb_artifacts/133981200/707680297/174a3d9bc61fec126cc7d5bdff5c6c5a?Expires=1706688970&GoogleAccessId=gorilla-files-url-signer-man%40wandb-production.iam.gserviceaccount.com&Signature=kuQL2vv4ZrJMNP8ScZYD%2F1hqehOOYHiCOdMHRR5RG2VDIeKWuqBNncAZbu8meTCvhMbIyz%2By%2FfAi0KXcah6iDUufB9mhZM0EFeR0V9vd3TpvG8s4dqIKBnhH%2FsCMXzfjuAgl3NWESXKwEFwTIi3EFmM27dEG8pzlQcFpMFGvs4IZiymQ%2FTmzqRn2mmEYZOdIMi35AR4nus1RoSMUq8dkKgHL49QckDgc5SUde4L4jsjg1o66To4vq4gyoFUzq3Vh74gLAALPE%2BH%2FPdT86TdHsW7rrwaR8YTveQi9%2F5h5aWu4b1a1qbU524NGBSKS9NVRItwl2fxaL88%2FT6EHKlKllg%3D%3D (Caused by NewConnectionError('<urllib3.connection.HTTPSConnection object at 0x7f4a1c2b1820>: Failed to establish a new connection: [Errno 110] Connection timed out'))
2024-01-30 17:12:05,878 ERROR   wandb-upload_1:1134335 [internal_api.py:upload_file():2767] upload_file request headers: {'User-Agent': 'python-requests/2.23.0', 'Accept-Encoding': 'gzip, deflate', 'Accept': '*/*', 'Connection': 'keep-alive', 'Content-MD5': 'F0o9m8Yf7BJsx9W9/1xsWg==', 'Content-Type': 'text/plain; charset=utf-8', 'Content-Length': '2179'}
2024-01-30 17:12:05,878 ERROR   wandb-upload_1:1134335 [internal_api.py:upload_file():2769] upload_file response body: 
2024-01-30 17:12:14,070 ERROR   wandb-upload_0:1134335 [internal_api.py:upload_file():2765] upload_file exception https://storage.googleapis.com/wandb-production.appspot.com/dynamic_x/bert_pytorch/jomc1iuf/wandb-metadata.json?Expires=1706688636&GoogleAccessId=gorilla-files-url-signer-man%40wandb-production.iam.gserviceaccount.com&Signature=vqMRnHJotxH%2BLQdQMnF%2FUEG8Q6OLuZGZfMxalY%2FUnvEM%2Be8ZyMBnFDWuHSTfqOP7Pc69TyNGv0JgkpsClhvPAOakvmdu3qmO%2FdMTYx7MsVtQXm1uaTgAUHKXfGVYRGzX9azkKZ0%2BKwudrkvH7EdBXfilA6u8o670q%2FJ1FhvzKDDw%2FoXnoX36K76PI7uhlnPHE8WjKkYY%2FyGiq7WsA%2BStW4O6FJKFdx47Ho0dU6x5DJjnJKGZY3RjFc3njJGPCbv5ihnK9fMa%2ByElS0PvXjOCVqNBXK5eyNZsuN5E3cnvHSA9ov2kAxBLJ%2F0H%2BX0cOb714VK5eTKeQXMrGebJPG%2B3ow%3D%3D: HTTPSConnectionPool(host='storage.googleapis.com', port=443): Max retries exceeded with url: /wandb-production.appspot.com/dynamic_x/bert_pytorch/jomc1iuf/wandb-metadata.json?Expires=1706688636&GoogleAccessId=gorilla-files-url-signer-man%40wandb-production.iam.gserviceaccount.com&Signature=vqMRnHJotxH%2BLQdQMnF%2FUEG8Q6OLuZGZfMxalY%2FUnvEM%2Be8ZyMBnFDWuHSTfqOP7Pc69TyNGv0JgkpsClhvPAOakvmdu3qmO%2FdMTYx7MsVtQXm1uaTgAUHKXfGVYRGzX9azkKZ0%2BKwudrkvH7EdBXfilA6u8o670q%2FJ1FhvzKDDw%2FoXnoX36K76PI7uhlnPHE8WjKkYY%2FyGiq7WsA%2BStW4O6FJKFdx47Ho0dU6x5DJjnJKGZY3RjFc3njJGPCbv5ihnK9fMa%2ByElS0PvXjOCVqNBXK5eyNZsuN5E3cnvHSA9ov2kAxBLJ%2F0H%2BX0cOb714VK5eTKeQXMrGebJPG%2B3ow%3D%3D (Caused by NewConnectionError('<urllib3.connection.HTTPSConnection object at 0x7f4a1c2b1eb0>: Failed to establish a new connection: [Errno 110] Connection timed out'))
2024-01-30 17:12:14,070 ERROR   wandb-upload_0:1134335 [internal_api.py:upload_file():2767] upload_file request headers: {'User-Agent': 'python-requests/2.23.0', 'Accept-Encoding': 'gzip, deflate', 'Accept': '*/*', 'Connection': 'keep-alive', 'Content-Length': '15548'}
2024-01-30 17:12:14,070 ERROR   wandb-upload_0:1134335 [internal_api.py:upload_file():2769] upload_file response body: 
2024-01-30 17:17:11,250 ERROR   wandb-upload_1:1134335 [internal_api.py:upload_file():2765] upload_file exception https://storage.googleapis.com/wandb-artifacts-prod/wandb_artifacts/133981200/707680297/174a3d9bc61fec126cc7d5bdff5c6c5a?Expires=1706688970&GoogleAccessId=gorilla-files-url-signer-man%40wandb-production.iam.gserviceaccount.com&Signature=kuQL2vv4ZrJMNP8ScZYD%2F1hqehOOYHiCOdMHRR5RG2VDIeKWuqBNncAZbu8meTCvhMbIyz%2By%2FfAi0KXcah6iDUufB9mhZM0EFeR0V9vd3TpvG8s4dqIKBnhH%2FsCMXzfjuAgl3NWESXKwEFwTIi3EFmM27dEG8pzlQcFpMFGvs4IZiymQ%2FTmzqRn2mmEYZOdIMi35AR4nus1RoSMUq8dkKgHL49QckDgc5SUde4L4jsjg1o66To4vq4gyoFUzq3Vh74gLAALPE%2BH%2FPdT86TdHsW7rrwaR8YTveQi9%2F5h5aWu4b1a1qbU524NGBSKS9NVRItwl2fxaL88%2FT6EHKlKllg%3D%3D: HTTPSConnectionPool(host='storage.googleapis.com', port=443): Max retries exceeded with url: /wandb-artifacts-prod/wandb_artifacts/133981200/707680297/174a3d9bc61fec126cc7d5bdff5c6c5a?Expires=1706688970&GoogleAccessId=gorilla-files-url-signer-man%40wandb-production.iam.gserviceaccount.com&Signature=kuQL2vv4ZrJMNP8ScZYD%2F1hqehOOYHiCOdMHRR5RG2VDIeKWuqBNncAZbu8meTCvhMbIyz%2By%2FfAi0KXcah6iDUufB9mhZM0EFeR0V9vd3TpvG8s4dqIKBnhH%2FsCMXzfjuAgl3NWESXKwEFwTIi3EFmM27dEG8pzlQcFpMFGvs4IZiymQ%2FTmzqRn2mmEYZOdIMi35AR4nus1RoSMUq8dkKgHL49QckDgc5SUde4L4jsjg1o66To4vq4gyoFUzq3Vh74gLAALPE%2BH%2FPdT86TdHsW7rrwaR8YTveQi9%2F5h5aWu4b1a1qbU524NGBSKS9NVRItwl2fxaL88%2FT6EHKlKllg%3D%3D (Caused by NewConnectionError('<urllib3.connection.HTTPSConnection object at 0x7f4a1c2b8cd0>: Failed to establish a new connection: [Errno 101] Network is unreachable'))
2024-01-30 17:17:11,250 ERROR   wandb-upload_1:1134335 [internal_api.py:upload_file():2767] upload_file request headers: {'User-Agent': 'python-requests/2.23.0', 'Accept-Encoding': 'gzip, deflate', 'Accept': '*/*', 'Connection': 'keep-alive', 'Content-MD5': 'F0o9m8Yf7BJsx9W9/1xsWg==', 'Content-Type': 'text/plain; charset=utf-8', 'Content-Length': '2179'}
2024-01-30 17:17:11,250 ERROR   wandb-upload_1:1134335 [internal_api.py:upload_file():2769] upload_file response body: 
2024-01-30 17:17:29,614 ERROR   wandb-upload_0:1134335 [internal_api.py:upload_file():2765] upload_file exception https://storage.googleapis.com/wandb-production.appspot.com/dynamic_x/bert_pytorch/jomc1iuf/wandb-metadata.json?Expires=1706688636&GoogleAccessId=gorilla-files-url-signer-man%40wandb-production.iam.gserviceaccount.com&Signature=vqMRnHJotxH%2BLQdQMnF%2FUEG8Q6OLuZGZfMxalY%2FUnvEM%2Be8ZyMBnFDWuHSTfqOP7Pc69TyNGv0JgkpsClhvPAOakvmdu3qmO%2FdMTYx7MsVtQXm1uaTgAUHKXfGVYRGzX9azkKZ0%2BKwudrkvH7EdBXfilA6u8o670q%2FJ1FhvzKDDw%2FoXnoX36K76PI7uhlnPHE8WjKkYY%2FyGiq7WsA%2BStW4O6FJKFdx47Ho0dU6x5DJjnJKGZY3RjFc3njJGPCbv5ihnK9fMa%2ByElS0PvXjOCVqNBXK5eyNZsuN5E3cnvHSA9ov2kAxBLJ%2F0H%2BX0cOb714VK5eTKeQXMrGebJPG%2B3ow%3D%3D: HTTPSConnectionPool(host='storage.googleapis.com', port=443): Max retries exceeded with url: /wandb-production.appspot.com/dynamic_x/bert_pytorch/jomc1iuf/wandb-metadata.json?Expires=1706688636&GoogleAccessId=gorilla-files-url-signer-man%40wandb-production.iam.gserviceaccount.com&Signature=vqMRnHJotxH%2BLQdQMnF%2FUEG8Q6OLuZGZfMxalY%2FUnvEM%2Be8ZyMBnFDWuHSTfqOP7Pc69TyNGv0JgkpsClhvPAOakvmdu3qmO%2FdMTYx7MsVtQXm1uaTgAUHKXfGVYRGzX9azkKZ0%2BKwudrkvH7EdBXfilA6u8o670q%2FJ1FhvzKDDw%2FoXnoX36K76PI7uhlnPHE8WjKkYY%2FyGiq7WsA%2BStW4O6FJKFdx47Ho0dU6x5DJjnJKGZY3RjFc3njJGPCbv5ihnK9fMa%2ByElS0PvXjOCVqNBXK5eyNZsuN5E3cnvHSA9ov2kAxBLJ%2F0H%2BX0cOb714VK5eTKeQXMrGebJPG%2B3ow%3D%3D (Caused by NewConnectionError('<urllib3.connection.HTTPSConnection object at 0x7f4a1c2b17c0>: Failed to establish a new connection: [Errno 101] Network is unreachable'))
2024-01-30 17:17:29,614 ERROR   wandb-upload_0:1134335 [internal_api.py:upload_file():2767] upload_file request headers: {'User-Agent': 'python-requests/2.23.0', 'Accept-Encoding': 'gzip, deflate', 'Accept': '*/*', 'Connection': 'keep-alive', 'Content-Length': '15548'}
2024-01-30 17:17:29,614 ERROR   wandb-upload_0:1134335 [internal_api.py:upload_file():2769] upload_file response body: 
2024-01-30 17:17:48,111 ERROR   wandb-upload_2:1134335 [internal_api.py:upload_file():2765] upload_file exception https://storage.googleapis.com/wandb-artifacts-prod/wandb_artifacts/133981200/707680297/6873c23a2381d1524249eb1a948a45a5?Expires=1706688971&GoogleAccessId=gorilla-files-url-signer-man%40wandb-production.iam.gserviceaccount.com&Signature=BaxYtObKuOKiS%2BvcMZU2Bezuyv9eS0Y2vXMmMFcDMFcl4y2oCR0lR9wGzAwOVoKLOd5hG0z1Mmmx7Rp3upmhGpwWr%2FXkHRKmwv%2FHZIPSEVOcWkI2g7C8aEaTdEYNC1N20ZkAnvj8JZKAIR8KMaK3YkCZAJivQjoKpHlXHjfCA8hUxBTQonlTiX0PFoiE%2BxauwWDyPN1jVf%2FK7GIhtcupjAHERrhBuO%2FN7djnw%2BgnY65zmfi0wv2y98ZwB5unjBxHRxpNo%2BrIuF9KM9Bu6xxjFDL%2FAUNoXlr3LuFr5xzvAWPILjDUZItXiiFWKZyqs1Liv%2BiGTgavm%2Foca%2B5QRSWhtQ%3D%3D: HTTPSConnectionPool(host='storage.googleapis.com', port=443): Max retries exceeded with url: /wandb-artifacts-prod/wandb_artifacts/133981200/707680297/6873c23a2381d1524249eb1a948a45a5?Expires=1706688971&GoogleAccessId=gorilla-files-url-signer-man%40wandb-production.iam.gserviceaccount.com&Signature=BaxYtObKuOKiS%2BvcMZU2Bezuyv9eS0Y2vXMmMFcDMFcl4y2oCR0lR9wGzAwOVoKLOd5hG0z1Mmmx7Rp3upmhGpwWr%2FXkHRKmwv%2FHZIPSEVOcWkI2g7C8aEaTdEYNC1N20ZkAnvj8JZKAIR8KMaK3YkCZAJivQjoKpHlXHjfCA8hUxBTQonlTiX0PFoiE%2BxauwWDyPN1jVf%2FK7GIhtcupjAHERrhBuO%2FN7djnw%2BgnY65zmfi0wv2y98ZwB5unjBxHRxpNo%2BrIuF9KM9Bu6xxjFDL%2FAUNoXlr3LuFr5xzvAWPILjDUZItXiiFWKZyqs1Liv%2BiGTgavm%2Foca%2B5QRSWhtQ%3D%3D (Caused by NewConnectionError('<urllib3.connection.HTTPSConnection object at 0x7f4a1c2bc280>: Failed to establish a new connection: [Errno 101] Network is unreachable'))
2024-01-30 17:17:48,111 ERROR   wandb-upload_2:1134335 [internal_api.py:upload_file():2767] upload_file request headers: {'User-Agent': 'python-requests/2.23.0', 'Accept-Encoding': 'gzip, deflate', 'Accept': '*/*', 'Connection': 'keep-alive', 'Content-MD5': 'aHPCOiOB0VJCSesalIpFpQ==', 'Content-Type': 'application/json', 'Content-Length': '609'}
2024-01-30 17:17:48,111 ERROR   wandb-upload_2:1134335 [internal_api.py:upload_file():2769] upload_file response body: 
2024-01-30 17:22:49,591 INFO    wandb-upload_1:1134335 [upload_job.py:push():89] Uploaded file /home/yanxindong/.local/share/wandb/artifacts/staging/tmpsvkioo13
2024-01-30 17:23:25,118 INFO    wandb-upload_0:1134335 [upload_job.py:push():131] Uploaded file /tmp/tmp65ely4fvwandb/wff10amd-wandb-metadata.json
2024-01-30 17:23:33,314 INFO    wandb-upload_2:1134335 [upload_job.py:push():89] Uploaded file /home/yanxindong/.local/share/wandb/artifacts/staging/tmp6vf92u7k
2024-01-30 17:23:36,274 INFO    SenderThread:1134335 [sender.py:send_artifact():1494] sent artifact job-https___github.com_kkkjj-d_mkor.git_bert_run_pretraining.py - {'id': 'QXJ0aWZhY3Q6NzA3NjgwMjk3', 'state': 'PENDING', 'artifactSequence': {'id': 'QXJ0aWZhY3RDb2xsZWN0aW9uOjEzMzk4MTIwMA==', 'latestArtifact': {'id': 'QXJ0aWZhY3Q6NzAzOTc3Mjk3', 'versionIndex': 8}}}
2024-01-30 17:23:36,274 INFO    SenderThread:1134335 [sender.py:finish():1572] shutting down sender
2024-01-30 17:23:36,275 INFO    SenderThread:1134335 [dir_watcher.py:finish():358] shutting down directory watcher
2024-01-30 17:23:36,693 INFO    SenderThread:1134335 [dir_watcher.py:finish():388] scan: /home/yanxindong/mkor/bert/wandb/run-20240130_161012-jomc1iuf/files
2024-01-30 17:23:36,693 INFO    SenderThread:1134335 [dir_watcher.py:finish():402] scan save: /home/yanxindong/mkor/bert/wandb/run-20240130_161012-jomc1iuf/files/wandb-summary.json wandb-summary.json
2024-01-30 17:23:36,694 INFO    SenderThread:1134335 [dir_watcher.py:finish():402] scan save: /home/yanxindong/mkor/bert/wandb/run-20240130_161012-jomc1iuf/files/conda-environment.yaml conda-environment.yaml
2024-01-30 17:23:36,694 INFO    SenderThread:1134335 [dir_watcher.py:finish():402] scan save: /home/yanxindong/mkor/bert/wandb/run-20240130_161012-jomc1iuf/files/wandb-metadata.json wandb-metadata.json
2024-01-30 17:23:36,695 INFO    SenderThread:1134335 [dir_watcher.py:finish():402] scan save: /home/yanxindong/mkor/bert/wandb/run-20240130_161012-jomc1iuf/files/output.log output.log
2024-01-30 17:23:36,695 INFO    SenderThread:1134335 [dir_watcher.py:finish():402] scan save: /home/yanxindong/mkor/bert/wandb/run-20240130_161012-jomc1iuf/files/requirements.txt requirements.txt
2024-01-30 17:23:36,695 INFO    SenderThread:1134335 [dir_watcher.py:finish():402] scan save: /home/yanxindong/mkor/bert/wandb/run-20240130_161012-jomc1iuf/files/config.yaml config.yaml
2024-01-30 17:23:36,695 INFO    SenderThread:1134335 [file_pusher.py:finish():175] shutting down file pusher
2024-01-30 17:23:36,696 INFO    SenderThread:1134335 [file_pusher.py:join():181] waiting for file pusher
2024-01-30 17:23:37,336 INFO    wandb-upload_3:1134335 [upload_job.py:push():131] Uploaded file /home/yanxindong/mkor/bert/wandb/run-20240130_161012-jomc1iuf/files/wandb-summary.json
2024-01-30 17:23:37,705 INFO    wandb-upload_2:1134335 [upload_job.py:push():131] Uploaded file /home/yanxindong/mkor/bert/wandb/run-20240130_161012-jomc1iuf/files/config.yaml
2024-01-30 17:23:37,712 INFO    wandb-upload_0:1134335 [upload_job.py:push():131] Uploaded file /home/yanxindong/mkor/bert/wandb/run-20240130_161012-jomc1iuf/files/output.log
2024-01-30 17:23:37,718 INFO    wandb-upload_4:1134335 [upload_job.py:push():131] Uploaded file /home/yanxindong/mkor/bert/wandb/run-20240130_161012-jomc1iuf/files/requirements.txt
2024-01-30 17:23:38,459 INFO    wandb-upload_1:1134335 [upload_job.py:push():131] Uploaded file /home/yanxindong/mkor/bert/wandb/run-20240130_161012-jomc1iuf/files/conda-environment.yaml
2024-01-30 17:23:38,698 INFO    SenderThread:1134335 [file_stream.py:finish():595] file stream finish called
2024-01-30 17:23:38,979 INFO    SenderThread:1134335 [file_stream.py:finish():599] file stream finish is done
