2024-01-30 16:10:12,571 INFO    StreamThr :1134331 [internal.py:wandb_internal():86] W&B internal server running at pid: 1134331, started at: 2024-01-30 16:10:12.570456
2024-01-30 16:10:12,608 DEBUG   HandlerThread:1134331 [handler.py:handle_request():146] handle_request: status
2024-01-30 16:10:12,625 INFO    WriterThread:1134331 [datastore.py:open_for_write():87] open: /home/yanxindong/mkor/bert/wandb/run-20240130_161012-0vfv9wkn/run-0vfv9wkn.wandb
2024-01-30 16:10:12,626 DEBUG   SenderThread:1134331 [sender.py:send():382] send: header
2024-01-30 16:10:12,626 DEBUG   SenderThread:1134331 [sender.py:send():382] send: run
2024-01-30 16:10:13,927 INFO    SenderThread:1134331 [dir_watcher.py:__init__():211] watching files in: /home/yanxindong/mkor/bert/wandb/run-20240130_161012-0vfv9wkn/files
2024-01-30 16:10:13,927 INFO    SenderThread:1134331 [sender.py:_start_run_threads():1136] run started: 0vfv9wkn with start time 1706602212.540877
2024-01-30 16:10:13,928 DEBUG   HandlerThread:1134331 [handler.py:handle_request():146] handle_request: check_version
2024-01-30 16:10:13,928 DEBUG   SenderThread:1134331 [sender.py:send_request():409] send_request: check_version
2024-01-30 16:10:14,879 DEBUG   HandlerThread:1134331 [handler.py:handle_request():146] handle_request: run_start
2024-01-30 16:10:14,888 DEBUG   HandlerThread:1134331 [system_info.py:__init__():27] System info init
2024-01-30 16:10:14,888 DEBUG   HandlerThread:1134331 [system_info.py:__init__():42] System info init done
2024-01-30 16:10:14,888 INFO    HandlerThread:1134331 [system_monitor.py:start():194] Starting system monitor
2024-01-30 16:10:14,905 INFO    SystemMonitor:1134331 [system_monitor.py:_start():158] Starting system asset monitoring threads
2024-01-30 16:10:14,905 INFO    HandlerThread:1134331 [system_monitor.py:probe():214] Collecting system info
2024-01-30 16:10:14,922 INFO    SystemMonitor:1134331 [interfaces.py:start():190] Started cpu monitoring
2024-01-30 16:10:14,946 INFO    SystemMonitor:1134331 [interfaces.py:start():190] Started disk monitoring
2024-01-30 16:10:14,965 INFO    SystemMonitor:1134331 [interfaces.py:start():190] Started gpu monitoring
2024-01-30 16:10:14,977 INFO    SystemMonitor:1134331 [interfaces.py:start():190] Started memory monitoring
2024-01-30 16:10:14,995 INFO    SystemMonitor:1134331 [interfaces.py:start():190] Started network monitoring
2024-01-30 16:10:15,087 DEBUG   HandlerThread:1134331 [system_info.py:probe():151] Probing system
2024-01-30 16:10:15,122 DEBUG   HandlerThread:1134331 [system_info.py:_probe_git():136] Probing git
2024-01-30 16:10:15,176 DEBUG   HandlerThread:1134331 [system_info.py:_probe_git():144] Probing git done
2024-01-30 16:10:15,176 DEBUG   HandlerThread:1134331 [system_info.py:probe():199] Probing system done
2024-01-30 16:10:15,176 DEBUG   HandlerThread:1134331 [system_monitor.py:probe():223] {'os': 'Linux-5.15.0-92-generic-x86_64-with-glibc2.17', 'python': '3.8.17', 'heartbeatAt': '2024-01-30T08:10:15.087356', 'startedAt': '2024-01-30T08:10:12.535041', 'docker': None, 'cuda': None, 'args': ('--local_rank=2', '--config_file', 'config/bert_pretraining_phase2_config.json', '--input_dir', '/home/yanxindong/mkor/bert/data/encoded/sequences_lowercase_max_seq_len_512_next_seq_task_true', '--output_dir', 'results/adam', '--weight_decay', '0.01', '--num_steps_per_checkpoint', '200'), 'state': 'running', 'program': 'run_pretraining.py', 'codePathLocal': 'run_pretraining.py', 'codePath': 'bert/run_pretraining.py', 'git': {'remote': 'https://github.com/kkkjj-d/mkor.git', 'commit': 'efe99e84fef5594780cfb1df6d6a1f61da4ebba0'}, 'email': '1262670315@qq.com', 'root': '/home/yanxindong/mkor', 'host': 'a6000-X640-G40', 'username': 'yanxindong', 'executable': '/home/yanxindong/anaconda/envs/eva/bin/python', 'cpu_count': 64, 'cpu_count_logical': 128, 'cpu_freq': {'current': 850.78125, 'min': 800.0, 'max': 3400.0}, 'cpu_freq_per_core': [{'current': 3299.997, 'min': 800.0, 'max': 3400.0}, {'current': 900.0, 'min': 800.0, 'max': 3400.0}, {'current': 800.0, 'min': 800.0, 'max': 3400.0}, {'current': 800.0, 'min': 800.0, 'max': 3400.0}, {'current': 800.0, 'min': 800.0, 'max': 3400.0}, {'current': 800.0, 'min': 800.0, 'max': 3400.0}, {'current': 800.0, 'min': 800.0, 'max': 3400.0}, {'current': 800.0, 'min': 800.0, 'max': 3400.0}, {'current': 900.0, 'min': 800.0, 'max': 3400.0}, {'current': 800.0, 'min': 800.0, 'max': 3400.0}, {'current': 800.0, 'min': 800.0, 'max': 3400.0}, {'current': 800.0, 'min': 800.0, 'max': 3400.0}, {'current': 800.0, 'min': 800.0, 'max': 3400.0}, {'current': 800.0, 'min': 800.0, 'max': 3400.0}, {'current': 800.0, 'min': 800.0, 'max': 3400.0}, {'current': 800.0, 'min': 800.0, 'max': 3400.0}, {'current': 800.0, 'min': 800.0, 'max': 3400.0}, {'current': 800.0, 'min': 800.0, 'max': 3400.0}, {'current': 800.0, 'min': 800.0, 'max': 3400.0}, {'current': 800.0, 'min': 800.0, 'max': 3400.0}, {'current': 800.0, 'min': 800.0, 'max': 3400.0}, {'current': 800.0, 'min': 800.0, 'max': 3400.0}, {'current': 800.0, 'min': 800.0, 'max': 3400.0}, {'current': 800.0, 'min': 800.0, 'max': 3400.0}, {'current': 800.0, 'min': 800.0, 'max': 3400.0}, {'current': 800.0, 'min': 800.0, 'max': 3400.0}, {'current': 800.0, 'min': 800.0, 'max': 3400.0}, {'current': 800.0, 'min': 800.0, 'max': 3400.0}, {'current': 800.0, 'min': 800.0, 'max': 3400.0}, {'current': 800.0, 'min': 800.0, 'max': 3400.0}, {'current': 800.0, 'min': 800.0, 'max': 3400.0}, {'current': 800.0, 'min': 800.0, 'max': 3400.0}, {'current': 800.0, 'min': 800.0, 'max': 3400.0}, {'current': 800.0, 'min': 800.0, 'max': 3400.0}, {'current': 1300.0, 'min': 800.0, 'max': 3400.0}, {'current': 800.0, 'min': 800.0, 'max': 3400.0}, {'current': 800.0, 'min': 800.0, 'max': 3400.0}, {'current': 800.0, 'min': 800.0, 'max': 3400.0}, {'current': 800.0, 'min': 800.0, 'max': 3400.0}, {'current': 800.0, 'min': 800.0, 'max': 3400.0}, {'current': 800.0, 'min': 800.0, 'max': 3400.0}, {'current': 800.0, 'min': 800.0, 'max': 3400.0}, {'current': 800.0, 'min': 800.0, 'max': 3400.0}, {'current': 800.0, 'min': 800.0, 'max': 3400.0}, {'current': 800.0, 'min': 800.0, 'max': 3400.0}, {'current': 800.0, 'min': 800.0, 'max': 3400.0}, {'current': 800.0, 'min': 800.0, 'max': 3400.0}, {'current': 800.0, 'min': 800.0, 'max': 3400.0}, {'current': 800.0, 'min': 800.0, 'max': 3400.0}, {'current': 800.0, 'min': 800.0, 'max': 3400.0}, {'current': 800.0, 'min': 800.0, 'max': 3400.0}, {'current': 1000.0, 'min': 800.0, 'max': 3400.0}, {'current': 800.0, 'min': 800.0, 'max': 3400.0}, {'current': 800.0, 'min': 800.0, 'max': 3400.0}, {'current': 800.0, 'min': 800.0, 'max': 3400.0}, {'current': 800.0, 'min': 800.0, 'max': 3400.0}, {'current': 800.0, 'min': 800.0, 'max': 3400.0}, {'current': 800.0, 'min': 800.0, 'max': 3400.0}, {'current': 800.0, 'min': 800.0, 'max': 3400.0}, {'current': 800.0, 'min': 800.0, 'max': 3400.0}, {'current': 800.0, 'min': 800.0, 'max': 3400.0}, {'current': 800.0, 'min': 800.0, 'max': 3400.0}, {'current': 800.0, 'min': 800.0, 'max': 3400.0}, {'current': 800.0, 'min': 800.0, 'max': 3400.0}, {'current': 3299.997, 'min': 800.0, 'max': 3400.0}, {'current': 800.0, 'min': 800.0, 'max': 3400.0}, {'current': 800.0, 'min': 800.0, 'max': 3400.0}, {'current': 800.0, 'min': 800.0, 'max': 3400.0}, {'current': 800.0, 'min': 800.0, 'max': 3400.0}, {'current': 800.0, 'min': 800.0, 'max': 3400.0}, {'current': 800.0, 'min': 800.0, 'max': 3400.0}, {'current': 800.0, 'min': 800.0, 'max': 3400.0}, {'current': 800.0, 'min': 800.0, 'max': 3400.0}, {'current': 800.0, 'min': 800.0, 'max': 3400.0}, {'current': 800.0, 'min': 800.0, 'max': 3400.0}, {'current': 800.0, 'min': 800.0, 'max': 3400.0}, {'current': 800.0, 'min': 800.0, 'max': 3400.0}, {'current': 800.0, 'min': 800.0, 'max': 3400.0}, {'current': 800.0, 'min': 800.0, 'max': 3400.0}, {'current': 800.0, 'min': 800.0, 'max': 3400.0}, {'current': 800.0, 'min': 800.0, 'max': 3400.0}, {'current': 800.0, 'min': 800.0, 'max': 3400.0}, {'current': 800.0, 'min': 800.0, 'max': 3400.0}, {'current': 800.0, 'min': 800.0, 'max': 3400.0}, {'current': 800.0, 'min': 800.0, 'max': 3400.0}, {'current': 800.0, 'min': 800.0, 'max': 3400.0}, {'current': 800.0, 'min': 800.0, 'max': 3400.0}, {'current': 800.0, 'min': 800.0, 'max': 3400.0}, {'current': 800.0, 'min': 800.0, 'max': 3400.0}, {'current': 800.0, 'min': 800.0, 'max': 3400.0}, {'current': 800.0, 'min': 800.0, 'max': 3400.0}, {'current': 800.0, 'min': 800.0, 'max': 3400.0}, {'current': 800.0, 'min': 800.0, 'max': 3400.0}, {'current': 800.0, 'min': 800.0, 'max': 3400.0}, {'current': 800.0, 'min': 800.0, 'max': 3400.0}, {'current': 800.0, 'min': 800.0, 'max': 3400.0}, {'current': 800.0, 'min': 800.0, 'max': 3400.0}, {'current': 800.0, 'min': 800.0, 'max': 3400.0}, {'current': 800.0, 'min': 800.0, 'max': 3400.0}, {'current': 800.0, 'min': 800.0, 'max': 3400.0}, {'current': 800.0, 'min': 800.0, 'max': 3400.0}, {'current': 800.0, 'min': 800.0, 'max': 3400.0}, {'current': 800.0, 'min': 800.0, 'max': 3400.0}, {'current': 800.0, 'min': 800.0, 'max': 3400.0}, {'current': 800.0, 'min': 800.0, 'max': 3400.0}, {'current': 800.0, 'min': 800.0, 'max': 3400.0}, {'current': 800.0, 'min': 800.0, 'max': 3400.0}, {'current': 800.0, 'min': 800.0, 'max': 3400.0}, {'current': 800.0, 'min': 800.0, 'max': 3400.0}, {'current': 800.0, 'min': 800.0, 'max': 3400.0}, {'current': 900.0, 'min': 800.0, 'max': 3400.0}, {'current': 800.0, 'min': 800.0, 'max': 3400.0}, {'current': 800.0, 'min': 800.0, 'max': 3400.0}, {'current': 800.0, 'min': 800.0, 'max': 3400.0}, {'current': 800.0, 'min': 800.0, 'max': 3400.0}, {'current': 800.0, 'min': 800.0, 'max': 3400.0}, {'current': 800.0, 'min': 800.0, 'max': 3400.0}, {'current': 800.0, 'min': 800.0, 'max': 3400.0}, {'current': 800.0, 'min': 800.0, 'max': 3400.0}, {'current': 800.0, 'min': 800.0, 'max': 3400.0}, {'current': 800.0, 'min': 800.0, 'max': 3400.0}, {'current': 800.0, 'min': 800.0, 'max': 3400.0}, {'current': 800.0, 'min': 800.0, 'max': 3400.0}, {'current': 800.0, 'min': 800.0, 'max': 3400.0}, {'current': 800.0, 'min': 800.0, 'max': 3400.0}, {'current': 800.0, 'min': 800.0, 'max': 3400.0}, {'current': 800.0, 'min': 800.0, 'max': 3400.0}, {'current': 800.0, 'min': 800.0, 'max': 3400.0}], 'disk': {'/': {'total': 438.05088806152344, 'used': 30.817367553710938}}, 'gpu': 'NVIDIA RTX A6000', 'gpu_count': 8, 'gpu_devices': [{'name': 'NVIDIA RTX A6000', 'memory_total': 51527024640}, {'name': 'NVIDIA RTX A6000', 'memory_total': 51527024640}, {'name': 'NVIDIA RTX A6000', 'memory_total': 51527024640}, {'name': 'NVIDIA RTX A6000', 'memory_total': 51527024640}, {'name': 'NVIDIA RTX A6000', 'memory_total': 51527024640}, {'name': 'NVIDIA RTX A6000', 'memory_total': 51527024640}, {'name': 'NVIDIA RTX A6000', 'memory_total': 51527024640}, {'name': 'NVIDIA RTX A6000', 'memory_total': 51527024640}], 'memory': {'total': 503.51252365112305}}
2024-01-30 16:10:15,176 INFO    HandlerThread:1134331 [system_monitor.py:probe():224] Finished collecting system info
2024-01-30 16:10:15,176 INFO    HandlerThread:1134331 [system_monitor.py:probe():227] Publishing system info
2024-01-30 16:10:15,176 DEBUG   HandlerThread:1134331 [system_info.py:_save_conda():208] Saving list of conda packages installed into the current environment
2024-01-30 16:10:15,944 INFO    Thread-12 :1134331 [dir_watcher.py:_on_file_created():271] file/dir created: /home/yanxindong/mkor/bert/wandb/run-20240130_161012-0vfv9wkn/files/conda-environment.yaml
2024-01-30 16:10:34,953 INFO    Thread-12 :1134331 [dir_watcher.py:_on_file_modified():288] file/dir modified: /home/yanxindong/mkor/bert/wandb/run-20240130_161012-0vfv9wkn/files/conda-environment.yaml
2024-01-30 16:10:35,831 DEBUG   HandlerThread:1134331 [system_info.py:_save_conda():220] Saving conda packages done
2024-01-30 16:10:35,833 INFO    HandlerThread:1134331 [system_monitor.py:probe():229] Finished publishing system info
2024-01-30 16:10:35,839 DEBUG   HandlerThread:1134331 [handler.py:handle_request():146] handle_request: status_report
2024-01-30 16:10:35,845 DEBUG   HandlerThread:1134331 [handler.py:handle_request():146] handle_request: keepalive
2024-01-30 16:10:35,845 DEBUG   HandlerThread:1134331 [handler.py:handle_request():146] handle_request: status_report
2024-01-30 16:10:35,845 DEBUG   HandlerThread:1134331 [handler.py:handle_request():146] handle_request: keepalive
2024-01-30 16:10:35,845 DEBUG   HandlerThread:1134331 [handler.py:handle_request():146] handle_request: status_report
2024-01-30 16:10:35,846 DEBUG   HandlerThread:1134331 [handler.py:handle_request():146] handle_request: keepalive
2024-01-30 16:10:35,846 DEBUG   HandlerThread:1134331 [handler.py:handle_request():146] handle_request: status_report
2024-01-30 16:10:35,846 DEBUG   HandlerThread:1134331 [handler.py:handle_request():146] handle_request: keepalive
2024-01-30 16:10:35,846 DEBUG   HandlerThread:1134331 [handler.py:handle_request():146] handle_request: python_packages
2024-01-30 16:10:35,846 DEBUG   SenderThread:1134331 [sender.py:send():382] send: files
2024-01-30 16:10:35,846 INFO    SenderThread:1134331 [sender.py:_save_file():1403] saving file wandb-metadata.json with policy now
2024-01-30 16:10:35,847 DEBUG   SenderThread:1134331 [sender.py:send_request():409] send_request: python_packages
2024-01-30 16:10:35,877 DEBUG   HandlerThread:1134331 [handler.py:handle_request():146] handle_request: stop_status
2024-01-30 16:10:35,877 DEBUG   SenderThread:1134331 [sender.py:send_request():409] send_request: stop_status
2024-01-30 16:10:35,913 DEBUG   HandlerThread:1134331 [handler.py:handle_request():146] handle_request: internal_messages
2024-01-30 16:10:35,953 INFO    Thread-12 :1134331 [dir_watcher.py:_on_file_created():271] file/dir created: /home/yanxindong/mkor/bert/wandb/run-20240130_161012-0vfv9wkn/files/wandb-metadata.json
2024-01-30 16:10:35,953 INFO    Thread-12 :1134331 [dir_watcher.py:_on_file_created():271] file/dir created: /home/yanxindong/mkor/bert/wandb/run-20240130_161012-0vfv9wkn/files/requirements.txt
2024-01-30 16:10:36,179 DEBUG   SenderThread:1134331 [sender.py:send():382] send: telemetry
2024-01-30 16:10:36,584 ERROR   wandb-upload_0:1134331 [internal_api.py:upload_file():2765] upload_file exception https://storage.googleapis.com/wandb-production.appspot.com/dynamic_x/bert_pytorch/0vfv9wkn/wandb-metadata.json?Expires=1706688636&GoogleAccessId=gorilla-files-url-signer-man%40wandb-production.iam.gserviceaccount.com&Signature=TOE9Ck7npWvU2grZxrdepfkP7GGkjk2DxVjQW47W2UtaiiUt9kEhpI8qATqI9uozu9XFTPhU9B87d%2B31EOqc9ZxpA3r1tpLJ5J7Plx6BWPUp5B1h1IqJ7JfEnxhfv1KuBRsZ4ZG3gHKdTgEWAXjynDk78cVjyKp5vBw2jOFC4mRI1vjmETrSdu%2BYuLu%2FICD3Nn2TKxzd0d60n9W08r6kTgtEFZZTNPhXe2Jk74oVaKOAuf50B2cELpiGPX2IRImbiSKjqs3lFWxZWaUFL23Qk82VimFqiSWHwpjIE5BQOJf04g41QgvonPnCiDTPQOMZgpAuOSqgczyaRNBOPFqrQQ%3D%3D: HTTPSConnectionPool(host='storage.googleapis.com', port=443): Max retries exceeded with url: /wandb-production.appspot.com/dynamic_x/bert_pytorch/0vfv9wkn/wandb-metadata.json?Expires=1706688636&GoogleAccessId=gorilla-files-url-signer-man%40wandb-production.iam.gserviceaccount.com&Signature=TOE9Ck7npWvU2grZxrdepfkP7GGkjk2DxVjQW47W2UtaiiUt9kEhpI8qATqI9uozu9XFTPhU9B87d%2B31EOqc9ZxpA3r1tpLJ5J7Plx6BWPUp5B1h1IqJ7JfEnxhfv1KuBRsZ4ZG3gHKdTgEWAXjynDk78cVjyKp5vBw2jOFC4mRI1vjmETrSdu%2BYuLu%2FICD3Nn2TKxzd0d60n9W08r6kTgtEFZZTNPhXe2Jk74oVaKOAuf50B2cELpiGPX2IRImbiSKjqs3lFWxZWaUFL23Qk82VimFqiSWHwpjIE5BQOJf04g41QgvonPnCiDTPQOMZgpAuOSqgczyaRNBOPFqrQQ%3D%3D (Caused by NewConnectionError('<urllib3.connection.HTTPSConnection object at 0x7f31a01237c0>: Failed to establish a new connection: [Errno 111] Connection refused'))
2024-01-30 16:10:36,585 ERROR   wandb-upload_0:1134331 [internal_api.py:upload_file():2767] upload_file request headers: {'User-Agent': 'python-requests/2.23.0', 'Accept-Encoding': 'gzip, deflate', 'Accept': '*/*', 'Connection': 'keep-alive', 'Content-Length': '15546'}
2024-01-30 16:10:36,585 ERROR   wandb-upload_0:1134331 [internal_api.py:upload_file():2769] upload_file response body: 
2024-01-30 16:10:37,814 ERROR   wandb-upload_0:1134331 [internal_api.py:upload_file():2765] upload_file exception https://storage.googleapis.com/wandb-production.appspot.com/dynamic_x/bert_pytorch/0vfv9wkn/wandb-metadata.json?Expires=1706688636&GoogleAccessId=gorilla-files-url-signer-man%40wandb-production.iam.gserviceaccount.com&Signature=TOE9Ck7npWvU2grZxrdepfkP7GGkjk2DxVjQW47W2UtaiiUt9kEhpI8qATqI9uozu9XFTPhU9B87d%2B31EOqc9ZxpA3r1tpLJ5J7Plx6BWPUp5B1h1IqJ7JfEnxhfv1KuBRsZ4ZG3gHKdTgEWAXjynDk78cVjyKp5vBw2jOFC4mRI1vjmETrSdu%2BYuLu%2FICD3Nn2TKxzd0d60n9W08r6kTgtEFZZTNPhXe2Jk74oVaKOAuf50B2cELpiGPX2IRImbiSKjqs3lFWxZWaUFL23Qk82VimFqiSWHwpjIE5BQOJf04g41QgvonPnCiDTPQOMZgpAuOSqgczyaRNBOPFqrQQ%3D%3D: HTTPSConnectionPool(host='storage.googleapis.com', port=443): Max retries exceeded with url: /wandb-production.appspot.com/dynamic_x/bert_pytorch/0vfv9wkn/wandb-metadata.json?Expires=1706688636&GoogleAccessId=gorilla-files-url-signer-man%40wandb-production.iam.gserviceaccount.com&Signature=TOE9Ck7npWvU2grZxrdepfkP7GGkjk2DxVjQW47W2UtaiiUt9kEhpI8qATqI9uozu9XFTPhU9B87d%2B31EOqc9ZxpA3r1tpLJ5J7Plx6BWPUp5B1h1IqJ7JfEnxhfv1KuBRsZ4ZG3gHKdTgEWAXjynDk78cVjyKp5vBw2jOFC4mRI1vjmETrSdu%2BYuLu%2FICD3Nn2TKxzd0d60n9W08r6kTgtEFZZTNPhXe2Jk74oVaKOAuf50B2cELpiGPX2IRImbiSKjqs3lFWxZWaUFL23Qk82VimFqiSWHwpjIE5BQOJf04g41QgvonPnCiDTPQOMZgpAuOSqgczyaRNBOPFqrQQ%3D%3D (Caused by NewConnectionError('<urllib3.connection.HTTPSConnection object at 0x7f31a01236d0>: Failed to establish a new connection: [Errno 111] Connection refused'))
2024-01-30 16:10:37,814 ERROR   wandb-upload_0:1134331 [internal_api.py:upload_file():2767] upload_file request headers: {'User-Agent': 'python-requests/2.23.0', 'Accept-Encoding': 'gzip, deflate', 'Accept': '*/*', 'Connection': 'keep-alive', 'Content-Length': '15546'}
2024-01-30 16:10:37,814 ERROR   wandb-upload_0:1134331 [internal_api.py:upload_file():2769] upload_file response body: 
2024-01-30 16:10:38,180 DEBUG   HandlerThread:1134331 [handler.py:handle_request():146] handle_request: status_report
2024-01-30 16:10:40,306 ERROR   wandb-upload_0:1134331 [internal_api.py:upload_file():2765] upload_file exception https://storage.googleapis.com/wandb-production.appspot.com/dynamic_x/bert_pytorch/0vfv9wkn/wandb-metadata.json?Expires=1706688636&GoogleAccessId=gorilla-files-url-signer-man%40wandb-production.iam.gserviceaccount.com&Signature=TOE9Ck7npWvU2grZxrdepfkP7GGkjk2DxVjQW47W2UtaiiUt9kEhpI8qATqI9uozu9XFTPhU9B87d%2B31EOqc9ZxpA3r1tpLJ5J7Plx6BWPUp5B1h1IqJ7JfEnxhfv1KuBRsZ4ZG3gHKdTgEWAXjynDk78cVjyKp5vBw2jOFC4mRI1vjmETrSdu%2BYuLu%2FICD3Nn2TKxzd0d60n9W08r6kTgtEFZZTNPhXe2Jk74oVaKOAuf50B2cELpiGPX2IRImbiSKjqs3lFWxZWaUFL23Qk82VimFqiSWHwpjIE5BQOJf04g41QgvonPnCiDTPQOMZgpAuOSqgczyaRNBOPFqrQQ%3D%3D: HTTPSConnectionPool(host='storage.googleapis.com', port=443): Max retries exceeded with url: /wandb-production.appspot.com/dynamic_x/bert_pytorch/0vfv9wkn/wandb-metadata.json?Expires=1706688636&GoogleAccessId=gorilla-files-url-signer-man%40wandb-production.iam.gserviceaccount.com&Signature=TOE9Ck7npWvU2grZxrdepfkP7GGkjk2DxVjQW47W2UtaiiUt9kEhpI8qATqI9uozu9XFTPhU9B87d%2B31EOqc9ZxpA3r1tpLJ5J7Plx6BWPUp5B1h1IqJ7JfEnxhfv1KuBRsZ4ZG3gHKdTgEWAXjynDk78cVjyKp5vBw2jOFC4mRI1vjmETrSdu%2BYuLu%2FICD3Nn2TKxzd0d60n9W08r6kTgtEFZZTNPhXe2Jk74oVaKOAuf50B2cELpiGPX2IRImbiSKjqs3lFWxZWaUFL23Qk82VimFqiSWHwpjIE5BQOJf04g41QgvonPnCiDTPQOMZgpAuOSqgczyaRNBOPFqrQQ%3D%3D (Caused by NewConnectionError('<urllib3.connection.HTTPSConnection object at 0x7f31a0123820>: Failed to establish a new connection: [Errno 111] Connection refused'))
2024-01-30 16:10:40,306 ERROR   wandb-upload_0:1134331 [internal_api.py:upload_file():2767] upload_file request headers: {'User-Agent': 'python-requests/2.23.0', 'Accept-Encoding': 'gzip, deflate', 'Accept': '*/*', 'Connection': 'keep-alive', 'Content-Length': '15546'}
2024-01-30 16:10:40,306 ERROR   wandb-upload_0:1134331 [internal_api.py:upload_file():2769] upload_file response body: 
2024-01-30 16:10:40,306 INFO    wandb-upload_0:1134331 [retry.py:__call__():172] Retry attempt failed:
Traceback (most recent call last):
  File "/home/yanxindong/anaconda/envs/eva/lib/python3.8/site-packages/urllib3/connection.py", line 159, in _new_conn
    conn = connection.create_connection(
  File "/home/yanxindong/anaconda/envs/eva/lib/python3.8/site-packages/urllib3/util/connection.py", line 84, in create_connection
    raise err
  File "/home/yanxindong/anaconda/envs/eva/lib/python3.8/site-packages/urllib3/util/connection.py", line 74, in create_connection
    sock.connect(sa)
ConnectionRefusedError: [Errno 111] Connection refused

During handling of the above exception, another exception occurred:

Traceback (most recent call last):
  File "/home/yanxindong/anaconda/envs/eva/lib/python3.8/site-packages/urllib3/connectionpool.py", line 670, in urlopen
    httplib_response = self._make_request(
  File "/home/yanxindong/anaconda/envs/eva/lib/python3.8/site-packages/urllib3/connectionpool.py", line 381, in _make_request
    self._validate_conn(conn)
  File "/home/yanxindong/anaconda/envs/eva/lib/python3.8/site-packages/urllib3/connectionpool.py", line 978, in _validate_conn
    conn.connect()
  File "/home/yanxindong/anaconda/envs/eva/lib/python3.8/site-packages/urllib3/connection.py", line 309, in connect
    conn = self._new_conn()
  File "/home/yanxindong/anaconda/envs/eva/lib/python3.8/site-packages/urllib3/connection.py", line 171, in _new_conn
    raise NewConnectionError(
urllib3.exceptions.NewConnectionError: <urllib3.connection.HTTPSConnection object at 0x7f31a0123820>: Failed to establish a new connection: [Errno 111] Connection refused

During handling of the above exception, another exception occurred:

Traceback (most recent call last):
  File "/home/yanxindong/anaconda/envs/eva/lib/python3.8/site-packages/requests/adapters.py", line 439, in send
    resp = conn.urlopen(
  File "/home/yanxindong/anaconda/envs/eva/lib/python3.8/site-packages/urllib3/connectionpool.py", line 726, in urlopen
    retries = retries.increment(
  File "/home/yanxindong/anaconda/envs/eva/lib/python3.8/site-packages/urllib3/util/retry.py", line 446, in increment
    raise MaxRetryError(_pool, url, error or ResponseError(cause))
urllib3.exceptions.MaxRetryError: HTTPSConnectionPool(host='storage.googleapis.com', port=443): Max retries exceeded with url: /wandb-production.appspot.com/dynamic_x/bert_pytorch/0vfv9wkn/wandb-metadata.json?Expires=1706688636&GoogleAccessId=gorilla-files-url-signer-man%40wandb-production.iam.gserviceaccount.com&Signature=TOE9Ck7npWvU2grZxrdepfkP7GGkjk2DxVjQW47W2UtaiiUt9kEhpI8qATqI9uozu9XFTPhU9B87d%2B31EOqc9ZxpA3r1tpLJ5J7Plx6BWPUp5B1h1IqJ7JfEnxhfv1KuBRsZ4ZG3gHKdTgEWAXjynDk78cVjyKp5vBw2jOFC4mRI1vjmETrSdu%2BYuLu%2FICD3Nn2TKxzd0d60n9W08r6kTgtEFZZTNPhXe2Jk74oVaKOAuf50B2cELpiGPX2IRImbiSKjqs3lFWxZWaUFL23Qk82VimFqiSWHwpjIE5BQOJf04g41QgvonPnCiDTPQOMZgpAuOSqgczyaRNBOPFqrQQ%3D%3D (Caused by NewConnectionError('<urllib3.connection.HTTPSConnection object at 0x7f31a0123820>: Failed to establish a new connection: [Errno 111] Connection refused'))

During handling of the above exception, another exception occurred:

Traceback (most recent call last):
  File "/home/yanxindong/anaconda/envs/eva/lib/python3.8/site-packages/wandb/sdk/internal/internal_api.py", line 2758, in upload_file
    response = self._upload_file_session.put(
  File "/home/yanxindong/anaconda/envs/eva/lib/python3.8/site-packages/requests/sessions.py", line 590, in put
    return self.request('PUT', url, data=data, **kwargs)
  File "/home/yanxindong/anaconda/envs/eva/lib/python3.8/site-packages/requests/sessions.py", line 530, in request
    resp = self.send(prep, **send_kwargs)
  File "/home/yanxindong/anaconda/envs/eva/lib/python3.8/site-packages/requests/sessions.py", line 643, in send
    r = adapter.send(request, **kwargs)
  File "/home/yanxindong/anaconda/envs/eva/lib/python3.8/site-packages/requests/adapters.py", line 516, in send
    raise ConnectionError(e, request=request)
requests.exceptions.ConnectionError: HTTPSConnectionPool(host='storage.googleapis.com', port=443): Max retries exceeded with url: /wandb-production.appspot.com/dynamic_x/bert_pytorch/0vfv9wkn/wandb-metadata.json?Expires=1706688636&GoogleAccessId=gorilla-files-url-signer-man%40wandb-production.iam.gserviceaccount.com&Signature=TOE9Ck7npWvU2grZxrdepfkP7GGkjk2DxVjQW47W2UtaiiUt9kEhpI8qATqI9uozu9XFTPhU9B87d%2B31EOqc9ZxpA3r1tpLJ5J7Plx6BWPUp5B1h1IqJ7JfEnxhfv1KuBRsZ4ZG3gHKdTgEWAXjynDk78cVjyKp5vBw2jOFC4mRI1vjmETrSdu%2BYuLu%2FICD3Nn2TKxzd0d60n9W08r6kTgtEFZZTNPhXe2Jk74oVaKOAuf50B2cELpiGPX2IRImbiSKjqs3lFWxZWaUFL23Qk82VimFqiSWHwpjIE5BQOJf04g41QgvonPnCiDTPQOMZgpAuOSqgczyaRNBOPFqrQQ%3D%3D (Caused by NewConnectionError('<urllib3.connection.HTTPSConnection object at 0x7f31a0123820>: Failed to establish a new connection: [Errno 111] Connection refused'))

During handling of the above exception, another exception occurred:

Traceback (most recent call last):
  File "/home/yanxindong/anaconda/envs/eva/lib/python3.8/site-packages/wandb/sdk/lib/retry.py", line 131, in __call__
    result = self._call_fn(*args, **kwargs)
  File "/home/yanxindong/anaconda/envs/eva/lib/python3.8/site-packages/wandb/sdk/internal/internal_api.py", line 2789, in upload_file
    raise _e.with_traceback(sys.exc_info()[2])
  File "/home/yanxindong/anaconda/envs/eva/lib/python3.8/site-packages/wandb/sdk/internal/internal_api.py", line 2758, in upload_file
    response = self._upload_file_session.put(
  File "/home/yanxindong/anaconda/envs/eva/lib/python3.8/site-packages/requests/sessions.py", line 590, in put
    return self.request('PUT', url, data=data, **kwargs)
  File "/home/yanxindong/anaconda/envs/eva/lib/python3.8/site-packages/requests/sessions.py", line 530, in request
    resp = self.send(prep, **send_kwargs)
  File "/home/yanxindong/anaconda/envs/eva/lib/python3.8/site-packages/requests/sessions.py", line 643, in send
    r = adapter.send(request, **kwargs)
  File "/home/yanxindong/anaconda/envs/eva/lib/python3.8/site-packages/requests/adapters.py", line 516, in send
    raise ConnectionError(e, request=request)
wandb.sdk.lib.retry.TransientError: None
2024-01-30 16:10:43,186 DEBUG   HandlerThread:1134331 [handler.py:handle_request():146] handle_request: status_report
2024-01-30 16:10:44,602 ERROR   wandb-upload_0:1134331 [internal_api.py:upload_file():2765] upload_file exception https://storage.googleapis.com/wandb-production.appspot.com/dynamic_x/bert_pytorch/0vfv9wkn/wandb-metadata.json?Expires=1706688636&GoogleAccessId=gorilla-files-url-signer-man%40wandb-production.iam.gserviceaccount.com&Signature=TOE9Ck7npWvU2grZxrdepfkP7GGkjk2DxVjQW47W2UtaiiUt9kEhpI8qATqI9uozu9XFTPhU9B87d%2B31EOqc9ZxpA3r1tpLJ5J7Plx6BWPUp5B1h1IqJ7JfEnxhfv1KuBRsZ4ZG3gHKdTgEWAXjynDk78cVjyKp5vBw2jOFC4mRI1vjmETrSdu%2BYuLu%2FICD3Nn2TKxzd0d60n9W08r6kTgtEFZZTNPhXe2Jk74oVaKOAuf50B2cELpiGPX2IRImbiSKjqs3lFWxZWaUFL23Qk82VimFqiSWHwpjIE5BQOJf04g41QgvonPnCiDTPQOMZgpAuOSqgczyaRNBOPFqrQQ%3D%3D: HTTPSConnectionPool(host='storage.googleapis.com', port=443): Max retries exceeded with url: /wandb-production.appspot.com/dynamic_x/bert_pytorch/0vfv9wkn/wandb-metadata.json?Expires=1706688636&GoogleAccessId=gorilla-files-url-signer-man%40wandb-production.iam.gserviceaccount.com&Signature=TOE9Ck7npWvU2grZxrdepfkP7GGkjk2DxVjQW47W2UtaiiUt9kEhpI8qATqI9uozu9XFTPhU9B87d%2B31EOqc9ZxpA3r1tpLJ5J7Plx6BWPUp5B1h1IqJ7JfEnxhfv1KuBRsZ4ZG3gHKdTgEWAXjynDk78cVjyKp5vBw2jOFC4mRI1vjmETrSdu%2BYuLu%2FICD3Nn2TKxzd0d60n9W08r6kTgtEFZZTNPhXe2Jk74oVaKOAuf50B2cELpiGPX2IRImbiSKjqs3lFWxZWaUFL23Qk82VimFqiSWHwpjIE5BQOJf04g41QgvonPnCiDTPQOMZgpAuOSqgczyaRNBOPFqrQQ%3D%3D (Caused by NewConnectionError('<urllib3.connection.HTTPSConnection object at 0x7f31a0111a30>: Failed to establish a new connection: [Errno 111] Connection refused'))
2024-01-30 16:10:44,602 ERROR   wandb-upload_0:1134331 [internal_api.py:upload_file():2767] upload_file request headers: {'User-Agent': 'python-requests/2.23.0', 'Accept-Encoding': 'gzip, deflate', 'Accept': '*/*', 'Connection': 'keep-alive', 'Content-Length': '15546'}
2024-01-30 16:10:44,602 ERROR   wandb-upload_0:1134331 [internal_api.py:upload_file():2769] upload_file response body: 
2024-01-30 16:10:44,955 INFO    Thread-12 :1134331 [dir_watcher.py:_on_file_modified():288] file/dir modified: /home/yanxindong/mkor/bert/wandb/run-20240130_161012-0vfv9wkn/files/config.yaml
2024-01-30 16:10:49,304 DEBUG   HandlerThread:1134331 [handler.py:handle_request():146] handle_request: status_report
2024-01-30 16:10:50,872 DEBUG   HandlerThread:1134331 [handler.py:handle_request():146] handle_request: stop_status
2024-01-30 16:10:50,872 DEBUG   SenderThread:1134331 [sender.py:send_request():409] send_request: stop_status
2024-01-30 16:10:50,906 DEBUG   HandlerThread:1134331 [handler.py:handle_request():146] handle_request: internal_messages
2024-01-30 16:10:53,287 ERROR   wandb-upload_0:1134331 [internal_api.py:upload_file():2765] upload_file exception https://storage.googleapis.com/wandb-production.appspot.com/dynamic_x/bert_pytorch/0vfv9wkn/wandb-metadata.json?Expires=1706688636&GoogleAccessId=gorilla-files-url-signer-man%40wandb-production.iam.gserviceaccount.com&Signature=TOE9Ck7npWvU2grZxrdepfkP7GGkjk2DxVjQW47W2UtaiiUt9kEhpI8qATqI9uozu9XFTPhU9B87d%2B31EOqc9ZxpA3r1tpLJ5J7Plx6BWPUp5B1h1IqJ7JfEnxhfv1KuBRsZ4ZG3gHKdTgEWAXjynDk78cVjyKp5vBw2jOFC4mRI1vjmETrSdu%2BYuLu%2FICD3Nn2TKxzd0d60n9W08r6kTgtEFZZTNPhXe2Jk74oVaKOAuf50B2cELpiGPX2IRImbiSKjqs3lFWxZWaUFL23Qk82VimFqiSWHwpjIE5BQOJf04g41QgvonPnCiDTPQOMZgpAuOSqgczyaRNBOPFqrQQ%3D%3D: HTTPSConnectionPool(host='storage.googleapis.com', port=443): Max retries exceeded with url: /wandb-production.appspot.com/dynamic_x/bert_pytorch/0vfv9wkn/wandb-metadata.json?Expires=1706688636&GoogleAccessId=gorilla-files-url-signer-man%40wandb-production.iam.gserviceaccount.com&Signature=TOE9Ck7npWvU2grZxrdepfkP7GGkjk2DxVjQW47W2UtaiiUt9kEhpI8qATqI9uozu9XFTPhU9B87d%2B31EOqc9ZxpA3r1tpLJ5J7Plx6BWPUp5B1h1IqJ7JfEnxhfv1KuBRsZ4ZG3gHKdTgEWAXjynDk78cVjyKp5vBw2jOFC4mRI1vjmETrSdu%2BYuLu%2FICD3Nn2TKxzd0d60n9W08r6kTgtEFZZTNPhXe2Jk74oVaKOAuf50B2cELpiGPX2IRImbiSKjqs3lFWxZWaUFL23Qk82VimFqiSWHwpjIE5BQOJf04g41QgvonPnCiDTPQOMZgpAuOSqgczyaRNBOPFqrQQ%3D%3D (Caused by NewConnectionError('<urllib3.connection.HTTPSConnection object at 0x7f31a0123af0>: Failed to establish a new connection: [Errno 111] Connection refused'))
2024-01-30 16:10:53,287 ERROR   wandb-upload_0:1134331 [internal_api.py:upload_file():2767] upload_file request headers: {'User-Agent': 'python-requests/2.23.0', 'Accept-Encoding': 'gzip, deflate', 'Accept': '*/*', 'Connection': 'keep-alive', 'Content-Length': '15546'}
2024-01-30 16:10:53,287 ERROR   wandb-upload_0:1134331 [internal_api.py:upload_file():2769] upload_file response body: 
2024-01-30 16:10:55,249 DEBUG   HandlerThread:1134331 [handler.py:handle_request():146] handle_request: status_report
2024-01-30 16:11:00,250 DEBUG   HandlerThread:1134331 [handler.py:handle_request():146] handle_request: status_report
2024-01-30 16:11:05,251 DEBUG   HandlerThread:1134331 [handler.py:handle_request():146] handle_request: status_report
2024-01-30 16:11:05,862 DEBUG   HandlerThread:1134331 [handler.py:handle_request():146] handle_request: stop_status
2024-01-30 16:11:05,863 DEBUG   SenderThread:1134331 [sender.py:send_request():409] send_request: stop_status
2024-01-30 16:11:05,909 DEBUG   HandlerThread:1134331 [handler.py:handle_request():146] handle_request: internal_messages
2024-01-30 16:11:11,195 DEBUG   HandlerThread:1134331 [handler.py:handle_request():146] handle_request: status_report
2024-01-30 16:11:11,551 ERROR   wandb-upload_0:1134331 [internal_api.py:upload_file():2765] upload_file exception https://storage.googleapis.com/wandb-production.appspot.com/dynamic_x/bert_pytorch/0vfv9wkn/wandb-metadata.json?Expires=1706688636&GoogleAccessId=gorilla-files-url-signer-man%40wandb-production.iam.gserviceaccount.com&Signature=TOE9Ck7npWvU2grZxrdepfkP7GGkjk2DxVjQW47W2UtaiiUt9kEhpI8qATqI9uozu9XFTPhU9B87d%2B31EOqc9ZxpA3r1tpLJ5J7Plx6BWPUp5B1h1IqJ7JfEnxhfv1KuBRsZ4ZG3gHKdTgEWAXjynDk78cVjyKp5vBw2jOFC4mRI1vjmETrSdu%2BYuLu%2FICD3Nn2TKxzd0d60n9W08r6kTgtEFZZTNPhXe2Jk74oVaKOAuf50B2cELpiGPX2IRImbiSKjqs3lFWxZWaUFL23Qk82VimFqiSWHwpjIE5BQOJf04g41QgvonPnCiDTPQOMZgpAuOSqgczyaRNBOPFqrQQ%3D%3D: HTTPSConnectionPool(host='storage.googleapis.com', port=443): Max retries exceeded with url: /wandb-production.appspot.com/dynamic_x/bert_pytorch/0vfv9wkn/wandb-metadata.json?Expires=1706688636&GoogleAccessId=gorilla-files-url-signer-man%40wandb-production.iam.gserviceaccount.com&Signature=TOE9Ck7npWvU2grZxrdepfkP7GGkjk2DxVjQW47W2UtaiiUt9kEhpI8qATqI9uozu9XFTPhU9B87d%2B31EOqc9ZxpA3r1tpLJ5J7Plx6BWPUp5B1h1IqJ7JfEnxhfv1KuBRsZ4ZG3gHKdTgEWAXjynDk78cVjyKp5vBw2jOFC4mRI1vjmETrSdu%2BYuLu%2FICD3Nn2TKxzd0d60n9W08r6kTgtEFZZTNPhXe2Jk74oVaKOAuf50B2cELpiGPX2IRImbiSKjqs3lFWxZWaUFL23Qk82VimFqiSWHwpjIE5BQOJf04g41QgvonPnCiDTPQOMZgpAuOSqgczyaRNBOPFqrQQ%3D%3D (Caused by NewConnectionError('<urllib3.connection.HTTPSConnection object at 0x7f31a005d9a0>: Failed to establish a new connection: [Errno 111] Connection refused'))
2024-01-30 16:11:11,551 ERROR   wandb-upload_0:1134331 [internal_api.py:upload_file():2767] upload_file request headers: {'User-Agent': 'python-requests/2.23.0', 'Accept-Encoding': 'gzip, deflate', 'Accept': '*/*', 'Connection': 'keep-alive', 'Content-Length': '15546'}
2024-01-30 16:11:11,551 ERROR   wandb-upload_0:1134331 [internal_api.py:upload_file():2769] upload_file response body: 
2024-01-30 16:11:14,995 DEBUG   SystemMonitor:1134331 [system_monitor.py:_start():172] Starting system metrics aggregation loop
2024-01-30 16:11:14,999 DEBUG   SenderThread:1134331 [sender.py:send():382] send: stats
2024-01-30 16:11:17,001 DEBUG   HandlerThread:1134331 [handler.py:handle_request():146] handle_request: status_report
2024-01-30 16:11:20,862 DEBUG   HandlerThread:1134331 [handler.py:handle_request():146] handle_request: stop_status
2024-01-30 16:11:20,863 DEBUG   SenderThread:1134331 [sender.py:send_request():409] send_request: stop_status
2024-01-30 16:11:20,906 DEBUG   HandlerThread:1134331 [handler.py:handle_request():146] handle_request: internal_messages
2024-01-30 16:11:22,189 DEBUG   HandlerThread:1134331 [handler.py:handle_request():146] handle_request: status_report
2024-01-30 16:11:27,237 DEBUG   HandlerThread:1134331 [handler.py:handle_request():146] handle_request: status_report
2024-01-30 16:11:32,277 DEBUG   HandlerThread:1134331 [handler.py:handle_request():146] handle_request: status_report
2024-01-30 16:11:35,863 DEBUG   HandlerThread:1134331 [handler.py:handle_request():146] handle_request: stop_status
2024-01-30 16:11:35,863 DEBUG   SenderThread:1134331 [sender.py:send_request():409] send_request: stop_status
2024-01-30 16:11:35,926 DEBUG   HandlerThread:1134331 [handler.py:handle_request():146] handle_request: internal_messages
2024-01-30 16:11:38,193 DEBUG   HandlerThread:1134331 [handler.py:handle_request():146] handle_request: status_report
2024-01-30 16:11:43,201 DEBUG   HandlerThread:1134331 [handler.py:handle_request():146] handle_request: status_report
2024-01-30 16:11:45,002 DEBUG   SenderThread:1134331 [sender.py:send():382] send: stats
2024-01-30 16:11:48,895 ERROR   wandb-upload_0:1134331 [internal_api.py:upload_file():2765] upload_file exception https://storage.googleapis.com/wandb-production.appspot.com/dynamic_x/bert_pytorch/0vfv9wkn/wandb-metadata.json?Expires=1706688636&GoogleAccessId=gorilla-files-url-signer-man%40wandb-production.iam.gserviceaccount.com&Signature=TOE9Ck7npWvU2grZxrdepfkP7GGkjk2DxVjQW47W2UtaiiUt9kEhpI8qATqI9uozu9XFTPhU9B87d%2B31EOqc9ZxpA3r1tpLJ5J7Plx6BWPUp5B1h1IqJ7JfEnxhfv1KuBRsZ4ZG3gHKdTgEWAXjynDk78cVjyKp5vBw2jOFC4mRI1vjmETrSdu%2BYuLu%2FICD3Nn2TKxzd0d60n9W08r6kTgtEFZZTNPhXe2Jk74oVaKOAuf50B2cELpiGPX2IRImbiSKjqs3lFWxZWaUFL23Qk82VimFqiSWHwpjIE5BQOJf04g41QgvonPnCiDTPQOMZgpAuOSqgczyaRNBOPFqrQQ%3D%3D: HTTPSConnectionPool(host='storage.googleapis.com', port=443): Max retries exceeded with url: /wandb-production.appspot.com/dynamic_x/bert_pytorch/0vfv9wkn/wandb-metadata.json?Expires=1706688636&GoogleAccessId=gorilla-files-url-signer-man%40wandb-production.iam.gserviceaccount.com&Signature=TOE9Ck7npWvU2grZxrdepfkP7GGkjk2DxVjQW47W2UtaiiUt9kEhpI8qATqI9uozu9XFTPhU9B87d%2B31EOqc9ZxpA3r1tpLJ5J7Plx6BWPUp5B1h1IqJ7JfEnxhfv1KuBRsZ4ZG3gHKdTgEWAXjynDk78cVjyKp5vBw2jOFC4mRI1vjmETrSdu%2BYuLu%2FICD3Nn2TKxzd0d60n9W08r6kTgtEFZZTNPhXe2Jk74oVaKOAuf50B2cELpiGPX2IRImbiSKjqs3lFWxZWaUFL23Qk82VimFqiSWHwpjIE5BQOJf04g41QgvonPnCiDTPQOMZgpAuOSqgczyaRNBOPFqrQQ%3D%3D (Caused by NewConnectionError('<urllib3.connection.HTTPSConnection object at 0x7f31a0130b50>: Failed to establish a new connection: [Errno 101] Network is unreachable'))
2024-01-30 16:11:48,895 ERROR   wandb-upload_0:1134331 [internal_api.py:upload_file():2767] upload_file request headers: {'User-Agent': 'python-requests/2.23.0', 'Accept-Encoding': 'gzip, deflate', 'Accept': '*/*', 'Connection': 'keep-alive', 'Content-Length': '15546'}
2024-01-30 16:11:48,895 ERROR   wandb-upload_0:1134331 [internal_api.py:upload_file():2769] upload_file response body: 
2024-01-30 16:11:49,003 DEBUG   HandlerThread:1134331 [handler.py:handle_request():146] handle_request: status_report
2024-01-30 16:11:50,863 DEBUG   HandlerThread:1134331 [handler.py:handle_request():146] handle_request: stop_status
2024-01-30 16:11:50,863 DEBUG   SenderThread:1134331 [sender.py:send_request():409] send_request: stop_status
2024-01-30 16:11:50,906 DEBUG   HandlerThread:1134331 [handler.py:handle_request():146] handle_request: internal_messages
2024-01-30 16:11:54,142 DEBUG   HandlerThread:1134331 [handler.py:handle_request():146] handle_request: status_report
2024-01-30 16:11:55,215 INFO    Thread-12 :1134331 [dir_watcher.py:_on_file_created():271] file/dir created: /home/yanxindong/mkor/bert/wandb/run-20240130_161012-0vfv9wkn/files/output.log
2024-01-30 16:11:57,216 INFO    Thread-12 :1134331 [dir_watcher.py:_on_file_modified():288] file/dir modified: /home/yanxindong/mkor/bert/wandb/run-20240130_161012-0vfv9wkn/files/output.log
2024-01-30 16:11:59,201 DEBUG   HandlerThread:1134331 [handler.py:handle_request():146] handle_request: status_report
2024-01-30 16:12:04,201 DEBUG   HandlerThread:1134331 [handler.py:handle_request():146] handle_request: status_report
2024-01-30 16:12:07,238 DEBUG   HandlerThread:1134331 [handler.py:handle_request():146] handle_request: internal_messages
2024-01-30 16:12:07,244 DEBUG   HandlerThread:1134331 [handler.py:handle_request():146] handle_request: stop_status
2024-01-30 16:12:07,244 DEBUG   SenderThread:1134331 [sender.py:send_request():409] send_request: stop_status
2024-01-30 16:12:09,593 DEBUG   HandlerThread:1134331 [handler.py:handle_request():146] handle_request: status_report
2024-01-30 16:12:14,840 DEBUG   HandlerThread:1134331 [handler.py:handle_request():146] handle_request: status_report
2024-01-30 16:12:15,004 DEBUG   SenderThread:1134331 [sender.py:send():382] send: stats
2024-01-30 16:12:20,051 DEBUG   HandlerThread:1134331 [handler.py:handle_request():146] handle_request: status_report
2024-01-30 16:12:22,289 DEBUG   HandlerThread:1134331 [handler.py:handle_request():146] handle_request: stop_status
2024-01-30 16:12:22,290 DEBUG   HandlerThread:1134331 [handler.py:handle_request():146] handle_request: internal_messages
2024-01-30 16:12:22,290 DEBUG   SenderThread:1134331 [sender.py:send_request():409] send_request: stop_status
2024-01-30 16:12:25,812 DEBUG   HandlerThread:1134331 [handler.py:handle_request():146] handle_request: status_report
2024-01-30 16:12:30,874 DEBUG   HandlerThread:1134331 [handler.py:handle_request():146] handle_request: status_report
2024-01-30 16:12:35,930 DEBUG   HandlerThread:1134331 [handler.py:handle_request():146] handle_request: status_report
2024-01-30 16:12:37,289 DEBUG   HandlerThread:1134331 [handler.py:handle_request():146] handle_request: stop_status
2024-01-30 16:12:37,290 DEBUG   HandlerThread:1134331 [handler.py:handle_request():146] handle_request: internal_messages
2024-01-30 16:12:37,290 DEBUG   SenderThread:1134331 [sender.py:send_request():409] send_request: stop_status
2024-01-30 16:12:41,904 DEBUG   HandlerThread:1134331 [handler.py:handle_request():146] handle_request: status_report
2024-01-30 16:12:45,007 DEBUG   SenderThread:1134331 [sender.py:send():382] send: stats
2024-01-30 16:12:47,008 DEBUG   HandlerThread:1134331 [handler.py:handle_request():146] handle_request: status_report
2024-01-30 16:12:52,009 DEBUG   HandlerThread:1134331 [handler.py:handle_request():146] handle_request: status_report
2024-01-30 16:12:52,238 DEBUG   HandlerThread:1134331 [handler.py:handle_request():146] handle_request: stop_status
2024-01-30 16:12:52,238 DEBUG   SenderThread:1134331 [sender.py:send_request():409] send_request: stop_status
2024-01-30 16:12:52,242 DEBUG   HandlerThread:1134331 [handler.py:handle_request():146] handle_request: internal_messages
2024-01-30 16:12:57,524 DEBUG   HandlerThread:1134331 [handler.py:handle_request():146] handle_request: status_report
2024-01-30 16:13:02,524 DEBUG   HandlerThread:1134331 [handler.py:handle_request():146] handle_request: status_report
2024-01-30 16:13:07,238 DEBUG   HandlerThread:1134331 [handler.py:handle_request():146] handle_request: stop_status
2024-01-30 16:13:07,238 DEBUG   SenderThread:1134331 [sender.py:send_request():409] send_request: stop_status
2024-01-30 16:13:07,281 DEBUG   HandlerThread:1134331 [handler.py:handle_request():146] handle_request: internal_messages
2024-01-30 16:13:07,550 ERROR   wandb-upload_0:1134331 [internal_api.py:upload_file():2765] upload_file exception https://storage.googleapis.com/wandb-production.appspot.com/dynamic_x/bert_pytorch/0vfv9wkn/wandb-metadata.json?Expires=1706688636&GoogleAccessId=gorilla-files-url-signer-man%40wandb-production.iam.gserviceaccount.com&Signature=TOE9Ck7npWvU2grZxrdepfkP7GGkjk2DxVjQW47W2UtaiiUt9kEhpI8qATqI9uozu9XFTPhU9B87d%2B31EOqc9ZxpA3r1tpLJ5J7Plx6BWPUp5B1h1IqJ7JfEnxhfv1KuBRsZ4ZG3gHKdTgEWAXjynDk78cVjyKp5vBw2jOFC4mRI1vjmETrSdu%2BYuLu%2FICD3Nn2TKxzd0d60n9W08r6kTgtEFZZTNPhXe2Jk74oVaKOAuf50B2cELpiGPX2IRImbiSKjqs3lFWxZWaUFL23Qk82VimFqiSWHwpjIE5BQOJf04g41QgvonPnCiDTPQOMZgpAuOSqgczyaRNBOPFqrQQ%3D%3D: HTTPSConnectionPool(host='storage.googleapis.com', port=443): Max retries exceeded with url: /wandb-production.appspot.com/dynamic_x/bert_pytorch/0vfv9wkn/wandb-metadata.json?Expires=1706688636&GoogleAccessId=gorilla-files-url-signer-man%40wandb-production.iam.gserviceaccount.com&Signature=TOE9Ck7npWvU2grZxrdepfkP7GGkjk2DxVjQW47W2UtaiiUt9kEhpI8qATqI9uozu9XFTPhU9B87d%2B31EOqc9ZxpA3r1tpLJ5J7Plx6BWPUp5B1h1IqJ7JfEnxhfv1KuBRsZ4ZG3gHKdTgEWAXjynDk78cVjyKp5vBw2jOFC4mRI1vjmETrSdu%2BYuLu%2FICD3Nn2TKxzd0d60n9W08r6kTgtEFZZTNPhXe2Jk74oVaKOAuf50B2cELpiGPX2IRImbiSKjqs3lFWxZWaUFL23Qk82VimFqiSWHwpjIE5BQOJf04g41QgvonPnCiDTPQOMZgpAuOSqgczyaRNBOPFqrQQ%3D%3D (Caused by NewConnectionError('<urllib3.connection.HTTPSConnection object at 0x7f31a0123a00>: Failed to establish a new connection: [Errno 101] Network is unreachable'))
2024-01-30 16:13:07,550 ERROR   wandb-upload_0:1134331 [internal_api.py:upload_file():2767] upload_file request headers: {'User-Agent': 'python-requests/2.23.0', 'Accept-Encoding': 'gzip, deflate', 'Accept': '*/*', 'Connection': 'keep-alive', 'Content-Length': '15546'}
2024-01-30 16:13:07,550 ERROR   wandb-upload_0:1134331 [internal_api.py:upload_file():2769] upload_file response body: 
2024-01-30 16:13:07,558 DEBUG   HandlerThread:1134331 [handler.py:handle_request():146] handle_request: status_report
2024-01-30 16:13:12,559 DEBUG   HandlerThread:1134331 [handler.py:handle_request():146] handle_request: status_report
2024-01-30 16:13:15,139 DEBUG   SenderThread:1134331 [sender.py:send():382] send: stats
2024-01-30 16:13:18,147 DEBUG   HandlerThread:1134331 [handler.py:handle_request():146] handle_request: status_report
2024-01-30 16:13:22,239 DEBUG   HandlerThread:1134331 [handler.py:handle_request():146] handle_request: stop_status
2024-01-30 16:13:22,239 DEBUG   SenderThread:1134331 [sender.py:send_request():409] send_request: stop_status
2024-01-30 16:13:22,281 DEBUG   HandlerThread:1134331 [handler.py:handle_request():146] handle_request: internal_messages
2024-01-30 16:13:23,501 DEBUG   HandlerThread:1134331 [handler.py:handle_request():146] handle_request: status_report
2024-01-30 16:13:28,546 DEBUG   HandlerThread:1134331 [handler.py:handle_request():146] handle_request: status_report
2024-01-30 16:13:33,562 DEBUG   HandlerThread:1134331 [handler.py:handle_request():146] handle_request: status_report
2024-01-30 16:13:37,256 DEBUG   HandlerThread:1134331 [handler.py:handle_request():146] handle_request: stop_status
2024-01-30 16:13:37,257 DEBUG   SenderThread:1134331 [sender.py:send_request():409] send_request: stop_status
2024-01-30 16:13:37,281 DEBUG   HandlerThread:1134331 [handler.py:handle_request():146] handle_request: internal_messages
2024-01-30 16:13:38,615 DEBUG   HandlerThread:1134331 [handler.py:handle_request():146] handle_request: status_report
2024-01-30 16:13:43,741 DEBUG   HandlerThread:1134331 [handler.py:handle_request():146] handle_request: status_report
2024-01-30 16:13:45,142 DEBUG   SenderThread:1134331 [sender.py:send():382] send: stats
2024-01-30 16:13:49,144 DEBUG   HandlerThread:1134331 [handler.py:handle_request():146] handle_request: status_report
2024-01-30 16:13:52,239 DEBUG   HandlerThread:1134331 [handler.py:handle_request():146] handle_request: stop_status
2024-01-30 16:13:52,239 DEBUG   SenderThread:1134331 [sender.py:send_request():409] send_request: stop_status
2024-01-30 16:13:52,281 DEBUG   HandlerThread:1134331 [handler.py:handle_request():146] handle_request: internal_messages
2024-01-30 16:13:54,523 DEBUG   HandlerThread:1134331 [handler.py:handle_request():146] handle_request: status_report
2024-01-30 16:13:59,524 DEBUG   HandlerThread:1134331 [handler.py:handle_request():146] handle_request: status_report
2024-01-30 16:14:04,525 DEBUG   HandlerThread:1134331 [handler.py:handle_request():146] handle_request: status_report
2024-01-30 16:14:07,239 DEBUG   HandlerThread:1134331 [handler.py:handle_request():146] handle_request: stop_status
2024-01-30 16:14:07,239 DEBUG   SenderThread:1134331 [sender.py:send_request():409] send_request: stop_status
2024-01-30 16:14:07,281 DEBUG   HandlerThread:1134331 [handler.py:handle_request():146] handle_request: internal_messages
2024-01-30 16:14:09,617 DEBUG   HandlerThread:1134331 [handler.py:handle_request():146] handle_request: status_report
2024-01-30 16:14:14,617 DEBUG   HandlerThread:1134331 [handler.py:handle_request():146] handle_request: status_report
2024-01-30 16:14:15,144 DEBUG   SenderThread:1134331 [sender.py:send():382] send: stats
2024-01-30 16:14:20,201 DEBUG   HandlerThread:1134331 [handler.py:handle_request():146] handle_request: status_report
2024-01-30 16:14:22,239 DEBUG   HandlerThread:1134331 [handler.py:handle_request():146] handle_request: stop_status
2024-01-30 16:14:22,239 DEBUG   SenderThread:1134331 [sender.py:send_request():409] send_request: stop_status
2024-01-30 16:14:22,339 DEBUG   HandlerThread:1134331 [handler.py:handle_request():146] handle_request: internal_messages
2024-01-30 16:14:25,691 DEBUG   HandlerThread:1134331 [handler.py:handle_request():146] handle_request: status_report
2024-01-30 16:14:30,742 DEBUG   HandlerThread:1134331 [handler.py:handle_request():146] handle_request: status_report
2024-01-30 16:14:35,864 DEBUG   HandlerThread:1134331 [handler.py:handle_request():146] handle_request: status_report
2024-01-30 16:14:37,240 DEBUG   HandlerThread:1134331 [handler.py:handle_request():146] handle_request: stop_status
2024-01-30 16:14:37,240 DEBUG   SenderThread:1134331 [sender.py:send_request():409] send_request: stop_status
2024-01-30 16:14:37,245 DEBUG   HandlerThread:1134331 [handler.py:handle_request():146] handle_request: internal_messages
2024-01-30 16:14:41,664 DEBUG   HandlerThread:1134331 [handler.py:handle_request():146] handle_request: status_report
2024-01-30 16:14:45,155 DEBUG   SenderThread:1134331 [sender.py:send():382] send: stats
2024-01-30 16:14:47,157 DEBUG   HandlerThread:1134331 [handler.py:handle_request():146] handle_request: status_report
2024-01-30 16:14:52,157 DEBUG   HandlerThread:1134331 [handler.py:handle_request():146] handle_request: status_report
2024-01-30 16:14:52,240 DEBUG   HandlerThread:1134331 [handler.py:handle_request():146] handle_request: stop_status
2024-01-30 16:14:52,240 DEBUG   SenderThread:1134331 [sender.py:send_request():409] send_request: stop_status
2024-01-30 16:14:52,285 DEBUG   HandlerThread:1134331 [handler.py:handle_request():146] handle_request: internal_messages
2024-01-30 16:14:57,587 DEBUG   HandlerThread:1134331 [handler.py:handle_request():146] handle_request: status_report
2024-01-30 16:15:02,588 DEBUG   HandlerThread:1134331 [handler.py:handle_request():146] handle_request: status_report
2024-01-30 16:15:07,240 DEBUG   HandlerThread:1134331 [handler.py:handle_request():146] handle_request: stop_status
2024-01-30 16:15:07,240 DEBUG   SenderThread:1134331 [sender.py:send_request():409] send_request: stop_status
2024-01-30 16:15:07,281 DEBUG   HandlerThread:1134331 [handler.py:handle_request():146] handle_request: internal_messages
2024-01-30 16:15:08,563 DEBUG   HandlerThread:1134331 [handler.py:handle_request():146] handle_request: status_report
2024-01-30 16:15:13,564 DEBUG   HandlerThread:1134331 [handler.py:handle_request():146] handle_request: status_report
2024-01-30 16:15:15,158 DEBUG   SenderThread:1134331 [sender.py:send():382] send: stats
2024-01-30 16:15:19,312 DEBUG   HandlerThread:1134331 [handler.py:handle_request():146] handle_request: status_report
2024-01-30 16:15:22,240 DEBUG   HandlerThread:1134331 [handler.py:handle_request():146] handle_request: stop_status
2024-01-30 16:15:22,241 DEBUG   SenderThread:1134331 [sender.py:send_request():409] send_request: stop_status
2024-01-30 16:15:22,281 DEBUG   HandlerThread:1134331 [handler.py:handle_request():146] handle_request: internal_messages
2024-01-30 16:15:24,531 DEBUG   HandlerThread:1134331 [handler.py:handle_request():146] handle_request: status_report
2024-01-30 16:15:28,429 ERROR   wandb-upload_0:1134331 [internal_api.py:upload_file():2765] upload_file exception https://storage.googleapis.com/wandb-production.appspot.com/dynamic_x/bert_pytorch/0vfv9wkn/wandb-metadata.json?Expires=1706688636&GoogleAccessId=gorilla-files-url-signer-man%40wandb-production.iam.gserviceaccount.com&Signature=TOE9Ck7npWvU2grZxrdepfkP7GGkjk2DxVjQW47W2UtaiiUt9kEhpI8qATqI9uozu9XFTPhU9B87d%2B31EOqc9ZxpA3r1tpLJ5J7Plx6BWPUp5B1h1IqJ7JfEnxhfv1KuBRsZ4ZG3gHKdTgEWAXjynDk78cVjyKp5vBw2jOFC4mRI1vjmETrSdu%2BYuLu%2FICD3Nn2TKxzd0d60n9W08r6kTgtEFZZTNPhXe2Jk74oVaKOAuf50B2cELpiGPX2IRImbiSKjqs3lFWxZWaUFL23Qk82VimFqiSWHwpjIE5BQOJf04g41QgvonPnCiDTPQOMZgpAuOSqgczyaRNBOPFqrQQ%3D%3D: HTTPSConnectionPool(host='storage.googleapis.com', port=443): Max retries exceeded with url: /wandb-production.appspot.com/dynamic_x/bert_pytorch/0vfv9wkn/wandb-metadata.json?Expires=1706688636&GoogleAccessId=gorilla-files-url-signer-man%40wandb-production.iam.gserviceaccount.com&Signature=TOE9Ck7npWvU2grZxrdepfkP7GGkjk2DxVjQW47W2UtaiiUt9kEhpI8qATqI9uozu9XFTPhU9B87d%2B31EOqc9ZxpA3r1tpLJ5J7Plx6BWPUp5B1h1IqJ7JfEnxhfv1KuBRsZ4ZG3gHKdTgEWAXjynDk78cVjyKp5vBw2jOFC4mRI1vjmETrSdu%2BYuLu%2FICD3Nn2TKxzd0d60n9W08r6kTgtEFZZTNPhXe2Jk74oVaKOAuf50B2cELpiGPX2IRImbiSKjqs3lFWxZWaUFL23Qk82VimFqiSWHwpjIE5BQOJf04g41QgvonPnCiDTPQOMZgpAuOSqgczyaRNBOPFqrQQ%3D%3D (Caused by NewConnectionError('<urllib3.connection.HTTPSConnection object at 0x7f31a0157cd0>: Failed to establish a new connection: [Errno 101] Network is unreachable'))
2024-01-30 16:15:28,429 ERROR   wandb-upload_0:1134331 [internal_api.py:upload_file():2767] upload_file request headers: {'User-Agent': 'python-requests/2.23.0', 'Accept-Encoding': 'gzip, deflate', 'Accept': '*/*', 'Connection': 'keep-alive', 'Content-Length': '15546'}
2024-01-30 16:15:28,429 ERROR   wandb-upload_0:1134331 [internal_api.py:upload_file():2769] upload_file response body: 
2024-01-30 16:15:29,550 DEBUG   HandlerThread:1134331 [handler.py:handle_request():146] handle_request: status_report
2024-01-30 16:15:34,645 DEBUG   HandlerThread:1134331 [handler.py:handle_request():146] handle_request: status_report
2024-01-30 16:15:37,314 DEBUG   HandlerThread:1134331 [handler.py:handle_request():146] handle_request: stop_status
2024-01-30 16:15:37,314 DEBUG   HandlerThread:1134331 [handler.py:handle_request():146] handle_request: internal_messages
2024-01-30 16:15:37,314 DEBUG   SenderThread:1134331 [sender.py:send_request():409] send_request: stop_status
2024-01-30 16:15:40,606 DEBUG   HandlerThread:1134331 [handler.py:handle_request():146] handle_request: status_report
2024-01-30 16:15:45,160 DEBUG   SenderThread:1134331 [sender.py:send():382] send: stats
2024-01-30 16:15:46,161 DEBUG   HandlerThread:1134331 [handler.py:handle_request():146] handle_request: status_report
2024-01-30 16:15:51,162 DEBUG   HandlerThread:1134331 [handler.py:handle_request():146] handle_request: status_report
2024-01-30 16:15:52,240 DEBUG   HandlerThread:1134331 [handler.py:handle_request():146] handle_request: stop_status
2024-01-30 16:15:52,241 DEBUG   SenderThread:1134331 [sender.py:send_request():409] send_request: stop_status
2024-01-30 16:15:52,281 DEBUG   HandlerThread:1134331 [handler.py:handle_request():146] handle_request: internal_messages
2024-01-30 16:15:56,582 DEBUG   HandlerThread:1134331 [handler.py:handle_request():146] handle_request: status_report
2024-01-30 16:16:01,583 DEBUG   HandlerThread:1134331 [handler.py:handle_request():146] handle_request: status_report
2024-01-30 16:16:06,584 DEBUG   HandlerThread:1134331 [handler.py:handle_request():146] handle_request: status_report
2024-01-30 16:16:07,158 DEBUG   SenderThread:1134331 [sender.py:send():382] send: exit
2024-01-30 16:16:07,159 INFO    SenderThread:1134331 [sender.py:send_exit():589] handling exit code: 1
2024-01-30 16:16:07,159 INFO    SenderThread:1134331 [sender.py:send_exit():591] handling runtime: 352
2024-01-30 16:16:07,159 INFO    SenderThread:1134331 [sender.py:_save_file():1403] saving file wandb-summary.json with policy end
2024-01-30 16:16:07,159 INFO    SenderThread:1134331 [sender.py:send_exit():597] send defer
2024-01-30 16:16:07,160 DEBUG   HandlerThread:1134331 [handler.py:handle_request():146] handle_request: defer
2024-01-30 16:16:07,160 INFO    HandlerThread:1134331 [handler.py:handle_request_defer():172] handle defer: 0
2024-01-30 16:16:07,160 DEBUG   SenderThread:1134331 [sender.py:send_request():409] send_request: defer
2024-01-30 16:16:07,160 INFO    SenderThread:1134331 [sender.py:send_request_defer():613] handle sender defer: 0
2024-01-30 16:16:07,160 INFO    SenderThread:1134331 [sender.py:transition_state():617] send defer: 1
2024-01-30 16:16:07,160 DEBUG   HandlerThread:1134331 [handler.py:handle_request():146] handle_request: defer
2024-01-30 16:16:07,160 INFO    HandlerThread:1134331 [handler.py:handle_request_defer():172] handle defer: 1
2024-01-30 16:16:07,160 DEBUG   SenderThread:1134331 [sender.py:send_request():409] send_request: defer
2024-01-30 16:16:07,160 INFO    SenderThread:1134331 [sender.py:send_request_defer():613] handle sender defer: 1
2024-01-30 16:16:07,160 INFO    SenderThread:1134331 [sender.py:transition_state():617] send defer: 2
2024-01-30 16:16:07,160 DEBUG   HandlerThread:1134331 [handler.py:handle_request():146] handle_request: defer
2024-01-30 16:16:07,160 INFO    HandlerThread:1134331 [handler.py:handle_request_defer():172] handle defer: 2
2024-01-30 16:16:07,160 INFO    HandlerThread:1134331 [system_monitor.py:finish():203] Stopping system monitor
2024-01-30 16:16:07,160 DEBUG   SystemMonitor:1134331 [system_monitor.py:_start():179] Finished system metrics aggregation loop
2024-01-30 16:16:07,160 DEBUG   SystemMonitor:1134331 [system_monitor.py:_start():183] Publishing last batch of metrics
2024-01-30 16:16:07,169 INFO    HandlerThread:1134331 [interfaces.py:finish():202] Joined cpu monitor
2024-01-30 16:16:07,170 INFO    HandlerThread:1134331 [interfaces.py:finish():202] Joined disk monitor
2024-01-30 16:16:07,966 INFO    Thread-12 :1134331 [dir_watcher.py:_on_file_created():271] file/dir created: /home/yanxindong/mkor/bert/wandb/run-20240130_161012-0vfv9wkn/files/wandb-summary.json
2024-01-30 16:16:08,978 INFO    Thread-12 :1134331 [dir_watcher.py:_on_file_modified():288] file/dir modified: /home/yanxindong/mkor/bert/wandb/run-20240130_161012-0vfv9wkn/files/output.log
2024-01-30 16:16:16,339 INFO    HandlerThread:1134331 [interfaces.py:finish():202] Joined gpu monitor
2024-01-30 16:16:16,339 INFO    HandlerThread:1134331 [interfaces.py:finish():202] Joined memory monitor
2024-01-30 16:16:16,339 INFO    HandlerThread:1134331 [interfaces.py:finish():202] Joined network monitor
2024-01-30 16:16:16,339 DEBUG   HandlerThread:1134331 [handler.py:handle_request():146] handle_request: poll_exit
2024-01-30 16:16:16,340 DEBUG   HandlerThread:1134331 [handler.py:handle_request():146] handle_request: status_report
2024-01-30 16:16:16,340 DEBUG   HandlerThread:1134331 [handler.py:handle_request():146] handle_request: keepalive
2024-01-30 16:16:16,340 DEBUG   SenderThread:1134331 [sender.py:send_request():409] send_request: defer
2024-01-30 16:16:16,340 INFO    SenderThread:1134331 [sender.py:send_request_defer():613] handle sender defer: 2
2024-01-30 16:16:16,340 INFO    SenderThread:1134331 [sender.py:transition_state():617] send defer: 3
2024-01-30 16:16:16,341 DEBUG   SenderThread:1134331 [sender.py:send():382] send: stats
2024-01-30 16:16:16,342 DEBUG   SenderThread:1134331 [sender.py:send_request():409] send_request: poll_exit
2024-01-30 16:16:16,344 DEBUG   HandlerThread:1134331 [handler.py:handle_request():146] handle_request: defer
2024-01-30 16:16:16,344 INFO    HandlerThread:1134331 [handler.py:handle_request_defer():172] handle defer: 3
2024-01-30 16:16:16,344 DEBUG   SenderThread:1134331 [sender.py:send_request():409] send_request: defer
2024-01-30 16:16:16,344 INFO    SenderThread:1134331 [sender.py:send_request_defer():613] handle sender defer: 3
2024-01-30 16:16:16,344 INFO    SenderThread:1134331 [sender.py:transition_state():617] send defer: 4
2024-01-30 16:16:16,345 DEBUG   HandlerThread:1134331 [handler.py:handle_request():146] handle_request: defer
2024-01-30 16:16:16,345 INFO    HandlerThread:1134331 [handler.py:handle_request_defer():172] handle defer: 4
2024-01-30 16:16:16,345 DEBUG   SenderThread:1134331 [sender.py:send_request():409] send_request: defer
2024-01-30 16:16:16,345 INFO    SenderThread:1134331 [sender.py:send_request_defer():613] handle sender defer: 4
2024-01-30 16:16:16,345 INFO    SenderThread:1134331 [sender.py:transition_state():617] send defer: 5
2024-01-30 16:16:16,345 DEBUG   HandlerThread:1134331 [handler.py:handle_request():146] handle_request: defer
2024-01-30 16:16:16,345 INFO    HandlerThread:1134331 [handler.py:handle_request_defer():172] handle defer: 5
2024-01-30 16:16:16,345 DEBUG   SenderThread:1134331 [sender.py:send():382] send: summary
2024-01-30 16:16:16,345 INFO    SenderThread:1134331 [sender.py:_save_file():1403] saving file wandb-summary.json with policy end
2024-01-30 16:16:16,346 DEBUG   SenderThread:1134331 [sender.py:send_request():409] send_request: defer
2024-01-30 16:16:16,346 INFO    SenderThread:1134331 [sender.py:send_request_defer():613] handle sender defer: 5
2024-01-30 16:16:16,346 INFO    SenderThread:1134331 [sender.py:transition_state():617] send defer: 6
2024-01-30 16:16:16,346 DEBUG   HandlerThread:1134331 [handler.py:handle_request():146] handle_request: defer
2024-01-30 16:16:16,346 INFO    HandlerThread:1134331 [handler.py:handle_request_defer():172] handle defer: 6
2024-01-30 16:16:16,346 DEBUG   SenderThread:1134331 [sender.py:send_request():409] send_request: defer
2024-01-30 16:16:16,346 INFO    SenderThread:1134331 [sender.py:send_request_defer():613] handle sender defer: 6
2024-01-30 16:16:16,346 INFO    SenderThread:1134331 [sender.py:transition_state():617] send defer: 7
2024-01-30 16:16:16,346 DEBUG   HandlerThread:1134331 [handler.py:handle_request():146] handle_request: status_report
2024-01-30 16:16:16,346 DEBUG   HandlerThread:1134331 [handler.py:handle_request():146] handle_request: defer
2024-01-30 16:16:16,346 INFO    HandlerThread:1134331 [handler.py:handle_request_defer():172] handle defer: 7
2024-01-30 16:16:16,346 DEBUG   SenderThread:1134331 [sender.py:send_request():409] send_request: defer
2024-01-30 16:16:16,346 INFO    SenderThread:1134331 [sender.py:send_request_defer():613] handle sender defer: 7
2024-01-30 16:16:16,703 INFO    SenderThread:1134331 [sender.py:transition_state():617] send defer: 8
2024-01-30 16:16:16,704 DEBUG   HandlerThread:1134331 [handler.py:handle_request():146] handle_request: defer
2024-01-30 16:16:16,704 INFO    HandlerThread:1134331 [handler.py:handle_request_defer():172] handle defer: 8
2024-01-30 16:16:16,704 DEBUG   SenderThread:1134331 [sender.py:send_request():409] send_request: defer
2024-01-30 16:16:16,704 INFO    SenderThread:1134331 [sender.py:send_request_defer():613] handle sender defer: 8
2024-01-30 16:16:16,704 INFO    SenderThread:1134331 [job_builder.py:build():296] Attempting to build job artifact
2024-01-30 16:16:16,704 INFO    SenderThread:1134331 [job_builder.py:_get_source_type():426] is repo sourced job
2024-01-30 16:16:16,877 INFO    SenderThread:1134331 [job_builder.py:build():402] adding wandb-job metadata file
2024-01-30 16:16:16,880 INFO    SenderThread:1134331 [sender.py:transition_state():617] send defer: 9
2024-01-30 16:16:16,880 DEBUG   HandlerThread:1134331 [handler.py:handle_request():146] handle_request: defer
2024-01-30 16:16:16,880 INFO    HandlerThread:1134331 [handler.py:handle_request_defer():172] handle defer: 9
2024-01-30 16:16:16,881 DEBUG   SenderThread:1134331 [sender.py:send():382] send: artifact
2024-01-30 16:16:17,022 INFO    Thread-12 :1134331 [dir_watcher.py:_on_file_modified():288] file/dir modified: /home/yanxindong/mkor/bert/wandb/run-20240130_161012-0vfv9wkn/files/output.log
2024-01-30 16:16:17,022 INFO    Thread-12 :1134331 [dir_watcher.py:_on_file_modified():288] file/dir modified: /home/yanxindong/mkor/bert/wandb/run-20240130_161012-0vfv9wkn/files/wandb-summary.json
2024-01-30 16:16:17,202 DEBUG   HandlerThread:1134331 [handler.py:handle_request():146] handle_request: poll_exit
2024-01-30 16:16:18,666 ERROR   wandb-upload_1:1134331 [internal_api.py:upload_file():2765] upload_file exception https://storage.googleapis.com/wandb-artifacts-prod/wandb_artifacts/133981200/707680482/174a3d9bc61fec126cc7d5bdff5c6c5a?Expires=1706688978&GoogleAccessId=gorilla-files-url-signer-man%40wandb-production.iam.gserviceaccount.com&Signature=cbtDPc9y%2ByNDqLWUkoqNfv9%2BFmv9BMiMrSHcAoresaF%2F5zpFnevKhT4IxSZwW8ln5fFnp1%2BGuAoFB8Vy%2B0KWZT2PFTA9h7493UfrojVdKstWKu1zMwGIIv9Ki%2B%2B0AI0Y4pqbVFEUyvyM0qKLgSBKKSXa4i3dBkvMbvm%2BaMOzuyJBYBno9cgiMJKY7PaT3qp%2FUk5Ng7h1cisaygxZjjbpolE9T1r3q2rR%2Bu%2FjC9mnSMhsafcXzn%2BKzDEPVbCHVWkSV5ZjBpVn6T4bLb9i9bpTm%2FDZc1I18cSR1stlp9OKN8i1uj4vPgWR%2Faio38JhkXkVcsgx6%2BAcWoQAo2X9g%2Fm8Mg%3D%3D: HTTPSConnectionPool(host='storage.googleapis.com', port=443): Max retries exceeded with url: /wandb-artifacts-prod/wandb_artifacts/133981200/707680482/174a3d9bc61fec126cc7d5bdff5c6c5a?Expires=1706688978&GoogleAccessId=gorilla-files-url-signer-man%40wandb-production.iam.gserviceaccount.com&Signature=cbtDPc9y%2ByNDqLWUkoqNfv9%2BFmv9BMiMrSHcAoresaF%2F5zpFnevKhT4IxSZwW8ln5fFnp1%2BGuAoFB8Vy%2B0KWZT2PFTA9h7493UfrojVdKstWKu1zMwGIIv9Ki%2B%2B0AI0Y4pqbVFEUyvyM0qKLgSBKKSXa4i3dBkvMbvm%2BaMOzuyJBYBno9cgiMJKY7PaT3qp%2FUk5Ng7h1cisaygxZjjbpolE9T1r3q2rR%2Bu%2FjC9mnSMhsafcXzn%2BKzDEPVbCHVWkSV5ZjBpVn6T4bLb9i9bpTm%2FDZc1I18cSR1stlp9OKN8i1uj4vPgWR%2Faio38JhkXkVcsgx6%2BAcWoQAo2X9g%2Fm8Mg%3D%3D (Caused by NewConnectionError('<urllib3.connection.HTTPSConnection object at 0x7f31a005d370>: Failed to establish a new connection: [Errno 101] Network is unreachable'))
2024-01-30 16:16:18,666 ERROR   wandb-upload_1:1134331 [internal_api.py:upload_file():2767] upload_file request headers: {'User-Agent': 'python-requests/2.23.0', 'Accept-Encoding': 'gzip, deflate', 'Accept': '*/*', 'Connection': 'keep-alive', 'Content-MD5': 'F0o9m8Yf7BJsx9W9/1xsWg==', 'Content-Type': 'text/plain; charset=utf-8', 'Content-Length': '2179'}
2024-01-30 16:16:18,666 ERROR   wandb-upload_1:1134331 [internal_api.py:upload_file():2769] upload_file response body: 
2024-01-30 16:16:19,226 ERROR   wandb-upload_2:1134331 [internal_api.py:upload_file():2765] upload_file exception https://storage.googleapis.com/wandb-artifacts-prod/wandb_artifacts/133981200/707680482/6873c23a2381d1524249eb1a948a45a5?Expires=1706688979&GoogleAccessId=gorilla-files-url-signer-man%40wandb-production.iam.gserviceaccount.com&Signature=UIXrVQypAxHgZq44Mo8m7DKDiOHx4COYTEbj552yh6Cp%2FURg0VnzG54tqZWNmFlghXrcWDl8YsQHDh%2FbuUoCI2eGmCVgBIvjGNTuiGXbH6NhhaAeyAz4CozwmGl98FVvP7bFO7Dz1mwcEIskDGug8qttLU3ROL182sGhTILhhaTyZnlgvCp%2FALjZa%2F2NhdhrUgS81lZoLXo4oHyINK%2FRazN3ypBFND8j6SUL1kEARakxPGrgK0Z3JUyvsvbOK81KVUmLPIojAGNB71JPYXIwwQdC3GPU%2FFcI9Cv1uN4Sb9j24oq2op2YpqAOfcYnerZVSMkBZIzld91LQg7%2BTQvDKQ%3D%3D: HTTPSConnectionPool(host='storage.googleapis.com', port=443): Max retries exceeded with url: /wandb-artifacts-prod/wandb_artifacts/133981200/707680482/6873c23a2381d1524249eb1a948a45a5?Expires=1706688979&GoogleAccessId=gorilla-files-url-signer-man%40wandb-production.iam.gserviceaccount.com&Signature=UIXrVQypAxHgZq44Mo8m7DKDiOHx4COYTEbj552yh6Cp%2FURg0VnzG54tqZWNmFlghXrcWDl8YsQHDh%2FbuUoCI2eGmCVgBIvjGNTuiGXbH6NhhaAeyAz4CozwmGl98FVvP7bFO7Dz1mwcEIskDGug8qttLU3ROL182sGhTILhhaTyZnlgvCp%2FALjZa%2F2NhdhrUgS81lZoLXo4oHyINK%2FRazN3ypBFND8j6SUL1kEARakxPGrgK0Z3JUyvsvbOK81KVUmLPIojAGNB71JPYXIwwQdC3GPU%2FFcI9Cv1uN4Sb9j24oq2op2YpqAOfcYnerZVSMkBZIzld91LQg7%2BTQvDKQ%3D%3D (Caused by NewConnectionError('<urllib3.connection.HTTPSConnection object at 0x7f31a005d5b0>: Failed to establish a new connection: [Errno 101] Network is unreachable'))
2024-01-30 16:16:19,226 ERROR   wandb-upload_2:1134331 [internal_api.py:upload_file():2767] upload_file request headers: {'User-Agent': 'python-requests/2.23.0', 'Accept-Encoding': 'gzip, deflate', 'Accept': '*/*', 'Connection': 'keep-alive', 'Content-MD5': 'aHPCOiOB0VJCSesalIpFpQ==', 'Content-Type': 'application/json', 'Content-Length': '609'}
2024-01-30 16:16:19,226 ERROR   wandb-upload_2:1134331 [internal_api.py:upload_file():2769] upload_file response body: 
2024-01-30 16:16:19,818 ERROR   wandb-upload_1:1134331 [internal_api.py:upload_file():2765] upload_file exception https://storage.googleapis.com/wandb-artifacts-prod/wandb_artifacts/133981200/707680482/174a3d9bc61fec126cc7d5bdff5c6c5a?Expires=1706688978&GoogleAccessId=gorilla-files-url-signer-man%40wandb-production.iam.gserviceaccount.com&Signature=cbtDPc9y%2ByNDqLWUkoqNfv9%2BFmv9BMiMrSHcAoresaF%2F5zpFnevKhT4IxSZwW8ln5fFnp1%2BGuAoFB8Vy%2B0KWZT2PFTA9h7493UfrojVdKstWKu1zMwGIIv9Ki%2B%2B0AI0Y4pqbVFEUyvyM0qKLgSBKKSXa4i3dBkvMbvm%2BaMOzuyJBYBno9cgiMJKY7PaT3qp%2FUk5Ng7h1cisaygxZjjbpolE9T1r3q2rR%2Bu%2FjC9mnSMhsafcXzn%2BKzDEPVbCHVWkSV5ZjBpVn6T4bLb9i9bpTm%2FDZc1I18cSR1stlp9OKN8i1uj4vPgWR%2Faio38JhkXkVcsgx6%2BAcWoQAo2X9g%2Fm8Mg%3D%3D: HTTPSConnectionPool(host='storage.googleapis.com', port=443): Max retries exceeded with url: /wandb-artifacts-prod/wandb_artifacts/133981200/707680482/174a3d9bc61fec126cc7d5bdff5c6c5a?Expires=1706688978&GoogleAccessId=gorilla-files-url-signer-man%40wandb-production.iam.gserviceaccount.com&Signature=cbtDPc9y%2ByNDqLWUkoqNfv9%2BFmv9BMiMrSHcAoresaF%2F5zpFnevKhT4IxSZwW8ln5fFnp1%2BGuAoFB8Vy%2B0KWZT2PFTA9h7493UfrojVdKstWKu1zMwGIIv9Ki%2B%2B0AI0Y4pqbVFEUyvyM0qKLgSBKKSXa4i3dBkvMbvm%2BaMOzuyJBYBno9cgiMJKY7PaT3qp%2FUk5Ng7h1cisaygxZjjbpolE9T1r3q2rR%2Bu%2FjC9mnSMhsafcXzn%2BKzDEPVbCHVWkSV5ZjBpVn6T4bLb9i9bpTm%2FDZc1I18cSR1stlp9OKN8i1uj4vPgWR%2Faio38JhkXkVcsgx6%2BAcWoQAo2X9g%2Fm8Mg%3D%3D (Caused by NewConnectionError('<urllib3.connection.HTTPSConnection object at 0x7f31a005dd30>: Failed to establish a new connection: [Errno 101] Network is unreachable'))
2024-01-30 16:16:19,818 ERROR   wandb-upload_1:1134331 [internal_api.py:upload_file():2767] upload_file request headers: {'User-Agent': 'python-requests/2.23.0', 'Accept-Encoding': 'gzip, deflate', 'Accept': '*/*', 'Connection': 'keep-alive', 'Content-MD5': 'F0o9m8Yf7BJsx9W9/1xsWg==', 'Content-Type': 'text/plain; charset=utf-8', 'Content-Length': '2179'}
2024-01-30 16:16:19,818 ERROR   wandb-upload_1:1134331 [internal_api.py:upload_file():2769] upload_file response body: 
2024-01-30 16:16:20,346 ERROR   wandb-upload_2:1134331 [internal_api.py:upload_file():2765] upload_file exception https://storage.googleapis.com/wandb-artifacts-prod/wandb_artifacts/133981200/707680482/6873c23a2381d1524249eb1a948a45a5?Expires=1706688979&GoogleAccessId=gorilla-files-url-signer-man%40wandb-production.iam.gserviceaccount.com&Signature=UIXrVQypAxHgZq44Mo8m7DKDiOHx4COYTEbj552yh6Cp%2FURg0VnzG54tqZWNmFlghXrcWDl8YsQHDh%2FbuUoCI2eGmCVgBIvjGNTuiGXbH6NhhaAeyAz4CozwmGl98FVvP7bFO7Dz1mwcEIskDGug8qttLU3ROL182sGhTILhhaTyZnlgvCp%2FALjZa%2F2NhdhrUgS81lZoLXo4oHyINK%2FRazN3ypBFND8j6SUL1kEARakxPGrgK0Z3JUyvsvbOK81KVUmLPIojAGNB71JPYXIwwQdC3GPU%2FFcI9Cv1uN4Sb9j24oq2op2YpqAOfcYnerZVSMkBZIzld91LQg7%2BTQvDKQ%3D%3D: HTTPSConnectionPool(host='storage.googleapis.com', port=443): Max retries exceeded with url: /wandb-artifacts-prod/wandb_artifacts/133981200/707680482/6873c23a2381d1524249eb1a948a45a5?Expires=1706688979&GoogleAccessId=gorilla-files-url-signer-man%40wandb-production.iam.gserviceaccount.com&Signature=UIXrVQypAxHgZq44Mo8m7DKDiOHx4COYTEbj552yh6Cp%2FURg0VnzG54tqZWNmFlghXrcWDl8YsQHDh%2FbuUoCI2eGmCVgBIvjGNTuiGXbH6NhhaAeyAz4CozwmGl98FVvP7bFO7Dz1mwcEIskDGug8qttLU3ROL182sGhTILhhaTyZnlgvCp%2FALjZa%2F2NhdhrUgS81lZoLXo4oHyINK%2FRazN3ypBFND8j6SUL1kEARakxPGrgK0Z3JUyvsvbOK81KVUmLPIojAGNB71JPYXIwwQdC3GPU%2FFcI9Cv1uN4Sb9j24oq2op2YpqAOfcYnerZVSMkBZIzld91LQg7%2BTQvDKQ%3D%3D (Caused by NewConnectionError('<urllib3.connection.HTTPSConnection object at 0x7f31a0040e50>: Failed to establish a new connection: [Errno 101] Network is unreachable'))
2024-01-30 16:16:20,346 ERROR   wandb-upload_2:1134331 [internal_api.py:upload_file():2767] upload_file request headers: {'User-Agent': 'python-requests/2.23.0', 'Accept-Encoding': 'gzip, deflate', 'Accept': '*/*', 'Connection': 'keep-alive', 'Content-MD5': 'aHPCOiOB0VJCSesalIpFpQ==', 'Content-Type': 'application/json', 'Content-Length': '609'}
2024-01-30 16:16:20,346 ERROR   wandb-upload_2:1134331 [internal_api.py:upload_file():2769] upload_file response body: 
2024-01-30 16:16:20,347 INFO    wandb-upload_2:1134331 [retry.py:__call__():172] Retry attempt failed:
Traceback (most recent call last):
  File "/home/yanxindong/anaconda/envs/eva/lib/python3.8/site-packages/urllib3/connection.py", line 159, in _new_conn
    conn = connection.create_connection(
  File "/home/yanxindong/anaconda/envs/eva/lib/python3.8/site-packages/urllib3/util/connection.py", line 84, in create_connection
    raise err
  File "/home/yanxindong/anaconda/envs/eva/lib/python3.8/site-packages/urllib3/util/connection.py", line 74, in create_connection
    sock.connect(sa)
OSError: [Errno 101] Network is unreachable

During handling of the above exception, another exception occurred:

Traceback (most recent call last):
  File "/home/yanxindong/anaconda/envs/eva/lib/python3.8/site-packages/urllib3/connectionpool.py", line 670, in urlopen
    httplib_response = self._make_request(
  File "/home/yanxindong/anaconda/envs/eva/lib/python3.8/site-packages/urllib3/connectionpool.py", line 381, in _make_request
    self._validate_conn(conn)
  File "/home/yanxindong/anaconda/envs/eva/lib/python3.8/site-packages/urllib3/connectionpool.py", line 978, in _validate_conn
    conn.connect()
  File "/home/yanxindong/anaconda/envs/eva/lib/python3.8/site-packages/urllib3/connection.py", line 309, in connect
    conn = self._new_conn()
  File "/home/yanxindong/anaconda/envs/eva/lib/python3.8/site-packages/urllib3/connection.py", line 171, in _new_conn
    raise NewConnectionError(
urllib3.exceptions.NewConnectionError: <urllib3.connection.HTTPSConnection object at 0x7f31a0040e50>: Failed to establish a new connection: [Errno 101] Network is unreachable

During handling of the above exception, another exception occurred:

Traceback (most recent call last):
  File "/home/yanxindong/anaconda/envs/eva/lib/python3.8/site-packages/requests/adapters.py", line 439, in send
    resp = conn.urlopen(
  File "/home/yanxindong/anaconda/envs/eva/lib/python3.8/site-packages/urllib3/connectionpool.py", line 726, in urlopen
    retries = retries.increment(
  File "/home/yanxindong/anaconda/envs/eva/lib/python3.8/site-packages/urllib3/util/retry.py", line 446, in increment
    raise MaxRetryError(_pool, url, error or ResponseError(cause))
urllib3.exceptions.MaxRetryError: HTTPSConnectionPool(host='storage.googleapis.com', port=443): Max retries exceeded with url: /wandb-artifacts-prod/wandb_artifacts/133981200/707680482/6873c23a2381d1524249eb1a948a45a5?Expires=1706688979&GoogleAccessId=gorilla-files-url-signer-man%40wandb-production.iam.gserviceaccount.com&Signature=UIXrVQypAxHgZq44Mo8m7DKDiOHx4COYTEbj552yh6Cp%2FURg0VnzG54tqZWNmFlghXrcWDl8YsQHDh%2FbuUoCI2eGmCVgBIvjGNTuiGXbH6NhhaAeyAz4CozwmGl98FVvP7bFO7Dz1mwcEIskDGug8qttLU3ROL182sGhTILhhaTyZnlgvCp%2FALjZa%2F2NhdhrUgS81lZoLXo4oHyINK%2FRazN3ypBFND8j6SUL1kEARakxPGrgK0Z3JUyvsvbOK81KVUmLPIojAGNB71JPYXIwwQdC3GPU%2FFcI9Cv1uN4Sb9j24oq2op2YpqAOfcYnerZVSMkBZIzld91LQg7%2BTQvDKQ%3D%3D (Caused by NewConnectionError('<urllib3.connection.HTTPSConnection object at 0x7f31a0040e50>: Failed to establish a new connection: [Errno 101] Network is unreachable'))

During handling of the above exception, another exception occurred:

Traceback (most recent call last):
  File "/home/yanxindong/anaconda/envs/eva/lib/python3.8/site-packages/wandb/sdk/internal/internal_api.py", line 2758, in upload_file
    response = self._upload_file_session.put(
  File "/home/yanxindong/anaconda/envs/eva/lib/python3.8/site-packages/requests/sessions.py", line 590, in put
    return self.request('PUT', url, data=data, **kwargs)
  File "/home/yanxindong/anaconda/envs/eva/lib/python3.8/site-packages/requests/sessions.py", line 530, in request
    resp = self.send(prep, **send_kwargs)
  File "/home/yanxindong/anaconda/envs/eva/lib/python3.8/site-packages/requests/sessions.py", line 643, in send
    r = adapter.send(request, **kwargs)
  File "/home/yanxindong/anaconda/envs/eva/lib/python3.8/site-packages/requests/adapters.py", line 516, in send
    raise ConnectionError(e, request=request)
requests.exceptions.ConnectionError: HTTPSConnectionPool(host='storage.googleapis.com', port=443): Max retries exceeded with url: /wandb-artifacts-prod/wandb_artifacts/133981200/707680482/6873c23a2381d1524249eb1a948a45a5?Expires=1706688979&GoogleAccessId=gorilla-files-url-signer-man%40wandb-production.iam.gserviceaccount.com&Signature=UIXrVQypAxHgZq44Mo8m7DKDiOHx4COYTEbj552yh6Cp%2FURg0VnzG54tqZWNmFlghXrcWDl8YsQHDh%2FbuUoCI2eGmCVgBIvjGNTuiGXbH6NhhaAeyAz4CozwmGl98FVvP7bFO7Dz1mwcEIskDGug8qttLU3ROL182sGhTILhhaTyZnlgvCp%2FALjZa%2F2NhdhrUgS81lZoLXo4oHyINK%2FRazN3ypBFND8j6SUL1kEARakxPGrgK0Z3JUyvsvbOK81KVUmLPIojAGNB71JPYXIwwQdC3GPU%2FFcI9Cv1uN4Sb9j24oq2op2YpqAOfcYnerZVSMkBZIzld91LQg7%2BTQvDKQ%3D%3D (Caused by NewConnectionError('<urllib3.connection.HTTPSConnection object at 0x7f31a0040e50>: Failed to establish a new connection: [Errno 101] Network is unreachable'))

During handling of the above exception, another exception occurred:

Traceback (most recent call last):
  File "/home/yanxindong/anaconda/envs/eva/lib/python3.8/site-packages/wandb/sdk/lib/retry.py", line 131, in __call__
    result = self._call_fn(*args, **kwargs)
  File "/home/yanxindong/anaconda/envs/eva/lib/python3.8/site-packages/wandb/sdk/internal/internal_api.py", line 2789, in upload_file
    raise _e.with_traceback(sys.exc_info()[2])
  File "/home/yanxindong/anaconda/envs/eva/lib/python3.8/site-packages/wandb/sdk/internal/internal_api.py", line 2758, in upload_file
    response = self._upload_file_session.put(
  File "/home/yanxindong/anaconda/envs/eva/lib/python3.8/site-packages/requests/sessions.py", line 590, in put
    return self.request('PUT', url, data=data, **kwargs)
  File "/home/yanxindong/anaconda/envs/eva/lib/python3.8/site-packages/requests/sessions.py", line 530, in request
    resp = self.send(prep, **send_kwargs)
  File "/home/yanxindong/anaconda/envs/eva/lib/python3.8/site-packages/requests/sessions.py", line 643, in send
    r = adapter.send(request, **kwargs)
  File "/home/yanxindong/anaconda/envs/eva/lib/python3.8/site-packages/requests/adapters.py", line 516, in send
    raise ConnectionError(e, request=request)
wandb.sdk.lib.retry.TransientError: None
2024-01-30 16:16:21,950 ERROR   wandb-upload_1:1134331 [internal_api.py:upload_file():2765] upload_file exception https://storage.googleapis.com/wandb-artifacts-prod/wandb_artifacts/133981200/707680482/174a3d9bc61fec126cc7d5bdff5c6c5a?Expires=1706688978&GoogleAccessId=gorilla-files-url-signer-man%40wandb-production.iam.gserviceaccount.com&Signature=cbtDPc9y%2ByNDqLWUkoqNfv9%2BFmv9BMiMrSHcAoresaF%2F5zpFnevKhT4IxSZwW8ln5fFnp1%2BGuAoFB8Vy%2B0KWZT2PFTA9h7493UfrojVdKstWKu1zMwGIIv9Ki%2B%2B0AI0Y4pqbVFEUyvyM0qKLgSBKKSXa4i3dBkvMbvm%2BaMOzuyJBYBno9cgiMJKY7PaT3qp%2FUk5Ng7h1cisaygxZjjbpolE9T1r3q2rR%2Bu%2FjC9mnSMhsafcXzn%2BKzDEPVbCHVWkSV5ZjBpVn6T4bLb9i9bpTm%2FDZc1I18cSR1stlp9OKN8i1uj4vPgWR%2Faio38JhkXkVcsgx6%2BAcWoQAo2X9g%2Fm8Mg%3D%3D: HTTPSConnectionPool(host='storage.googleapis.com', port=443): Max retries exceeded with url: /wandb-artifacts-prod/wandb_artifacts/133981200/707680482/174a3d9bc61fec126cc7d5bdff5c6c5a?Expires=1706688978&GoogleAccessId=gorilla-files-url-signer-man%40wandb-production.iam.gserviceaccount.com&Signature=cbtDPc9y%2ByNDqLWUkoqNfv9%2BFmv9BMiMrSHcAoresaF%2F5zpFnevKhT4IxSZwW8ln5fFnp1%2BGuAoFB8Vy%2B0KWZT2PFTA9h7493UfrojVdKstWKu1zMwGIIv9Ki%2B%2B0AI0Y4pqbVFEUyvyM0qKLgSBKKSXa4i3dBkvMbvm%2BaMOzuyJBYBno9cgiMJKY7PaT3qp%2FUk5Ng7h1cisaygxZjjbpolE9T1r3q2rR%2Bu%2FjC9mnSMhsafcXzn%2BKzDEPVbCHVWkSV5ZjBpVn6T4bLb9i9bpTm%2FDZc1I18cSR1stlp9OKN8i1uj4vPgWR%2Faio38JhkXkVcsgx6%2BAcWoQAo2X9g%2Fm8Mg%3D%3D (Caused by NewConnectionError('<urllib3.connection.HTTPSConnection object at 0x7f31a0040c10>: Failed to establish a new connection: [Errno 101] Network is unreachable'))
2024-01-30 16:16:21,950 ERROR   wandb-upload_1:1134331 [internal_api.py:upload_file():2767] upload_file request headers: {'User-Agent': 'python-requests/2.23.0', 'Accept-Encoding': 'gzip, deflate', 'Accept': '*/*', 'Connection': 'keep-alive', 'Content-MD5': 'F0o9m8Yf7BJsx9W9/1xsWg==', 'Content-Type': 'text/plain; charset=utf-8', 'Content-Length': '2179'}
2024-01-30 16:16:21,950 ERROR   wandb-upload_1:1134331 [internal_api.py:upload_file():2769] upload_file response body: 
2024-01-30 16:16:22,204 DEBUG   HandlerThread:1134331 [handler.py:handle_request():146] handle_request: keepalive
2024-01-30 16:16:22,633 ERROR   wandb-upload_2:1134331 [internal_api.py:upload_file():2765] upload_file exception https://storage.googleapis.com/wandb-artifacts-prod/wandb_artifacts/133981200/707680482/6873c23a2381d1524249eb1a948a45a5?Expires=1706688979&GoogleAccessId=gorilla-files-url-signer-man%40wandb-production.iam.gserviceaccount.com&Signature=UIXrVQypAxHgZq44Mo8m7DKDiOHx4COYTEbj552yh6Cp%2FURg0VnzG54tqZWNmFlghXrcWDl8YsQHDh%2FbuUoCI2eGmCVgBIvjGNTuiGXbH6NhhaAeyAz4CozwmGl98FVvP7bFO7Dz1mwcEIskDGug8qttLU3ROL182sGhTILhhaTyZnlgvCp%2FALjZa%2F2NhdhrUgS81lZoLXo4oHyINK%2FRazN3ypBFND8j6SUL1kEARakxPGrgK0Z3JUyvsvbOK81KVUmLPIojAGNB71JPYXIwwQdC3GPU%2FFcI9Cv1uN4Sb9j24oq2op2YpqAOfcYnerZVSMkBZIzld91LQg7%2BTQvDKQ%3D%3D: HTTPSConnectionPool(host='storage.googleapis.com', port=443): Max retries exceeded with url: /wandb-artifacts-prod/wandb_artifacts/133981200/707680482/6873c23a2381d1524249eb1a948a45a5?Expires=1706688979&GoogleAccessId=gorilla-files-url-signer-man%40wandb-production.iam.gserviceaccount.com&Signature=UIXrVQypAxHgZq44Mo8m7DKDiOHx4COYTEbj552yh6Cp%2FURg0VnzG54tqZWNmFlghXrcWDl8YsQHDh%2FbuUoCI2eGmCVgBIvjGNTuiGXbH6NhhaAeyAz4CozwmGl98FVvP7bFO7Dz1mwcEIskDGug8qttLU3ROL182sGhTILhhaTyZnlgvCp%2FALjZa%2F2NhdhrUgS81lZoLXo4oHyINK%2FRazN3ypBFND8j6SUL1kEARakxPGrgK0Z3JUyvsvbOK81KVUmLPIojAGNB71JPYXIwwQdC3GPU%2FFcI9Cv1uN4Sb9j24oq2op2YpqAOfcYnerZVSMkBZIzld91LQg7%2BTQvDKQ%3D%3D (Caused by NewConnectionError('<urllib3.connection.HTTPSConnection object at 0x7f31a0040850>: Failed to establish a new connection: [Errno 101] Network is unreachable'))
2024-01-30 16:16:22,633 ERROR   wandb-upload_2:1134331 [internal_api.py:upload_file():2767] upload_file request headers: {'User-Agent': 'python-requests/2.23.0', 'Accept-Encoding': 'gzip, deflate', 'Accept': '*/*', 'Connection': 'keep-alive', 'Content-MD5': 'aHPCOiOB0VJCSesalIpFpQ==', 'Content-Type': 'application/json', 'Content-Length': '609'}
2024-01-30 16:16:22,633 ERROR   wandb-upload_2:1134331 [internal_api.py:upload_file():2769] upload_file response body: 
2024-01-30 16:16:26,954 ERROR   wandb-upload_1:1134331 [internal_api.py:upload_file():2765] upload_file exception https://storage.googleapis.com/wandb-artifacts-prod/wandb_artifacts/133981200/707680482/174a3d9bc61fec126cc7d5bdff5c6c5a?Expires=1706688978&GoogleAccessId=gorilla-files-url-signer-man%40wandb-production.iam.gserviceaccount.com&Signature=cbtDPc9y%2ByNDqLWUkoqNfv9%2BFmv9BMiMrSHcAoresaF%2F5zpFnevKhT4IxSZwW8ln5fFnp1%2BGuAoFB8Vy%2B0KWZT2PFTA9h7493UfrojVdKstWKu1zMwGIIv9Ki%2B%2B0AI0Y4pqbVFEUyvyM0qKLgSBKKSXa4i3dBkvMbvm%2BaMOzuyJBYBno9cgiMJKY7PaT3qp%2FUk5Ng7h1cisaygxZjjbpolE9T1r3q2rR%2Bu%2FjC9mnSMhsafcXzn%2BKzDEPVbCHVWkSV5ZjBpVn6T4bLb9i9bpTm%2FDZc1I18cSR1stlp9OKN8i1uj4vPgWR%2Faio38JhkXkVcsgx6%2BAcWoQAo2X9g%2Fm8Mg%3D%3D: HTTPSConnectionPool(host='storage.googleapis.com', port=443): Max retries exceeded with url: /wandb-artifacts-prod/wandb_artifacts/133981200/707680482/174a3d9bc61fec126cc7d5bdff5c6c5a?Expires=1706688978&GoogleAccessId=gorilla-files-url-signer-man%40wandb-production.iam.gserviceaccount.com&Signature=cbtDPc9y%2ByNDqLWUkoqNfv9%2BFmv9BMiMrSHcAoresaF%2F5zpFnevKhT4IxSZwW8ln5fFnp1%2BGuAoFB8Vy%2B0KWZT2PFTA9h7493UfrojVdKstWKu1zMwGIIv9Ki%2B%2B0AI0Y4pqbVFEUyvyM0qKLgSBKKSXa4i3dBkvMbvm%2BaMOzuyJBYBno9cgiMJKY7PaT3qp%2FUk5Ng7h1cisaygxZjjbpolE9T1r3q2rR%2Bu%2FjC9mnSMhsafcXzn%2BKzDEPVbCHVWkSV5ZjBpVn6T4bLb9i9bpTm%2FDZc1I18cSR1stlp9OKN8i1uj4vPgWR%2Faio38JhkXkVcsgx6%2BAcWoQAo2X9g%2Fm8Mg%3D%3D (Caused by NewConnectionError('<urllib3.connection.HTTPSConnection object at 0x7f31a005d0a0>: Failed to establish a new connection: [Errno 101] Network is unreachable'))
2024-01-30 16:16:26,954 ERROR   wandb-upload_1:1134331 [internal_api.py:upload_file():2767] upload_file request headers: {'User-Agent': 'python-requests/2.23.0', 'Accept-Encoding': 'gzip, deflate', 'Accept': '*/*', 'Connection': 'keep-alive', 'Content-MD5': 'F0o9m8Yf7BJsx9W9/1xsWg==', 'Content-Type': 'text/plain; charset=utf-8', 'Content-Length': '2179'}
2024-01-30 16:16:26,954 ERROR   wandb-upload_1:1134331 [internal_api.py:upload_file():2769] upload_file response body: 
2024-01-30 16:16:27,206 DEBUG   HandlerThread:1134331 [handler.py:handle_request():146] handle_request: keepalive
2024-01-30 16:16:27,445 ERROR   wandb-upload_2:1134331 [internal_api.py:upload_file():2765] upload_file exception https://storage.googleapis.com/wandb-artifacts-prod/wandb_artifacts/133981200/707680482/6873c23a2381d1524249eb1a948a45a5?Expires=1706688979&GoogleAccessId=gorilla-files-url-signer-man%40wandb-production.iam.gserviceaccount.com&Signature=UIXrVQypAxHgZq44Mo8m7DKDiOHx4COYTEbj552yh6Cp%2FURg0VnzG54tqZWNmFlghXrcWDl8YsQHDh%2FbuUoCI2eGmCVgBIvjGNTuiGXbH6NhhaAeyAz4CozwmGl98FVvP7bFO7Dz1mwcEIskDGug8qttLU3ROL182sGhTILhhaTyZnlgvCp%2FALjZa%2F2NhdhrUgS81lZoLXo4oHyINK%2FRazN3ypBFND8j6SUL1kEARakxPGrgK0Z3JUyvsvbOK81KVUmLPIojAGNB71JPYXIwwQdC3GPU%2FFcI9Cv1uN4Sb9j24oq2op2YpqAOfcYnerZVSMkBZIzld91LQg7%2BTQvDKQ%3D%3D: HTTPSConnectionPool(host='storage.googleapis.com', port=443): Max retries exceeded with url: /wandb-artifacts-prod/wandb_artifacts/133981200/707680482/6873c23a2381d1524249eb1a948a45a5?Expires=1706688979&GoogleAccessId=gorilla-files-url-signer-man%40wandb-production.iam.gserviceaccount.com&Signature=UIXrVQypAxHgZq44Mo8m7DKDiOHx4COYTEbj552yh6Cp%2FURg0VnzG54tqZWNmFlghXrcWDl8YsQHDh%2FbuUoCI2eGmCVgBIvjGNTuiGXbH6NhhaAeyAz4CozwmGl98FVvP7bFO7Dz1mwcEIskDGug8qttLU3ROL182sGhTILhhaTyZnlgvCp%2FALjZa%2F2NhdhrUgS81lZoLXo4oHyINK%2FRazN3ypBFND8j6SUL1kEARakxPGrgK0Z3JUyvsvbOK81KVUmLPIojAGNB71JPYXIwwQdC3GPU%2FFcI9Cv1uN4Sb9j24oq2op2YpqAOfcYnerZVSMkBZIzld91LQg7%2BTQvDKQ%3D%3D (Caused by NewConnectionError('<urllib3.connection.HTTPSConnection object at 0x7f31a005d3a0>: Failed to establish a new connection: [Errno 101] Network is unreachable'))
2024-01-30 16:16:27,445 ERROR   wandb-upload_2:1134331 [internal_api.py:upload_file():2767] upload_file request headers: {'User-Agent': 'python-requests/2.23.0', 'Accept-Encoding': 'gzip, deflate', 'Accept': '*/*', 'Connection': 'keep-alive', 'Content-MD5': 'aHPCOiOB0VJCSesalIpFpQ==', 'Content-Type': 'application/json', 'Content-Length': '609'}
2024-01-30 16:16:27,445 ERROR   wandb-upload_2:1134331 [internal_api.py:upload_file():2769] upload_file response body: 
2024-01-30 16:16:32,208 DEBUG   HandlerThread:1134331 [handler.py:handle_request():146] handle_request: keepalive
2024-01-30 16:16:36,271 ERROR   wandb-upload_1:1134331 [internal_api.py:upload_file():2765] upload_file exception https://storage.googleapis.com/wandb-artifacts-prod/wandb_artifacts/133981200/707680482/174a3d9bc61fec126cc7d5bdff5c6c5a?Expires=1706688978&GoogleAccessId=gorilla-files-url-signer-man%40wandb-production.iam.gserviceaccount.com&Signature=cbtDPc9y%2ByNDqLWUkoqNfv9%2BFmv9BMiMrSHcAoresaF%2F5zpFnevKhT4IxSZwW8ln5fFnp1%2BGuAoFB8Vy%2B0KWZT2PFTA9h7493UfrojVdKstWKu1zMwGIIv9Ki%2B%2B0AI0Y4pqbVFEUyvyM0qKLgSBKKSXa4i3dBkvMbvm%2BaMOzuyJBYBno9cgiMJKY7PaT3qp%2FUk5Ng7h1cisaygxZjjbpolE9T1r3q2rR%2Bu%2FjC9mnSMhsafcXzn%2BKzDEPVbCHVWkSV5ZjBpVn6T4bLb9i9bpTm%2FDZc1I18cSR1stlp9OKN8i1uj4vPgWR%2Faio38JhkXkVcsgx6%2BAcWoQAo2X9g%2Fm8Mg%3D%3D: HTTPSConnectionPool(host='storage.googleapis.com', port=443): Max retries exceeded with url: /wandb-artifacts-prod/wandb_artifacts/133981200/707680482/174a3d9bc61fec126cc7d5bdff5c6c5a?Expires=1706688978&GoogleAccessId=gorilla-files-url-signer-man%40wandb-production.iam.gserviceaccount.com&Signature=cbtDPc9y%2ByNDqLWUkoqNfv9%2BFmv9BMiMrSHcAoresaF%2F5zpFnevKhT4IxSZwW8ln5fFnp1%2BGuAoFB8Vy%2B0KWZT2PFTA9h7493UfrojVdKstWKu1zMwGIIv9Ki%2B%2B0AI0Y4pqbVFEUyvyM0qKLgSBKKSXa4i3dBkvMbvm%2BaMOzuyJBYBno9cgiMJKY7PaT3qp%2FUk5Ng7h1cisaygxZjjbpolE9T1r3q2rR%2Bu%2FjC9mnSMhsafcXzn%2BKzDEPVbCHVWkSV5ZjBpVn6T4bLb9i9bpTm%2FDZc1I18cSR1stlp9OKN8i1uj4vPgWR%2Faio38JhkXkVcsgx6%2BAcWoQAo2X9g%2Fm8Mg%3D%3D (Caused by NewConnectionError('<urllib3.connection.HTTPSConnection object at 0x7f31a0040a30>: Failed to establish a new connection: [Errno 101] Network is unreachable'))
2024-01-30 16:16:36,271 ERROR   wandb-upload_1:1134331 [internal_api.py:upload_file():2767] upload_file request headers: {'User-Agent': 'python-requests/2.23.0', 'Accept-Encoding': 'gzip, deflate', 'Accept': '*/*', 'Connection': 'keep-alive', 'Content-MD5': 'F0o9m8Yf7BJsx9W9/1xsWg==', 'Content-Type': 'text/plain; charset=utf-8', 'Content-Length': '2179'}
2024-01-30 16:16:36,271 ERROR   wandb-upload_1:1134331 [internal_api.py:upload_file():2769] upload_file response body: 
2024-01-30 16:16:37,044 ERROR   wandb-upload_2:1134331 [internal_api.py:upload_file():2765] upload_file exception https://storage.googleapis.com/wandb-artifacts-prod/wandb_artifacts/133981200/707680482/6873c23a2381d1524249eb1a948a45a5?Expires=1706688979&GoogleAccessId=gorilla-files-url-signer-man%40wandb-production.iam.gserviceaccount.com&Signature=UIXrVQypAxHgZq44Mo8m7DKDiOHx4COYTEbj552yh6Cp%2FURg0VnzG54tqZWNmFlghXrcWDl8YsQHDh%2FbuUoCI2eGmCVgBIvjGNTuiGXbH6NhhaAeyAz4CozwmGl98FVvP7bFO7Dz1mwcEIskDGug8qttLU3ROL182sGhTILhhaTyZnlgvCp%2FALjZa%2F2NhdhrUgS81lZoLXo4oHyINK%2FRazN3ypBFND8j6SUL1kEARakxPGrgK0Z3JUyvsvbOK81KVUmLPIojAGNB71JPYXIwwQdC3GPU%2FFcI9Cv1uN4Sb9j24oq2op2YpqAOfcYnerZVSMkBZIzld91LQg7%2BTQvDKQ%3D%3D: HTTPSConnectionPool(host='storage.googleapis.com', port=443): Max retries exceeded with url: /wandb-artifacts-prod/wandb_artifacts/133981200/707680482/6873c23a2381d1524249eb1a948a45a5?Expires=1706688979&GoogleAccessId=gorilla-files-url-signer-man%40wandb-production.iam.gserviceaccount.com&Signature=UIXrVQypAxHgZq44Mo8m7DKDiOHx4COYTEbj552yh6Cp%2FURg0VnzG54tqZWNmFlghXrcWDl8YsQHDh%2FbuUoCI2eGmCVgBIvjGNTuiGXbH6NhhaAeyAz4CozwmGl98FVvP7bFO7Dz1mwcEIskDGug8qttLU3ROL182sGhTILhhaTyZnlgvCp%2FALjZa%2F2NhdhrUgS81lZoLXo4oHyINK%2FRazN3ypBFND8j6SUL1kEARakxPGrgK0Z3JUyvsvbOK81KVUmLPIojAGNB71JPYXIwwQdC3GPU%2FFcI9Cv1uN4Sb9j24oq2op2YpqAOfcYnerZVSMkBZIzld91LQg7%2BTQvDKQ%3D%3D (Caused by NewConnectionError('<urllib3.connection.HTTPSConnection object at 0x7f31a0040040>: Failed to establish a new connection: [Errno 101] Network is unreachable'))
2024-01-30 16:16:37,044 ERROR   wandb-upload_2:1134331 [internal_api.py:upload_file():2767] upload_file request headers: {'User-Agent': 'python-requests/2.23.0', 'Accept-Encoding': 'gzip, deflate', 'Accept': '*/*', 'Connection': 'keep-alive', 'Content-MD5': 'aHPCOiOB0VJCSesalIpFpQ==', 'Content-Type': 'application/json', 'Content-Length': '609'}
2024-01-30 16:16:37,044 ERROR   wandb-upload_2:1134331 [internal_api.py:upload_file():2769] upload_file response body: 
2024-01-30 16:16:37,211 DEBUG   HandlerThread:1134331 [handler.py:handle_request():146] handle_request: keepalive
2024-01-30 16:16:42,213 DEBUG   HandlerThread:1134331 [handler.py:handle_request():146] handle_request: keepalive
2024-01-30 16:16:47,215 DEBUG   HandlerThread:1134331 [handler.py:handle_request():146] handle_request: keepalive
2024-01-30 16:16:52,217 DEBUG   HandlerThread:1134331 [handler.py:handle_request():146] handle_request: keepalive
2024-01-30 16:16:55,486 ERROR   wandb-upload_1:1134331 [internal_api.py:upload_file():2765] upload_file exception https://storage.googleapis.com/wandb-artifacts-prod/wandb_artifacts/133981200/707680482/174a3d9bc61fec126cc7d5bdff5c6c5a?Expires=1706688978&GoogleAccessId=gorilla-files-url-signer-man%40wandb-production.iam.gserviceaccount.com&Signature=cbtDPc9y%2ByNDqLWUkoqNfv9%2BFmv9BMiMrSHcAoresaF%2F5zpFnevKhT4IxSZwW8ln5fFnp1%2BGuAoFB8Vy%2B0KWZT2PFTA9h7493UfrojVdKstWKu1zMwGIIv9Ki%2B%2B0AI0Y4pqbVFEUyvyM0qKLgSBKKSXa4i3dBkvMbvm%2BaMOzuyJBYBno9cgiMJKY7PaT3qp%2FUk5Ng7h1cisaygxZjjbpolE9T1r3q2rR%2Bu%2FjC9mnSMhsafcXzn%2BKzDEPVbCHVWkSV5ZjBpVn6T4bLb9i9bpTm%2FDZc1I18cSR1stlp9OKN8i1uj4vPgWR%2Faio38JhkXkVcsgx6%2BAcWoQAo2X9g%2Fm8Mg%3D%3D: HTTPSConnectionPool(host='storage.googleapis.com', port=443): Max retries exceeded with url: /wandb-artifacts-prod/wandb_artifacts/133981200/707680482/174a3d9bc61fec126cc7d5bdff5c6c5a?Expires=1706688978&GoogleAccessId=gorilla-files-url-signer-man%40wandb-production.iam.gserviceaccount.com&Signature=cbtDPc9y%2ByNDqLWUkoqNfv9%2BFmv9BMiMrSHcAoresaF%2F5zpFnevKhT4IxSZwW8ln5fFnp1%2BGuAoFB8Vy%2B0KWZT2PFTA9h7493UfrojVdKstWKu1zMwGIIv9Ki%2B%2B0AI0Y4pqbVFEUyvyM0qKLgSBKKSXa4i3dBkvMbvm%2BaMOzuyJBYBno9cgiMJKY7PaT3qp%2FUk5Ng7h1cisaygxZjjbpolE9T1r3q2rR%2Bu%2FjC9mnSMhsafcXzn%2BKzDEPVbCHVWkSV5ZjBpVn6T4bLb9i9bpTm%2FDZc1I18cSR1stlp9OKN8i1uj4vPgWR%2Faio38JhkXkVcsgx6%2BAcWoQAo2X9g%2Fm8Mg%3D%3D (Caused by NewConnectionError('<urllib3.connection.HTTPSConnection object at 0x7f31887833a0>: Failed to establish a new connection: [Errno 101] Network is unreachable'))
2024-01-30 16:16:55,486 ERROR   wandb-upload_1:1134331 [internal_api.py:upload_file():2767] upload_file request headers: {'User-Agent': 'python-requests/2.23.0', 'Accept-Encoding': 'gzip, deflate', 'Accept': '*/*', 'Connection': 'keep-alive', 'Content-MD5': 'F0o9m8Yf7BJsx9W9/1xsWg==', 'Content-Type': 'text/plain; charset=utf-8', 'Content-Length': '2179'}
2024-01-30 16:16:55,487 ERROR   wandb-upload_1:1134331 [internal_api.py:upload_file():2769] upload_file response body: 
2024-01-30 16:16:56,762 ERROR   wandb-upload_2:1134331 [internal_api.py:upload_file():2765] upload_file exception https://storage.googleapis.com/wandb-artifacts-prod/wandb_artifacts/133981200/707680482/6873c23a2381d1524249eb1a948a45a5?Expires=1706688979&GoogleAccessId=gorilla-files-url-signer-man%40wandb-production.iam.gserviceaccount.com&Signature=UIXrVQypAxHgZq44Mo8m7DKDiOHx4COYTEbj552yh6Cp%2FURg0VnzG54tqZWNmFlghXrcWDl8YsQHDh%2FbuUoCI2eGmCVgBIvjGNTuiGXbH6NhhaAeyAz4CozwmGl98FVvP7bFO7Dz1mwcEIskDGug8qttLU3ROL182sGhTILhhaTyZnlgvCp%2FALjZa%2F2NhdhrUgS81lZoLXo4oHyINK%2FRazN3ypBFND8j6SUL1kEARakxPGrgK0Z3JUyvsvbOK81KVUmLPIojAGNB71JPYXIwwQdC3GPU%2FFcI9Cv1uN4Sb9j24oq2op2YpqAOfcYnerZVSMkBZIzld91LQg7%2BTQvDKQ%3D%3D: HTTPSConnectionPool(host='storage.googleapis.com', port=443): Max retries exceeded with url: /wandb-artifacts-prod/wandb_artifacts/133981200/707680482/6873c23a2381d1524249eb1a948a45a5?Expires=1706688979&GoogleAccessId=gorilla-files-url-signer-man%40wandb-production.iam.gserviceaccount.com&Signature=UIXrVQypAxHgZq44Mo8m7DKDiOHx4COYTEbj552yh6Cp%2FURg0VnzG54tqZWNmFlghXrcWDl8YsQHDh%2FbuUoCI2eGmCVgBIvjGNTuiGXbH6NhhaAeyAz4CozwmGl98FVvP7bFO7Dz1mwcEIskDGug8qttLU3ROL182sGhTILhhaTyZnlgvCp%2FALjZa%2F2NhdhrUgS81lZoLXo4oHyINK%2FRazN3ypBFND8j6SUL1kEARakxPGrgK0Z3JUyvsvbOK81KVUmLPIojAGNB71JPYXIwwQdC3GPU%2FFcI9Cv1uN4Sb9j24oq2op2YpqAOfcYnerZVSMkBZIzld91LQg7%2BTQvDKQ%3D%3D (Caused by NewConnectionError('<urllib3.connection.HTTPSConnection object at 0x7f3188783070>: Failed to establish a new connection: [Errno 101] Network is unreachable'))
2024-01-30 16:16:56,763 ERROR   wandb-upload_2:1134331 [internal_api.py:upload_file():2767] upload_file request headers: {'User-Agent': 'python-requests/2.23.0', 'Accept-Encoding': 'gzip, deflate', 'Accept': '*/*', 'Connection': 'keep-alive', 'Content-MD5': 'aHPCOiOB0VJCSesalIpFpQ==', 'Content-Type': 'application/json', 'Content-Length': '609'}
2024-01-30 16:16:56,763 ERROR   wandb-upload_2:1134331 [internal_api.py:upload_file():2769] upload_file response body: 
2024-01-30 16:16:57,220 DEBUG   HandlerThread:1134331 [handler.py:handle_request():146] handle_request: keepalive
2024-01-30 16:17:02,222 DEBUG   HandlerThread:1134331 [handler.py:handle_request():146] handle_request: keepalive
2024-01-30 16:17:07,224 DEBUG   HandlerThread:1134331 [handler.py:handle_request():146] handle_request: keepalive
2024-01-30 16:17:12,226 DEBUG   HandlerThread:1134331 [handler.py:handle_request():146] handle_request: keepalive
2024-01-30 16:17:17,229 DEBUG   HandlerThread:1134331 [handler.py:handle_request():146] handle_request: keepalive
2024-01-30 16:17:22,231 DEBUG   HandlerThread:1134331 [handler.py:handle_request():146] handle_request: keepalive
2024-01-30 16:17:27,233 DEBUG   HandlerThread:1134331 [handler.py:handle_request():146] handle_request: keepalive
2024-01-30 16:17:28,151 ERROR   wandb-upload_1:1134331 [internal_api.py:upload_file():2765] upload_file exception https://storage.googleapis.com/wandb-artifacts-prod/wandb_artifacts/133981200/707680482/174a3d9bc61fec126cc7d5bdff5c6c5a?Expires=1706688978&GoogleAccessId=gorilla-files-url-signer-man%40wandb-production.iam.gserviceaccount.com&Signature=cbtDPc9y%2ByNDqLWUkoqNfv9%2BFmv9BMiMrSHcAoresaF%2F5zpFnevKhT4IxSZwW8ln5fFnp1%2BGuAoFB8Vy%2B0KWZT2PFTA9h7493UfrojVdKstWKu1zMwGIIv9Ki%2B%2B0AI0Y4pqbVFEUyvyM0qKLgSBKKSXa4i3dBkvMbvm%2BaMOzuyJBYBno9cgiMJKY7PaT3qp%2FUk5Ng7h1cisaygxZjjbpolE9T1r3q2rR%2Bu%2FjC9mnSMhsafcXzn%2BKzDEPVbCHVWkSV5ZjBpVn6T4bLb9i9bpTm%2FDZc1I18cSR1stlp9OKN8i1uj4vPgWR%2Faio38JhkXkVcsgx6%2BAcWoQAo2X9g%2Fm8Mg%3D%3D: HTTPSConnectionPool(host='storage.googleapis.com', port=443): Max retries exceeded with url: /wandb-artifacts-prod/wandb_artifacts/133981200/707680482/174a3d9bc61fec126cc7d5bdff5c6c5a?Expires=1706688978&GoogleAccessId=gorilla-files-url-signer-man%40wandb-production.iam.gserviceaccount.com&Signature=cbtDPc9y%2ByNDqLWUkoqNfv9%2BFmv9BMiMrSHcAoresaF%2F5zpFnevKhT4IxSZwW8ln5fFnp1%2BGuAoFB8Vy%2B0KWZT2PFTA9h7493UfrojVdKstWKu1zMwGIIv9Ki%2B%2B0AI0Y4pqbVFEUyvyM0qKLgSBKKSXa4i3dBkvMbvm%2BaMOzuyJBYBno9cgiMJKY7PaT3qp%2FUk5Ng7h1cisaygxZjjbpolE9T1r3q2rR%2Bu%2FjC9mnSMhsafcXzn%2BKzDEPVbCHVWkSV5ZjBpVn6T4bLb9i9bpTm%2FDZc1I18cSR1stlp9OKN8i1uj4vPgWR%2Faio38JhkXkVcsgx6%2BAcWoQAo2X9g%2Fm8Mg%3D%3D (Caused by NewConnectionError('<urllib3.connection.HTTPSConnection object at 0x7f3188783940>: Failed to establish a new connection: [Errno 101] Network is unreachable'))
2024-01-30 16:17:28,152 ERROR   wandb-upload_1:1134331 [internal_api.py:upload_file():2767] upload_file request headers: {'User-Agent': 'python-requests/2.23.0', 'Accept-Encoding': 'gzip, deflate', 'Accept': '*/*', 'Connection': 'keep-alive', 'Content-MD5': 'F0o9m8Yf7BJsx9W9/1xsWg==', 'Content-Type': 'text/plain; charset=utf-8', 'Content-Length': '2179'}
2024-01-30 16:17:28,152 ERROR   wandb-upload_1:1134331 [internal_api.py:upload_file():2769] upload_file response body: 
2024-01-30 16:17:32,236 DEBUG   HandlerThread:1134331 [handler.py:handle_request():146] handle_request: keepalive
2024-01-30 16:17:34,165 ERROR   wandb-upload_2:1134331 [internal_api.py:upload_file():2765] upload_file exception https://storage.googleapis.com/wandb-artifacts-prod/wandb_artifacts/133981200/707680482/6873c23a2381d1524249eb1a948a45a5?Expires=1706688979&GoogleAccessId=gorilla-files-url-signer-man%40wandb-production.iam.gserviceaccount.com&Signature=UIXrVQypAxHgZq44Mo8m7DKDiOHx4COYTEbj552yh6Cp%2FURg0VnzG54tqZWNmFlghXrcWDl8YsQHDh%2FbuUoCI2eGmCVgBIvjGNTuiGXbH6NhhaAeyAz4CozwmGl98FVvP7bFO7Dz1mwcEIskDGug8qttLU3ROL182sGhTILhhaTyZnlgvCp%2FALjZa%2F2NhdhrUgS81lZoLXo4oHyINK%2FRazN3ypBFND8j6SUL1kEARakxPGrgK0Z3JUyvsvbOK81KVUmLPIojAGNB71JPYXIwwQdC3GPU%2FFcI9Cv1uN4Sb9j24oq2op2YpqAOfcYnerZVSMkBZIzld91LQg7%2BTQvDKQ%3D%3D: HTTPSConnectionPool(host='storage.googleapis.com', port=443): Max retries exceeded with url: /wandb-artifacts-prod/wandb_artifacts/133981200/707680482/6873c23a2381d1524249eb1a948a45a5?Expires=1706688979&GoogleAccessId=gorilla-files-url-signer-man%40wandb-production.iam.gserviceaccount.com&Signature=UIXrVQypAxHgZq44Mo8m7DKDiOHx4COYTEbj552yh6Cp%2FURg0VnzG54tqZWNmFlghXrcWDl8YsQHDh%2FbuUoCI2eGmCVgBIvjGNTuiGXbH6NhhaAeyAz4CozwmGl98FVvP7bFO7Dz1mwcEIskDGug8qttLU3ROL182sGhTILhhaTyZnlgvCp%2FALjZa%2F2NhdhrUgS81lZoLXo4oHyINK%2FRazN3ypBFND8j6SUL1kEARakxPGrgK0Z3JUyvsvbOK81KVUmLPIojAGNB71JPYXIwwQdC3GPU%2FFcI9Cv1uN4Sb9j24oq2op2YpqAOfcYnerZVSMkBZIzld91LQg7%2BTQvDKQ%3D%3D (Caused by NewConnectionError('<urllib3.connection.HTTPSConnection object at 0x7f3188783e80>: Failed to establish a new connection: [Errno 101] Network is unreachable'))
2024-01-30 16:17:34,166 ERROR   wandb-upload_2:1134331 [internal_api.py:upload_file():2767] upload_file request headers: {'User-Agent': 'python-requests/2.23.0', 'Accept-Encoding': 'gzip, deflate', 'Accept': '*/*', 'Connection': 'keep-alive', 'Content-MD5': 'aHPCOiOB0VJCSesalIpFpQ==', 'Content-Type': 'application/json', 'Content-Length': '609'}
2024-01-30 16:17:34,166 ERROR   wandb-upload_2:1134331 [internal_api.py:upload_file():2769] upload_file response body: 
2024-01-30 16:17:37,238 DEBUG   HandlerThread:1134331 [handler.py:handle_request():146] handle_request: keepalive
2024-01-30 16:17:42,240 DEBUG   HandlerThread:1134331 [handler.py:handle_request():146] handle_request: keepalive
2024-01-30 16:17:47,243 DEBUG   HandlerThread:1134331 [handler.py:handle_request():146] handle_request: keepalive
2024-01-30 16:17:52,246 DEBUG   HandlerThread:1134331 [handler.py:handle_request():146] handle_request: keepalive
2024-01-30 16:20:35,506 ERROR   wandb-upload_0:1134331 [internal_api.py:upload_file():2765] upload_file exception https://storage.googleapis.com/wandb-production.appspot.com/dynamic_x/bert_pytorch/0vfv9wkn/wandb-metadata.json?Expires=1706688636&GoogleAccessId=gorilla-files-url-signer-man%40wandb-production.iam.gserviceaccount.com&Signature=TOE9Ck7npWvU2grZxrdepfkP7GGkjk2DxVjQW47W2UtaiiUt9kEhpI8qATqI9uozu9XFTPhU9B87d%2B31EOqc9ZxpA3r1tpLJ5J7Plx6BWPUp5B1h1IqJ7JfEnxhfv1KuBRsZ4ZG3gHKdTgEWAXjynDk78cVjyKp5vBw2jOFC4mRI1vjmETrSdu%2BYuLu%2FICD3Nn2TKxzd0d60n9W08r6kTgtEFZZTNPhXe2Jk74oVaKOAuf50B2cELpiGPX2IRImbiSKjqs3lFWxZWaUFL23Qk82VimFqiSWHwpjIE5BQOJf04g41QgvonPnCiDTPQOMZgpAuOSqgczyaRNBOPFqrQQ%3D%3D: HTTPSConnectionPool(host='storage.googleapis.com', port=443): Max retries exceeded with url: /wandb-production.appspot.com/dynamic_x/bert_pytorch/0vfv9wkn/wandb-metadata.json?Expires=1706688636&GoogleAccessId=gorilla-files-url-signer-man%40wandb-production.iam.gserviceaccount.com&Signature=TOE9Ck7npWvU2grZxrdepfkP7GGkjk2DxVjQW47W2UtaiiUt9kEhpI8qATqI9uozu9XFTPhU9B87d%2B31EOqc9ZxpA3r1tpLJ5J7Plx6BWPUp5B1h1IqJ7JfEnxhfv1KuBRsZ4ZG3gHKdTgEWAXjynDk78cVjyKp5vBw2jOFC4mRI1vjmETrSdu%2BYuLu%2FICD3Nn2TKxzd0d60n9W08r6kTgtEFZZTNPhXe2Jk74oVaKOAuf50B2cELpiGPX2IRImbiSKjqs3lFWxZWaUFL23Qk82VimFqiSWHwpjIE5BQOJf04g41QgvonPnCiDTPQOMZgpAuOSqgczyaRNBOPFqrQQ%3D%3D (Caused by NewConnectionError('<urllib3.connection.HTTPSConnection object at 0x7f3188789340>: Failed to establish a new connection: [Errno 111] Connection refused'))
2024-01-30 16:20:35,506 ERROR   wandb-upload_0:1134331 [internal_api.py:upload_file():2767] upload_file request headers: {'User-Agent': 'python-requests/2.23.0', 'Accept-Encoding': 'gzip, deflate', 'Accept': '*/*', 'Connection': 'keep-alive', 'Content-Length': '15546'}
2024-01-30 16:20:35,506 ERROR   wandb-upload_0:1134331 [internal_api.py:upload_file():2769] upload_file response body: 
2024-01-30 16:25:53,526 ERROR   wandb-upload_0:1134331 [internal_api.py:upload_file():2765] upload_file exception https://storage.googleapis.com/wandb-production.appspot.com/dynamic_x/bert_pytorch/0vfv9wkn/wandb-metadata.json?Expires=1706688636&GoogleAccessId=gorilla-files-url-signer-man%40wandb-production.iam.gserviceaccount.com&Signature=TOE9Ck7npWvU2grZxrdepfkP7GGkjk2DxVjQW47W2UtaiiUt9kEhpI8qATqI9uozu9XFTPhU9B87d%2B31EOqc9ZxpA3r1tpLJ5J7Plx6BWPUp5B1h1IqJ7JfEnxhfv1KuBRsZ4ZG3gHKdTgEWAXjynDk78cVjyKp5vBw2jOFC4mRI1vjmETrSdu%2BYuLu%2FICD3Nn2TKxzd0d60n9W08r6kTgtEFZZTNPhXe2Jk74oVaKOAuf50B2cELpiGPX2IRImbiSKjqs3lFWxZWaUFL23Qk82VimFqiSWHwpjIE5BQOJf04g41QgvonPnCiDTPQOMZgpAuOSqgczyaRNBOPFqrQQ%3D%3D: HTTPSConnectionPool(host='storage.googleapis.com', port=443): Max retries exceeded with url: /wandb-production.appspot.com/dynamic_x/bert_pytorch/0vfv9wkn/wandb-metadata.json?Expires=1706688636&GoogleAccessId=gorilla-files-url-signer-man%40wandb-production.iam.gserviceaccount.com&Signature=TOE9Ck7npWvU2grZxrdepfkP7GGkjk2DxVjQW47W2UtaiiUt9kEhpI8qATqI9uozu9XFTPhU9B87d%2B31EOqc9ZxpA3r1tpLJ5J7Plx6BWPUp5B1h1IqJ7JfEnxhfv1KuBRsZ4ZG3gHKdTgEWAXjynDk78cVjyKp5vBw2jOFC4mRI1vjmETrSdu%2BYuLu%2FICD3Nn2TKxzd0d60n9W08r6kTgtEFZZTNPhXe2Jk74oVaKOAuf50B2cELpiGPX2IRImbiSKjqs3lFWxZWaUFL23Qk82VimFqiSWHwpjIE5BQOJf04g41QgvonPnCiDTPQOMZgpAuOSqgczyaRNBOPFqrQQ%3D%3D (Caused by NewConnectionError('<urllib3.connection.HTTPSConnection object at 0x7f3188789be0>: Failed to establish a new connection: [Errno 111] Connection refused'))
2024-01-30 16:25:53,526 ERROR   wandb-upload_0:1134331 [internal_api.py:upload_file():2767] upload_file request headers: {'User-Agent': 'python-requests/2.23.0', 'Accept-Encoding': 'gzip, deflate', 'Accept': '*/*', 'Connection': 'keep-alive', 'Content-Length': '15546'}
2024-01-30 16:25:53,526 ERROR   wandb-upload_0:1134331 [internal_api.py:upload_file():2769] upload_file response body: 
2024-01-30 16:31:12,458 ERROR   wandb-upload_0:1134331 [internal_api.py:upload_file():2765] upload_file exception https://storage.googleapis.com/wandb-production.appspot.com/dynamic_x/bert_pytorch/0vfv9wkn/wandb-metadata.json?Expires=1706688636&GoogleAccessId=gorilla-files-url-signer-man%40wandb-production.iam.gserviceaccount.com&Signature=TOE9Ck7npWvU2grZxrdepfkP7GGkjk2DxVjQW47W2UtaiiUt9kEhpI8qATqI9uozu9XFTPhU9B87d%2B31EOqc9ZxpA3r1tpLJ5J7Plx6BWPUp5B1h1IqJ7JfEnxhfv1KuBRsZ4ZG3gHKdTgEWAXjynDk78cVjyKp5vBw2jOFC4mRI1vjmETrSdu%2BYuLu%2FICD3Nn2TKxzd0d60n9W08r6kTgtEFZZTNPhXe2Jk74oVaKOAuf50B2cELpiGPX2IRImbiSKjqs3lFWxZWaUFL23Qk82VimFqiSWHwpjIE5BQOJf04g41QgvonPnCiDTPQOMZgpAuOSqgczyaRNBOPFqrQQ%3D%3D: HTTPSConnectionPool(host='storage.googleapis.com', port=443): Max retries exceeded with url: /wandb-production.appspot.com/dynamic_x/bert_pytorch/0vfv9wkn/wandb-metadata.json?Expires=1706688636&GoogleAccessId=gorilla-files-url-signer-man%40wandb-production.iam.gserviceaccount.com&Signature=TOE9Ck7npWvU2grZxrdepfkP7GGkjk2DxVjQW47W2UtaiiUt9kEhpI8qATqI9uozu9XFTPhU9B87d%2B31EOqc9ZxpA3r1tpLJ5J7Plx6BWPUp5B1h1IqJ7JfEnxhfv1KuBRsZ4ZG3gHKdTgEWAXjynDk78cVjyKp5vBw2jOFC4mRI1vjmETrSdu%2BYuLu%2FICD3Nn2TKxzd0d60n9W08r6kTgtEFZZTNPhXe2Jk74oVaKOAuf50B2cELpiGPX2IRImbiSKjqs3lFWxZWaUFL23Qk82VimFqiSWHwpjIE5BQOJf04g41QgvonPnCiDTPQOMZgpAuOSqgczyaRNBOPFqrQQ%3D%3D (Caused by NewConnectionError('<urllib3.connection.HTTPSConnection object at 0x7f31a005d250>: Failed to establish a new connection: [Errno 111] Connection refused'))
2024-01-30 16:31:12,459 ERROR   wandb-upload_0:1134331 [internal_api.py:upload_file():2767] upload_file request headers: {'User-Agent': 'python-requests/2.23.0', 'Accept-Encoding': 'gzip, deflate', 'Accept': '*/*', 'Connection': 'keep-alive', 'Content-Length': '15546'}
2024-01-30 16:31:12,459 ERROR   wandb-upload_0:1134331 [internal_api.py:upload_file():2769] upload_file response body: 
2024-01-30 16:36:40,486 ERROR   wandb-upload_0:1134331 [internal_api.py:upload_file():2765] upload_file exception https://storage.googleapis.com/wandb-production.appspot.com/dynamic_x/bert_pytorch/0vfv9wkn/wandb-metadata.json?Expires=1706688636&GoogleAccessId=gorilla-files-url-signer-man%40wandb-production.iam.gserviceaccount.com&Signature=TOE9Ck7npWvU2grZxrdepfkP7GGkjk2DxVjQW47W2UtaiiUt9kEhpI8qATqI9uozu9XFTPhU9B87d%2B31EOqc9ZxpA3r1tpLJ5J7Plx6BWPUp5B1h1IqJ7JfEnxhfv1KuBRsZ4ZG3gHKdTgEWAXjynDk78cVjyKp5vBw2jOFC4mRI1vjmETrSdu%2BYuLu%2FICD3Nn2TKxzd0d60n9W08r6kTgtEFZZTNPhXe2Jk74oVaKOAuf50B2cELpiGPX2IRImbiSKjqs3lFWxZWaUFL23Qk82VimFqiSWHwpjIE5BQOJf04g41QgvonPnCiDTPQOMZgpAuOSqgczyaRNBOPFqrQQ%3D%3D: HTTPSConnectionPool(host='storage.googleapis.com', port=443): Max retries exceeded with url: /wandb-production.appspot.com/dynamic_x/bert_pytorch/0vfv9wkn/wandb-metadata.json?Expires=1706688636&GoogleAccessId=gorilla-files-url-signer-man%40wandb-production.iam.gserviceaccount.com&Signature=TOE9Ck7npWvU2grZxrdepfkP7GGkjk2DxVjQW47W2UtaiiUt9kEhpI8qATqI9uozu9XFTPhU9B87d%2B31EOqc9ZxpA3r1tpLJ5J7Plx6BWPUp5B1h1IqJ7JfEnxhfv1KuBRsZ4ZG3gHKdTgEWAXjynDk78cVjyKp5vBw2jOFC4mRI1vjmETrSdu%2BYuLu%2FICD3Nn2TKxzd0d60n9W08r6kTgtEFZZTNPhXe2Jk74oVaKOAuf50B2cELpiGPX2IRImbiSKjqs3lFWxZWaUFL23Qk82VimFqiSWHwpjIE5BQOJf04g41QgvonPnCiDTPQOMZgpAuOSqgczyaRNBOPFqrQQ%3D%3D (Caused by NewConnectionError('<urllib3.connection.HTTPSConnection object at 0x7f318878bc10>: Failed to establish a new connection: [Errno 111] Connection refused'))
2024-01-30 16:36:40,486 ERROR   wandb-upload_0:1134331 [internal_api.py:upload_file():2767] upload_file request headers: {'User-Agent': 'python-requests/2.23.0', 'Accept-Encoding': 'gzip, deflate', 'Accept': '*/*', 'Connection': 'keep-alive', 'Content-Length': '15546'}
2024-01-30 16:36:40,486 ERROR   wandb-upload_0:1134331 [internal_api.py:upload_file():2769] upload_file response body: 
2024-01-30 16:37:45,174 WARNING StreamThr :1134331 [internal.py:is_dead():414] Internal process exiting, parent pid 1134041 disappeared
2024-01-30 16:37:45,174 ERROR   StreamThr :1134331 [internal.py:wandb_internal():152] Internal process shutdown.
2024-01-30 16:37:45,321 INFO    WriterThread:1134331 [datastore.py:close():296] close: /home/yanxindong/mkor/bert/wandb/run-20240130_161012-0vfv9wkn/run-0vfv9wkn.wandb
2024-01-30 16:37:45,349 INFO    HandlerThread:1134331 [handler.py:finish():869] shutting down handler
2024-01-30 16:40:25,334 ERROR   wandb-upload_1:1134331 [internal_api.py:upload_file():2765] upload_file exception https://storage.googleapis.com/wandb-artifacts-prod/wandb_artifacts/133981200/707680482/174a3d9bc61fec126cc7d5bdff5c6c5a?Expires=1706688978&GoogleAccessId=gorilla-files-url-signer-man%40wandb-production.iam.gserviceaccount.com&Signature=cbtDPc9y%2ByNDqLWUkoqNfv9%2BFmv9BMiMrSHcAoresaF%2F5zpFnevKhT4IxSZwW8ln5fFnp1%2BGuAoFB8Vy%2B0KWZT2PFTA9h7493UfrojVdKstWKu1zMwGIIv9Ki%2B%2B0AI0Y4pqbVFEUyvyM0qKLgSBKKSXa4i3dBkvMbvm%2BaMOzuyJBYBno9cgiMJKY7PaT3qp%2FUk5Ng7h1cisaygxZjjbpolE9T1r3q2rR%2Bu%2FjC9mnSMhsafcXzn%2BKzDEPVbCHVWkSV5ZjBpVn6T4bLb9i9bpTm%2FDZc1I18cSR1stlp9OKN8i1uj4vPgWR%2Faio38JhkXkVcsgx6%2BAcWoQAo2X9g%2Fm8Mg%3D%3D: HTTPSConnectionPool(host='storage.googleapis.com', port=443): Max retries exceeded with url: /wandb-artifacts-prod/wandb_artifacts/133981200/707680482/174a3d9bc61fec126cc7d5bdff5c6c5a?Expires=1706688978&GoogleAccessId=gorilla-files-url-signer-man%40wandb-production.iam.gserviceaccount.com&Signature=cbtDPc9y%2ByNDqLWUkoqNfv9%2BFmv9BMiMrSHcAoresaF%2F5zpFnevKhT4IxSZwW8ln5fFnp1%2BGuAoFB8Vy%2B0KWZT2PFTA9h7493UfrojVdKstWKu1zMwGIIv9Ki%2B%2B0AI0Y4pqbVFEUyvyM0qKLgSBKKSXa4i3dBkvMbvm%2BaMOzuyJBYBno9cgiMJKY7PaT3qp%2FUk5Ng7h1cisaygxZjjbpolE9T1r3q2rR%2Bu%2FjC9mnSMhsafcXzn%2BKzDEPVbCHVWkSV5ZjBpVn6T4bLb9i9bpTm%2FDZc1I18cSR1stlp9OKN8i1uj4vPgWR%2Faio38JhkXkVcsgx6%2BAcWoQAo2X9g%2Fm8Mg%3D%3D (Caused by NewConnectionError('<urllib3.connection.HTTPSConnection object at 0x7f31a00408b0>: Failed to establish a new connection: [Errno 101] Network is unreachable'))
2024-01-30 16:40:25,334 ERROR   wandb-upload_1:1134331 [internal_api.py:upload_file():2767] upload_file request headers: {'User-Agent': 'python-requests/2.23.0', 'Accept-Encoding': 'gzip, deflate', 'Accept': '*/*', 'Connection': 'keep-alive', 'Content-MD5': 'F0o9m8Yf7BJsx9W9/1xsWg==', 'Content-Type': 'text/plain; charset=utf-8', 'Content-Length': '2179'}
2024-01-30 16:40:25,334 ERROR   wandb-upload_1:1134331 [internal_api.py:upload_file():2769] upload_file response body: 
2024-01-30 16:40:43,766 ERROR   wandb-upload_2:1134331 [internal_api.py:upload_file():2765] upload_file exception https://storage.googleapis.com/wandb-artifacts-prod/wandb_artifacts/133981200/707680482/6873c23a2381d1524249eb1a948a45a5?Expires=1706688979&GoogleAccessId=gorilla-files-url-signer-man%40wandb-production.iam.gserviceaccount.com&Signature=UIXrVQypAxHgZq44Mo8m7DKDiOHx4COYTEbj552yh6Cp%2FURg0VnzG54tqZWNmFlghXrcWDl8YsQHDh%2FbuUoCI2eGmCVgBIvjGNTuiGXbH6NhhaAeyAz4CozwmGl98FVvP7bFO7Dz1mwcEIskDGug8qttLU3ROL182sGhTILhhaTyZnlgvCp%2FALjZa%2F2NhdhrUgS81lZoLXo4oHyINK%2FRazN3ypBFND8j6SUL1kEARakxPGrgK0Z3JUyvsvbOK81KVUmLPIojAGNB71JPYXIwwQdC3GPU%2FFcI9Cv1uN4Sb9j24oq2op2YpqAOfcYnerZVSMkBZIzld91LQg7%2BTQvDKQ%3D%3D: HTTPSConnectionPool(host='storage.googleapis.com', port=443): Max retries exceeded with url: /wandb-artifacts-prod/wandb_artifacts/133981200/707680482/6873c23a2381d1524249eb1a948a45a5?Expires=1706688979&GoogleAccessId=gorilla-files-url-signer-man%40wandb-production.iam.gserviceaccount.com&Signature=UIXrVQypAxHgZq44Mo8m7DKDiOHx4COYTEbj552yh6Cp%2FURg0VnzG54tqZWNmFlghXrcWDl8YsQHDh%2FbuUoCI2eGmCVgBIvjGNTuiGXbH6NhhaAeyAz4CozwmGl98FVvP7bFO7Dz1mwcEIskDGug8qttLU3ROL182sGhTILhhaTyZnlgvCp%2FALjZa%2F2NhdhrUgS81lZoLXo4oHyINK%2FRazN3ypBFND8j6SUL1kEARakxPGrgK0Z3JUyvsvbOK81KVUmLPIojAGNB71JPYXIwwQdC3GPU%2FFcI9Cv1uN4Sb9j24oq2op2YpqAOfcYnerZVSMkBZIzld91LQg7%2BTQvDKQ%3D%3D (Caused by NewConnectionError('<urllib3.connection.HTTPSConnection object at 0x7f318878bb50>: Failed to establish a new connection: [Errno 101] Network is unreachable'))
2024-01-30 16:40:43,766 ERROR   wandb-upload_2:1134331 [internal_api.py:upload_file():2767] upload_file request headers: {'User-Agent': 'python-requests/2.23.0', 'Accept-Encoding': 'gzip, deflate', 'Accept': '*/*', 'Connection': 'keep-alive', 'Content-MD5': 'aHPCOiOB0VJCSesalIpFpQ==', 'Content-Type': 'application/json', 'Content-Length': '609'}
2024-01-30 16:40:43,766 ERROR   wandb-upload_2:1134331 [internal_api.py:upload_file():2769] upload_file response body: 
2024-01-30 16:42:18,503 ERROR   wandb-upload_0:1134331 [internal_api.py:upload_file():2765] upload_file exception https://storage.googleapis.com/wandb-production.appspot.com/dynamic_x/bert_pytorch/0vfv9wkn/wandb-metadata.json?Expires=1706688636&GoogleAccessId=gorilla-files-url-signer-man%40wandb-production.iam.gserviceaccount.com&Signature=TOE9Ck7npWvU2grZxrdepfkP7GGkjk2DxVjQW47W2UtaiiUt9kEhpI8qATqI9uozu9XFTPhU9B87d%2B31EOqc9ZxpA3r1tpLJ5J7Plx6BWPUp5B1h1IqJ7JfEnxhfv1KuBRsZ4ZG3gHKdTgEWAXjynDk78cVjyKp5vBw2jOFC4mRI1vjmETrSdu%2BYuLu%2FICD3Nn2TKxzd0d60n9W08r6kTgtEFZZTNPhXe2Jk74oVaKOAuf50B2cELpiGPX2IRImbiSKjqs3lFWxZWaUFL23Qk82VimFqiSWHwpjIE5BQOJf04g41QgvonPnCiDTPQOMZgpAuOSqgczyaRNBOPFqrQQ%3D%3D: HTTPSConnectionPool(host='storage.googleapis.com', port=443): Max retries exceeded with url: /wandb-production.appspot.com/dynamic_x/bert_pytorch/0vfv9wkn/wandb-metadata.json?Expires=1706688636&GoogleAccessId=gorilla-files-url-signer-man%40wandb-production.iam.gserviceaccount.com&Signature=TOE9Ck7npWvU2grZxrdepfkP7GGkjk2DxVjQW47W2UtaiiUt9kEhpI8qATqI9uozu9XFTPhU9B87d%2B31EOqc9ZxpA3r1tpLJ5J7Plx6BWPUp5B1h1IqJ7JfEnxhfv1KuBRsZ4ZG3gHKdTgEWAXjynDk78cVjyKp5vBw2jOFC4mRI1vjmETrSdu%2BYuLu%2FICD3Nn2TKxzd0d60n9W08r6kTgtEFZZTNPhXe2Jk74oVaKOAuf50B2cELpiGPX2IRImbiSKjqs3lFWxZWaUFL23Qk82VimFqiSWHwpjIE5BQOJf04g41QgvonPnCiDTPQOMZgpAuOSqgczyaRNBOPFqrQQ%3D%3D (Caused by NewConnectionError('<urllib3.connection.HTTPSConnection object at 0x7f31887832e0>: Failed to establish a new connection: [Errno 101] Network is unreachable'))
2024-01-30 16:42:18,503 ERROR   wandb-upload_0:1134331 [internal_api.py:upload_file():2767] upload_file request headers: {'User-Agent': 'python-requests/2.23.0', 'Accept-Encoding': 'gzip, deflate', 'Accept': '*/*', 'Connection': 'keep-alive', 'Content-Length': '15546'}
2024-01-30 16:42:18,504 ERROR   wandb-upload_0:1134331 [internal_api.py:upload_file():2769] upload_file response body: 
2024-01-30 16:42:42,595 ERROR   wandb-upload_1:1134331 [internal_api.py:upload_file():2765] upload_file exception https://storage.googleapis.com/wandb-artifacts-prod/wandb_artifacts/133981200/707680482/174a3d9bc61fec126cc7d5bdff5c6c5a?Expires=1706688978&GoogleAccessId=gorilla-files-url-signer-man%40wandb-production.iam.gserviceaccount.com&Signature=cbtDPc9y%2ByNDqLWUkoqNfv9%2BFmv9BMiMrSHcAoresaF%2F5zpFnevKhT4IxSZwW8ln5fFnp1%2BGuAoFB8Vy%2B0KWZT2PFTA9h7493UfrojVdKstWKu1zMwGIIv9Ki%2B%2B0AI0Y4pqbVFEUyvyM0qKLgSBKKSXa4i3dBkvMbvm%2BaMOzuyJBYBno9cgiMJKY7PaT3qp%2FUk5Ng7h1cisaygxZjjbpolE9T1r3q2rR%2Bu%2FjC9mnSMhsafcXzn%2BKzDEPVbCHVWkSV5ZjBpVn6T4bLb9i9bpTm%2FDZc1I18cSR1stlp9OKN8i1uj4vPgWR%2Faio38JhkXkVcsgx6%2BAcWoQAo2X9g%2Fm8Mg%3D%3D: HTTPSConnectionPool(host='storage.googleapis.com', port=443): Max retries exceeded with url: /wandb-artifacts-prod/wandb_artifacts/133981200/707680482/174a3d9bc61fec126cc7d5bdff5c6c5a?Expires=1706688978&GoogleAccessId=gorilla-files-url-signer-man%40wandb-production.iam.gserviceaccount.com&Signature=cbtDPc9y%2ByNDqLWUkoqNfv9%2BFmv9BMiMrSHcAoresaF%2F5zpFnevKhT4IxSZwW8ln5fFnp1%2BGuAoFB8Vy%2B0KWZT2PFTA9h7493UfrojVdKstWKu1zMwGIIv9Ki%2B%2B0AI0Y4pqbVFEUyvyM0qKLgSBKKSXa4i3dBkvMbvm%2BaMOzuyJBYBno9cgiMJKY7PaT3qp%2FUk5Ng7h1cisaygxZjjbpolE9T1r3q2rR%2Bu%2FjC9mnSMhsafcXzn%2BKzDEPVbCHVWkSV5ZjBpVn6T4bLb9i9bpTm%2FDZc1I18cSR1stlp9OKN8i1uj4vPgWR%2Faio38JhkXkVcsgx6%2BAcWoQAo2X9g%2Fm8Mg%3D%3D (Caused by NewConnectionError('<urllib3.connection.HTTPSConnection object at 0x7f3188789550>: Failed to establish a new connection: [Errno 101] Network is unreachable'))
2024-01-30 16:42:42,595 ERROR   wandb-upload_1:1134331 [internal_api.py:upload_file():2767] upload_file request headers: {'User-Agent': 'python-requests/2.23.0', 'Accept-Encoding': 'gzip, deflate', 'Accept': '*/*', 'Connection': 'keep-alive', 'Content-MD5': 'F0o9m8Yf7BJsx9W9/1xsWg==', 'Content-Type': 'text/plain; charset=utf-8', 'Content-Length': '2179'}
2024-01-30 16:42:42,595 ERROR   wandb-upload_1:1134331 [internal_api.py:upload_file():2769] upload_file response body: 
2024-01-30 16:43:23,100 ERROR   wandb-upload_2:1134331 [internal_api.py:upload_file():2765] upload_file exception https://storage.googleapis.com/wandb-artifacts-prod/wandb_artifacts/133981200/707680482/6873c23a2381d1524249eb1a948a45a5?Expires=1706688979&GoogleAccessId=gorilla-files-url-signer-man%40wandb-production.iam.gserviceaccount.com&Signature=UIXrVQypAxHgZq44Mo8m7DKDiOHx4COYTEbj552yh6Cp%2FURg0VnzG54tqZWNmFlghXrcWDl8YsQHDh%2FbuUoCI2eGmCVgBIvjGNTuiGXbH6NhhaAeyAz4CozwmGl98FVvP7bFO7Dz1mwcEIskDGug8qttLU3ROL182sGhTILhhaTyZnlgvCp%2FALjZa%2F2NhdhrUgS81lZoLXo4oHyINK%2FRazN3ypBFND8j6SUL1kEARakxPGrgK0Z3JUyvsvbOK81KVUmLPIojAGNB71JPYXIwwQdC3GPU%2FFcI9Cv1uN4Sb9j24oq2op2YpqAOfcYnerZVSMkBZIzld91LQg7%2BTQvDKQ%3D%3D: HTTPSConnectionPool(host='storage.googleapis.com', port=443): Max retries exceeded with url: /wandb-artifacts-prod/wandb_artifacts/133981200/707680482/6873c23a2381d1524249eb1a948a45a5?Expires=1706688979&GoogleAccessId=gorilla-files-url-signer-man%40wandb-production.iam.gserviceaccount.com&Signature=UIXrVQypAxHgZq44Mo8m7DKDiOHx4COYTEbj552yh6Cp%2FURg0VnzG54tqZWNmFlghXrcWDl8YsQHDh%2FbuUoCI2eGmCVgBIvjGNTuiGXbH6NhhaAeyAz4CozwmGl98FVvP7bFO7Dz1mwcEIskDGug8qttLU3ROL182sGhTILhhaTyZnlgvCp%2FALjZa%2F2NhdhrUgS81lZoLXo4oHyINK%2FRazN3ypBFND8j6SUL1kEARakxPGrgK0Z3JUyvsvbOK81KVUmLPIojAGNB71JPYXIwwQdC3GPU%2FFcI9Cv1uN4Sb9j24oq2op2YpqAOfcYnerZVSMkBZIzld91LQg7%2BTQvDKQ%3D%3D (Caused by NewConnectionError('<urllib3.connection.HTTPSConnection object at 0x7f3188783850>: Failed to establish a new connection: [Errno 101] Network is unreachable'))
2024-01-30 16:43:23,100 ERROR   wandb-upload_2:1134331 [internal_api.py:upload_file():2767] upload_file request headers: {'User-Agent': 'python-requests/2.23.0', 'Accept-Encoding': 'gzip, deflate', 'Accept': '*/*', 'Connection': 'keep-alive', 'Content-MD5': 'aHPCOiOB0VJCSesalIpFpQ==', 'Content-Type': 'application/json', 'Content-Length': '609'}
2024-01-30 16:43:23,100 ERROR   wandb-upload_2:1134331 [internal_api.py:upload_file():2769] upload_file response body: 
2024-01-30 17:11:06,486 ERROR   wandb-upload_1:1134331 [internal_api.py:upload_file():2765] upload_file exception https://storage.googleapis.com/wandb-artifacts-prod/wandb_artifacts/133981200/707680482/174a3d9bc61fec126cc7d5bdff5c6c5a?Expires=1706688978&GoogleAccessId=gorilla-files-url-signer-man%40wandb-production.iam.gserviceaccount.com&Signature=cbtDPc9y%2ByNDqLWUkoqNfv9%2BFmv9BMiMrSHcAoresaF%2F5zpFnevKhT4IxSZwW8ln5fFnp1%2BGuAoFB8Vy%2B0KWZT2PFTA9h7493UfrojVdKstWKu1zMwGIIv9Ki%2B%2B0AI0Y4pqbVFEUyvyM0qKLgSBKKSXa4i3dBkvMbvm%2BaMOzuyJBYBno9cgiMJKY7PaT3qp%2FUk5Ng7h1cisaygxZjjbpolE9T1r3q2rR%2Bu%2FjC9mnSMhsafcXzn%2BKzDEPVbCHVWkSV5ZjBpVn6T4bLb9i9bpTm%2FDZc1I18cSR1stlp9OKN8i1uj4vPgWR%2Faio38JhkXkVcsgx6%2BAcWoQAo2X9g%2Fm8Mg%3D%3D: HTTPSConnectionPool(host='storage.googleapis.com', port=443): Max retries exceeded with url: /wandb-artifacts-prod/wandb_artifacts/133981200/707680482/174a3d9bc61fec126cc7d5bdff5c6c5a?Expires=1706688978&GoogleAccessId=gorilla-files-url-signer-man%40wandb-production.iam.gserviceaccount.com&Signature=cbtDPc9y%2ByNDqLWUkoqNfv9%2BFmv9BMiMrSHcAoresaF%2F5zpFnevKhT4IxSZwW8ln5fFnp1%2BGuAoFB8Vy%2B0KWZT2PFTA9h7493UfrojVdKstWKu1zMwGIIv9Ki%2B%2B0AI0Y4pqbVFEUyvyM0qKLgSBKKSXa4i3dBkvMbvm%2BaMOzuyJBYBno9cgiMJKY7PaT3qp%2FUk5Ng7h1cisaygxZjjbpolE9T1r3q2rR%2Bu%2FjC9mnSMhsafcXzn%2BKzDEPVbCHVWkSV5ZjBpVn6T4bLb9i9bpTm%2FDZc1I18cSR1stlp9OKN8i1uj4vPgWR%2Faio38JhkXkVcsgx6%2BAcWoQAo2X9g%2Fm8Mg%3D%3D (Caused by NewConnectionError('<urllib3.connection.HTTPSConnection object at 0x7f318878b9a0>: Failed to establish a new connection: [Errno 110] Connection timed out'))
2024-01-30 17:11:06,486 ERROR   wandb-upload_1:1134331 [internal_api.py:upload_file():2767] upload_file request headers: {'User-Agent': 'python-requests/2.23.0', 'Accept-Encoding': 'gzip, deflate', 'Accept': '*/*', 'Connection': 'keep-alive', 'Content-MD5': 'F0o9m8Yf7BJsx9W9/1xsWg==', 'Content-Type': 'text/plain; charset=utf-8', 'Content-Length': '2179'}
2024-01-30 17:11:06,486 ERROR   wandb-upload_1:1134331 [internal_api.py:upload_file():2769] upload_file response body: 
2024-01-30 17:11:31,062 ERROR   wandb-upload_0:1134331 [internal_api.py:upload_file():2765] upload_file exception https://storage.googleapis.com/wandb-production.appspot.com/dynamic_x/bert_pytorch/0vfv9wkn/wandb-metadata.json?Expires=1706688636&GoogleAccessId=gorilla-files-url-signer-man%40wandb-production.iam.gserviceaccount.com&Signature=TOE9Ck7npWvU2grZxrdepfkP7GGkjk2DxVjQW47W2UtaiiUt9kEhpI8qATqI9uozu9XFTPhU9B87d%2B31EOqc9ZxpA3r1tpLJ5J7Plx6BWPUp5B1h1IqJ7JfEnxhfv1KuBRsZ4ZG3gHKdTgEWAXjynDk78cVjyKp5vBw2jOFC4mRI1vjmETrSdu%2BYuLu%2FICD3Nn2TKxzd0d60n9W08r6kTgtEFZZTNPhXe2Jk74oVaKOAuf50B2cELpiGPX2IRImbiSKjqs3lFWxZWaUFL23Qk82VimFqiSWHwpjIE5BQOJf04g41QgvonPnCiDTPQOMZgpAuOSqgczyaRNBOPFqrQQ%3D%3D: HTTPSConnectionPool(host='storage.googleapis.com', port=443): Max retries exceeded with url: /wandb-production.appspot.com/dynamic_x/bert_pytorch/0vfv9wkn/wandb-metadata.json?Expires=1706688636&GoogleAccessId=gorilla-files-url-signer-man%40wandb-production.iam.gserviceaccount.com&Signature=TOE9Ck7npWvU2grZxrdepfkP7GGkjk2DxVjQW47W2UtaiiUt9kEhpI8qATqI9uozu9XFTPhU9B87d%2B31EOqc9ZxpA3r1tpLJ5J7Plx6BWPUp5B1h1IqJ7JfEnxhfv1KuBRsZ4ZG3gHKdTgEWAXjynDk78cVjyKp5vBw2jOFC4mRI1vjmETrSdu%2BYuLu%2FICD3Nn2TKxzd0d60n9W08r6kTgtEFZZTNPhXe2Jk74oVaKOAuf50B2cELpiGPX2IRImbiSKjqs3lFWxZWaUFL23Qk82VimFqiSWHwpjIE5BQOJf04g41QgvonPnCiDTPQOMZgpAuOSqgczyaRNBOPFqrQQ%3D%3D (Caused by NewConnectionError('<urllib3.connection.HTTPSConnection object at 0x7f3188789e20>: Failed to establish a new connection: [Errno 110] Connection timed out'))
2024-01-30 17:11:31,062 ERROR   wandb-upload_0:1134331 [internal_api.py:upload_file():2767] upload_file request headers: {'User-Agent': 'python-requests/2.23.0', 'Accept-Encoding': 'gzip, deflate', 'Accept': '*/*', 'Connection': 'keep-alive', 'Content-Length': '15546'}
2024-01-30 17:11:31,062 ERROR   wandb-upload_0:1134331 [internal_api.py:upload_file():2769] upload_file response body: 
2024-01-30 17:12:03,830 ERROR   wandb-upload_2:1134331 [internal_api.py:upload_file():2765] upload_file exception https://storage.googleapis.com/wandb-artifacts-prod/wandb_artifacts/133981200/707680482/6873c23a2381d1524249eb1a948a45a5?Expires=1706688979&GoogleAccessId=gorilla-files-url-signer-man%40wandb-production.iam.gserviceaccount.com&Signature=UIXrVQypAxHgZq44Mo8m7DKDiOHx4COYTEbj552yh6Cp%2FURg0VnzG54tqZWNmFlghXrcWDl8YsQHDh%2FbuUoCI2eGmCVgBIvjGNTuiGXbH6NhhaAeyAz4CozwmGl98FVvP7bFO7Dz1mwcEIskDGug8qttLU3ROL182sGhTILhhaTyZnlgvCp%2FALjZa%2F2NhdhrUgS81lZoLXo4oHyINK%2FRazN3ypBFND8j6SUL1kEARakxPGrgK0Z3JUyvsvbOK81KVUmLPIojAGNB71JPYXIwwQdC3GPU%2FFcI9Cv1uN4Sb9j24oq2op2YpqAOfcYnerZVSMkBZIzld91LQg7%2BTQvDKQ%3D%3D: HTTPSConnectionPool(host='storage.googleapis.com', port=443): Max retries exceeded with url: /wandb-artifacts-prod/wandb_artifacts/133981200/707680482/6873c23a2381d1524249eb1a948a45a5?Expires=1706688979&GoogleAccessId=gorilla-files-url-signer-man%40wandb-production.iam.gserviceaccount.com&Signature=UIXrVQypAxHgZq44Mo8m7DKDiOHx4COYTEbj552yh6Cp%2FURg0VnzG54tqZWNmFlghXrcWDl8YsQHDh%2FbuUoCI2eGmCVgBIvjGNTuiGXbH6NhhaAeyAz4CozwmGl98FVvP7bFO7Dz1mwcEIskDGug8qttLU3ROL182sGhTILhhaTyZnlgvCp%2FALjZa%2F2NhdhrUgS81lZoLXo4oHyINK%2FRazN3ypBFND8j6SUL1kEARakxPGrgK0Z3JUyvsvbOK81KVUmLPIojAGNB71JPYXIwwQdC3GPU%2FFcI9Cv1uN4Sb9j24oq2op2YpqAOfcYnerZVSMkBZIzld91LQg7%2BTQvDKQ%3D%3D (Caused by NewConnectionError('<urllib3.connection.HTTPSConnection object at 0x7f31887793d0>: Failed to establish a new connection: [Errno 110] Connection timed out'))
2024-01-30 17:12:03,830 ERROR   wandb-upload_2:1134331 [internal_api.py:upload_file():2767] upload_file request headers: {'User-Agent': 'python-requests/2.23.0', 'Accept-Encoding': 'gzip, deflate', 'Accept': '*/*', 'Connection': 'keep-alive', 'Content-MD5': 'aHPCOiOB0VJCSesalIpFpQ==', 'Content-Type': 'application/json', 'Content-Length': '609'}
2024-01-30 17:12:03,830 ERROR   wandb-upload_2:1134331 [internal_api.py:upload_file():2769] upload_file response body: 
2024-01-30 17:16:25,240 ERROR   wandb-upload_1:1134331 [internal_api.py:upload_file():2765] upload_file exception https://storage.googleapis.com/wandb-artifacts-prod/wandb_artifacts/133981200/707680482/174a3d9bc61fec126cc7d5bdff5c6c5a?Expires=1706688978&GoogleAccessId=gorilla-files-url-signer-man%40wandb-production.iam.gserviceaccount.com&Signature=cbtDPc9y%2ByNDqLWUkoqNfv9%2BFmv9BMiMrSHcAoresaF%2F5zpFnevKhT4IxSZwW8ln5fFnp1%2BGuAoFB8Vy%2B0KWZT2PFTA9h7493UfrojVdKstWKu1zMwGIIv9Ki%2B%2B0AI0Y4pqbVFEUyvyM0qKLgSBKKSXa4i3dBkvMbvm%2BaMOzuyJBYBno9cgiMJKY7PaT3qp%2FUk5Ng7h1cisaygxZjjbpolE9T1r3q2rR%2Bu%2FjC9mnSMhsafcXzn%2BKzDEPVbCHVWkSV5ZjBpVn6T4bLb9i9bpTm%2FDZc1I18cSR1stlp9OKN8i1uj4vPgWR%2Faio38JhkXkVcsgx6%2BAcWoQAo2X9g%2Fm8Mg%3D%3D: HTTPSConnectionPool(host='storage.googleapis.com', port=443): Max retries exceeded with url: /wandb-artifacts-prod/wandb_artifacts/133981200/707680482/174a3d9bc61fec126cc7d5bdff5c6c5a?Expires=1706688978&GoogleAccessId=gorilla-files-url-signer-man%40wandb-production.iam.gserviceaccount.com&Signature=cbtDPc9y%2ByNDqLWUkoqNfv9%2BFmv9BMiMrSHcAoresaF%2F5zpFnevKhT4IxSZwW8ln5fFnp1%2BGuAoFB8Vy%2B0KWZT2PFTA9h7493UfrojVdKstWKu1zMwGIIv9Ki%2B%2B0AI0Y4pqbVFEUyvyM0qKLgSBKKSXa4i3dBkvMbvm%2BaMOzuyJBYBno9cgiMJKY7PaT3qp%2FUk5Ng7h1cisaygxZjjbpolE9T1r3q2rR%2Bu%2FjC9mnSMhsafcXzn%2BKzDEPVbCHVWkSV5ZjBpVn6T4bLb9i9bpTm%2FDZc1I18cSR1stlp9OKN8i1uj4vPgWR%2Faio38JhkXkVcsgx6%2BAcWoQAo2X9g%2Fm8Mg%3D%3D (Caused by NewConnectionError('<urllib3.connection.HTTPSConnection object at 0x7f31a005dc10>: Failed to establish a new connection: [Errno 101] Network is unreachable'))
2024-01-30 17:16:25,240 ERROR   wandb-upload_1:1134331 [internal_api.py:upload_file():2767] upload_file request headers: {'User-Agent': 'python-requests/2.23.0', 'Accept-Encoding': 'gzip, deflate', 'Accept': '*/*', 'Connection': 'keep-alive', 'Content-MD5': 'F0o9m8Yf7BJsx9W9/1xsWg==', 'Content-Type': 'text/plain; charset=utf-8', 'Content-Length': '2179'}
2024-01-30 17:16:25,240 ERROR   wandb-upload_1:1134331 [internal_api.py:upload_file():2769] upload_file response body: 
2024-01-30 17:17:17,524 ERROR   wandb-upload_0:1134331 [internal_api.py:upload_file():2765] upload_file exception https://storage.googleapis.com/wandb-production.appspot.com/dynamic_x/bert_pytorch/0vfv9wkn/wandb-metadata.json?Expires=1706688636&GoogleAccessId=gorilla-files-url-signer-man%40wandb-production.iam.gserviceaccount.com&Signature=TOE9Ck7npWvU2grZxrdepfkP7GGkjk2DxVjQW47W2UtaiiUt9kEhpI8qATqI9uozu9XFTPhU9B87d%2B31EOqc9ZxpA3r1tpLJ5J7Plx6BWPUp5B1h1IqJ7JfEnxhfv1KuBRsZ4ZG3gHKdTgEWAXjynDk78cVjyKp5vBw2jOFC4mRI1vjmETrSdu%2BYuLu%2FICD3Nn2TKxzd0d60n9W08r6kTgtEFZZTNPhXe2Jk74oVaKOAuf50B2cELpiGPX2IRImbiSKjqs3lFWxZWaUFL23Qk82VimFqiSWHwpjIE5BQOJf04g41QgvonPnCiDTPQOMZgpAuOSqgczyaRNBOPFqrQQ%3D%3D: HTTPSConnectionPool(host='storage.googleapis.com', port=443): Max retries exceeded with url: /wandb-production.appspot.com/dynamic_x/bert_pytorch/0vfv9wkn/wandb-metadata.json?Expires=1706688636&GoogleAccessId=gorilla-files-url-signer-man%40wandb-production.iam.gserviceaccount.com&Signature=TOE9Ck7npWvU2grZxrdepfkP7GGkjk2DxVjQW47W2UtaiiUt9kEhpI8qATqI9uozu9XFTPhU9B87d%2B31EOqc9ZxpA3r1tpLJ5J7Plx6BWPUp5B1h1IqJ7JfEnxhfv1KuBRsZ4ZG3gHKdTgEWAXjynDk78cVjyKp5vBw2jOFC4mRI1vjmETrSdu%2BYuLu%2FICD3Nn2TKxzd0d60n9W08r6kTgtEFZZTNPhXe2Jk74oVaKOAuf50B2cELpiGPX2IRImbiSKjqs3lFWxZWaUFL23Qk82VimFqiSWHwpjIE5BQOJf04g41QgvonPnCiDTPQOMZgpAuOSqgczyaRNBOPFqrQQ%3D%3D (Caused by NewConnectionError('<urllib3.connection.HTTPSConnection object at 0x7f3188783dc0>: Failed to establish a new connection: [Errno 101] Network is unreachable'))
2024-01-30 17:17:17,524 ERROR   wandb-upload_0:1134331 [internal_api.py:upload_file():2767] upload_file request headers: {'User-Agent': 'python-requests/2.23.0', 'Accept-Encoding': 'gzip, deflate', 'Accept': '*/*', 'Connection': 'keep-alive', 'Content-Length': '15546'}
2024-01-30 17:17:17,524 ERROR   wandb-upload_0:1134331 [internal_api.py:upload_file():2769] upload_file response body: 
2024-01-30 17:17:55,607 ERROR   wandb-upload_2:1134331 [internal_api.py:upload_file():2765] upload_file exception https://storage.googleapis.com/wandb-artifacts-prod/wandb_artifacts/133981200/707680482/6873c23a2381d1524249eb1a948a45a5?Expires=1706688979&GoogleAccessId=gorilla-files-url-signer-man%40wandb-production.iam.gserviceaccount.com&Signature=UIXrVQypAxHgZq44Mo8m7DKDiOHx4COYTEbj552yh6Cp%2FURg0VnzG54tqZWNmFlghXrcWDl8YsQHDh%2FbuUoCI2eGmCVgBIvjGNTuiGXbH6NhhaAeyAz4CozwmGl98FVvP7bFO7Dz1mwcEIskDGug8qttLU3ROL182sGhTILhhaTyZnlgvCp%2FALjZa%2F2NhdhrUgS81lZoLXo4oHyINK%2FRazN3ypBFND8j6SUL1kEARakxPGrgK0Z3JUyvsvbOK81KVUmLPIojAGNB71JPYXIwwQdC3GPU%2FFcI9Cv1uN4Sb9j24oq2op2YpqAOfcYnerZVSMkBZIzld91LQg7%2BTQvDKQ%3D%3D: HTTPSConnectionPool(host='storage.googleapis.com', port=443): Max retries exceeded with url: /wandb-artifacts-prod/wandb_artifacts/133981200/707680482/6873c23a2381d1524249eb1a948a45a5?Expires=1706688979&GoogleAccessId=gorilla-files-url-signer-man%40wandb-production.iam.gserviceaccount.com&Signature=UIXrVQypAxHgZq44Mo8m7DKDiOHx4COYTEbj552yh6Cp%2FURg0VnzG54tqZWNmFlghXrcWDl8YsQHDh%2FbuUoCI2eGmCVgBIvjGNTuiGXbH6NhhaAeyAz4CozwmGl98FVvP7bFO7Dz1mwcEIskDGug8qttLU3ROL182sGhTILhhaTyZnlgvCp%2FALjZa%2F2NhdhrUgS81lZoLXo4oHyINK%2FRazN3ypBFND8j6SUL1kEARakxPGrgK0Z3JUyvsvbOK81KVUmLPIojAGNB71JPYXIwwQdC3GPU%2FFcI9Cv1uN4Sb9j24oq2op2YpqAOfcYnerZVSMkBZIzld91LQg7%2BTQvDKQ%3D%3D (Caused by NewConnectionError('<urllib3.connection.HTTPSConnection object at 0x7f31a005d9a0>: Failed to establish a new connection: [Errno 101] Network is unreachable'))
2024-01-30 17:17:55,607 ERROR   wandb-upload_2:1134331 [internal_api.py:upload_file():2767] upload_file request headers: {'User-Agent': 'python-requests/2.23.0', 'Accept-Encoding': 'gzip, deflate', 'Accept': '*/*', 'Connection': 'keep-alive', 'Content-MD5': 'aHPCOiOB0VJCSesalIpFpQ==', 'Content-Type': 'application/json', 'Content-Length': '609'}
2024-01-30 17:17:55,608 ERROR   wandb-upload_2:1134331 [internal_api.py:upload_file():2769] upload_file response body: 
2024-01-30 17:22:37,874 INFO    wandb-upload_1:1134331 [upload_job.py:push():89] Uploaded file /home/yanxindong/.local/share/wandb/artifacts/staging/tmpc4u6wn4h
2024-01-30 17:22:59,978 INFO    wandb-upload_2:1134331 [upload_job.py:push():89] Uploaded file /home/yanxindong/.local/share/wandb/artifacts/staging/tmpabpozer0
2024-01-30 17:23:03,272 INFO    SenderThread:1134331 [sender.py:send_artifact():1494] sent artifact job-https___github.com_kkkjj-d_mkor.git_bert_run_pretraining.py - {'id': 'QXJ0aWZhY3Q6NzA3NjgwNDgy', 'state': 'PENDING', 'artifactSequence': {'id': 'QXJ0aWZhY3RDb2xsZWN0aW9uOjEzMzk4MTIwMA==', 'latestArtifact': {'id': 'QXJ0aWZhY3Q6NzAzOTc3Mjk3', 'versionIndex': 8}}}
2024-01-30 17:23:03,273 INFO    SenderThread:1134331 [sender.py:finish():1572] shutting down sender
2024-01-30 17:23:03,273 INFO    SenderThread:1134331 [dir_watcher.py:finish():358] shutting down directory watcher
2024-01-30 17:23:03,508 INFO    SenderThread:1134331 [dir_watcher.py:finish():388] scan: /home/yanxindong/mkor/bert/wandb/run-20240130_161012-0vfv9wkn/files
2024-01-30 17:23:03,508 INFO    SenderThread:1134331 [dir_watcher.py:finish():402] scan save: /home/yanxindong/mkor/bert/wandb/run-20240130_161012-0vfv9wkn/files/wandb-summary.json wandb-summary.json
2024-01-30 17:23:03,508 INFO    SenderThread:1134331 [dir_watcher.py:finish():402] scan save: /home/yanxindong/mkor/bert/wandb/run-20240130_161012-0vfv9wkn/files/conda-environment.yaml conda-environment.yaml
2024-01-30 17:23:03,509 INFO    SenderThread:1134331 [dir_watcher.py:finish():402] scan save: /home/yanxindong/mkor/bert/wandb/run-20240130_161012-0vfv9wkn/files/wandb-metadata.json wandb-metadata.json
2024-01-30 17:23:03,509 INFO    SenderThread:1134331 [dir_watcher.py:finish():402] scan save: /home/yanxindong/mkor/bert/wandb/run-20240130_161012-0vfv9wkn/files/output.log output.log
2024-01-30 17:23:03,510 INFO    SenderThread:1134331 [dir_watcher.py:finish():402] scan save: /home/yanxindong/mkor/bert/wandb/run-20240130_161012-0vfv9wkn/files/requirements.txt requirements.txt
2024-01-30 17:23:03,513 INFO    SenderThread:1134331 [dir_watcher.py:finish():402] scan save: /home/yanxindong/mkor/bert/wandb/run-20240130_161012-0vfv9wkn/files/config.yaml config.yaml
2024-01-30 17:23:03,524 INFO    SenderThread:1134331 [file_pusher.py:finish():175] shutting down file pusher
2024-01-30 17:23:03,524 INFO    SenderThread:1134331 [file_pusher.py:join():181] waiting for file pusher
2024-01-30 17:23:04,170 INFO    wandb-upload_1:1134331 [upload_job.py:push():131] Uploaded file /home/yanxindong/mkor/bert/wandb/run-20240130_161012-0vfv9wkn/files/wandb-summary.json
2024-01-30 17:23:04,536 INFO    wandb-upload_3:1134331 [upload_job.py:push():131] Uploaded file /home/yanxindong/mkor/bert/wandb/run-20240130_161012-0vfv9wkn/files/output.log
2024-01-30 17:23:04,538 INFO    wandb-upload_4:1134331 [upload_job.py:push():131] Uploaded file /home/yanxindong/mkor/bert/wandb/run-20240130_161012-0vfv9wkn/files/requirements.txt
2024-01-30 17:23:04,539 INFO    wandb-upload_5:1134331 [upload_job.py:push():131] Uploaded file /home/yanxindong/mkor/bert/wandb/run-20240130_161012-0vfv9wkn/files/config.yaml
2024-01-30 17:23:05,278 INFO    wandb-upload_2:1134331 [upload_job.py:push():131] Uploaded file /home/yanxindong/mkor/bert/wandb/run-20240130_161012-0vfv9wkn/files/conda-environment.yaml
2024-01-30 17:23:21,076 INFO    wandb-upload_0:1134331 [upload_job.py:push():131] Uploaded file /tmp/tmpg6euxc1hwandb/p2vkt9xa-wandb-metadata.json
2024-01-30 17:23:21,544 INFO    SenderThread:1134331 [file_stream.py:finish():595] file stream finish called
2024-01-30 17:23:21,841 INFO    SenderThread:1134331 [file_stream.py:finish():599] file stream finish is done
