2024-01-30 16:10:12,604 INFO    StreamThr :1134332 [internal.py:wandb_internal():86] W&B internal server running at pid: 1134332, started at: 2024-01-30 16:10:12.603991
2024-01-30 16:10:12,613 DEBUG   HandlerThread:1134332 [handler.py:handle_request():146] handle_request: status
2024-01-30 16:10:12,614 INFO    WriterThread:1134332 [datastore.py:open_for_write():87] open: /home/yanxindong/mkor/bert/wandb/run-20240130_161012-xvi6icyy/run-xvi6icyy.wandb
2024-01-30 16:10:12,615 DEBUG   SenderThread:1134332 [sender.py:send():382] send: header
2024-01-30 16:10:12,621 DEBUG   SenderThread:1134332 [sender.py:send():382] send: run
2024-01-30 16:10:13,926 DEBUG   HandlerThread:1134332 [handler.py:handle_request():146] handle_request: check_version
2024-01-30 16:10:13,928 INFO    SenderThread:1134332 [dir_watcher.py:__init__():211] watching files in: /home/yanxindong/mkor/bert/wandb/run-20240130_161012-xvi6icyy/files
2024-01-30 16:10:13,928 INFO    SenderThread:1134332 [sender.py:_start_run_threads():1136] run started: xvi6icyy with start time 1706602212.577093
2024-01-30 16:10:13,928 DEBUG   SenderThread:1134332 [sender.py:send_request():409] send_request: check_version
2024-01-30 16:10:14,851 DEBUG   HandlerThread:1134332 [handler.py:handle_request():146] handle_request: run_start
2024-01-30 16:10:14,861 DEBUG   HandlerThread:1134332 [system_info.py:__init__():27] System info init
2024-01-30 16:10:14,861 DEBUG   HandlerThread:1134332 [system_info.py:__init__():42] System info init done
2024-01-30 16:10:14,861 INFO    HandlerThread:1134332 [system_monitor.py:start():194] Starting system monitor
2024-01-30 16:10:14,892 INFO    SystemMonitor:1134332 [system_monitor.py:_start():158] Starting system asset monitoring threads
2024-01-30 16:10:14,892 INFO    HandlerThread:1134332 [system_monitor.py:probe():214] Collecting system info
2024-01-30 16:10:14,945 INFO    SystemMonitor:1134332 [interfaces.py:start():190] Started cpu monitoring
2024-01-30 16:10:14,977 INFO    SystemMonitor:1134332 [interfaces.py:start():190] Started disk monitoring
2024-01-30 16:10:15,001 INFO    SystemMonitor:1134332 [interfaces.py:start():190] Started gpu monitoring
2024-01-30 16:10:15,017 INFO    SystemMonitor:1134332 [interfaces.py:start():190] Started memory monitoring
2024-01-30 16:10:15,032 INFO    SystemMonitor:1134332 [interfaces.py:start():190] Started network monitoring
2024-01-30 16:10:15,100 DEBUG   HandlerThread:1134332 [system_info.py:probe():151] Probing system
2024-01-30 16:10:15,129 DEBUG   HandlerThread:1134332 [system_info.py:_probe_git():136] Probing git
2024-01-30 16:10:15,190 DEBUG   HandlerThread:1134332 [system_info.py:_probe_git():144] Probing git done
2024-01-30 16:10:15,190 DEBUG   HandlerThread:1134332 [system_info.py:probe():199] Probing system done
2024-01-30 16:10:15,190 DEBUG   HandlerThread:1134332 [system_monitor.py:probe():223] {'os': 'Linux-5.15.0-92-generic-x86_64-with-glibc2.17', 'python': '3.8.17', 'heartbeatAt': '2024-01-30T08:10:15.100309', 'startedAt': '2024-01-30T08:10:12.555082', 'docker': None, 'cuda': None, 'args': ('--local_rank=5', '--config_file', 'config/bert_pretraining_phase2_config.json', '--input_dir', '/home/yanxindong/mkor/bert/data/encoded/sequences_lowercase_max_seq_len_512_next_seq_task_true', '--output_dir', 'results/adam', '--weight_decay', '0.01', '--num_steps_per_checkpoint', '200'), 'state': 'running', 'program': 'run_pretraining.py', 'codePathLocal': 'run_pretraining.py', 'codePath': 'bert/run_pretraining.py', 'git': {'remote': 'https://github.com/kkkjj-d/mkor.git', 'commit': 'efe99e84fef5594780cfb1df6d6a1f61da4ebba0'}, 'email': '1262670315@qq.com', 'root': '/home/yanxindong/mkor', 'host': 'a6000-X640-G40', 'username': 'yanxindong', 'executable': '/home/yanxindong/anaconda/envs/eva/bin/python', 'cpu_count': 64, 'cpu_count_logical': 128, 'cpu_freq': {'current': 850.78125, 'min': 800.0, 'max': 3400.0}, 'cpu_freq_per_core': [{'current': 3299.997, 'min': 800.0, 'max': 3400.0}, {'current': 900.0, 'min': 800.0, 'max': 3400.0}, {'current': 800.0, 'min': 800.0, 'max': 3400.0}, {'current': 800.0, 'min': 800.0, 'max': 3400.0}, {'current': 800.0, 'min': 800.0, 'max': 3400.0}, {'current': 800.0, 'min': 800.0, 'max': 3400.0}, {'current': 800.0, 'min': 800.0, 'max': 3400.0}, {'current': 800.0, 'min': 800.0, 'max': 3400.0}, {'current': 900.0, 'min': 800.0, 'max': 3400.0}, {'current': 800.0, 'min': 800.0, 'max': 3400.0}, {'current': 800.0, 'min': 800.0, 'max': 3400.0}, {'current': 800.0, 'min': 800.0, 'max': 3400.0}, {'current': 800.0, 'min': 800.0, 'max': 3400.0}, {'current': 800.0, 'min': 800.0, 'max': 3400.0}, {'current': 800.0, 'min': 800.0, 'max': 3400.0}, {'current': 800.0, 'min': 800.0, 'max': 3400.0}, {'current': 800.0, 'min': 800.0, 'max': 3400.0}, {'current': 800.0, 'min': 800.0, 'max': 3400.0}, {'current': 800.0, 'min': 800.0, 'max': 3400.0}, {'current': 800.0, 'min': 800.0, 'max': 3400.0}, {'current': 800.0, 'min': 800.0, 'max': 3400.0}, {'current': 800.0, 'min': 800.0, 'max': 3400.0}, {'current': 800.0, 'min': 800.0, 'max': 3400.0}, {'current': 800.0, 'min': 800.0, 'max': 3400.0}, {'current': 800.0, 'min': 800.0, 'max': 3400.0}, {'current': 800.0, 'min': 800.0, 'max': 3400.0}, {'current': 800.0, 'min': 800.0, 'max': 3400.0}, {'current': 800.0, 'min': 800.0, 'max': 3400.0}, {'current': 800.0, 'min': 800.0, 'max': 3400.0}, {'current': 800.0, 'min': 800.0, 'max': 3400.0}, {'current': 800.0, 'min': 800.0, 'max': 3400.0}, {'current': 800.0, 'min': 800.0, 'max': 3400.0}, {'current': 800.0, 'min': 800.0, 'max': 3400.0}, {'current': 800.0, 'min': 800.0, 'max': 3400.0}, {'current': 1300.0, 'min': 800.0, 'max': 3400.0}, {'current': 800.0, 'min': 800.0, 'max': 3400.0}, {'current': 800.0, 'min': 800.0, 'max': 3400.0}, {'current': 800.0, 'min': 800.0, 'max': 3400.0}, {'current': 800.0, 'min': 800.0, 'max': 3400.0}, {'current': 800.0, 'min': 800.0, 'max': 3400.0}, {'current': 800.0, 'min': 800.0, 'max': 3400.0}, {'current': 800.0, 'min': 800.0, 'max': 3400.0}, {'current': 800.0, 'min': 800.0, 'max': 3400.0}, {'current': 800.0, 'min': 800.0, 'max': 3400.0}, {'current': 800.0, 'min': 800.0, 'max': 3400.0}, {'current': 800.0, 'min': 800.0, 'max': 3400.0}, {'current': 800.0, 'min': 800.0, 'max': 3400.0}, {'current': 800.0, 'min': 800.0, 'max': 3400.0}, {'current': 800.0, 'min': 800.0, 'max': 3400.0}, {'current': 800.0, 'min': 800.0, 'max': 3400.0}, {'current': 800.0, 'min': 800.0, 'max': 3400.0}, {'current': 1000.0, 'min': 800.0, 'max': 3400.0}, {'current': 800.0, 'min': 800.0, 'max': 3400.0}, {'current': 800.0, 'min': 800.0, 'max': 3400.0}, {'current': 800.0, 'min': 800.0, 'max': 3400.0}, {'current': 800.0, 'min': 800.0, 'max': 3400.0}, {'current': 800.0, 'min': 800.0, 'max': 3400.0}, {'current': 800.0, 'min': 800.0, 'max': 3400.0}, {'current': 800.0, 'min': 800.0, 'max': 3400.0}, {'current': 800.0, 'min': 800.0, 'max': 3400.0}, {'current': 800.0, 'min': 800.0, 'max': 3400.0}, {'current': 800.0, 'min': 800.0, 'max': 3400.0}, {'current': 800.0, 'min': 800.0, 'max': 3400.0}, {'current': 800.0, 'min': 800.0, 'max': 3400.0}, {'current': 3300.0, 'min': 800.0, 'max': 3400.0}, {'current': 800.0, 'min': 800.0, 'max': 3400.0}, {'current': 800.0, 'min': 800.0, 'max': 3400.0}, {'current': 800.0, 'min': 800.0, 'max': 3400.0}, {'current': 800.0, 'min': 800.0, 'max': 3400.0}, {'current': 800.0, 'min': 800.0, 'max': 3400.0}, {'current': 800.0, 'min': 800.0, 'max': 3400.0}, {'current': 800.0, 'min': 800.0, 'max': 3400.0}, {'current': 800.0, 'min': 800.0, 'max': 3400.0}, {'current': 800.0, 'min': 800.0, 'max': 3400.0}, {'current': 800.0, 'min': 800.0, 'max': 3400.0}, {'current': 800.0, 'min': 800.0, 'max': 3400.0}, {'current': 800.0, 'min': 800.0, 'max': 3400.0}, {'current': 800.0, 'min': 800.0, 'max': 3400.0}, {'current': 800.0, 'min': 800.0, 'max': 3400.0}, {'current': 800.0, 'min': 800.0, 'max': 3400.0}, {'current': 800.0, 'min': 800.0, 'max': 3400.0}, {'current': 800.0, 'min': 800.0, 'max': 3400.0}, {'current': 800.0, 'min': 800.0, 'max': 3400.0}, {'current': 800.0, 'min': 800.0, 'max': 3400.0}, {'current': 800.0, 'min': 800.0, 'max': 3400.0}, {'current': 800.0, 'min': 800.0, 'max': 3400.0}, {'current': 800.0, 'min': 800.0, 'max': 3400.0}, {'current': 800.0, 'min': 800.0, 'max': 3400.0}, {'current': 800.0, 'min': 800.0, 'max': 3400.0}, {'current': 800.0, 'min': 800.0, 'max': 3400.0}, {'current': 800.0, 'min': 800.0, 'max': 3400.0}, {'current': 800.0, 'min': 800.0, 'max': 3400.0}, {'current': 800.0, 'min': 800.0, 'max': 3400.0}, {'current': 800.0, 'min': 800.0, 'max': 3400.0}, {'current': 800.0, 'min': 800.0, 'max': 3400.0}, {'current': 800.0, 'min': 800.0, 'max': 3400.0}, {'current': 800.0, 'min': 800.0, 'max': 3400.0}, {'current': 800.0, 'min': 800.0, 'max': 3400.0}, {'current': 800.0, 'min': 800.0, 'max': 3400.0}, {'current': 800.0, 'min': 800.0, 'max': 3400.0}, {'current': 800.0, 'min': 800.0, 'max': 3400.0}, {'current': 800.0, 'min': 800.0, 'max': 3400.0}, {'current': 800.0, 'min': 800.0, 'max': 3400.0}, {'current': 800.0, 'min': 800.0, 'max': 3400.0}, {'current': 800.0, 'min': 800.0, 'max': 3400.0}, {'current': 800.0, 'min': 800.0, 'max': 3400.0}, {'current': 800.0, 'min': 800.0, 'max': 3400.0}, {'current': 800.0, 'min': 800.0, 'max': 3400.0}, {'current': 800.0, 'min': 800.0, 'max': 3400.0}, {'current': 800.0, 'min': 800.0, 'max': 3400.0}, {'current': 900.0, 'min': 800.0, 'max': 3400.0}, {'current': 800.0, 'min': 800.0, 'max': 3400.0}, {'current': 800.0, 'min': 800.0, 'max': 3400.0}, {'current': 800.0, 'min': 800.0, 'max': 3400.0}, {'current': 800.0, 'min': 800.0, 'max': 3400.0}, {'current': 800.0, 'min': 800.0, 'max': 3400.0}, {'current': 800.0, 'min': 800.0, 'max': 3400.0}, {'current': 800.0, 'min': 800.0, 'max': 3400.0}, {'current': 800.0, 'min': 800.0, 'max': 3400.0}, {'current': 800.0, 'min': 800.0, 'max': 3400.0}, {'current': 800.0, 'min': 800.0, 'max': 3400.0}, {'current': 800.0, 'min': 800.0, 'max': 3400.0}, {'current': 800.0, 'min': 800.0, 'max': 3400.0}, {'current': 800.0, 'min': 800.0, 'max': 3400.0}, {'current': 800.0, 'min': 800.0, 'max': 3400.0}, {'current': 800.0, 'min': 800.0, 'max': 3400.0}, {'current': 800.0, 'min': 800.0, 'max': 3400.0}, {'current': 800.0, 'min': 800.0, 'max': 3400.0}], 'disk': {'/': {'total': 438.05088806152344, 'used': 30.817367553710938}}, 'gpu': 'NVIDIA RTX A6000', 'gpu_count': 8, 'gpu_devices': [{'name': 'NVIDIA RTX A6000', 'memory_total': 51527024640}, {'name': 'NVIDIA RTX A6000', 'memory_total': 51527024640}, {'name': 'NVIDIA RTX A6000', 'memory_total': 51527024640}, {'name': 'NVIDIA RTX A6000', 'memory_total': 51527024640}, {'name': 'NVIDIA RTX A6000', 'memory_total': 51527024640}, {'name': 'NVIDIA RTX A6000', 'memory_total': 51527024640}, {'name': 'NVIDIA RTX A6000', 'memory_total': 51527024640}, {'name': 'NVIDIA RTX A6000', 'memory_total': 51527024640}], 'memory': {'total': 503.51252365112305}}
2024-01-30 16:10:15,191 INFO    HandlerThread:1134332 [system_monitor.py:probe():224] Finished collecting system info
2024-01-30 16:10:15,191 INFO    HandlerThread:1134332 [system_monitor.py:probe():227] Publishing system info
2024-01-30 16:10:15,191 DEBUG   HandlerThread:1134332 [system_info.py:_save_conda():208] Saving list of conda packages installed into the current environment
2024-01-30 16:10:15,930 INFO    Thread-12 :1134332 [dir_watcher.py:_on_file_created():271] file/dir created: /home/yanxindong/mkor/bert/wandb/run-20240130_161012-xvi6icyy/files/conda-environment.yaml
2024-01-30 16:10:35,932 INFO    Thread-12 :1134332 [dir_watcher.py:_on_file_modified():288] file/dir modified: /home/yanxindong/mkor/bert/wandb/run-20240130_161012-xvi6icyy/files/conda-environment.yaml
2024-01-30 16:10:36,166 DEBUG   HandlerThread:1134332 [system_info.py:_save_conda():220] Saving conda packages done
2024-01-30 16:10:36,168 INFO    HandlerThread:1134332 [system_monitor.py:probe():229] Finished publishing system info
2024-01-30 16:10:36,173 DEBUG   HandlerThread:1134332 [handler.py:handle_request():146] handle_request: status_report
2024-01-30 16:10:36,173 DEBUG   HandlerThread:1134332 [handler.py:handle_request():146] handle_request: keepalive
2024-01-30 16:10:36,173 DEBUG   HandlerThread:1134332 [handler.py:handle_request():146] handle_request: status_report
2024-01-30 16:10:36,173 DEBUG   HandlerThread:1134332 [handler.py:handle_request():146] handle_request: keepalive
2024-01-30 16:10:36,174 DEBUG   HandlerThread:1134332 [handler.py:handle_request():146] handle_request: status_report
2024-01-30 16:10:36,174 DEBUG   HandlerThread:1134332 [handler.py:handle_request():146] handle_request: keepalive
2024-01-30 16:10:36,174 DEBUG   HandlerThread:1134332 [handler.py:handle_request():146] handle_request: status_report
2024-01-30 16:10:36,174 DEBUG   HandlerThread:1134332 [handler.py:handle_request():146] handle_request: keepalive
2024-01-30 16:10:36,174 DEBUG   SenderThread:1134332 [sender.py:send():382] send: files
2024-01-30 16:10:36,174 INFO    SenderThread:1134332 [sender.py:_save_file():1403] saving file wandb-metadata.json with policy now
2024-01-30 16:10:36,180 DEBUG   HandlerThread:1134332 [handler.py:handle_request():146] handle_request: python_packages
2024-01-30 16:10:36,180 DEBUG   SenderThread:1134332 [sender.py:send_request():409] send_request: python_packages
2024-01-30 16:10:36,199 DEBUG   HandlerThread:1134332 [handler.py:handle_request():146] handle_request: stop_status
2024-01-30 16:10:36,199 DEBUG   SenderThread:1134332 [sender.py:send_request():409] send_request: stop_status
2024-01-30 16:10:36,237 DEBUG   HandlerThread:1134332 [handler.py:handle_request():146] handle_request: internal_messages
2024-01-30 16:10:36,716 DEBUG   SenderThread:1134332 [sender.py:send():382] send: telemetry
2024-01-30 16:10:36,718 ERROR   wandb-upload_0:1134332 [internal_api.py:upload_file():2765] upload_file exception https://storage.googleapis.com/wandb-production.appspot.com/dynamic_x/bert_pytorch/xvi6icyy/wandb-metadata.json?Expires=1706688636&GoogleAccessId=gorilla-files-url-signer-man%40wandb-production.iam.gserviceaccount.com&Signature=DDf5vt5B92k8FYrTqi6v6Act%2FfsD9m%2BtUVurplBl8LHodFHKovhbdxHYYJR5cFNp8a0AfZ3MCJn%2B5dREN0vhZjZyhcBFwq%2FB505kAYJBPgN5auQm2s2pMgRQ9m66zD%2BCm1H3qJoWOWsEMOfuDUdIgIP%2BepXp4vcXUpixcIB3Ltb6FJSEsBgsWrJ%2FJcEzGMhRvrPmNQ5BA%2B%2BcryyrygOB8Fe7zZ7D6FTKPBZ6WS7miVf5h9Ozal%2Bnniwgqfc%2FrLSYohUljAvr7Nth5H6NDdlHDblgOlmd3WGJwptZK3BteBymjNDdyw2%2FoSas8CR1dyjfOEUtogb6%2FWin3slTGhKezg%3D%3D: HTTPSConnectionPool(host='storage.googleapis.com', port=443): Max retries exceeded with url: /wandb-production.appspot.com/dynamic_x/bert_pytorch/xvi6icyy/wandb-metadata.json?Expires=1706688636&GoogleAccessId=gorilla-files-url-signer-man%40wandb-production.iam.gserviceaccount.com&Signature=DDf5vt5B92k8FYrTqi6v6Act%2FfsD9m%2BtUVurplBl8LHodFHKovhbdxHYYJR5cFNp8a0AfZ3MCJn%2B5dREN0vhZjZyhcBFwq%2FB505kAYJBPgN5auQm2s2pMgRQ9m66zD%2BCm1H3qJoWOWsEMOfuDUdIgIP%2BepXp4vcXUpixcIB3Ltb6FJSEsBgsWrJ%2FJcEzGMhRvrPmNQ5BA%2B%2BcryyrygOB8Fe7zZ7D6FTKPBZ6WS7miVf5h9Ozal%2Bnniwgqfc%2FrLSYohUljAvr7Nth5H6NDdlHDblgOlmd3WGJwptZK3BteBymjNDdyw2%2FoSas8CR1dyjfOEUtogb6%2FWin3slTGhKezg%3D%3D (Caused by NewConnectionError('<urllib3.connection.HTTPSConnection object at 0x7f5f241d70d0>: Failed to establish a new connection: [Errno 111] Connection refused'))
2024-01-30 16:10:36,718 ERROR   wandb-upload_0:1134332 [internal_api.py:upload_file():2767] upload_file request headers: {'User-Agent': 'python-requests/2.23.0', 'Accept-Encoding': 'gzip, deflate', 'Accept': '*/*', 'Connection': 'keep-alive', 'Content-Length': '15544'}
2024-01-30 16:10:36,718 ERROR   wandb-upload_0:1134332 [internal_api.py:upload_file():2769] upload_file response body: 
2024-01-30 16:10:36,936 INFO    Thread-12 :1134332 [dir_watcher.py:_on_file_created():271] file/dir created: /home/yanxindong/mkor/bert/wandb/run-20240130_161012-xvi6icyy/files/wandb-metadata.json
2024-01-30 16:10:36,936 INFO    Thread-12 :1134332 [dir_watcher.py:_on_file_created():271] file/dir created: /home/yanxindong/mkor/bert/wandb/run-20240130_161012-xvi6icyy/files/requirements.txt
2024-01-30 16:10:37,841 ERROR   wandb-upload_0:1134332 [internal_api.py:upload_file():2765] upload_file exception https://storage.googleapis.com/wandb-production.appspot.com/dynamic_x/bert_pytorch/xvi6icyy/wandb-metadata.json?Expires=1706688636&GoogleAccessId=gorilla-files-url-signer-man%40wandb-production.iam.gserviceaccount.com&Signature=DDf5vt5B92k8FYrTqi6v6Act%2FfsD9m%2BtUVurplBl8LHodFHKovhbdxHYYJR5cFNp8a0AfZ3MCJn%2B5dREN0vhZjZyhcBFwq%2FB505kAYJBPgN5auQm2s2pMgRQ9m66zD%2BCm1H3qJoWOWsEMOfuDUdIgIP%2BepXp4vcXUpixcIB3Ltb6FJSEsBgsWrJ%2FJcEzGMhRvrPmNQ5BA%2B%2BcryyrygOB8Fe7zZ7D6FTKPBZ6WS7miVf5h9Ozal%2Bnniwgqfc%2FrLSYohUljAvr7Nth5H6NDdlHDblgOlmd3WGJwptZK3BteBymjNDdyw2%2FoSas8CR1dyjfOEUtogb6%2FWin3slTGhKezg%3D%3D: HTTPSConnectionPool(host='storage.googleapis.com', port=443): Max retries exceeded with url: /wandb-production.appspot.com/dynamic_x/bert_pytorch/xvi6icyy/wandb-metadata.json?Expires=1706688636&GoogleAccessId=gorilla-files-url-signer-man%40wandb-production.iam.gserviceaccount.com&Signature=DDf5vt5B92k8FYrTqi6v6Act%2FfsD9m%2BtUVurplBl8LHodFHKovhbdxHYYJR5cFNp8a0AfZ3MCJn%2B5dREN0vhZjZyhcBFwq%2FB505kAYJBPgN5auQm2s2pMgRQ9m66zD%2BCm1H3qJoWOWsEMOfuDUdIgIP%2BepXp4vcXUpixcIB3Ltb6FJSEsBgsWrJ%2FJcEzGMhRvrPmNQ5BA%2B%2BcryyrygOB8Fe7zZ7D6FTKPBZ6WS7miVf5h9Ozal%2Bnniwgqfc%2FrLSYohUljAvr7Nth5H6NDdlHDblgOlmd3WGJwptZK3BteBymjNDdyw2%2FoSas8CR1dyjfOEUtogb6%2FWin3slTGhKezg%3D%3D (Caused by NewConnectionError('<urllib3.connection.HTTPSConnection object at 0x7f5f241d7490>: Failed to establish a new connection: [Errno 111] Connection refused'))
2024-01-30 16:10:37,841 ERROR   wandb-upload_0:1134332 [internal_api.py:upload_file():2767] upload_file request headers: {'User-Agent': 'python-requests/2.23.0', 'Accept-Encoding': 'gzip, deflate', 'Accept': '*/*', 'Connection': 'keep-alive', 'Content-Length': '15544'}
2024-01-30 16:10:37,841 ERROR   wandb-upload_0:1134332 [internal_api.py:upload_file():2769] upload_file response body: 
2024-01-30 16:10:38,716 DEBUG   HandlerThread:1134332 [handler.py:handle_request():146] handle_request: status_report
2024-01-30 16:10:39,858 ERROR   wandb-upload_0:1134332 [internal_api.py:upload_file():2765] upload_file exception https://storage.googleapis.com/wandb-production.appspot.com/dynamic_x/bert_pytorch/xvi6icyy/wandb-metadata.json?Expires=1706688636&GoogleAccessId=gorilla-files-url-signer-man%40wandb-production.iam.gserviceaccount.com&Signature=DDf5vt5B92k8FYrTqi6v6Act%2FfsD9m%2BtUVurplBl8LHodFHKovhbdxHYYJR5cFNp8a0AfZ3MCJn%2B5dREN0vhZjZyhcBFwq%2FB505kAYJBPgN5auQm2s2pMgRQ9m66zD%2BCm1H3qJoWOWsEMOfuDUdIgIP%2BepXp4vcXUpixcIB3Ltb6FJSEsBgsWrJ%2FJcEzGMhRvrPmNQ5BA%2B%2BcryyrygOB8Fe7zZ7D6FTKPBZ6WS7miVf5h9Ozal%2Bnniwgqfc%2FrLSYohUljAvr7Nth5H6NDdlHDblgOlmd3WGJwptZK3BteBymjNDdyw2%2FoSas8CR1dyjfOEUtogb6%2FWin3slTGhKezg%3D%3D: HTTPSConnectionPool(host='storage.googleapis.com', port=443): Max retries exceeded with url: /wandb-production.appspot.com/dynamic_x/bert_pytorch/xvi6icyy/wandb-metadata.json?Expires=1706688636&GoogleAccessId=gorilla-files-url-signer-man%40wandb-production.iam.gserviceaccount.com&Signature=DDf5vt5B92k8FYrTqi6v6Act%2FfsD9m%2BtUVurplBl8LHodFHKovhbdxHYYJR5cFNp8a0AfZ3MCJn%2B5dREN0vhZjZyhcBFwq%2FB505kAYJBPgN5auQm2s2pMgRQ9m66zD%2BCm1H3qJoWOWsEMOfuDUdIgIP%2BepXp4vcXUpixcIB3Ltb6FJSEsBgsWrJ%2FJcEzGMhRvrPmNQ5BA%2B%2BcryyrygOB8Fe7zZ7D6FTKPBZ6WS7miVf5h9Ozal%2Bnniwgqfc%2FrLSYohUljAvr7Nth5H6NDdlHDblgOlmd3WGJwptZK3BteBymjNDdyw2%2FoSas8CR1dyjfOEUtogb6%2FWin3slTGhKezg%3D%3D (Caused by NewConnectionError('<urllib3.connection.HTTPSConnection object at 0x7f5f241d7e50>: Failed to establish a new connection: [Errno 111] Connection refused'))
2024-01-30 16:10:39,858 ERROR   wandb-upload_0:1134332 [internal_api.py:upload_file():2767] upload_file request headers: {'User-Agent': 'python-requests/2.23.0', 'Accept-Encoding': 'gzip, deflate', 'Accept': '*/*', 'Connection': 'keep-alive', 'Content-Length': '15544'}
2024-01-30 16:10:39,858 ERROR   wandb-upload_0:1134332 [internal_api.py:upload_file():2769] upload_file response body: 
2024-01-30 16:10:39,859 INFO    wandb-upload_0:1134332 [retry.py:__call__():172] Retry attempt failed:
Traceback (most recent call last):
  File "/home/yanxindong/anaconda/envs/eva/lib/python3.8/site-packages/urllib3/connection.py", line 159, in _new_conn
    conn = connection.create_connection(
  File "/home/yanxindong/anaconda/envs/eva/lib/python3.8/site-packages/urllib3/util/connection.py", line 84, in create_connection
    raise err
  File "/home/yanxindong/anaconda/envs/eva/lib/python3.8/site-packages/urllib3/util/connection.py", line 74, in create_connection
    sock.connect(sa)
ConnectionRefusedError: [Errno 111] Connection refused

During handling of the above exception, another exception occurred:

Traceback (most recent call last):
  File "/home/yanxindong/anaconda/envs/eva/lib/python3.8/site-packages/urllib3/connectionpool.py", line 670, in urlopen
    httplib_response = self._make_request(
  File "/home/yanxindong/anaconda/envs/eva/lib/python3.8/site-packages/urllib3/connectionpool.py", line 381, in _make_request
    self._validate_conn(conn)
  File "/home/yanxindong/anaconda/envs/eva/lib/python3.8/site-packages/urllib3/connectionpool.py", line 978, in _validate_conn
    conn.connect()
  File "/home/yanxindong/anaconda/envs/eva/lib/python3.8/site-packages/urllib3/connection.py", line 309, in connect
    conn = self._new_conn()
  File "/home/yanxindong/anaconda/envs/eva/lib/python3.8/site-packages/urllib3/connection.py", line 171, in _new_conn
    raise NewConnectionError(
urllib3.exceptions.NewConnectionError: <urllib3.connection.HTTPSConnection object at 0x7f5f241d7e50>: Failed to establish a new connection: [Errno 111] Connection refused

During handling of the above exception, another exception occurred:

Traceback (most recent call last):
  File "/home/yanxindong/anaconda/envs/eva/lib/python3.8/site-packages/requests/adapters.py", line 439, in send
    resp = conn.urlopen(
  File "/home/yanxindong/anaconda/envs/eva/lib/python3.8/site-packages/urllib3/connectionpool.py", line 726, in urlopen
    retries = retries.increment(
  File "/home/yanxindong/anaconda/envs/eva/lib/python3.8/site-packages/urllib3/util/retry.py", line 446, in increment
    raise MaxRetryError(_pool, url, error or ResponseError(cause))
urllib3.exceptions.MaxRetryError: HTTPSConnectionPool(host='storage.googleapis.com', port=443): Max retries exceeded with url: /wandb-production.appspot.com/dynamic_x/bert_pytorch/xvi6icyy/wandb-metadata.json?Expires=1706688636&GoogleAccessId=gorilla-files-url-signer-man%40wandb-production.iam.gserviceaccount.com&Signature=DDf5vt5B92k8FYrTqi6v6Act%2FfsD9m%2BtUVurplBl8LHodFHKovhbdxHYYJR5cFNp8a0AfZ3MCJn%2B5dREN0vhZjZyhcBFwq%2FB505kAYJBPgN5auQm2s2pMgRQ9m66zD%2BCm1H3qJoWOWsEMOfuDUdIgIP%2BepXp4vcXUpixcIB3Ltb6FJSEsBgsWrJ%2FJcEzGMhRvrPmNQ5BA%2B%2BcryyrygOB8Fe7zZ7D6FTKPBZ6WS7miVf5h9Ozal%2Bnniwgqfc%2FrLSYohUljAvr7Nth5H6NDdlHDblgOlmd3WGJwptZK3BteBymjNDdyw2%2FoSas8CR1dyjfOEUtogb6%2FWin3slTGhKezg%3D%3D (Caused by NewConnectionError('<urllib3.connection.HTTPSConnection object at 0x7f5f241d7e50>: Failed to establish a new connection: [Errno 111] Connection refused'))

During handling of the above exception, another exception occurred:

Traceback (most recent call last):
  File "/home/yanxindong/anaconda/envs/eva/lib/python3.8/site-packages/wandb/sdk/internal/internal_api.py", line 2758, in upload_file
    response = self._upload_file_session.put(
  File "/home/yanxindong/anaconda/envs/eva/lib/python3.8/site-packages/requests/sessions.py", line 590, in put
    return self.request('PUT', url, data=data, **kwargs)
  File "/home/yanxindong/anaconda/envs/eva/lib/python3.8/site-packages/requests/sessions.py", line 530, in request
    resp = self.send(prep, **send_kwargs)
  File "/home/yanxindong/anaconda/envs/eva/lib/python3.8/site-packages/requests/sessions.py", line 643, in send
    r = adapter.send(request, **kwargs)
  File "/home/yanxindong/anaconda/envs/eva/lib/python3.8/site-packages/requests/adapters.py", line 516, in send
    raise ConnectionError(e, request=request)
requests.exceptions.ConnectionError: HTTPSConnectionPool(host='storage.googleapis.com', port=443): Max retries exceeded with url: /wandb-production.appspot.com/dynamic_x/bert_pytorch/xvi6icyy/wandb-metadata.json?Expires=1706688636&GoogleAccessId=gorilla-files-url-signer-man%40wandb-production.iam.gserviceaccount.com&Signature=DDf5vt5B92k8FYrTqi6v6Act%2FfsD9m%2BtUVurplBl8LHodFHKovhbdxHYYJR5cFNp8a0AfZ3MCJn%2B5dREN0vhZjZyhcBFwq%2FB505kAYJBPgN5auQm2s2pMgRQ9m66zD%2BCm1H3qJoWOWsEMOfuDUdIgIP%2BepXp4vcXUpixcIB3Ltb6FJSEsBgsWrJ%2FJcEzGMhRvrPmNQ5BA%2B%2BcryyrygOB8Fe7zZ7D6FTKPBZ6WS7miVf5h9Ozal%2Bnniwgqfc%2FrLSYohUljAvr7Nth5H6NDdlHDblgOlmd3WGJwptZK3BteBymjNDdyw2%2FoSas8CR1dyjfOEUtogb6%2FWin3slTGhKezg%3D%3D (Caused by NewConnectionError('<urllib3.connection.HTTPSConnection object at 0x7f5f241d7e50>: Failed to establish a new connection: [Errno 111] Connection refused'))

During handling of the above exception, another exception occurred:

Traceback (most recent call last):
  File "/home/yanxindong/anaconda/envs/eva/lib/python3.8/site-packages/wandb/sdk/lib/retry.py", line 131, in __call__
    result = self._call_fn(*args, **kwargs)
  File "/home/yanxindong/anaconda/envs/eva/lib/python3.8/site-packages/wandb/sdk/internal/internal_api.py", line 2789, in upload_file
    raise _e.with_traceback(sys.exc_info()[2])
  File "/home/yanxindong/anaconda/envs/eva/lib/python3.8/site-packages/wandb/sdk/internal/internal_api.py", line 2758, in upload_file
    response = self._upload_file_session.put(
  File "/home/yanxindong/anaconda/envs/eva/lib/python3.8/site-packages/requests/sessions.py", line 590, in put
    return self.request('PUT', url, data=data, **kwargs)
  File "/home/yanxindong/anaconda/envs/eva/lib/python3.8/site-packages/requests/sessions.py", line 530, in request
    resp = self.send(prep, **send_kwargs)
  File "/home/yanxindong/anaconda/envs/eva/lib/python3.8/site-packages/requests/sessions.py", line 643, in send
    r = adapter.send(request, **kwargs)
  File "/home/yanxindong/anaconda/envs/eva/lib/python3.8/site-packages/requests/adapters.py", line 516, in send
    raise ConnectionError(e, request=request)
wandb.sdk.lib.retry.TransientError: None
2024-01-30 16:10:43,722 DEBUG   HandlerThread:1134332 [handler.py:handle_request():146] handle_request: status_report
2024-01-30 16:10:44,118 ERROR   wandb-upload_0:1134332 [internal_api.py:upload_file():2765] upload_file exception https://storage.googleapis.com/wandb-production.appspot.com/dynamic_x/bert_pytorch/xvi6icyy/wandb-metadata.json?Expires=1706688636&GoogleAccessId=gorilla-files-url-signer-man%40wandb-production.iam.gserviceaccount.com&Signature=DDf5vt5B92k8FYrTqi6v6Act%2FfsD9m%2BtUVurplBl8LHodFHKovhbdxHYYJR5cFNp8a0AfZ3MCJn%2B5dREN0vhZjZyhcBFwq%2FB505kAYJBPgN5auQm2s2pMgRQ9m66zD%2BCm1H3qJoWOWsEMOfuDUdIgIP%2BepXp4vcXUpixcIB3Ltb6FJSEsBgsWrJ%2FJcEzGMhRvrPmNQ5BA%2B%2BcryyrygOB8Fe7zZ7D6FTKPBZ6WS7miVf5h9Ozal%2Bnniwgqfc%2FrLSYohUljAvr7Nth5H6NDdlHDblgOlmd3WGJwptZK3BteBymjNDdyw2%2FoSas8CR1dyjfOEUtogb6%2FWin3slTGhKezg%3D%3D: HTTPSConnectionPool(host='storage.googleapis.com', port=443): Max retries exceeded with url: /wandb-production.appspot.com/dynamic_x/bert_pytorch/xvi6icyy/wandb-metadata.json?Expires=1706688636&GoogleAccessId=gorilla-files-url-signer-man%40wandb-production.iam.gserviceaccount.com&Signature=DDf5vt5B92k8FYrTqi6v6Act%2FfsD9m%2BtUVurplBl8LHodFHKovhbdxHYYJR5cFNp8a0AfZ3MCJn%2B5dREN0vhZjZyhcBFwq%2FB505kAYJBPgN5auQm2s2pMgRQ9m66zD%2BCm1H3qJoWOWsEMOfuDUdIgIP%2BepXp4vcXUpixcIB3Ltb6FJSEsBgsWrJ%2FJcEzGMhRvrPmNQ5BA%2B%2BcryyrygOB8Fe7zZ7D6FTKPBZ6WS7miVf5h9Ozal%2Bnniwgqfc%2FrLSYohUljAvr7Nth5H6NDdlHDblgOlmd3WGJwptZK3BteBymjNDdyw2%2FoSas8CR1dyjfOEUtogb6%2FWin3slTGhKezg%3D%3D (Caused by NewConnectionError('<urllib3.connection.HTTPSConnection object at 0x7f5f241d7a00>: Failed to establish a new connection: [Errno 111] Connection refused'))
2024-01-30 16:10:44,118 ERROR   wandb-upload_0:1134332 [internal_api.py:upload_file():2767] upload_file request headers: {'User-Agent': 'python-requests/2.23.0', 'Accept-Encoding': 'gzip, deflate', 'Accept': '*/*', 'Connection': 'keep-alive', 'Content-Length': '15544'}
2024-01-30 16:10:44,118 ERROR   wandb-upload_0:1134332 [internal_api.py:upload_file():2769] upload_file response body: 
2024-01-30 16:10:45,943 INFO    Thread-12 :1134332 [dir_watcher.py:_on_file_modified():288] file/dir modified: /home/yanxindong/mkor/bert/wandb/run-20240130_161012-xvi6icyy/files/config.yaml
2024-01-30 16:10:49,984 DEBUG   HandlerThread:1134332 [handler.py:handle_request():146] handle_request: status_report
2024-01-30 16:10:51,225 DEBUG   HandlerThread:1134332 [handler.py:handle_request():146] handle_request: stop_status
2024-01-30 16:10:51,226 DEBUG   SenderThread:1134332 [sender.py:send_request():409] send_request: stop_status
2024-01-30 16:10:51,237 DEBUG   HandlerThread:1134332 [handler.py:handle_request():146] handle_request: internal_messages
2024-01-30 16:10:53,556 ERROR   wandb-upload_0:1134332 [internal_api.py:upload_file():2765] upload_file exception https://storage.googleapis.com/wandb-production.appspot.com/dynamic_x/bert_pytorch/xvi6icyy/wandb-metadata.json?Expires=1706688636&GoogleAccessId=gorilla-files-url-signer-man%40wandb-production.iam.gserviceaccount.com&Signature=DDf5vt5B92k8FYrTqi6v6Act%2FfsD9m%2BtUVurplBl8LHodFHKovhbdxHYYJR5cFNp8a0AfZ3MCJn%2B5dREN0vhZjZyhcBFwq%2FB505kAYJBPgN5auQm2s2pMgRQ9m66zD%2BCm1H3qJoWOWsEMOfuDUdIgIP%2BepXp4vcXUpixcIB3Ltb6FJSEsBgsWrJ%2FJcEzGMhRvrPmNQ5BA%2B%2BcryyrygOB8Fe7zZ7D6FTKPBZ6WS7miVf5h9Ozal%2Bnniwgqfc%2FrLSYohUljAvr7Nth5H6NDdlHDblgOlmd3WGJwptZK3BteBymjNDdyw2%2FoSas8CR1dyjfOEUtogb6%2FWin3slTGhKezg%3D%3D: HTTPSConnectionPool(host='storage.googleapis.com', port=443): Max retries exceeded with url: /wandb-production.appspot.com/dynamic_x/bert_pytorch/xvi6icyy/wandb-metadata.json?Expires=1706688636&GoogleAccessId=gorilla-files-url-signer-man%40wandb-production.iam.gserviceaccount.com&Signature=DDf5vt5B92k8FYrTqi6v6Act%2FfsD9m%2BtUVurplBl8LHodFHKovhbdxHYYJR5cFNp8a0AfZ3MCJn%2B5dREN0vhZjZyhcBFwq%2FB505kAYJBPgN5auQm2s2pMgRQ9m66zD%2BCm1H3qJoWOWsEMOfuDUdIgIP%2BepXp4vcXUpixcIB3Ltb6FJSEsBgsWrJ%2FJcEzGMhRvrPmNQ5BA%2B%2BcryyrygOB8Fe7zZ7D6FTKPBZ6WS7miVf5h9Ozal%2Bnniwgqfc%2FrLSYohUljAvr7Nth5H6NDdlHDblgOlmd3WGJwptZK3BteBymjNDdyw2%2FoSas8CR1dyjfOEUtogb6%2FWin3slTGhKezg%3D%3D (Caused by NewConnectionError('<urllib3.connection.HTTPSConnection object at 0x7f5f241dc3d0>: Failed to establish a new connection: [Errno 111] Connection refused'))
2024-01-30 16:10:53,556 ERROR   wandb-upload_0:1134332 [internal_api.py:upload_file():2767] upload_file request headers: {'User-Agent': 'python-requests/2.23.0', 'Accept-Encoding': 'gzip, deflate', 'Accept': '*/*', 'Connection': 'keep-alive', 'Content-Length': '15544'}
2024-01-30 16:10:53,556 ERROR   wandb-upload_0:1134332 [internal_api.py:upload_file():2769] upload_file response body: 
2024-01-30 16:10:55,613 DEBUG   HandlerThread:1134332 [handler.py:handle_request():146] handle_request: status_report
2024-01-30 16:11:00,614 DEBUG   HandlerThread:1134332 [handler.py:handle_request():146] handle_request: status_report
2024-01-30 16:11:05,614 DEBUG   HandlerThread:1134332 [handler.py:handle_request():146] handle_request: status_report
2024-01-30 16:11:06,194 DEBUG   HandlerThread:1134332 [handler.py:handle_request():146] handle_request: stop_status
2024-01-30 16:11:06,194 DEBUG   SenderThread:1134332 [sender.py:send_request():409] send_request: stop_status
2024-01-30 16:11:06,237 DEBUG   HandlerThread:1134332 [handler.py:handle_request():146] handle_request: internal_messages
2024-01-30 16:11:11,463 DEBUG   HandlerThread:1134332 [handler.py:handle_request():146] handle_request: status_report
2024-01-30 16:11:11,599 ERROR   wandb-upload_0:1134332 [internal_api.py:upload_file():2765] upload_file exception https://storage.googleapis.com/wandb-production.appspot.com/dynamic_x/bert_pytorch/xvi6icyy/wandb-metadata.json?Expires=1706688636&GoogleAccessId=gorilla-files-url-signer-man%40wandb-production.iam.gserviceaccount.com&Signature=DDf5vt5B92k8FYrTqi6v6Act%2FfsD9m%2BtUVurplBl8LHodFHKovhbdxHYYJR5cFNp8a0AfZ3MCJn%2B5dREN0vhZjZyhcBFwq%2FB505kAYJBPgN5auQm2s2pMgRQ9m66zD%2BCm1H3qJoWOWsEMOfuDUdIgIP%2BepXp4vcXUpixcIB3Ltb6FJSEsBgsWrJ%2FJcEzGMhRvrPmNQ5BA%2B%2BcryyrygOB8Fe7zZ7D6FTKPBZ6WS7miVf5h9Ozal%2Bnniwgqfc%2FrLSYohUljAvr7Nth5H6NDdlHDblgOlmd3WGJwptZK3BteBymjNDdyw2%2FoSas8CR1dyjfOEUtogb6%2FWin3slTGhKezg%3D%3D: HTTPSConnectionPool(host='storage.googleapis.com', port=443): Max retries exceeded with url: /wandb-production.appspot.com/dynamic_x/bert_pytorch/xvi6icyy/wandb-metadata.json?Expires=1706688636&GoogleAccessId=gorilla-files-url-signer-man%40wandb-production.iam.gserviceaccount.com&Signature=DDf5vt5B92k8FYrTqi6v6Act%2FfsD9m%2BtUVurplBl8LHodFHKovhbdxHYYJR5cFNp8a0AfZ3MCJn%2B5dREN0vhZjZyhcBFwq%2FB505kAYJBPgN5auQm2s2pMgRQ9m66zD%2BCm1H3qJoWOWsEMOfuDUdIgIP%2BepXp4vcXUpixcIB3Ltb6FJSEsBgsWrJ%2FJcEzGMhRvrPmNQ5BA%2B%2BcryyrygOB8Fe7zZ7D6FTKPBZ6WS7miVf5h9Ozal%2Bnniwgqfc%2FrLSYohUljAvr7Nth5H6NDdlHDblgOlmd3WGJwptZK3BteBymjNDdyw2%2FoSas8CR1dyjfOEUtogb6%2FWin3slTGhKezg%3D%3D (Caused by NewConnectionError('<urllib3.connection.HTTPSConnection object at 0x7f5f2411b640>: Failed to establish a new connection: [Errno 111] Connection refused'))
2024-01-30 16:11:11,599 ERROR   wandb-upload_0:1134332 [internal_api.py:upload_file():2767] upload_file request headers: {'User-Agent': 'python-requests/2.23.0', 'Accept-Encoding': 'gzip, deflate', 'Accept': '*/*', 'Connection': 'keep-alive', 'Content-Length': '15544'}
2024-01-30 16:11:11,599 ERROR   wandb-upload_0:1134332 [internal_api.py:upload_file():2769] upload_file response body: 
2024-01-30 16:11:15,032 DEBUG   SystemMonitor:1134332 [system_monitor.py:_start():172] Starting system metrics aggregation loop
2024-01-30 16:11:15,036 DEBUG   SenderThread:1134332 [sender.py:send():382] send: stats
2024-01-30 16:11:17,037 DEBUG   HandlerThread:1134332 [handler.py:handle_request():146] handle_request: status_report
2024-01-30 16:11:21,194 DEBUG   HandlerThread:1134332 [handler.py:handle_request():146] handle_request: stop_status
2024-01-30 16:11:21,194 DEBUG   SenderThread:1134332 [sender.py:send_request():409] send_request: stop_status
2024-01-30 16:11:21,242 DEBUG   HandlerThread:1134332 [handler.py:handle_request():146] handle_request: internal_messages
2024-01-30 16:11:22,450 DEBUG   HandlerThread:1134332 [handler.py:handle_request():146] handle_request: status_report
2024-01-30 16:11:27,451 DEBUG   HandlerThread:1134332 [handler.py:handle_request():146] handle_request: status_report
2024-01-30 16:11:32,533 DEBUG   HandlerThread:1134332 [handler.py:handle_request():146] handle_request: status_report
2024-01-30 16:11:36,210 DEBUG   HandlerThread:1134332 [handler.py:handle_request():146] handle_request: stop_status
2024-01-30 16:11:36,210 DEBUG   SenderThread:1134332 [sender.py:send_request():409] send_request: stop_status
2024-01-30 16:11:36,237 DEBUG   HandlerThread:1134332 [handler.py:handle_request():146] handle_request: internal_messages
2024-01-30 16:11:38,528 DEBUG   HandlerThread:1134332 [handler.py:handle_request():146] handle_request: status_report
2024-01-30 16:11:43,529 DEBUG   HandlerThread:1134332 [handler.py:handle_request():146] handle_request: status_report
2024-01-30 16:11:45,039 DEBUG   SenderThread:1134332 [sender.py:send():382] send: stats
2024-01-30 16:11:49,040 DEBUG   HandlerThread:1134332 [handler.py:handle_request():146] handle_request: status_report
2024-01-30 16:11:50,290 ERROR   wandb-upload_0:1134332 [internal_api.py:upload_file():2765] upload_file exception https://storage.googleapis.com/wandb-production.appspot.com/dynamic_x/bert_pytorch/xvi6icyy/wandb-metadata.json?Expires=1706688636&GoogleAccessId=gorilla-files-url-signer-man%40wandb-production.iam.gserviceaccount.com&Signature=DDf5vt5B92k8FYrTqi6v6Act%2FfsD9m%2BtUVurplBl8LHodFHKovhbdxHYYJR5cFNp8a0AfZ3MCJn%2B5dREN0vhZjZyhcBFwq%2FB505kAYJBPgN5auQm2s2pMgRQ9m66zD%2BCm1H3qJoWOWsEMOfuDUdIgIP%2BepXp4vcXUpixcIB3Ltb6FJSEsBgsWrJ%2FJcEzGMhRvrPmNQ5BA%2B%2BcryyrygOB8Fe7zZ7D6FTKPBZ6WS7miVf5h9Ozal%2Bnniwgqfc%2FrLSYohUljAvr7Nth5H6NDdlHDblgOlmd3WGJwptZK3BteBymjNDdyw2%2FoSas8CR1dyjfOEUtogb6%2FWin3slTGhKezg%3D%3D: HTTPSConnectionPool(host='storage.googleapis.com', port=443): Max retries exceeded with url: /wandb-production.appspot.com/dynamic_x/bert_pytorch/xvi6icyy/wandb-metadata.json?Expires=1706688636&GoogleAccessId=gorilla-files-url-signer-man%40wandb-production.iam.gserviceaccount.com&Signature=DDf5vt5B92k8FYrTqi6v6Act%2FfsD9m%2BtUVurplBl8LHodFHKovhbdxHYYJR5cFNp8a0AfZ3MCJn%2B5dREN0vhZjZyhcBFwq%2FB505kAYJBPgN5auQm2s2pMgRQ9m66zD%2BCm1H3qJoWOWsEMOfuDUdIgIP%2BepXp4vcXUpixcIB3Ltb6FJSEsBgsWrJ%2FJcEzGMhRvrPmNQ5BA%2B%2BcryyrygOB8Fe7zZ7D6FTKPBZ6WS7miVf5h9Ozal%2Bnniwgqfc%2FrLSYohUljAvr7Nth5H6NDdlHDblgOlmd3WGJwptZK3BteBymjNDdyw2%2FoSas8CR1dyjfOEUtogb6%2FWin3slTGhKezg%3D%3D (Caused by NewConnectionError('<urllib3.connection.HTTPSConnection object at 0x7f5f2411b940>: Failed to establish a new connection: [Errno 101] Network is unreachable'))
2024-01-30 16:11:50,290 ERROR   wandb-upload_0:1134332 [internal_api.py:upload_file():2767] upload_file request headers: {'User-Agent': 'python-requests/2.23.0', 'Accept-Encoding': 'gzip, deflate', 'Accept': '*/*', 'Connection': 'keep-alive', 'Content-Length': '15544'}
2024-01-30 16:11:50,290 ERROR   wandb-upload_0:1134332 [internal_api.py:upload_file():2769] upload_file response body: 
2024-01-30 16:11:51,194 DEBUG   HandlerThread:1134332 [handler.py:handle_request():146] handle_request: stop_status
2024-01-30 16:11:51,195 DEBUG   SenderThread:1134332 [sender.py:send_request():409] send_request: stop_status
2024-01-30 16:11:51,237 DEBUG   HandlerThread:1134332 [handler.py:handle_request():146] handle_request: internal_messages
2024-01-30 16:11:54,538 DEBUG   HandlerThread:1134332 [handler.py:handle_request():146] handle_request: status_report
2024-01-30 16:11:55,215 INFO    Thread-12 :1134332 [dir_watcher.py:_on_file_created():271] file/dir created: /home/yanxindong/mkor/bert/wandb/run-20240130_161012-xvi6icyy/files/output.log
2024-01-30 16:11:58,216 INFO    Thread-12 :1134332 [dir_watcher.py:_on_file_modified():288] file/dir modified: /home/yanxindong/mkor/bert/wandb/run-20240130_161012-xvi6icyy/files/output.log
2024-01-30 16:12:00,220 DEBUG   HandlerThread:1134332 [handler.py:handle_request():146] handle_request: status_report
2024-01-30 16:12:05,221 DEBUG   HandlerThread:1134332 [handler.py:handle_request():146] handle_request: status_report
2024-01-30 16:12:07,592 DEBUG   HandlerThread:1134332 [handler.py:handle_request():146] handle_request: internal_messages
2024-01-30 16:12:07,594 DEBUG   HandlerThread:1134332 [handler.py:handle_request():146] handle_request: stop_status
2024-01-30 16:12:07,594 DEBUG   SenderThread:1134332 [sender.py:send_request():409] send_request: stop_status
2024-01-30 16:12:10,666 DEBUG   HandlerThread:1134332 [handler.py:handle_request():146] handle_request: status_report
2024-01-30 16:12:15,041 DEBUG   SenderThread:1134332 [sender.py:send():382] send: stats
2024-01-30 16:12:16,101 DEBUG   HandlerThread:1134332 [handler.py:handle_request():146] handle_request: status_report
2024-01-30 16:12:21,223 DEBUG   HandlerThread:1134332 [handler.py:handle_request():146] handle_request: status_report
2024-01-30 16:12:22,591 DEBUG   HandlerThread:1134332 [handler.py:handle_request():146] handle_request: internal_messages
2024-01-30 16:12:22,594 DEBUG   HandlerThread:1134332 [handler.py:handle_request():146] handle_request: stop_status
2024-01-30 16:12:22,594 DEBUG   SenderThread:1134332 [sender.py:send_request():409] send_request: stop_status
2024-01-30 16:12:27,125 DEBUG   HandlerThread:1134332 [handler.py:handle_request():146] handle_request: status_report
2024-01-30 16:12:32,290 DEBUG   HandlerThread:1134332 [handler.py:handle_request():146] handle_request: status_report
2024-01-30 16:12:37,318 DEBUG   HandlerThread:1134332 [handler.py:handle_request():146] handle_request: status_report
2024-01-30 16:12:37,592 DEBUG   HandlerThread:1134332 [handler.py:handle_request():146] handle_request: internal_messages
2024-01-30 16:12:37,594 DEBUG   HandlerThread:1134332 [handler.py:handle_request():146] handle_request: stop_status
2024-01-30 16:12:37,594 DEBUG   SenderThread:1134332 [sender.py:send_request():409] send_request: stop_status
2024-01-30 16:12:43,000 DEBUG   HandlerThread:1134332 [handler.py:handle_request():146] handle_request: status_report
2024-01-30 16:12:45,044 DEBUG   SenderThread:1134332 [sender.py:send():382] send: stats
2024-01-30 16:12:48,046 DEBUG   HandlerThread:1134332 [handler.py:handle_request():146] handle_request: status_report
2024-01-30 16:12:52,592 DEBUG   HandlerThread:1134332 [handler.py:handle_request():146] handle_request: internal_messages
2024-01-30 16:12:52,594 DEBUG   HandlerThread:1134332 [handler.py:handle_request():146] handle_request: stop_status
2024-01-30 16:12:52,594 DEBUG   SenderThread:1134332 [sender.py:send_request():409] send_request: stop_status
2024-01-30 16:12:53,902 DEBUG   HandlerThread:1134332 [handler.py:handle_request():146] handle_request: status_report
2024-01-30 16:12:54,954 ERROR   wandb-upload_0:1134332 [internal_api.py:upload_file():2765] upload_file exception https://storage.googleapis.com/wandb-production.appspot.com/dynamic_x/bert_pytorch/xvi6icyy/wandb-metadata.json?Expires=1706688636&GoogleAccessId=gorilla-files-url-signer-man%40wandb-production.iam.gserviceaccount.com&Signature=DDf5vt5B92k8FYrTqi6v6Act%2FfsD9m%2BtUVurplBl8LHodFHKovhbdxHYYJR5cFNp8a0AfZ3MCJn%2B5dREN0vhZjZyhcBFwq%2FB505kAYJBPgN5auQm2s2pMgRQ9m66zD%2BCm1H3qJoWOWsEMOfuDUdIgIP%2BepXp4vcXUpixcIB3Ltb6FJSEsBgsWrJ%2FJcEzGMhRvrPmNQ5BA%2B%2BcryyrygOB8Fe7zZ7D6FTKPBZ6WS7miVf5h9Ozal%2Bnniwgqfc%2FrLSYohUljAvr7Nth5H6NDdlHDblgOlmd3WGJwptZK3BteBymjNDdyw2%2FoSas8CR1dyjfOEUtogb6%2FWin3slTGhKezg%3D%3D: HTTPSConnectionPool(host='storage.googleapis.com', port=443): Max retries exceeded with url: /wandb-production.appspot.com/dynamic_x/bert_pytorch/xvi6icyy/wandb-metadata.json?Expires=1706688636&GoogleAccessId=gorilla-files-url-signer-man%40wandb-production.iam.gserviceaccount.com&Signature=DDf5vt5B92k8FYrTqi6v6Act%2FfsD9m%2BtUVurplBl8LHodFHKovhbdxHYYJR5cFNp8a0AfZ3MCJn%2B5dREN0vhZjZyhcBFwq%2FB505kAYJBPgN5auQm2s2pMgRQ9m66zD%2BCm1H3qJoWOWsEMOfuDUdIgIP%2BepXp4vcXUpixcIB3Ltb6FJSEsBgsWrJ%2FJcEzGMhRvrPmNQ5BA%2B%2BcryyrygOB8Fe7zZ7D6FTKPBZ6WS7miVf5h9Ozal%2Bnniwgqfc%2FrLSYohUljAvr7Nth5H6NDdlHDblgOlmd3WGJwptZK3BteBymjNDdyw2%2FoSas8CR1dyjfOEUtogb6%2FWin3slTGhKezg%3D%3D (Caused by NewConnectionError('<urllib3.connection.HTTPSConnection object at 0x7f5f2411bbe0>: Failed to establish a new connection: [Errno 101] Network is unreachable'))
2024-01-30 16:12:54,954 ERROR   wandb-upload_0:1134332 [internal_api.py:upload_file():2767] upload_file request headers: {'User-Agent': 'python-requests/2.23.0', 'Accept-Encoding': 'gzip, deflate', 'Accept': '*/*', 'Connection': 'keep-alive', 'Content-Length': '15544'}
2024-01-30 16:12:54,954 ERROR   wandb-upload_0:1134332 [internal_api.py:upload_file():2769] upload_file response body: 
2024-01-30 16:12:58,903 DEBUG   HandlerThread:1134332 [handler.py:handle_request():146] handle_request: status_report
2024-01-30 16:13:03,904 DEBUG   HandlerThread:1134332 [handler.py:handle_request():146] handle_request: status_report
2024-01-30 16:13:07,592 DEBUG   HandlerThread:1134332 [handler.py:handle_request():146] handle_request: internal_messages
2024-01-30 16:13:07,594 DEBUG   HandlerThread:1134332 [handler.py:handle_request():146] handle_request: stop_status
2024-01-30 16:13:07,594 DEBUG   SenderThread:1134332 [sender.py:send_request():409] send_request: stop_status
2024-01-30 16:13:08,957 DEBUG   HandlerThread:1134332 [handler.py:handle_request():146] handle_request: status_report
2024-01-30 16:13:13,993 DEBUG   HandlerThread:1134332 [handler.py:handle_request():146] handle_request: status_report
2024-01-30 16:13:15,118 DEBUG   SenderThread:1134332 [sender.py:send():382] send: stats
2024-01-30 16:13:19,157 DEBUG   HandlerThread:1134332 [handler.py:handle_request():146] handle_request: status_report
2024-01-30 16:13:22,605 DEBUG   HandlerThread:1134332 [handler.py:handle_request():146] handle_request: internal_messages
2024-01-30 16:13:22,606 DEBUG   HandlerThread:1134332 [handler.py:handle_request():146] handle_request: stop_status
2024-01-30 16:13:22,606 DEBUG   SenderThread:1134332 [sender.py:send_request():409] send_request: stop_status
2024-01-30 16:13:25,010 DEBUG   HandlerThread:1134332 [handler.py:handle_request():146] handle_request: status_report
2024-01-30 16:13:30,011 DEBUG   HandlerThread:1134332 [handler.py:handle_request():146] handle_request: status_report
2024-01-30 16:13:35,011 DEBUG   HandlerThread:1134332 [handler.py:handle_request():146] handle_request: status_report
2024-01-30 16:13:37,592 DEBUG   HandlerThread:1134332 [handler.py:handle_request():146] handle_request: internal_messages
2024-01-30 16:13:37,595 DEBUG   HandlerThread:1134332 [handler.py:handle_request():146] handle_request: stop_status
2024-01-30 16:13:37,595 DEBUG   SenderThread:1134332 [sender.py:send_request():409] send_request: stop_status
2024-01-30 16:13:40,891 DEBUG   HandlerThread:1134332 [handler.py:handle_request():146] handle_request: status_report
2024-01-30 16:13:45,121 DEBUG   SenderThread:1134332 [sender.py:send():382] send: stats
2024-01-30 16:13:46,122 DEBUG   HandlerThread:1134332 [handler.py:handle_request():146] handle_request: status_report
2024-01-30 16:13:51,123 DEBUG   HandlerThread:1134332 [handler.py:handle_request():146] handle_request: status_report
2024-01-30 16:13:52,592 DEBUG   HandlerThread:1134332 [handler.py:handle_request():146] handle_request: internal_messages
2024-01-30 16:13:52,594 DEBUG   HandlerThread:1134332 [handler.py:handle_request():146] handle_request: stop_status
2024-01-30 16:13:52,595 DEBUG   SenderThread:1134332 [sender.py:send_request():409] send_request: stop_status
2024-01-30 16:13:56,943 DEBUG   HandlerThread:1134332 [handler.py:handle_request():146] handle_request: status_report
2024-01-30 16:14:01,947 DEBUG   HandlerThread:1134332 [handler.py:handle_request():146] handle_request: status_report
2024-01-30 16:14:06,951 DEBUG   HandlerThread:1134332 [handler.py:handle_request():146] handle_request: status_report
2024-01-30 16:14:07,592 DEBUG   HandlerThread:1134332 [handler.py:handle_request():146] handle_request: internal_messages
2024-01-30 16:14:07,594 DEBUG   HandlerThread:1134332 [handler.py:handle_request():146] handle_request: stop_status
2024-01-30 16:14:07,595 DEBUG   SenderThread:1134332 [sender.py:send_request():409] send_request: stop_status
2024-01-30 16:14:12,900 DEBUG   HandlerThread:1134332 [handler.py:handle_request():146] handle_request: status_report
2024-01-30 16:14:15,123 DEBUG   SenderThread:1134332 [sender.py:send():382] send: stats
2024-01-30 16:14:18,226 DEBUG   HandlerThread:1134332 [handler.py:handle_request():146] handle_request: status_report
2024-01-30 16:14:22,592 DEBUG   HandlerThread:1134332 [handler.py:handle_request():146] handle_request: internal_messages
2024-01-30 16:14:22,595 DEBUG   HandlerThread:1134332 [handler.py:handle_request():146] handle_request: stop_status
2024-01-30 16:14:22,595 DEBUG   SenderThread:1134332 [sender.py:send_request():409] send_request: stop_status
2024-01-30 16:14:24,058 DEBUG   HandlerThread:1134332 [handler.py:handle_request():146] handle_request: status_report
2024-01-30 16:14:29,067 DEBUG   HandlerThread:1134332 [handler.py:handle_request():146] handle_request: status_report
2024-01-30 16:14:34,132 DEBUG   HandlerThread:1134332 [handler.py:handle_request():146] handle_request: status_report
2024-01-30 16:14:37,610 DEBUG   HandlerThread:1134332 [handler.py:handle_request():146] handle_request: internal_messages
2024-01-30 16:14:37,610 DEBUG   HandlerThread:1134332 [handler.py:handle_request():146] handle_request: stop_status
2024-01-30 16:14:37,610 DEBUG   SenderThread:1134332 [sender.py:send_request():409] send_request: stop_status
2024-01-30 16:14:39,986 DEBUG   HandlerThread:1134332 [handler.py:handle_request():146] handle_request: status_report
2024-01-30 16:14:45,060 DEBUG   HandlerThread:1134332 [handler.py:handle_request():146] handle_request: status_report
2024-01-30 16:14:45,124 DEBUG   SenderThread:1134332 [sender.py:send():382] send: stats
2024-01-30 16:14:50,126 DEBUG   HandlerThread:1134332 [handler.py:handle_request():146] handle_request: status_report
2024-01-30 16:14:52,592 DEBUG   HandlerThread:1134332 [handler.py:handle_request():146] handle_request: internal_messages
2024-01-30 16:14:52,595 DEBUG   HandlerThread:1134332 [handler.py:handle_request():146] handle_request: stop_status
2024-01-30 16:14:52,595 DEBUG   SenderThread:1134332 [sender.py:send_request():409] send_request: stop_status
2024-01-30 16:14:55,892 DEBUG   HandlerThread:1134332 [handler.py:handle_request():146] handle_request: status_report
2024-01-30 16:15:00,892 DEBUG   HandlerThread:1134332 [handler.py:handle_request():146] handle_request: status_report
2024-01-30 16:15:05,893 DEBUG   HandlerThread:1134332 [handler.py:handle_request():146] handle_request: status_report
2024-01-30 16:15:07,592 DEBUG   HandlerThread:1134332 [handler.py:handle_request():146] handle_request: internal_messages
2024-01-30 16:15:07,595 DEBUG   HandlerThread:1134332 [handler.py:handle_request():146] handle_request: stop_status
2024-01-30 16:15:07,595 DEBUG   SenderThread:1134332 [sender.py:send_request():409] send_request: stop_status
2024-01-30 16:15:10,934 DEBUG   HandlerThread:1134332 [handler.py:handle_request():146] handle_request: status_report
2024-01-30 16:15:15,127 DEBUG   SenderThread:1134332 [sender.py:send():382] send: stats
2024-01-30 16:15:16,128 DEBUG   HandlerThread:1134332 [handler.py:handle_request():146] handle_request: status_report
2024-01-30 16:15:21,281 DEBUG   HandlerThread:1134332 [handler.py:handle_request():146] handle_request: status_report
2024-01-30 16:15:22,593 DEBUG   HandlerThread:1134332 [handler.py:handle_request():146] handle_request: internal_messages
2024-01-30 16:15:22,595 DEBUG   HandlerThread:1134332 [handler.py:handle_request():146] handle_request: stop_status
2024-01-30 16:15:22,595 DEBUG   SenderThread:1134332 [sender.py:send_request():409] send_request: stop_status
2024-01-30 16:15:27,169 DEBUG   HandlerThread:1134332 [handler.py:handle_request():146] handle_request: status_report
2024-01-30 16:15:29,326 ERROR   wandb-upload_0:1134332 [internal_api.py:upload_file():2765] upload_file exception https://storage.googleapis.com/wandb-production.appspot.com/dynamic_x/bert_pytorch/xvi6icyy/wandb-metadata.json?Expires=1706688636&GoogleAccessId=gorilla-files-url-signer-man%40wandb-production.iam.gserviceaccount.com&Signature=DDf5vt5B92k8FYrTqi6v6Act%2FfsD9m%2BtUVurplBl8LHodFHKovhbdxHYYJR5cFNp8a0AfZ3MCJn%2B5dREN0vhZjZyhcBFwq%2FB505kAYJBPgN5auQm2s2pMgRQ9m66zD%2BCm1H3qJoWOWsEMOfuDUdIgIP%2BepXp4vcXUpixcIB3Ltb6FJSEsBgsWrJ%2FJcEzGMhRvrPmNQ5BA%2B%2BcryyrygOB8Fe7zZ7D6FTKPBZ6WS7miVf5h9Ozal%2Bnniwgqfc%2FrLSYohUljAvr7Nth5H6NDdlHDblgOlmd3WGJwptZK3BteBymjNDdyw2%2FoSas8CR1dyjfOEUtogb6%2FWin3slTGhKezg%3D%3D: HTTPSConnectionPool(host='storage.googleapis.com', port=443): Max retries exceeded with url: /wandb-production.appspot.com/dynamic_x/bert_pytorch/xvi6icyy/wandb-metadata.json?Expires=1706688636&GoogleAccessId=gorilla-files-url-signer-man%40wandb-production.iam.gserviceaccount.com&Signature=DDf5vt5B92k8FYrTqi6v6Act%2FfsD9m%2BtUVurplBl8LHodFHKovhbdxHYYJR5cFNp8a0AfZ3MCJn%2B5dREN0vhZjZyhcBFwq%2FB505kAYJBPgN5auQm2s2pMgRQ9m66zD%2BCm1H3qJoWOWsEMOfuDUdIgIP%2BepXp4vcXUpixcIB3Ltb6FJSEsBgsWrJ%2FJcEzGMhRvrPmNQ5BA%2B%2BcryyrygOB8Fe7zZ7D6FTKPBZ6WS7miVf5h9Ozal%2Bnniwgqfc%2FrLSYohUljAvr7Nth5H6NDdlHDblgOlmd3WGJwptZK3BteBymjNDdyw2%2FoSas8CR1dyjfOEUtogb6%2FWin3slTGhKezg%3D%3D (Caused by NewConnectionError('<urllib3.connection.HTTPSConnection object at 0x7f5f2411b820>: Failed to establish a new connection: [Errno 101] Network is unreachable'))
2024-01-30 16:15:29,327 ERROR   wandb-upload_0:1134332 [internal_api.py:upload_file():2767] upload_file request headers: {'User-Agent': 'python-requests/2.23.0', 'Accept-Encoding': 'gzip, deflate', 'Accept': '*/*', 'Connection': 'keep-alive', 'Content-Length': '15544'}
2024-01-30 16:15:29,327 ERROR   wandb-upload_0:1134332 [internal_api.py:upload_file():2769] upload_file response body: 
2024-01-30 16:15:32,214 DEBUG   HandlerThread:1134332 [handler.py:handle_request():146] handle_request: status_report
2024-01-30 16:15:37,314 DEBUG   HandlerThread:1134332 [handler.py:handle_request():146] handle_request: status_report
2024-01-30 16:15:37,594 DEBUG   HandlerThread:1134332 [handler.py:handle_request():146] handle_request: internal_messages
2024-01-30 16:15:37,595 DEBUG   HandlerThread:1134332 [handler.py:handle_request():146] handle_request: stop_status
2024-01-30 16:15:37,595 DEBUG   SenderThread:1134332 [sender.py:send_request():409] send_request: stop_status
2024-01-30 16:15:42,918 DEBUG   HandlerThread:1134332 [handler.py:handle_request():146] handle_request: status_report
2024-01-30 16:15:45,129 DEBUG   SenderThread:1134332 [sender.py:send():382] send: stats
2024-01-30 16:15:48,130 DEBUG   HandlerThread:1134332 [handler.py:handle_request():146] handle_request: status_report
2024-01-30 16:15:52,593 DEBUG   HandlerThread:1134332 [handler.py:handle_request():146] handle_request: internal_messages
2024-01-30 16:15:52,595 DEBUG   HandlerThread:1134332 [handler.py:handle_request():146] handle_request: stop_status
2024-01-30 16:15:52,595 DEBUG   SenderThread:1134332 [sender.py:send_request():409] send_request: stop_status
2024-01-30 16:15:53,944 DEBUG   HandlerThread:1134332 [handler.py:handle_request():146] handle_request: status_report
2024-01-30 16:15:58,944 DEBUG   HandlerThread:1134332 [handler.py:handle_request():146] handle_request: status_report
2024-01-30 16:16:03,945 DEBUG   HandlerThread:1134332 [handler.py:handle_request():146] handle_request: status_report
2024-01-30 16:16:07,593 DEBUG   HandlerThread:1134332 [handler.py:handle_request():146] handle_request: internal_messages
2024-01-30 16:16:07,596 DEBUG   HandlerThread:1134332 [handler.py:handle_request():146] handle_request: stop_status
2024-01-30 16:16:07,596 DEBUG   SenderThread:1134332 [sender.py:send_request():409] send_request: stop_status
2024-01-30 16:16:09,931 DEBUG   HandlerThread:1134332 [handler.py:handle_request():146] handle_request: status_report
2024-01-30 16:16:14,934 DEBUG   HandlerThread:1134332 [handler.py:handle_request():146] handle_request: status_report
2024-01-30 16:16:15,131 DEBUG   SenderThread:1134332 [sender.py:send():382] send: stats
2024-01-30 16:16:20,189 DEBUG   HandlerThread:1134332 [handler.py:handle_request():146] handle_request: status_report
2024-01-30 16:16:22,594 DEBUG   HandlerThread:1134332 [handler.py:handle_request():146] handle_request: internal_messages
2024-01-30 16:16:22,596 DEBUG   HandlerThread:1134332 [handler.py:handle_request():146] handle_request: stop_status
2024-01-30 16:16:22,596 DEBUG   SenderThread:1134332 [sender.py:send_request():409] send_request: stop_status
2024-01-30 16:16:23,256 DEBUG   SenderThread:1134332 [sender.py:send():382] send: exit
2024-01-30 16:16:23,256 INFO    SenderThread:1134332 [sender.py:send_exit():589] handling exit code: 1
2024-01-30 16:16:23,257 INFO    SenderThread:1134332 [sender.py:send_exit():591] handling runtime: 368
2024-01-30 16:16:23,257 INFO    SenderThread:1134332 [sender.py:_save_file():1403] saving file wandb-summary.json with policy end
2024-01-30 16:16:23,257 INFO    SenderThread:1134332 [sender.py:send_exit():597] send defer
2024-01-30 16:16:23,259 DEBUG   HandlerThread:1134332 [handler.py:handle_request():146] handle_request: defer
2024-01-30 16:16:23,259 INFO    HandlerThread:1134332 [handler.py:handle_request_defer():172] handle defer: 0
2024-01-30 16:16:23,259 DEBUG   SenderThread:1134332 [sender.py:send_request():409] send_request: defer
2024-01-30 16:16:23,259 INFO    SenderThread:1134332 [sender.py:send_request_defer():613] handle sender defer: 0
2024-01-30 16:16:23,259 INFO    SenderThread:1134332 [sender.py:transition_state():617] send defer: 1
2024-01-30 16:16:23,260 DEBUG   HandlerThread:1134332 [handler.py:handle_request():146] handle_request: defer
2024-01-30 16:16:23,260 INFO    HandlerThread:1134332 [handler.py:handle_request_defer():172] handle defer: 1
2024-01-30 16:16:23,260 DEBUG   SenderThread:1134332 [sender.py:send_request():409] send_request: defer
2024-01-30 16:16:23,260 INFO    SenderThread:1134332 [sender.py:send_request_defer():613] handle sender defer: 1
2024-01-30 16:16:23,260 INFO    SenderThread:1134332 [sender.py:transition_state():617] send defer: 2
2024-01-30 16:16:23,260 DEBUG   HandlerThread:1134332 [handler.py:handle_request():146] handle_request: defer
2024-01-30 16:16:23,260 INFO    HandlerThread:1134332 [handler.py:handle_request_defer():172] handle defer: 2
2024-01-30 16:16:23,260 INFO    HandlerThread:1134332 [system_monitor.py:finish():203] Stopping system monitor
2024-01-30 16:16:23,260 DEBUG   SystemMonitor:1134332 [system_monitor.py:_start():179] Finished system metrics aggregation loop
2024-01-30 16:16:23,260 DEBUG   SystemMonitor:1134332 [system_monitor.py:_start():183] Publishing last batch of metrics
2024-01-30 16:16:23,263 INFO    HandlerThread:1134332 [interfaces.py:finish():202] Joined cpu monitor
2024-01-30 16:16:23,263 INFO    HandlerThread:1134332 [interfaces.py:finish():202] Joined disk monitor
2024-01-30 16:16:23,744 INFO    Thread-12 :1134332 [dir_watcher.py:_on_file_created():271] file/dir created: /home/yanxindong/mkor/bert/wandb/run-20240130_161012-xvi6icyy/files/wandb-summary.json
2024-01-30 16:16:23,928 INFO    HandlerThread:1134332 [interfaces.py:finish():202] Joined gpu monitor
2024-01-30 16:16:23,928 INFO    HandlerThread:1134332 [interfaces.py:finish():202] Joined memory monitor
2024-01-30 16:16:23,929 INFO    HandlerThread:1134332 [interfaces.py:finish():202] Joined network monitor
2024-01-30 16:16:23,929 DEBUG   SenderThread:1134332 [sender.py:send_request():409] send_request: defer
2024-01-30 16:16:23,929 INFO    SenderThread:1134332 [sender.py:send_request_defer():613] handle sender defer: 2
2024-01-30 16:16:23,929 INFO    SenderThread:1134332 [sender.py:transition_state():617] send defer: 3
2024-01-30 16:16:23,930 DEBUG   HandlerThread:1134332 [handler.py:handle_request():146] handle_request: defer
2024-01-30 16:16:23,930 INFO    HandlerThread:1134332 [handler.py:handle_request_defer():172] handle defer: 3
2024-01-30 16:16:23,930 DEBUG   SenderThread:1134332 [sender.py:send():382] send: stats
2024-01-30 16:16:23,931 DEBUG   SenderThread:1134332 [sender.py:send_request():409] send_request: defer
2024-01-30 16:16:23,931 INFO    SenderThread:1134332 [sender.py:send_request_defer():613] handle sender defer: 3
2024-01-30 16:16:23,931 INFO    SenderThread:1134332 [sender.py:transition_state():617] send defer: 4
2024-01-30 16:16:23,931 DEBUG   HandlerThread:1134332 [handler.py:handle_request():146] handle_request: defer
2024-01-30 16:16:23,931 INFO    HandlerThread:1134332 [handler.py:handle_request_defer():172] handle defer: 4
2024-01-30 16:16:23,931 DEBUG   SenderThread:1134332 [sender.py:send_request():409] send_request: defer
2024-01-30 16:16:23,932 INFO    SenderThread:1134332 [sender.py:send_request_defer():613] handle sender defer: 4
2024-01-30 16:16:23,932 INFO    SenderThread:1134332 [sender.py:transition_state():617] send defer: 5
2024-01-30 16:16:23,932 DEBUG   HandlerThread:1134332 [handler.py:handle_request():146] handle_request: defer
2024-01-30 16:16:23,932 INFO    HandlerThread:1134332 [handler.py:handle_request_defer():172] handle defer: 5
2024-01-30 16:16:23,932 DEBUG   SenderThread:1134332 [sender.py:send():382] send: summary
2024-01-30 16:16:23,932 INFO    SenderThread:1134332 [sender.py:_save_file():1403] saving file wandb-summary.json with policy end
2024-01-30 16:16:23,932 DEBUG   SenderThread:1134332 [sender.py:send_request():409] send_request: defer
2024-01-30 16:16:23,932 INFO    SenderThread:1134332 [sender.py:send_request_defer():613] handle sender defer: 5
2024-01-30 16:16:23,932 INFO    SenderThread:1134332 [sender.py:transition_state():617] send defer: 6
2024-01-30 16:16:23,933 DEBUG   HandlerThread:1134332 [handler.py:handle_request():146] handle_request: defer
2024-01-30 16:16:23,933 INFO    HandlerThread:1134332 [handler.py:handle_request_defer():172] handle defer: 6
2024-01-30 16:16:23,933 DEBUG   SenderThread:1134332 [sender.py:send_request():409] send_request: defer
2024-01-30 16:16:23,933 INFO    SenderThread:1134332 [sender.py:send_request_defer():613] handle sender defer: 6
2024-01-30 16:16:23,933 INFO    SenderThread:1134332 [sender.py:transition_state():617] send defer: 7
2024-01-30 16:16:23,933 DEBUG   HandlerThread:1134332 [handler.py:handle_request():146] handle_request: status_report
2024-01-30 16:16:23,933 DEBUG   HandlerThread:1134332 [handler.py:handle_request():146] handle_request: defer
2024-01-30 16:16:23,933 INFO    HandlerThread:1134332 [handler.py:handle_request_defer():172] handle defer: 7
2024-01-30 16:16:23,933 DEBUG   SenderThread:1134332 [sender.py:send_request():409] send_request: defer
2024-01-30 16:16:23,933 INFO    SenderThread:1134332 [sender.py:send_request_defer():613] handle sender defer: 7
2024-01-30 16:16:24,256 DEBUG   HandlerThread:1134332 [handler.py:handle_request():146] handle_request: poll_exit
2024-01-30 16:16:24,610 INFO    SenderThread:1134332 [sender.py:transition_state():617] send defer: 8
2024-01-30 16:16:24,610 DEBUG   SenderThread:1134332 [sender.py:send_request():409] send_request: poll_exit
2024-01-30 16:16:24,611 DEBUG   HandlerThread:1134332 [handler.py:handle_request():146] handle_request: defer
2024-01-30 16:16:24,611 INFO    HandlerThread:1134332 [handler.py:handle_request_defer():172] handle defer: 8
2024-01-30 16:16:24,611 DEBUG   SenderThread:1134332 [sender.py:send_request():409] send_request: defer
2024-01-30 16:16:24,611 INFO    SenderThread:1134332 [sender.py:send_request_defer():613] handle sender defer: 8
2024-01-30 16:16:24,611 INFO    SenderThread:1134332 [job_builder.py:build():296] Attempting to build job artifact
2024-01-30 16:16:24,612 INFO    SenderThread:1134332 [job_builder.py:_get_source_type():426] is repo sourced job
2024-01-30 16:16:24,631 INFO    SenderThread:1134332 [job_builder.py:build():402] adding wandb-job metadata file
2024-01-30 16:16:24,633 INFO    SenderThread:1134332 [sender.py:transition_state():617] send defer: 9
2024-01-30 16:16:24,634 DEBUG   HandlerThread:1134332 [handler.py:handle_request():146] handle_request: defer
2024-01-30 16:16:24,634 DEBUG   SenderThread:1134332 [sender.py:send():382] send: artifact
2024-01-30 16:16:24,634 INFO    HandlerThread:1134332 [handler.py:handle_request_defer():172] handle defer: 9
2024-01-30 16:16:24,743 INFO    Thread-12 :1134332 [dir_watcher.py:_on_file_modified():288] file/dir modified: /home/yanxindong/mkor/bert/wandb/run-20240130_161012-xvi6icyy/files/wandb-summary.json
2024-01-30 16:16:24,744 INFO    Thread-12 :1134332 [dir_watcher.py:_on_file_modified():288] file/dir modified: /home/yanxindong/mkor/bert/wandb/run-20240130_161012-xvi6icyy/files/output.log
2024-01-30 16:16:25,257 DEBUG   HandlerThread:1134332 [handler.py:handle_request():146] handle_request: poll_exit
2024-01-30 16:16:26,425 ERROR   wandb-upload_2:1134332 [internal_api.py:upload_file():2765] upload_file exception https://storage.googleapis.com/wandb-artifacts-prod/wandb_artifacts/133981200/707680658/6873c23a2381d1524249eb1a948a45a5?Expires=1706688986&GoogleAccessId=gorilla-files-url-signer-man%40wandb-production.iam.gserviceaccount.com&Signature=jkXXIP9d5i%2FP6fLZLuehv7R75MUWlEuy0JALMLT49xl%2BxBfMMLO0GilsgxfGNnlT6dQ4AoMb6jraXRo51p7Gifj0qeemqu5SmZrovJXsApv4q6R1ryKhBj%2FGrorL7OjfMgoO7usFey3jjg4vvrsxbMEsBa%2FXXB2iKGw3H1Fny4yUMtS7GNPmrgeRnFrBH%2FhaYi4VKu9e4sZXkL7Qcf8bUt%2BGo7OnCRhykEYaqEf3mwFhUJDThowZvvp1Z45hpWnoV1czFn9T%2Fps4o5Ses7mLOZPDU7HoaRR1YXJ1KjbOwC931oXbI3Gjht1%2FC0o61uwRb9z1hvn2rX5Vd1O5kikXlg%3D%3D: HTTPSConnectionPool(host='storage.googleapis.com', port=443): Max retries exceeded with url: /wandb-artifacts-prod/wandb_artifacts/133981200/707680658/6873c23a2381d1524249eb1a948a45a5?Expires=1706688986&GoogleAccessId=gorilla-files-url-signer-man%40wandb-production.iam.gserviceaccount.com&Signature=jkXXIP9d5i%2FP6fLZLuehv7R75MUWlEuy0JALMLT49xl%2BxBfMMLO0GilsgxfGNnlT6dQ4AoMb6jraXRo51p7Gifj0qeemqu5SmZrovJXsApv4q6R1ryKhBj%2FGrorL7OjfMgoO7usFey3jjg4vvrsxbMEsBa%2FXXB2iKGw3H1Fny4yUMtS7GNPmrgeRnFrBH%2FhaYi4VKu9e4sZXkL7Qcf8bUt%2BGo7OnCRhykEYaqEf3mwFhUJDThowZvvp1Z45hpWnoV1czFn9T%2Fps4o5Ses7mLOZPDU7HoaRR1YXJ1KjbOwC931oXbI3Gjht1%2FC0o61uwRb9z1hvn2rX5Vd1O5kikXlg%3D%3D (Caused by NewConnectionError('<urllib3.connection.HTTPSConnection object at 0x7f5f2405ed00>: Failed to establish a new connection: [Errno 101] Network is unreachable'))
2024-01-30 16:16:26,425 ERROR   wandb-upload_2:1134332 [internal_api.py:upload_file():2767] upload_file request headers: {'User-Agent': 'python-requests/2.23.0', 'Accept-Encoding': 'gzip, deflate', 'Accept': '*/*', 'Connection': 'keep-alive', 'Content-MD5': 'aHPCOiOB0VJCSesalIpFpQ==', 'Content-Type': 'application/json', 'Content-Length': '609'}
2024-01-30 16:16:26,425 ERROR   wandb-upload_2:1134332 [internal_api.py:upload_file():2769] upload_file response body: 
2024-01-30 16:16:26,425 ERROR   wandb-upload_1:1134332 [internal_api.py:upload_file():2765] upload_file exception https://storage.googleapis.com/wandb-artifacts-prod/wandb_artifacts/133981200/707680658/174a3d9bc61fec126cc7d5bdff5c6c5a?Expires=1706688986&GoogleAccessId=gorilla-files-url-signer-man%40wandb-production.iam.gserviceaccount.com&Signature=lBkj7FRI0vqPgHLx%2BOg7Yx%2BGOVCE4lfpqcS%2ByMrWmpzNtyMXnIEKkckanv1jvH649kkftO%2FY2pGVpnjPUSY%2BP%2Fbqfd3teYO2q6JA%2BRwZqnwibRsNs1wTzHeDxLlx3emDxpU9QGUPD8bpCI%2F8m8flx%2Bp1%2Fn84IlmAAzVnmeDtF4hsL9sld5%2BP4NwiDw3KK8hNzztpYao1SO6uN1dTl0UFdQ7muF9Hzh%2FwypwV03JGmgq10%2BQyr512zR6BzcjlIULUTnlgK2aZIvb2WuEFqLSOXeh0IJ08%2BMP4NJoGbXIWJ%2FqoG2ncCls%2FlNgco0n8TM38P13NXVJMOsK%2FqmhHRLDRlA%3D%3D: HTTPSConnectionPool(host='storage.googleapis.com', port=443): Max retries exceeded with url: /wandb-artifacts-prod/wandb_artifacts/133981200/707680658/174a3d9bc61fec126cc7d5bdff5c6c5a?Expires=1706688986&GoogleAccessId=gorilla-files-url-signer-man%40wandb-production.iam.gserviceaccount.com&Signature=lBkj7FRI0vqPgHLx%2BOg7Yx%2BGOVCE4lfpqcS%2ByMrWmpzNtyMXnIEKkckanv1jvH649kkftO%2FY2pGVpnjPUSY%2BP%2Fbqfd3teYO2q6JA%2BRwZqnwibRsNs1wTzHeDxLlx3emDxpU9QGUPD8bpCI%2F8m8flx%2Bp1%2Fn84IlmAAzVnmeDtF4hsL9sld5%2BP4NwiDw3KK8hNzztpYao1SO6uN1dTl0UFdQ7muF9Hzh%2FwypwV03JGmgq10%2BQyr512zR6BzcjlIULUTnlgK2aZIvb2WuEFqLSOXeh0IJ08%2BMP4NJoGbXIWJ%2FqoG2ncCls%2FlNgco0n8TM38P13NXVJMOsK%2FqmhHRLDRlA%3D%3D (Caused by NewConnectionError('<urllib3.connection.HTTPSConnection object at 0x7f5f2405ee50>: Failed to establish a new connection: [Errno 101] Network is unreachable'))
2024-01-30 16:16:26,425 ERROR   wandb-upload_1:1134332 [internal_api.py:upload_file():2767] upload_file request headers: {'User-Agent': 'python-requests/2.23.0', 'Accept-Encoding': 'gzip, deflate', 'Accept': '*/*', 'Connection': 'keep-alive', 'Content-MD5': 'F0o9m8Yf7BJsx9W9/1xsWg==', 'Content-Type': 'text/plain; charset=utf-8', 'Content-Length': '2179'}
2024-01-30 16:16:26,426 ERROR   wandb-upload_1:1134332 [internal_api.py:upload_file():2769] upload_file response body: 
2024-01-30 16:16:27,445 ERROR   wandb-upload_1:1134332 [internal_api.py:upload_file():2765] upload_file exception https://storage.googleapis.com/wandb-artifacts-prod/wandb_artifacts/133981200/707680658/174a3d9bc61fec126cc7d5bdff5c6c5a?Expires=1706688986&GoogleAccessId=gorilla-files-url-signer-man%40wandb-production.iam.gserviceaccount.com&Signature=lBkj7FRI0vqPgHLx%2BOg7Yx%2BGOVCE4lfpqcS%2ByMrWmpzNtyMXnIEKkckanv1jvH649kkftO%2FY2pGVpnjPUSY%2BP%2Fbqfd3teYO2q6JA%2BRwZqnwibRsNs1wTzHeDxLlx3emDxpU9QGUPD8bpCI%2F8m8flx%2Bp1%2Fn84IlmAAzVnmeDtF4hsL9sld5%2BP4NwiDw3KK8hNzztpYao1SO6uN1dTl0UFdQ7muF9Hzh%2FwypwV03JGmgq10%2BQyr512zR6BzcjlIULUTnlgK2aZIvb2WuEFqLSOXeh0IJ08%2BMP4NJoGbXIWJ%2FqoG2ncCls%2FlNgco0n8TM38P13NXVJMOsK%2FqmhHRLDRlA%3D%3D: HTTPSConnectionPool(host='storage.googleapis.com', port=443): Max retries exceeded with url: /wandb-artifacts-prod/wandb_artifacts/133981200/707680658/174a3d9bc61fec126cc7d5bdff5c6c5a?Expires=1706688986&GoogleAccessId=gorilla-files-url-signer-man%40wandb-production.iam.gserviceaccount.com&Signature=lBkj7FRI0vqPgHLx%2BOg7Yx%2BGOVCE4lfpqcS%2ByMrWmpzNtyMXnIEKkckanv1jvH649kkftO%2FY2pGVpnjPUSY%2BP%2Fbqfd3teYO2q6JA%2BRwZqnwibRsNs1wTzHeDxLlx3emDxpU9QGUPD8bpCI%2F8m8flx%2Bp1%2Fn84IlmAAzVnmeDtF4hsL9sld5%2BP4NwiDw3KK8hNzztpYao1SO6uN1dTl0UFdQ7muF9Hzh%2FwypwV03JGmgq10%2BQyr512zR6BzcjlIULUTnlgK2aZIvb2WuEFqLSOXeh0IJ08%2BMP4NJoGbXIWJ%2FqoG2ncCls%2FlNgco0n8TM38P13NXVJMOsK%2FqmhHRLDRlA%3D%3D (Caused by NewConnectionError('<urllib3.connection.HTTPSConnection object at 0x7f5f2422f1f0>: Failed to establish a new connection: [Errno 101] Network is unreachable'))
2024-01-30 16:16:27,445 ERROR   wandb-upload_1:1134332 [internal_api.py:upload_file():2767] upload_file request headers: {'User-Agent': 'python-requests/2.23.0', 'Accept-Encoding': 'gzip, deflate', 'Accept': '*/*', 'Connection': 'keep-alive', 'Content-MD5': 'F0o9m8Yf7BJsx9W9/1xsWg==', 'Content-Type': 'text/plain; charset=utf-8', 'Content-Length': '2179'}
2024-01-30 16:16:27,445 ERROR   wandb-upload_1:1134332 [internal_api.py:upload_file():2769] upload_file response body: 
2024-01-30 16:16:27,652 ERROR   wandb-upload_2:1134332 [internal_api.py:upload_file():2765] upload_file exception https://storage.googleapis.com/wandb-artifacts-prod/wandb_artifacts/133981200/707680658/6873c23a2381d1524249eb1a948a45a5?Expires=1706688986&GoogleAccessId=gorilla-files-url-signer-man%40wandb-production.iam.gserviceaccount.com&Signature=jkXXIP9d5i%2FP6fLZLuehv7R75MUWlEuy0JALMLT49xl%2BxBfMMLO0GilsgxfGNnlT6dQ4AoMb6jraXRo51p7Gifj0qeemqu5SmZrovJXsApv4q6R1ryKhBj%2FGrorL7OjfMgoO7usFey3jjg4vvrsxbMEsBa%2FXXB2iKGw3H1Fny4yUMtS7GNPmrgeRnFrBH%2FhaYi4VKu9e4sZXkL7Qcf8bUt%2BGo7OnCRhykEYaqEf3mwFhUJDThowZvvp1Z45hpWnoV1czFn9T%2Fps4o5Ses7mLOZPDU7HoaRR1YXJ1KjbOwC931oXbI3Gjht1%2FC0o61uwRb9z1hvn2rX5Vd1O5kikXlg%3D%3D: HTTPSConnectionPool(host='storage.googleapis.com', port=443): Max retries exceeded with url: /wandb-artifacts-prod/wandb_artifacts/133981200/707680658/6873c23a2381d1524249eb1a948a45a5?Expires=1706688986&GoogleAccessId=gorilla-files-url-signer-man%40wandb-production.iam.gserviceaccount.com&Signature=jkXXIP9d5i%2FP6fLZLuehv7R75MUWlEuy0JALMLT49xl%2BxBfMMLO0GilsgxfGNnlT6dQ4AoMb6jraXRo51p7Gifj0qeemqu5SmZrovJXsApv4q6R1ryKhBj%2FGrorL7OjfMgoO7usFey3jjg4vvrsxbMEsBa%2FXXB2iKGw3H1Fny4yUMtS7GNPmrgeRnFrBH%2FhaYi4VKu9e4sZXkL7Qcf8bUt%2BGo7OnCRhykEYaqEf3mwFhUJDThowZvvp1Z45hpWnoV1czFn9T%2Fps4o5Ses7mLOZPDU7HoaRR1YXJ1KjbOwC931oXbI3Gjht1%2FC0o61uwRb9z1hvn2rX5Vd1O5kikXlg%3D%3D (Caused by NewConnectionError('<urllib3.connection.HTTPSConnection object at 0x7f5f2405e820>: Failed to establish a new connection: [Errno 101] Network is unreachable'))
2024-01-30 16:16:27,653 ERROR   wandb-upload_2:1134332 [internal_api.py:upload_file():2767] upload_file request headers: {'User-Agent': 'python-requests/2.23.0', 'Accept-Encoding': 'gzip, deflate', 'Accept': '*/*', 'Connection': 'keep-alive', 'Content-MD5': 'aHPCOiOB0VJCSesalIpFpQ==', 'Content-Type': 'application/json', 'Content-Length': '609'}
2024-01-30 16:16:27,653 ERROR   wandb-upload_2:1134332 [internal_api.py:upload_file():2769] upload_file response body: 
2024-01-30 16:16:29,715 ERROR   wandb-upload_2:1134332 [internal_api.py:upload_file():2765] upload_file exception https://storage.googleapis.com/wandb-artifacts-prod/wandb_artifacts/133981200/707680658/6873c23a2381d1524249eb1a948a45a5?Expires=1706688986&GoogleAccessId=gorilla-files-url-signer-man%40wandb-production.iam.gserviceaccount.com&Signature=jkXXIP9d5i%2FP6fLZLuehv7R75MUWlEuy0JALMLT49xl%2BxBfMMLO0GilsgxfGNnlT6dQ4AoMb6jraXRo51p7Gifj0qeemqu5SmZrovJXsApv4q6R1ryKhBj%2FGrorL7OjfMgoO7usFey3jjg4vvrsxbMEsBa%2FXXB2iKGw3H1Fny4yUMtS7GNPmrgeRnFrBH%2FhaYi4VKu9e4sZXkL7Qcf8bUt%2BGo7OnCRhykEYaqEf3mwFhUJDThowZvvp1Z45hpWnoV1czFn9T%2Fps4o5Ses7mLOZPDU7HoaRR1YXJ1KjbOwC931oXbI3Gjht1%2FC0o61uwRb9z1hvn2rX5Vd1O5kikXlg%3D%3D: HTTPSConnectionPool(host='storage.googleapis.com', port=443): Max retries exceeded with url: /wandb-artifacts-prod/wandb_artifacts/133981200/707680658/6873c23a2381d1524249eb1a948a45a5?Expires=1706688986&GoogleAccessId=gorilla-files-url-signer-man%40wandb-production.iam.gserviceaccount.com&Signature=jkXXIP9d5i%2FP6fLZLuehv7R75MUWlEuy0JALMLT49xl%2BxBfMMLO0GilsgxfGNnlT6dQ4AoMb6jraXRo51p7Gifj0qeemqu5SmZrovJXsApv4q6R1ryKhBj%2FGrorL7OjfMgoO7usFey3jjg4vvrsxbMEsBa%2FXXB2iKGw3H1Fny4yUMtS7GNPmrgeRnFrBH%2FhaYi4VKu9e4sZXkL7Qcf8bUt%2BGo7OnCRhykEYaqEf3mwFhUJDThowZvvp1Z45hpWnoV1czFn9T%2Fps4o5Ses7mLOZPDU7HoaRR1YXJ1KjbOwC931oXbI3Gjht1%2FC0o61uwRb9z1hvn2rX5Vd1O5kikXlg%3D%3D (Caused by NewConnectionError('<urllib3.connection.HTTPSConnection object at 0x7f5f1c7f28e0>: Failed to establish a new connection: [Errno 101] Network is unreachable'))
2024-01-30 16:16:29,715 ERROR   wandb-upload_2:1134332 [internal_api.py:upload_file():2767] upload_file request headers: {'User-Agent': 'python-requests/2.23.0', 'Accept-Encoding': 'gzip, deflate', 'Accept': '*/*', 'Connection': 'keep-alive', 'Content-MD5': 'aHPCOiOB0VJCSesalIpFpQ==', 'Content-Type': 'application/json', 'Content-Length': '609'}
2024-01-30 16:16:29,715 ERROR   wandb-upload_2:1134332 [internal_api.py:upload_file():2769] upload_file response body: 
2024-01-30 16:16:29,715 INFO    wandb-upload_2:1134332 [retry.py:__call__():172] Retry attempt failed:
Traceback (most recent call last):
  File "/home/yanxindong/anaconda/envs/eva/lib/python3.8/site-packages/urllib3/connection.py", line 159, in _new_conn
    conn = connection.create_connection(
  File "/home/yanxindong/anaconda/envs/eva/lib/python3.8/site-packages/urllib3/util/connection.py", line 84, in create_connection
    raise err
  File "/home/yanxindong/anaconda/envs/eva/lib/python3.8/site-packages/urllib3/util/connection.py", line 74, in create_connection
    sock.connect(sa)
OSError: [Errno 101] Network is unreachable

During handling of the above exception, another exception occurred:

Traceback (most recent call last):
  File "/home/yanxindong/anaconda/envs/eva/lib/python3.8/site-packages/urllib3/connectionpool.py", line 670, in urlopen
    httplib_response = self._make_request(
  File "/home/yanxindong/anaconda/envs/eva/lib/python3.8/site-packages/urllib3/connectionpool.py", line 381, in _make_request
    self._validate_conn(conn)
  File "/home/yanxindong/anaconda/envs/eva/lib/python3.8/site-packages/urllib3/connectionpool.py", line 978, in _validate_conn
    conn.connect()
  File "/home/yanxindong/anaconda/envs/eva/lib/python3.8/site-packages/urllib3/connection.py", line 309, in connect
    conn = self._new_conn()
  File "/home/yanxindong/anaconda/envs/eva/lib/python3.8/site-packages/urllib3/connection.py", line 171, in _new_conn
    raise NewConnectionError(
urllib3.exceptions.NewConnectionError: <urllib3.connection.HTTPSConnection object at 0x7f5f1c7f28e0>: Failed to establish a new connection: [Errno 101] Network is unreachable

During handling of the above exception, another exception occurred:

Traceback (most recent call last):
  File "/home/yanxindong/anaconda/envs/eva/lib/python3.8/site-packages/requests/adapters.py", line 439, in send
    resp = conn.urlopen(
  File "/home/yanxindong/anaconda/envs/eva/lib/python3.8/site-packages/urllib3/connectionpool.py", line 726, in urlopen
    retries = retries.increment(
  File "/home/yanxindong/anaconda/envs/eva/lib/python3.8/site-packages/urllib3/util/retry.py", line 446, in increment
    raise MaxRetryError(_pool, url, error or ResponseError(cause))
urllib3.exceptions.MaxRetryError: HTTPSConnectionPool(host='storage.googleapis.com', port=443): Max retries exceeded with url: /wandb-artifacts-prod/wandb_artifacts/133981200/707680658/6873c23a2381d1524249eb1a948a45a5?Expires=1706688986&GoogleAccessId=gorilla-files-url-signer-man%40wandb-production.iam.gserviceaccount.com&Signature=jkXXIP9d5i%2FP6fLZLuehv7R75MUWlEuy0JALMLT49xl%2BxBfMMLO0GilsgxfGNnlT6dQ4AoMb6jraXRo51p7Gifj0qeemqu5SmZrovJXsApv4q6R1ryKhBj%2FGrorL7OjfMgoO7usFey3jjg4vvrsxbMEsBa%2FXXB2iKGw3H1Fny4yUMtS7GNPmrgeRnFrBH%2FhaYi4VKu9e4sZXkL7Qcf8bUt%2BGo7OnCRhykEYaqEf3mwFhUJDThowZvvp1Z45hpWnoV1czFn9T%2Fps4o5Ses7mLOZPDU7HoaRR1YXJ1KjbOwC931oXbI3Gjht1%2FC0o61uwRb9z1hvn2rX5Vd1O5kikXlg%3D%3D (Caused by NewConnectionError('<urllib3.connection.HTTPSConnection object at 0x7f5f1c7f28e0>: Failed to establish a new connection: [Errno 101] Network is unreachable'))

During handling of the above exception, another exception occurred:

Traceback (most recent call last):
  File "/home/yanxindong/anaconda/envs/eva/lib/python3.8/site-packages/wandb/sdk/internal/internal_api.py", line 2758, in upload_file
    response = self._upload_file_session.put(
  File "/home/yanxindong/anaconda/envs/eva/lib/python3.8/site-packages/requests/sessions.py", line 590, in put
    return self.request('PUT', url, data=data, **kwargs)
  File "/home/yanxindong/anaconda/envs/eva/lib/python3.8/site-packages/requests/sessions.py", line 530, in request
    resp = self.send(prep, **send_kwargs)
  File "/home/yanxindong/anaconda/envs/eva/lib/python3.8/site-packages/requests/sessions.py", line 643, in send
    r = adapter.send(request, **kwargs)
  File "/home/yanxindong/anaconda/envs/eva/lib/python3.8/site-packages/requests/adapters.py", line 516, in send
    raise ConnectionError(e, request=request)
requests.exceptions.ConnectionError: HTTPSConnectionPool(host='storage.googleapis.com', port=443): Max retries exceeded with url: /wandb-artifacts-prod/wandb_artifacts/133981200/707680658/6873c23a2381d1524249eb1a948a45a5?Expires=1706688986&GoogleAccessId=gorilla-files-url-signer-man%40wandb-production.iam.gserviceaccount.com&Signature=jkXXIP9d5i%2FP6fLZLuehv7R75MUWlEuy0JALMLT49xl%2BxBfMMLO0GilsgxfGNnlT6dQ4AoMb6jraXRo51p7Gifj0qeemqu5SmZrovJXsApv4q6R1ryKhBj%2FGrorL7OjfMgoO7usFey3jjg4vvrsxbMEsBa%2FXXB2iKGw3H1Fny4yUMtS7GNPmrgeRnFrBH%2FhaYi4VKu9e4sZXkL7Qcf8bUt%2BGo7OnCRhykEYaqEf3mwFhUJDThowZvvp1Z45hpWnoV1czFn9T%2Fps4o5Ses7mLOZPDU7HoaRR1YXJ1KjbOwC931oXbI3Gjht1%2FC0o61uwRb9z1hvn2rX5Vd1O5kikXlg%3D%3D (Caused by NewConnectionError('<urllib3.connection.HTTPSConnection object at 0x7f5f1c7f28e0>: Failed to establish a new connection: [Errno 101] Network is unreachable'))

During handling of the above exception, another exception occurred:

Traceback (most recent call last):
  File "/home/yanxindong/anaconda/envs/eva/lib/python3.8/site-packages/wandb/sdk/lib/retry.py", line 131, in __call__
    result = self._call_fn(*args, **kwargs)
  File "/home/yanxindong/anaconda/envs/eva/lib/python3.8/site-packages/wandb/sdk/internal/internal_api.py", line 2789, in upload_file
    raise _e.with_traceback(sys.exc_info()[2])
  File "/home/yanxindong/anaconda/envs/eva/lib/python3.8/site-packages/wandb/sdk/internal/internal_api.py", line 2758, in upload_file
    response = self._upload_file_session.put(
  File "/home/yanxindong/anaconda/envs/eva/lib/python3.8/site-packages/requests/sessions.py", line 590, in put
    return self.request('PUT', url, data=data, **kwargs)
  File "/home/yanxindong/anaconda/envs/eva/lib/python3.8/site-packages/requests/sessions.py", line 530, in request
    resp = self.send(prep, **send_kwargs)
  File "/home/yanxindong/anaconda/envs/eva/lib/python3.8/site-packages/requests/sessions.py", line 643, in send
    r = adapter.send(request, **kwargs)
  File "/home/yanxindong/anaconda/envs/eva/lib/python3.8/site-packages/requests/adapters.py", line 516, in send
    raise ConnectionError(e, request=request)
wandb.sdk.lib.retry.TransientError: None
2024-01-30 16:16:29,716 ERROR   wandb-upload_1:1134332 [internal_api.py:upload_file():2765] upload_file exception https://storage.googleapis.com/wandb-artifacts-prod/wandb_artifacts/133981200/707680658/174a3d9bc61fec126cc7d5bdff5c6c5a?Expires=1706688986&GoogleAccessId=gorilla-files-url-signer-man%40wandb-production.iam.gserviceaccount.com&Signature=lBkj7FRI0vqPgHLx%2BOg7Yx%2BGOVCE4lfpqcS%2ByMrWmpzNtyMXnIEKkckanv1jvH649kkftO%2FY2pGVpnjPUSY%2BP%2Fbqfd3teYO2q6JA%2BRwZqnwibRsNs1wTzHeDxLlx3emDxpU9QGUPD8bpCI%2F8m8flx%2Bp1%2Fn84IlmAAzVnmeDtF4hsL9sld5%2BP4NwiDw3KK8hNzztpYao1SO6uN1dTl0UFdQ7muF9Hzh%2FwypwV03JGmgq10%2BQyr512zR6BzcjlIULUTnlgK2aZIvb2WuEFqLSOXeh0IJ08%2BMP4NJoGbXIWJ%2FqoG2ncCls%2FlNgco0n8TM38P13NXVJMOsK%2FqmhHRLDRlA%3D%3D: HTTPSConnectionPool(host='storage.googleapis.com', port=443): Max retries exceeded with url: /wandb-artifacts-prod/wandb_artifacts/133981200/707680658/174a3d9bc61fec126cc7d5bdff5c6c5a?Expires=1706688986&GoogleAccessId=gorilla-files-url-signer-man%40wandb-production.iam.gserviceaccount.com&Signature=lBkj7FRI0vqPgHLx%2BOg7Yx%2BGOVCE4lfpqcS%2ByMrWmpzNtyMXnIEKkckanv1jvH649kkftO%2FY2pGVpnjPUSY%2BP%2Fbqfd3teYO2q6JA%2BRwZqnwibRsNs1wTzHeDxLlx3emDxpU9QGUPD8bpCI%2F8m8flx%2Bp1%2Fn84IlmAAzVnmeDtF4hsL9sld5%2BP4NwiDw3KK8hNzztpYao1SO6uN1dTl0UFdQ7muF9Hzh%2FwypwV03JGmgq10%2BQyr512zR6BzcjlIULUTnlgK2aZIvb2WuEFqLSOXeh0IJ08%2BMP4NJoGbXIWJ%2FqoG2ncCls%2FlNgco0n8TM38P13NXVJMOsK%2FqmhHRLDRlA%3D%3D (Caused by NewConnectionError('<urllib3.connection.HTTPSConnection object at 0x7f5f1c7f2ac0>: Failed to establish a new connection: [Errno 101] Network is unreachable'))
2024-01-30 16:16:29,716 ERROR   wandb-upload_1:1134332 [internal_api.py:upload_file():2767] upload_file request headers: {'User-Agent': 'python-requests/2.23.0', 'Accept-Encoding': 'gzip, deflate', 'Accept': '*/*', 'Connection': 'keep-alive', 'Content-MD5': 'F0o9m8Yf7BJsx9W9/1xsWg==', 'Content-Type': 'text/plain; charset=utf-8', 'Content-Length': '2179'}
2024-01-30 16:16:29,716 ERROR   wandb-upload_1:1134332 [internal_api.py:upload_file():2769] upload_file response body: 
2024-01-30 16:16:29,716 INFO    wandb-upload_1:1134332 [retry.py:__call__():172] Retry attempt failed:
Traceback (most recent call last):
  File "/home/yanxindong/anaconda/envs/eva/lib/python3.8/site-packages/urllib3/connection.py", line 159, in _new_conn
    conn = connection.create_connection(
  File "/home/yanxindong/anaconda/envs/eva/lib/python3.8/site-packages/urllib3/util/connection.py", line 84, in create_connection
    raise err
  File "/home/yanxindong/anaconda/envs/eva/lib/python3.8/site-packages/urllib3/util/connection.py", line 74, in create_connection
    sock.connect(sa)
OSError: [Errno 101] Network is unreachable

During handling of the above exception, another exception occurred:

Traceback (most recent call last):
  File "/home/yanxindong/anaconda/envs/eva/lib/python3.8/site-packages/urllib3/connectionpool.py", line 670, in urlopen
    httplib_response = self._make_request(
  File "/home/yanxindong/anaconda/envs/eva/lib/python3.8/site-packages/urllib3/connectionpool.py", line 381, in _make_request
    self._validate_conn(conn)
  File "/home/yanxindong/anaconda/envs/eva/lib/python3.8/site-packages/urllib3/connectionpool.py", line 978, in _validate_conn
    conn.connect()
  File "/home/yanxindong/anaconda/envs/eva/lib/python3.8/site-packages/urllib3/connection.py", line 309, in connect
    conn = self._new_conn()
  File "/home/yanxindong/anaconda/envs/eva/lib/python3.8/site-packages/urllib3/connection.py", line 171, in _new_conn
    raise NewConnectionError(
urllib3.exceptions.NewConnectionError: <urllib3.connection.HTTPSConnection object at 0x7f5f1c7f2ac0>: Failed to establish a new connection: [Errno 101] Network is unreachable

During handling of the above exception, another exception occurred:

Traceback (most recent call last):
  File "/home/yanxindong/anaconda/envs/eva/lib/python3.8/site-packages/requests/adapters.py", line 439, in send
    resp = conn.urlopen(
  File "/home/yanxindong/anaconda/envs/eva/lib/python3.8/site-packages/urllib3/connectionpool.py", line 726, in urlopen
    retries = retries.increment(
  File "/home/yanxindong/anaconda/envs/eva/lib/python3.8/site-packages/urllib3/util/retry.py", line 446, in increment
    raise MaxRetryError(_pool, url, error or ResponseError(cause))
urllib3.exceptions.MaxRetryError: HTTPSConnectionPool(host='storage.googleapis.com', port=443): Max retries exceeded with url: /wandb-artifacts-prod/wandb_artifacts/133981200/707680658/174a3d9bc61fec126cc7d5bdff5c6c5a?Expires=1706688986&GoogleAccessId=gorilla-files-url-signer-man%40wandb-production.iam.gserviceaccount.com&Signature=lBkj7FRI0vqPgHLx%2BOg7Yx%2BGOVCE4lfpqcS%2ByMrWmpzNtyMXnIEKkckanv1jvH649kkftO%2FY2pGVpnjPUSY%2BP%2Fbqfd3teYO2q6JA%2BRwZqnwibRsNs1wTzHeDxLlx3emDxpU9QGUPD8bpCI%2F8m8flx%2Bp1%2Fn84IlmAAzVnmeDtF4hsL9sld5%2BP4NwiDw3KK8hNzztpYao1SO6uN1dTl0UFdQ7muF9Hzh%2FwypwV03JGmgq10%2BQyr512zR6BzcjlIULUTnlgK2aZIvb2WuEFqLSOXeh0IJ08%2BMP4NJoGbXIWJ%2FqoG2ncCls%2FlNgco0n8TM38P13NXVJMOsK%2FqmhHRLDRlA%3D%3D (Caused by NewConnectionError('<urllib3.connection.HTTPSConnection object at 0x7f5f1c7f2ac0>: Failed to establish a new connection: [Errno 101] Network is unreachable'))

During handling of the above exception, another exception occurred:

Traceback (most recent call last):
  File "/home/yanxindong/anaconda/envs/eva/lib/python3.8/site-packages/wandb/sdk/internal/internal_api.py", line 2758, in upload_file
    response = self._upload_file_session.put(
  File "/home/yanxindong/anaconda/envs/eva/lib/python3.8/site-packages/requests/sessions.py", line 590, in put
    return self.request('PUT', url, data=data, **kwargs)
  File "/home/yanxindong/anaconda/envs/eva/lib/python3.8/site-packages/requests/sessions.py", line 530, in request
    resp = self.send(prep, **send_kwargs)
  File "/home/yanxindong/anaconda/envs/eva/lib/python3.8/site-packages/requests/sessions.py", line 643, in send
    r = adapter.send(request, **kwargs)
  File "/home/yanxindong/anaconda/envs/eva/lib/python3.8/site-packages/requests/adapters.py", line 516, in send
    raise ConnectionError(e, request=request)
requests.exceptions.ConnectionError: HTTPSConnectionPool(host='storage.googleapis.com', port=443): Max retries exceeded with url: /wandb-artifacts-prod/wandb_artifacts/133981200/707680658/174a3d9bc61fec126cc7d5bdff5c6c5a?Expires=1706688986&GoogleAccessId=gorilla-files-url-signer-man%40wandb-production.iam.gserviceaccount.com&Signature=lBkj7FRI0vqPgHLx%2BOg7Yx%2BGOVCE4lfpqcS%2ByMrWmpzNtyMXnIEKkckanv1jvH649kkftO%2FY2pGVpnjPUSY%2BP%2Fbqfd3teYO2q6JA%2BRwZqnwibRsNs1wTzHeDxLlx3emDxpU9QGUPD8bpCI%2F8m8flx%2Bp1%2Fn84IlmAAzVnmeDtF4hsL9sld5%2BP4NwiDw3KK8hNzztpYao1SO6uN1dTl0UFdQ7muF9Hzh%2FwypwV03JGmgq10%2BQyr512zR6BzcjlIULUTnlgK2aZIvb2WuEFqLSOXeh0IJ08%2BMP4NJoGbXIWJ%2FqoG2ncCls%2FlNgco0n8TM38P13NXVJMOsK%2FqmhHRLDRlA%3D%3D (Caused by NewConnectionError('<urllib3.connection.HTTPSConnection object at 0x7f5f1c7f2ac0>: Failed to establish a new connection: [Errno 101] Network is unreachable'))

During handling of the above exception, another exception occurred:

Traceback (most recent call last):
  File "/home/yanxindong/anaconda/envs/eva/lib/python3.8/site-packages/wandb/sdk/lib/retry.py", line 131, in __call__
    result = self._call_fn(*args, **kwargs)
  File "/home/yanxindong/anaconda/envs/eva/lib/python3.8/site-packages/wandb/sdk/internal/internal_api.py", line 2789, in upload_file
    raise _e.with_traceback(sys.exc_info()[2])
  File "/home/yanxindong/anaconda/envs/eva/lib/python3.8/site-packages/wandb/sdk/internal/internal_api.py", line 2758, in upload_file
    response = self._upload_file_session.put(
  File "/home/yanxindong/anaconda/envs/eva/lib/python3.8/site-packages/requests/sessions.py", line 590, in put
    return self.request('PUT', url, data=data, **kwargs)
  File "/home/yanxindong/anaconda/envs/eva/lib/python3.8/site-packages/requests/sessions.py", line 530, in request
    resp = self.send(prep, **send_kwargs)
  File "/home/yanxindong/anaconda/envs/eva/lib/python3.8/site-packages/requests/sessions.py", line 643, in send
    r = adapter.send(request, **kwargs)
  File "/home/yanxindong/anaconda/envs/eva/lib/python3.8/site-packages/requests/adapters.py", line 516, in send
    raise ConnectionError(e, request=request)
wandb.sdk.lib.retry.TransientError: None
2024-01-30 16:16:30,259 DEBUG   HandlerThread:1134332 [handler.py:handle_request():146] handle_request: keepalive
2024-01-30 16:16:34,036 ERROR   wandb-upload_2:1134332 [internal_api.py:upload_file():2765] upload_file exception https://storage.googleapis.com/wandb-artifacts-prod/wandb_artifacts/133981200/707680658/6873c23a2381d1524249eb1a948a45a5?Expires=1706688986&GoogleAccessId=gorilla-files-url-signer-man%40wandb-production.iam.gserviceaccount.com&Signature=jkXXIP9d5i%2FP6fLZLuehv7R75MUWlEuy0JALMLT49xl%2BxBfMMLO0GilsgxfGNnlT6dQ4AoMb6jraXRo51p7Gifj0qeemqu5SmZrovJXsApv4q6R1ryKhBj%2FGrorL7OjfMgoO7usFey3jjg4vvrsxbMEsBa%2FXXB2iKGw3H1Fny4yUMtS7GNPmrgeRnFrBH%2FhaYi4VKu9e4sZXkL7Qcf8bUt%2BGo7OnCRhykEYaqEf3mwFhUJDThowZvvp1Z45hpWnoV1czFn9T%2Fps4o5Ses7mLOZPDU7HoaRR1YXJ1KjbOwC931oXbI3Gjht1%2FC0o61uwRb9z1hvn2rX5Vd1O5kikXlg%3D%3D: HTTPSConnectionPool(host='storage.googleapis.com', port=443): Max retries exceeded with url: /wandb-artifacts-prod/wandb_artifacts/133981200/707680658/6873c23a2381d1524249eb1a948a45a5?Expires=1706688986&GoogleAccessId=gorilla-files-url-signer-man%40wandb-production.iam.gserviceaccount.com&Signature=jkXXIP9d5i%2FP6fLZLuehv7R75MUWlEuy0JALMLT49xl%2BxBfMMLO0GilsgxfGNnlT6dQ4AoMb6jraXRo51p7Gifj0qeemqu5SmZrovJXsApv4q6R1ryKhBj%2FGrorL7OjfMgoO7usFey3jjg4vvrsxbMEsBa%2FXXB2iKGw3H1Fny4yUMtS7GNPmrgeRnFrBH%2FhaYi4VKu9e4sZXkL7Qcf8bUt%2BGo7OnCRhykEYaqEf3mwFhUJDThowZvvp1Z45hpWnoV1czFn9T%2Fps4o5Ses7mLOZPDU7HoaRR1YXJ1KjbOwC931oXbI3Gjht1%2FC0o61uwRb9z1hvn2rX5Vd1O5kikXlg%3D%3D (Caused by NewConnectionError('<urllib3.connection.HTTPSConnection object at 0x7f5f1c7ec4c0>: Failed to establish a new connection: [Errno 101] Network is unreachable'))
2024-01-30 16:16:34,036 ERROR   wandb-upload_2:1134332 [internal_api.py:upload_file():2767] upload_file request headers: {'User-Agent': 'python-requests/2.23.0', 'Accept-Encoding': 'gzip, deflate', 'Accept': '*/*', 'Connection': 'keep-alive', 'Content-MD5': 'aHPCOiOB0VJCSesalIpFpQ==', 'Content-Type': 'application/json', 'Content-Length': '609'}
2024-01-30 16:16:34,036 ERROR   wandb-upload_2:1134332 [internal_api.py:upload_file():2769] upload_file response body: 
2024-01-30 16:16:34,314 ERROR   wandb-upload_1:1134332 [internal_api.py:upload_file():2765] upload_file exception https://storage.googleapis.com/wandb-artifacts-prod/wandb_artifacts/133981200/707680658/174a3d9bc61fec126cc7d5bdff5c6c5a?Expires=1706688986&GoogleAccessId=gorilla-files-url-signer-man%40wandb-production.iam.gserviceaccount.com&Signature=lBkj7FRI0vqPgHLx%2BOg7Yx%2BGOVCE4lfpqcS%2ByMrWmpzNtyMXnIEKkckanv1jvH649kkftO%2FY2pGVpnjPUSY%2BP%2Fbqfd3teYO2q6JA%2BRwZqnwibRsNs1wTzHeDxLlx3emDxpU9QGUPD8bpCI%2F8m8flx%2Bp1%2Fn84IlmAAzVnmeDtF4hsL9sld5%2BP4NwiDw3KK8hNzztpYao1SO6uN1dTl0UFdQ7muF9Hzh%2FwypwV03JGmgq10%2BQyr512zR6BzcjlIULUTnlgK2aZIvb2WuEFqLSOXeh0IJ08%2BMP4NJoGbXIWJ%2FqoG2ncCls%2FlNgco0n8TM38P13NXVJMOsK%2FqmhHRLDRlA%3D%3D: HTTPSConnectionPool(host='storage.googleapis.com', port=443): Max retries exceeded with url: /wandb-artifacts-prod/wandb_artifacts/133981200/707680658/174a3d9bc61fec126cc7d5bdff5c6c5a?Expires=1706688986&GoogleAccessId=gorilla-files-url-signer-man%40wandb-production.iam.gserviceaccount.com&Signature=lBkj7FRI0vqPgHLx%2BOg7Yx%2BGOVCE4lfpqcS%2ByMrWmpzNtyMXnIEKkckanv1jvH649kkftO%2FY2pGVpnjPUSY%2BP%2Fbqfd3teYO2q6JA%2BRwZqnwibRsNs1wTzHeDxLlx3emDxpU9QGUPD8bpCI%2F8m8flx%2Bp1%2Fn84IlmAAzVnmeDtF4hsL9sld5%2BP4NwiDw3KK8hNzztpYao1SO6uN1dTl0UFdQ7muF9Hzh%2FwypwV03JGmgq10%2BQyr512zR6BzcjlIULUTnlgK2aZIvb2WuEFqLSOXeh0IJ08%2BMP4NJoGbXIWJ%2FqoG2ncCls%2FlNgco0n8TM38P13NXVJMOsK%2FqmhHRLDRlA%3D%3D (Caused by NewConnectionError('<urllib3.connection.HTTPSConnection object at 0x7f5f1c7ec9a0>: Failed to establish a new connection: [Errno 101] Network is unreachable'))
2024-01-30 16:16:34,314 ERROR   wandb-upload_1:1134332 [internal_api.py:upload_file():2767] upload_file request headers: {'User-Agent': 'python-requests/2.23.0', 'Accept-Encoding': 'gzip, deflate', 'Accept': '*/*', 'Connection': 'keep-alive', 'Content-MD5': 'F0o9m8Yf7BJsx9W9/1xsWg==', 'Content-Type': 'text/plain; charset=utf-8', 'Content-Length': '2179'}
2024-01-30 16:16:34,314 ERROR   wandb-upload_1:1134332 [internal_api.py:upload_file():2769] upload_file response body: 
2024-01-30 16:16:35,261 DEBUG   HandlerThread:1134332 [handler.py:handle_request():146] handle_request: keepalive
2024-01-30 16:16:40,263 DEBUG   HandlerThread:1134332 [handler.py:handle_request():146] handle_request: keepalive
2024-01-30 16:16:42,395 ERROR   wandb-upload_1:1134332 [internal_api.py:upload_file():2765] upload_file exception https://storage.googleapis.com/wandb-artifacts-prod/wandb_artifacts/133981200/707680658/174a3d9bc61fec126cc7d5bdff5c6c5a?Expires=1706688986&GoogleAccessId=gorilla-files-url-signer-man%40wandb-production.iam.gserviceaccount.com&Signature=lBkj7FRI0vqPgHLx%2BOg7Yx%2BGOVCE4lfpqcS%2ByMrWmpzNtyMXnIEKkckanv1jvH649kkftO%2FY2pGVpnjPUSY%2BP%2Fbqfd3teYO2q6JA%2BRwZqnwibRsNs1wTzHeDxLlx3emDxpU9QGUPD8bpCI%2F8m8flx%2Bp1%2Fn84IlmAAzVnmeDtF4hsL9sld5%2BP4NwiDw3KK8hNzztpYao1SO6uN1dTl0UFdQ7muF9Hzh%2FwypwV03JGmgq10%2BQyr512zR6BzcjlIULUTnlgK2aZIvb2WuEFqLSOXeh0IJ08%2BMP4NJoGbXIWJ%2FqoG2ncCls%2FlNgco0n8TM38P13NXVJMOsK%2FqmhHRLDRlA%3D%3D: HTTPSConnectionPool(host='storage.googleapis.com', port=443): Max retries exceeded with url: /wandb-artifacts-prod/wandb_artifacts/133981200/707680658/174a3d9bc61fec126cc7d5bdff5c6c5a?Expires=1706688986&GoogleAccessId=gorilla-files-url-signer-man%40wandb-production.iam.gserviceaccount.com&Signature=lBkj7FRI0vqPgHLx%2BOg7Yx%2BGOVCE4lfpqcS%2ByMrWmpzNtyMXnIEKkckanv1jvH649kkftO%2FY2pGVpnjPUSY%2BP%2Fbqfd3teYO2q6JA%2BRwZqnwibRsNs1wTzHeDxLlx3emDxpU9QGUPD8bpCI%2F8m8flx%2Bp1%2Fn84IlmAAzVnmeDtF4hsL9sld5%2BP4NwiDw3KK8hNzztpYao1SO6uN1dTl0UFdQ7muF9Hzh%2FwypwV03JGmgq10%2BQyr512zR6BzcjlIULUTnlgK2aZIvb2WuEFqLSOXeh0IJ08%2BMP4NJoGbXIWJ%2FqoG2ncCls%2FlNgco0n8TM38P13NXVJMOsK%2FqmhHRLDRlA%3D%3D (Caused by NewConnectionError('<urllib3.connection.HTTPSConnection object at 0x7f5f1c7e7070>: Failed to establish a new connection: [Errno 101] Network is unreachable'))
2024-01-30 16:16:42,395 ERROR   wandb-upload_1:1134332 [internal_api.py:upload_file():2767] upload_file request headers: {'User-Agent': 'python-requests/2.23.0', 'Accept-Encoding': 'gzip, deflate', 'Accept': '*/*', 'Connection': 'keep-alive', 'Content-MD5': 'F0o9m8Yf7BJsx9W9/1xsWg==', 'Content-Type': 'text/plain; charset=utf-8', 'Content-Length': '2179'}
2024-01-30 16:16:42,395 ERROR   wandb-upload_1:1134332 [internal_api.py:upload_file():2769] upload_file response body: 
2024-01-30 16:16:43,824 ERROR   wandb-upload_2:1134332 [internal_api.py:upload_file():2765] upload_file exception https://storage.googleapis.com/wandb-artifacts-prod/wandb_artifacts/133981200/707680658/6873c23a2381d1524249eb1a948a45a5?Expires=1706688986&GoogleAccessId=gorilla-files-url-signer-man%40wandb-production.iam.gserviceaccount.com&Signature=jkXXIP9d5i%2FP6fLZLuehv7R75MUWlEuy0JALMLT49xl%2BxBfMMLO0GilsgxfGNnlT6dQ4AoMb6jraXRo51p7Gifj0qeemqu5SmZrovJXsApv4q6R1ryKhBj%2FGrorL7OjfMgoO7usFey3jjg4vvrsxbMEsBa%2FXXB2iKGw3H1Fny4yUMtS7GNPmrgeRnFrBH%2FhaYi4VKu9e4sZXkL7Qcf8bUt%2BGo7OnCRhykEYaqEf3mwFhUJDThowZvvp1Z45hpWnoV1czFn9T%2Fps4o5Ses7mLOZPDU7HoaRR1YXJ1KjbOwC931oXbI3Gjht1%2FC0o61uwRb9z1hvn2rX5Vd1O5kikXlg%3D%3D: HTTPSConnectionPool(host='storage.googleapis.com', port=443): Max retries exceeded with url: /wandb-artifacts-prod/wandb_artifacts/133981200/707680658/6873c23a2381d1524249eb1a948a45a5?Expires=1706688986&GoogleAccessId=gorilla-files-url-signer-man%40wandb-production.iam.gserviceaccount.com&Signature=jkXXIP9d5i%2FP6fLZLuehv7R75MUWlEuy0JALMLT49xl%2BxBfMMLO0GilsgxfGNnlT6dQ4AoMb6jraXRo51p7Gifj0qeemqu5SmZrovJXsApv4q6R1ryKhBj%2FGrorL7OjfMgoO7usFey3jjg4vvrsxbMEsBa%2FXXB2iKGw3H1Fny4yUMtS7GNPmrgeRnFrBH%2FhaYi4VKu9e4sZXkL7Qcf8bUt%2BGo7OnCRhykEYaqEf3mwFhUJDThowZvvp1Z45hpWnoV1czFn9T%2Fps4o5Ses7mLOZPDU7HoaRR1YXJ1KjbOwC931oXbI3Gjht1%2FC0o61uwRb9z1hvn2rX5Vd1O5kikXlg%3D%3D (Caused by NewConnectionError('<urllib3.connection.HTTPSConnection object at 0x7f5f1c7e79a0>: Failed to establish a new connection: [Errno 101] Network is unreachable'))
2024-01-30 16:16:43,825 ERROR   wandb-upload_2:1134332 [internal_api.py:upload_file():2767] upload_file request headers: {'User-Agent': 'python-requests/2.23.0', 'Accept-Encoding': 'gzip, deflate', 'Accept': '*/*', 'Connection': 'keep-alive', 'Content-MD5': 'aHPCOiOB0VJCSesalIpFpQ==', 'Content-Type': 'application/json', 'Content-Length': '609'}
2024-01-30 16:16:43,825 ERROR   wandb-upload_2:1134332 [internal_api.py:upload_file():2769] upload_file response body: 
2024-01-30 16:16:45,265 DEBUG   HandlerThread:1134332 [handler.py:handle_request():146] handle_request: keepalive
2024-01-30 16:16:50,267 DEBUG   HandlerThread:1134332 [handler.py:handle_request():146] handle_request: keepalive
2024-01-30 16:16:55,270 DEBUG   HandlerThread:1134332 [handler.py:handle_request():146] handle_request: keepalive
2024-01-30 16:17:00,152 ERROR   wandb-upload_2:1134332 [internal_api.py:upload_file():2765] upload_file exception https://storage.googleapis.com/wandb-artifacts-prod/wandb_artifacts/133981200/707680658/6873c23a2381d1524249eb1a948a45a5?Expires=1706688986&GoogleAccessId=gorilla-files-url-signer-man%40wandb-production.iam.gserviceaccount.com&Signature=jkXXIP9d5i%2FP6fLZLuehv7R75MUWlEuy0JALMLT49xl%2BxBfMMLO0GilsgxfGNnlT6dQ4AoMb6jraXRo51p7Gifj0qeemqu5SmZrovJXsApv4q6R1ryKhBj%2FGrorL7OjfMgoO7usFey3jjg4vvrsxbMEsBa%2FXXB2iKGw3H1Fny4yUMtS7GNPmrgeRnFrBH%2FhaYi4VKu9e4sZXkL7Qcf8bUt%2BGo7OnCRhykEYaqEf3mwFhUJDThowZvvp1Z45hpWnoV1czFn9T%2Fps4o5Ses7mLOZPDU7HoaRR1YXJ1KjbOwC931oXbI3Gjht1%2FC0o61uwRb9z1hvn2rX5Vd1O5kikXlg%3D%3D: HTTPSConnectionPool(host='storage.googleapis.com', port=443): Max retries exceeded with url: /wandb-artifacts-prod/wandb_artifacts/133981200/707680658/6873c23a2381d1524249eb1a948a45a5?Expires=1706688986&GoogleAccessId=gorilla-files-url-signer-man%40wandb-production.iam.gserviceaccount.com&Signature=jkXXIP9d5i%2FP6fLZLuehv7R75MUWlEuy0JALMLT49xl%2BxBfMMLO0GilsgxfGNnlT6dQ4AoMb6jraXRo51p7Gifj0qeemqu5SmZrovJXsApv4q6R1ryKhBj%2FGrorL7OjfMgoO7usFey3jjg4vvrsxbMEsBa%2FXXB2iKGw3H1Fny4yUMtS7GNPmrgeRnFrBH%2FhaYi4VKu9e4sZXkL7Qcf8bUt%2BGo7OnCRhykEYaqEf3mwFhUJDThowZvvp1Z45hpWnoV1czFn9T%2Fps4o5Ses7mLOZPDU7HoaRR1YXJ1KjbOwC931oXbI3Gjht1%2FC0o61uwRb9z1hvn2rX5Vd1O5kikXlg%3D%3D (Caused by NewConnectionError('<urllib3.connection.HTTPSConnection object at 0x7f5f1c7ec130>: Failed to establish a new connection: [Errno 101] Network is unreachable'))
2024-01-30 16:17:00,153 ERROR   wandb-upload_2:1134332 [internal_api.py:upload_file():2767] upload_file request headers: {'User-Agent': 'python-requests/2.23.0', 'Accept-Encoding': 'gzip, deflate', 'Accept': '*/*', 'Connection': 'keep-alive', 'Content-MD5': 'aHPCOiOB0VJCSesalIpFpQ==', 'Content-Type': 'application/json', 'Content-Length': '609'}
2024-01-30 16:17:00,153 ERROR   wandb-upload_2:1134332 [internal_api.py:upload_file():2769] upload_file response body: 
2024-01-30 16:17:00,271 DEBUG   HandlerThread:1134332 [handler.py:handle_request():146] handle_request: keepalive
2024-01-30 16:17:02,100 ERROR   wandb-upload_1:1134332 [internal_api.py:upload_file():2765] upload_file exception https://storage.googleapis.com/wandb-artifacts-prod/wandb_artifacts/133981200/707680658/174a3d9bc61fec126cc7d5bdff5c6c5a?Expires=1706688986&GoogleAccessId=gorilla-files-url-signer-man%40wandb-production.iam.gserviceaccount.com&Signature=lBkj7FRI0vqPgHLx%2BOg7Yx%2BGOVCE4lfpqcS%2ByMrWmpzNtyMXnIEKkckanv1jvH649kkftO%2FY2pGVpnjPUSY%2BP%2Fbqfd3teYO2q6JA%2BRwZqnwibRsNs1wTzHeDxLlx3emDxpU9QGUPD8bpCI%2F8m8flx%2Bp1%2Fn84IlmAAzVnmeDtF4hsL9sld5%2BP4NwiDw3KK8hNzztpYao1SO6uN1dTl0UFdQ7muF9Hzh%2FwypwV03JGmgq10%2BQyr512zR6BzcjlIULUTnlgK2aZIvb2WuEFqLSOXeh0IJ08%2BMP4NJoGbXIWJ%2FqoG2ncCls%2FlNgco0n8TM38P13NXVJMOsK%2FqmhHRLDRlA%3D%3D: HTTPSConnectionPool(host='storage.googleapis.com', port=443): Max retries exceeded with url: /wandb-artifacts-prod/wandb_artifacts/133981200/707680658/174a3d9bc61fec126cc7d5bdff5c6c5a?Expires=1706688986&GoogleAccessId=gorilla-files-url-signer-man%40wandb-production.iam.gserviceaccount.com&Signature=lBkj7FRI0vqPgHLx%2BOg7Yx%2BGOVCE4lfpqcS%2ByMrWmpzNtyMXnIEKkckanv1jvH649kkftO%2FY2pGVpnjPUSY%2BP%2Fbqfd3teYO2q6JA%2BRwZqnwibRsNs1wTzHeDxLlx3emDxpU9QGUPD8bpCI%2F8m8flx%2Bp1%2Fn84IlmAAzVnmeDtF4hsL9sld5%2BP4NwiDw3KK8hNzztpYao1SO6uN1dTl0UFdQ7muF9Hzh%2FwypwV03JGmgq10%2BQyr512zR6BzcjlIULUTnlgK2aZIvb2WuEFqLSOXeh0IJ08%2BMP4NJoGbXIWJ%2FqoG2ncCls%2FlNgco0n8TM38P13NXVJMOsK%2FqmhHRLDRlA%3D%3D (Caused by NewConnectionError('<urllib3.connection.HTTPSConnection object at 0x7f5f1c7ec790>: Failed to establish a new connection: [Errno 101] Network is unreachable'))
2024-01-30 16:17:02,100 ERROR   wandb-upload_1:1134332 [internal_api.py:upload_file():2767] upload_file request headers: {'User-Agent': 'python-requests/2.23.0', 'Accept-Encoding': 'gzip, deflate', 'Accept': '*/*', 'Connection': 'keep-alive', 'Content-MD5': 'F0o9m8Yf7BJsx9W9/1xsWg==', 'Content-Type': 'text/plain; charset=utf-8', 'Content-Length': '2179'}
2024-01-30 16:17:02,100 ERROR   wandb-upload_1:1134332 [internal_api.py:upload_file():2769] upload_file response body: 
2024-01-30 16:17:05,274 DEBUG   HandlerThread:1134332 [handler.py:handle_request():146] handle_request: keepalive
2024-01-30 16:17:10,276 DEBUG   HandlerThread:1134332 [handler.py:handle_request():146] handle_request: keepalive
2024-01-30 16:17:15,278 DEBUG   HandlerThread:1134332 [handler.py:handle_request():146] handle_request: keepalive
2024-01-30 16:17:20,280 DEBUG   HandlerThread:1134332 [handler.py:handle_request():146] handle_request: keepalive
2024-01-30 16:17:25,282 DEBUG   HandlerThread:1134332 [handler.py:handle_request():146] handle_request: keepalive
2024-01-30 16:17:30,284 DEBUG   HandlerThread:1134332 [handler.py:handle_request():146] handle_request: keepalive
2024-01-30 16:17:33,418 ERROR   wandb-upload_2:1134332 [internal_api.py:upload_file():2765] upload_file exception https://storage.googleapis.com/wandb-artifacts-prod/wandb_artifacts/133981200/707680658/6873c23a2381d1524249eb1a948a45a5?Expires=1706688986&GoogleAccessId=gorilla-files-url-signer-man%40wandb-production.iam.gserviceaccount.com&Signature=jkXXIP9d5i%2FP6fLZLuehv7R75MUWlEuy0JALMLT49xl%2BxBfMMLO0GilsgxfGNnlT6dQ4AoMb6jraXRo51p7Gifj0qeemqu5SmZrovJXsApv4q6R1ryKhBj%2FGrorL7OjfMgoO7usFey3jjg4vvrsxbMEsBa%2FXXB2iKGw3H1Fny4yUMtS7GNPmrgeRnFrBH%2FhaYi4VKu9e4sZXkL7Qcf8bUt%2BGo7OnCRhykEYaqEf3mwFhUJDThowZvvp1Z45hpWnoV1czFn9T%2Fps4o5Ses7mLOZPDU7HoaRR1YXJ1KjbOwC931oXbI3Gjht1%2FC0o61uwRb9z1hvn2rX5Vd1O5kikXlg%3D%3D: HTTPSConnectionPool(host='storage.googleapis.com', port=443): Max retries exceeded with url: /wandb-artifacts-prod/wandb_artifacts/133981200/707680658/6873c23a2381d1524249eb1a948a45a5?Expires=1706688986&GoogleAccessId=gorilla-files-url-signer-man%40wandb-production.iam.gserviceaccount.com&Signature=jkXXIP9d5i%2FP6fLZLuehv7R75MUWlEuy0JALMLT49xl%2BxBfMMLO0GilsgxfGNnlT6dQ4AoMb6jraXRo51p7Gifj0qeemqu5SmZrovJXsApv4q6R1ryKhBj%2FGrorL7OjfMgoO7usFey3jjg4vvrsxbMEsBa%2FXXB2iKGw3H1Fny4yUMtS7GNPmrgeRnFrBH%2FhaYi4VKu9e4sZXkL7Qcf8bUt%2BGo7OnCRhykEYaqEf3mwFhUJDThowZvvp1Z45hpWnoV1czFn9T%2Fps4o5Ses7mLOZPDU7HoaRR1YXJ1KjbOwC931oXbI3Gjht1%2FC0o61uwRb9z1hvn2rX5Vd1O5kikXlg%3D%3D (Caused by NewConnectionError('<urllib3.connection.HTTPSConnection object at 0x7f5f2405ecd0>: Failed to establish a new connection: [Errno 101] Network is unreachable'))
2024-01-30 16:17:33,418 ERROR   wandb-upload_2:1134332 [internal_api.py:upload_file():2767] upload_file request headers: {'User-Agent': 'python-requests/2.23.0', 'Accept-Encoding': 'gzip, deflate', 'Accept': '*/*', 'Connection': 'keep-alive', 'Content-MD5': 'aHPCOiOB0VJCSesalIpFpQ==', 'Content-Type': 'application/json', 'Content-Length': '609'}
2024-01-30 16:17:33,418 ERROR   wandb-upload_2:1134332 [internal_api.py:upload_file():2769] upload_file response body: 
2024-01-30 16:17:34,811 ERROR   wandb-upload_1:1134332 [internal_api.py:upload_file():2765] upload_file exception https://storage.googleapis.com/wandb-artifacts-prod/wandb_artifacts/133981200/707680658/174a3d9bc61fec126cc7d5bdff5c6c5a?Expires=1706688986&GoogleAccessId=gorilla-files-url-signer-man%40wandb-production.iam.gserviceaccount.com&Signature=lBkj7FRI0vqPgHLx%2BOg7Yx%2BGOVCE4lfpqcS%2ByMrWmpzNtyMXnIEKkckanv1jvH649kkftO%2FY2pGVpnjPUSY%2BP%2Fbqfd3teYO2q6JA%2BRwZqnwibRsNs1wTzHeDxLlx3emDxpU9QGUPD8bpCI%2F8m8flx%2Bp1%2Fn84IlmAAzVnmeDtF4hsL9sld5%2BP4NwiDw3KK8hNzztpYao1SO6uN1dTl0UFdQ7muF9Hzh%2FwypwV03JGmgq10%2BQyr512zR6BzcjlIULUTnlgK2aZIvb2WuEFqLSOXeh0IJ08%2BMP4NJoGbXIWJ%2FqoG2ncCls%2FlNgco0n8TM38P13NXVJMOsK%2FqmhHRLDRlA%3D%3D: HTTPSConnectionPool(host='storage.googleapis.com', port=443): Max retries exceeded with url: /wandb-artifacts-prod/wandb_artifacts/133981200/707680658/174a3d9bc61fec126cc7d5bdff5c6c5a?Expires=1706688986&GoogleAccessId=gorilla-files-url-signer-man%40wandb-production.iam.gserviceaccount.com&Signature=lBkj7FRI0vqPgHLx%2BOg7Yx%2BGOVCE4lfpqcS%2ByMrWmpzNtyMXnIEKkckanv1jvH649kkftO%2FY2pGVpnjPUSY%2BP%2Fbqfd3teYO2q6JA%2BRwZqnwibRsNs1wTzHeDxLlx3emDxpU9QGUPD8bpCI%2F8m8flx%2Bp1%2Fn84IlmAAzVnmeDtF4hsL9sld5%2BP4NwiDw3KK8hNzztpYao1SO6uN1dTl0UFdQ7muF9Hzh%2FwypwV03JGmgq10%2BQyr512zR6BzcjlIULUTnlgK2aZIvb2WuEFqLSOXeh0IJ08%2BMP4NJoGbXIWJ%2FqoG2ncCls%2FlNgco0n8TM38P13NXVJMOsK%2FqmhHRLDRlA%3D%3D (Caused by NewConnectionError('<urllib3.connection.HTTPSConnection object at 0x7f5f1c7eb760>: Failed to establish a new connection: [Errno 101] Network is unreachable'))
2024-01-30 16:17:34,811 ERROR   wandb-upload_1:1134332 [internal_api.py:upload_file():2767] upload_file request headers: {'User-Agent': 'python-requests/2.23.0', 'Accept-Encoding': 'gzip, deflate', 'Accept': '*/*', 'Connection': 'keep-alive', 'Content-MD5': 'F0o9m8Yf7BJsx9W9/1xsWg==', 'Content-Type': 'text/plain; charset=utf-8', 'Content-Length': '2179'}
2024-01-30 16:17:34,811 ERROR   wandb-upload_1:1134332 [internal_api.py:upload_file():2769] upload_file response body: 
2024-01-30 16:17:35,287 DEBUG   HandlerThread:1134332 [handler.py:handle_request():146] handle_request: keepalive
2024-01-30 16:17:40,289 DEBUG   HandlerThread:1134332 [handler.py:handle_request():146] handle_request: keepalive
2024-01-30 16:17:45,291 DEBUG   HandlerThread:1134332 [handler.py:handle_request():146] handle_request: keepalive
2024-01-30 16:17:50,293 DEBUG   HandlerThread:1134332 [handler.py:handle_request():146] handle_request: keepalive
2024-01-30 16:17:55,296 DEBUG   HandlerThread:1134332 [handler.py:handle_request():146] handle_request: keepalive
2024-01-30 16:20:40,361 ERROR   wandb-upload_0:1134332 [internal_api.py:upload_file():2765] upload_file exception https://storage.googleapis.com/wandb-production.appspot.com/dynamic_x/bert_pytorch/xvi6icyy/wandb-metadata.json?Expires=1706688636&GoogleAccessId=gorilla-files-url-signer-man%40wandb-production.iam.gserviceaccount.com&Signature=DDf5vt5B92k8FYrTqi6v6Act%2FfsD9m%2BtUVurplBl8LHodFHKovhbdxHYYJR5cFNp8a0AfZ3MCJn%2B5dREN0vhZjZyhcBFwq%2FB505kAYJBPgN5auQm2s2pMgRQ9m66zD%2BCm1H3qJoWOWsEMOfuDUdIgIP%2BepXp4vcXUpixcIB3Ltb6FJSEsBgsWrJ%2FJcEzGMhRvrPmNQ5BA%2B%2BcryyrygOB8Fe7zZ7D6FTKPBZ6WS7miVf5h9Ozal%2Bnniwgqfc%2FrLSYohUljAvr7Nth5H6NDdlHDblgOlmd3WGJwptZK3BteBymjNDdyw2%2FoSas8CR1dyjfOEUtogb6%2FWin3slTGhKezg%3D%3D: HTTPSConnectionPool(host='storage.googleapis.com', port=443): Max retries exceeded with url: /wandb-production.appspot.com/dynamic_x/bert_pytorch/xvi6icyy/wandb-metadata.json?Expires=1706688636&GoogleAccessId=gorilla-files-url-signer-man%40wandb-production.iam.gserviceaccount.com&Signature=DDf5vt5B92k8FYrTqi6v6Act%2FfsD9m%2BtUVurplBl8LHodFHKovhbdxHYYJR5cFNp8a0AfZ3MCJn%2B5dREN0vhZjZyhcBFwq%2FB505kAYJBPgN5auQm2s2pMgRQ9m66zD%2BCm1H3qJoWOWsEMOfuDUdIgIP%2BepXp4vcXUpixcIB3Ltb6FJSEsBgsWrJ%2FJcEzGMhRvrPmNQ5BA%2B%2BcryyrygOB8Fe7zZ7D6FTKPBZ6WS7miVf5h9Ozal%2Bnniwgqfc%2FrLSYohUljAvr7Nth5H6NDdlHDblgOlmd3WGJwptZK3BteBymjNDdyw2%2FoSas8CR1dyjfOEUtogb6%2FWin3slTGhKezg%3D%3D (Caused by NewConnectionError('<urllib3.connection.HTTPSConnection object at 0x7f5f1c7e7940>: Failed to establish a new connection: [Errno 101] Network is unreachable'))
2024-01-30 16:20:40,362 ERROR   wandb-upload_0:1134332 [internal_api.py:upload_file():2767] upload_file request headers: {'User-Agent': 'python-requests/2.23.0', 'Accept-Encoding': 'gzip, deflate', 'Accept': '*/*', 'Connection': 'keep-alive', 'Content-Length': '15544'}
2024-01-30 16:20:40,362 ERROR   wandb-upload_0:1134332 [internal_api.py:upload_file():2769] upload_file response body: 
2024-01-30 16:26:49,009 ERROR   wandb-upload_0:1134332 [internal_api.py:upload_file():2765] upload_file exception https://storage.googleapis.com/wandb-production.appspot.com/dynamic_x/bert_pytorch/xvi6icyy/wandb-metadata.json?Expires=1706688636&GoogleAccessId=gorilla-files-url-signer-man%40wandb-production.iam.gserviceaccount.com&Signature=DDf5vt5B92k8FYrTqi6v6Act%2FfsD9m%2BtUVurplBl8LHodFHKovhbdxHYYJR5cFNp8a0AfZ3MCJn%2B5dREN0vhZjZyhcBFwq%2FB505kAYJBPgN5auQm2s2pMgRQ9m66zD%2BCm1H3qJoWOWsEMOfuDUdIgIP%2BepXp4vcXUpixcIB3Ltb6FJSEsBgsWrJ%2FJcEzGMhRvrPmNQ5BA%2B%2BcryyrygOB8Fe7zZ7D6FTKPBZ6WS7miVf5h9Ozal%2Bnniwgqfc%2FrLSYohUljAvr7Nth5H6NDdlHDblgOlmd3WGJwptZK3BteBymjNDdyw2%2FoSas8CR1dyjfOEUtogb6%2FWin3slTGhKezg%3D%3D: HTTPSConnectionPool(host='storage.googleapis.com', port=443): Max retries exceeded with url: /wandb-production.appspot.com/dynamic_x/bert_pytorch/xvi6icyy/wandb-metadata.json?Expires=1706688636&GoogleAccessId=gorilla-files-url-signer-man%40wandb-production.iam.gserviceaccount.com&Signature=DDf5vt5B92k8FYrTqi6v6Act%2FfsD9m%2BtUVurplBl8LHodFHKovhbdxHYYJR5cFNp8a0AfZ3MCJn%2B5dREN0vhZjZyhcBFwq%2FB505kAYJBPgN5auQm2s2pMgRQ9m66zD%2BCm1H3qJoWOWsEMOfuDUdIgIP%2BepXp4vcXUpixcIB3Ltb6FJSEsBgsWrJ%2FJcEzGMhRvrPmNQ5BA%2B%2BcryyrygOB8Fe7zZ7D6FTKPBZ6WS7miVf5h9Ozal%2Bnniwgqfc%2FrLSYohUljAvr7Nth5H6NDdlHDblgOlmd3WGJwptZK3BteBymjNDdyw2%2FoSas8CR1dyjfOEUtogb6%2FWin3slTGhKezg%3D%3D (Caused by NewConnectionError('<urllib3.connection.HTTPSConnection object at 0x7f5f1c7de100>: Failed to establish a new connection: [Errno 111] Connection refused'))
2024-01-30 16:26:49,009 ERROR   wandb-upload_0:1134332 [internal_api.py:upload_file():2767] upload_file request headers: {'User-Agent': 'python-requests/2.23.0', 'Accept-Encoding': 'gzip, deflate', 'Accept': '*/*', 'Connection': 'keep-alive', 'Content-Length': '15544'}
2024-01-30 16:26:49,009 ERROR   wandb-upload_0:1134332 [internal_api.py:upload_file():2769] upload_file response body: 
2024-01-30 16:31:52,167 ERROR   wandb-upload_0:1134332 [internal_api.py:upload_file():2765] upload_file exception https://storage.googleapis.com/wandb-production.appspot.com/dynamic_x/bert_pytorch/xvi6icyy/wandb-metadata.json?Expires=1706688636&GoogleAccessId=gorilla-files-url-signer-man%40wandb-production.iam.gserviceaccount.com&Signature=DDf5vt5B92k8FYrTqi6v6Act%2FfsD9m%2BtUVurplBl8LHodFHKovhbdxHYYJR5cFNp8a0AfZ3MCJn%2B5dREN0vhZjZyhcBFwq%2FB505kAYJBPgN5auQm2s2pMgRQ9m66zD%2BCm1H3qJoWOWsEMOfuDUdIgIP%2BepXp4vcXUpixcIB3Ltb6FJSEsBgsWrJ%2FJcEzGMhRvrPmNQ5BA%2B%2BcryyrygOB8Fe7zZ7D6FTKPBZ6WS7miVf5h9Ozal%2Bnniwgqfc%2FrLSYohUljAvr7Nth5H6NDdlHDblgOlmd3WGJwptZK3BteBymjNDdyw2%2FoSas8CR1dyjfOEUtogb6%2FWin3slTGhKezg%3D%3D: HTTPSConnectionPool(host='storage.googleapis.com', port=443): Max retries exceeded with url: /wandb-production.appspot.com/dynamic_x/bert_pytorch/xvi6icyy/wandb-metadata.json?Expires=1706688636&GoogleAccessId=gorilla-files-url-signer-man%40wandb-production.iam.gserviceaccount.com&Signature=DDf5vt5B92k8FYrTqi6v6Act%2FfsD9m%2BtUVurplBl8LHodFHKovhbdxHYYJR5cFNp8a0AfZ3MCJn%2B5dREN0vhZjZyhcBFwq%2FB505kAYJBPgN5auQm2s2pMgRQ9m66zD%2BCm1H3qJoWOWsEMOfuDUdIgIP%2BepXp4vcXUpixcIB3Ltb6FJSEsBgsWrJ%2FJcEzGMhRvrPmNQ5BA%2B%2BcryyrygOB8Fe7zZ7D6FTKPBZ6WS7miVf5h9Ozal%2Bnniwgqfc%2FrLSYohUljAvr7Nth5H6NDdlHDblgOlmd3WGJwptZK3BteBymjNDdyw2%2FoSas8CR1dyjfOEUtogb6%2FWin3slTGhKezg%3D%3D (Caused by NewConnectionError('<urllib3.connection.HTTPSConnection object at 0x7f5f1c7defd0>: Failed to establish a new connection: [Errno 111] Connection refused'))
2024-01-30 16:31:52,167 ERROR   wandb-upload_0:1134332 [internal_api.py:upload_file():2767] upload_file request headers: {'User-Agent': 'python-requests/2.23.0', 'Accept-Encoding': 'gzip, deflate', 'Accept': '*/*', 'Connection': 'keep-alive', 'Content-Length': '15544'}
2024-01-30 16:31:52,167 ERROR   wandb-upload_0:1134332 [internal_api.py:upload_file():2769] upload_file response body: 
2024-01-30 16:37:20,595 ERROR   wandb-upload_0:1134332 [internal_api.py:upload_file():2765] upload_file exception https://storage.googleapis.com/wandb-production.appspot.com/dynamic_x/bert_pytorch/xvi6icyy/wandb-metadata.json?Expires=1706688636&GoogleAccessId=gorilla-files-url-signer-man%40wandb-production.iam.gserviceaccount.com&Signature=DDf5vt5B92k8FYrTqi6v6Act%2FfsD9m%2BtUVurplBl8LHodFHKovhbdxHYYJR5cFNp8a0AfZ3MCJn%2B5dREN0vhZjZyhcBFwq%2FB505kAYJBPgN5auQm2s2pMgRQ9m66zD%2BCm1H3qJoWOWsEMOfuDUdIgIP%2BepXp4vcXUpixcIB3Ltb6FJSEsBgsWrJ%2FJcEzGMhRvrPmNQ5BA%2B%2BcryyrygOB8Fe7zZ7D6FTKPBZ6WS7miVf5h9Ozal%2Bnniwgqfc%2FrLSYohUljAvr7Nth5H6NDdlHDblgOlmd3WGJwptZK3BteBymjNDdyw2%2FoSas8CR1dyjfOEUtogb6%2FWin3slTGhKezg%3D%3D: HTTPSConnectionPool(host='storage.googleapis.com', port=443): Max retries exceeded with url: /wandb-production.appspot.com/dynamic_x/bert_pytorch/xvi6icyy/wandb-metadata.json?Expires=1706688636&GoogleAccessId=gorilla-files-url-signer-man%40wandb-production.iam.gserviceaccount.com&Signature=DDf5vt5B92k8FYrTqi6v6Act%2FfsD9m%2BtUVurplBl8LHodFHKovhbdxHYYJR5cFNp8a0AfZ3MCJn%2B5dREN0vhZjZyhcBFwq%2FB505kAYJBPgN5auQm2s2pMgRQ9m66zD%2BCm1H3qJoWOWsEMOfuDUdIgIP%2BepXp4vcXUpixcIB3Ltb6FJSEsBgsWrJ%2FJcEzGMhRvrPmNQ5BA%2B%2BcryyrygOB8Fe7zZ7D6FTKPBZ6WS7miVf5h9Ozal%2Bnniwgqfc%2FrLSYohUljAvr7Nth5H6NDdlHDblgOlmd3WGJwptZK3BteBymjNDdyw2%2FoSas8CR1dyjfOEUtogb6%2FWin3slTGhKezg%3D%3D (Caused by NewConnectionError('<urllib3.connection.HTTPSConnection object at 0x7f5f1c7de580>: Failed to establish a new connection: [Errno 111] Connection refused'))
2024-01-30 16:37:20,595 ERROR   wandb-upload_0:1134332 [internal_api.py:upload_file():2767] upload_file request headers: {'User-Agent': 'python-requests/2.23.0', 'Accept-Encoding': 'gzip, deflate', 'Accept': '*/*', 'Connection': 'keep-alive', 'Content-Length': '15544'}
2024-01-30 16:37:20,595 ERROR   wandb-upload_0:1134332 [internal_api.py:upload_file():2769] upload_file response body: 
2024-01-30 16:37:45,975 WARNING StreamThr :1134332 [internal.py:is_dead():414] Internal process exiting, parent pid 1134044 disappeared
2024-01-30 16:37:45,976 ERROR   StreamThr :1134332 [internal.py:wandb_internal():152] Internal process shutdown.
2024-01-30 16:37:46,375 INFO    WriterThread:1134332 [datastore.py:close():296] close: /home/yanxindong/mkor/bert/wandb/run-20240130_161012-xvi6icyy/run-xvi6icyy.wandb
2024-01-30 16:37:46,405 INFO    HandlerThread:1134332 [handler.py:finish():869] shutting down handler
2024-01-30 16:40:33,526 ERROR   wandb-upload_2:1134332 [internal_api.py:upload_file():2765] upload_file exception https://storage.googleapis.com/wandb-artifacts-prod/wandb_artifacts/133981200/707680658/6873c23a2381d1524249eb1a948a45a5?Expires=1706688986&GoogleAccessId=gorilla-files-url-signer-man%40wandb-production.iam.gserviceaccount.com&Signature=jkXXIP9d5i%2FP6fLZLuehv7R75MUWlEuy0JALMLT49xl%2BxBfMMLO0GilsgxfGNnlT6dQ4AoMb6jraXRo51p7Gifj0qeemqu5SmZrovJXsApv4q6R1ryKhBj%2FGrorL7OjfMgoO7usFey3jjg4vvrsxbMEsBa%2FXXB2iKGw3H1Fny4yUMtS7GNPmrgeRnFrBH%2FhaYi4VKu9e4sZXkL7Qcf8bUt%2BGo7OnCRhykEYaqEf3mwFhUJDThowZvvp1Z45hpWnoV1czFn9T%2Fps4o5Ses7mLOZPDU7HoaRR1YXJ1KjbOwC931oXbI3Gjht1%2FC0o61uwRb9z1hvn2rX5Vd1O5kikXlg%3D%3D: HTTPSConnectionPool(host='storage.googleapis.com', port=443): Max retries exceeded with url: /wandb-artifacts-prod/wandb_artifacts/133981200/707680658/6873c23a2381d1524249eb1a948a45a5?Expires=1706688986&GoogleAccessId=gorilla-files-url-signer-man%40wandb-production.iam.gserviceaccount.com&Signature=jkXXIP9d5i%2FP6fLZLuehv7R75MUWlEuy0JALMLT49xl%2BxBfMMLO0GilsgxfGNnlT6dQ4AoMb6jraXRo51p7Gifj0qeemqu5SmZrovJXsApv4q6R1ryKhBj%2FGrorL7OjfMgoO7usFey3jjg4vvrsxbMEsBa%2FXXB2iKGw3H1Fny4yUMtS7GNPmrgeRnFrBH%2FhaYi4VKu9e4sZXkL7Qcf8bUt%2BGo7OnCRhykEYaqEf3mwFhUJDThowZvvp1Z45hpWnoV1czFn9T%2Fps4o5Ses7mLOZPDU7HoaRR1YXJ1KjbOwC931oXbI3Gjht1%2FC0o61uwRb9z1hvn2rX5Vd1O5kikXlg%3D%3D (Caused by NewConnectionError('<urllib3.connection.HTTPSConnection object at 0x7f5f2405e700>: Failed to establish a new connection: [Errno 101] Network is unreachable'))
2024-01-30 16:40:33,526 ERROR   wandb-upload_2:1134332 [internal_api.py:upload_file():2767] upload_file request headers: {'User-Agent': 'python-requests/2.23.0', 'Accept-Encoding': 'gzip, deflate', 'Accept': '*/*', 'Connection': 'keep-alive', 'Content-MD5': 'aHPCOiOB0VJCSesalIpFpQ==', 'Content-Type': 'application/json', 'Content-Length': '609'}
2024-01-30 16:40:33,526 ERROR   wandb-upload_2:1134332 [internal_api.py:upload_file():2769] upload_file response body: 
2024-01-30 16:40:37,622 ERROR   wandb-upload_1:1134332 [internal_api.py:upload_file():2765] upload_file exception https://storage.googleapis.com/wandb-artifacts-prod/wandb_artifacts/133981200/707680658/174a3d9bc61fec126cc7d5bdff5c6c5a?Expires=1706688986&GoogleAccessId=gorilla-files-url-signer-man%40wandb-production.iam.gserviceaccount.com&Signature=lBkj7FRI0vqPgHLx%2BOg7Yx%2BGOVCE4lfpqcS%2ByMrWmpzNtyMXnIEKkckanv1jvH649kkftO%2FY2pGVpnjPUSY%2BP%2Fbqfd3teYO2q6JA%2BRwZqnwibRsNs1wTzHeDxLlx3emDxpU9QGUPD8bpCI%2F8m8flx%2Bp1%2Fn84IlmAAzVnmeDtF4hsL9sld5%2BP4NwiDw3KK8hNzztpYao1SO6uN1dTl0UFdQ7muF9Hzh%2FwypwV03JGmgq10%2BQyr512zR6BzcjlIULUTnlgK2aZIvb2WuEFqLSOXeh0IJ08%2BMP4NJoGbXIWJ%2FqoG2ncCls%2FlNgco0n8TM38P13NXVJMOsK%2FqmhHRLDRlA%3D%3D: HTTPSConnectionPool(host='storage.googleapis.com', port=443): Max retries exceeded with url: /wandb-artifacts-prod/wandb_artifacts/133981200/707680658/174a3d9bc61fec126cc7d5bdff5c6c5a?Expires=1706688986&GoogleAccessId=gorilla-files-url-signer-man%40wandb-production.iam.gserviceaccount.com&Signature=lBkj7FRI0vqPgHLx%2BOg7Yx%2BGOVCE4lfpqcS%2ByMrWmpzNtyMXnIEKkckanv1jvH649kkftO%2FY2pGVpnjPUSY%2BP%2Fbqfd3teYO2q6JA%2BRwZqnwibRsNs1wTzHeDxLlx3emDxpU9QGUPD8bpCI%2F8m8flx%2Bp1%2Fn84IlmAAzVnmeDtF4hsL9sld5%2BP4NwiDw3KK8hNzztpYao1SO6uN1dTl0UFdQ7muF9Hzh%2FwypwV03JGmgq10%2BQyr512zR6BzcjlIULUTnlgK2aZIvb2WuEFqLSOXeh0IJ08%2BMP4NJoGbXIWJ%2FqoG2ncCls%2FlNgco0n8TM38P13NXVJMOsK%2FqmhHRLDRlA%3D%3D (Caused by NewConnectionError('<urllib3.connection.HTTPSConnection object at 0x7f5f1c7f2460>: Failed to establish a new connection: [Errno 101] Network is unreachable'))
2024-01-30 16:40:37,622 ERROR   wandb-upload_1:1134332 [internal_api.py:upload_file():2767] upload_file request headers: {'User-Agent': 'python-requests/2.23.0', 'Accept-Encoding': 'gzip, deflate', 'Accept': '*/*', 'Connection': 'keep-alive', 'Content-MD5': 'F0o9m8Yf7BJsx9W9/1xsWg==', 'Content-Type': 'text/plain; charset=utf-8', 'Content-Length': '2179'}
2024-01-30 16:40:37,622 ERROR   wandb-upload_1:1134332 [internal_api.py:upload_file():2769] upload_file response body: 
2024-01-30 16:43:04,332 ERROR   wandb-upload_1:1134332 [internal_api.py:upload_file():2765] upload_file exception https://storage.googleapis.com/wandb-artifacts-prod/wandb_artifacts/133981200/707680658/174a3d9bc61fec126cc7d5bdff5c6c5a?Expires=1706688986&GoogleAccessId=gorilla-files-url-signer-man%40wandb-production.iam.gserviceaccount.com&Signature=lBkj7FRI0vqPgHLx%2BOg7Yx%2BGOVCE4lfpqcS%2ByMrWmpzNtyMXnIEKkckanv1jvH649kkftO%2FY2pGVpnjPUSY%2BP%2Fbqfd3teYO2q6JA%2BRwZqnwibRsNs1wTzHeDxLlx3emDxpU9QGUPD8bpCI%2F8m8flx%2Bp1%2Fn84IlmAAzVnmeDtF4hsL9sld5%2BP4NwiDw3KK8hNzztpYao1SO6uN1dTl0UFdQ7muF9Hzh%2FwypwV03JGmgq10%2BQyr512zR6BzcjlIULUTnlgK2aZIvb2WuEFqLSOXeh0IJ08%2BMP4NJoGbXIWJ%2FqoG2ncCls%2FlNgco0n8TM38P13NXVJMOsK%2FqmhHRLDRlA%3D%3D: HTTPSConnectionPool(host='storage.googleapis.com', port=443): Max retries exceeded with url: /wandb-artifacts-prod/wandb_artifacts/133981200/707680658/174a3d9bc61fec126cc7d5bdff5c6c5a?Expires=1706688986&GoogleAccessId=gorilla-files-url-signer-man%40wandb-production.iam.gserviceaccount.com&Signature=lBkj7FRI0vqPgHLx%2BOg7Yx%2BGOVCE4lfpqcS%2ByMrWmpzNtyMXnIEKkckanv1jvH649kkftO%2FY2pGVpnjPUSY%2BP%2Fbqfd3teYO2q6JA%2BRwZqnwibRsNs1wTzHeDxLlx3emDxpU9QGUPD8bpCI%2F8m8flx%2Bp1%2Fn84IlmAAzVnmeDtF4hsL9sld5%2BP4NwiDw3KK8hNzztpYao1SO6uN1dTl0UFdQ7muF9Hzh%2FwypwV03JGmgq10%2BQyr512zR6BzcjlIULUTnlgK2aZIvb2WuEFqLSOXeh0IJ08%2BMP4NJoGbXIWJ%2FqoG2ncCls%2FlNgco0n8TM38P13NXVJMOsK%2FqmhHRLDRlA%3D%3D (Caused by NewConnectionError('<urllib3.connection.HTTPSConnection object at 0x7f5f1c7ecac0>: Failed to establish a new connection: [Errno 101] Network is unreachable'))
2024-01-30 16:43:04,332 ERROR   wandb-upload_1:1134332 [internal_api.py:upload_file():2767] upload_file request headers: {'User-Agent': 'python-requests/2.23.0', 'Accept-Encoding': 'gzip, deflate', 'Accept': '*/*', 'Connection': 'keep-alive', 'Content-MD5': 'F0o9m8Yf7BJsx9W9/1xsWg==', 'Content-Type': 'text/plain; charset=utf-8', 'Content-Length': '2179'}
2024-01-30 16:43:04,332 ERROR   wandb-upload_1:1134332 [internal_api.py:upload_file():2769] upload_file response body: 
2024-01-30 16:43:09,811 ERROR   wandb-upload_2:1134332 [internal_api.py:upload_file():2765] upload_file exception https://storage.googleapis.com/wandb-artifacts-prod/wandb_artifacts/133981200/707680658/6873c23a2381d1524249eb1a948a45a5?Expires=1706688986&GoogleAccessId=gorilla-files-url-signer-man%40wandb-production.iam.gserviceaccount.com&Signature=jkXXIP9d5i%2FP6fLZLuehv7R75MUWlEuy0JALMLT49xl%2BxBfMMLO0GilsgxfGNnlT6dQ4AoMb6jraXRo51p7Gifj0qeemqu5SmZrovJXsApv4q6R1ryKhBj%2FGrorL7OjfMgoO7usFey3jjg4vvrsxbMEsBa%2FXXB2iKGw3H1Fny4yUMtS7GNPmrgeRnFrBH%2FhaYi4VKu9e4sZXkL7Qcf8bUt%2BGo7OnCRhykEYaqEf3mwFhUJDThowZvvp1Z45hpWnoV1czFn9T%2Fps4o5Ses7mLOZPDU7HoaRR1YXJ1KjbOwC931oXbI3Gjht1%2FC0o61uwRb9z1hvn2rX5Vd1O5kikXlg%3D%3D: HTTPSConnectionPool(host='storage.googleapis.com', port=443): Max retries exceeded with url: /wandb-artifacts-prod/wandb_artifacts/133981200/707680658/6873c23a2381d1524249eb1a948a45a5?Expires=1706688986&GoogleAccessId=gorilla-files-url-signer-man%40wandb-production.iam.gserviceaccount.com&Signature=jkXXIP9d5i%2FP6fLZLuehv7R75MUWlEuy0JALMLT49xl%2BxBfMMLO0GilsgxfGNnlT6dQ4AoMb6jraXRo51p7Gifj0qeemqu5SmZrovJXsApv4q6R1ryKhBj%2FGrorL7OjfMgoO7usFey3jjg4vvrsxbMEsBa%2FXXB2iKGw3H1Fny4yUMtS7GNPmrgeRnFrBH%2FhaYi4VKu9e4sZXkL7Qcf8bUt%2BGo7OnCRhykEYaqEf3mwFhUJDThowZvvp1Z45hpWnoV1czFn9T%2Fps4o5Ses7mLOZPDU7HoaRR1YXJ1KjbOwC931oXbI3Gjht1%2FC0o61uwRb9z1hvn2rX5Vd1O5kikXlg%3D%3D (Caused by NewConnectionError('<urllib3.connection.HTTPSConnection object at 0x7f5f1c7f22b0>: Failed to establish a new connection: [Errno 101] Network is unreachable'))
2024-01-30 16:43:09,811 ERROR   wandb-upload_2:1134332 [internal_api.py:upload_file():2767] upload_file request headers: {'User-Agent': 'python-requests/2.23.0', 'Accept-Encoding': 'gzip, deflate', 'Accept': '*/*', 'Connection': 'keep-alive', 'Content-MD5': 'aHPCOiOB0VJCSesalIpFpQ==', 'Content-Type': 'application/json', 'Content-Length': '609'}
2024-01-30 16:43:09,811 ERROR   wandb-upload_2:1134332 [internal_api.py:upload_file():2769] upload_file response body: 
2024-01-30 16:43:32,606 ERROR   wandb-upload_0:1134332 [internal_api.py:upload_file():2765] upload_file exception https://storage.googleapis.com/wandb-production.appspot.com/dynamic_x/bert_pytorch/xvi6icyy/wandb-metadata.json?Expires=1706688636&GoogleAccessId=gorilla-files-url-signer-man%40wandb-production.iam.gserviceaccount.com&Signature=DDf5vt5B92k8FYrTqi6v6Act%2FfsD9m%2BtUVurplBl8LHodFHKovhbdxHYYJR5cFNp8a0AfZ3MCJn%2B5dREN0vhZjZyhcBFwq%2FB505kAYJBPgN5auQm2s2pMgRQ9m66zD%2BCm1H3qJoWOWsEMOfuDUdIgIP%2BepXp4vcXUpixcIB3Ltb6FJSEsBgsWrJ%2FJcEzGMhRvrPmNQ5BA%2B%2BcryyrygOB8Fe7zZ7D6FTKPBZ6WS7miVf5h9Ozal%2Bnniwgqfc%2FrLSYohUljAvr7Nth5H6NDdlHDblgOlmd3WGJwptZK3BteBymjNDdyw2%2FoSas8CR1dyjfOEUtogb6%2FWin3slTGhKezg%3D%3D: HTTPSConnectionPool(host='storage.googleapis.com', port=443): Max retries exceeded with url: /wandb-production.appspot.com/dynamic_x/bert_pytorch/xvi6icyy/wandb-metadata.json?Expires=1706688636&GoogleAccessId=gorilla-files-url-signer-man%40wandb-production.iam.gserviceaccount.com&Signature=DDf5vt5B92k8FYrTqi6v6Act%2FfsD9m%2BtUVurplBl8LHodFHKovhbdxHYYJR5cFNp8a0AfZ3MCJn%2B5dREN0vhZjZyhcBFwq%2FB505kAYJBPgN5auQm2s2pMgRQ9m66zD%2BCm1H3qJoWOWsEMOfuDUdIgIP%2BepXp4vcXUpixcIB3Ltb6FJSEsBgsWrJ%2FJcEzGMhRvrPmNQ5BA%2B%2BcryyrygOB8Fe7zZ7D6FTKPBZ6WS7miVf5h9Ozal%2Bnniwgqfc%2FrLSYohUljAvr7Nth5H6NDdlHDblgOlmd3WGJwptZK3BteBymjNDdyw2%2FoSas8CR1dyjfOEUtogb6%2FWin3slTGhKezg%3D%3D (Caused by NewConnectionError('<urllib3.connection.HTTPSConnection object at 0x7f5f1c7e7640>: Failed to establish a new connection: [Errno 101] Network is unreachable'))
2024-01-30 16:43:32,606 ERROR   wandb-upload_0:1134332 [internal_api.py:upload_file():2767] upload_file request headers: {'User-Agent': 'python-requests/2.23.0', 'Accept-Encoding': 'gzip, deflate', 'Accept': '*/*', 'Connection': 'keep-alive', 'Content-Length': '15544'}
2024-01-30 16:43:32,606 ERROR   wandb-upload_0:1134332 [internal_api.py:upload_file():2769] upload_file response body: 
2024-01-30 17:12:22,262 ERROR   wandb-upload_1:1134332 [internal_api.py:upload_file():2765] upload_file exception https://storage.googleapis.com/wandb-artifacts-prod/wandb_artifacts/133981200/707680658/174a3d9bc61fec126cc7d5bdff5c6c5a?Expires=1706688986&GoogleAccessId=gorilla-files-url-signer-man%40wandb-production.iam.gserviceaccount.com&Signature=lBkj7FRI0vqPgHLx%2BOg7Yx%2BGOVCE4lfpqcS%2ByMrWmpzNtyMXnIEKkckanv1jvH649kkftO%2FY2pGVpnjPUSY%2BP%2Fbqfd3teYO2q6JA%2BRwZqnwibRsNs1wTzHeDxLlx3emDxpU9QGUPD8bpCI%2F8m8flx%2Bp1%2Fn84IlmAAzVnmeDtF4hsL9sld5%2BP4NwiDw3KK8hNzztpYao1SO6uN1dTl0UFdQ7muF9Hzh%2FwypwV03JGmgq10%2BQyr512zR6BzcjlIULUTnlgK2aZIvb2WuEFqLSOXeh0IJ08%2BMP4NJoGbXIWJ%2FqoG2ncCls%2FlNgco0n8TM38P13NXVJMOsK%2FqmhHRLDRlA%3D%3D: HTTPSConnectionPool(host='storage.googleapis.com', port=443): Max retries exceeded with url: /wandb-artifacts-prod/wandb_artifacts/133981200/707680658/174a3d9bc61fec126cc7d5bdff5c6c5a?Expires=1706688986&GoogleAccessId=gorilla-files-url-signer-man%40wandb-production.iam.gserviceaccount.com&Signature=lBkj7FRI0vqPgHLx%2BOg7Yx%2BGOVCE4lfpqcS%2ByMrWmpzNtyMXnIEKkckanv1jvH649kkftO%2FY2pGVpnjPUSY%2BP%2Fbqfd3teYO2q6JA%2BRwZqnwibRsNs1wTzHeDxLlx3emDxpU9QGUPD8bpCI%2F8m8flx%2Bp1%2Fn84IlmAAzVnmeDtF4hsL9sld5%2BP4NwiDw3KK8hNzztpYao1SO6uN1dTl0UFdQ7muF9Hzh%2FwypwV03JGmgq10%2BQyr512zR6BzcjlIULUTnlgK2aZIvb2WuEFqLSOXeh0IJ08%2BMP4NJoGbXIWJ%2FqoG2ncCls%2FlNgco0n8TM38P13NXVJMOsK%2FqmhHRLDRlA%3D%3D (Caused by NewConnectionError('<urllib3.connection.HTTPSConnection object at 0x7f5f1c7da520>: Failed to establish a new connection: [Errno 110] Connection timed out'))
2024-01-30 17:12:22,262 ERROR   wandb-upload_1:1134332 [internal_api.py:upload_file():2767] upload_file request headers: {'User-Agent': 'python-requests/2.23.0', 'Accept-Encoding': 'gzip, deflate', 'Accept': '*/*', 'Connection': 'keep-alive', 'Content-MD5': 'F0o9m8Yf7BJsx9W9/1xsWg==', 'Content-Type': 'text/plain; charset=utf-8', 'Content-Length': '2179'}
2024-01-30 17:12:22,262 ERROR   wandb-upload_1:1134332 [internal_api.py:upload_file():2769] upload_file response body: 
2024-01-30 17:12:26,358 ERROR   wandb-upload_2:1134332 [internal_api.py:upload_file():2765] upload_file exception https://storage.googleapis.com/wandb-artifacts-prod/wandb_artifacts/133981200/707680658/6873c23a2381d1524249eb1a948a45a5?Expires=1706688986&GoogleAccessId=gorilla-files-url-signer-man%40wandb-production.iam.gserviceaccount.com&Signature=jkXXIP9d5i%2FP6fLZLuehv7R75MUWlEuy0JALMLT49xl%2BxBfMMLO0GilsgxfGNnlT6dQ4AoMb6jraXRo51p7Gifj0qeemqu5SmZrovJXsApv4q6R1ryKhBj%2FGrorL7OjfMgoO7usFey3jjg4vvrsxbMEsBa%2FXXB2iKGw3H1Fny4yUMtS7GNPmrgeRnFrBH%2FhaYi4VKu9e4sZXkL7Qcf8bUt%2BGo7OnCRhykEYaqEf3mwFhUJDThowZvvp1Z45hpWnoV1czFn9T%2Fps4o5Ses7mLOZPDU7HoaRR1YXJ1KjbOwC931oXbI3Gjht1%2FC0o61uwRb9z1hvn2rX5Vd1O5kikXlg%3D%3D: HTTPSConnectionPool(host='storage.googleapis.com', port=443): Max retries exceeded with url: /wandb-artifacts-prod/wandb_artifacts/133981200/707680658/6873c23a2381d1524249eb1a948a45a5?Expires=1706688986&GoogleAccessId=gorilla-files-url-signer-man%40wandb-production.iam.gserviceaccount.com&Signature=jkXXIP9d5i%2FP6fLZLuehv7R75MUWlEuy0JALMLT49xl%2BxBfMMLO0GilsgxfGNnlT6dQ4AoMb6jraXRo51p7Gifj0qeemqu5SmZrovJXsApv4q6R1ryKhBj%2FGrorL7OjfMgoO7usFey3jjg4vvrsxbMEsBa%2FXXB2iKGw3H1Fny4yUMtS7GNPmrgeRnFrBH%2FhaYi4VKu9e4sZXkL7Qcf8bUt%2BGo7OnCRhykEYaqEf3mwFhUJDThowZvvp1Z45hpWnoV1czFn9T%2Fps4o5Ses7mLOZPDU7HoaRR1YXJ1KjbOwC931oXbI3Gjht1%2FC0o61uwRb9z1hvn2rX5Vd1O5kikXlg%3D%3D (Caused by NewConnectionError('<urllib3.connection.HTTPSConnection object at 0x7f5f1c7dfc10>: Failed to establish a new connection: [Errno 110] Connection timed out'))
2024-01-30 17:12:26,358 ERROR   wandb-upload_2:1134332 [internal_api.py:upload_file():2767] upload_file request headers: {'User-Agent': 'python-requests/2.23.0', 'Accept-Encoding': 'gzip, deflate', 'Accept': '*/*', 'Connection': 'keep-alive', 'Content-MD5': 'aHPCOiOB0VJCSesalIpFpQ==', 'Content-Type': 'application/json', 'Content-Length': '609'}
2024-01-30 17:12:26,358 ERROR   wandb-upload_2:1134332 [internal_api.py:upload_file():2769] upload_file response body: 
2024-01-30 17:13:05,270 ERROR   wandb-upload_0:1134332 [internal_api.py:upload_file():2765] upload_file exception https://storage.googleapis.com/wandb-production.appspot.com/dynamic_x/bert_pytorch/xvi6icyy/wandb-metadata.json?Expires=1706688636&GoogleAccessId=gorilla-files-url-signer-man%40wandb-production.iam.gserviceaccount.com&Signature=DDf5vt5B92k8FYrTqi6v6Act%2FfsD9m%2BtUVurplBl8LHodFHKovhbdxHYYJR5cFNp8a0AfZ3MCJn%2B5dREN0vhZjZyhcBFwq%2FB505kAYJBPgN5auQm2s2pMgRQ9m66zD%2BCm1H3qJoWOWsEMOfuDUdIgIP%2BepXp4vcXUpixcIB3Ltb6FJSEsBgsWrJ%2FJcEzGMhRvrPmNQ5BA%2B%2BcryyrygOB8Fe7zZ7D6FTKPBZ6WS7miVf5h9Ozal%2Bnniwgqfc%2FrLSYohUljAvr7Nth5H6NDdlHDblgOlmd3WGJwptZK3BteBymjNDdyw2%2FoSas8CR1dyjfOEUtogb6%2FWin3slTGhKezg%3D%3D: HTTPSConnectionPool(host='storage.googleapis.com', port=443): Max retries exceeded with url: /wandb-production.appspot.com/dynamic_x/bert_pytorch/xvi6icyy/wandb-metadata.json?Expires=1706688636&GoogleAccessId=gorilla-files-url-signer-man%40wandb-production.iam.gserviceaccount.com&Signature=DDf5vt5B92k8FYrTqi6v6Act%2FfsD9m%2BtUVurplBl8LHodFHKovhbdxHYYJR5cFNp8a0AfZ3MCJn%2B5dREN0vhZjZyhcBFwq%2FB505kAYJBPgN5auQm2s2pMgRQ9m66zD%2BCm1H3qJoWOWsEMOfuDUdIgIP%2BepXp4vcXUpixcIB3Ltb6FJSEsBgsWrJ%2FJcEzGMhRvrPmNQ5BA%2B%2BcryyrygOB8Fe7zZ7D6FTKPBZ6WS7miVf5h9Ozal%2Bnniwgqfc%2FrLSYohUljAvr7Nth5H6NDdlHDblgOlmd3WGJwptZK3BteBymjNDdyw2%2FoSas8CR1dyjfOEUtogb6%2FWin3slTGhKezg%3D%3D (Caused by NewConnectionError('<urllib3.connection.HTTPSConnection object at 0x7f5f1c7e7eb0>: Failed to establish a new connection: [Errno 110] Connection timed out'))
2024-01-30 17:13:05,270 ERROR   wandb-upload_0:1134332 [internal_api.py:upload_file():2767] upload_file request headers: {'User-Agent': 'python-requests/2.23.0', 'Accept-Encoding': 'gzip, deflate', 'Accept': '*/*', 'Connection': 'keep-alive', 'Content-Length': '15544'}
2024-01-30 17:13:05,270 ERROR   wandb-upload_0:1134332 [internal_api.py:upload_file():2769] upload_file response body: 
2024-01-30 17:17:57,259 ERROR   wandb-upload_1:1134332 [internal_api.py:upload_file():2765] upload_file exception https://storage.googleapis.com/wandb-artifacts-prod/wandb_artifacts/133981200/707680658/174a3d9bc61fec126cc7d5bdff5c6c5a?Expires=1706688986&GoogleAccessId=gorilla-files-url-signer-man%40wandb-production.iam.gserviceaccount.com&Signature=lBkj7FRI0vqPgHLx%2BOg7Yx%2BGOVCE4lfpqcS%2ByMrWmpzNtyMXnIEKkckanv1jvH649kkftO%2FY2pGVpnjPUSY%2BP%2Fbqfd3teYO2q6JA%2BRwZqnwibRsNs1wTzHeDxLlx3emDxpU9QGUPD8bpCI%2F8m8flx%2Bp1%2Fn84IlmAAzVnmeDtF4hsL9sld5%2BP4NwiDw3KK8hNzztpYao1SO6uN1dTl0UFdQ7muF9Hzh%2FwypwV03JGmgq10%2BQyr512zR6BzcjlIULUTnlgK2aZIvb2WuEFqLSOXeh0IJ08%2BMP4NJoGbXIWJ%2FqoG2ncCls%2FlNgco0n8TM38P13NXVJMOsK%2FqmhHRLDRlA%3D%3D: HTTPSConnectionPool(host='storage.googleapis.com', port=443): Max retries exceeded with url: /wandb-artifacts-prod/wandb_artifacts/133981200/707680658/174a3d9bc61fec126cc7d5bdff5c6c5a?Expires=1706688986&GoogleAccessId=gorilla-files-url-signer-man%40wandb-production.iam.gserviceaccount.com&Signature=lBkj7FRI0vqPgHLx%2BOg7Yx%2BGOVCE4lfpqcS%2ByMrWmpzNtyMXnIEKkckanv1jvH649kkftO%2FY2pGVpnjPUSY%2BP%2Fbqfd3teYO2q6JA%2BRwZqnwibRsNs1wTzHeDxLlx3emDxpU9QGUPD8bpCI%2F8m8flx%2Bp1%2Fn84IlmAAzVnmeDtF4hsL9sld5%2BP4NwiDw3KK8hNzztpYao1SO6uN1dTl0UFdQ7muF9Hzh%2FwypwV03JGmgq10%2BQyr512zR6BzcjlIULUTnlgK2aZIvb2WuEFqLSOXeh0IJ08%2BMP4NJoGbXIWJ%2FqoG2ncCls%2FlNgco0n8TM38P13NXVJMOsK%2FqmhHRLDRlA%3D%3D (Caused by NewConnectionError('<urllib3.connection.HTTPSConnection object at 0x7f5f1c7e7f40>: Failed to establish a new connection: [Errno 101] Network is unreachable'))
2024-01-30 17:17:57,259 ERROR   wandb-upload_1:1134332 [internal_api.py:upload_file():2767] upload_file request headers: {'User-Agent': 'python-requests/2.23.0', 'Accept-Encoding': 'gzip, deflate', 'Accept': '*/*', 'Connection': 'keep-alive', 'Content-MD5': 'F0o9m8Yf7BJsx9W9/1xsWg==', 'Content-Type': 'text/plain; charset=utf-8', 'Content-Length': '2179'}
2024-01-30 17:17:57,259 ERROR   wandb-upload_1:1134332 [internal_api.py:upload_file():2769] upload_file response body: 
2024-01-30 17:18:14,392 ERROR   wandb-upload_2:1134332 [internal_api.py:upload_file():2765] upload_file exception https://storage.googleapis.com/wandb-artifacts-prod/wandb_artifacts/133981200/707680658/6873c23a2381d1524249eb1a948a45a5?Expires=1706688986&GoogleAccessId=gorilla-files-url-signer-man%40wandb-production.iam.gserviceaccount.com&Signature=jkXXIP9d5i%2FP6fLZLuehv7R75MUWlEuy0JALMLT49xl%2BxBfMMLO0GilsgxfGNnlT6dQ4AoMb6jraXRo51p7Gifj0qeemqu5SmZrovJXsApv4q6R1ryKhBj%2FGrorL7OjfMgoO7usFey3jjg4vvrsxbMEsBa%2FXXB2iKGw3H1Fny4yUMtS7GNPmrgeRnFrBH%2FhaYi4VKu9e4sZXkL7Qcf8bUt%2BGo7OnCRhykEYaqEf3mwFhUJDThowZvvp1Z45hpWnoV1czFn9T%2Fps4o5Ses7mLOZPDU7HoaRR1YXJ1KjbOwC931oXbI3Gjht1%2FC0o61uwRb9z1hvn2rX5Vd1O5kikXlg%3D%3D: HTTPSConnectionPool(host='storage.googleapis.com', port=443): Max retries exceeded with url: /wandb-artifacts-prod/wandb_artifacts/133981200/707680658/6873c23a2381d1524249eb1a948a45a5?Expires=1706688986&GoogleAccessId=gorilla-files-url-signer-man%40wandb-production.iam.gserviceaccount.com&Signature=jkXXIP9d5i%2FP6fLZLuehv7R75MUWlEuy0JALMLT49xl%2BxBfMMLO0GilsgxfGNnlT6dQ4AoMb6jraXRo51p7Gifj0qeemqu5SmZrovJXsApv4q6R1ryKhBj%2FGrorL7OjfMgoO7usFey3jjg4vvrsxbMEsBa%2FXXB2iKGw3H1Fny4yUMtS7GNPmrgeRnFrBH%2FhaYi4VKu9e4sZXkL7Qcf8bUt%2BGo7OnCRhykEYaqEf3mwFhUJDThowZvvp1Z45hpWnoV1czFn9T%2Fps4o5Ses7mLOZPDU7HoaRR1YXJ1KjbOwC931oXbI3Gjht1%2FC0o61uwRb9z1hvn2rX5Vd1O5kikXlg%3D%3D (Caused by NewConnectionError('<urllib3.connection.HTTPSConnection object at 0x7f5f1c7dec70>: Failed to establish a new connection: [Errno 101] Network is unreachable'))
2024-01-30 17:18:14,393 ERROR   wandb-upload_2:1134332 [internal_api.py:upload_file():2767] upload_file request headers: {'User-Agent': 'python-requests/2.23.0', 'Accept-Encoding': 'gzip, deflate', 'Accept': '*/*', 'Connection': 'keep-alive', 'Content-MD5': 'aHPCOiOB0VJCSesalIpFpQ==', 'Content-Type': 'application/json', 'Content-Length': '609'}
2024-01-30 17:18:14,393 ERROR   wandb-upload_2:1134332 [internal_api.py:upload_file():2769] upload_file response body: 
2024-01-30 17:19:07,401 ERROR   wandb-upload_0:1134332 [internal_api.py:upload_file():2765] upload_file exception https://storage.googleapis.com/wandb-production.appspot.com/dynamic_x/bert_pytorch/xvi6icyy/wandb-metadata.json?Expires=1706688636&GoogleAccessId=gorilla-files-url-signer-man%40wandb-production.iam.gserviceaccount.com&Signature=DDf5vt5B92k8FYrTqi6v6Act%2FfsD9m%2BtUVurplBl8LHodFHKovhbdxHYYJR5cFNp8a0AfZ3MCJn%2B5dREN0vhZjZyhcBFwq%2FB505kAYJBPgN5auQm2s2pMgRQ9m66zD%2BCm1H3qJoWOWsEMOfuDUdIgIP%2BepXp4vcXUpixcIB3Ltb6FJSEsBgsWrJ%2FJcEzGMhRvrPmNQ5BA%2B%2BcryyrygOB8Fe7zZ7D6FTKPBZ6WS7miVf5h9Ozal%2Bnniwgqfc%2FrLSYohUljAvr7Nth5H6NDdlHDblgOlmd3WGJwptZK3BteBymjNDdyw2%2FoSas8CR1dyjfOEUtogb6%2FWin3slTGhKezg%3D%3D: HTTPSConnectionPool(host='storage.googleapis.com', port=443): Max retries exceeded with url: /wandb-production.appspot.com/dynamic_x/bert_pytorch/xvi6icyy/wandb-metadata.json?Expires=1706688636&GoogleAccessId=gorilla-files-url-signer-man%40wandb-production.iam.gserviceaccount.com&Signature=DDf5vt5B92k8FYrTqi6v6Act%2FfsD9m%2BtUVurplBl8LHodFHKovhbdxHYYJR5cFNp8a0AfZ3MCJn%2B5dREN0vhZjZyhcBFwq%2FB505kAYJBPgN5auQm2s2pMgRQ9m66zD%2BCm1H3qJoWOWsEMOfuDUdIgIP%2BepXp4vcXUpixcIB3Ltb6FJSEsBgsWrJ%2FJcEzGMhRvrPmNQ5BA%2B%2BcryyrygOB8Fe7zZ7D6FTKPBZ6WS7miVf5h9Ozal%2Bnniwgqfc%2FrLSYohUljAvr7Nth5H6NDdlHDblgOlmd3WGJwptZK3BteBymjNDdyw2%2FoSas8CR1dyjfOEUtogb6%2FWin3slTGhKezg%3D%3D (Caused by NewConnectionError('<urllib3.connection.HTTPSConnection object at 0x7f5f1c7f2a00>: Failed to establish a new connection: [Errno 111] Connection refused'))
2024-01-30 17:19:07,401 ERROR   wandb-upload_0:1134332 [internal_api.py:upload_file():2767] upload_file request headers: {'User-Agent': 'python-requests/2.23.0', 'Accept-Encoding': 'gzip, deflate', 'Accept': '*/*', 'Connection': 'keep-alive', 'Content-Length': '15544'}
2024-01-30 17:19:07,401 ERROR   wandb-upload_0:1134332 [internal_api.py:upload_file():2769] upload_file response body: 
2024-01-30 17:23:38,287 INFO    wandb-upload_2:1134332 [upload_job.py:push():89] Uploaded file /home/yanxindong/.local/share/wandb/artifacts/staging/tmpq_7l66ev
2024-01-30 17:23:51,345 INFO    wandb-upload_1:1134332 [upload_job.py:push():89] Uploaded file /home/yanxindong/.local/share/wandb/artifacts/staging/tmpd38et3jm
2024-01-30 17:23:54,592 INFO    SenderThread:1134332 [sender.py:send_artifact():1494] sent artifact job-https___github.com_kkkjj-d_mkor.git_bert_run_pretraining.py - {'id': 'QXJ0aWZhY3Q6NzA3NjgwNjU4', 'state': 'PENDING', 'artifactSequence': {'id': 'QXJ0aWZhY3RDb2xsZWN0aW9uOjEzMzk4MTIwMA==', 'latestArtifact': {'id': 'QXJ0aWZhY3Q6NzAzOTc3Mjk3', 'versionIndex': 8}}}
2024-01-30 17:23:54,592 INFO    SenderThread:1134332 [sender.py:finish():1572] shutting down sender
2024-01-30 17:23:54,592 INFO    SenderThread:1134332 [dir_watcher.py:finish():358] shutting down directory watcher
2024-01-30 17:23:55,176 INFO    SenderThread:1134332 [dir_watcher.py:finish():388] scan: /home/yanxindong/mkor/bert/wandb/run-20240130_161012-xvi6icyy/files
2024-01-30 17:23:55,176 INFO    SenderThread:1134332 [dir_watcher.py:finish():402] scan save: /home/yanxindong/mkor/bert/wandb/run-20240130_161012-xvi6icyy/files/wandb-summary.json wandb-summary.json
2024-01-30 17:23:55,177 INFO    SenderThread:1134332 [dir_watcher.py:finish():402] scan save: /home/yanxindong/mkor/bert/wandb/run-20240130_161012-xvi6icyy/files/conda-environment.yaml conda-environment.yaml
2024-01-30 17:23:55,177 INFO    SenderThread:1134332 [dir_watcher.py:finish():402] scan save: /home/yanxindong/mkor/bert/wandb/run-20240130_161012-xvi6icyy/files/wandb-metadata.json wandb-metadata.json
2024-01-30 17:23:55,178 INFO    SenderThread:1134332 [dir_watcher.py:finish():402] scan save: /home/yanxindong/mkor/bert/wandb/run-20240130_161012-xvi6icyy/files/output.log output.log
2024-01-30 17:23:55,181 INFO    SenderThread:1134332 [dir_watcher.py:finish():402] scan save: /home/yanxindong/mkor/bert/wandb/run-20240130_161012-xvi6icyy/files/requirements.txt requirements.txt
2024-01-30 17:23:55,185 INFO    SenderThread:1134332 [dir_watcher.py:finish():402] scan save: /home/yanxindong/mkor/bert/wandb/run-20240130_161012-xvi6icyy/files/config.yaml config.yaml
2024-01-30 17:23:55,185 INFO    SenderThread:1134332 [file_pusher.py:finish():175] shutting down file pusher
2024-01-30 17:23:55,189 INFO    SenderThread:1134332 [file_pusher.py:join():181] waiting for file pusher
2024-01-30 17:23:55,777 INFO    wandb-upload_2:1134332 [upload_job.py:push():131] Uploaded file /home/yanxindong/mkor/bert/wandb/run-20240130_161012-xvi6icyy/files/wandb-summary.json
2024-01-30 17:23:56,191 INFO    wandb-upload_4:1134332 [upload_job.py:push():131] Uploaded file /home/yanxindong/mkor/bert/wandb/run-20240130_161012-xvi6icyy/files/requirements.txt
2024-01-30 17:23:56,200 INFO    wandb-upload_5:1134332 [upload_job.py:push():131] Uploaded file /home/yanxindong/mkor/bert/wandb/run-20240130_161012-xvi6icyy/files/config.yaml
2024-01-30 17:23:56,320 INFO    wandb-upload_3:1134332 [upload_job.py:push():131] Uploaded file /home/yanxindong/mkor/bert/wandb/run-20240130_161012-xvi6icyy/files/output.log
2024-01-30 17:23:57,068 INFO    wandb-upload_1:1134332 [upload_job.py:push():131] Uploaded file /home/yanxindong/mkor/bert/wandb/run-20240130_161012-xvi6icyy/files/conda-environment.yaml
2024-01-30 17:24:57,661 INFO    wandb-upload_0:1134332 [upload_job.py:push():131] Uploaded file /tmp/tmpjcxmnx17wandb/ic10f3zn-wandb-metadata.json
2024-01-30 17:24:58,260 INFO    SenderThread:1134332 [file_stream.py:finish():595] file stream finish called
2024-01-30 17:24:58,538 INFO    SenderThread:1134332 [file_stream.py:finish():599] file stream finish is done
