2024-01-30 16:10:12,352 INFO    StreamThr :1134336 [internal.py:wandb_internal():86] W&B internal server running at pid: 1134336, started at: 2024-01-30 16:10:12.351449
2024-01-30 16:10:12,354 DEBUG   HandlerThread:1134336 [handler.py:handle_request():146] handle_request: status
2024-01-30 16:10:12,355 INFO    WriterThread:1134336 [datastore.py:open_for_write():87] open: /home/yanxindong/mkor/bert/wandb/run-20240130_161012-b793ft22/run-b793ft22.wandb
2024-01-30 16:10:12,355 DEBUG   SenderThread:1134336 [sender.py:send():382] send: header
2024-01-30 16:10:12,363 DEBUG   SenderThread:1134336 [sender.py:send():382] send: run
2024-01-30 16:10:13,650 DEBUG   HandlerThread:1134336 [handler.py:handle_request():146] handle_request: check_version
2024-01-30 16:10:13,652 INFO    SenderThread:1134336 [dir_watcher.py:__init__():211] watching files in: /home/yanxindong/mkor/bert/wandb/run-20240130_161012-b793ft22/files
2024-01-30 16:10:13,652 INFO    SenderThread:1134336 [sender.py:_start_run_threads():1136] run started: b793ft22 with start time 1706602212.351574
2024-01-30 16:10:13,652 DEBUG   SenderThread:1134336 [sender.py:send_request():409] send_request: check_version
2024-01-30 16:10:14,580 DEBUG   HandlerThread:1134336 [handler.py:handle_request():146] handle_request: run_start
2024-01-30 16:10:14,589 DEBUG   HandlerThread:1134336 [system_info.py:__init__():27] System info init
2024-01-30 16:10:14,589 DEBUG   HandlerThread:1134336 [system_info.py:__init__():42] System info init done
2024-01-30 16:10:14,589 INFO    HandlerThread:1134336 [system_monitor.py:start():194] Starting system monitor
2024-01-30 16:10:14,589 INFO    SystemMonitor:1134336 [system_monitor.py:_start():158] Starting system asset monitoring threads
2024-01-30 16:10:14,589 INFO    HandlerThread:1134336 [system_monitor.py:probe():214] Collecting system info
2024-01-30 16:10:14,590 INFO    SystemMonitor:1134336 [interfaces.py:start():190] Started cpu monitoring
2024-01-30 16:10:14,591 INFO    SystemMonitor:1134336 [interfaces.py:start():190] Started disk monitoring
2024-01-30 16:10:14,594 INFO    SystemMonitor:1134336 [interfaces.py:start():190] Started gpu monitoring
2024-01-30 16:10:14,596 INFO    SystemMonitor:1134336 [interfaces.py:start():190] Started memory monitoring
2024-01-30 16:10:14,597 INFO    SystemMonitor:1134336 [interfaces.py:start():190] Started network monitoring
2024-01-30 16:10:14,660 DEBUG   HandlerThread:1134336 [system_info.py:probe():151] Probing system
2024-01-30 16:10:14,665 DEBUG   HandlerThread:1134336 [system_info.py:_probe_git():136] Probing git
2024-01-30 16:10:14,674 DEBUG   HandlerThread:1134336 [system_info.py:_probe_git():144] Probing git done
2024-01-30 16:10:14,675 DEBUG   HandlerThread:1134336 [system_info.py:probe():199] Probing system done
2024-01-30 16:10:14,675 DEBUG   HandlerThread:1134336 [system_monitor.py:probe():223] {'os': 'Linux-5.15.0-92-generic-x86_64-with-glibc2.17', 'python': '3.8.17', 'heartbeatAt': '2024-01-30T08:10:14.660720', 'startedAt': '2024-01-30T08:10:12.343631', 'docker': None, 'cuda': None, 'args': ('--local_rank=3', '--config_file', 'config/bert_pretraining_phase2_config.json', '--input_dir', '/home/yanxindong/mkor/bert/data/encoded/sequences_lowercase_max_seq_len_512_next_seq_task_true', '--output_dir', 'results/adam', '--weight_decay', '0.01', '--num_steps_per_checkpoint', '200'), 'state': 'running', 'program': 'run_pretraining.py', 'codePathLocal': 'run_pretraining.py', 'codePath': 'bert/run_pretraining.py', 'git': {'remote': 'https://github.com/kkkjj-d/mkor.git', 'commit': 'efe99e84fef5594780cfb1df6d6a1f61da4ebba0'}, 'email': '1262670315@qq.com', 'root': '/home/yanxindong/mkor', 'host': 'a6000-X640-G40', 'username': 'yanxindong', 'executable': '/home/yanxindong/anaconda/envs/eva/bin/python', 'cpu_count': 64, 'cpu_count_logical': 128, 'cpu_freq': {'current': 851.857859375, 'min': 800.0, 'max': 3400.0}, 'cpu_freq_per_core': [{'current': 3400.0, 'min': 800.0, 'max': 3400.0}, {'current': 800.0, 'min': 800.0, 'max': 3400.0}, {'current': 800.0, 'min': 800.0, 'max': 3400.0}, {'current': 800.0, 'min': 800.0, 'max': 3400.0}, {'current': 800.0, 'min': 800.0, 'max': 3400.0}, {'current': 800.0, 'min': 800.0, 'max': 3400.0}, {'current': 800.0, 'min': 800.0, 'max': 3400.0}, {'current': 800.0, 'min': 800.0, 'max': 3400.0}, {'current': 900.0, 'min': 800.0, 'max': 3400.0}, {'current': 800.0, 'min': 800.0, 'max': 3400.0}, {'current': 800.0, 'min': 800.0, 'max': 3400.0}, {'current': 800.0, 'min': 800.0, 'max': 3400.0}, {'current': 800.0, 'min': 800.0, 'max': 3400.0}, {'current': 800.0, 'min': 800.0, 'max': 3400.0}, {'current': 800.0, 'min': 800.0, 'max': 3400.0}, {'current': 800.0, 'min': 800.0, 'max': 3400.0}, {'current': 800.0, 'min': 800.0, 'max': 3400.0}, {'current': 800.0, 'min': 800.0, 'max': 3400.0}, {'current': 900.0, 'min': 800.0, 'max': 3400.0}, {'current': 800.0, 'min': 800.0, 'max': 3400.0}, {'current': 800.0, 'min': 800.0, 'max': 3400.0}, {'current': 800.0, 'min': 800.0, 'max': 3400.0}, {'current': 800.0, 'min': 800.0, 'max': 3400.0}, {'current': 800.0, 'min': 800.0, 'max': 3400.0}, {'current': 800.0, 'min': 800.0, 'max': 3400.0}, {'current': 800.0, 'min': 800.0, 'max': 3400.0}, {'current': 800.0, 'min': 800.0, 'max': 3400.0}, {'current': 800.0, 'min': 800.0, 'max': 3400.0}, {'current': 800.0, 'min': 800.0, 'max': 3400.0}, {'current': 800.0, 'min': 800.0, 'max': 3400.0}, {'current': 800.0, 'min': 800.0, 'max': 3400.0}, {'current': 1300.0, 'min': 800.0, 'max': 3400.0}, {'current': 800.0, 'min': 800.0, 'max': 3400.0}, {'current': 800.0, 'min': 800.0, 'max': 3400.0}, {'current': 1300.0, 'min': 800.0, 'max': 3400.0}, {'current': 800.0, 'min': 800.0, 'max': 3400.0}, {'current': 800.0, 'min': 800.0, 'max': 3400.0}, {'current': 800.0, 'min': 800.0, 'max': 3400.0}, {'current': 800.0, 'min': 800.0, 'max': 3400.0}, {'current': 800.0, 'min': 800.0, 'max': 3400.0}, {'current': 800.0, 'min': 800.0, 'max': 3400.0}, {'current': 800.0, 'min': 800.0, 'max': 3400.0}, {'current': 800.0, 'min': 800.0, 'max': 3400.0}, {'current': 800.0, 'min': 800.0, 'max': 3400.0}, {'current': 800.0, 'min': 800.0, 'max': 3400.0}, {'current': 800.0, 'min': 800.0, 'max': 3400.0}, {'current': 800.0, 'min': 800.0, 'max': 3400.0}, {'current': 800.0, 'min': 800.0, 'max': 3400.0}, {'current': 800.0, 'min': 800.0, 'max': 3400.0}, {'current': 800.0, 'min': 800.0, 'max': 3400.0}, {'current': 800.0, 'min': 800.0, 'max': 3400.0}, {'current': 1000.0, 'min': 800.0, 'max': 3400.0}, {'current': 800.0, 'min': 800.0, 'max': 3400.0}, {'current': 800.0, 'min': 800.0, 'max': 3400.0}, {'current': 800.0, 'min': 800.0, 'max': 3400.0}, {'current': 800.0, 'min': 800.0, 'max': 3400.0}, {'current': 800.0, 'min': 800.0, 'max': 3400.0}, {'current': 800.0, 'min': 800.0, 'max': 3400.0}, {'current': 800.0, 'min': 800.0, 'max': 3400.0}, {'current': 800.0, 'min': 800.0, 'max': 3400.0}, {'current': 800.0, 'min': 800.0, 'max': 3400.0}, {'current': 800.0, 'min': 800.0, 'max': 3400.0}, {'current': 800.0, 'min': 800.0, 'max': 3400.0}, {'current': 800.0, 'min': 800.0, 'max': 3400.0}, {'current': 3300.001, 'min': 800.0, 'max': 3400.0}, {'current': 800.0, 'min': 800.0, 'max': 3400.0}, {'current': 800.0, 'min': 800.0, 'max': 3400.0}, {'current': 800.0, 'min': 800.0, 'max': 3400.0}, {'current': 800.0, 'min': 800.0, 'max': 3400.0}, {'current': 800.0, 'min': 800.0, 'max': 3400.0}, {'current': 800.0, 'min': 800.0, 'max': 3400.0}, {'current': 800.0, 'min': 800.0, 'max': 3400.0}, {'current': 800.0, 'min': 800.0, 'max': 3400.0}, {'current': 800.0, 'min': 800.0, 'max': 3400.0}, {'current': 800.0, 'min': 800.0, 'max': 3400.0}, {'current': 800.0, 'min': 800.0, 'max': 3400.0}, {'current': 800.0, 'min': 800.0, 'max': 3400.0}, {'current': 800.0, 'min': 800.0, 'max': 3400.0}, {'current': 800.0, 'min': 800.0, 'max': 3400.0}, {'current': 800.0, 'min': 800.0, 'max': 3400.0}, {'current': 800.0, 'min': 800.0, 'max': 3400.0}, {'current': 800.0, 'min': 800.0, 'max': 3400.0}, {'current': 800.0, 'min': 800.0, 'max': 3400.0}, {'current': 800.0, 'min': 800.0, 'max': 3400.0}, {'current': 800.0, 'min': 800.0, 'max': 3400.0}, {'current': 800.0, 'min': 800.0, 'max': 3400.0}, {'current': 800.0, 'min': 800.0, 'max': 3400.0}, {'current': 800.0, 'min': 800.0, 'max': 3400.0}, {'current': 800.0, 'min': 800.0, 'max': 3400.0}, {'current': 800.0, 'min': 800.0, 'max': 3400.0}, {'current': 800.0, 'min': 800.0, 'max': 3400.0}, {'current': 800.0, 'min': 800.0, 'max': 3400.0}, {'current': 800.0, 'min': 800.0, 'max': 3400.0}, {'current': 800.0, 'min': 800.0, 'max': 3400.0}, {'current': 800.0, 'min': 800.0, 'max': 3400.0}, {'current': 800.0, 'min': 800.0, 'max': 3400.0}, {'current': 800.0, 'min': 800.0, 'max': 3400.0}, {'current': 800.0, 'min': 800.0, 'max': 3400.0}, {'current': 800.0, 'min': 800.0, 'max': 3400.0}, {'current': 800.0, 'min': 800.0, 'max': 3400.0}, {'current': 800.0, 'min': 800.0, 'max': 3400.0}, {'current': 800.0, 'min': 800.0, 'max': 3400.0}, {'current': 800.0, 'min': 800.0, 'max': 3400.0}, {'current': 800.0, 'min': 800.0, 'max': 3400.0}, {'current': 800.0, 'min': 800.0, 'max': 3400.0}, {'current': 800.0, 'min': 800.0, 'max': 3400.0}, {'current': 800.0, 'min': 800.0, 'max': 3400.0}, {'current': 800.0, 'min': 800.0, 'max': 3400.0}, {'current': 800.0, 'min': 800.0, 'max': 3400.0}, {'current': 800.0, 'min': 800.0, 'max': 3400.0}, {'current': 900.0, 'min': 800.0, 'max': 3400.0}, {'current': 900.0, 'min': 800.0, 'max': 3400.0}, {'current': 800.0, 'min': 800.0, 'max': 3400.0}, {'current': 800.0, 'min': 800.0, 'max': 3400.0}, {'current': 800.0, 'min': 800.0, 'max': 3400.0}, {'current': 800.0, 'min': 800.0, 'max': 3400.0}, {'current': 800.0, 'min': 800.0, 'max': 3400.0}, {'current': 800.0, 'min': 800.0, 'max': 3400.0}, {'current': 800.0, 'min': 800.0, 'max': 3400.0}, {'current': 800.0, 'min': 800.0, 'max': 3400.0}, {'current': 800.0, 'min': 800.0, 'max': 3400.0}, {'current': 800.0, 'min': 800.0, 'max': 3400.0}, {'current': 800.0, 'min': 800.0, 'max': 3400.0}, {'current': 800.0, 'min': 800.0, 'max': 3400.0}, {'current': 800.0, 'min': 800.0, 'max': 3400.0}, {'current': 800.0, 'min': 800.0, 'max': 3400.0}, {'current': 800.0, 'min': 800.0, 'max': 3400.0}, {'current': 800.0, 'min': 800.0, 'max': 3400.0}], 'disk': {'/': {'total': 438.05088806152344, 'used': 30.817367553710938}}, 'gpu': 'NVIDIA RTX A6000', 'gpu_count': 8, 'gpu_devices': [{'name': 'NVIDIA RTX A6000', 'memory_total': 51527024640}, {'name': 'NVIDIA RTX A6000', 'memory_total': 51527024640}, {'name': 'NVIDIA RTX A6000', 'memory_total': 51527024640}, {'name': 'NVIDIA RTX A6000', 'memory_total': 51527024640}, {'name': 'NVIDIA RTX A6000', 'memory_total': 51527024640}, {'name': 'NVIDIA RTX A6000', 'memory_total': 51527024640}, {'name': 'NVIDIA RTX A6000', 'memory_total': 51527024640}, {'name': 'NVIDIA RTX A6000', 'memory_total': 51527024640}], 'memory': {'total': 503.51252365112305}}
2024-01-30 16:10:14,675 INFO    HandlerThread:1134336 [system_monitor.py:probe():224] Finished collecting system info
2024-01-30 16:10:14,675 INFO    HandlerThread:1134336 [system_monitor.py:probe():227] Publishing system info
2024-01-30 16:10:14,675 DEBUG   HandlerThread:1134336 [system_info.py:_save_conda():208] Saving list of conda packages installed into the current environment
2024-01-30 16:10:15,654 INFO    Thread-12 :1134336 [dir_watcher.py:_on_file_created():271] file/dir created: /home/yanxindong/mkor/bert/wandb/run-20240130_161012-b793ft22/files/conda-environment.yaml
2024-01-30 16:10:34,656 INFO    Thread-12 :1134336 [dir_watcher.py:_on_file_modified():288] file/dir modified: /home/yanxindong/mkor/bert/wandb/run-20240130_161012-b793ft22/files/conda-environment.yaml
2024-01-30 16:10:34,700 DEBUG   HandlerThread:1134336 [system_info.py:_save_conda():220] Saving conda packages done
2024-01-30 16:10:34,702 INFO    HandlerThread:1134336 [system_monitor.py:probe():229] Finished publishing system info
2024-01-30 16:10:34,709 DEBUG   HandlerThread:1134336 [handler.py:handle_request():146] handle_request: status_report
2024-01-30 16:10:34,715 DEBUG   HandlerThread:1134336 [handler.py:handle_request():146] handle_request: keepalive
2024-01-30 16:10:34,716 DEBUG   HandlerThread:1134336 [handler.py:handle_request():146] handle_request: status_report
2024-01-30 16:10:34,716 DEBUG   HandlerThread:1134336 [handler.py:handle_request():146] handle_request: keepalive
2024-01-30 16:10:34,716 DEBUG   HandlerThread:1134336 [handler.py:handle_request():146] handle_request: status_report
2024-01-30 16:10:34,716 DEBUG   HandlerThread:1134336 [handler.py:handle_request():146] handle_request: keepalive
2024-01-30 16:10:34,716 DEBUG   HandlerThread:1134336 [handler.py:handle_request():146] handle_request: status_report
2024-01-30 16:10:34,716 DEBUG   HandlerThread:1134336 [handler.py:handle_request():146] handle_request: keepalive
2024-01-30 16:10:34,716 DEBUG   HandlerThread:1134336 [handler.py:handle_request():146] handle_request: python_packages
2024-01-30 16:10:34,717 DEBUG   SenderThread:1134336 [sender.py:send():382] send: files
2024-01-30 16:10:34,717 INFO    SenderThread:1134336 [sender.py:_save_file():1403] saving file wandb-metadata.json with policy now
2024-01-30 16:10:34,718 DEBUG   SenderThread:1134336 [sender.py:send_request():409] send_request: python_packages
2024-01-30 16:10:34,738 DEBUG   HandlerThread:1134336 [handler.py:handle_request():146] handle_request: stop_status
2024-01-30 16:10:34,746 DEBUG   SenderThread:1134336 [sender.py:send_request():409] send_request: stop_status
2024-01-30 16:10:34,792 DEBUG   HandlerThread:1134336 [handler.py:handle_request():146] handle_request: internal_messages
2024-01-30 16:10:35,046 DEBUG   SenderThread:1134336 [sender.py:send():382] send: telemetry
2024-01-30 16:10:35,455 ERROR   wandb-upload_0:1134336 [internal_api.py:upload_file():2765] upload_file exception https://storage.googleapis.com/wandb-production.appspot.com/dynamic_x/bert_pytorch/b793ft22/wandb-metadata.json?Expires=1706688635&GoogleAccessId=gorilla-files-url-signer-man%40wandb-production.iam.gserviceaccount.com&Signature=GG9waHJzWIlSJt%2Ffs%2FHu2%2BD10Edc0UB5RwtSEHDRx5B6hSob1QIFCoc9hbhtMhww1fag62T52vRjDNqI6H2we9y%2F47axeW8khE0atCO71FwFln3XLW6SX%2FBorIN%2FS9vR2GJfixLLvA0ls47ONf9qNJnUvP1MkQ%2Ffkam%2BQNao1jVYRAB0ZTNwyJrYoCHZjvs8k7HrQ1j9sxRKSNd3WAjRUcEp3WZmAvP%2BggQej6i4pCumKL0nMtEMhagfInuyBmL8DO5GiJuz9LTMrvP3Z0mmTUgl8Ixo7cr2WSgV7CwumFq097BZFo%2FQm4MYm6rZvT%2BEHoOPLgz%2Fg%2Bb7IuLw8JgmtQ%3D%3D: HTTPSConnectionPool(host='storage.googleapis.com', port=443): Max retries exceeded with url: /wandb-production.appspot.com/dynamic_x/bert_pytorch/b793ft22/wandb-metadata.json?Expires=1706688635&GoogleAccessId=gorilla-files-url-signer-man%40wandb-production.iam.gserviceaccount.com&Signature=GG9waHJzWIlSJt%2Ffs%2FHu2%2BD10Edc0UB5RwtSEHDRx5B6hSob1QIFCoc9hbhtMhww1fag62T52vRjDNqI6H2we9y%2F47axeW8khE0atCO71FwFln3XLW6SX%2FBorIN%2FS9vR2GJfixLLvA0ls47ONf9qNJnUvP1MkQ%2Ffkam%2BQNao1jVYRAB0ZTNwyJrYoCHZjvs8k7HrQ1j9sxRKSNd3WAjRUcEp3WZmAvP%2BggQej6i4pCumKL0nMtEMhagfInuyBmL8DO5GiJuz9LTMrvP3Z0mmTUgl8Ixo7cr2WSgV7CwumFq097BZFo%2FQm4MYm6rZvT%2BEHoOPLgz%2Fg%2Bb7IuLw8JgmtQ%3D%3D (Caused by NewConnectionError('<urllib3.connection.HTTPSConnection object at 0x7f9eb44141f0>: Failed to establish a new connection: [Errno 111] Connection refused'))
2024-01-30 16:10:35,455 ERROR   wandb-upload_0:1134336 [internal_api.py:upload_file():2767] upload_file request headers: {'User-Agent': 'python-requests/2.23.0', 'Accept-Encoding': 'gzip, deflate', 'Accept': '*/*', 'Connection': 'keep-alive', 'Content-Length': '15549'}
2024-01-30 16:10:35,455 ERROR   wandb-upload_0:1134336 [internal_api.py:upload_file():2769] upload_file response body: 
2024-01-30 16:10:35,656 INFO    Thread-12 :1134336 [dir_watcher.py:_on_file_created():271] file/dir created: /home/yanxindong/mkor/bert/wandb/run-20240130_161012-b793ft22/files/wandb-metadata.json
2024-01-30 16:10:35,657 INFO    Thread-12 :1134336 [dir_watcher.py:_on_file_created():271] file/dir created: /home/yanxindong/mkor/bert/wandb/run-20240130_161012-b793ft22/files/requirements.txt
2024-01-30 16:10:36,684 ERROR   wandb-upload_0:1134336 [internal_api.py:upload_file():2765] upload_file exception https://storage.googleapis.com/wandb-production.appspot.com/dynamic_x/bert_pytorch/b793ft22/wandb-metadata.json?Expires=1706688635&GoogleAccessId=gorilla-files-url-signer-man%40wandb-production.iam.gserviceaccount.com&Signature=GG9waHJzWIlSJt%2Ffs%2FHu2%2BD10Edc0UB5RwtSEHDRx5B6hSob1QIFCoc9hbhtMhww1fag62T52vRjDNqI6H2we9y%2F47axeW8khE0atCO71FwFln3XLW6SX%2FBorIN%2FS9vR2GJfixLLvA0ls47ONf9qNJnUvP1MkQ%2Ffkam%2BQNao1jVYRAB0ZTNwyJrYoCHZjvs8k7HrQ1j9sxRKSNd3WAjRUcEp3WZmAvP%2BggQej6i4pCumKL0nMtEMhagfInuyBmL8DO5GiJuz9LTMrvP3Z0mmTUgl8Ixo7cr2WSgV7CwumFq097BZFo%2FQm4MYm6rZvT%2BEHoOPLgz%2Fg%2Bb7IuLw8JgmtQ%3D%3D: HTTPSConnectionPool(host='storage.googleapis.com', port=443): Max retries exceeded with url: /wandb-production.appspot.com/dynamic_x/bert_pytorch/b793ft22/wandb-metadata.json?Expires=1706688635&GoogleAccessId=gorilla-files-url-signer-man%40wandb-production.iam.gserviceaccount.com&Signature=GG9waHJzWIlSJt%2Ffs%2FHu2%2BD10Edc0UB5RwtSEHDRx5B6hSob1QIFCoc9hbhtMhww1fag62T52vRjDNqI6H2we9y%2F47axeW8khE0atCO71FwFln3XLW6SX%2FBorIN%2FS9vR2GJfixLLvA0ls47ONf9qNJnUvP1MkQ%2Ffkam%2BQNao1jVYRAB0ZTNwyJrYoCHZjvs8k7HrQ1j9sxRKSNd3WAjRUcEp3WZmAvP%2BggQej6i4pCumKL0nMtEMhagfInuyBmL8DO5GiJuz9LTMrvP3Z0mmTUgl8Ixo7cr2WSgV7CwumFq097BZFo%2FQm4MYm6rZvT%2BEHoOPLgz%2Fg%2Bb7IuLw8JgmtQ%3D%3D (Caused by NewConnectionError('<urllib3.connection.HTTPSConnection object at 0x7f9eb4414730>: Failed to establish a new connection: [Errno 111] Connection refused'))
2024-01-30 16:10:36,684 ERROR   wandb-upload_0:1134336 [internal_api.py:upload_file():2767] upload_file request headers: {'User-Agent': 'python-requests/2.23.0', 'Accept-Encoding': 'gzip, deflate', 'Accept': '*/*', 'Connection': 'keep-alive', 'Content-Length': '15549'}
2024-01-30 16:10:36,684 ERROR   wandb-upload_0:1134336 [internal_api.py:upload_file():2769] upload_file response body: 
2024-01-30 16:10:38,047 DEBUG   HandlerThread:1134336 [handler.py:handle_request():146] handle_request: status_report
2024-01-30 16:10:38,996 ERROR   wandb-upload_0:1134336 [internal_api.py:upload_file():2765] upload_file exception https://storage.googleapis.com/wandb-production.appspot.com/dynamic_x/bert_pytorch/b793ft22/wandb-metadata.json?Expires=1706688635&GoogleAccessId=gorilla-files-url-signer-man%40wandb-production.iam.gserviceaccount.com&Signature=GG9waHJzWIlSJt%2Ffs%2FHu2%2BD10Edc0UB5RwtSEHDRx5B6hSob1QIFCoc9hbhtMhww1fag62T52vRjDNqI6H2we9y%2F47axeW8khE0atCO71FwFln3XLW6SX%2FBorIN%2FS9vR2GJfixLLvA0ls47ONf9qNJnUvP1MkQ%2Ffkam%2BQNao1jVYRAB0ZTNwyJrYoCHZjvs8k7HrQ1j9sxRKSNd3WAjRUcEp3WZmAvP%2BggQej6i4pCumKL0nMtEMhagfInuyBmL8DO5GiJuz9LTMrvP3Z0mmTUgl8Ixo7cr2WSgV7CwumFq097BZFo%2FQm4MYm6rZvT%2BEHoOPLgz%2Fg%2Bb7IuLw8JgmtQ%3D%3D: HTTPSConnectionPool(host='storage.googleapis.com', port=443): Max retries exceeded with url: /wandb-production.appspot.com/dynamic_x/bert_pytorch/b793ft22/wandb-metadata.json?Expires=1706688635&GoogleAccessId=gorilla-files-url-signer-man%40wandb-production.iam.gserviceaccount.com&Signature=GG9waHJzWIlSJt%2Ffs%2FHu2%2BD10Edc0UB5RwtSEHDRx5B6hSob1QIFCoc9hbhtMhww1fag62T52vRjDNqI6H2we9y%2F47axeW8khE0atCO71FwFln3XLW6SX%2FBorIN%2FS9vR2GJfixLLvA0ls47ONf9qNJnUvP1MkQ%2Ffkam%2BQNao1jVYRAB0ZTNwyJrYoCHZjvs8k7HrQ1j9sxRKSNd3WAjRUcEp3WZmAvP%2BggQej6i4pCumKL0nMtEMhagfInuyBmL8DO5GiJuz9LTMrvP3Z0mmTUgl8Ixo7cr2WSgV7CwumFq097BZFo%2FQm4MYm6rZvT%2BEHoOPLgz%2Fg%2Bb7IuLw8JgmtQ%3D%3D (Caused by NewConnectionError('<urllib3.connection.HTTPSConnection object at 0x7f9eb442b190>: Failed to establish a new connection: [Errno 111] Connection refused'))
2024-01-30 16:10:38,996 ERROR   wandb-upload_0:1134336 [internal_api.py:upload_file():2767] upload_file request headers: {'User-Agent': 'python-requests/2.23.0', 'Accept-Encoding': 'gzip, deflate', 'Accept': '*/*', 'Connection': 'keep-alive', 'Content-Length': '15549'}
2024-01-30 16:10:38,996 ERROR   wandb-upload_0:1134336 [internal_api.py:upload_file():2769] upload_file response body: 
2024-01-30 16:10:38,996 INFO    wandb-upload_0:1134336 [retry.py:__call__():172] Retry attempt failed:
Traceback (most recent call last):
  File "/home/yanxindong/anaconda/envs/eva/lib/python3.8/site-packages/urllib3/connection.py", line 159, in _new_conn
    conn = connection.create_connection(
  File "/home/yanxindong/anaconda/envs/eva/lib/python3.8/site-packages/urllib3/util/connection.py", line 84, in create_connection
    raise err
  File "/home/yanxindong/anaconda/envs/eva/lib/python3.8/site-packages/urllib3/util/connection.py", line 74, in create_connection
    sock.connect(sa)
ConnectionRefusedError: [Errno 111] Connection refused

During handling of the above exception, another exception occurred:

Traceback (most recent call last):
  File "/home/yanxindong/anaconda/envs/eva/lib/python3.8/site-packages/urllib3/connectionpool.py", line 670, in urlopen
    httplib_response = self._make_request(
  File "/home/yanxindong/anaconda/envs/eva/lib/python3.8/site-packages/urllib3/connectionpool.py", line 381, in _make_request
    self._validate_conn(conn)
  File "/home/yanxindong/anaconda/envs/eva/lib/python3.8/site-packages/urllib3/connectionpool.py", line 978, in _validate_conn
    conn.connect()
  File "/home/yanxindong/anaconda/envs/eva/lib/python3.8/site-packages/urllib3/connection.py", line 309, in connect
    conn = self._new_conn()
  File "/home/yanxindong/anaconda/envs/eva/lib/python3.8/site-packages/urllib3/connection.py", line 171, in _new_conn
    raise NewConnectionError(
urllib3.exceptions.NewConnectionError: <urllib3.connection.HTTPSConnection object at 0x7f9eb442b190>: Failed to establish a new connection: [Errno 111] Connection refused

During handling of the above exception, another exception occurred:

Traceback (most recent call last):
  File "/home/yanxindong/anaconda/envs/eva/lib/python3.8/site-packages/requests/adapters.py", line 439, in send
    resp = conn.urlopen(
  File "/home/yanxindong/anaconda/envs/eva/lib/python3.8/site-packages/urllib3/connectionpool.py", line 726, in urlopen
    retries = retries.increment(
  File "/home/yanxindong/anaconda/envs/eva/lib/python3.8/site-packages/urllib3/util/retry.py", line 446, in increment
    raise MaxRetryError(_pool, url, error or ResponseError(cause))
urllib3.exceptions.MaxRetryError: HTTPSConnectionPool(host='storage.googleapis.com', port=443): Max retries exceeded with url: /wandb-production.appspot.com/dynamic_x/bert_pytorch/b793ft22/wandb-metadata.json?Expires=1706688635&GoogleAccessId=gorilla-files-url-signer-man%40wandb-production.iam.gserviceaccount.com&Signature=GG9waHJzWIlSJt%2Ffs%2FHu2%2BD10Edc0UB5RwtSEHDRx5B6hSob1QIFCoc9hbhtMhww1fag62T52vRjDNqI6H2we9y%2F47axeW8khE0atCO71FwFln3XLW6SX%2FBorIN%2FS9vR2GJfixLLvA0ls47ONf9qNJnUvP1MkQ%2Ffkam%2BQNao1jVYRAB0ZTNwyJrYoCHZjvs8k7HrQ1j9sxRKSNd3WAjRUcEp3WZmAvP%2BggQej6i4pCumKL0nMtEMhagfInuyBmL8DO5GiJuz9LTMrvP3Z0mmTUgl8Ixo7cr2WSgV7CwumFq097BZFo%2FQm4MYm6rZvT%2BEHoOPLgz%2Fg%2Bb7IuLw8JgmtQ%3D%3D (Caused by NewConnectionError('<urllib3.connection.HTTPSConnection object at 0x7f9eb442b190>: Failed to establish a new connection: [Errno 111] Connection refused'))

During handling of the above exception, another exception occurred:

Traceback (most recent call last):
  File "/home/yanxindong/anaconda/envs/eva/lib/python3.8/site-packages/wandb/sdk/internal/internal_api.py", line 2758, in upload_file
    response = self._upload_file_session.put(
  File "/home/yanxindong/anaconda/envs/eva/lib/python3.8/site-packages/requests/sessions.py", line 590, in put
    return self.request('PUT', url, data=data, **kwargs)
  File "/home/yanxindong/anaconda/envs/eva/lib/python3.8/site-packages/requests/sessions.py", line 530, in request
    resp = self.send(prep, **send_kwargs)
  File "/home/yanxindong/anaconda/envs/eva/lib/python3.8/site-packages/requests/sessions.py", line 643, in send
    r = adapter.send(request, **kwargs)
  File "/home/yanxindong/anaconda/envs/eva/lib/python3.8/site-packages/requests/adapters.py", line 516, in send
    raise ConnectionError(e, request=request)
requests.exceptions.ConnectionError: HTTPSConnectionPool(host='storage.googleapis.com', port=443): Max retries exceeded with url: /wandb-production.appspot.com/dynamic_x/bert_pytorch/b793ft22/wandb-metadata.json?Expires=1706688635&GoogleAccessId=gorilla-files-url-signer-man%40wandb-production.iam.gserviceaccount.com&Signature=GG9waHJzWIlSJt%2Ffs%2FHu2%2BD10Edc0UB5RwtSEHDRx5B6hSob1QIFCoc9hbhtMhww1fag62T52vRjDNqI6H2we9y%2F47axeW8khE0atCO71FwFln3XLW6SX%2FBorIN%2FS9vR2GJfixLLvA0ls47ONf9qNJnUvP1MkQ%2Ffkam%2BQNao1jVYRAB0ZTNwyJrYoCHZjvs8k7HrQ1j9sxRKSNd3WAjRUcEp3WZmAvP%2BggQej6i4pCumKL0nMtEMhagfInuyBmL8DO5GiJuz9LTMrvP3Z0mmTUgl8Ixo7cr2WSgV7CwumFq097BZFo%2FQm4MYm6rZvT%2BEHoOPLgz%2Fg%2Bb7IuLw8JgmtQ%3D%3D (Caused by NewConnectionError('<urllib3.connection.HTTPSConnection object at 0x7f9eb442b190>: Failed to establish a new connection: [Errno 111] Connection refused'))

During handling of the above exception, another exception occurred:

Traceback (most recent call last):
  File "/home/yanxindong/anaconda/envs/eva/lib/python3.8/site-packages/wandb/sdk/lib/retry.py", line 131, in __call__
    result = self._call_fn(*args, **kwargs)
  File "/home/yanxindong/anaconda/envs/eva/lib/python3.8/site-packages/wandb/sdk/internal/internal_api.py", line 2789, in upload_file
    raise _e.with_traceback(sys.exc_info()[2])
  File "/home/yanxindong/anaconda/envs/eva/lib/python3.8/site-packages/wandb/sdk/internal/internal_api.py", line 2758, in upload_file
    response = self._upload_file_session.put(
  File "/home/yanxindong/anaconda/envs/eva/lib/python3.8/site-packages/requests/sessions.py", line 590, in put
    return self.request('PUT', url, data=data, **kwargs)
  File "/home/yanxindong/anaconda/envs/eva/lib/python3.8/site-packages/requests/sessions.py", line 530, in request
    resp = self.send(prep, **send_kwargs)
  File "/home/yanxindong/anaconda/envs/eva/lib/python3.8/site-packages/requests/sessions.py", line 643, in send
    r = adapter.send(request, **kwargs)
  File "/home/yanxindong/anaconda/envs/eva/lib/python3.8/site-packages/requests/adapters.py", line 516, in send
    raise ConnectionError(e, request=request)
wandb.sdk.lib.retry.TransientError: None
2024-01-30 16:10:43,053 DEBUG   HandlerThread:1134336 [handler.py:handle_request():146] handle_request: status_report
2024-01-30 16:10:43,225 ERROR   wandb-upload_0:1134336 [internal_api.py:upload_file():2765] upload_file exception https://storage.googleapis.com/wandb-production.appspot.com/dynamic_x/bert_pytorch/b793ft22/wandb-metadata.json?Expires=1706688635&GoogleAccessId=gorilla-files-url-signer-man%40wandb-production.iam.gserviceaccount.com&Signature=GG9waHJzWIlSJt%2Ffs%2FHu2%2BD10Edc0UB5RwtSEHDRx5B6hSob1QIFCoc9hbhtMhww1fag62T52vRjDNqI6H2we9y%2F47axeW8khE0atCO71FwFln3XLW6SX%2FBorIN%2FS9vR2GJfixLLvA0ls47ONf9qNJnUvP1MkQ%2Ffkam%2BQNao1jVYRAB0ZTNwyJrYoCHZjvs8k7HrQ1j9sxRKSNd3WAjRUcEp3WZmAvP%2BggQej6i4pCumKL0nMtEMhagfInuyBmL8DO5GiJuz9LTMrvP3Z0mmTUgl8Ixo7cr2WSgV7CwumFq097BZFo%2FQm4MYm6rZvT%2BEHoOPLgz%2Fg%2Bb7IuLw8JgmtQ%3D%3D: HTTPSConnectionPool(host='storage.googleapis.com', port=443): Max retries exceeded with url: /wandb-production.appspot.com/dynamic_x/bert_pytorch/b793ft22/wandb-metadata.json?Expires=1706688635&GoogleAccessId=gorilla-files-url-signer-man%40wandb-production.iam.gserviceaccount.com&Signature=GG9waHJzWIlSJt%2Ffs%2FHu2%2BD10Edc0UB5RwtSEHDRx5B6hSob1QIFCoc9hbhtMhww1fag62T52vRjDNqI6H2we9y%2F47axeW8khE0atCO71FwFln3XLW6SX%2FBorIN%2FS9vR2GJfixLLvA0ls47ONf9qNJnUvP1MkQ%2Ffkam%2BQNao1jVYRAB0ZTNwyJrYoCHZjvs8k7HrQ1j9sxRKSNd3WAjRUcEp3WZmAvP%2BggQej6i4pCumKL0nMtEMhagfInuyBmL8DO5GiJuz9LTMrvP3Z0mmTUgl8Ixo7cr2WSgV7CwumFq097BZFo%2FQm4MYm6rZvT%2BEHoOPLgz%2Fg%2Bb7IuLw8JgmtQ%3D%3D (Caused by NewConnectionError('<urllib3.connection.HTTPSConnection object at 0x7f9eb4351910>: Failed to establish a new connection: [Errno 111] Connection refused'))
2024-01-30 16:10:43,225 ERROR   wandb-upload_0:1134336 [internal_api.py:upload_file():2767] upload_file request headers: {'User-Agent': 'python-requests/2.23.0', 'Accept-Encoding': 'gzip, deflate', 'Accept': '*/*', 'Connection': 'keep-alive', 'Content-Length': '15549'}
2024-01-30 16:10:43,225 ERROR   wandb-upload_0:1134336 [internal_api.py:upload_file():2769] upload_file response body: 
2024-01-30 16:10:44,658 INFO    Thread-12 :1134336 [dir_watcher.py:_on_file_modified():288] file/dir modified: /home/yanxindong/mkor/bert/wandb/run-20240130_161012-b793ft22/files/config.yaml
2024-01-30 16:10:49,286 DEBUG   HandlerThread:1134336 [handler.py:handle_request():146] handle_request: status_report
2024-01-30 16:10:49,738 DEBUG   HandlerThread:1134336 [handler.py:handle_request():146] handle_request: stop_status
2024-01-30 16:10:49,738 DEBUG   SenderThread:1134336 [sender.py:send_request():409] send_request: stop_status
2024-01-30 16:10:49,797 DEBUG   HandlerThread:1134336 [handler.py:handle_request():146] handle_request: internal_messages
2024-01-30 16:10:52,755 ERROR   wandb-upload_0:1134336 [internal_api.py:upload_file():2765] upload_file exception https://storage.googleapis.com/wandb-production.appspot.com/dynamic_x/bert_pytorch/b793ft22/wandb-metadata.json?Expires=1706688635&GoogleAccessId=gorilla-files-url-signer-man%40wandb-production.iam.gserviceaccount.com&Signature=GG9waHJzWIlSJt%2Ffs%2FHu2%2BD10Edc0UB5RwtSEHDRx5B6hSob1QIFCoc9hbhtMhww1fag62T52vRjDNqI6H2we9y%2F47axeW8khE0atCO71FwFln3XLW6SX%2FBorIN%2FS9vR2GJfixLLvA0ls47ONf9qNJnUvP1MkQ%2Ffkam%2BQNao1jVYRAB0ZTNwyJrYoCHZjvs8k7HrQ1j9sxRKSNd3WAjRUcEp3WZmAvP%2BggQej6i4pCumKL0nMtEMhagfInuyBmL8DO5GiJuz9LTMrvP3Z0mmTUgl8Ixo7cr2WSgV7CwumFq097BZFo%2FQm4MYm6rZvT%2BEHoOPLgz%2Fg%2Bb7IuLw8JgmtQ%3D%3D: HTTPSConnectionPool(host='storage.googleapis.com', port=443): Max retries exceeded with url: /wandb-production.appspot.com/dynamic_x/bert_pytorch/b793ft22/wandb-metadata.json?Expires=1706688635&GoogleAccessId=gorilla-files-url-signer-man%40wandb-production.iam.gserviceaccount.com&Signature=GG9waHJzWIlSJt%2Ffs%2FHu2%2BD10Edc0UB5RwtSEHDRx5B6hSob1QIFCoc9hbhtMhww1fag62T52vRjDNqI6H2we9y%2F47axeW8khE0atCO71FwFln3XLW6SX%2FBorIN%2FS9vR2GJfixLLvA0ls47ONf9qNJnUvP1MkQ%2Ffkam%2BQNao1jVYRAB0ZTNwyJrYoCHZjvs8k7HrQ1j9sxRKSNd3WAjRUcEp3WZmAvP%2BggQej6i4pCumKL0nMtEMhagfInuyBmL8DO5GiJuz9LTMrvP3Z0mmTUgl8Ixo7cr2WSgV7CwumFq097BZFo%2FQm4MYm6rZvT%2BEHoOPLgz%2Fg%2Bb7IuLw8JgmtQ%3D%3D (Caused by NewConnectionError('<urllib3.connection.HTTPSConnection object at 0x7f9eb442bd60>: Failed to establish a new connection: [Errno 111] Connection refused'))
2024-01-30 16:10:52,756 ERROR   wandb-upload_0:1134336 [internal_api.py:upload_file():2767] upload_file request headers: {'User-Agent': 'python-requests/2.23.0', 'Accept-Encoding': 'gzip, deflate', 'Accept': '*/*', 'Connection': 'keep-alive', 'Content-Length': '15549'}
2024-01-30 16:10:52,756 ERROR   wandb-upload_0:1134336 [internal_api.py:upload_file():2769] upload_file response body: 
2024-01-30 16:10:55,111 DEBUG   HandlerThread:1134336 [handler.py:handle_request():146] handle_request: status_report
2024-01-30 16:11:00,112 DEBUG   HandlerThread:1134336 [handler.py:handle_request():146] handle_request: status_report
2024-01-30 16:11:04,738 DEBUG   HandlerThread:1134336 [handler.py:handle_request():146] handle_request: stop_status
2024-01-30 16:11:04,739 DEBUG   SenderThread:1134336 [sender.py:send_request():409] send_request: stop_status
2024-01-30 16:11:04,790 DEBUG   HandlerThread:1134336 [handler.py:handle_request():146] handle_request: internal_messages
2024-01-30 16:11:06,025 DEBUG   HandlerThread:1134336 [handler.py:handle_request():146] handle_request: status_report
2024-01-30 16:11:08,795 ERROR   wandb-upload_0:1134336 [internal_api.py:upload_file():2765] upload_file exception https://storage.googleapis.com/wandb-production.appspot.com/dynamic_x/bert_pytorch/b793ft22/wandb-metadata.json?Expires=1706688635&GoogleAccessId=gorilla-files-url-signer-man%40wandb-production.iam.gserviceaccount.com&Signature=GG9waHJzWIlSJt%2Ffs%2FHu2%2BD10Edc0UB5RwtSEHDRx5B6hSob1QIFCoc9hbhtMhww1fag62T52vRjDNqI6H2we9y%2F47axeW8khE0atCO71FwFln3XLW6SX%2FBorIN%2FS9vR2GJfixLLvA0ls47ONf9qNJnUvP1MkQ%2Ffkam%2BQNao1jVYRAB0ZTNwyJrYoCHZjvs8k7HrQ1j9sxRKSNd3WAjRUcEp3WZmAvP%2BggQej6i4pCumKL0nMtEMhagfInuyBmL8DO5GiJuz9LTMrvP3Z0mmTUgl8Ixo7cr2WSgV7CwumFq097BZFo%2FQm4MYm6rZvT%2BEHoOPLgz%2Fg%2Bb7IuLw8JgmtQ%3D%3D: HTTPSConnectionPool(host='storage.googleapis.com', port=443): Max retries exceeded with url: /wandb-production.appspot.com/dynamic_x/bert_pytorch/b793ft22/wandb-metadata.json?Expires=1706688635&GoogleAccessId=gorilla-files-url-signer-man%40wandb-production.iam.gserviceaccount.com&Signature=GG9waHJzWIlSJt%2Ffs%2FHu2%2BD10Edc0UB5RwtSEHDRx5B6hSob1QIFCoc9hbhtMhww1fag62T52vRjDNqI6H2we9y%2F47axeW8khE0atCO71FwFln3XLW6SX%2FBorIN%2FS9vR2GJfixLLvA0ls47ONf9qNJnUvP1MkQ%2Ffkam%2BQNao1jVYRAB0ZTNwyJrYoCHZjvs8k7HrQ1j9sxRKSNd3WAjRUcEp3WZmAvP%2BggQej6i4pCumKL0nMtEMhagfInuyBmL8DO5GiJuz9LTMrvP3Z0mmTUgl8Ixo7cr2WSgV7CwumFq097BZFo%2FQm4MYm6rZvT%2BEHoOPLgz%2Fg%2Bb7IuLw8JgmtQ%3D%3D (Caused by NewConnectionError('<urllib3.connection.HTTPSConnection object at 0x7f9eb442b1c0>: Failed to establish a new connection: [Errno 111] Connection refused'))
2024-01-30 16:11:08,795 ERROR   wandb-upload_0:1134336 [internal_api.py:upload_file():2767] upload_file request headers: {'User-Agent': 'python-requests/2.23.0', 'Accept-Encoding': 'gzip, deflate', 'Accept': '*/*', 'Connection': 'keep-alive', 'Content-Length': '15549'}
2024-01-30 16:11:08,795 ERROR   wandb-upload_0:1134336 [internal_api.py:upload_file():2769] upload_file response body: 
2024-01-30 16:11:11,026 DEBUG   HandlerThread:1134336 [handler.py:handle_request():146] handle_request: status_report
2024-01-30 16:11:14,597 DEBUG   SystemMonitor:1134336 [system_monitor.py:_start():172] Starting system metrics aggregation loop
2024-01-30 16:11:14,600 DEBUG   SenderThread:1134336 [sender.py:send():382] send: stats
2024-01-30 16:11:16,602 DEBUG   HandlerThread:1134336 [handler.py:handle_request():146] handle_request: status_report
2024-01-30 16:11:19,738 DEBUG   HandlerThread:1134336 [handler.py:handle_request():146] handle_request: stop_status
2024-01-30 16:11:19,739 DEBUG   SenderThread:1134336 [sender.py:send_request():409] send_request: stop_status
2024-01-30 16:11:19,790 DEBUG   HandlerThread:1134336 [handler.py:handle_request():146] handle_request: internal_messages
2024-01-30 16:11:22,010 DEBUG   HandlerThread:1134336 [handler.py:handle_request():146] handle_request: status_report
2024-01-30 16:11:27,022 DEBUG   HandlerThread:1134336 [handler.py:handle_request():146] handle_request: status_report
2024-01-30 16:11:32,079 DEBUG   HandlerThread:1134336 [handler.py:handle_request():146] handle_request: status_report
2024-01-30 16:11:34,739 DEBUG   HandlerThread:1134336 [handler.py:handle_request():146] handle_request: stop_status
2024-01-30 16:11:34,739 DEBUG   SenderThread:1134336 [sender.py:send_request():409] send_request: stop_status
2024-01-30 16:11:34,790 DEBUG   HandlerThread:1134336 [handler.py:handle_request():146] handle_request: internal_messages
2024-01-30 16:11:37,144 DEBUG   HandlerThread:1134336 [handler.py:handle_request():146] handle_request: status_report
2024-01-30 16:11:41,403 ERROR   wandb-upload_0:1134336 [internal_api.py:upload_file():2765] upload_file exception https://storage.googleapis.com/wandb-production.appspot.com/dynamic_x/bert_pytorch/b793ft22/wandb-metadata.json?Expires=1706688635&GoogleAccessId=gorilla-files-url-signer-man%40wandb-production.iam.gserviceaccount.com&Signature=GG9waHJzWIlSJt%2Ffs%2FHu2%2BD10Edc0UB5RwtSEHDRx5B6hSob1QIFCoc9hbhtMhww1fag62T52vRjDNqI6H2we9y%2F47axeW8khE0atCO71FwFln3XLW6SX%2FBorIN%2FS9vR2GJfixLLvA0ls47ONf9qNJnUvP1MkQ%2Ffkam%2BQNao1jVYRAB0ZTNwyJrYoCHZjvs8k7HrQ1j9sxRKSNd3WAjRUcEp3WZmAvP%2BggQej6i4pCumKL0nMtEMhagfInuyBmL8DO5GiJuz9LTMrvP3Z0mmTUgl8Ixo7cr2WSgV7CwumFq097BZFo%2FQm4MYm6rZvT%2BEHoOPLgz%2Fg%2Bb7IuLw8JgmtQ%3D%3D: HTTPSConnectionPool(host='storage.googleapis.com', port=443): Max retries exceeded with url: /wandb-production.appspot.com/dynamic_x/bert_pytorch/b793ft22/wandb-metadata.json?Expires=1706688635&GoogleAccessId=gorilla-files-url-signer-man%40wandb-production.iam.gserviceaccount.com&Signature=GG9waHJzWIlSJt%2Ffs%2FHu2%2BD10Edc0UB5RwtSEHDRx5B6hSob1QIFCoc9hbhtMhww1fag62T52vRjDNqI6H2we9y%2F47axeW8khE0atCO71FwFln3XLW6SX%2FBorIN%2FS9vR2GJfixLLvA0ls47ONf9qNJnUvP1MkQ%2Ffkam%2BQNao1jVYRAB0ZTNwyJrYoCHZjvs8k7HrQ1j9sxRKSNd3WAjRUcEp3WZmAvP%2BggQej6i4pCumKL0nMtEMhagfInuyBmL8DO5GiJuz9LTMrvP3Z0mmTUgl8Ixo7cr2WSgV7CwumFq097BZFo%2FQm4MYm6rZvT%2BEHoOPLgz%2Fg%2Bb7IuLw8JgmtQ%3D%3D (Caused by NewConnectionError('<urllib3.connection.HTTPSConnection object at 0x7f9eb4351340>: Failed to establish a new connection: [Errno 111] Connection refused'))
2024-01-30 16:11:41,403 ERROR   wandb-upload_0:1134336 [internal_api.py:upload_file():2767] upload_file request headers: {'User-Agent': 'python-requests/2.23.0', 'Accept-Encoding': 'gzip, deflate', 'Accept': '*/*', 'Connection': 'keep-alive', 'Content-Length': '15549'}
2024-01-30 16:11:41,403 ERROR   wandb-upload_0:1134336 [internal_api.py:upload_file():2769] upload_file response body: 
2024-01-30 16:11:42,145 DEBUG   HandlerThread:1134336 [handler.py:handle_request():146] handle_request: status_report
2024-01-30 16:11:44,603 DEBUG   SenderThread:1134336 [sender.py:send():382] send: stats
2024-01-30 16:11:47,605 DEBUG   HandlerThread:1134336 [handler.py:handle_request():146] handle_request: status_report
2024-01-30 16:11:49,738 DEBUG   HandlerThread:1134336 [handler.py:handle_request():146] handle_request: stop_status
2024-01-30 16:11:49,739 DEBUG   SenderThread:1134336 [sender.py:send_request():409] send_request: stop_status
2024-01-30 16:11:49,790 DEBUG   HandlerThread:1134336 [handler.py:handle_request():146] handle_request: internal_messages
2024-01-30 16:11:53,033 DEBUG   HandlerThread:1134336 [handler.py:handle_request():146] handle_request: status_report
2024-01-30 16:11:55,803 INFO    Thread-12 :1134336 [dir_watcher.py:_on_file_created():271] file/dir created: /home/yanxindong/mkor/bert/wandb/run-20240130_161012-b793ft22/files/output.log
2024-01-30 16:11:57,803 INFO    Thread-12 :1134336 [dir_watcher.py:_on_file_modified():288] file/dir modified: /home/yanxindong/mkor/bert/wandb/run-20240130_161012-b793ft22/files/output.log
2024-01-30 16:11:58,220 DEBUG   HandlerThread:1134336 [handler.py:handle_request():146] handle_request: status_report
2024-01-30 16:12:03,221 DEBUG   HandlerThread:1134336 [handler.py:handle_request():146] handle_request: status_report
2024-01-30 16:12:06,851 DEBUG   HandlerThread:1134336 [handler.py:handle_request():146] handle_request: internal_messages
2024-01-30 16:12:06,852 DEBUG   HandlerThread:1134336 [handler.py:handle_request():146] handle_request: stop_status
2024-01-30 16:12:06,852 DEBUG   SenderThread:1134336 [sender.py:send_request():409] send_request: stop_status
2024-01-30 16:12:08,359 DEBUG   HandlerThread:1134336 [handler.py:handle_request():146] handle_request: status_report
2024-01-30 16:12:13,743 DEBUG   HandlerThread:1134336 [handler.py:handle_request():146] handle_request: status_report
2024-01-30 16:12:14,648 DEBUG   SenderThread:1134336 [sender.py:send():382] send: stats
2024-01-30 16:12:19,651 DEBUG   HandlerThread:1134336 [handler.py:handle_request():146] handle_request: status_report
2024-01-30 16:12:21,850 DEBUG   HandlerThread:1134336 [handler.py:handle_request():146] handle_request: internal_messages
2024-01-30 16:12:21,852 DEBUG   HandlerThread:1134336 [handler.py:handle_request():146] handle_request: stop_status
2024-01-30 16:12:21,853 DEBUG   SenderThread:1134336 [sender.py:send_request():409] send_request: stop_status
2024-01-30 16:12:25,254 DEBUG   HandlerThread:1134336 [handler.py:handle_request():146] handle_request: status_report
2024-01-30 16:12:30,268 DEBUG   HandlerThread:1134336 [handler.py:handle_request():146] handle_request: status_report
2024-01-30 16:12:35,327 DEBUG   HandlerThread:1134336 [handler.py:handle_request():146] handle_request: status_report
2024-01-30 16:12:36,918 DEBUG   HandlerThread:1134336 [handler.py:handle_request():146] handle_request: internal_messages
2024-01-30 16:12:36,918 DEBUG   HandlerThread:1134336 [handler.py:handle_request():146] handle_request: stop_status
2024-01-30 16:12:36,918 DEBUG   SenderThread:1134336 [sender.py:send_request():409] send_request: stop_status
2024-01-30 16:12:40,365 DEBUG   HandlerThread:1134336 [handler.py:handle_request():146] handle_request: status_report
2024-01-30 16:12:44,651 DEBUG   SenderThread:1134336 [sender.py:send():382] send: stats
2024-01-30 16:12:45,652 DEBUG   HandlerThread:1134336 [handler.py:handle_request():146] handle_request: status_report
2024-01-30 16:12:48,301 ERROR   wandb-upload_0:1134336 [internal_api.py:upload_file():2765] upload_file exception https://storage.googleapis.com/wandb-production.appspot.com/dynamic_x/bert_pytorch/b793ft22/wandb-metadata.json?Expires=1706688635&GoogleAccessId=gorilla-files-url-signer-man%40wandb-production.iam.gserviceaccount.com&Signature=GG9waHJzWIlSJt%2Ffs%2FHu2%2BD10Edc0UB5RwtSEHDRx5B6hSob1QIFCoc9hbhtMhww1fag62T52vRjDNqI6H2we9y%2F47axeW8khE0atCO71FwFln3XLW6SX%2FBorIN%2FS9vR2GJfixLLvA0ls47ONf9qNJnUvP1MkQ%2Ffkam%2BQNao1jVYRAB0ZTNwyJrYoCHZjvs8k7HrQ1j9sxRKSNd3WAjRUcEp3WZmAvP%2BggQej6i4pCumKL0nMtEMhagfInuyBmL8DO5GiJuz9LTMrvP3Z0mmTUgl8Ixo7cr2WSgV7CwumFq097BZFo%2FQm4MYm6rZvT%2BEHoOPLgz%2Fg%2Bb7IuLw8JgmtQ%3D%3D: HTTPSConnectionPool(host='storage.googleapis.com', port=443): Max retries exceeded with url: /wandb-production.appspot.com/dynamic_x/bert_pytorch/b793ft22/wandb-metadata.json?Expires=1706688635&GoogleAccessId=gorilla-files-url-signer-man%40wandb-production.iam.gserviceaccount.com&Signature=GG9waHJzWIlSJt%2Ffs%2FHu2%2BD10Edc0UB5RwtSEHDRx5B6hSob1QIFCoc9hbhtMhww1fag62T52vRjDNqI6H2we9y%2F47axeW8khE0atCO71FwFln3XLW6SX%2FBorIN%2FS9vR2GJfixLLvA0ls47ONf9qNJnUvP1MkQ%2Ffkam%2BQNao1jVYRAB0ZTNwyJrYoCHZjvs8k7HrQ1j9sxRKSNd3WAjRUcEp3WZmAvP%2BggQej6i4pCumKL0nMtEMhagfInuyBmL8DO5GiJuz9LTMrvP3Z0mmTUgl8Ixo7cr2WSgV7CwumFq097BZFo%2FQm4MYm6rZvT%2BEHoOPLgz%2Fg%2Bb7IuLw8JgmtQ%3D%3D (Caused by NewConnectionError('<urllib3.connection.HTTPSConnection object at 0x7f9eb429d3d0>: Failed to establish a new connection: [Errno 101] Network is unreachable'))
2024-01-30 16:12:48,301 ERROR   wandb-upload_0:1134336 [internal_api.py:upload_file():2767] upload_file request headers: {'User-Agent': 'python-requests/2.23.0', 'Accept-Encoding': 'gzip, deflate', 'Accept': '*/*', 'Connection': 'keep-alive', 'Content-Length': '15549'}
2024-01-30 16:12:48,301 ERROR   wandb-upload_0:1134336 [internal_api.py:upload_file():2769] upload_file response body: 
2024-01-30 16:12:50,653 DEBUG   HandlerThread:1134336 [handler.py:handle_request():146] handle_request: status_report
2024-01-30 16:12:51,850 DEBUG   HandlerThread:1134336 [handler.py:handle_request():146] handle_request: internal_messages
2024-01-30 16:12:51,852 DEBUG   HandlerThread:1134336 [handler.py:handle_request():146] handle_request: stop_status
2024-01-30 16:12:51,853 DEBUG   SenderThread:1134336 [sender.py:send_request():409] send_request: stop_status
2024-01-30 16:12:56,215 DEBUG   HandlerThread:1134336 [handler.py:handle_request():146] handle_request: status_report
2024-01-30 16:13:01,216 DEBUG   HandlerThread:1134336 [handler.py:handle_request():146] handle_request: status_report
2024-01-30 16:13:06,217 DEBUG   HandlerThread:1134336 [handler.py:handle_request():146] handle_request: status_report
2024-01-30 16:13:06,851 DEBUG   HandlerThread:1134336 [handler.py:handle_request():146] handle_request: internal_messages
2024-01-30 16:13:06,853 DEBUG   HandlerThread:1134336 [handler.py:handle_request():146] handle_request: stop_status
2024-01-30 16:13:06,853 DEBUG   SenderThread:1134336 [sender.py:send_request():409] send_request: stop_status
2024-01-30 16:13:12,133 DEBUG   HandlerThread:1134336 [handler.py:handle_request():146] handle_request: status_report
2024-01-30 16:13:14,653 DEBUG   SenderThread:1134336 [sender.py:send():382] send: stats
2024-01-30 16:13:17,690 DEBUG   HandlerThread:1134336 [handler.py:handle_request():146] handle_request: status_report
2024-01-30 16:13:21,851 DEBUG   HandlerThread:1134336 [handler.py:handle_request():146] handle_request: internal_messages
2024-01-30 16:13:21,853 DEBUG   HandlerThread:1134336 [handler.py:handle_request():146] handle_request: stop_status
2024-01-30 16:13:21,853 DEBUG   SenderThread:1134336 [sender.py:send_request():409] send_request: stop_status
2024-01-30 16:13:23,193 DEBUG   HandlerThread:1134336 [handler.py:handle_request():146] handle_request: status_report
2024-01-30 16:13:28,226 DEBUG   HandlerThread:1134336 [handler.py:handle_request():146] handle_request: status_report
2024-01-30 16:13:33,322 DEBUG   HandlerThread:1134336 [handler.py:handle_request():146] handle_request: status_report
2024-01-30 16:13:36,886 DEBUG   HandlerThread:1134336 [handler.py:handle_request():146] handle_request: internal_messages
2024-01-30 16:13:36,886 DEBUG   HandlerThread:1134336 [handler.py:handle_request():146] handle_request: stop_status
2024-01-30 16:13:36,886 DEBUG   SenderThread:1134336 [sender.py:send_request():409] send_request: stop_status
2024-01-30 16:13:39,238 DEBUG   HandlerThread:1134336 [handler.py:handle_request():146] handle_request: status_report
2024-01-30 16:13:44,274 DEBUG   HandlerThread:1134336 [handler.py:handle_request():146] handle_request: status_report
2024-01-30 16:13:44,656 DEBUG   SenderThread:1134336 [sender.py:send():382] send: stats
2024-01-30 16:13:49,657 DEBUG   HandlerThread:1134336 [handler.py:handle_request():146] handle_request: status_report
2024-01-30 16:13:51,851 DEBUG   HandlerThread:1134336 [handler.py:handle_request():146] handle_request: internal_messages
2024-01-30 16:13:51,853 DEBUG   HandlerThread:1134336 [handler.py:handle_request():146] handle_request: stop_status
2024-01-30 16:13:51,853 DEBUG   SenderThread:1134336 [sender.py:send_request():409] send_request: stop_status
2024-01-30 16:13:55,227 DEBUG   HandlerThread:1134336 [handler.py:handle_request():146] handle_request: status_report
2024-01-30 16:14:00,228 DEBUG   HandlerThread:1134336 [handler.py:handle_request():146] handle_request: status_report
2024-01-30 16:14:05,228 DEBUG   HandlerThread:1134336 [handler.py:handle_request():146] handle_request: status_report
2024-01-30 16:14:06,853 DEBUG   HandlerThread:1134336 [handler.py:handle_request():146] handle_request: internal_messages
2024-01-30 16:14:06,853 DEBUG   HandlerThread:1134336 [handler.py:handle_request():146] handle_request: stop_status
2024-01-30 16:14:06,854 DEBUG   SenderThread:1134336 [sender.py:send_request():409] send_request: stop_status
2024-01-30 16:14:11,205 DEBUG   HandlerThread:1134336 [handler.py:handle_request():146] handle_request: status_report
2024-01-30 16:14:14,658 DEBUG   SenderThread:1134336 [sender.py:send():382] send: stats
2024-01-30 16:14:16,682 DEBUG   HandlerThread:1134336 [handler.py:handle_request():146] handle_request: status_report
2024-01-30 16:14:21,796 DEBUG   HandlerThread:1134336 [handler.py:handle_request():146] handle_request: status_report
2024-01-30 16:14:21,897 DEBUG   HandlerThread:1134336 [handler.py:handle_request():146] handle_request: internal_messages
2024-01-30 16:14:21,898 DEBUG   HandlerThread:1134336 [handler.py:handle_request():146] handle_request: stop_status
2024-01-30 16:14:21,898 DEBUG   SenderThread:1134336 [sender.py:send_request():409] send_request: stop_status
2024-01-30 16:14:27,342 DEBUG   HandlerThread:1134336 [handler.py:handle_request():146] handle_request: status_report
2024-01-30 16:14:32,377 DEBUG   HandlerThread:1134336 [handler.py:handle_request():146] handle_request: status_report
2024-01-30 16:14:36,854 DEBUG   HandlerThread:1134336 [handler.py:handle_request():146] handle_request: internal_messages
2024-01-30 16:14:36,854 DEBUG   HandlerThread:1134336 [handler.py:handle_request():146] handle_request: stop_status
2024-01-30 16:14:36,854 DEBUG   SenderThread:1134336 [sender.py:send_request():409] send_request: stop_status
2024-01-30 16:14:38,201 DEBUG   HandlerThread:1134336 [handler.py:handle_request():146] handle_request: status_report
2024-01-30 16:14:43,330 DEBUG   HandlerThread:1134336 [handler.py:handle_request():146] handle_request: status_report
2024-01-30 16:14:44,663 DEBUG   SenderThread:1134336 [sender.py:send():382] send: stats
2024-01-30 16:14:48,675 DEBUG   HandlerThread:1134336 [handler.py:handle_request():146] handle_request: status_report
2024-01-30 16:14:51,854 DEBUG   HandlerThread:1134336 [handler.py:handle_request():146] handle_request: internal_messages
2024-01-30 16:14:51,854 DEBUG   HandlerThread:1134336 [handler.py:handle_request():146] handle_request: stop_status
2024-01-30 16:14:51,854 DEBUG   SenderThread:1134336 [sender.py:send_request():409] send_request: stop_status
2024-01-30 16:14:54,269 DEBUG   HandlerThread:1134336 [handler.py:handle_request():146] handle_request: status_report
2024-01-30 16:14:59,270 DEBUG   HandlerThread:1134336 [handler.py:handle_request():146] handle_request: status_report
2024-01-30 16:14:59,683 ERROR   wandb-upload_0:1134336 [internal_api.py:upload_file():2765] upload_file exception https://storage.googleapis.com/wandb-production.appspot.com/dynamic_x/bert_pytorch/b793ft22/wandb-metadata.json?Expires=1706688635&GoogleAccessId=gorilla-files-url-signer-man%40wandb-production.iam.gserviceaccount.com&Signature=GG9waHJzWIlSJt%2Ffs%2FHu2%2BD10Edc0UB5RwtSEHDRx5B6hSob1QIFCoc9hbhtMhww1fag62T52vRjDNqI6H2we9y%2F47axeW8khE0atCO71FwFln3XLW6SX%2FBorIN%2FS9vR2GJfixLLvA0ls47ONf9qNJnUvP1MkQ%2Ffkam%2BQNao1jVYRAB0ZTNwyJrYoCHZjvs8k7HrQ1j9sxRKSNd3WAjRUcEp3WZmAvP%2BggQej6i4pCumKL0nMtEMhagfInuyBmL8DO5GiJuz9LTMrvP3Z0mmTUgl8Ixo7cr2WSgV7CwumFq097BZFo%2FQm4MYm6rZvT%2BEHoOPLgz%2Fg%2Bb7IuLw8JgmtQ%3D%3D: HTTPSConnectionPool(host='storage.googleapis.com', port=443): Max retries exceeded with url: /wandb-production.appspot.com/dynamic_x/bert_pytorch/b793ft22/wandb-metadata.json?Expires=1706688635&GoogleAccessId=gorilla-files-url-signer-man%40wandb-production.iam.gserviceaccount.com&Signature=GG9waHJzWIlSJt%2Ffs%2FHu2%2BD10Edc0UB5RwtSEHDRx5B6hSob1QIFCoc9hbhtMhww1fag62T52vRjDNqI6H2we9y%2F47axeW8khE0atCO71FwFln3XLW6SX%2FBorIN%2FS9vR2GJfixLLvA0ls47ONf9qNJnUvP1MkQ%2Ffkam%2BQNao1jVYRAB0ZTNwyJrYoCHZjvs8k7HrQ1j9sxRKSNd3WAjRUcEp3WZmAvP%2BggQej6i4pCumKL0nMtEMhagfInuyBmL8DO5GiJuz9LTMrvP3Z0mmTUgl8Ixo7cr2WSgV7CwumFq097BZFo%2FQm4MYm6rZvT%2BEHoOPLgz%2Fg%2Bb7IuLw8JgmtQ%3D%3D (Caused by NewConnectionError('<urllib3.connection.HTTPSConnection object at 0x7f9eb442b670>: Failed to establish a new connection: [Errno 101] Network is unreachable'))
2024-01-30 16:14:59,683 ERROR   wandb-upload_0:1134336 [internal_api.py:upload_file():2767] upload_file request headers: {'User-Agent': 'python-requests/2.23.0', 'Accept-Encoding': 'gzip, deflate', 'Accept': '*/*', 'Connection': 'keep-alive', 'Content-Length': '15549'}
2024-01-30 16:14:59,683 ERROR   wandb-upload_0:1134336 [internal_api.py:upload_file():2769] upload_file response body: 
2024-01-30 16:15:04,270 DEBUG   HandlerThread:1134336 [handler.py:handle_request():146] handle_request: status_report
2024-01-30 16:15:06,854 DEBUG   HandlerThread:1134336 [handler.py:handle_request():146] handle_request: internal_messages
2024-01-30 16:15:06,854 DEBUG   HandlerThread:1134336 [handler.py:handle_request():146] handle_request: stop_status
2024-01-30 16:15:06,855 DEBUG   SenderThread:1134336 [sender.py:send_request():409] send_request: stop_status
2024-01-30 16:15:10,149 DEBUG   HandlerThread:1134336 [handler.py:handle_request():146] handle_request: status_report
2024-01-30 16:15:14,666 DEBUG   SenderThread:1134336 [sender.py:send():382] send: stats
2024-01-30 16:15:15,668 DEBUG   HandlerThread:1134336 [handler.py:handle_request():146] handle_request: status_report
2024-01-30 16:15:20,763 DEBUG   HandlerThread:1134336 [handler.py:handle_request():146] handle_request: status_report
2024-01-30 16:15:21,882 DEBUG   HandlerThread:1134336 [handler.py:handle_request():146] handle_request: internal_messages
2024-01-30 16:15:21,882 DEBUG   HandlerThread:1134336 [handler.py:handle_request():146] handle_request: stop_status
2024-01-30 16:15:21,883 DEBUG   SenderThread:1134336 [sender.py:send_request():409] send_request: stop_status
2024-01-30 16:15:26,307 DEBUG   HandlerThread:1134336 [handler.py:handle_request():146] handle_request: status_report
2024-01-30 16:15:29,862 DEBUG   SenderThread:1134336 [sender.py:send():382] send: exit
2024-01-30 16:15:29,862 INFO    SenderThread:1134336 [sender.py:send_exit():589] handling exit code: 1
2024-01-30 16:15:29,862 INFO    SenderThread:1134336 [sender.py:send_exit():591] handling runtime: 315
2024-01-30 16:15:29,863 INFO    SenderThread:1134336 [sender.py:_save_file():1403] saving file wandb-summary.json with policy end
2024-01-30 16:15:29,863 INFO    SenderThread:1134336 [sender.py:send_exit():597] send defer
2024-01-30 16:15:29,863 DEBUG   HandlerThread:1134336 [handler.py:handle_request():146] handle_request: defer
2024-01-30 16:15:29,863 INFO    HandlerThread:1134336 [handler.py:handle_request_defer():172] handle defer: 0
2024-01-30 16:15:29,863 DEBUG   SenderThread:1134336 [sender.py:send_request():409] send_request: defer
2024-01-30 16:15:29,863 INFO    SenderThread:1134336 [sender.py:send_request_defer():613] handle sender defer: 0
2024-01-30 16:15:29,864 INFO    SenderThread:1134336 [sender.py:transition_state():617] send defer: 1
2024-01-30 16:15:29,864 DEBUG   HandlerThread:1134336 [handler.py:handle_request():146] handle_request: defer
2024-01-30 16:15:29,864 INFO    HandlerThread:1134336 [handler.py:handle_request_defer():172] handle defer: 1
2024-01-30 16:15:29,864 DEBUG   SenderThread:1134336 [sender.py:send_request():409] send_request: defer
2024-01-30 16:15:29,864 INFO    SenderThread:1134336 [sender.py:send_request_defer():613] handle sender defer: 1
2024-01-30 16:15:29,864 INFO    SenderThread:1134336 [sender.py:transition_state():617] send defer: 2
2024-01-30 16:15:29,864 DEBUG   HandlerThread:1134336 [handler.py:handle_request():146] handle_request: defer
2024-01-30 16:15:29,864 INFO    HandlerThread:1134336 [handler.py:handle_request_defer():172] handle defer: 2
2024-01-30 16:15:29,864 INFO    HandlerThread:1134336 [system_monitor.py:finish():203] Stopping system monitor
2024-01-30 16:15:29,864 DEBUG   SystemMonitor:1134336 [system_monitor.py:_start():179] Finished system metrics aggregation loop
2024-01-30 16:15:29,864 DEBUG   SystemMonitor:1134336 [system_monitor.py:_start():183] Publishing last batch of metrics
2024-01-30 16:15:29,867 INFO    HandlerThread:1134336 [interfaces.py:finish():202] Joined cpu monitor
2024-01-30 16:15:29,867 INFO    HandlerThread:1134336 [interfaces.py:finish():202] Joined disk monitor
2024-01-30 16:15:30,566 INFO    Thread-12 :1134336 [dir_watcher.py:_on_file_modified():288] file/dir modified: /home/yanxindong/mkor/bert/wandb/run-20240130_161012-b793ft22/files/output.log
2024-01-30 16:15:30,567 INFO    Thread-12 :1134336 [dir_watcher.py:_on_file_created():271] file/dir created: /home/yanxindong/mkor/bert/wandb/run-20240130_161012-b793ft22/files/wandb-summary.json
2024-01-30 16:15:44,888 INFO    HandlerThread:1134336 [interfaces.py:finish():202] Joined gpu monitor
2024-01-30 16:15:44,889 INFO    HandlerThread:1134336 [interfaces.py:finish():202] Joined memory monitor
2024-01-30 16:15:44,889 INFO    HandlerThread:1134336 [interfaces.py:finish():202] Joined network monitor
2024-01-30 16:15:44,889 DEBUG   HandlerThread:1134336 [handler.py:handle_request():146] handle_request: poll_exit
2024-01-30 16:15:44,889 DEBUG   HandlerThread:1134336 [handler.py:handle_request():146] handle_request: status_report
2024-01-30 16:15:44,889 DEBUG   HandlerThread:1134336 [handler.py:handle_request():146] handle_request: keepalive
2024-01-30 16:15:44,889 DEBUG   HandlerThread:1134336 [handler.py:handle_request():146] handle_request: status_report
2024-01-30 16:15:44,889 DEBUG   HandlerThread:1134336 [handler.py:handle_request():146] handle_request: keepalive
2024-01-30 16:15:44,889 DEBUG   HandlerThread:1134336 [handler.py:handle_request():146] handle_request: status_report
2024-01-30 16:15:44,890 DEBUG   SenderThread:1134336 [sender.py:send_request():409] send_request: defer
2024-01-30 16:15:44,890 INFO    SenderThread:1134336 [sender.py:send_request_defer():613] handle sender defer: 2
2024-01-30 16:15:44,890 INFO    SenderThread:1134336 [sender.py:transition_state():617] send defer: 3
2024-01-30 16:15:44,890 DEBUG   SenderThread:1134336 [sender.py:send():382] send: stats
2024-01-30 16:15:44,891 DEBUG   SenderThread:1134336 [sender.py:send_request():409] send_request: poll_exit
2024-01-30 16:15:44,894 DEBUG   HandlerThread:1134336 [handler.py:handle_request():146] handle_request: defer
2024-01-30 16:15:44,895 INFO    HandlerThread:1134336 [handler.py:handle_request_defer():172] handle defer: 3
2024-01-30 16:15:44,895 DEBUG   SenderThread:1134336 [sender.py:send_request():409] send_request: defer
2024-01-30 16:15:44,895 INFO    SenderThread:1134336 [sender.py:send_request_defer():613] handle sender defer: 3
2024-01-30 16:15:44,895 INFO    SenderThread:1134336 [sender.py:transition_state():617] send defer: 4
2024-01-30 16:15:44,895 DEBUG   HandlerThread:1134336 [handler.py:handle_request():146] handle_request: defer
2024-01-30 16:15:44,895 INFO    HandlerThread:1134336 [handler.py:handle_request_defer():172] handle defer: 4
2024-01-30 16:15:44,895 DEBUG   SenderThread:1134336 [sender.py:send_request():409] send_request: defer
2024-01-30 16:15:44,895 INFO    SenderThread:1134336 [sender.py:send_request_defer():613] handle sender defer: 4
2024-01-30 16:15:44,895 INFO    SenderThread:1134336 [sender.py:transition_state():617] send defer: 5
2024-01-30 16:15:44,895 DEBUG   HandlerThread:1134336 [handler.py:handle_request():146] handle_request: defer
2024-01-30 16:15:44,895 INFO    HandlerThread:1134336 [handler.py:handle_request_defer():172] handle defer: 5
2024-01-30 16:15:44,895 DEBUG   SenderThread:1134336 [sender.py:send():382] send: summary
2024-01-30 16:15:44,896 INFO    SenderThread:1134336 [sender.py:_save_file():1403] saving file wandb-summary.json with policy end
2024-01-30 16:15:44,896 DEBUG   SenderThread:1134336 [sender.py:send_request():409] send_request: defer
2024-01-30 16:15:44,896 INFO    SenderThread:1134336 [sender.py:send_request_defer():613] handle sender defer: 5
2024-01-30 16:15:44,896 INFO    SenderThread:1134336 [sender.py:transition_state():617] send defer: 6
2024-01-30 16:15:44,896 DEBUG   HandlerThread:1134336 [handler.py:handle_request():146] handle_request: defer
2024-01-30 16:15:44,896 INFO    HandlerThread:1134336 [handler.py:handle_request_defer():172] handle defer: 6
2024-01-30 16:15:44,896 DEBUG   SenderThread:1134336 [sender.py:send_request():409] send_request: defer
2024-01-30 16:15:44,896 INFO    SenderThread:1134336 [sender.py:send_request_defer():613] handle sender defer: 6
2024-01-30 16:15:44,897 INFO    SenderThread:1134336 [sender.py:transition_state():617] send defer: 7
2024-01-30 16:15:44,897 DEBUG   HandlerThread:1134336 [handler.py:handle_request():146] handle_request: status_report
2024-01-30 16:15:44,897 DEBUG   HandlerThread:1134336 [handler.py:handle_request():146] handle_request: defer
2024-01-30 16:15:44,897 INFO    HandlerThread:1134336 [handler.py:handle_request_defer():172] handle defer: 7
2024-01-30 16:15:44,897 DEBUG   SenderThread:1134336 [sender.py:send_request():409] send_request: defer
2024-01-30 16:15:44,897 INFO    SenderThread:1134336 [sender.py:send_request_defer():613] handle sender defer: 7
2024-01-30 16:15:45,042 DEBUG   HandlerThread:1134336 [handler.py:handle_request():146] handle_request: poll_exit
2024-01-30 16:15:45,851 INFO    Thread-12 :1134336 [dir_watcher.py:_on_file_modified():288] file/dir modified: /home/yanxindong/mkor/bert/wandb/run-20240130_161012-b793ft22/files/wandb-summary.json
2024-01-30 16:15:46,592 INFO    SenderThread:1134336 [sender.py:transition_state():617] send defer: 8
2024-01-30 16:15:46,592 DEBUG   SenderThread:1134336 [sender.py:send_request():409] send_request: poll_exit
2024-01-30 16:15:46,592 DEBUG   HandlerThread:1134336 [handler.py:handle_request():146] handle_request: defer
2024-01-30 16:15:46,592 INFO    HandlerThread:1134336 [handler.py:handle_request_defer():172] handle defer: 8
2024-01-30 16:15:46,592 DEBUG   SenderThread:1134336 [sender.py:send_request():409] send_request: defer
2024-01-30 16:15:46,592 INFO    SenderThread:1134336 [sender.py:send_request_defer():613] handle sender defer: 8
2024-01-30 16:15:46,593 INFO    SenderThread:1134336 [job_builder.py:build():296] Attempting to build job artifact
2024-01-30 16:15:46,593 INFO    SenderThread:1134336 [job_builder.py:_get_source_type():426] is repo sourced job
2024-01-30 16:15:46,852 INFO    Thread-12 :1134336 [dir_watcher.py:_on_file_modified():288] file/dir modified: /home/yanxindong/mkor/bert/wandb/run-20240130_161012-b793ft22/files/output.log
2024-01-30 16:15:46,956 INFO    SenderThread:1134336 [job_builder.py:build():402] adding wandb-job metadata file
2024-01-30 16:15:46,959 INFO    SenderThread:1134336 [sender.py:transition_state():617] send defer: 9
2024-01-30 16:15:46,959 DEBUG   HandlerThread:1134336 [handler.py:handle_request():146] handle_request: defer
2024-01-30 16:15:46,959 INFO    HandlerThread:1134336 [handler.py:handle_request_defer():172] handle defer: 9
2024-01-30 16:15:46,960 DEBUG   SenderThread:1134336 [sender.py:send():382] send: artifact
2024-01-30 16:15:47,043 DEBUG   HandlerThread:1134336 [handler.py:handle_request():146] handle_request: poll_exit
2024-01-30 16:15:48,784 ERROR   wandb-upload_1:1134336 [internal_api.py:upload_file():2765] upload_file exception https://storage.googleapis.com/wandb-artifacts-prod/wandb_artifacts/133981200/707679855/174a3d9bc61fec126cc7d5bdff5c6c5a?Expires=1706688948&GoogleAccessId=gorilla-files-url-signer-man%40wandb-production.iam.gserviceaccount.com&Signature=u%2BCUYnh%2FDljt0walWlrYbjZVLuTPFwTaOFdcUM5pAJDYH6OtsDS6u7RwqtzbNJD6RtkwT1cc2pplIXCd56wmeAhfW0dGEHpgsKDZKoLKXAmFy%2B7Xj4dTCtrEF1xPnfL34E%2BcMm3LEEPakQyH6aimmCiR6Cz53VtGN3P1o6WwOIVLDVQCkB4UXgWknVwK5YDom6WvXajMQmuVmYOVhPvgjAeiV6cr4pyi%2FteDB9Z7%2B59ZkjkZ956mAgmeZjyGnWkXqI35mUiWX%2BcLOOxu%2BvBXnqX9SV7ZxdLHhzSsuYunOaXUDPdw7hXWd6%2F2UmTdZfbawSHlj3P%2By%2FH2ZzkoLfk0aw%3D%3D: HTTPSConnectionPool(host='storage.googleapis.com', port=443): Max retries exceeded with url: /wandb-artifacts-prod/wandb_artifacts/133981200/707679855/174a3d9bc61fec126cc7d5bdff5c6c5a?Expires=1706688948&GoogleAccessId=gorilla-files-url-signer-man%40wandb-production.iam.gserviceaccount.com&Signature=u%2BCUYnh%2FDljt0walWlrYbjZVLuTPFwTaOFdcUM5pAJDYH6OtsDS6u7RwqtzbNJD6RtkwT1cc2pplIXCd56wmeAhfW0dGEHpgsKDZKoLKXAmFy%2B7Xj4dTCtrEF1xPnfL34E%2BcMm3LEEPakQyH6aimmCiR6Cz53VtGN3P1o6WwOIVLDVQCkB4UXgWknVwK5YDom6WvXajMQmuVmYOVhPvgjAeiV6cr4pyi%2FteDB9Z7%2B59ZkjkZ956mAgmeZjyGnWkXqI35mUiWX%2BcLOOxu%2BvBXnqX9SV7ZxdLHhzSsuYunOaXUDPdw7hXWd6%2F2UmTdZfbawSHlj3P%2By%2FH2ZzkoLfk0aw%3D%3D (Caused by NewConnectionError('<urllib3.connection.HTTPSConnection object at 0x7f9eb442b460>: Failed to establish a new connection: [Errno 101] Network is unreachable'))
2024-01-30 16:15:48,784 ERROR   wandb-upload_1:1134336 [internal_api.py:upload_file():2767] upload_file request headers: {'User-Agent': 'python-requests/2.23.0', 'Accept-Encoding': 'gzip, deflate', 'Accept': '*/*', 'Connection': 'keep-alive', 'Content-MD5': 'F0o9m8Yf7BJsx9W9/1xsWg==', 'Content-Type': 'text/plain; charset=utf-8', 'Content-Length': '2179'}
2024-01-30 16:15:48,784 ERROR   wandb-upload_1:1134336 [internal_api.py:upload_file():2769] upload_file response body: 
2024-01-30 16:15:49,375 ERROR   wandb-upload_2:1134336 [internal_api.py:upload_file():2765] upload_file exception https://storage.googleapis.com/wandb-artifacts-prod/wandb_artifacts/133981200/707679855/6873c23a2381d1524249eb1a948a45a5?Expires=1706688949&GoogleAccessId=gorilla-files-url-signer-man%40wandb-production.iam.gserviceaccount.com&Signature=MWNcFNPi%2Fyyg1Xup6XMuAp1Ok4jfdLm3oSNtxmzyEY1f0jHWXyUSc2PkNQLP%2BI7iHTDM2IaW7%2FUPkxROerlg632E%2FexKjST9Ap%2BM4xbvtS%2FMHcYeqH2sRz8Ffq%2BMV%2BPJiua3cOHT%2BekCLcDJWCbgHFyjh88Acd6ayedFYlwVnxZyi%2FmQ7Qly%2F3zxka8vQM1AtK0LxJrphC81EgCP63k7wqyVCgrmuBy9ZybeZauD%2FBvuWtKtSBVYz8Rybzgw9oVwoGsebKpLNv1M2WJkGmdH2nX7Gjyzl6%2BM4q1JaQ5UP5XGUp9q6RZ%2FcqEpq32GkGVkMWWsrfzKEdSTRV64ectXKg%3D%3D: HTTPSConnectionPool(host='storage.googleapis.com', port=443): Max retries exceeded with url: /wandb-artifacts-prod/wandb_artifacts/133981200/707679855/6873c23a2381d1524249eb1a948a45a5?Expires=1706688949&GoogleAccessId=gorilla-files-url-signer-man%40wandb-production.iam.gserviceaccount.com&Signature=MWNcFNPi%2Fyyg1Xup6XMuAp1Ok4jfdLm3oSNtxmzyEY1f0jHWXyUSc2PkNQLP%2BI7iHTDM2IaW7%2FUPkxROerlg632E%2FexKjST9Ap%2BM4xbvtS%2FMHcYeqH2sRz8Ffq%2BMV%2BPJiua3cOHT%2BekCLcDJWCbgHFyjh88Acd6ayedFYlwVnxZyi%2FmQ7Qly%2F3zxka8vQM1AtK0LxJrphC81EgCP63k7wqyVCgrmuBy9ZybeZauD%2FBvuWtKtSBVYz8Rybzgw9oVwoGsebKpLNv1M2WJkGmdH2nX7Gjyzl6%2BM4q1JaQ5UP5XGUp9q6RZ%2FcqEpq32GkGVkMWWsrfzKEdSTRV64ectXKg%3D%3D (Caused by NewConnectionError('<urllib3.connection.HTTPSConnection object at 0x7f9eb442b9a0>: Failed to establish a new connection: [Errno 101] Network is unreachable'))
2024-01-30 16:15:49,375 ERROR   wandb-upload_2:1134336 [internal_api.py:upload_file():2767] upload_file request headers: {'User-Agent': 'python-requests/2.23.0', 'Accept-Encoding': 'gzip, deflate', 'Accept': '*/*', 'Connection': 'keep-alive', 'Content-MD5': 'aHPCOiOB0VJCSesalIpFpQ==', 'Content-Type': 'application/json', 'Content-Length': '609'}
2024-01-30 16:15:49,375 ERROR   wandb-upload_2:1134336 [internal_api.py:upload_file():2769] upload_file response body: 
2024-01-30 16:15:49,970 ERROR   wandb-upload_1:1134336 [internal_api.py:upload_file():2765] upload_file exception https://storage.googleapis.com/wandb-artifacts-prod/wandb_artifacts/133981200/707679855/174a3d9bc61fec126cc7d5bdff5c6c5a?Expires=1706688948&GoogleAccessId=gorilla-files-url-signer-man%40wandb-production.iam.gserviceaccount.com&Signature=u%2BCUYnh%2FDljt0walWlrYbjZVLuTPFwTaOFdcUM5pAJDYH6OtsDS6u7RwqtzbNJD6RtkwT1cc2pplIXCd56wmeAhfW0dGEHpgsKDZKoLKXAmFy%2B7Xj4dTCtrEF1xPnfL34E%2BcMm3LEEPakQyH6aimmCiR6Cz53VtGN3P1o6WwOIVLDVQCkB4UXgWknVwK5YDom6WvXajMQmuVmYOVhPvgjAeiV6cr4pyi%2FteDB9Z7%2B59ZkjkZ956mAgmeZjyGnWkXqI35mUiWX%2BcLOOxu%2BvBXnqX9SV7ZxdLHhzSsuYunOaXUDPdw7hXWd6%2F2UmTdZfbawSHlj3P%2By%2FH2ZzkoLfk0aw%3D%3D: HTTPSConnectionPool(host='storage.googleapis.com', port=443): Max retries exceeded with url: /wandb-artifacts-prod/wandb_artifacts/133981200/707679855/174a3d9bc61fec126cc7d5bdff5c6c5a?Expires=1706688948&GoogleAccessId=gorilla-files-url-signer-man%40wandb-production.iam.gserviceaccount.com&Signature=u%2BCUYnh%2FDljt0walWlrYbjZVLuTPFwTaOFdcUM5pAJDYH6OtsDS6u7RwqtzbNJD6RtkwT1cc2pplIXCd56wmeAhfW0dGEHpgsKDZKoLKXAmFy%2B7Xj4dTCtrEF1xPnfL34E%2BcMm3LEEPakQyH6aimmCiR6Cz53VtGN3P1o6WwOIVLDVQCkB4UXgWknVwK5YDom6WvXajMQmuVmYOVhPvgjAeiV6cr4pyi%2FteDB9Z7%2B59ZkjkZ956mAgmeZjyGnWkXqI35mUiWX%2BcLOOxu%2BvBXnqX9SV7ZxdLHhzSsuYunOaXUDPdw7hXWd6%2F2UmTdZfbawSHlj3P%2By%2FH2ZzkoLfk0aw%3D%3D (Caused by NewConnectionError('<urllib3.connection.HTTPSConnection object at 0x7f9eb435aa00>: Failed to establish a new connection: [Errno 101] Network is unreachable'))
2024-01-30 16:15:49,970 ERROR   wandb-upload_1:1134336 [internal_api.py:upload_file():2767] upload_file request headers: {'User-Agent': 'python-requests/2.23.0', 'Accept-Encoding': 'gzip, deflate', 'Accept': '*/*', 'Connection': 'keep-alive', 'Content-MD5': 'F0o9m8Yf7BJsx9W9/1xsWg==', 'Content-Type': 'text/plain; charset=utf-8', 'Content-Length': '2179'}
2024-01-30 16:15:49,970 ERROR   wandb-upload_1:1134336 [internal_api.py:upload_file():2769] upload_file response body: 
2024-01-30 16:15:50,618 ERROR   wandb-upload_2:1134336 [internal_api.py:upload_file():2765] upload_file exception https://storage.googleapis.com/wandb-artifacts-prod/wandb_artifacts/133981200/707679855/6873c23a2381d1524249eb1a948a45a5?Expires=1706688949&GoogleAccessId=gorilla-files-url-signer-man%40wandb-production.iam.gserviceaccount.com&Signature=MWNcFNPi%2Fyyg1Xup6XMuAp1Ok4jfdLm3oSNtxmzyEY1f0jHWXyUSc2PkNQLP%2BI7iHTDM2IaW7%2FUPkxROerlg632E%2FexKjST9Ap%2BM4xbvtS%2FMHcYeqH2sRz8Ffq%2BMV%2BPJiua3cOHT%2BekCLcDJWCbgHFyjh88Acd6ayedFYlwVnxZyi%2FmQ7Qly%2F3zxka8vQM1AtK0LxJrphC81EgCP63k7wqyVCgrmuBy9ZybeZauD%2FBvuWtKtSBVYz8Rybzgw9oVwoGsebKpLNv1M2WJkGmdH2nX7Gjyzl6%2BM4q1JaQ5UP5XGUp9q6RZ%2FcqEpq32GkGVkMWWsrfzKEdSTRV64ectXKg%3D%3D: HTTPSConnectionPool(host='storage.googleapis.com', port=443): Max retries exceeded with url: /wandb-artifacts-prod/wandb_artifacts/133981200/707679855/6873c23a2381d1524249eb1a948a45a5?Expires=1706688949&GoogleAccessId=gorilla-files-url-signer-man%40wandb-production.iam.gserviceaccount.com&Signature=MWNcFNPi%2Fyyg1Xup6XMuAp1Ok4jfdLm3oSNtxmzyEY1f0jHWXyUSc2PkNQLP%2BI7iHTDM2IaW7%2FUPkxROerlg632E%2FexKjST9Ap%2BM4xbvtS%2FMHcYeqH2sRz8Ffq%2BMV%2BPJiua3cOHT%2BekCLcDJWCbgHFyjh88Acd6ayedFYlwVnxZyi%2FmQ7Qly%2F3zxka8vQM1AtK0LxJrphC81EgCP63k7wqyVCgrmuBy9ZybeZauD%2FBvuWtKtSBVYz8Rybzgw9oVwoGsebKpLNv1M2WJkGmdH2nX7Gjyzl6%2BM4q1JaQ5UP5XGUp9q6RZ%2FcqEpq32GkGVkMWWsrfzKEdSTRV64ectXKg%3D%3D (Caused by NewConnectionError('<urllib3.connection.HTTPSConnection object at 0x7f9eb42aac40>: Failed to establish a new connection: [Errno 101] Network is unreachable'))
2024-01-30 16:15:50,618 ERROR   wandb-upload_2:1134336 [internal_api.py:upload_file():2767] upload_file request headers: {'User-Agent': 'python-requests/2.23.0', 'Accept-Encoding': 'gzip, deflate', 'Accept': '*/*', 'Connection': 'keep-alive', 'Content-MD5': 'aHPCOiOB0VJCSesalIpFpQ==', 'Content-Type': 'application/json', 'Content-Length': '609'}
2024-01-30 16:15:50,618 ERROR   wandb-upload_2:1134336 [internal_api.py:upload_file():2769] upload_file response body: 
2024-01-30 16:15:50,618 INFO    wandb-upload_2:1134336 [retry.py:__call__():172] Retry attempt failed:
Traceback (most recent call last):
  File "/home/yanxindong/anaconda/envs/eva/lib/python3.8/site-packages/urllib3/connection.py", line 159, in _new_conn
    conn = connection.create_connection(
  File "/home/yanxindong/anaconda/envs/eva/lib/python3.8/site-packages/urllib3/util/connection.py", line 84, in create_connection
    raise err
  File "/home/yanxindong/anaconda/envs/eva/lib/python3.8/site-packages/urllib3/util/connection.py", line 74, in create_connection
    sock.connect(sa)
OSError: [Errno 101] Network is unreachable

During handling of the above exception, another exception occurred:

Traceback (most recent call last):
  File "/home/yanxindong/anaconda/envs/eva/lib/python3.8/site-packages/urllib3/connectionpool.py", line 670, in urlopen
    httplib_response = self._make_request(
  File "/home/yanxindong/anaconda/envs/eva/lib/python3.8/site-packages/urllib3/connectionpool.py", line 381, in _make_request
    self._validate_conn(conn)
  File "/home/yanxindong/anaconda/envs/eva/lib/python3.8/site-packages/urllib3/connectionpool.py", line 978, in _validate_conn
    conn.connect()
  File "/home/yanxindong/anaconda/envs/eva/lib/python3.8/site-packages/urllib3/connection.py", line 309, in connect
    conn = self._new_conn()
  File "/home/yanxindong/anaconda/envs/eva/lib/python3.8/site-packages/urllib3/connection.py", line 171, in _new_conn
    raise NewConnectionError(
urllib3.exceptions.NewConnectionError: <urllib3.connection.HTTPSConnection object at 0x7f9eb42aac40>: Failed to establish a new connection: [Errno 101] Network is unreachable

During handling of the above exception, another exception occurred:

Traceback (most recent call last):
  File "/home/yanxindong/anaconda/envs/eva/lib/python3.8/site-packages/requests/adapters.py", line 439, in send
    resp = conn.urlopen(
  File "/home/yanxindong/anaconda/envs/eva/lib/python3.8/site-packages/urllib3/connectionpool.py", line 726, in urlopen
    retries = retries.increment(
  File "/home/yanxindong/anaconda/envs/eva/lib/python3.8/site-packages/urllib3/util/retry.py", line 446, in increment
    raise MaxRetryError(_pool, url, error or ResponseError(cause))
urllib3.exceptions.MaxRetryError: HTTPSConnectionPool(host='storage.googleapis.com', port=443): Max retries exceeded with url: /wandb-artifacts-prod/wandb_artifacts/133981200/707679855/6873c23a2381d1524249eb1a948a45a5?Expires=1706688949&GoogleAccessId=gorilla-files-url-signer-man%40wandb-production.iam.gserviceaccount.com&Signature=MWNcFNPi%2Fyyg1Xup6XMuAp1Ok4jfdLm3oSNtxmzyEY1f0jHWXyUSc2PkNQLP%2BI7iHTDM2IaW7%2FUPkxROerlg632E%2FexKjST9Ap%2BM4xbvtS%2FMHcYeqH2sRz8Ffq%2BMV%2BPJiua3cOHT%2BekCLcDJWCbgHFyjh88Acd6ayedFYlwVnxZyi%2FmQ7Qly%2F3zxka8vQM1AtK0LxJrphC81EgCP63k7wqyVCgrmuBy9ZybeZauD%2FBvuWtKtSBVYz8Rybzgw9oVwoGsebKpLNv1M2WJkGmdH2nX7Gjyzl6%2BM4q1JaQ5UP5XGUp9q6RZ%2FcqEpq32GkGVkMWWsrfzKEdSTRV64ectXKg%3D%3D (Caused by NewConnectionError('<urllib3.connection.HTTPSConnection object at 0x7f9eb42aac40>: Failed to establish a new connection: [Errno 101] Network is unreachable'))

During handling of the above exception, another exception occurred:

Traceback (most recent call last):
  File "/home/yanxindong/anaconda/envs/eva/lib/python3.8/site-packages/wandb/sdk/internal/internal_api.py", line 2758, in upload_file
    response = self._upload_file_session.put(
  File "/home/yanxindong/anaconda/envs/eva/lib/python3.8/site-packages/requests/sessions.py", line 590, in put
    return self.request('PUT', url, data=data, **kwargs)
  File "/home/yanxindong/anaconda/envs/eva/lib/python3.8/site-packages/requests/sessions.py", line 530, in request
    resp = self.send(prep, **send_kwargs)
  File "/home/yanxindong/anaconda/envs/eva/lib/python3.8/site-packages/requests/sessions.py", line 643, in send
    r = adapter.send(request, **kwargs)
  File "/home/yanxindong/anaconda/envs/eva/lib/python3.8/site-packages/requests/adapters.py", line 516, in send
    raise ConnectionError(e, request=request)
requests.exceptions.ConnectionError: HTTPSConnectionPool(host='storage.googleapis.com', port=443): Max retries exceeded with url: /wandb-artifacts-prod/wandb_artifacts/133981200/707679855/6873c23a2381d1524249eb1a948a45a5?Expires=1706688949&GoogleAccessId=gorilla-files-url-signer-man%40wandb-production.iam.gserviceaccount.com&Signature=MWNcFNPi%2Fyyg1Xup6XMuAp1Ok4jfdLm3oSNtxmzyEY1f0jHWXyUSc2PkNQLP%2BI7iHTDM2IaW7%2FUPkxROerlg632E%2FexKjST9Ap%2BM4xbvtS%2FMHcYeqH2sRz8Ffq%2BMV%2BPJiua3cOHT%2BekCLcDJWCbgHFyjh88Acd6ayedFYlwVnxZyi%2FmQ7Qly%2F3zxka8vQM1AtK0LxJrphC81EgCP63k7wqyVCgrmuBy9ZybeZauD%2FBvuWtKtSBVYz8Rybzgw9oVwoGsebKpLNv1M2WJkGmdH2nX7Gjyzl6%2BM4q1JaQ5UP5XGUp9q6RZ%2FcqEpq32GkGVkMWWsrfzKEdSTRV64ectXKg%3D%3D (Caused by NewConnectionError('<urllib3.connection.HTTPSConnection object at 0x7f9eb42aac40>: Failed to establish a new connection: [Errno 101] Network is unreachable'))

During handling of the above exception, another exception occurred:

Traceback (most recent call last):
  File "/home/yanxindong/anaconda/envs/eva/lib/python3.8/site-packages/wandb/sdk/lib/retry.py", line 131, in __call__
    result = self._call_fn(*args, **kwargs)
  File "/home/yanxindong/anaconda/envs/eva/lib/python3.8/site-packages/wandb/sdk/internal/internal_api.py", line 2789, in upload_file
    raise _e.with_traceback(sys.exc_info()[2])
  File "/home/yanxindong/anaconda/envs/eva/lib/python3.8/site-packages/wandb/sdk/internal/internal_api.py", line 2758, in upload_file
    response = self._upload_file_session.put(
  File "/home/yanxindong/anaconda/envs/eva/lib/python3.8/site-packages/requests/sessions.py", line 590, in put
    return self.request('PUT', url, data=data, **kwargs)
  File "/home/yanxindong/anaconda/envs/eva/lib/python3.8/site-packages/requests/sessions.py", line 530, in request
    resp = self.send(prep, **send_kwargs)
  File "/home/yanxindong/anaconda/envs/eva/lib/python3.8/site-packages/requests/sessions.py", line 643, in send
    r = adapter.send(request, **kwargs)
  File "/home/yanxindong/anaconda/envs/eva/lib/python3.8/site-packages/requests/adapters.py", line 516, in send
    raise ConnectionError(e, request=request)
wandb.sdk.lib.retry.TransientError: None
2024-01-30 16:15:52,048 DEBUG   HandlerThread:1134336 [handler.py:handle_request():146] handle_request: keepalive
2024-01-30 16:15:52,294 ERROR   wandb-upload_1:1134336 [internal_api.py:upload_file():2765] upload_file exception https://storage.googleapis.com/wandb-artifacts-prod/wandb_artifacts/133981200/707679855/174a3d9bc61fec126cc7d5bdff5c6c5a?Expires=1706688948&GoogleAccessId=gorilla-files-url-signer-man%40wandb-production.iam.gserviceaccount.com&Signature=u%2BCUYnh%2FDljt0walWlrYbjZVLuTPFwTaOFdcUM5pAJDYH6OtsDS6u7RwqtzbNJD6RtkwT1cc2pplIXCd56wmeAhfW0dGEHpgsKDZKoLKXAmFy%2B7Xj4dTCtrEF1xPnfL34E%2BcMm3LEEPakQyH6aimmCiR6Cz53VtGN3P1o6WwOIVLDVQCkB4UXgWknVwK5YDom6WvXajMQmuVmYOVhPvgjAeiV6cr4pyi%2FteDB9Z7%2B59ZkjkZ956mAgmeZjyGnWkXqI35mUiWX%2BcLOOxu%2BvBXnqX9SV7ZxdLHhzSsuYunOaXUDPdw7hXWd6%2F2UmTdZfbawSHlj3P%2By%2FH2ZzkoLfk0aw%3D%3D: HTTPSConnectionPool(host='storage.googleapis.com', port=443): Max retries exceeded with url: /wandb-artifacts-prod/wandb_artifacts/133981200/707679855/174a3d9bc61fec126cc7d5bdff5c6c5a?Expires=1706688948&GoogleAccessId=gorilla-files-url-signer-man%40wandb-production.iam.gserviceaccount.com&Signature=u%2BCUYnh%2FDljt0walWlrYbjZVLuTPFwTaOFdcUM5pAJDYH6OtsDS6u7RwqtzbNJD6RtkwT1cc2pplIXCd56wmeAhfW0dGEHpgsKDZKoLKXAmFy%2B7Xj4dTCtrEF1xPnfL34E%2BcMm3LEEPakQyH6aimmCiR6Cz53VtGN3P1o6WwOIVLDVQCkB4UXgWknVwK5YDom6WvXajMQmuVmYOVhPvgjAeiV6cr4pyi%2FteDB9Z7%2B59ZkjkZ956mAgmeZjyGnWkXqI35mUiWX%2BcLOOxu%2BvBXnqX9SV7ZxdLHhzSsuYunOaXUDPdw7hXWd6%2F2UmTdZfbawSHlj3P%2By%2FH2ZzkoLfk0aw%3D%3D (Caused by NewConnectionError('<urllib3.connection.HTTPSConnection object at 0x7f9eb42aa790>: Failed to establish a new connection: [Errno 101] Network is unreachable'))
2024-01-30 16:15:52,294 ERROR   wandb-upload_1:1134336 [internal_api.py:upload_file():2767] upload_file request headers: {'User-Agent': 'python-requests/2.23.0', 'Accept-Encoding': 'gzip, deflate', 'Accept': '*/*', 'Connection': 'keep-alive', 'Content-MD5': 'F0o9m8Yf7BJsx9W9/1xsWg==', 'Content-Type': 'text/plain; charset=utf-8', 'Content-Length': '2179'}
2024-01-30 16:15:52,294 ERROR   wandb-upload_1:1134336 [internal_api.py:upload_file():2769] upload_file response body: 
2024-01-30 16:15:53,082 ERROR   wandb-upload_2:1134336 [internal_api.py:upload_file():2765] upload_file exception https://storage.googleapis.com/wandb-artifacts-prod/wandb_artifacts/133981200/707679855/6873c23a2381d1524249eb1a948a45a5?Expires=1706688949&GoogleAccessId=gorilla-files-url-signer-man%40wandb-production.iam.gserviceaccount.com&Signature=MWNcFNPi%2Fyyg1Xup6XMuAp1Ok4jfdLm3oSNtxmzyEY1f0jHWXyUSc2PkNQLP%2BI7iHTDM2IaW7%2FUPkxROerlg632E%2FexKjST9Ap%2BM4xbvtS%2FMHcYeqH2sRz8Ffq%2BMV%2BPJiua3cOHT%2BekCLcDJWCbgHFyjh88Acd6ayedFYlwVnxZyi%2FmQ7Qly%2F3zxka8vQM1AtK0LxJrphC81EgCP63k7wqyVCgrmuBy9ZybeZauD%2FBvuWtKtSBVYz8Rybzgw9oVwoGsebKpLNv1M2WJkGmdH2nX7Gjyzl6%2BM4q1JaQ5UP5XGUp9q6RZ%2FcqEpq32GkGVkMWWsrfzKEdSTRV64ectXKg%3D%3D: HTTPSConnectionPool(host='storage.googleapis.com', port=443): Max retries exceeded with url: /wandb-artifacts-prod/wandb_artifacts/133981200/707679855/6873c23a2381d1524249eb1a948a45a5?Expires=1706688949&GoogleAccessId=gorilla-files-url-signer-man%40wandb-production.iam.gserviceaccount.com&Signature=MWNcFNPi%2Fyyg1Xup6XMuAp1Ok4jfdLm3oSNtxmzyEY1f0jHWXyUSc2PkNQLP%2BI7iHTDM2IaW7%2FUPkxROerlg632E%2FexKjST9Ap%2BM4xbvtS%2FMHcYeqH2sRz8Ffq%2BMV%2BPJiua3cOHT%2BekCLcDJWCbgHFyjh88Acd6ayedFYlwVnxZyi%2FmQ7Qly%2F3zxka8vQM1AtK0LxJrphC81EgCP63k7wqyVCgrmuBy9ZybeZauD%2FBvuWtKtSBVYz8Rybzgw9oVwoGsebKpLNv1M2WJkGmdH2nX7Gjyzl6%2BM4q1JaQ5UP5XGUp9q6RZ%2FcqEpq32GkGVkMWWsrfzKEdSTRV64ectXKg%3D%3D (Caused by NewConnectionError('<urllib3.connection.HTTPSConnection object at 0x7f9eb42aa610>: Failed to establish a new connection: [Errno 101] Network is unreachable'))
2024-01-30 16:15:53,082 ERROR   wandb-upload_2:1134336 [internal_api.py:upload_file():2767] upload_file request headers: {'User-Agent': 'python-requests/2.23.0', 'Accept-Encoding': 'gzip, deflate', 'Accept': '*/*', 'Connection': 'keep-alive', 'Content-MD5': 'aHPCOiOB0VJCSesalIpFpQ==', 'Content-Type': 'application/json', 'Content-Length': '609'}
2024-01-30 16:15:53,082 ERROR   wandb-upload_2:1134336 [internal_api.py:upload_file():2769] upload_file response body: 
2024-01-30 16:15:56,554 ERROR   wandb-upload_1:1134336 [internal_api.py:upload_file():2765] upload_file exception https://storage.googleapis.com/wandb-artifacts-prod/wandb_artifacts/133981200/707679855/174a3d9bc61fec126cc7d5bdff5c6c5a?Expires=1706688948&GoogleAccessId=gorilla-files-url-signer-man%40wandb-production.iam.gserviceaccount.com&Signature=u%2BCUYnh%2FDljt0walWlrYbjZVLuTPFwTaOFdcUM5pAJDYH6OtsDS6u7RwqtzbNJD6RtkwT1cc2pplIXCd56wmeAhfW0dGEHpgsKDZKoLKXAmFy%2B7Xj4dTCtrEF1xPnfL34E%2BcMm3LEEPakQyH6aimmCiR6Cz53VtGN3P1o6WwOIVLDVQCkB4UXgWknVwK5YDom6WvXajMQmuVmYOVhPvgjAeiV6cr4pyi%2FteDB9Z7%2B59ZkjkZ956mAgmeZjyGnWkXqI35mUiWX%2BcLOOxu%2BvBXnqX9SV7ZxdLHhzSsuYunOaXUDPdw7hXWd6%2F2UmTdZfbawSHlj3P%2By%2FH2ZzkoLfk0aw%3D%3D: HTTPSConnectionPool(host='storage.googleapis.com', port=443): Max retries exceeded with url: /wandb-artifacts-prod/wandb_artifacts/133981200/707679855/174a3d9bc61fec126cc7d5bdff5c6c5a?Expires=1706688948&GoogleAccessId=gorilla-files-url-signer-man%40wandb-production.iam.gserviceaccount.com&Signature=u%2BCUYnh%2FDljt0walWlrYbjZVLuTPFwTaOFdcUM5pAJDYH6OtsDS6u7RwqtzbNJD6RtkwT1cc2pplIXCd56wmeAhfW0dGEHpgsKDZKoLKXAmFy%2B7Xj4dTCtrEF1xPnfL34E%2BcMm3LEEPakQyH6aimmCiR6Cz53VtGN3P1o6WwOIVLDVQCkB4UXgWknVwK5YDom6WvXajMQmuVmYOVhPvgjAeiV6cr4pyi%2FteDB9Z7%2B59ZkjkZ956mAgmeZjyGnWkXqI35mUiWX%2BcLOOxu%2BvBXnqX9SV7ZxdLHhzSsuYunOaXUDPdw7hXWd6%2F2UmTdZfbawSHlj3P%2By%2FH2ZzkoLfk0aw%3D%3D (Caused by NewConnectionError('<urllib3.connection.HTTPSConnection object at 0x7f9eb442bb80>: Failed to establish a new connection: [Errno 101] Network is unreachable'))
2024-01-30 16:15:56,554 ERROR   wandb-upload_1:1134336 [internal_api.py:upload_file():2767] upload_file request headers: {'User-Agent': 'python-requests/2.23.0', 'Accept-Encoding': 'gzip, deflate', 'Accept': '*/*', 'Connection': 'keep-alive', 'Content-MD5': 'F0o9m8Yf7BJsx9W9/1xsWg==', 'Content-Type': 'text/plain; charset=utf-8', 'Content-Length': '2179'}
2024-01-30 16:15:56,554 ERROR   wandb-upload_1:1134336 [internal_api.py:upload_file():2769] upload_file response body: 
2024-01-30 16:15:57,049 DEBUG   HandlerThread:1134336 [handler.py:handle_request():146] handle_request: keepalive
2024-01-30 16:15:57,658 ERROR   wandb-upload_2:1134336 [internal_api.py:upload_file():2765] upload_file exception https://storage.googleapis.com/wandb-artifacts-prod/wandb_artifacts/133981200/707679855/6873c23a2381d1524249eb1a948a45a5?Expires=1706688949&GoogleAccessId=gorilla-files-url-signer-man%40wandb-production.iam.gserviceaccount.com&Signature=MWNcFNPi%2Fyyg1Xup6XMuAp1Ok4jfdLm3oSNtxmzyEY1f0jHWXyUSc2PkNQLP%2BI7iHTDM2IaW7%2FUPkxROerlg632E%2FexKjST9Ap%2BM4xbvtS%2FMHcYeqH2sRz8Ffq%2BMV%2BPJiua3cOHT%2BekCLcDJWCbgHFyjh88Acd6ayedFYlwVnxZyi%2FmQ7Qly%2F3zxka8vQM1AtK0LxJrphC81EgCP63k7wqyVCgrmuBy9ZybeZauD%2FBvuWtKtSBVYz8Rybzgw9oVwoGsebKpLNv1M2WJkGmdH2nX7Gjyzl6%2BM4q1JaQ5UP5XGUp9q6RZ%2FcqEpq32GkGVkMWWsrfzKEdSTRV64ectXKg%3D%3D: HTTPSConnectionPool(host='storage.googleapis.com', port=443): Max retries exceeded with url: /wandb-artifacts-prod/wandb_artifacts/133981200/707679855/6873c23a2381d1524249eb1a948a45a5?Expires=1706688949&GoogleAccessId=gorilla-files-url-signer-man%40wandb-production.iam.gserviceaccount.com&Signature=MWNcFNPi%2Fyyg1Xup6XMuAp1Ok4jfdLm3oSNtxmzyEY1f0jHWXyUSc2PkNQLP%2BI7iHTDM2IaW7%2FUPkxROerlg632E%2FexKjST9Ap%2BM4xbvtS%2FMHcYeqH2sRz8Ffq%2BMV%2BPJiua3cOHT%2BekCLcDJWCbgHFyjh88Acd6ayedFYlwVnxZyi%2FmQ7Qly%2F3zxka8vQM1AtK0LxJrphC81EgCP63k7wqyVCgrmuBy9ZybeZauD%2FBvuWtKtSBVYz8Rybzgw9oVwoGsebKpLNv1M2WJkGmdH2nX7Gjyzl6%2BM4q1JaQ5UP5XGUp9q6RZ%2FcqEpq32GkGVkMWWsrfzKEdSTRV64ectXKg%3D%3D (Caused by NewConnectionError('<urllib3.connection.HTTPSConnection object at 0x7f9eb42aa970>: Failed to establish a new connection: [Errno 101] Network is unreachable'))
2024-01-30 16:15:57,658 ERROR   wandb-upload_2:1134336 [internal_api.py:upload_file():2767] upload_file request headers: {'User-Agent': 'python-requests/2.23.0', 'Accept-Encoding': 'gzip, deflate', 'Accept': '*/*', 'Connection': 'keep-alive', 'Content-MD5': 'aHPCOiOB0VJCSesalIpFpQ==', 'Content-Type': 'application/json', 'Content-Length': '609'}
2024-01-30 16:15:57,658 ERROR   wandb-upload_2:1134336 [internal_api.py:upload_file():2769] upload_file response body: 
2024-01-30 16:16:02,051 DEBUG   HandlerThread:1134336 [handler.py:handle_request():146] handle_request: keepalive
2024-01-30 16:16:06,138 ERROR   wandb-upload_1:1134336 [internal_api.py:upload_file():2765] upload_file exception https://storage.googleapis.com/wandb-artifacts-prod/wandb_artifacts/133981200/707679855/174a3d9bc61fec126cc7d5bdff5c6c5a?Expires=1706688948&GoogleAccessId=gorilla-files-url-signer-man%40wandb-production.iam.gserviceaccount.com&Signature=u%2BCUYnh%2FDljt0walWlrYbjZVLuTPFwTaOFdcUM5pAJDYH6OtsDS6u7RwqtzbNJD6RtkwT1cc2pplIXCd56wmeAhfW0dGEHpgsKDZKoLKXAmFy%2B7Xj4dTCtrEF1xPnfL34E%2BcMm3LEEPakQyH6aimmCiR6Cz53VtGN3P1o6WwOIVLDVQCkB4UXgWknVwK5YDom6WvXajMQmuVmYOVhPvgjAeiV6cr4pyi%2FteDB9Z7%2B59ZkjkZ956mAgmeZjyGnWkXqI35mUiWX%2BcLOOxu%2BvBXnqX9SV7ZxdLHhzSsuYunOaXUDPdw7hXWd6%2F2UmTdZfbawSHlj3P%2By%2FH2ZzkoLfk0aw%3D%3D: HTTPSConnectionPool(host='storage.googleapis.com', port=443): Max retries exceeded with url: /wandb-artifacts-prod/wandb_artifacts/133981200/707679855/174a3d9bc61fec126cc7d5bdff5c6c5a?Expires=1706688948&GoogleAccessId=gorilla-files-url-signer-man%40wandb-production.iam.gserviceaccount.com&Signature=u%2BCUYnh%2FDljt0walWlrYbjZVLuTPFwTaOFdcUM5pAJDYH6OtsDS6u7RwqtzbNJD6RtkwT1cc2pplIXCd56wmeAhfW0dGEHpgsKDZKoLKXAmFy%2B7Xj4dTCtrEF1xPnfL34E%2BcMm3LEEPakQyH6aimmCiR6Cz53VtGN3P1o6WwOIVLDVQCkB4UXgWknVwK5YDom6WvXajMQmuVmYOVhPvgjAeiV6cr4pyi%2FteDB9Z7%2B59ZkjkZ956mAgmeZjyGnWkXqI35mUiWX%2BcLOOxu%2BvBXnqX9SV7ZxdLHhzSsuYunOaXUDPdw7hXWd6%2F2UmTdZfbawSHlj3P%2By%2FH2ZzkoLfk0aw%3D%3D (Caused by NewConnectionError('<urllib3.connection.HTTPSConnection object at 0x7f9eb435a580>: Failed to establish a new connection: [Errno 101] Network is unreachable'))
2024-01-30 16:16:06,139 ERROR   wandb-upload_1:1134336 [internal_api.py:upload_file():2767] upload_file request headers: {'User-Agent': 'python-requests/2.23.0', 'Accept-Encoding': 'gzip, deflate', 'Accept': '*/*', 'Connection': 'keep-alive', 'Content-MD5': 'F0o9m8Yf7BJsx9W9/1xsWg==', 'Content-Type': 'text/plain; charset=utf-8', 'Content-Length': '2179'}
2024-01-30 16:16:06,139 ERROR   wandb-upload_1:1134336 [internal_api.py:upload_file():2769] upload_file response body: 
2024-01-30 16:16:07,052 DEBUG   HandlerThread:1134336 [handler.py:handle_request():146] handle_request: keepalive
2024-01-30 16:16:07,640 ERROR   wandb-upload_2:1134336 [internal_api.py:upload_file():2765] upload_file exception https://storage.googleapis.com/wandb-artifacts-prod/wandb_artifacts/133981200/707679855/6873c23a2381d1524249eb1a948a45a5?Expires=1706688949&GoogleAccessId=gorilla-files-url-signer-man%40wandb-production.iam.gserviceaccount.com&Signature=MWNcFNPi%2Fyyg1Xup6XMuAp1Ok4jfdLm3oSNtxmzyEY1f0jHWXyUSc2PkNQLP%2BI7iHTDM2IaW7%2FUPkxROerlg632E%2FexKjST9Ap%2BM4xbvtS%2FMHcYeqH2sRz8Ffq%2BMV%2BPJiua3cOHT%2BekCLcDJWCbgHFyjh88Acd6ayedFYlwVnxZyi%2FmQ7Qly%2F3zxka8vQM1AtK0LxJrphC81EgCP63k7wqyVCgrmuBy9ZybeZauD%2FBvuWtKtSBVYz8Rybzgw9oVwoGsebKpLNv1M2WJkGmdH2nX7Gjyzl6%2BM4q1JaQ5UP5XGUp9q6RZ%2FcqEpq32GkGVkMWWsrfzKEdSTRV64ectXKg%3D%3D: HTTPSConnectionPool(host='storage.googleapis.com', port=443): Max retries exceeded with url: /wandb-artifacts-prod/wandb_artifacts/133981200/707679855/6873c23a2381d1524249eb1a948a45a5?Expires=1706688949&GoogleAccessId=gorilla-files-url-signer-man%40wandb-production.iam.gserviceaccount.com&Signature=MWNcFNPi%2Fyyg1Xup6XMuAp1Ok4jfdLm3oSNtxmzyEY1f0jHWXyUSc2PkNQLP%2BI7iHTDM2IaW7%2FUPkxROerlg632E%2FexKjST9Ap%2BM4xbvtS%2FMHcYeqH2sRz8Ffq%2BMV%2BPJiua3cOHT%2BekCLcDJWCbgHFyjh88Acd6ayedFYlwVnxZyi%2FmQ7Qly%2F3zxka8vQM1AtK0LxJrphC81EgCP63k7wqyVCgrmuBy9ZybeZauD%2FBvuWtKtSBVYz8Rybzgw9oVwoGsebKpLNv1M2WJkGmdH2nX7Gjyzl6%2BM4q1JaQ5UP5XGUp9q6RZ%2FcqEpq32GkGVkMWWsrfzKEdSTRV64ectXKg%3D%3D (Caused by NewConnectionError('<urllib3.connection.HTTPSConnection object at 0x7f9eb435a2b0>: Failed to establish a new connection: [Errno 101] Network is unreachable'))
2024-01-30 16:16:07,640 ERROR   wandb-upload_2:1134336 [internal_api.py:upload_file():2767] upload_file request headers: {'User-Agent': 'python-requests/2.23.0', 'Accept-Encoding': 'gzip, deflate', 'Accept': '*/*', 'Connection': 'keep-alive', 'Content-MD5': 'aHPCOiOB0VJCSesalIpFpQ==', 'Content-Type': 'application/json', 'Content-Length': '609'}
2024-01-30 16:16:07,640 ERROR   wandb-upload_2:1134336 [internal_api.py:upload_file():2769] upload_file response body: 
2024-01-30 16:16:12,054 DEBUG   HandlerThread:1134336 [handler.py:handle_request():146] handle_request: keepalive
2024-01-30 16:16:17,056 DEBUG   HandlerThread:1134336 [handler.py:handle_request():146] handle_request: keepalive
2024-01-30 16:16:22,058 DEBUG   HandlerThread:1134336 [handler.py:handle_request():146] handle_request: keepalive
2024-01-30 16:16:23,882 ERROR   wandb-upload_2:1134336 [internal_api.py:upload_file():2765] upload_file exception https://storage.googleapis.com/wandb-artifacts-prod/wandb_artifacts/133981200/707679855/6873c23a2381d1524249eb1a948a45a5?Expires=1706688949&GoogleAccessId=gorilla-files-url-signer-man%40wandb-production.iam.gserviceaccount.com&Signature=MWNcFNPi%2Fyyg1Xup6XMuAp1Ok4jfdLm3oSNtxmzyEY1f0jHWXyUSc2PkNQLP%2BI7iHTDM2IaW7%2FUPkxROerlg632E%2FexKjST9Ap%2BM4xbvtS%2FMHcYeqH2sRz8Ffq%2BMV%2BPJiua3cOHT%2BekCLcDJWCbgHFyjh88Acd6ayedFYlwVnxZyi%2FmQ7Qly%2F3zxka8vQM1AtK0LxJrphC81EgCP63k7wqyVCgrmuBy9ZybeZauD%2FBvuWtKtSBVYz8Rybzgw9oVwoGsebKpLNv1M2WJkGmdH2nX7Gjyzl6%2BM4q1JaQ5UP5XGUp9q6RZ%2FcqEpq32GkGVkMWWsrfzKEdSTRV64ectXKg%3D%3D: HTTPSConnectionPool(host='storage.googleapis.com', port=443): Max retries exceeded with url: /wandb-artifacts-prod/wandb_artifacts/133981200/707679855/6873c23a2381d1524249eb1a948a45a5?Expires=1706688949&GoogleAccessId=gorilla-files-url-signer-man%40wandb-production.iam.gserviceaccount.com&Signature=MWNcFNPi%2Fyyg1Xup6XMuAp1Ok4jfdLm3oSNtxmzyEY1f0jHWXyUSc2PkNQLP%2BI7iHTDM2IaW7%2FUPkxROerlg632E%2FexKjST9Ap%2BM4xbvtS%2FMHcYeqH2sRz8Ffq%2BMV%2BPJiua3cOHT%2BekCLcDJWCbgHFyjh88Acd6ayedFYlwVnxZyi%2FmQ7Qly%2F3zxka8vQM1AtK0LxJrphC81EgCP63k7wqyVCgrmuBy9ZybeZauD%2FBvuWtKtSBVYz8Rybzgw9oVwoGsebKpLNv1M2WJkGmdH2nX7Gjyzl6%2BM4q1JaQ5UP5XGUp9q6RZ%2FcqEpq32GkGVkMWWsrfzKEdSTRV64ectXKg%3D%3D (Caused by NewConnectionError('<urllib3.connection.HTTPSConnection object at 0x7f9eb42729a0>: Failed to establish a new connection: [Errno 101] Network is unreachable'))
2024-01-30 16:16:23,882 ERROR   wandb-upload_2:1134336 [internal_api.py:upload_file():2767] upload_file request headers: {'User-Agent': 'python-requests/2.23.0', 'Accept-Encoding': 'gzip, deflate', 'Accept': '*/*', 'Connection': 'keep-alive', 'Content-MD5': 'aHPCOiOB0VJCSesalIpFpQ==', 'Content-Type': 'application/json', 'Content-Length': '609'}
2024-01-30 16:16:23,882 ERROR   wandb-upload_2:1134336 [internal_api.py:upload_file():2769] upload_file response body: 
2024-01-30 16:16:25,779 ERROR   wandb-upload_1:1134336 [internal_api.py:upload_file():2765] upload_file exception https://storage.googleapis.com/wandb-artifacts-prod/wandb_artifacts/133981200/707679855/174a3d9bc61fec126cc7d5bdff5c6c5a?Expires=1706688948&GoogleAccessId=gorilla-files-url-signer-man%40wandb-production.iam.gserviceaccount.com&Signature=u%2BCUYnh%2FDljt0walWlrYbjZVLuTPFwTaOFdcUM5pAJDYH6OtsDS6u7RwqtzbNJD6RtkwT1cc2pplIXCd56wmeAhfW0dGEHpgsKDZKoLKXAmFy%2B7Xj4dTCtrEF1xPnfL34E%2BcMm3LEEPakQyH6aimmCiR6Cz53VtGN3P1o6WwOIVLDVQCkB4UXgWknVwK5YDom6WvXajMQmuVmYOVhPvgjAeiV6cr4pyi%2FteDB9Z7%2B59ZkjkZ956mAgmeZjyGnWkXqI35mUiWX%2BcLOOxu%2BvBXnqX9SV7ZxdLHhzSsuYunOaXUDPdw7hXWd6%2F2UmTdZfbawSHlj3P%2By%2FH2ZzkoLfk0aw%3D%3D: HTTPSConnectionPool(host='storage.googleapis.com', port=443): Max retries exceeded with url: /wandb-artifacts-prod/wandb_artifacts/133981200/707679855/174a3d9bc61fec126cc7d5bdff5c6c5a?Expires=1706688948&GoogleAccessId=gorilla-files-url-signer-man%40wandb-production.iam.gserviceaccount.com&Signature=u%2BCUYnh%2FDljt0walWlrYbjZVLuTPFwTaOFdcUM5pAJDYH6OtsDS6u7RwqtzbNJD6RtkwT1cc2pplIXCd56wmeAhfW0dGEHpgsKDZKoLKXAmFy%2B7Xj4dTCtrEF1xPnfL34E%2BcMm3LEEPakQyH6aimmCiR6Cz53VtGN3P1o6WwOIVLDVQCkB4UXgWknVwK5YDom6WvXajMQmuVmYOVhPvgjAeiV6cr4pyi%2FteDB9Z7%2B59ZkjkZ956mAgmeZjyGnWkXqI35mUiWX%2BcLOOxu%2BvBXnqX9SV7ZxdLHhzSsuYunOaXUDPdw7hXWd6%2F2UmTdZfbawSHlj3P%2By%2FH2ZzkoLfk0aw%3D%3D (Caused by NewConnectionError('<urllib3.connection.HTTPSConnection object at 0x7f9eb4272f10>: Failed to establish a new connection: [Errno 101] Network is unreachable'))
2024-01-30 16:16:25,779 ERROR   wandb-upload_1:1134336 [internal_api.py:upload_file():2767] upload_file request headers: {'User-Agent': 'python-requests/2.23.0', 'Accept-Encoding': 'gzip, deflate', 'Accept': '*/*', 'Connection': 'keep-alive', 'Content-MD5': 'F0o9m8Yf7BJsx9W9/1xsWg==', 'Content-Type': 'text/plain; charset=utf-8', 'Content-Length': '2179'}
2024-01-30 16:16:25,779 ERROR   wandb-upload_1:1134336 [internal_api.py:upload_file():2769] upload_file response body: 
2024-01-30 16:16:27,060 DEBUG   HandlerThread:1134336 [handler.py:handle_request():146] handle_request: keepalive
2024-01-30 16:16:32,062 DEBUG   HandlerThread:1134336 [handler.py:handle_request():146] handle_request: keepalive
2024-01-30 16:16:37,064 DEBUG   HandlerThread:1134336 [handler.py:handle_request():146] handle_request: keepalive
2024-01-30 16:16:42,066 DEBUG   HandlerThread:1134336 [handler.py:handle_request():146] handle_request: keepalive
2024-01-30 16:16:47,068 DEBUG   HandlerThread:1134336 [handler.py:handle_request():146] handle_request: keepalive
2024-01-30 16:16:52,071 DEBUG   HandlerThread:1134336 [handler.py:handle_request():146] handle_request: keepalive
2024-01-30 16:16:57,073 DEBUG   HandlerThread:1134336 [handler.py:handle_request():146] handle_request: keepalive
2024-01-30 16:16:58,468 ERROR   wandb-upload_1:1134336 [internal_api.py:upload_file():2765] upload_file exception https://storage.googleapis.com/wandb-artifacts-prod/wandb_artifacts/133981200/707679855/174a3d9bc61fec126cc7d5bdff5c6c5a?Expires=1706688948&GoogleAccessId=gorilla-files-url-signer-man%40wandb-production.iam.gserviceaccount.com&Signature=u%2BCUYnh%2FDljt0walWlrYbjZVLuTPFwTaOFdcUM5pAJDYH6OtsDS6u7RwqtzbNJD6RtkwT1cc2pplIXCd56wmeAhfW0dGEHpgsKDZKoLKXAmFy%2B7Xj4dTCtrEF1xPnfL34E%2BcMm3LEEPakQyH6aimmCiR6Cz53VtGN3P1o6WwOIVLDVQCkB4UXgWknVwK5YDom6WvXajMQmuVmYOVhPvgjAeiV6cr4pyi%2FteDB9Z7%2B59ZkjkZ956mAgmeZjyGnWkXqI35mUiWX%2BcLOOxu%2BvBXnqX9SV7ZxdLHhzSsuYunOaXUDPdw7hXWd6%2F2UmTdZfbawSHlj3P%2By%2FH2ZzkoLfk0aw%3D%3D: HTTPSConnectionPool(host='storage.googleapis.com', port=443): Max retries exceeded with url: /wandb-artifacts-prod/wandb_artifacts/133981200/707679855/174a3d9bc61fec126cc7d5bdff5c6c5a?Expires=1706688948&GoogleAccessId=gorilla-files-url-signer-man%40wandb-production.iam.gserviceaccount.com&Signature=u%2BCUYnh%2FDljt0walWlrYbjZVLuTPFwTaOFdcUM5pAJDYH6OtsDS6u7RwqtzbNJD6RtkwT1cc2pplIXCd56wmeAhfW0dGEHpgsKDZKoLKXAmFy%2B7Xj4dTCtrEF1xPnfL34E%2BcMm3LEEPakQyH6aimmCiR6Cz53VtGN3P1o6WwOIVLDVQCkB4UXgWknVwK5YDom6WvXajMQmuVmYOVhPvgjAeiV6cr4pyi%2FteDB9Z7%2B59ZkjkZ956mAgmeZjyGnWkXqI35mUiWX%2BcLOOxu%2BvBXnqX9SV7ZxdLHhzSsuYunOaXUDPdw7hXWd6%2F2UmTdZfbawSHlj3P%2By%2FH2ZzkoLfk0aw%3D%3D (Caused by NewConnectionError('<urllib3.connection.HTTPSConnection object at 0x7f9eb4272e20>: Failed to establish a new connection: [Errno 101] Network is unreachable'))
2024-01-30 16:16:58,468 ERROR   wandb-upload_1:1134336 [internal_api.py:upload_file():2767] upload_file request headers: {'User-Agent': 'python-requests/2.23.0', 'Accept-Encoding': 'gzip, deflate', 'Accept': '*/*', 'Connection': 'keep-alive', 'Content-MD5': 'F0o9m8Yf7BJsx9W9/1xsWg==', 'Content-Type': 'text/plain; charset=utf-8', 'Content-Length': '2179'}
2024-01-30 16:16:58,468 ERROR   wandb-upload_1:1134336 [internal_api.py:upload_file():2769] upload_file response body: 
2024-01-30 16:16:58,863 ERROR   wandb-upload_2:1134336 [internal_api.py:upload_file():2765] upload_file exception https://storage.googleapis.com/wandb-artifacts-prod/wandb_artifacts/133981200/707679855/6873c23a2381d1524249eb1a948a45a5?Expires=1706688949&GoogleAccessId=gorilla-files-url-signer-man%40wandb-production.iam.gserviceaccount.com&Signature=MWNcFNPi%2Fyyg1Xup6XMuAp1Ok4jfdLm3oSNtxmzyEY1f0jHWXyUSc2PkNQLP%2BI7iHTDM2IaW7%2FUPkxROerlg632E%2FexKjST9Ap%2BM4xbvtS%2FMHcYeqH2sRz8Ffq%2BMV%2BPJiua3cOHT%2BekCLcDJWCbgHFyjh88Acd6ayedFYlwVnxZyi%2FmQ7Qly%2F3zxka8vQM1AtK0LxJrphC81EgCP63k7wqyVCgrmuBy9ZybeZauD%2FBvuWtKtSBVYz8Rybzgw9oVwoGsebKpLNv1M2WJkGmdH2nX7Gjyzl6%2BM4q1JaQ5UP5XGUp9q6RZ%2FcqEpq32GkGVkMWWsrfzKEdSTRV64ectXKg%3D%3D: HTTPSConnectionPool(host='storage.googleapis.com', port=443): Max retries exceeded with url: /wandb-artifacts-prod/wandb_artifacts/133981200/707679855/6873c23a2381d1524249eb1a948a45a5?Expires=1706688949&GoogleAccessId=gorilla-files-url-signer-man%40wandb-production.iam.gserviceaccount.com&Signature=MWNcFNPi%2Fyyg1Xup6XMuAp1Ok4jfdLm3oSNtxmzyEY1f0jHWXyUSc2PkNQLP%2BI7iHTDM2IaW7%2FUPkxROerlg632E%2FexKjST9Ap%2BM4xbvtS%2FMHcYeqH2sRz8Ffq%2BMV%2BPJiua3cOHT%2BekCLcDJWCbgHFyjh88Acd6ayedFYlwVnxZyi%2FmQ7Qly%2F3zxka8vQM1AtK0LxJrphC81EgCP63k7wqyVCgrmuBy9ZybeZauD%2FBvuWtKtSBVYz8Rybzgw9oVwoGsebKpLNv1M2WJkGmdH2nX7Gjyzl6%2BM4q1JaQ5UP5XGUp9q6RZ%2FcqEpq32GkGVkMWWsrfzKEdSTRV64ectXKg%3D%3D (Caused by NewConnectionError('<urllib3.connection.HTTPSConnection object at 0x7f9eb4272af0>: Failed to establish a new connection: [Errno 101] Network is unreachable'))
2024-01-30 16:16:58,863 ERROR   wandb-upload_2:1134336 [internal_api.py:upload_file():2767] upload_file request headers: {'User-Agent': 'python-requests/2.23.0', 'Accept-Encoding': 'gzip, deflate', 'Accept': '*/*', 'Connection': 'keep-alive', 'Content-MD5': 'aHPCOiOB0VJCSesalIpFpQ==', 'Content-Type': 'application/json', 'Content-Length': '609'}
2024-01-30 16:16:58,863 ERROR   wandb-upload_2:1134336 [internal_api.py:upload_file():2769] upload_file response body: 
2024-01-30 16:17:02,075 DEBUG   HandlerThread:1134336 [handler.py:handle_request():146] handle_request: keepalive
2024-01-30 16:17:07,083 DEBUG   HandlerThread:1134336 [handler.py:handle_request():146] handle_request: keepalive
2024-01-30 16:17:12,085 DEBUG   HandlerThread:1134336 [handler.py:handle_request():146] handle_request: keepalive
2024-01-30 16:17:17,087 DEBUG   HandlerThread:1134336 [handler.py:handle_request():146] handle_request: keepalive
2024-01-30 16:17:22,089 DEBUG   HandlerThread:1134336 [handler.py:handle_request():146] handle_request: keepalive
2024-01-30 16:17:27,091 DEBUG   HandlerThread:1134336 [handler.py:handle_request():146] handle_request: keepalive
2024-01-30 16:17:32,093 DEBUG   HandlerThread:1134336 [handler.py:handle_request():146] handle_request: keepalive
2024-01-30 16:17:37,096 DEBUG   HandlerThread:1134336 [handler.py:handle_request():146] handle_request: keepalive
2024-01-30 16:17:42,098 DEBUG   HandlerThread:1134336 [handler.py:handle_request():146] handle_request: keepalive
2024-01-30 16:17:47,100 DEBUG   HandlerThread:1134336 [handler.py:handle_request():146] handle_request: keepalive
2024-01-30 16:17:52,103 DEBUG   HandlerThread:1134336 [handler.py:handle_request():146] handle_request: keepalive
2024-01-30 16:18:04,037 ERROR   wandb-upload_1:1134336 [internal_api.py:upload_file():2765] upload_file exception https://storage.googleapis.com/wandb-artifacts-prod/wandb_artifacts/133981200/707679855/174a3d9bc61fec126cc7d5bdff5c6c5a?Expires=1706688948&GoogleAccessId=gorilla-files-url-signer-man%40wandb-production.iam.gserviceaccount.com&Signature=u%2BCUYnh%2FDljt0walWlrYbjZVLuTPFwTaOFdcUM5pAJDYH6OtsDS6u7RwqtzbNJD6RtkwT1cc2pplIXCd56wmeAhfW0dGEHpgsKDZKoLKXAmFy%2B7Xj4dTCtrEF1xPnfL34E%2BcMm3LEEPakQyH6aimmCiR6Cz53VtGN3P1o6WwOIVLDVQCkB4UXgWknVwK5YDom6WvXajMQmuVmYOVhPvgjAeiV6cr4pyi%2FteDB9Z7%2B59ZkjkZ956mAgmeZjyGnWkXqI35mUiWX%2BcLOOxu%2BvBXnqX9SV7ZxdLHhzSsuYunOaXUDPdw7hXWd6%2F2UmTdZfbawSHlj3P%2By%2FH2ZzkoLfk0aw%3D%3D: HTTPSConnectionPool(host='storage.googleapis.com', port=443): Max retries exceeded with url: /wandb-artifacts-prod/wandb_artifacts/133981200/707679855/174a3d9bc61fec126cc7d5bdff5c6c5a?Expires=1706688948&GoogleAccessId=gorilla-files-url-signer-man%40wandb-production.iam.gserviceaccount.com&Signature=u%2BCUYnh%2FDljt0walWlrYbjZVLuTPFwTaOFdcUM5pAJDYH6OtsDS6u7RwqtzbNJD6RtkwT1cc2pplIXCd56wmeAhfW0dGEHpgsKDZKoLKXAmFy%2B7Xj4dTCtrEF1xPnfL34E%2BcMm3LEEPakQyH6aimmCiR6Cz53VtGN3P1o6WwOIVLDVQCkB4UXgWknVwK5YDom6WvXajMQmuVmYOVhPvgjAeiV6cr4pyi%2FteDB9Z7%2B59ZkjkZ956mAgmeZjyGnWkXqI35mUiWX%2BcLOOxu%2BvBXnqX9SV7ZxdLHhzSsuYunOaXUDPdw7hXWd6%2F2UmTdZfbawSHlj3P%2By%2FH2ZzkoLfk0aw%3D%3D (Caused by NewConnectionError('<urllib3.connection.HTTPSConnection object at 0x7f9eb426a4c0>: Failed to establish a new connection: [Errno 101] Network is unreachable'))
2024-01-30 16:18:04,037 ERROR   wandb-upload_1:1134336 [internal_api.py:upload_file():2767] upload_file request headers: {'User-Agent': 'python-requests/2.23.0', 'Accept-Encoding': 'gzip, deflate', 'Accept': '*/*', 'Connection': 'keep-alive', 'Content-MD5': 'F0o9m8Yf7BJsx9W9/1xsWg==', 'Content-Type': 'text/plain; charset=utf-8', 'Content-Length': '2179'}
2024-01-30 16:18:04,037 ERROR   wandb-upload_1:1134336 [internal_api.py:upload_file():2769] upload_file response body: 
2024-01-30 16:18:07,592 ERROR   wandb-upload_2:1134336 [internal_api.py:upload_file():2765] upload_file exception https://storage.googleapis.com/wandb-artifacts-prod/wandb_artifacts/133981200/707679855/6873c23a2381d1524249eb1a948a45a5?Expires=1706688949&GoogleAccessId=gorilla-files-url-signer-man%40wandb-production.iam.gserviceaccount.com&Signature=MWNcFNPi%2Fyyg1Xup6XMuAp1Ok4jfdLm3oSNtxmzyEY1f0jHWXyUSc2PkNQLP%2BI7iHTDM2IaW7%2FUPkxROerlg632E%2FexKjST9Ap%2BM4xbvtS%2FMHcYeqH2sRz8Ffq%2BMV%2BPJiua3cOHT%2BekCLcDJWCbgHFyjh88Acd6ayedFYlwVnxZyi%2FmQ7Qly%2F3zxka8vQM1AtK0LxJrphC81EgCP63k7wqyVCgrmuBy9ZybeZauD%2FBvuWtKtSBVYz8Rybzgw9oVwoGsebKpLNv1M2WJkGmdH2nX7Gjyzl6%2BM4q1JaQ5UP5XGUp9q6RZ%2FcqEpq32GkGVkMWWsrfzKEdSTRV64ectXKg%3D%3D: HTTPSConnectionPool(host='storage.googleapis.com', port=443): Max retries exceeded with url: /wandb-artifacts-prod/wandb_artifacts/133981200/707679855/6873c23a2381d1524249eb1a948a45a5?Expires=1706688949&GoogleAccessId=gorilla-files-url-signer-man%40wandb-production.iam.gserviceaccount.com&Signature=MWNcFNPi%2Fyyg1Xup6XMuAp1Ok4jfdLm3oSNtxmzyEY1f0jHWXyUSc2PkNQLP%2BI7iHTDM2IaW7%2FUPkxROerlg632E%2FexKjST9Ap%2BM4xbvtS%2FMHcYeqH2sRz8Ffq%2BMV%2BPJiua3cOHT%2BekCLcDJWCbgHFyjh88Acd6ayedFYlwVnxZyi%2FmQ7Qly%2F3zxka8vQM1AtK0LxJrphC81EgCP63k7wqyVCgrmuBy9ZybeZauD%2FBvuWtKtSBVYz8Rybzgw9oVwoGsebKpLNv1M2WJkGmdH2nX7Gjyzl6%2BM4q1JaQ5UP5XGUp9q6RZ%2FcqEpq32GkGVkMWWsrfzKEdSTRV64ectXKg%3D%3D (Caused by NewConnectionError('<urllib3.connection.HTTPSConnection object at 0x7f9eb426a700>: Failed to establish a new connection: [Errno 101] Network is unreachable'))
2024-01-30 16:18:07,592 ERROR   wandb-upload_2:1134336 [internal_api.py:upload_file():2767] upload_file request headers: {'User-Agent': 'python-requests/2.23.0', 'Accept-Encoding': 'gzip, deflate', 'Accept': '*/*', 'Connection': 'keep-alive', 'Content-MD5': 'aHPCOiOB0VJCSesalIpFpQ==', 'Content-Type': 'application/json', 'Content-Length': '609'}
2024-01-30 16:18:07,592 ERROR   wandb-upload_2:1134336 [internal_api.py:upload_file():2769] upload_file response body: 
2024-01-30 16:20:17,120 ERROR   wandb-upload_1:1134336 [internal_api.py:upload_file():2765] upload_file exception https://storage.googleapis.com/wandb-artifacts-prod/wandb_artifacts/133981200/707679855/174a3d9bc61fec126cc7d5bdff5c6c5a?Expires=1706688948&GoogleAccessId=gorilla-files-url-signer-man%40wandb-production.iam.gserviceaccount.com&Signature=u%2BCUYnh%2FDljt0walWlrYbjZVLuTPFwTaOFdcUM5pAJDYH6OtsDS6u7RwqtzbNJD6RtkwT1cc2pplIXCd56wmeAhfW0dGEHpgsKDZKoLKXAmFy%2B7Xj4dTCtrEF1xPnfL34E%2BcMm3LEEPakQyH6aimmCiR6Cz53VtGN3P1o6WwOIVLDVQCkB4UXgWknVwK5YDom6WvXajMQmuVmYOVhPvgjAeiV6cr4pyi%2FteDB9Z7%2B59ZkjkZ956mAgmeZjyGnWkXqI35mUiWX%2BcLOOxu%2BvBXnqX9SV7ZxdLHhzSsuYunOaXUDPdw7hXWd6%2F2UmTdZfbawSHlj3P%2By%2FH2ZzkoLfk0aw%3D%3D: HTTPSConnectionPool(host='storage.googleapis.com', port=443): Max retries exceeded with url: /wandb-artifacts-prod/wandb_artifacts/133981200/707679855/174a3d9bc61fec126cc7d5bdff5c6c5a?Expires=1706688948&GoogleAccessId=gorilla-files-url-signer-man%40wandb-production.iam.gserviceaccount.com&Signature=u%2BCUYnh%2FDljt0walWlrYbjZVLuTPFwTaOFdcUM5pAJDYH6OtsDS6u7RwqtzbNJD6RtkwT1cc2pplIXCd56wmeAhfW0dGEHpgsKDZKoLKXAmFy%2B7Xj4dTCtrEF1xPnfL34E%2BcMm3LEEPakQyH6aimmCiR6Cz53VtGN3P1o6WwOIVLDVQCkB4UXgWknVwK5YDom6WvXajMQmuVmYOVhPvgjAeiV6cr4pyi%2FteDB9Z7%2B59ZkjkZ956mAgmeZjyGnWkXqI35mUiWX%2BcLOOxu%2BvBXnqX9SV7ZxdLHhzSsuYunOaXUDPdw7hXWd6%2F2UmTdZfbawSHlj3P%2By%2FH2ZzkoLfk0aw%3D%3D (Caused by NewConnectionError('<urllib3.connection.HTTPSConnection object at 0x7f9eb426d520>: Failed to establish a new connection: [Errno 111] Connection refused'))
2024-01-30 16:20:17,120 ERROR   wandb-upload_1:1134336 [internal_api.py:upload_file():2767] upload_file request headers: {'User-Agent': 'python-requests/2.23.0', 'Accept-Encoding': 'gzip, deflate', 'Accept': '*/*', 'Connection': 'keep-alive', 'Content-MD5': 'F0o9m8Yf7BJsx9W9/1xsWg==', 'Content-Type': 'text/plain; charset=utf-8', 'Content-Length': '2179'}
2024-01-30 16:20:17,120 ERROR   wandb-upload_1:1134336 [internal_api.py:upload_file():2769] upload_file response body: 
2024-01-30 16:20:40,826 ERROR   wandb-upload_2:1134336 [internal_api.py:upload_file():2765] upload_file exception https://storage.googleapis.com/wandb-artifacts-prod/wandb_artifacts/133981200/707679855/6873c23a2381d1524249eb1a948a45a5?Expires=1706688949&GoogleAccessId=gorilla-files-url-signer-man%40wandb-production.iam.gserviceaccount.com&Signature=MWNcFNPi%2Fyyg1Xup6XMuAp1Ok4jfdLm3oSNtxmzyEY1f0jHWXyUSc2PkNQLP%2BI7iHTDM2IaW7%2FUPkxROerlg632E%2FexKjST9Ap%2BM4xbvtS%2FMHcYeqH2sRz8Ffq%2BMV%2BPJiua3cOHT%2BekCLcDJWCbgHFyjh88Acd6ayedFYlwVnxZyi%2FmQ7Qly%2F3zxka8vQM1AtK0LxJrphC81EgCP63k7wqyVCgrmuBy9ZybeZauD%2FBvuWtKtSBVYz8Rybzgw9oVwoGsebKpLNv1M2WJkGmdH2nX7Gjyzl6%2BM4q1JaQ5UP5XGUp9q6RZ%2FcqEpq32GkGVkMWWsrfzKEdSTRV64ectXKg%3D%3D: HTTPSConnectionPool(host='storage.googleapis.com', port=443): Max retries exceeded with url: /wandb-artifacts-prod/wandb_artifacts/133981200/707679855/6873c23a2381d1524249eb1a948a45a5?Expires=1706688949&GoogleAccessId=gorilla-files-url-signer-man%40wandb-production.iam.gserviceaccount.com&Signature=MWNcFNPi%2Fyyg1Xup6XMuAp1Ok4jfdLm3oSNtxmzyEY1f0jHWXyUSc2PkNQLP%2BI7iHTDM2IaW7%2FUPkxROerlg632E%2FexKjST9Ap%2BM4xbvtS%2FMHcYeqH2sRz8Ffq%2BMV%2BPJiua3cOHT%2BekCLcDJWCbgHFyjh88Acd6ayedFYlwVnxZyi%2FmQ7Qly%2F3zxka8vQM1AtK0LxJrphC81EgCP63k7wqyVCgrmuBy9ZybeZauD%2FBvuWtKtSBVYz8Rybzgw9oVwoGsebKpLNv1M2WJkGmdH2nX7Gjyzl6%2BM4q1JaQ5UP5XGUp9q6RZ%2FcqEpq32GkGVkMWWsrfzKEdSTRV64ectXKg%3D%3D (Caused by NewConnectionError('<urllib3.connection.HTTPSConnection object at 0x7f9eb4272700>: Failed to establish a new connection: [Errno 101] Network is unreachable'))
2024-01-30 16:20:40,827 ERROR   wandb-upload_2:1134336 [internal_api.py:upload_file():2767] upload_file request headers: {'User-Agent': 'python-requests/2.23.0', 'Accept-Encoding': 'gzip, deflate', 'Accept': '*/*', 'Connection': 'keep-alive', 'Content-MD5': 'aHPCOiOB0VJCSesalIpFpQ==', 'Content-Type': 'application/json', 'Content-Length': '609'}
2024-01-30 16:20:40,827 ERROR   wandb-upload_2:1134336 [internal_api.py:upload_file():2769] upload_file response body: 
2024-01-30 16:24:36,373 ERROR   wandb-upload_1:1134336 [internal_api.py:upload_file():2765] upload_file exception https://storage.googleapis.com/wandb-artifacts-prod/wandb_artifacts/133981200/707679855/174a3d9bc61fec126cc7d5bdff5c6c5a?Expires=1706688948&GoogleAccessId=gorilla-files-url-signer-man%40wandb-production.iam.gserviceaccount.com&Signature=u%2BCUYnh%2FDljt0walWlrYbjZVLuTPFwTaOFdcUM5pAJDYH6OtsDS6u7RwqtzbNJD6RtkwT1cc2pplIXCd56wmeAhfW0dGEHpgsKDZKoLKXAmFy%2B7Xj4dTCtrEF1xPnfL34E%2BcMm3LEEPakQyH6aimmCiR6Cz53VtGN3P1o6WwOIVLDVQCkB4UXgWknVwK5YDom6WvXajMQmuVmYOVhPvgjAeiV6cr4pyi%2FteDB9Z7%2B59ZkjkZ956mAgmeZjyGnWkXqI35mUiWX%2BcLOOxu%2BvBXnqX9SV7ZxdLHhzSsuYunOaXUDPdw7hXWd6%2F2UmTdZfbawSHlj3P%2By%2FH2ZzkoLfk0aw%3D%3D: HTTPSConnectionPool(host='storage.googleapis.com', port=443): Max retries exceeded with url: /wandb-artifacts-prod/wandb_artifacts/133981200/707679855/174a3d9bc61fec126cc7d5bdff5c6c5a?Expires=1706688948&GoogleAccessId=gorilla-files-url-signer-man%40wandb-production.iam.gserviceaccount.com&Signature=u%2BCUYnh%2FDljt0walWlrYbjZVLuTPFwTaOFdcUM5pAJDYH6OtsDS6u7RwqtzbNJD6RtkwT1cc2pplIXCd56wmeAhfW0dGEHpgsKDZKoLKXAmFy%2B7Xj4dTCtrEF1xPnfL34E%2BcMm3LEEPakQyH6aimmCiR6Cz53VtGN3P1o6WwOIVLDVQCkB4UXgWknVwK5YDom6WvXajMQmuVmYOVhPvgjAeiV6cr4pyi%2FteDB9Z7%2B59ZkjkZ956mAgmeZjyGnWkXqI35mUiWX%2BcLOOxu%2BvBXnqX9SV7ZxdLHhzSsuYunOaXUDPdw7hXWd6%2F2UmTdZfbawSHlj3P%2By%2FH2ZzkoLfk0aw%3D%3D (Caused by NewConnectionError('<urllib3.connection.HTTPSConnection object at 0x7f9eb426a370>: Failed to establish a new connection: [Errno 111] Connection refused'))
2024-01-30 16:24:36,374 ERROR   wandb-upload_1:1134336 [internal_api.py:upload_file():2767] upload_file request headers: {'User-Agent': 'python-requests/2.23.0', 'Accept-Encoding': 'gzip, deflate', 'Accept': '*/*', 'Connection': 'keep-alive', 'Content-MD5': 'F0o9m8Yf7BJsx9W9/1xsWg==', 'Content-Type': 'text/plain; charset=utf-8', 'Content-Length': '2179'}
2024-01-30 16:24:36,374 ERROR   wandb-upload_1:1134336 [internal_api.py:upload_file():2769] upload_file response body: 
2024-01-30 16:25:17,022 ERROR   wandb-upload_2:1134336 [internal_api.py:upload_file():2765] upload_file exception https://storage.googleapis.com/wandb-artifacts-prod/wandb_artifacts/133981200/707679855/6873c23a2381d1524249eb1a948a45a5?Expires=1706688949&GoogleAccessId=gorilla-files-url-signer-man%40wandb-production.iam.gserviceaccount.com&Signature=MWNcFNPi%2Fyyg1Xup6XMuAp1Ok4jfdLm3oSNtxmzyEY1f0jHWXyUSc2PkNQLP%2BI7iHTDM2IaW7%2FUPkxROerlg632E%2FexKjST9Ap%2BM4xbvtS%2FMHcYeqH2sRz8Ffq%2BMV%2BPJiua3cOHT%2BekCLcDJWCbgHFyjh88Acd6ayedFYlwVnxZyi%2FmQ7Qly%2F3zxka8vQM1AtK0LxJrphC81EgCP63k7wqyVCgrmuBy9ZybeZauD%2FBvuWtKtSBVYz8Rybzgw9oVwoGsebKpLNv1M2WJkGmdH2nX7Gjyzl6%2BM4q1JaQ5UP5XGUp9q6RZ%2FcqEpq32GkGVkMWWsrfzKEdSTRV64ectXKg%3D%3D: HTTPSConnectionPool(host='storage.googleapis.com', port=443): Max retries exceeded with url: /wandb-artifacts-prod/wandb_artifacts/133981200/707679855/6873c23a2381d1524249eb1a948a45a5?Expires=1706688949&GoogleAccessId=gorilla-files-url-signer-man%40wandb-production.iam.gserviceaccount.com&Signature=MWNcFNPi%2Fyyg1Xup6XMuAp1Ok4jfdLm3oSNtxmzyEY1f0jHWXyUSc2PkNQLP%2BI7iHTDM2IaW7%2FUPkxROerlg632E%2FexKjST9Ap%2BM4xbvtS%2FMHcYeqH2sRz8Ffq%2BMV%2BPJiua3cOHT%2BekCLcDJWCbgHFyjh88Acd6ayedFYlwVnxZyi%2FmQ7Qly%2F3zxka8vQM1AtK0LxJrphC81EgCP63k7wqyVCgrmuBy9ZybeZauD%2FBvuWtKtSBVYz8Rybzgw9oVwoGsebKpLNv1M2WJkGmdH2nX7Gjyzl6%2BM4q1JaQ5UP5XGUp9q6RZ%2FcqEpq32GkGVkMWWsrfzKEdSTRV64ectXKg%3D%3D (Caused by NewConnectionError('<urllib3.connection.HTTPSConnection object at 0x7f9eb43516d0>: Failed to establish a new connection: [Errno 111] Connection refused'))
2024-01-30 16:25:17,022 ERROR   wandb-upload_2:1134336 [internal_api.py:upload_file():2767] upload_file request headers: {'User-Agent': 'python-requests/2.23.0', 'Accept-Encoding': 'gzip, deflate', 'Accept': '*/*', 'Connection': 'keep-alive', 'Content-MD5': 'aHPCOiOB0VJCSesalIpFpQ==', 'Content-Type': 'application/json', 'Content-Length': '609'}
2024-01-30 16:25:17,022 ERROR   wandb-upload_2:1134336 [internal_api.py:upload_file():2769] upload_file response body: 
2024-01-30 16:29:41,547 ERROR   wandb-upload_1:1134336 [internal_api.py:upload_file():2765] upload_file exception https://storage.googleapis.com/wandb-artifacts-prod/wandb_artifacts/133981200/707679855/174a3d9bc61fec126cc7d5bdff5c6c5a?Expires=1706688948&GoogleAccessId=gorilla-files-url-signer-man%40wandb-production.iam.gserviceaccount.com&Signature=u%2BCUYnh%2FDljt0walWlrYbjZVLuTPFwTaOFdcUM5pAJDYH6OtsDS6u7RwqtzbNJD6RtkwT1cc2pplIXCd56wmeAhfW0dGEHpgsKDZKoLKXAmFy%2B7Xj4dTCtrEF1xPnfL34E%2BcMm3LEEPakQyH6aimmCiR6Cz53VtGN3P1o6WwOIVLDVQCkB4UXgWknVwK5YDom6WvXajMQmuVmYOVhPvgjAeiV6cr4pyi%2FteDB9Z7%2B59ZkjkZ956mAgmeZjyGnWkXqI35mUiWX%2BcLOOxu%2BvBXnqX9SV7ZxdLHhzSsuYunOaXUDPdw7hXWd6%2F2UmTdZfbawSHlj3P%2By%2FH2ZzkoLfk0aw%3D%3D: HTTPSConnectionPool(host='storage.googleapis.com', port=443): Max retries exceeded with url: /wandb-artifacts-prod/wandb_artifacts/133981200/707679855/174a3d9bc61fec126cc7d5bdff5c6c5a?Expires=1706688948&GoogleAccessId=gorilla-files-url-signer-man%40wandb-production.iam.gserviceaccount.com&Signature=u%2BCUYnh%2FDljt0walWlrYbjZVLuTPFwTaOFdcUM5pAJDYH6OtsDS6u7RwqtzbNJD6RtkwT1cc2pplIXCd56wmeAhfW0dGEHpgsKDZKoLKXAmFy%2B7Xj4dTCtrEF1xPnfL34E%2BcMm3LEEPakQyH6aimmCiR6Cz53VtGN3P1o6WwOIVLDVQCkB4UXgWknVwK5YDom6WvXajMQmuVmYOVhPvgjAeiV6cr4pyi%2FteDB9Z7%2B59ZkjkZ956mAgmeZjyGnWkXqI35mUiWX%2BcLOOxu%2BvBXnqX9SV7ZxdLHhzSsuYunOaXUDPdw7hXWd6%2F2UmTdZfbawSHlj3P%2By%2FH2ZzkoLfk0aw%3D%3D (Caused by NewConnectionError('<urllib3.connection.HTTPSConnection object at 0x7f9eb4351670>: Failed to establish a new connection: [Errno 111] Connection refused'))
2024-01-30 16:29:41,547 ERROR   wandb-upload_1:1134336 [internal_api.py:upload_file():2767] upload_file request headers: {'User-Agent': 'python-requests/2.23.0', 'Accept-Encoding': 'gzip, deflate', 'Accept': '*/*', 'Connection': 'keep-alive', 'Content-MD5': 'F0o9m8Yf7BJsx9W9/1xsWg==', 'Content-Type': 'text/plain; charset=utf-8', 'Content-Length': '2179'}
2024-01-30 16:29:41,547 ERROR   wandb-upload_1:1134336 [internal_api.py:upload_file():2769] upload_file response body: 
2024-01-30 16:31:29,378 ERROR   wandb-upload_2:1134336 [internal_api.py:upload_file():2765] upload_file exception https://storage.googleapis.com/wandb-artifacts-prod/wandb_artifacts/133981200/707679855/6873c23a2381d1524249eb1a948a45a5?Expires=1706688949&GoogleAccessId=gorilla-files-url-signer-man%40wandb-production.iam.gserviceaccount.com&Signature=MWNcFNPi%2Fyyg1Xup6XMuAp1Ok4jfdLm3oSNtxmzyEY1f0jHWXyUSc2PkNQLP%2BI7iHTDM2IaW7%2FUPkxROerlg632E%2FexKjST9Ap%2BM4xbvtS%2FMHcYeqH2sRz8Ffq%2BMV%2BPJiua3cOHT%2BekCLcDJWCbgHFyjh88Acd6ayedFYlwVnxZyi%2FmQ7Qly%2F3zxka8vQM1AtK0LxJrphC81EgCP63k7wqyVCgrmuBy9ZybeZauD%2FBvuWtKtSBVYz8Rybzgw9oVwoGsebKpLNv1M2WJkGmdH2nX7Gjyzl6%2BM4q1JaQ5UP5XGUp9q6RZ%2FcqEpq32GkGVkMWWsrfzKEdSTRV64ectXKg%3D%3D: HTTPSConnectionPool(host='storage.googleapis.com', port=443): Max retries exceeded with url: /wandb-artifacts-prod/wandb_artifacts/133981200/707679855/6873c23a2381d1524249eb1a948a45a5?Expires=1706688949&GoogleAccessId=gorilla-files-url-signer-man%40wandb-production.iam.gserviceaccount.com&Signature=MWNcFNPi%2Fyyg1Xup6XMuAp1Ok4jfdLm3oSNtxmzyEY1f0jHWXyUSc2PkNQLP%2BI7iHTDM2IaW7%2FUPkxROerlg632E%2FexKjST9Ap%2BM4xbvtS%2FMHcYeqH2sRz8Ffq%2BMV%2BPJiua3cOHT%2BekCLcDJWCbgHFyjh88Acd6ayedFYlwVnxZyi%2FmQ7Qly%2F3zxka8vQM1AtK0LxJrphC81EgCP63k7wqyVCgrmuBy9ZybeZauD%2FBvuWtKtSBVYz8Rybzgw9oVwoGsebKpLNv1M2WJkGmdH2nX7Gjyzl6%2BM4q1JaQ5UP5XGUp9q6RZ%2FcqEpq32GkGVkMWWsrfzKEdSTRV64ectXKg%3D%3D (Caused by NewConnectionError('<urllib3.connection.HTTPSConnection object at 0x7f9eb426d6a0>: Failed to establish a new connection: [Errno 111] Connection refused'))
2024-01-30 16:31:29,378 ERROR   wandb-upload_2:1134336 [internal_api.py:upload_file():2767] upload_file request headers: {'User-Agent': 'python-requests/2.23.0', 'Accept-Encoding': 'gzip, deflate', 'Accept': '*/*', 'Connection': 'keep-alive', 'Content-MD5': 'aHPCOiOB0VJCSesalIpFpQ==', 'Content-Type': 'application/json', 'Content-Length': '609'}
2024-01-30 16:31:29,378 ERROR   wandb-upload_2:1134336 [internal_api.py:upload_file():2769] upload_file response body: 
2024-01-30 16:34:42,778 ERROR   wandb-upload_1:1134336 [internal_api.py:upload_file():2765] upload_file exception https://storage.googleapis.com/wandb-artifacts-prod/wandb_artifacts/133981200/707679855/174a3d9bc61fec126cc7d5bdff5c6c5a?Expires=1706688948&GoogleAccessId=gorilla-files-url-signer-man%40wandb-production.iam.gserviceaccount.com&Signature=u%2BCUYnh%2FDljt0walWlrYbjZVLuTPFwTaOFdcUM5pAJDYH6OtsDS6u7RwqtzbNJD6RtkwT1cc2pplIXCd56wmeAhfW0dGEHpgsKDZKoLKXAmFy%2B7Xj4dTCtrEF1xPnfL34E%2BcMm3LEEPakQyH6aimmCiR6Cz53VtGN3P1o6WwOIVLDVQCkB4UXgWknVwK5YDom6WvXajMQmuVmYOVhPvgjAeiV6cr4pyi%2FteDB9Z7%2B59ZkjkZ956mAgmeZjyGnWkXqI35mUiWX%2BcLOOxu%2BvBXnqX9SV7ZxdLHhzSsuYunOaXUDPdw7hXWd6%2F2UmTdZfbawSHlj3P%2By%2FH2ZzkoLfk0aw%3D%3D: HTTPSConnectionPool(host='storage.googleapis.com', port=443): Max retries exceeded with url: /wandb-artifacts-prod/wandb_artifacts/133981200/707679855/174a3d9bc61fec126cc7d5bdff5c6c5a?Expires=1706688948&GoogleAccessId=gorilla-files-url-signer-man%40wandb-production.iam.gserviceaccount.com&Signature=u%2BCUYnh%2FDljt0walWlrYbjZVLuTPFwTaOFdcUM5pAJDYH6OtsDS6u7RwqtzbNJD6RtkwT1cc2pplIXCd56wmeAhfW0dGEHpgsKDZKoLKXAmFy%2B7Xj4dTCtrEF1xPnfL34E%2BcMm3LEEPakQyH6aimmCiR6Cz53VtGN3P1o6WwOIVLDVQCkB4UXgWknVwK5YDom6WvXajMQmuVmYOVhPvgjAeiV6cr4pyi%2FteDB9Z7%2B59ZkjkZ956mAgmeZjyGnWkXqI35mUiWX%2BcLOOxu%2BvBXnqX9SV7ZxdLHhzSsuYunOaXUDPdw7hXWd6%2F2UmTdZfbawSHlj3P%2By%2FH2ZzkoLfk0aw%3D%3D (Caused by NewConnectionError('<urllib3.connection.HTTPSConnection object at 0x7f9eb426d4f0>: Failed to establish a new connection: [Errno 111] Connection refused'))
2024-01-30 16:34:42,779 ERROR   wandb-upload_1:1134336 [internal_api.py:upload_file():2767] upload_file request headers: {'User-Agent': 'python-requests/2.23.0', 'Accept-Encoding': 'gzip, deflate', 'Accept': '*/*', 'Connection': 'keep-alive', 'Content-MD5': 'F0o9m8Yf7BJsx9W9/1xsWg==', 'Content-Type': 'text/plain; charset=utf-8', 'Content-Length': '2179'}
2024-01-30 16:34:42,779 ERROR   wandb-upload_1:1134336 [internal_api.py:upload_file():2769] upload_file response body: 
2024-01-30 16:37:16,704 ERROR   wandb-upload_2:1134336 [internal_api.py:upload_file():2765] upload_file exception https://storage.googleapis.com/wandb-artifacts-prod/wandb_artifacts/133981200/707679855/6873c23a2381d1524249eb1a948a45a5?Expires=1706688949&GoogleAccessId=gorilla-files-url-signer-man%40wandb-production.iam.gserviceaccount.com&Signature=MWNcFNPi%2Fyyg1Xup6XMuAp1Ok4jfdLm3oSNtxmzyEY1f0jHWXyUSc2PkNQLP%2BI7iHTDM2IaW7%2FUPkxROerlg632E%2FexKjST9Ap%2BM4xbvtS%2FMHcYeqH2sRz8Ffq%2BMV%2BPJiua3cOHT%2BekCLcDJWCbgHFyjh88Acd6ayedFYlwVnxZyi%2FmQ7Qly%2F3zxka8vQM1AtK0LxJrphC81EgCP63k7wqyVCgrmuBy9ZybeZauD%2FBvuWtKtSBVYz8Rybzgw9oVwoGsebKpLNv1M2WJkGmdH2nX7Gjyzl6%2BM4q1JaQ5UP5XGUp9q6RZ%2FcqEpq32GkGVkMWWsrfzKEdSTRV64ectXKg%3D%3D: HTTPSConnectionPool(host='storage.googleapis.com', port=443): Max retries exceeded with url: /wandb-artifacts-prod/wandb_artifacts/133981200/707679855/6873c23a2381d1524249eb1a948a45a5?Expires=1706688949&GoogleAccessId=gorilla-files-url-signer-man%40wandb-production.iam.gserviceaccount.com&Signature=MWNcFNPi%2Fyyg1Xup6XMuAp1Ok4jfdLm3oSNtxmzyEY1f0jHWXyUSc2PkNQLP%2BI7iHTDM2IaW7%2FUPkxROerlg632E%2FexKjST9Ap%2BM4xbvtS%2FMHcYeqH2sRz8Ffq%2BMV%2BPJiua3cOHT%2BekCLcDJWCbgHFyjh88Acd6ayedFYlwVnxZyi%2FmQ7Qly%2F3zxka8vQM1AtK0LxJrphC81EgCP63k7wqyVCgrmuBy9ZybeZauD%2FBvuWtKtSBVYz8Rybzgw9oVwoGsebKpLNv1M2WJkGmdH2nX7Gjyzl6%2BM4q1JaQ5UP5XGUp9q6RZ%2FcqEpq32GkGVkMWWsrfzKEdSTRV64ectXKg%3D%3D (Caused by NewConnectionError('<urllib3.connection.HTTPSConnection object at 0x7f9eb42686a0>: Failed to establish a new connection: [Errno 111] Connection refused'))
2024-01-30 16:37:16,704 ERROR   wandb-upload_2:1134336 [internal_api.py:upload_file():2767] upload_file request headers: {'User-Agent': 'python-requests/2.23.0', 'Accept-Encoding': 'gzip, deflate', 'Accept': '*/*', 'Connection': 'keep-alive', 'Content-MD5': 'aHPCOiOB0VJCSesalIpFpQ==', 'Content-Type': 'application/json', 'Content-Length': '609'}
2024-01-30 16:37:16,704 ERROR   wandb-upload_2:1134336 [internal_api.py:upload_file():2769] upload_file response body: 
2024-01-30 16:37:45,220 WARNING StreamThr :1134336 [internal.py:is_dead():414] Internal process exiting, parent pid 1134042 disappeared
2024-01-30 16:37:45,221 ERROR   StreamThr :1134336 [internal.py:wandb_internal():152] Internal process shutdown.
2024-01-30 16:37:45,224 INFO    HandlerThread:1134336 [handler.py:finish():869] shutting down handler
2024-01-30 16:37:46,174 INFO    WriterThread:1134336 [datastore.py:close():296] close: /home/yanxindong/mkor/bert/wandb/run-20240130_161012-b793ft22/run-b793ft22.wandb
2024-01-30 16:40:23,896 ERROR   wandb-upload_1:1134336 [internal_api.py:upload_file():2765] upload_file exception https://storage.googleapis.com/wandb-artifacts-prod/wandb_artifacts/133981200/707679855/174a3d9bc61fec126cc7d5bdff5c6c5a?Expires=1706688948&GoogleAccessId=gorilla-files-url-signer-man%40wandb-production.iam.gserviceaccount.com&Signature=u%2BCUYnh%2FDljt0walWlrYbjZVLuTPFwTaOFdcUM5pAJDYH6OtsDS6u7RwqtzbNJD6RtkwT1cc2pplIXCd56wmeAhfW0dGEHpgsKDZKoLKXAmFy%2B7Xj4dTCtrEF1xPnfL34E%2BcMm3LEEPakQyH6aimmCiR6Cz53VtGN3P1o6WwOIVLDVQCkB4UXgWknVwK5YDom6WvXajMQmuVmYOVhPvgjAeiV6cr4pyi%2FteDB9Z7%2B59ZkjkZ956mAgmeZjyGnWkXqI35mUiWX%2BcLOOxu%2BvBXnqX9SV7ZxdLHhzSsuYunOaXUDPdw7hXWd6%2F2UmTdZfbawSHlj3P%2By%2FH2ZzkoLfk0aw%3D%3D: HTTPSConnectionPool(host='storage.googleapis.com', port=443): Max retries exceeded with url: /wandb-artifacts-prod/wandb_artifacts/133981200/707679855/174a3d9bc61fec126cc7d5bdff5c6c5a?Expires=1706688948&GoogleAccessId=gorilla-files-url-signer-man%40wandb-production.iam.gserviceaccount.com&Signature=u%2BCUYnh%2FDljt0walWlrYbjZVLuTPFwTaOFdcUM5pAJDYH6OtsDS6u7RwqtzbNJD6RtkwT1cc2pplIXCd56wmeAhfW0dGEHpgsKDZKoLKXAmFy%2B7Xj4dTCtrEF1xPnfL34E%2BcMm3LEEPakQyH6aimmCiR6Cz53VtGN3P1o6WwOIVLDVQCkB4UXgWknVwK5YDom6WvXajMQmuVmYOVhPvgjAeiV6cr4pyi%2FteDB9Z7%2B59ZkjkZ956mAgmeZjyGnWkXqI35mUiWX%2BcLOOxu%2BvBXnqX9SV7ZxdLHhzSsuYunOaXUDPdw7hXWd6%2F2UmTdZfbawSHlj3P%2By%2FH2ZzkoLfk0aw%3D%3D (Caused by NewConnectionError('<urllib3.connection.HTTPSConnection object at 0x7f9eb4268d90>: Failed to establish a new connection: [Errno 101] Network is unreachable'))
2024-01-30 16:40:23,896 ERROR   wandb-upload_1:1134336 [internal_api.py:upload_file():2767] upload_file request headers: {'User-Agent': 'python-requests/2.23.0', 'Accept-Encoding': 'gzip, deflate', 'Accept': '*/*', 'Connection': 'keep-alive', 'Content-MD5': 'F0o9m8Yf7BJsx9W9/1xsWg==', 'Content-Type': 'text/plain; charset=utf-8', 'Content-Length': '2179'}
2024-01-30 16:40:23,896 ERROR   wandb-upload_1:1134336 [internal_api.py:upload_file():2769] upload_file response body: 
2024-01-30 16:41:06,294 ERROR   wandb-upload_0:1134336 [internal_api.py:upload_file():2765] upload_file exception https://storage.googleapis.com/wandb-production.appspot.com/dynamic_x/bert_pytorch/b793ft22/wandb-metadata.json?Expires=1706688635&GoogleAccessId=gorilla-files-url-signer-man%40wandb-production.iam.gserviceaccount.com&Signature=GG9waHJzWIlSJt%2Ffs%2FHu2%2BD10Edc0UB5RwtSEHDRx5B6hSob1QIFCoc9hbhtMhww1fag62T52vRjDNqI6H2we9y%2F47axeW8khE0atCO71FwFln3XLW6SX%2FBorIN%2FS9vR2GJfixLLvA0ls47ONf9qNJnUvP1MkQ%2Ffkam%2BQNao1jVYRAB0ZTNwyJrYoCHZjvs8k7HrQ1j9sxRKSNd3WAjRUcEp3WZmAvP%2BggQej6i4pCumKL0nMtEMhagfInuyBmL8DO5GiJuz9LTMrvP3Z0mmTUgl8Ixo7cr2WSgV7CwumFq097BZFo%2FQm4MYm6rZvT%2BEHoOPLgz%2Fg%2Bb7IuLw8JgmtQ%3D%3D: HTTPSConnectionPool(host='storage.googleapis.com', port=443): Max retries exceeded with url: /wandb-production.appspot.com/dynamic_x/bert_pytorch/b793ft22/wandb-metadata.json?Expires=1706688635&GoogleAccessId=gorilla-files-url-signer-man%40wandb-production.iam.gserviceaccount.com&Signature=GG9waHJzWIlSJt%2Ffs%2FHu2%2BD10Edc0UB5RwtSEHDRx5B6hSob1QIFCoc9hbhtMhww1fag62T52vRjDNqI6H2we9y%2F47axeW8khE0atCO71FwFln3XLW6SX%2FBorIN%2FS9vR2GJfixLLvA0ls47ONf9qNJnUvP1MkQ%2Ffkam%2BQNao1jVYRAB0ZTNwyJrYoCHZjvs8k7HrQ1j9sxRKSNd3WAjRUcEp3WZmAvP%2BggQej6i4pCumKL0nMtEMhagfInuyBmL8DO5GiJuz9LTMrvP3Z0mmTUgl8Ixo7cr2WSgV7CwumFq097BZFo%2FQm4MYm6rZvT%2BEHoOPLgz%2Fg%2Bb7IuLw8JgmtQ%3D%3D (Caused by NewConnectionError('<urllib3.connection.HTTPSConnection object at 0x7f9eb442b790>: Failed to establish a new connection: [Errno 101] Network is unreachable'))
2024-01-30 16:41:06,294 ERROR   wandb-upload_0:1134336 [internal_api.py:upload_file():2767] upload_file request headers: {'User-Agent': 'python-requests/2.23.0', 'Accept-Encoding': 'gzip, deflate', 'Accept': '*/*', 'Connection': 'keep-alive', 'Content-Length': '15549'}
2024-01-30 16:41:06,294 ERROR   wandb-upload_0:1134336 [internal_api.py:upload_file():2769] upload_file response body: 
2024-01-30 16:42:48,908 ERROR   wandb-upload_2:1134336 [internal_api.py:upload_file():2765] upload_file exception https://storage.googleapis.com/wandb-artifacts-prod/wandb_artifacts/133981200/707679855/6873c23a2381d1524249eb1a948a45a5?Expires=1706688949&GoogleAccessId=gorilla-files-url-signer-man%40wandb-production.iam.gserviceaccount.com&Signature=MWNcFNPi%2Fyyg1Xup6XMuAp1Ok4jfdLm3oSNtxmzyEY1f0jHWXyUSc2PkNQLP%2BI7iHTDM2IaW7%2FUPkxROerlg632E%2FexKjST9Ap%2BM4xbvtS%2FMHcYeqH2sRz8Ffq%2BMV%2BPJiua3cOHT%2BekCLcDJWCbgHFyjh88Acd6ayedFYlwVnxZyi%2FmQ7Qly%2F3zxka8vQM1AtK0LxJrphC81EgCP63k7wqyVCgrmuBy9ZybeZauD%2FBvuWtKtSBVYz8Rybzgw9oVwoGsebKpLNv1M2WJkGmdH2nX7Gjyzl6%2BM4q1JaQ5UP5XGUp9q6RZ%2FcqEpq32GkGVkMWWsrfzKEdSTRV64ectXKg%3D%3D: HTTPSConnectionPool(host='storage.googleapis.com', port=443): Max retries exceeded with url: /wandb-artifacts-prod/wandb_artifacts/133981200/707679855/6873c23a2381d1524249eb1a948a45a5?Expires=1706688949&GoogleAccessId=gorilla-files-url-signer-man%40wandb-production.iam.gserviceaccount.com&Signature=MWNcFNPi%2Fyyg1Xup6XMuAp1Ok4jfdLm3oSNtxmzyEY1f0jHWXyUSc2PkNQLP%2BI7iHTDM2IaW7%2FUPkxROerlg632E%2FexKjST9Ap%2BM4xbvtS%2FMHcYeqH2sRz8Ffq%2BMV%2BPJiua3cOHT%2BekCLcDJWCbgHFyjh88Acd6ayedFYlwVnxZyi%2FmQ7Qly%2F3zxka8vQM1AtK0LxJrphC81EgCP63k7wqyVCgrmuBy9ZybeZauD%2FBvuWtKtSBVYz8Rybzgw9oVwoGsebKpLNv1M2WJkGmdH2nX7Gjyzl6%2BM4q1JaQ5UP5XGUp9q6RZ%2FcqEpq32GkGVkMWWsrfzKEdSTRV64ectXKg%3D%3D (Caused by NewConnectionError('<urllib3.connection.HTTPSConnection object at 0x7f9eb4268b80>: Failed to establish a new connection: [Errno 101] Network is unreachable'))
2024-01-30 16:42:48,908 ERROR   wandb-upload_2:1134336 [internal_api.py:upload_file():2767] upload_file request headers: {'User-Agent': 'python-requests/2.23.0', 'Accept-Encoding': 'gzip, deflate', 'Accept': '*/*', 'Connection': 'keep-alive', 'Content-MD5': 'aHPCOiOB0VJCSesalIpFpQ==', 'Content-Type': 'application/json', 'Content-Length': '609'}
2024-01-30 16:42:48,908 ERROR   wandb-upload_2:1134336 [internal_api.py:upload_file():2769] upload_file response body: 
2024-01-30 16:45:34,391 ERROR   wandb-upload_1:1134336 [internal_api.py:upload_file():2765] upload_file exception https://storage.googleapis.com/wandb-artifacts-prod/wandb_artifacts/133981200/707679855/174a3d9bc61fec126cc7d5bdff5c6c5a?Expires=1706688948&GoogleAccessId=gorilla-files-url-signer-man%40wandb-production.iam.gserviceaccount.com&Signature=u%2BCUYnh%2FDljt0walWlrYbjZVLuTPFwTaOFdcUM5pAJDYH6OtsDS6u7RwqtzbNJD6RtkwT1cc2pplIXCd56wmeAhfW0dGEHpgsKDZKoLKXAmFy%2B7Xj4dTCtrEF1xPnfL34E%2BcMm3LEEPakQyH6aimmCiR6Cz53VtGN3P1o6WwOIVLDVQCkB4UXgWknVwK5YDom6WvXajMQmuVmYOVhPvgjAeiV6cr4pyi%2FteDB9Z7%2B59ZkjkZ956mAgmeZjyGnWkXqI35mUiWX%2BcLOOxu%2BvBXnqX9SV7ZxdLHhzSsuYunOaXUDPdw7hXWd6%2F2UmTdZfbawSHlj3P%2By%2FH2ZzkoLfk0aw%3D%3D: HTTPSConnectionPool(host='storage.googleapis.com', port=443): Max retries exceeded with url: /wandb-artifacts-prod/wandb_artifacts/133981200/707679855/174a3d9bc61fec126cc7d5bdff5c6c5a?Expires=1706688948&GoogleAccessId=gorilla-files-url-signer-man%40wandb-production.iam.gserviceaccount.com&Signature=u%2BCUYnh%2FDljt0walWlrYbjZVLuTPFwTaOFdcUM5pAJDYH6OtsDS6u7RwqtzbNJD6RtkwT1cc2pplIXCd56wmeAhfW0dGEHpgsKDZKoLKXAmFy%2B7Xj4dTCtrEF1xPnfL34E%2BcMm3LEEPakQyH6aimmCiR6Cz53VtGN3P1o6WwOIVLDVQCkB4UXgWknVwK5YDom6WvXajMQmuVmYOVhPvgjAeiV6cr4pyi%2FteDB9Z7%2B59ZkjkZ956mAgmeZjyGnWkXqI35mUiWX%2BcLOOxu%2BvBXnqX9SV7ZxdLHhzSsuYunOaXUDPdw7hXWd6%2F2UmTdZfbawSHlj3P%2By%2FH2ZzkoLfk0aw%3D%3D (Caused by NewConnectionError('<urllib3.connection.HTTPSConnection object at 0x7f9eb4351700>: Failed to establish a new connection: [Errno 101] Network is unreachable'))
2024-01-30 16:45:34,391 ERROR   wandb-upload_1:1134336 [internal_api.py:upload_file():2767] upload_file request headers: {'User-Agent': 'python-requests/2.23.0', 'Accept-Encoding': 'gzip, deflate', 'Accept': '*/*', 'Connection': 'keep-alive', 'Content-MD5': 'F0o9m8Yf7BJsx9W9/1xsWg==', 'Content-Type': 'text/plain; charset=utf-8', 'Content-Length': '2179'}
2024-01-30 16:45:34,391 ERROR   wandb-upload_1:1134336 [internal_api.py:upload_file():2769] upload_file response body: 
2024-01-30 16:46:10,884 ERROR   wandb-upload_0:1134336 [internal_api.py:upload_file():2765] upload_file exception https://storage.googleapis.com/wandb-production.appspot.com/dynamic_x/bert_pytorch/b793ft22/wandb-metadata.json?Expires=1706688635&GoogleAccessId=gorilla-files-url-signer-man%40wandb-production.iam.gserviceaccount.com&Signature=GG9waHJzWIlSJt%2Ffs%2FHu2%2BD10Edc0UB5RwtSEHDRx5B6hSob1QIFCoc9hbhtMhww1fag62T52vRjDNqI6H2we9y%2F47axeW8khE0atCO71FwFln3XLW6SX%2FBorIN%2FS9vR2GJfixLLvA0ls47ONf9qNJnUvP1MkQ%2Ffkam%2BQNao1jVYRAB0ZTNwyJrYoCHZjvs8k7HrQ1j9sxRKSNd3WAjRUcEp3WZmAvP%2BggQej6i4pCumKL0nMtEMhagfInuyBmL8DO5GiJuz9LTMrvP3Z0mmTUgl8Ixo7cr2WSgV7CwumFq097BZFo%2FQm4MYm6rZvT%2BEHoOPLgz%2Fg%2Bb7IuLw8JgmtQ%3D%3D: HTTPSConnectionPool(host='storage.googleapis.com', port=443): Max retries exceeded with url: /wandb-production.appspot.com/dynamic_x/bert_pytorch/b793ft22/wandb-metadata.json?Expires=1706688635&GoogleAccessId=gorilla-files-url-signer-man%40wandb-production.iam.gserviceaccount.com&Signature=GG9waHJzWIlSJt%2Ffs%2FHu2%2BD10Edc0UB5RwtSEHDRx5B6hSob1QIFCoc9hbhtMhww1fag62T52vRjDNqI6H2we9y%2F47axeW8khE0atCO71FwFln3XLW6SX%2FBorIN%2FS9vR2GJfixLLvA0ls47ONf9qNJnUvP1MkQ%2Ffkam%2BQNao1jVYRAB0ZTNwyJrYoCHZjvs8k7HrQ1j9sxRKSNd3WAjRUcEp3WZmAvP%2BggQej6i4pCumKL0nMtEMhagfInuyBmL8DO5GiJuz9LTMrvP3Z0mmTUgl8Ixo7cr2WSgV7CwumFq097BZFo%2FQm4MYm6rZvT%2BEHoOPLgz%2Fg%2Bb7IuLw8JgmtQ%3D%3D (Caused by NewConnectionError('<urllib3.connection.HTTPSConnection object at 0x7f9eb442bfd0>: Failed to establish a new connection: [Errno 101] Network is unreachable'))
2024-01-30 16:46:10,885 ERROR   wandb-upload_0:1134336 [internal_api.py:upload_file():2767] upload_file request headers: {'User-Agent': 'python-requests/2.23.0', 'Accept-Encoding': 'gzip, deflate', 'Accept': '*/*', 'Connection': 'keep-alive', 'Content-Length': '15549'}
2024-01-30 16:46:10,885 ERROR   wandb-upload_0:1134336 [internal_api.py:upload_file():2769] upload_file response body: 
2024-01-30 16:51:02,908 ERROR   wandb-upload_1:1134336 [internal_api.py:upload_file():2765] upload_file exception https://storage.googleapis.com/wandb-artifacts-prod/wandb_artifacts/133981200/707679855/174a3d9bc61fec126cc7d5bdff5c6c5a?Expires=1706688948&GoogleAccessId=gorilla-files-url-signer-man%40wandb-production.iam.gserviceaccount.com&Signature=u%2BCUYnh%2FDljt0walWlrYbjZVLuTPFwTaOFdcUM5pAJDYH6OtsDS6u7RwqtzbNJD6RtkwT1cc2pplIXCd56wmeAhfW0dGEHpgsKDZKoLKXAmFy%2B7Xj4dTCtrEF1xPnfL34E%2BcMm3LEEPakQyH6aimmCiR6Cz53VtGN3P1o6WwOIVLDVQCkB4UXgWknVwK5YDom6WvXajMQmuVmYOVhPvgjAeiV6cr4pyi%2FteDB9Z7%2B59ZkjkZ956mAgmeZjyGnWkXqI35mUiWX%2BcLOOxu%2BvBXnqX9SV7ZxdLHhzSsuYunOaXUDPdw7hXWd6%2F2UmTdZfbawSHlj3P%2By%2FH2ZzkoLfk0aw%3D%3D: HTTPSConnectionPool(host='storage.googleapis.com', port=443): Max retries exceeded with url: /wandb-artifacts-prod/wandb_artifacts/133981200/707679855/174a3d9bc61fec126cc7d5bdff5c6c5a?Expires=1706688948&GoogleAccessId=gorilla-files-url-signer-man%40wandb-production.iam.gserviceaccount.com&Signature=u%2BCUYnh%2FDljt0walWlrYbjZVLuTPFwTaOFdcUM5pAJDYH6OtsDS6u7RwqtzbNJD6RtkwT1cc2pplIXCd56wmeAhfW0dGEHpgsKDZKoLKXAmFy%2B7Xj4dTCtrEF1xPnfL34E%2BcMm3LEEPakQyH6aimmCiR6Cz53VtGN3P1o6WwOIVLDVQCkB4UXgWknVwK5YDom6WvXajMQmuVmYOVhPvgjAeiV6cr4pyi%2FteDB9Z7%2B59ZkjkZ956mAgmeZjyGnWkXqI35mUiWX%2BcLOOxu%2BvBXnqX9SV7ZxdLHhzSsuYunOaXUDPdw7hXWd6%2F2UmTdZfbawSHlj3P%2By%2FH2ZzkoLfk0aw%3D%3D (Caused by NewConnectionError('<urllib3.connection.HTTPSConnection object at 0x7f9eb435a0a0>: Failed to establish a new connection: [Errno 111] Connection refused'))
2024-01-30 16:51:02,908 ERROR   wandb-upload_1:1134336 [internal_api.py:upload_file():2767] upload_file request headers: {'User-Agent': 'python-requests/2.23.0', 'Accept-Encoding': 'gzip, deflate', 'Accept': '*/*', 'Connection': 'keep-alive', 'Content-MD5': 'F0o9m8Yf7BJsx9W9/1xsWg==', 'Content-Type': 'text/plain; charset=utf-8', 'Content-Length': '2179'}
2024-01-30 16:51:02,908 ERROR   wandb-upload_1:1134336 [internal_api.py:upload_file():2769] upload_file response body: 
2024-01-30 16:51:11,989 ERROR   wandb-upload_0:1134336 [internal_api.py:upload_file():2765] upload_file exception https://storage.googleapis.com/wandb-production.appspot.com/dynamic_x/bert_pytorch/b793ft22/wandb-metadata.json?Expires=1706688635&GoogleAccessId=gorilla-files-url-signer-man%40wandb-production.iam.gserviceaccount.com&Signature=GG9waHJzWIlSJt%2Ffs%2FHu2%2BD10Edc0UB5RwtSEHDRx5B6hSob1QIFCoc9hbhtMhww1fag62T52vRjDNqI6H2we9y%2F47axeW8khE0atCO71FwFln3XLW6SX%2FBorIN%2FS9vR2GJfixLLvA0ls47ONf9qNJnUvP1MkQ%2Ffkam%2BQNao1jVYRAB0ZTNwyJrYoCHZjvs8k7HrQ1j9sxRKSNd3WAjRUcEp3WZmAvP%2BggQej6i4pCumKL0nMtEMhagfInuyBmL8DO5GiJuz9LTMrvP3Z0mmTUgl8Ixo7cr2WSgV7CwumFq097BZFo%2FQm4MYm6rZvT%2BEHoOPLgz%2Fg%2Bb7IuLw8JgmtQ%3D%3D: HTTPSConnectionPool(host='storage.googleapis.com', port=443): Max retries exceeded with url: /wandb-production.appspot.com/dynamic_x/bert_pytorch/b793ft22/wandb-metadata.json?Expires=1706688635&GoogleAccessId=gorilla-files-url-signer-man%40wandb-production.iam.gserviceaccount.com&Signature=GG9waHJzWIlSJt%2Ffs%2FHu2%2BD10Edc0UB5RwtSEHDRx5B6hSob1QIFCoc9hbhtMhww1fag62T52vRjDNqI6H2we9y%2F47axeW8khE0atCO71FwFln3XLW6SX%2FBorIN%2FS9vR2GJfixLLvA0ls47ONf9qNJnUvP1MkQ%2Ffkam%2BQNao1jVYRAB0ZTNwyJrYoCHZjvs8k7HrQ1j9sxRKSNd3WAjRUcEp3WZmAvP%2BggQej6i4pCumKL0nMtEMhagfInuyBmL8DO5GiJuz9LTMrvP3Z0mmTUgl8Ixo7cr2WSgV7CwumFq097BZFo%2FQm4MYm6rZvT%2BEHoOPLgz%2Fg%2Bb7IuLw8JgmtQ%3D%3D (Caused by NewConnectionError('<urllib3.connection.HTTPSConnection object at 0x7f9eb4268250>: Failed to establish a new connection: [Errno 111] Connection refused'))
2024-01-30 16:51:11,989 ERROR   wandb-upload_0:1134336 [internal_api.py:upload_file():2767] upload_file request headers: {'User-Agent': 'python-requests/2.23.0', 'Accept-Encoding': 'gzip, deflate', 'Accept': '*/*', 'Connection': 'keep-alive', 'Content-Length': '15549'}
2024-01-30 16:51:11,989 ERROR   wandb-upload_0:1134336 [internal_api.py:upload_file():2769] upload_file response body: 
2024-01-30 16:56:21,337 ERROR   wandb-upload_0:1134336 [internal_api.py:upload_file():2765] upload_file exception https://storage.googleapis.com/wandb-production.appspot.com/dynamic_x/bert_pytorch/b793ft22/wandb-metadata.json?Expires=1706688635&GoogleAccessId=gorilla-files-url-signer-man%40wandb-production.iam.gserviceaccount.com&Signature=GG9waHJzWIlSJt%2Ffs%2FHu2%2BD10Edc0UB5RwtSEHDRx5B6hSob1QIFCoc9hbhtMhww1fag62T52vRjDNqI6H2we9y%2F47axeW8khE0atCO71FwFln3XLW6SX%2FBorIN%2FS9vR2GJfixLLvA0ls47ONf9qNJnUvP1MkQ%2Ffkam%2BQNao1jVYRAB0ZTNwyJrYoCHZjvs8k7HrQ1j9sxRKSNd3WAjRUcEp3WZmAvP%2BggQej6i4pCumKL0nMtEMhagfInuyBmL8DO5GiJuz9LTMrvP3Z0mmTUgl8Ixo7cr2WSgV7CwumFq097BZFo%2FQm4MYm6rZvT%2BEHoOPLgz%2Fg%2Bb7IuLw8JgmtQ%3D%3D: HTTPSConnectionPool(host='storage.googleapis.com', port=443): Max retries exceeded with url: /wandb-production.appspot.com/dynamic_x/bert_pytorch/b793ft22/wandb-metadata.json?Expires=1706688635&GoogleAccessId=gorilla-files-url-signer-man%40wandb-production.iam.gserviceaccount.com&Signature=GG9waHJzWIlSJt%2Ffs%2FHu2%2BD10Edc0UB5RwtSEHDRx5B6hSob1QIFCoc9hbhtMhww1fag62T52vRjDNqI6H2we9y%2F47axeW8khE0atCO71FwFln3XLW6SX%2FBorIN%2FS9vR2GJfixLLvA0ls47ONf9qNJnUvP1MkQ%2Ffkam%2BQNao1jVYRAB0ZTNwyJrYoCHZjvs8k7HrQ1j9sxRKSNd3WAjRUcEp3WZmAvP%2BggQej6i4pCumKL0nMtEMhagfInuyBmL8DO5GiJuz9LTMrvP3Z0mmTUgl8Ixo7cr2WSgV7CwumFq097BZFo%2FQm4MYm6rZvT%2BEHoOPLgz%2Fg%2Bb7IuLw8JgmtQ%3D%3D (Caused by NewConnectionError('<urllib3.connection.HTTPSConnection object at 0x7f9eb4272a60>: Failed to establish a new connection: [Errno 111] Connection refused'))
2024-01-30 16:56:21,337 ERROR   wandb-upload_0:1134336 [internal_api.py:upload_file():2767] upload_file request headers: {'User-Agent': 'python-requests/2.23.0', 'Accept-Encoding': 'gzip, deflate', 'Accept': '*/*', 'Connection': 'keep-alive', 'Content-Length': '15549'}
2024-01-30 16:56:21,337 ERROR   wandb-upload_0:1134336 [internal_api.py:upload_file():2769] upload_file response body: 
2024-01-30 16:56:30,957 ERROR   wandb-upload_1:1134336 [internal_api.py:upload_file():2765] upload_file exception https://storage.googleapis.com/wandb-artifacts-prod/wandb_artifacts/133981200/707679855/174a3d9bc61fec126cc7d5bdff5c6c5a?Expires=1706688948&GoogleAccessId=gorilla-files-url-signer-man%40wandb-production.iam.gserviceaccount.com&Signature=u%2BCUYnh%2FDljt0walWlrYbjZVLuTPFwTaOFdcUM5pAJDYH6OtsDS6u7RwqtzbNJD6RtkwT1cc2pplIXCd56wmeAhfW0dGEHpgsKDZKoLKXAmFy%2B7Xj4dTCtrEF1xPnfL34E%2BcMm3LEEPakQyH6aimmCiR6Cz53VtGN3P1o6WwOIVLDVQCkB4UXgWknVwK5YDom6WvXajMQmuVmYOVhPvgjAeiV6cr4pyi%2FteDB9Z7%2B59ZkjkZ956mAgmeZjyGnWkXqI35mUiWX%2BcLOOxu%2BvBXnqX9SV7ZxdLHhzSsuYunOaXUDPdw7hXWd6%2F2UmTdZfbawSHlj3P%2By%2FH2ZzkoLfk0aw%3D%3D: HTTPSConnectionPool(host='storage.googleapis.com', port=443): Max retries exceeded with url: /wandb-artifacts-prod/wandb_artifacts/133981200/707679855/174a3d9bc61fec126cc7d5bdff5c6c5a?Expires=1706688948&GoogleAccessId=gorilla-files-url-signer-man%40wandb-production.iam.gserviceaccount.com&Signature=u%2BCUYnh%2FDljt0walWlrYbjZVLuTPFwTaOFdcUM5pAJDYH6OtsDS6u7RwqtzbNJD6RtkwT1cc2pplIXCd56wmeAhfW0dGEHpgsKDZKoLKXAmFy%2B7Xj4dTCtrEF1xPnfL34E%2BcMm3LEEPakQyH6aimmCiR6Cz53VtGN3P1o6WwOIVLDVQCkB4UXgWknVwK5YDom6WvXajMQmuVmYOVhPvgjAeiV6cr4pyi%2FteDB9Z7%2B59ZkjkZ956mAgmeZjyGnWkXqI35mUiWX%2BcLOOxu%2BvBXnqX9SV7ZxdLHhzSsuYunOaXUDPdw7hXWd6%2F2UmTdZfbawSHlj3P%2By%2FH2ZzkoLfk0aw%3D%3D (Caused by NewConnectionError('<urllib3.connection.HTTPSConnection object at 0x7f9eb426d160>: Failed to establish a new connection: [Errno 111] Connection refused'))
2024-01-30 16:56:30,957 ERROR   wandb-upload_1:1134336 [internal_api.py:upload_file():2767] upload_file request headers: {'User-Agent': 'python-requests/2.23.0', 'Accept-Encoding': 'gzip, deflate', 'Accept': '*/*', 'Connection': 'keep-alive', 'Content-MD5': 'F0o9m8Yf7BJsx9W9/1xsWg==', 'Content-Type': 'text/plain; charset=utf-8', 'Content-Length': '2179'}
2024-01-30 16:56:30,957 ERROR   wandb-upload_1:1134336 [internal_api.py:upload_file():2769] upload_file response body: 
2024-01-30 17:02:21,810 ERROR   wandb-upload_1:1134336 [internal_api.py:upload_file():2765] upload_file exception https://storage.googleapis.com/wandb-artifacts-prod/wandb_artifacts/133981200/707679855/174a3d9bc61fec126cc7d5bdff5c6c5a?Expires=1706688948&GoogleAccessId=gorilla-files-url-signer-man%40wandb-production.iam.gserviceaccount.com&Signature=u%2BCUYnh%2FDljt0walWlrYbjZVLuTPFwTaOFdcUM5pAJDYH6OtsDS6u7RwqtzbNJD6RtkwT1cc2pplIXCd56wmeAhfW0dGEHpgsKDZKoLKXAmFy%2B7Xj4dTCtrEF1xPnfL34E%2BcMm3LEEPakQyH6aimmCiR6Cz53VtGN3P1o6WwOIVLDVQCkB4UXgWknVwK5YDom6WvXajMQmuVmYOVhPvgjAeiV6cr4pyi%2FteDB9Z7%2B59ZkjkZ956mAgmeZjyGnWkXqI35mUiWX%2BcLOOxu%2BvBXnqX9SV7ZxdLHhzSsuYunOaXUDPdw7hXWd6%2F2UmTdZfbawSHlj3P%2By%2FH2ZzkoLfk0aw%3D%3D: HTTPSConnectionPool(host='storage.googleapis.com', port=443): Max retries exceeded with url: /wandb-artifacts-prod/wandb_artifacts/133981200/707679855/174a3d9bc61fec126cc7d5bdff5c6c5a?Expires=1706688948&GoogleAccessId=gorilla-files-url-signer-man%40wandb-production.iam.gserviceaccount.com&Signature=u%2BCUYnh%2FDljt0walWlrYbjZVLuTPFwTaOFdcUM5pAJDYH6OtsDS6u7RwqtzbNJD6RtkwT1cc2pplIXCd56wmeAhfW0dGEHpgsKDZKoLKXAmFy%2B7Xj4dTCtrEF1xPnfL34E%2BcMm3LEEPakQyH6aimmCiR6Cz53VtGN3P1o6WwOIVLDVQCkB4UXgWknVwK5YDom6WvXajMQmuVmYOVhPvgjAeiV6cr4pyi%2FteDB9Z7%2B59ZkjkZ956mAgmeZjyGnWkXqI35mUiWX%2BcLOOxu%2BvBXnqX9SV7ZxdLHhzSsuYunOaXUDPdw7hXWd6%2F2UmTdZfbawSHlj3P%2By%2FH2ZzkoLfk0aw%3D%3D (Caused by NewConnectionError('<urllib3.connection.HTTPSConnection object at 0x7f9eb43515b0>: Failed to establish a new connection: [Errno 111] Connection refused'))
2024-01-30 17:02:21,810 ERROR   wandb-upload_1:1134336 [internal_api.py:upload_file():2767] upload_file request headers: {'User-Agent': 'python-requests/2.23.0', 'Accept-Encoding': 'gzip, deflate', 'Accept': '*/*', 'Connection': 'keep-alive', 'Content-MD5': 'F0o9m8Yf7BJsx9W9/1xsWg==', 'Content-Type': 'text/plain; charset=utf-8', 'Content-Length': '2179'}
2024-01-30 17:02:21,810 ERROR   wandb-upload_1:1134336 [internal_api.py:upload_file():2769] upload_file response body: 
2024-01-30 17:02:28,028 ERROR   wandb-upload_0:1134336 [internal_api.py:upload_file():2765] upload_file exception https://storage.googleapis.com/wandb-production.appspot.com/dynamic_x/bert_pytorch/b793ft22/wandb-metadata.json?Expires=1706688635&GoogleAccessId=gorilla-files-url-signer-man%40wandb-production.iam.gserviceaccount.com&Signature=GG9waHJzWIlSJt%2Ffs%2FHu2%2BD10Edc0UB5RwtSEHDRx5B6hSob1QIFCoc9hbhtMhww1fag62T52vRjDNqI6H2we9y%2F47axeW8khE0atCO71FwFln3XLW6SX%2FBorIN%2FS9vR2GJfixLLvA0ls47ONf9qNJnUvP1MkQ%2Ffkam%2BQNao1jVYRAB0ZTNwyJrYoCHZjvs8k7HrQ1j9sxRKSNd3WAjRUcEp3WZmAvP%2BggQej6i4pCumKL0nMtEMhagfInuyBmL8DO5GiJuz9LTMrvP3Z0mmTUgl8Ixo7cr2WSgV7CwumFq097BZFo%2FQm4MYm6rZvT%2BEHoOPLgz%2Fg%2Bb7IuLw8JgmtQ%3D%3D: HTTPSConnectionPool(host='storage.googleapis.com', port=443): Max retries exceeded with url: /wandb-production.appspot.com/dynamic_x/bert_pytorch/b793ft22/wandb-metadata.json?Expires=1706688635&GoogleAccessId=gorilla-files-url-signer-man%40wandb-production.iam.gserviceaccount.com&Signature=GG9waHJzWIlSJt%2Ffs%2FHu2%2BD10Edc0UB5RwtSEHDRx5B6hSob1QIFCoc9hbhtMhww1fag62T52vRjDNqI6H2we9y%2F47axeW8khE0atCO71FwFln3XLW6SX%2FBorIN%2FS9vR2GJfixLLvA0ls47ONf9qNJnUvP1MkQ%2Ffkam%2BQNao1jVYRAB0ZTNwyJrYoCHZjvs8k7HrQ1j9sxRKSNd3WAjRUcEp3WZmAvP%2BggQej6i4pCumKL0nMtEMhagfInuyBmL8DO5GiJuz9LTMrvP3Z0mmTUgl8Ixo7cr2WSgV7CwumFq097BZFo%2FQm4MYm6rZvT%2BEHoOPLgz%2Fg%2Bb7IuLw8JgmtQ%3D%3D (Caused by NewConnectionError('<urllib3.connection.HTTPSConnection object at 0x7f9eb4262280>: Failed to establish a new connection: [Errno 111] Connection refused'))
2024-01-30 17:02:28,028 ERROR   wandb-upload_0:1134336 [internal_api.py:upload_file():2767] upload_file request headers: {'User-Agent': 'python-requests/2.23.0', 'Accept-Encoding': 'gzip, deflate', 'Accept': '*/*', 'Connection': 'keep-alive', 'Content-Length': '15549'}
2024-01-30 17:02:28,028 ERROR   wandb-upload_0:1134336 [internal_api.py:upload_file():2769] upload_file response body: 
2024-01-30 17:07:52,604 ERROR   wandb-upload_1:1134336 [internal_api.py:upload_file():2765] upload_file exception https://storage.googleapis.com/wandb-artifacts-prod/wandb_artifacts/133981200/707679855/174a3d9bc61fec126cc7d5bdff5c6c5a?Expires=1706688948&GoogleAccessId=gorilla-files-url-signer-man%40wandb-production.iam.gserviceaccount.com&Signature=u%2BCUYnh%2FDljt0walWlrYbjZVLuTPFwTaOFdcUM5pAJDYH6OtsDS6u7RwqtzbNJD6RtkwT1cc2pplIXCd56wmeAhfW0dGEHpgsKDZKoLKXAmFy%2B7Xj4dTCtrEF1xPnfL34E%2BcMm3LEEPakQyH6aimmCiR6Cz53VtGN3P1o6WwOIVLDVQCkB4UXgWknVwK5YDom6WvXajMQmuVmYOVhPvgjAeiV6cr4pyi%2FteDB9Z7%2B59ZkjkZ956mAgmeZjyGnWkXqI35mUiWX%2BcLOOxu%2BvBXnqX9SV7ZxdLHhzSsuYunOaXUDPdw7hXWd6%2F2UmTdZfbawSHlj3P%2By%2FH2ZzkoLfk0aw%3D%3D: HTTPSConnectionPool(host='storage.googleapis.com', port=443): Max retries exceeded with url: /wandb-artifacts-prod/wandb_artifacts/133981200/707679855/174a3d9bc61fec126cc7d5bdff5c6c5a?Expires=1706688948&GoogleAccessId=gorilla-files-url-signer-man%40wandb-production.iam.gserviceaccount.com&Signature=u%2BCUYnh%2FDljt0walWlrYbjZVLuTPFwTaOFdcUM5pAJDYH6OtsDS6u7RwqtzbNJD6RtkwT1cc2pplIXCd56wmeAhfW0dGEHpgsKDZKoLKXAmFy%2B7Xj4dTCtrEF1xPnfL34E%2BcMm3LEEPakQyH6aimmCiR6Cz53VtGN3P1o6WwOIVLDVQCkB4UXgWknVwK5YDom6WvXajMQmuVmYOVhPvgjAeiV6cr4pyi%2FteDB9Z7%2B59ZkjkZ956mAgmeZjyGnWkXqI35mUiWX%2BcLOOxu%2BvBXnqX9SV7ZxdLHhzSsuYunOaXUDPdw7hXWd6%2F2UmTdZfbawSHlj3P%2By%2FH2ZzkoLfk0aw%3D%3D (Caused by NewConnectionError('<urllib3.connection.HTTPSConnection object at 0x7f9eb4351cd0>: Failed to establish a new connection: [Errno 111] Connection refused'))
2024-01-30 17:07:52,604 ERROR   wandb-upload_1:1134336 [internal_api.py:upload_file():2767] upload_file request headers: {'User-Agent': 'python-requests/2.23.0', 'Accept-Encoding': 'gzip, deflate', 'Accept': '*/*', 'Connection': 'keep-alive', 'Content-MD5': 'F0o9m8Yf7BJsx9W9/1xsWg==', 'Content-Type': 'text/plain; charset=utf-8', 'Content-Length': '2179'}
2024-01-30 17:07:52,604 ERROR   wandb-upload_1:1134336 [internal_api.py:upload_file():2769] upload_file response body: 
2024-01-30 17:08:34,834 ERROR   wandb-upload_0:1134336 [internal_api.py:upload_file():2765] upload_file exception https://storage.googleapis.com/wandb-production.appspot.com/dynamic_x/bert_pytorch/b793ft22/wandb-metadata.json?Expires=1706688635&GoogleAccessId=gorilla-files-url-signer-man%40wandb-production.iam.gserviceaccount.com&Signature=GG9waHJzWIlSJt%2Ffs%2FHu2%2BD10Edc0UB5RwtSEHDRx5B6hSob1QIFCoc9hbhtMhww1fag62T52vRjDNqI6H2we9y%2F47axeW8khE0atCO71FwFln3XLW6SX%2FBorIN%2FS9vR2GJfixLLvA0ls47ONf9qNJnUvP1MkQ%2Ffkam%2BQNao1jVYRAB0ZTNwyJrYoCHZjvs8k7HrQ1j9sxRKSNd3WAjRUcEp3WZmAvP%2BggQej6i4pCumKL0nMtEMhagfInuyBmL8DO5GiJuz9LTMrvP3Z0mmTUgl8Ixo7cr2WSgV7CwumFq097BZFo%2FQm4MYm6rZvT%2BEHoOPLgz%2Fg%2Bb7IuLw8JgmtQ%3D%3D: HTTPSConnectionPool(host='storage.googleapis.com', port=443): Max retries exceeded with url: /wandb-production.appspot.com/dynamic_x/bert_pytorch/b793ft22/wandb-metadata.json?Expires=1706688635&GoogleAccessId=gorilla-files-url-signer-man%40wandb-production.iam.gserviceaccount.com&Signature=GG9waHJzWIlSJt%2Ffs%2FHu2%2BD10Edc0UB5RwtSEHDRx5B6hSob1QIFCoc9hbhtMhww1fag62T52vRjDNqI6H2we9y%2F47axeW8khE0atCO71FwFln3XLW6SX%2FBorIN%2FS9vR2GJfixLLvA0ls47ONf9qNJnUvP1MkQ%2Ffkam%2BQNao1jVYRAB0ZTNwyJrYoCHZjvs8k7HrQ1j9sxRKSNd3WAjRUcEp3WZmAvP%2BggQej6i4pCumKL0nMtEMhagfInuyBmL8DO5GiJuz9LTMrvP3Z0mmTUgl8Ixo7cr2WSgV7CwumFq097BZFo%2FQm4MYm6rZvT%2BEHoOPLgz%2Fg%2Bb7IuLw8JgmtQ%3D%3D (Caused by NewConnectionError('<urllib3.connection.HTTPSConnection object at 0x7f9eb42625e0>: Failed to establish a new connection: [Errno 111] Connection refused'))
2024-01-30 17:08:34,834 ERROR   wandb-upload_0:1134336 [internal_api.py:upload_file():2767] upload_file request headers: {'User-Agent': 'python-requests/2.23.0', 'Accept-Encoding': 'gzip, deflate', 'Accept': '*/*', 'Connection': 'keep-alive', 'Content-Length': '15549'}
2024-01-30 17:08:34,834 ERROR   wandb-upload_0:1134336 [internal_api.py:upload_file():2769] upload_file response body: 
2024-01-30 17:12:50,934 ERROR   wandb-upload_2:1134336 [internal_api.py:upload_file():2765] upload_file exception https://storage.googleapis.com/wandb-artifacts-prod/wandb_artifacts/133981200/707679855/6873c23a2381d1524249eb1a948a45a5?Expires=1706688949&GoogleAccessId=gorilla-files-url-signer-man%40wandb-production.iam.gserviceaccount.com&Signature=MWNcFNPi%2Fyyg1Xup6XMuAp1Ok4jfdLm3oSNtxmzyEY1f0jHWXyUSc2PkNQLP%2BI7iHTDM2IaW7%2FUPkxROerlg632E%2FexKjST9Ap%2BM4xbvtS%2FMHcYeqH2sRz8Ffq%2BMV%2BPJiua3cOHT%2BekCLcDJWCbgHFyjh88Acd6ayedFYlwVnxZyi%2FmQ7Qly%2F3zxka8vQM1AtK0LxJrphC81EgCP63k7wqyVCgrmuBy9ZybeZauD%2FBvuWtKtSBVYz8Rybzgw9oVwoGsebKpLNv1M2WJkGmdH2nX7Gjyzl6%2BM4q1JaQ5UP5XGUp9q6RZ%2FcqEpq32GkGVkMWWsrfzKEdSTRV64ectXKg%3D%3D: HTTPSConnectionPool(host='storage.googleapis.com', port=443): Max retries exceeded with url: /wandb-artifacts-prod/wandb_artifacts/133981200/707679855/6873c23a2381d1524249eb1a948a45a5?Expires=1706688949&GoogleAccessId=gorilla-files-url-signer-man%40wandb-production.iam.gserviceaccount.com&Signature=MWNcFNPi%2Fyyg1Xup6XMuAp1Ok4jfdLm3oSNtxmzyEY1f0jHWXyUSc2PkNQLP%2BI7iHTDM2IaW7%2FUPkxROerlg632E%2FexKjST9Ap%2BM4xbvtS%2FMHcYeqH2sRz8Ffq%2BMV%2BPJiua3cOHT%2BekCLcDJWCbgHFyjh88Acd6ayedFYlwVnxZyi%2FmQ7Qly%2F3zxka8vQM1AtK0LxJrphC81EgCP63k7wqyVCgrmuBy9ZybeZauD%2FBvuWtKtSBVYz8Rybzgw9oVwoGsebKpLNv1M2WJkGmdH2nX7Gjyzl6%2BM4q1JaQ5UP5XGUp9q6RZ%2FcqEpq32GkGVkMWWsrfzKEdSTRV64ectXKg%3D%3D (Caused by NewConnectionError('<urllib3.connection.HTTPSConnection object at 0x7f9eb426de20>: Failed to establish a new connection: [Errno 110] Connection timed out'))
2024-01-30 17:12:50,934 ERROR   wandb-upload_2:1134336 [internal_api.py:upload_file():2767] upload_file request headers: {'User-Agent': 'python-requests/2.23.0', 'Accept-Encoding': 'gzip, deflate', 'Accept': '*/*', 'Connection': 'keep-alive', 'Content-MD5': 'aHPCOiOB0VJCSesalIpFpQ==', 'Content-Type': 'application/json', 'Content-Length': '609'}
2024-01-30 17:12:50,934 ERROR   wandb-upload_2:1134336 [internal_api.py:upload_file():2769] upload_file response body: 
2024-01-30 17:13:09,209 INFO    wandb-upload_1:1134336 [upload_job.py:push():89] Uploaded file /home/yanxindong/.local/share/wandb/artifacts/staging/tmpu2dtm69g
2024-01-30 17:13:46,072 INFO    wandb-upload_0:1134336 [upload_job.py:push():131] Uploaded file /tmp/tmpwo4u4op8wandb/9cqnq4f3-wandb-metadata.json
2024-01-30 17:18:23,347 ERROR   wandb-upload_2:1134336 [internal_api.py:upload_file():2765] upload_file exception https://storage.googleapis.com/wandb-artifacts-prod/wandb_artifacts/133981200/707679855/6873c23a2381d1524249eb1a948a45a5?Expires=1706688949&GoogleAccessId=gorilla-files-url-signer-man%40wandb-production.iam.gserviceaccount.com&Signature=MWNcFNPi%2Fyyg1Xup6XMuAp1Ok4jfdLm3oSNtxmzyEY1f0jHWXyUSc2PkNQLP%2BI7iHTDM2IaW7%2FUPkxROerlg632E%2FexKjST9Ap%2BM4xbvtS%2FMHcYeqH2sRz8Ffq%2BMV%2BPJiua3cOHT%2BekCLcDJWCbgHFyjh88Acd6ayedFYlwVnxZyi%2FmQ7Qly%2F3zxka8vQM1AtK0LxJrphC81EgCP63k7wqyVCgrmuBy9ZybeZauD%2FBvuWtKtSBVYz8Rybzgw9oVwoGsebKpLNv1M2WJkGmdH2nX7Gjyzl6%2BM4q1JaQ5UP5XGUp9q6RZ%2FcqEpq32GkGVkMWWsrfzKEdSTRV64ectXKg%3D%3D: HTTPSConnectionPool(host='storage.googleapis.com', port=443): Max retries exceeded with url: /wandb-artifacts-prod/wandb_artifacts/133981200/707679855/6873c23a2381d1524249eb1a948a45a5?Expires=1706688949&GoogleAccessId=gorilla-files-url-signer-man%40wandb-production.iam.gserviceaccount.com&Signature=MWNcFNPi%2Fyyg1Xup6XMuAp1Ok4jfdLm3oSNtxmzyEY1f0jHWXyUSc2PkNQLP%2BI7iHTDM2IaW7%2FUPkxROerlg632E%2FexKjST9Ap%2BM4xbvtS%2FMHcYeqH2sRz8Ffq%2BMV%2BPJiua3cOHT%2BekCLcDJWCbgHFyjh88Acd6ayedFYlwVnxZyi%2FmQ7Qly%2F3zxka8vQM1AtK0LxJrphC81EgCP63k7wqyVCgrmuBy9ZybeZauD%2FBvuWtKtSBVYz8Rybzgw9oVwoGsebKpLNv1M2WJkGmdH2nX7Gjyzl6%2BM4q1JaQ5UP5XGUp9q6RZ%2FcqEpq32GkGVkMWWsrfzKEdSTRV64ectXKg%3D%3D (Caused by NewConnectionError('<urllib3.connection.HTTPSConnection object at 0x7f9eb4351b80>: Failed to establish a new connection: [Errno 101] Network is unreachable'))
2024-01-30 17:18:23,347 ERROR   wandb-upload_2:1134336 [internal_api.py:upload_file():2767] upload_file request headers: {'User-Agent': 'python-requests/2.23.0', 'Accept-Encoding': 'gzip, deflate', 'Accept': '*/*', 'Connection': 'keep-alive', 'Content-MD5': 'aHPCOiOB0VJCSesalIpFpQ==', 'Content-Type': 'application/json', 'Content-Length': '609'}
2024-01-30 17:18:23,347 ERROR   wandb-upload_2:1134336 [internal_api.py:upload_file():2769] upload_file response body: 
2024-01-30 17:23:56,753 INFO    wandb-upload_2:1134336 [upload_job.py:push():89] Uploaded file /home/yanxindong/.local/share/wandb/artifacts/staging/tmpirb_algf
2024-01-30 17:23:59,969 INFO    SenderThread:1134336 [sender.py:send_artifact():1494] sent artifact job-https___github.com_kkkjj-d_mkor.git_bert_run_pretraining.py - {'id': 'QXJ0aWZhY3Q6NzA3Njc5ODU1', 'state': 'PENDING', 'artifactSequence': {'id': 'QXJ0aWZhY3RDb2xsZWN0aW9uOjEzMzk4MTIwMA==', 'latestArtifact': {'id': 'QXJ0aWZhY3Q6NzAzOTc3Mjk3', 'versionIndex': 8}}}
2024-01-30 17:23:59,969 INFO    SenderThread:1134336 [sender.py:finish():1572] shutting down sender
2024-01-30 17:23:59,969 INFO    SenderThread:1134336 [dir_watcher.py:finish():358] shutting down directory watcher
2024-01-30 17:24:00,291 INFO    SenderThread:1134336 [dir_watcher.py:finish():388] scan: /home/yanxindong/mkor/bert/wandb/run-20240130_161012-b793ft22/files
2024-01-30 17:24:00,291 INFO    SenderThread:1134336 [dir_watcher.py:finish():402] scan save: /home/yanxindong/mkor/bert/wandb/run-20240130_161012-b793ft22/files/wandb-summary.json wandb-summary.json
2024-01-30 17:24:00,292 INFO    SenderThread:1134336 [dir_watcher.py:finish():402] scan save: /home/yanxindong/mkor/bert/wandb/run-20240130_161012-b793ft22/files/conda-environment.yaml conda-environment.yaml
2024-01-30 17:24:00,292 INFO    SenderThread:1134336 [dir_watcher.py:finish():402] scan save: /home/yanxindong/mkor/bert/wandb/run-20240130_161012-b793ft22/files/wandb-metadata.json wandb-metadata.json
2024-01-30 17:24:00,292 INFO    SenderThread:1134336 [dir_watcher.py:finish():402] scan save: /home/yanxindong/mkor/bert/wandb/run-20240130_161012-b793ft22/files/output.log output.log
2024-01-30 17:24:00,292 INFO    SenderThread:1134336 [dir_watcher.py:finish():402] scan save: /home/yanxindong/mkor/bert/wandb/run-20240130_161012-b793ft22/files/requirements.txt requirements.txt
2024-01-30 17:24:00,293 INFO    SenderThread:1134336 [dir_watcher.py:finish():402] scan save: /home/yanxindong/mkor/bert/wandb/run-20240130_161012-b793ft22/files/config.yaml config.yaml
2024-01-30 17:24:00,293 INFO    SenderThread:1134336 [file_pusher.py:finish():175] shutting down file pusher
2024-01-30 17:24:00,301 INFO    SenderThread:1134336 [file_pusher.py:join():181] waiting for file pusher
2024-01-30 17:24:00,918 INFO    wandb-upload_3:1134336 [upload_job.py:push():131] Uploaded file /home/yanxindong/mkor/bert/wandb/run-20240130_161012-b793ft22/files/wandb-summary.json
2024-01-30 17:24:01,290 INFO    wandb-upload_2:1134336 [upload_job.py:push():131] Uploaded file /home/yanxindong/mkor/bert/wandb/run-20240130_161012-b793ft22/files/config.yaml
2024-01-30 17:24:01,310 INFO    wandb-upload_0:1134336 [upload_job.py:push():131] Uploaded file /home/yanxindong/mkor/bert/wandb/run-20240130_161012-b793ft22/files/requirements.txt
2024-01-30 17:24:01,327 INFO    wandb-upload_1:1134336 [upload_job.py:push():131] Uploaded file /home/yanxindong/mkor/bert/wandb/run-20240130_161012-b793ft22/files/output.log
2024-01-30 17:24:02,092 INFO    wandb-upload_4:1134336 [upload_job.py:push():131] Uploaded file /home/yanxindong/mkor/bert/wandb/run-20240130_161012-b793ft22/files/conda-environment.yaml
2024-01-30 17:24:02,306 INFO    SenderThread:1134336 [file_stream.py:finish():595] file stream finish called
2024-01-30 17:24:02,580 INFO    SenderThread:1134336 [file_stream.py:finish():599] file stream finish is done
