2024-01-30 16:10:12,577 INFO    StreamThr :1134330 [internal.py:wandb_internal():86] W&B internal server running at pid: 1134330, started at: 2024-01-30 16:10:12.576687
2024-01-30 16:10:12,613 DEBUG   HandlerThread:1134330 [handler.py:handle_request():146] handle_request: status
2024-01-30 16:10:12,625 INFO    WriterThread:1134330 [datastore.py:open_for_write():87] open: /home/yanxindong/mkor/bert/wandb/run-20240130_161012-87yhbfo2/run-87yhbfo2.wandb
2024-01-30 16:10:12,629 DEBUG   SenderThread:1134330 [sender.py:send():382] send: header
2024-01-30 16:10:12,629 DEBUG   SenderThread:1134330 [sender.py:send():382] send: run
2024-01-30 16:10:13,648 DEBUG   HandlerThread:1134330 [handler.py:handle_request():146] handle_request: check_version
2024-01-30 16:10:13,648 INFO    SenderThread:1134330 [dir_watcher.py:__init__():211] watching files in: /home/yanxindong/mkor/bert/wandb/run-20240130_161012-87yhbfo2/files
2024-01-30 16:10:13,648 INFO    SenderThread:1134330 [sender.py:_start_run_threads():1136] run started: 87yhbfo2 with start time 1706602212.580478
2024-01-30 16:10:13,648 DEBUG   SenderThread:1134330 [sender.py:send_request():409] send_request: check_version
2024-01-30 16:10:14,574 DEBUG   HandlerThread:1134330 [handler.py:handle_request():146] handle_request: run_start
2024-01-30 16:10:14,607 DEBUG   HandlerThread:1134330 [system_info.py:__init__():27] System info init
2024-01-30 16:10:14,607 DEBUG   HandlerThread:1134330 [system_info.py:__init__():42] System info init done
2024-01-30 16:10:14,607 INFO    HandlerThread:1134330 [system_monitor.py:start():194] Starting system monitor
2024-01-30 16:10:14,607 INFO    SystemMonitor:1134330 [system_monitor.py:_start():158] Starting system asset monitoring threads
2024-01-30 16:10:14,607 INFO    HandlerThread:1134330 [system_monitor.py:probe():214] Collecting system info
2024-01-30 16:10:14,610 INFO    SystemMonitor:1134330 [interfaces.py:start():190] Started cpu monitoring
2024-01-30 16:10:14,632 INFO    SystemMonitor:1134330 [interfaces.py:start():190] Started disk monitoring
2024-01-30 16:10:14,649 INFO    SystemMonitor:1134330 [interfaces.py:start():190] Started gpu monitoring
2024-01-30 16:10:14,654 INFO    SystemMonitor:1134330 [interfaces.py:start():190] Started memory monitoring
2024-01-30 16:10:14,661 INFO    SystemMonitor:1134330 [interfaces.py:start():190] Started network monitoring
2024-01-30 16:10:14,709 DEBUG   HandlerThread:1134330 [system_info.py:probe():151] Probing system
2024-01-30 16:10:14,722 DEBUG   HandlerThread:1134330 [system_info.py:_probe_git():136] Probing git
2024-01-30 16:10:14,754 DEBUG   HandlerThread:1134330 [system_info.py:_probe_git():144] Probing git done
2024-01-30 16:10:14,754 DEBUG   HandlerThread:1134330 [system_info.py:probe():199] Probing system done
2024-01-30 16:10:14,754 DEBUG   HandlerThread:1134330 [system_monitor.py:probe():223] {'os': 'Linux-5.15.0-92-generic-x86_64-with-glibc2.17', 'python': '3.8.17', 'heartbeatAt': '2024-01-30T08:10:14.710018', 'startedAt': '2024-01-30T08:10:12.555843', 'docker': None, 'cuda': None, 'args': ('--local_rank=4', '--config_file', 'config/bert_pretraining_phase2_config.json', '--input_dir', '/home/yanxindong/mkor/bert/data/encoded/sequences_lowercase_max_seq_len_512_next_seq_task_true', '--output_dir', 'results/adam', '--weight_decay', '0.01', '--num_steps_per_checkpoint', '200'), 'state': 'running', 'program': 'run_pretraining.py', 'codePathLocal': 'run_pretraining.py', 'codePath': 'bert/run_pretraining.py', 'git': {'remote': 'https://github.com/kkkjj-d/mkor.git', 'commit': 'efe99e84fef5594780cfb1df6d6a1f61da4ebba0'}, 'email': '1262670315@qq.com', 'root': '/home/yanxindong/mkor', 'host': 'a6000-X640-G40', 'username': 'yanxindong', 'executable': '/home/yanxindong/anaconda/envs/eva/bin/python', 'cpu_count': 64, 'cpu_count_logical': 128, 'cpu_freq': {'current': 852.487765625, 'min': 800.0, 'max': 3400.0}, 'cpu_freq_per_core': [{'current': 3299.997, 'min': 800.0, 'max': 3400.0}, {'current': 800.0, 'min': 800.0, 'max': 3400.0}, {'current': 800.0, 'min': 800.0, 'max': 3400.0}, {'current': 800.0, 'min': 800.0, 'max': 3400.0}, {'current': 800.0, 'min': 800.0, 'max': 3400.0}, {'current': 800.0, 'min': 800.0, 'max': 3400.0}, {'current': 800.0, 'min': 800.0, 'max': 3400.0}, {'current': 800.0, 'min': 800.0, 'max': 3400.0}, {'current': 900.0, 'min': 800.0, 'max': 3400.0}, {'current': 800.0, 'min': 800.0, 'max': 3400.0}, {'current': 800.0, 'min': 800.0, 'max': 3400.0}, {'current': 800.0, 'min': 800.0, 'max': 3400.0}, {'current': 800.0, 'min': 800.0, 'max': 3400.0}, {'current': 800.0, 'min': 800.0, 'max': 3400.0}, {'current': 800.0, 'min': 800.0, 'max': 3400.0}, {'current': 800.0, 'min': 800.0, 'max': 3400.0}, {'current': 800.0, 'min': 800.0, 'max': 3400.0}, {'current': 800.0, 'min': 800.0, 'max': 3400.0}, {'current': 900.0, 'min': 800.0, 'max': 3400.0}, {'current': 800.0, 'min': 800.0, 'max': 3400.0}, {'current': 800.0, 'min': 800.0, 'max': 3400.0}, {'current': 800.0, 'min': 800.0, 'max': 3400.0}, {'current': 800.0, 'min': 800.0, 'max': 3400.0}, {'current': 800.0, 'min': 800.0, 'max': 3400.0}, {'current': 800.0, 'min': 800.0, 'max': 3400.0}, {'current': 800.0, 'min': 800.0, 'max': 3400.0}, {'current': 800.0, 'min': 800.0, 'max': 3400.0}, {'current': 800.0, 'min': 800.0, 'max': 3400.0}, {'current': 800.0, 'min': 800.0, 'max': 3400.0}, {'current': 800.0, 'min': 800.0, 'max': 3400.0}, {'current': 800.0, 'min': 800.0, 'max': 3400.0}, {'current': 1300.0, 'min': 800.0, 'max': 3400.0}, {'current': 800.0, 'min': 800.0, 'max': 3400.0}, {'current': 800.0, 'min': 800.0, 'max': 3400.0}, {'current': 1300.0, 'min': 800.0, 'max': 3400.0}, {'current': 800.0, 'min': 800.0, 'max': 3400.0}, {'current': 800.0, 'min': 800.0, 'max': 3400.0}, {'current': 800.0, 'min': 800.0, 'max': 3400.0}, {'current': 800.0, 'min': 800.0, 'max': 3400.0}, {'current': 800.0, 'min': 800.0, 'max': 3400.0}, {'current': 800.0, 'min': 800.0, 'max': 3400.0}, {'current': 800.0, 'min': 800.0, 'max': 3400.0}, {'current': 800.0, 'min': 800.0, 'max': 3400.0}, {'current': 800.0, 'min': 800.0, 'max': 3400.0}, {'current': 800.0, 'min': 800.0, 'max': 3400.0}, {'current': 800.0, 'min': 800.0, 'max': 3400.0}, {'current': 800.0, 'min': 800.0, 'max': 3400.0}, {'current': 800.0, 'min': 800.0, 'max': 3400.0}, {'current': 800.0, 'min': 800.0, 'max': 3400.0}, {'current': 800.0, 'min': 800.0, 'max': 3400.0}, {'current': 800.0, 'min': 800.0, 'max': 3400.0}, {'current': 1000.0, 'min': 800.0, 'max': 3400.0}, {'current': 800.0, 'min': 800.0, 'max': 3400.0}, {'current': 800.0, 'min': 800.0, 'max': 3400.0}, {'current': 800.0, 'min': 800.0, 'max': 3400.0}, {'current': 800.0, 'min': 800.0, 'max': 3400.0}, {'current': 800.0, 'min': 800.0, 'max': 3400.0}, {'current': 800.0, 'min': 800.0, 'max': 3400.0}, {'current': 800.0, 'min': 800.0, 'max': 3400.0}, {'current': 800.0, 'min': 800.0, 'max': 3400.0}, {'current': 800.0, 'min': 800.0, 'max': 3400.0}, {'current': 800.0, 'min': 800.0, 'max': 3400.0}, {'current': 800.0, 'min': 800.0, 'max': 3400.0}, {'current': 800.0, 'min': 800.0, 'max': 3400.0}, {'current': 3299.996, 'min': 800.0, 'max': 3400.0}, {'current': 800.0, 'min': 800.0, 'max': 3400.0}, {'current': 800.0, 'min': 800.0, 'max': 3400.0}, {'current': 800.0, 'min': 800.0, 'max': 3400.0}, {'current': 800.0, 'min': 800.0, 'max': 3400.0}, {'current': 800.0, 'min': 800.0, 'max': 3400.0}, {'current': 800.0, 'min': 800.0, 'max': 3400.0}, {'current': 800.0, 'min': 800.0, 'max': 3400.0}, {'current': 800.0, 'min': 800.0, 'max': 3400.0}, {'current': 800.0, 'min': 800.0, 'max': 3400.0}, {'current': 800.0, 'min': 800.0, 'max': 3400.0}, {'current': 800.0, 'min': 800.0, 'max': 3400.0}, {'current': 800.0, 'min': 800.0, 'max': 3400.0}, {'current': 800.0, 'min': 800.0, 'max': 3400.0}, {'current': 800.0, 'min': 800.0, 'max': 3400.0}, {'current': 800.0, 'min': 800.0, 'max': 3400.0}, {'current': 800.0, 'min': 800.0, 'max': 3400.0}, {'current': 800.0, 'min': 800.0, 'max': 3400.0}, {'current': 800.0, 'min': 800.0, 'max': 3400.0}, {'current': 800.0, 'min': 800.0, 'max': 3400.0}, {'current': 800.0, 'min': 800.0, 'max': 3400.0}, {'current': 800.0, 'min': 800.0, 'max': 3400.0}, {'current': 800.0, 'min': 800.0, 'max': 3400.0}, {'current': 800.0, 'min': 800.0, 'max': 3400.0}, {'current': 800.0, 'min': 800.0, 'max': 3400.0}, {'current': 800.0, 'min': 800.0, 'max': 3400.0}, {'current': 800.0, 'min': 800.0, 'max': 3400.0}, {'current': 800.0, 'min': 800.0, 'max': 3400.0}, {'current': 800.0, 'min': 800.0, 'max': 3400.0}, {'current': 800.0, 'min': 800.0, 'max': 3400.0}, {'current': 800.0, 'min': 800.0, 'max': 3400.0}, {'current': 800.0, 'min': 800.0, 'max': 3400.0}, {'current': 800.0, 'min': 800.0, 'max': 3400.0}, {'current': 800.0, 'min': 800.0, 'max': 3400.0}, {'current': 800.0, 'min': 800.0, 'max': 3400.0}, {'current': 800.0, 'min': 800.0, 'max': 3400.0}, {'current': 800.0, 'min': 800.0, 'max': 3400.0}, {'current': 800.0, 'min': 800.0, 'max': 3400.0}, {'current': 800.0, 'min': 800.0, 'max': 3400.0}, {'current': 800.0, 'min': 800.0, 'max': 3400.0}, {'current': 800.0, 'min': 800.0, 'max': 3400.0}, {'current': 800.0, 'min': 800.0, 'max': 3400.0}, {'current': 800.0, 'min': 800.0, 'max': 3400.0}, {'current': 800.0, 'min': 800.0, 'max': 3400.0}, {'current': 800.0, 'min': 800.0, 'max': 3400.0}, {'current': 800.0, 'min': 800.0, 'max': 3400.0}, {'current': 900.0, 'min': 800.0, 'max': 3400.0}, {'current': 900.0, 'min': 800.0, 'max': 3400.0}, {'current': 800.0, 'min': 800.0, 'max': 3400.0}, {'current': 800.0, 'min': 800.0, 'max': 3400.0}, {'current': 800.0, 'min': 800.0, 'max': 3400.0}, {'current': 800.0, 'min': 800.0, 'max': 3400.0}, {'current': 800.0, 'min': 800.0, 'max': 3400.0}, {'current': 800.0, 'min': 800.0, 'max': 3400.0}, {'current': 800.0, 'min': 800.0, 'max': 3400.0}, {'current': 800.0, 'min': 800.0, 'max': 3400.0}, {'current': 800.0, 'min': 800.0, 'max': 3400.0}, {'current': 800.0, 'min': 800.0, 'max': 3400.0}, {'current': 800.0, 'min': 800.0, 'max': 3400.0}, {'current': 800.0, 'min': 800.0, 'max': 3400.0}, {'current': 800.0, 'min': 800.0, 'max': 3400.0}, {'current': 800.0, 'min': 800.0, 'max': 3400.0}, {'current': 800.0, 'min': 800.0, 'max': 3400.0}, {'current': 800.0, 'min': 800.0, 'max': 3400.0}], 'disk': {'/': {'total': 438.05088806152344, 'used': 30.817367553710938}}, 'gpu': 'NVIDIA RTX A6000', 'gpu_count': 8, 'gpu_devices': [{'name': 'NVIDIA RTX A6000', 'memory_total': 51527024640}, {'name': 'NVIDIA RTX A6000', 'memory_total': 51527024640}, {'name': 'NVIDIA RTX A6000', 'memory_total': 51527024640}, {'name': 'NVIDIA RTX A6000', 'memory_total': 51527024640}, {'name': 'NVIDIA RTX A6000', 'memory_total': 51527024640}, {'name': 'NVIDIA RTX A6000', 'memory_total': 51527024640}, {'name': 'NVIDIA RTX A6000', 'memory_total': 51527024640}, {'name': 'NVIDIA RTX A6000', 'memory_total': 51527024640}], 'memory': {'total': 503.51252365112305}}
2024-01-30 16:10:14,754 INFO    HandlerThread:1134330 [system_monitor.py:probe():224] Finished collecting system info
2024-01-30 16:10:14,754 INFO    HandlerThread:1134330 [system_monitor.py:probe():227] Publishing system info
2024-01-30 16:10:14,755 DEBUG   HandlerThread:1134330 [system_info.py:_save_conda():208] Saving list of conda packages installed into the current environment
2024-01-30 16:10:15,635 INFO    Thread-12 :1134330 [dir_watcher.py:_on_file_created():271] file/dir created: /home/yanxindong/mkor/bert/wandb/run-20240130_161012-87yhbfo2/files/conda-environment.yaml
2024-01-30 16:10:35,608 DEBUG   HandlerThread:1134330 [system_info.py:_save_conda():220] Saving conda packages done
2024-01-30 16:10:35,610 INFO    HandlerThread:1134330 [system_monitor.py:probe():229] Finished publishing system info
2024-01-30 16:10:35,615 DEBUG   HandlerThread:1134330 [handler.py:handle_request():146] handle_request: status_report
2024-01-30 16:10:35,621 DEBUG   HandlerThread:1134330 [handler.py:handle_request():146] handle_request: keepalive
2024-01-30 16:10:35,622 DEBUG   HandlerThread:1134330 [handler.py:handle_request():146] handle_request: status_report
2024-01-30 16:10:35,622 DEBUG   HandlerThread:1134330 [handler.py:handle_request():146] handle_request: keepalive
2024-01-30 16:10:35,622 DEBUG   HandlerThread:1134330 [handler.py:handle_request():146] handle_request: status_report
2024-01-30 16:10:35,622 DEBUG   HandlerThread:1134330 [handler.py:handle_request():146] handle_request: keepalive
2024-01-30 16:10:35,622 DEBUG   HandlerThread:1134330 [handler.py:handle_request():146] handle_request: status_report
2024-01-30 16:10:35,622 DEBUG   HandlerThread:1134330 [handler.py:handle_request():146] handle_request: keepalive
2024-01-30 16:10:35,622 DEBUG   HandlerThread:1134330 [handler.py:handle_request():146] handle_request: python_packages
2024-01-30 16:10:35,622 DEBUG   SenderThread:1134330 [sender.py:send():382] send: files
2024-01-30 16:10:35,622 INFO    SenderThread:1134330 [sender.py:_save_file():1403] saving file wandb-metadata.json with policy now
2024-01-30 16:10:35,623 DEBUG   SenderThread:1134330 [sender.py:send_request():409] send_request: python_packages
2024-01-30 16:10:35,642 DEBUG   HandlerThread:1134330 [handler.py:handle_request():146] handle_request: stop_status
2024-01-30 16:10:35,642 DEBUG   SenderThread:1134330 [sender.py:send_request():409] send_request: stop_status
2024-01-30 16:10:35,645 INFO    Thread-12 :1134330 [dir_watcher.py:_on_file_modified():288] file/dir modified: /home/yanxindong/mkor/bert/wandb/run-20240130_161012-87yhbfo2/files/conda-environment.yaml
2024-01-30 16:10:35,645 INFO    Thread-12 :1134330 [dir_watcher.py:_on_file_created():271] file/dir created: /home/yanxindong/mkor/bert/wandb/run-20240130_161012-87yhbfo2/files/requirements.txt
2024-01-30 16:10:35,645 INFO    Thread-12 :1134330 [dir_watcher.py:_on_file_created():271] file/dir created: /home/yanxindong/mkor/bert/wandb/run-20240130_161012-87yhbfo2/files/wandb-metadata.json
2024-01-30 16:10:35,702 DEBUG   HandlerThread:1134330 [handler.py:handle_request():146] handle_request: internal_messages
2024-01-30 16:10:36,000 DEBUG   SenderThread:1134330 [sender.py:send():382] send: telemetry
2024-01-30 16:10:36,360 ERROR   wandb-upload_0:1134330 [internal_api.py:upload_file():2765] upload_file exception https://storage.googleapis.com/wandb-production.appspot.com/dynamic_x/bert_pytorch/87yhbfo2/wandb-metadata.json?Expires=1706688636&GoogleAccessId=gorilla-files-url-signer-man%40wandb-production.iam.gserviceaccount.com&Signature=i6ygl6e%2F1NTaK6CPvF0NXZCkqswXBKlbsIAlDONRJsh%2B3x8JGZM%2F%2F23d4nP224TGJJG%2FCwEhFPdSuwxqSBYHv%2By9Ud6qOPv71v5oMy3xjK95cP8S5aO5KfCrnKtrIOmrXhlAhzuwVq6uvAKGfNqgQD6MEyp8CsvfEfy7pGsDDEXhj40LUnzeh4v3UzcU9ErrNfA3%2Fisa1FmirWu%2FkUcHDNpTeHVwdhLMUqnr5fYBL47fFxTQFwVRLqi9eHGGatIhaAP0mH%2BbS54b2T7CtyGpcXkoRBRSTcKBdvyiBiPDGie7PGw9Xsb6h0zFIIHbjehEtC3Q24GdjVu1TNNGFHYb3w%3D%3D: HTTPSConnectionPool(host='storage.googleapis.com', port=443): Max retries exceeded with url: /wandb-production.appspot.com/dynamic_x/bert_pytorch/87yhbfo2/wandb-metadata.json?Expires=1706688636&GoogleAccessId=gorilla-files-url-signer-man%40wandb-production.iam.gserviceaccount.com&Signature=i6ygl6e%2F1NTaK6CPvF0NXZCkqswXBKlbsIAlDONRJsh%2B3x8JGZM%2F%2F23d4nP224TGJJG%2FCwEhFPdSuwxqSBYHv%2By9Ud6qOPv71v5oMy3xjK95cP8S5aO5KfCrnKtrIOmrXhlAhzuwVq6uvAKGfNqgQD6MEyp8CsvfEfy7pGsDDEXhj40LUnzeh4v3UzcU9ErrNfA3%2Fisa1FmirWu%2FkUcHDNpTeHVwdhLMUqnr5fYBL47fFxTQFwVRLqi9eHGGatIhaAP0mH%2BbS54b2T7CtyGpcXkoRBRSTcKBdvyiBiPDGie7PGw9Xsb6h0zFIIHbjehEtC3Q24GdjVu1TNNGFHYb3w%3D%3D (Caused by NewConnectionError('<urllib3.connection.HTTPSConnection object at 0x7f859811b250>: Failed to establish a new connection: [Errno 111] Connection refused'))
2024-01-30 16:10:36,360 ERROR   wandb-upload_0:1134330 [internal_api.py:upload_file():2767] upload_file request headers: {'User-Agent': 'python-requests/2.23.0', 'Accept-Encoding': 'gzip, deflate', 'Accept': '*/*', 'Connection': 'keep-alive', 'Content-Length': '15551'}
2024-01-30 16:10:36,360 ERROR   wandb-upload_0:1134330 [internal_api.py:upload_file():2769] upload_file response body: 
2024-01-30 16:10:37,423 ERROR   wandb-upload_0:1134330 [internal_api.py:upload_file():2765] upload_file exception https://storage.googleapis.com/wandb-production.appspot.com/dynamic_x/bert_pytorch/87yhbfo2/wandb-metadata.json?Expires=1706688636&GoogleAccessId=gorilla-files-url-signer-man%40wandb-production.iam.gserviceaccount.com&Signature=i6ygl6e%2F1NTaK6CPvF0NXZCkqswXBKlbsIAlDONRJsh%2B3x8JGZM%2F%2F23d4nP224TGJJG%2FCwEhFPdSuwxqSBYHv%2By9Ud6qOPv71v5oMy3xjK95cP8S5aO5KfCrnKtrIOmrXhlAhzuwVq6uvAKGfNqgQD6MEyp8CsvfEfy7pGsDDEXhj40LUnzeh4v3UzcU9ErrNfA3%2Fisa1FmirWu%2FkUcHDNpTeHVwdhLMUqnr5fYBL47fFxTQFwVRLqi9eHGGatIhaAP0mH%2BbS54b2T7CtyGpcXkoRBRSTcKBdvyiBiPDGie7PGw9Xsb6h0zFIIHbjehEtC3Q24GdjVu1TNNGFHYb3w%3D%3D: HTTPSConnectionPool(host='storage.googleapis.com', port=443): Max retries exceeded with url: /wandb-production.appspot.com/dynamic_x/bert_pytorch/87yhbfo2/wandb-metadata.json?Expires=1706688636&GoogleAccessId=gorilla-files-url-signer-man%40wandb-production.iam.gserviceaccount.com&Signature=i6ygl6e%2F1NTaK6CPvF0NXZCkqswXBKlbsIAlDONRJsh%2B3x8JGZM%2F%2F23d4nP224TGJJG%2FCwEhFPdSuwxqSBYHv%2By9Ud6qOPv71v5oMy3xjK95cP8S5aO5KfCrnKtrIOmrXhlAhzuwVq6uvAKGfNqgQD6MEyp8CsvfEfy7pGsDDEXhj40LUnzeh4v3UzcU9ErrNfA3%2Fisa1FmirWu%2FkUcHDNpTeHVwdhLMUqnr5fYBL47fFxTQFwVRLqi9eHGGatIhaAP0mH%2BbS54b2T7CtyGpcXkoRBRSTcKBdvyiBiPDGie7PGw9Xsb6h0zFIIHbjehEtC3Q24GdjVu1TNNGFHYb3w%3D%3D (Caused by NewConnectionError('<urllib3.connection.HTTPSConnection object at 0x7f859811bf10>: Failed to establish a new connection: [Errno 111] Connection refused'))
2024-01-30 16:10:37,423 ERROR   wandb-upload_0:1134330 [internal_api.py:upload_file():2767] upload_file request headers: {'User-Agent': 'python-requests/2.23.0', 'Accept-Encoding': 'gzip, deflate', 'Accept': '*/*', 'Connection': 'keep-alive', 'Content-Length': '15551'}
2024-01-30 16:10:37,423 ERROR   wandb-upload_0:1134330 [internal_api.py:upload_file():2769] upload_file response body: 
2024-01-30 16:10:39,001 DEBUG   HandlerThread:1134330 [handler.py:handle_request():146] handle_request: status_report
2024-01-30 16:10:39,690 ERROR   wandb-upload_0:1134330 [internal_api.py:upload_file():2765] upload_file exception https://storage.googleapis.com/wandb-production.appspot.com/dynamic_x/bert_pytorch/87yhbfo2/wandb-metadata.json?Expires=1706688636&GoogleAccessId=gorilla-files-url-signer-man%40wandb-production.iam.gserviceaccount.com&Signature=i6ygl6e%2F1NTaK6CPvF0NXZCkqswXBKlbsIAlDONRJsh%2B3x8JGZM%2F%2F23d4nP224TGJJG%2FCwEhFPdSuwxqSBYHv%2By9Ud6qOPv71v5oMy3xjK95cP8S5aO5KfCrnKtrIOmrXhlAhzuwVq6uvAKGfNqgQD6MEyp8CsvfEfy7pGsDDEXhj40LUnzeh4v3UzcU9ErrNfA3%2Fisa1FmirWu%2FkUcHDNpTeHVwdhLMUqnr5fYBL47fFxTQFwVRLqi9eHGGatIhaAP0mH%2BbS54b2T7CtyGpcXkoRBRSTcKBdvyiBiPDGie7PGw9Xsb6h0zFIIHbjehEtC3Q24GdjVu1TNNGFHYb3w%3D%3D: HTTPSConnectionPool(host='storage.googleapis.com', port=443): Max retries exceeded with url: /wandb-production.appspot.com/dynamic_x/bert_pytorch/87yhbfo2/wandb-metadata.json?Expires=1706688636&GoogleAccessId=gorilla-files-url-signer-man%40wandb-production.iam.gserviceaccount.com&Signature=i6ygl6e%2F1NTaK6CPvF0NXZCkqswXBKlbsIAlDONRJsh%2B3x8JGZM%2F%2F23d4nP224TGJJG%2FCwEhFPdSuwxqSBYHv%2By9Ud6qOPv71v5oMy3xjK95cP8S5aO5KfCrnKtrIOmrXhlAhzuwVq6uvAKGfNqgQD6MEyp8CsvfEfy7pGsDDEXhj40LUnzeh4v3UzcU9ErrNfA3%2Fisa1FmirWu%2FkUcHDNpTeHVwdhLMUqnr5fYBL47fFxTQFwVRLqi9eHGGatIhaAP0mH%2BbS54b2T7CtyGpcXkoRBRSTcKBdvyiBiPDGie7PGw9Xsb6h0zFIIHbjehEtC3Q24GdjVu1TNNGFHYb3w%3D%3D (Caused by NewConnectionError('<urllib3.connection.HTTPSConnection object at 0x7f859811b550>: Failed to establish a new connection: [Errno 111] Connection refused'))
2024-01-30 16:10:39,690 ERROR   wandb-upload_0:1134330 [internal_api.py:upload_file():2767] upload_file request headers: {'User-Agent': 'python-requests/2.23.0', 'Accept-Encoding': 'gzip, deflate', 'Accept': '*/*', 'Connection': 'keep-alive', 'Content-Length': '15551'}
2024-01-30 16:10:39,690 ERROR   wandb-upload_0:1134330 [internal_api.py:upload_file():2769] upload_file response body: 
2024-01-30 16:10:39,690 INFO    wandb-upload_0:1134330 [retry.py:__call__():172] Retry attempt failed:
Traceback (most recent call last):
  File "/home/yanxindong/anaconda/envs/eva/lib/python3.8/site-packages/urllib3/connection.py", line 159, in _new_conn
    conn = connection.create_connection(
  File "/home/yanxindong/anaconda/envs/eva/lib/python3.8/site-packages/urllib3/util/connection.py", line 84, in create_connection
    raise err
  File "/home/yanxindong/anaconda/envs/eva/lib/python3.8/site-packages/urllib3/util/connection.py", line 74, in create_connection
    sock.connect(sa)
ConnectionRefusedError: [Errno 111] Connection refused

During handling of the above exception, another exception occurred:

Traceback (most recent call last):
  File "/home/yanxindong/anaconda/envs/eva/lib/python3.8/site-packages/urllib3/connectionpool.py", line 670, in urlopen
    httplib_response = self._make_request(
  File "/home/yanxindong/anaconda/envs/eva/lib/python3.8/site-packages/urllib3/connectionpool.py", line 381, in _make_request
    self._validate_conn(conn)
  File "/home/yanxindong/anaconda/envs/eva/lib/python3.8/site-packages/urllib3/connectionpool.py", line 978, in _validate_conn
    conn.connect()
  File "/home/yanxindong/anaconda/envs/eva/lib/python3.8/site-packages/urllib3/connection.py", line 309, in connect
    conn = self._new_conn()
  File "/home/yanxindong/anaconda/envs/eva/lib/python3.8/site-packages/urllib3/connection.py", line 171, in _new_conn
    raise NewConnectionError(
urllib3.exceptions.NewConnectionError: <urllib3.connection.HTTPSConnection object at 0x7f859811b550>: Failed to establish a new connection: [Errno 111] Connection refused

During handling of the above exception, another exception occurred:

Traceback (most recent call last):
  File "/home/yanxindong/anaconda/envs/eva/lib/python3.8/site-packages/requests/adapters.py", line 439, in send
    resp = conn.urlopen(
  File "/home/yanxindong/anaconda/envs/eva/lib/python3.8/site-packages/urllib3/connectionpool.py", line 726, in urlopen
    retries = retries.increment(
  File "/home/yanxindong/anaconda/envs/eva/lib/python3.8/site-packages/urllib3/util/retry.py", line 446, in increment
    raise MaxRetryError(_pool, url, error or ResponseError(cause))
urllib3.exceptions.MaxRetryError: HTTPSConnectionPool(host='storage.googleapis.com', port=443): Max retries exceeded with url: /wandb-production.appspot.com/dynamic_x/bert_pytorch/87yhbfo2/wandb-metadata.json?Expires=1706688636&GoogleAccessId=gorilla-files-url-signer-man%40wandb-production.iam.gserviceaccount.com&Signature=i6ygl6e%2F1NTaK6CPvF0NXZCkqswXBKlbsIAlDONRJsh%2B3x8JGZM%2F%2F23d4nP224TGJJG%2FCwEhFPdSuwxqSBYHv%2By9Ud6qOPv71v5oMy3xjK95cP8S5aO5KfCrnKtrIOmrXhlAhzuwVq6uvAKGfNqgQD6MEyp8CsvfEfy7pGsDDEXhj40LUnzeh4v3UzcU9ErrNfA3%2Fisa1FmirWu%2FkUcHDNpTeHVwdhLMUqnr5fYBL47fFxTQFwVRLqi9eHGGatIhaAP0mH%2BbS54b2T7CtyGpcXkoRBRSTcKBdvyiBiPDGie7PGw9Xsb6h0zFIIHbjehEtC3Q24GdjVu1TNNGFHYb3w%3D%3D (Caused by NewConnectionError('<urllib3.connection.HTTPSConnection object at 0x7f859811b550>: Failed to establish a new connection: [Errno 111] Connection refused'))

During handling of the above exception, another exception occurred:

Traceback (most recent call last):
  File "/home/yanxindong/anaconda/envs/eva/lib/python3.8/site-packages/wandb/sdk/internal/internal_api.py", line 2758, in upload_file
    response = self._upload_file_session.put(
  File "/home/yanxindong/anaconda/envs/eva/lib/python3.8/site-packages/requests/sessions.py", line 590, in put
    return self.request('PUT', url, data=data, **kwargs)
  File "/home/yanxindong/anaconda/envs/eva/lib/python3.8/site-packages/requests/sessions.py", line 530, in request
    resp = self.send(prep, **send_kwargs)
  File "/home/yanxindong/anaconda/envs/eva/lib/python3.8/site-packages/requests/sessions.py", line 643, in send
    r = adapter.send(request, **kwargs)
  File "/home/yanxindong/anaconda/envs/eva/lib/python3.8/site-packages/requests/adapters.py", line 516, in send
    raise ConnectionError(e, request=request)
requests.exceptions.ConnectionError: HTTPSConnectionPool(host='storage.googleapis.com', port=443): Max retries exceeded with url: /wandb-production.appspot.com/dynamic_x/bert_pytorch/87yhbfo2/wandb-metadata.json?Expires=1706688636&GoogleAccessId=gorilla-files-url-signer-man%40wandb-production.iam.gserviceaccount.com&Signature=i6ygl6e%2F1NTaK6CPvF0NXZCkqswXBKlbsIAlDONRJsh%2B3x8JGZM%2F%2F23d4nP224TGJJG%2FCwEhFPdSuwxqSBYHv%2By9Ud6qOPv71v5oMy3xjK95cP8S5aO5KfCrnKtrIOmrXhlAhzuwVq6uvAKGfNqgQD6MEyp8CsvfEfy7pGsDDEXhj40LUnzeh4v3UzcU9ErrNfA3%2Fisa1FmirWu%2FkUcHDNpTeHVwdhLMUqnr5fYBL47fFxTQFwVRLqi9eHGGatIhaAP0mH%2BbS54b2T7CtyGpcXkoRBRSTcKBdvyiBiPDGie7PGw9Xsb6h0zFIIHbjehEtC3Q24GdjVu1TNNGFHYb3w%3D%3D (Caused by NewConnectionError('<urllib3.connection.HTTPSConnection object at 0x7f859811b550>: Failed to establish a new connection: [Errno 111] Connection refused'))

During handling of the above exception, another exception occurred:

Traceback (most recent call last):
  File "/home/yanxindong/anaconda/envs/eva/lib/python3.8/site-packages/wandb/sdk/lib/retry.py", line 131, in __call__
    result = self._call_fn(*args, **kwargs)
  File "/home/yanxindong/anaconda/envs/eva/lib/python3.8/site-packages/wandb/sdk/internal/internal_api.py", line 2789, in upload_file
    raise _e.with_traceback(sys.exc_info()[2])
  File "/home/yanxindong/anaconda/envs/eva/lib/python3.8/site-packages/wandb/sdk/internal/internal_api.py", line 2758, in upload_file
    response = self._upload_file_session.put(
  File "/home/yanxindong/anaconda/envs/eva/lib/python3.8/site-packages/requests/sessions.py", line 590, in put
    return self.request('PUT', url, data=data, **kwargs)
  File "/home/yanxindong/anaconda/envs/eva/lib/python3.8/site-packages/requests/sessions.py", line 530, in request
    resp = self.send(prep, **send_kwargs)
  File "/home/yanxindong/anaconda/envs/eva/lib/python3.8/site-packages/requests/sessions.py", line 643, in send
    r = adapter.send(request, **kwargs)
  File "/home/yanxindong/anaconda/envs/eva/lib/python3.8/site-packages/requests/adapters.py", line 516, in send
    raise ConnectionError(e, request=request)
wandb.sdk.lib.retry.TransientError: None
2024-01-30 16:10:44,009 DEBUG   HandlerThread:1134330 [handler.py:handle_request():146] handle_request: status_report
2024-01-30 16:10:44,666 ERROR   wandb-upload_0:1134330 [internal_api.py:upload_file():2765] upload_file exception https://storage.googleapis.com/wandb-production.appspot.com/dynamic_x/bert_pytorch/87yhbfo2/wandb-metadata.json?Expires=1706688636&GoogleAccessId=gorilla-files-url-signer-man%40wandb-production.iam.gserviceaccount.com&Signature=i6ygl6e%2F1NTaK6CPvF0NXZCkqswXBKlbsIAlDONRJsh%2B3x8JGZM%2F%2F23d4nP224TGJJG%2FCwEhFPdSuwxqSBYHv%2By9Ud6qOPv71v5oMy3xjK95cP8S5aO5KfCrnKtrIOmrXhlAhzuwVq6uvAKGfNqgQD6MEyp8CsvfEfy7pGsDDEXhj40LUnzeh4v3UzcU9ErrNfA3%2Fisa1FmirWu%2FkUcHDNpTeHVwdhLMUqnr5fYBL47fFxTQFwVRLqi9eHGGatIhaAP0mH%2BbS54b2T7CtyGpcXkoRBRSTcKBdvyiBiPDGie7PGw9Xsb6h0zFIIHbjehEtC3Q24GdjVu1TNNGFHYb3w%3D%3D: HTTPSConnectionPool(host='storage.googleapis.com', port=443): Max retries exceeded with url: /wandb-production.appspot.com/dynamic_x/bert_pytorch/87yhbfo2/wandb-metadata.json?Expires=1706688636&GoogleAccessId=gorilla-files-url-signer-man%40wandb-production.iam.gserviceaccount.com&Signature=i6ygl6e%2F1NTaK6CPvF0NXZCkqswXBKlbsIAlDONRJsh%2B3x8JGZM%2F%2F23d4nP224TGJJG%2FCwEhFPdSuwxqSBYHv%2By9Ud6qOPv71v5oMy3xjK95cP8S5aO5KfCrnKtrIOmrXhlAhzuwVq6uvAKGfNqgQD6MEyp8CsvfEfy7pGsDDEXhj40LUnzeh4v3UzcU9ErrNfA3%2Fisa1FmirWu%2FkUcHDNpTeHVwdhLMUqnr5fYBL47fFxTQFwVRLqi9eHGGatIhaAP0mH%2BbS54b2T7CtyGpcXkoRBRSTcKBdvyiBiPDGie7PGw9Xsb6h0zFIIHbjehEtC3Q24GdjVu1TNNGFHYb3w%3D%3D (Caused by NewConnectionError('<urllib3.connection.HTTPSConnection object at 0x7f859812ffd0>: Failed to establish a new connection: [Errno 111] Connection refused'))
2024-01-30 16:10:44,666 ERROR   wandb-upload_0:1134330 [internal_api.py:upload_file():2767] upload_file request headers: {'User-Agent': 'python-requests/2.23.0', 'Accept-Encoding': 'gzip, deflate', 'Accept': '*/*', 'Connection': 'keep-alive', 'Content-Length': '15551'}
2024-01-30 16:10:44,666 ERROR   wandb-upload_0:1134330 [internal_api.py:upload_file():2769] upload_file response body: 
2024-01-30 16:10:45,654 INFO    Thread-12 :1134330 [dir_watcher.py:_on_file_modified():288] file/dir modified: /home/yanxindong/mkor/bert/wandb/run-20240130_161012-87yhbfo2/files/config.yaml
2024-01-30 16:10:49,694 DEBUG   HandlerThread:1134330 [handler.py:handle_request():146] handle_request: status_report
2024-01-30 16:10:50,661 DEBUG   HandlerThread:1134330 [handler.py:handle_request():146] handle_request: stop_status
2024-01-30 16:10:50,662 DEBUG   SenderThread:1134330 [sender.py:send_request():409] send_request: stop_status
2024-01-30 16:10:50,686 DEBUG   HandlerThread:1134330 [handler.py:handle_request():146] handle_request: internal_messages
2024-01-30 16:10:54,391 ERROR   wandb-upload_0:1134330 [internal_api.py:upload_file():2765] upload_file exception https://storage.googleapis.com/wandb-production.appspot.com/dynamic_x/bert_pytorch/87yhbfo2/wandb-metadata.json?Expires=1706688636&GoogleAccessId=gorilla-files-url-signer-man%40wandb-production.iam.gserviceaccount.com&Signature=i6ygl6e%2F1NTaK6CPvF0NXZCkqswXBKlbsIAlDONRJsh%2B3x8JGZM%2F%2F23d4nP224TGJJG%2FCwEhFPdSuwxqSBYHv%2By9Ud6qOPv71v5oMy3xjK95cP8S5aO5KfCrnKtrIOmrXhlAhzuwVq6uvAKGfNqgQD6MEyp8CsvfEfy7pGsDDEXhj40LUnzeh4v3UzcU9ErrNfA3%2Fisa1FmirWu%2FkUcHDNpTeHVwdhLMUqnr5fYBL47fFxTQFwVRLqi9eHGGatIhaAP0mH%2BbS54b2T7CtyGpcXkoRBRSTcKBdvyiBiPDGie7PGw9Xsb6h0zFIIHbjehEtC3Q24GdjVu1TNNGFHYb3w%3D%3D: HTTPSConnectionPool(host='storage.googleapis.com', port=443): Max retries exceeded with url: /wandb-production.appspot.com/dynamic_x/bert_pytorch/87yhbfo2/wandb-metadata.json?Expires=1706688636&GoogleAccessId=gorilla-files-url-signer-man%40wandb-production.iam.gserviceaccount.com&Signature=i6ygl6e%2F1NTaK6CPvF0NXZCkqswXBKlbsIAlDONRJsh%2B3x8JGZM%2F%2F23d4nP224TGJJG%2FCwEhFPdSuwxqSBYHv%2By9Ud6qOPv71v5oMy3xjK95cP8S5aO5KfCrnKtrIOmrXhlAhzuwVq6uvAKGfNqgQD6MEyp8CsvfEfy7pGsDDEXhj40LUnzeh4v3UzcU9ErrNfA3%2Fisa1FmirWu%2FkUcHDNpTeHVwdhLMUqnr5fYBL47fFxTQFwVRLqi9eHGGatIhaAP0mH%2BbS54b2T7CtyGpcXkoRBRSTcKBdvyiBiPDGie7PGw9Xsb6h0zFIIHbjehEtC3Q24GdjVu1TNNGFHYb3w%3D%3D (Caused by NewConnectionError('<urllib3.connection.HTTPSConnection object at 0x7f859811beb0>: Failed to establish a new connection: [Errno 111] Connection refused'))
2024-01-30 16:10:54,391 ERROR   wandb-upload_0:1134330 [internal_api.py:upload_file():2767] upload_file request headers: {'User-Agent': 'python-requests/2.23.0', 'Accept-Encoding': 'gzip, deflate', 'Accept': '*/*', 'Connection': 'keep-alive', 'Content-Length': '15551'}
2024-01-30 16:10:54,392 ERROR   wandb-upload_0:1134330 [internal_api.py:upload_file():2769] upload_file response body: 
2024-01-30 16:10:55,020 DEBUG   HandlerThread:1134330 [handler.py:handle_request():146] handle_request: status_report
2024-01-30 16:11:00,021 DEBUG   HandlerThread:1134330 [handler.py:handle_request():146] handle_request: status_report
2024-01-30 16:11:05,021 DEBUG   HandlerThread:1134330 [handler.py:handle_request():146] handle_request: status_report
2024-01-30 16:11:05,637 DEBUG   HandlerThread:1134330 [handler.py:handle_request():146] handle_request: stop_status
2024-01-30 16:11:05,637 DEBUG   SenderThread:1134330 [sender.py:send_request():409] send_request: stop_status
2024-01-30 16:11:05,686 DEBUG   HandlerThread:1134330 [handler.py:handle_request():146] handle_request: internal_messages
2024-01-30 16:11:10,948 DEBUG   HandlerThread:1134330 [handler.py:handle_request():146] handle_request: status_report
2024-01-30 16:11:11,728 ERROR   wandb-upload_0:1134330 [internal_api.py:upload_file():2765] upload_file exception https://storage.googleapis.com/wandb-production.appspot.com/dynamic_x/bert_pytorch/87yhbfo2/wandb-metadata.json?Expires=1706688636&GoogleAccessId=gorilla-files-url-signer-man%40wandb-production.iam.gserviceaccount.com&Signature=i6ygl6e%2F1NTaK6CPvF0NXZCkqswXBKlbsIAlDONRJsh%2B3x8JGZM%2F%2F23d4nP224TGJJG%2FCwEhFPdSuwxqSBYHv%2By9Ud6qOPv71v5oMy3xjK95cP8S5aO5KfCrnKtrIOmrXhlAhzuwVq6uvAKGfNqgQD6MEyp8CsvfEfy7pGsDDEXhj40LUnzeh4v3UzcU9ErrNfA3%2Fisa1FmirWu%2FkUcHDNpTeHVwdhLMUqnr5fYBL47fFxTQFwVRLqi9eHGGatIhaAP0mH%2BbS54b2T7CtyGpcXkoRBRSTcKBdvyiBiPDGie7PGw9Xsb6h0zFIIHbjehEtC3Q24GdjVu1TNNGFHYb3w%3D%3D: HTTPSConnectionPool(host='storage.googleapis.com', port=443): Max retries exceeded with url: /wandb-production.appspot.com/dynamic_x/bert_pytorch/87yhbfo2/wandb-metadata.json?Expires=1706688636&GoogleAccessId=gorilla-files-url-signer-man%40wandb-production.iam.gserviceaccount.com&Signature=i6ygl6e%2F1NTaK6CPvF0NXZCkqswXBKlbsIAlDONRJsh%2B3x8JGZM%2F%2F23d4nP224TGJJG%2FCwEhFPdSuwxqSBYHv%2By9Ud6qOPv71v5oMy3xjK95cP8S5aO5KfCrnKtrIOmrXhlAhzuwVq6uvAKGfNqgQD6MEyp8CsvfEfy7pGsDDEXhj40LUnzeh4v3UzcU9ErrNfA3%2Fisa1FmirWu%2FkUcHDNpTeHVwdhLMUqnr5fYBL47fFxTQFwVRLqi9eHGGatIhaAP0mH%2BbS54b2T7CtyGpcXkoRBRSTcKBdvyiBiPDGie7PGw9Xsb6h0zFIIHbjehEtC3Q24GdjVu1TNNGFHYb3w%3D%3D (Caused by NewConnectionError('<urllib3.connection.HTTPSConnection object at 0x7f85980621f0>: Failed to establish a new connection: [Errno 111] Connection refused'))
2024-01-30 16:11:11,728 ERROR   wandb-upload_0:1134330 [internal_api.py:upload_file():2767] upload_file request headers: {'User-Agent': 'python-requests/2.23.0', 'Accept-Encoding': 'gzip, deflate', 'Accept': '*/*', 'Connection': 'keep-alive', 'Content-Length': '15551'}
2024-01-30 16:11:11,728 ERROR   wandb-upload_0:1134330 [internal_api.py:upload_file():2769] upload_file response body: 
2024-01-30 16:11:14,661 DEBUG   SystemMonitor:1134330 [system_monitor.py:_start():172] Starting system metrics aggregation loop
2024-01-30 16:11:14,665 DEBUG   SenderThread:1134330 [sender.py:send():382] send: stats
2024-01-30 16:11:16,667 DEBUG   HandlerThread:1134330 [handler.py:handle_request():146] handle_request: status_report
2024-01-30 16:11:20,637 DEBUG   HandlerThread:1134330 [handler.py:handle_request():146] handle_request: stop_status
2024-01-30 16:11:20,638 DEBUG   SenderThread:1134330 [sender.py:send_request():409] send_request: stop_status
2024-01-30 16:11:20,686 DEBUG   HandlerThread:1134330 [handler.py:handle_request():146] handle_request: internal_messages
2024-01-30 16:11:21,937 DEBUG   HandlerThread:1134330 [handler.py:handle_request():146] handle_request: status_report
2024-01-30 16:11:26,938 DEBUG   HandlerThread:1134330 [handler.py:handle_request():146] handle_request: status_report
2024-01-30 16:11:31,981 DEBUG   HandlerThread:1134330 [handler.py:handle_request():146] handle_request: status_report
2024-01-30 16:11:35,637 DEBUG   HandlerThread:1134330 [handler.py:handle_request():146] handle_request: stop_status
2024-01-30 16:11:35,637 DEBUG   SenderThread:1134330 [sender.py:send_request():409] send_request: stop_status
2024-01-30 16:11:35,686 DEBUG   HandlerThread:1134330 [handler.py:handle_request():146] handle_request: internal_messages
2024-01-30 16:11:37,917 DEBUG   HandlerThread:1134330 [handler.py:handle_request():146] handle_request: status_report
2024-01-30 16:11:42,917 DEBUG   HandlerThread:1134330 [handler.py:handle_request():146] handle_request: status_report
2024-01-30 16:11:44,668 DEBUG   SenderThread:1134330 [sender.py:send():382] send: stats
2024-01-30 16:11:46,988 ERROR   wandb-upload_0:1134330 [internal_api.py:upload_file():2765] upload_file exception https://storage.googleapis.com/wandb-production.appspot.com/dynamic_x/bert_pytorch/87yhbfo2/wandb-metadata.json?Expires=1706688636&GoogleAccessId=gorilla-files-url-signer-man%40wandb-production.iam.gserviceaccount.com&Signature=i6ygl6e%2F1NTaK6CPvF0NXZCkqswXBKlbsIAlDONRJsh%2B3x8JGZM%2F%2F23d4nP224TGJJG%2FCwEhFPdSuwxqSBYHv%2By9Ud6qOPv71v5oMy3xjK95cP8S5aO5KfCrnKtrIOmrXhlAhzuwVq6uvAKGfNqgQD6MEyp8CsvfEfy7pGsDDEXhj40LUnzeh4v3UzcU9ErrNfA3%2Fisa1FmirWu%2FkUcHDNpTeHVwdhLMUqnr5fYBL47fFxTQFwVRLqi9eHGGatIhaAP0mH%2BbS54b2T7CtyGpcXkoRBRSTcKBdvyiBiPDGie7PGw9Xsb6h0zFIIHbjehEtC3Q24GdjVu1TNNGFHYb3w%3D%3D: HTTPSConnectionPool(host='storage.googleapis.com', port=443): Max retries exceeded with url: /wandb-production.appspot.com/dynamic_x/bert_pytorch/87yhbfo2/wandb-metadata.json?Expires=1706688636&GoogleAccessId=gorilla-files-url-signer-man%40wandb-production.iam.gserviceaccount.com&Signature=i6ygl6e%2F1NTaK6CPvF0NXZCkqswXBKlbsIAlDONRJsh%2B3x8JGZM%2F%2F23d4nP224TGJJG%2FCwEhFPdSuwxqSBYHv%2By9Ud6qOPv71v5oMy3xjK95cP8S5aO5KfCrnKtrIOmrXhlAhzuwVq6uvAKGfNqgQD6MEyp8CsvfEfy7pGsDDEXhj40LUnzeh4v3UzcU9ErrNfA3%2Fisa1FmirWu%2FkUcHDNpTeHVwdhLMUqnr5fYBL47fFxTQFwVRLqi9eHGGatIhaAP0mH%2BbS54b2T7CtyGpcXkoRBRSTcKBdvyiBiPDGie7PGw9Xsb6h0zFIIHbjehEtC3Q24GdjVu1TNNGFHYb3w%3D%3D (Caused by NewConnectionError('<urllib3.connection.HTTPSConnection object at 0x7f859812fb20>: Failed to establish a new connection: [Errno 101] Network is unreachable'))
2024-01-30 16:11:46,989 ERROR   wandb-upload_0:1134330 [internal_api.py:upload_file():2767] upload_file request headers: {'User-Agent': 'python-requests/2.23.0', 'Accept-Encoding': 'gzip, deflate', 'Accept': '*/*', 'Connection': 'keep-alive', 'Content-Length': '15551'}
2024-01-30 16:11:46,989 ERROR   wandb-upload_0:1134330 [internal_api.py:upload_file():2769] upload_file response body: 
2024-01-30 16:11:48,669 DEBUG   HandlerThread:1134330 [handler.py:handle_request():146] handle_request: status_report
2024-01-30 16:11:50,637 DEBUG   HandlerThread:1134330 [handler.py:handle_request():146] handle_request: stop_status
2024-01-30 16:11:50,638 DEBUG   SenderThread:1134330 [sender.py:send_request():409] send_request: stop_status
2024-01-30 16:11:50,686 DEBUG   HandlerThread:1134330 [handler.py:handle_request():146] handle_request: internal_messages
2024-01-30 16:11:53,931 DEBUG   HandlerThread:1134330 [handler.py:handle_request():146] handle_request: status_report
2024-01-30 16:11:55,956 INFO    Thread-12 :1134330 [dir_watcher.py:_on_file_created():271] file/dir created: /home/yanxindong/mkor/bert/wandb/run-20240130_161012-87yhbfo2/files/output.log
2024-01-30 16:11:57,956 INFO    Thread-12 :1134330 [dir_watcher.py:_on_file_modified():288] file/dir modified: /home/yanxindong/mkor/bert/wandb/run-20240130_161012-87yhbfo2/files/output.log
2024-01-30 16:11:59,217 DEBUG   HandlerThread:1134330 [handler.py:handle_request():146] handle_request: status_report
2024-01-30 16:12:04,219 DEBUG   HandlerThread:1134330 [handler.py:handle_request():146] handle_request: status_report
2024-01-30 16:12:08,236 DEBUG   HandlerThread:1134330 [handler.py:handle_request():146] handle_request: internal_messages
2024-01-30 16:12:08,236 DEBUG   HandlerThread:1134330 [handler.py:handle_request():146] handle_request: stop_status
2024-01-30 16:12:08,236 DEBUG   SenderThread:1134330 [sender.py:send_request():409] send_request: stop_status
2024-01-30 16:12:09,589 DEBUG   HandlerThread:1134330 [handler.py:handle_request():146] handle_request: status_report
2024-01-30 16:12:14,670 DEBUG   SenderThread:1134330 [sender.py:send():382] send: stats
2024-01-30 16:12:14,673 DEBUG   HandlerThread:1134330 [handler.py:handle_request():146] handle_request: status_report
2024-01-30 16:12:19,692 DEBUG   HandlerThread:1134330 [handler.py:handle_request():146] handle_request: status_report
2024-01-30 16:12:23,293 DEBUG   HandlerThread:1134330 [handler.py:handle_request():146] handle_request: internal_messages
2024-01-30 16:12:23,294 DEBUG   HandlerThread:1134330 [handler.py:handle_request():146] handle_request: stop_status
2024-01-30 16:12:23,298 DEBUG   SenderThread:1134330 [sender.py:send_request():409] send_request: stop_status
2024-01-30 16:12:25,639 DEBUG   HandlerThread:1134330 [handler.py:handle_request():146] handle_request: status_report
2024-01-30 16:12:30,639 DEBUG   HandlerThread:1134330 [handler.py:handle_request():146] handle_request: status_report
2024-01-30 16:12:35,640 DEBUG   HandlerThread:1134330 [handler.py:handle_request():146] handle_request: status_report
2024-01-30 16:12:38,236 DEBUG   HandlerThread:1134330 [handler.py:handle_request():146] handle_request: stop_status
2024-01-30 16:12:38,237 DEBUG   SenderThread:1134330 [sender.py:send_request():409] send_request: stop_status
2024-01-30 16:12:38,405 DEBUG   HandlerThread:1134330 [handler.py:handle_request():146] handle_request: internal_messages
2024-01-30 16:12:41,597 DEBUG   HandlerThread:1134330 [handler.py:handle_request():146] handle_request: status_report
2024-01-30 16:12:44,672 DEBUG   SenderThread:1134330 [sender.py:send():382] send: stats
2024-01-30 16:12:46,674 DEBUG   HandlerThread:1134330 [handler.py:handle_request():146] handle_request: status_report
2024-01-30 16:12:51,674 DEBUG   HandlerThread:1134330 [handler.py:handle_request():146] handle_request: status_report
2024-01-30 16:12:53,237 DEBUG   HandlerThread:1134330 [handler.py:handle_request():146] handle_request: stop_status
2024-01-30 16:12:53,237 DEBUG   SenderThread:1134330 [sender.py:send_request():409] send_request: stop_status
2024-01-30 16:12:53,277 DEBUG   HandlerThread:1134330 [handler.py:handle_request():146] handle_request: internal_messages
2024-01-30 16:12:57,570 DEBUG   HandlerThread:1134330 [handler.py:handle_request():146] handle_request: status_report
2024-01-30 16:13:02,571 DEBUG   HandlerThread:1134330 [handler.py:handle_request():146] handle_request: status_report
2024-01-30 16:13:03,346 ERROR   wandb-upload_0:1134330 [internal_api.py:upload_file():2765] upload_file exception https://storage.googleapis.com/wandb-production.appspot.com/dynamic_x/bert_pytorch/87yhbfo2/wandb-metadata.json?Expires=1706688636&GoogleAccessId=gorilla-files-url-signer-man%40wandb-production.iam.gserviceaccount.com&Signature=i6ygl6e%2F1NTaK6CPvF0NXZCkqswXBKlbsIAlDONRJsh%2B3x8JGZM%2F%2F23d4nP224TGJJG%2FCwEhFPdSuwxqSBYHv%2By9Ud6qOPv71v5oMy3xjK95cP8S5aO5KfCrnKtrIOmrXhlAhzuwVq6uvAKGfNqgQD6MEyp8CsvfEfy7pGsDDEXhj40LUnzeh4v3UzcU9ErrNfA3%2Fisa1FmirWu%2FkUcHDNpTeHVwdhLMUqnr5fYBL47fFxTQFwVRLqi9eHGGatIhaAP0mH%2BbS54b2T7CtyGpcXkoRBRSTcKBdvyiBiPDGie7PGw9Xsb6h0zFIIHbjehEtC3Q24GdjVu1TNNGFHYb3w%3D%3D: HTTPSConnectionPool(host='storage.googleapis.com', port=443): Max retries exceeded with url: /wandb-production.appspot.com/dynamic_x/bert_pytorch/87yhbfo2/wandb-metadata.json?Expires=1706688636&GoogleAccessId=gorilla-files-url-signer-man%40wandb-production.iam.gserviceaccount.com&Signature=i6ygl6e%2F1NTaK6CPvF0NXZCkqswXBKlbsIAlDONRJsh%2B3x8JGZM%2F%2F23d4nP224TGJJG%2FCwEhFPdSuwxqSBYHv%2By9Ud6qOPv71v5oMy3xjK95cP8S5aO5KfCrnKtrIOmrXhlAhzuwVq6uvAKGfNqgQD6MEyp8CsvfEfy7pGsDDEXhj40LUnzeh4v3UzcU9ErrNfA3%2Fisa1FmirWu%2FkUcHDNpTeHVwdhLMUqnr5fYBL47fFxTQFwVRLqi9eHGGatIhaAP0mH%2BbS54b2T7CtyGpcXkoRBRSTcKBdvyiBiPDGie7PGw9Xsb6h0zFIIHbjehEtC3Q24GdjVu1TNNGFHYb3w%3D%3D (Caused by NewConnectionError('<urllib3.connection.HTTPSConnection object at 0x7f859815b340>: Failed to establish a new connection: [Errno 101] Network is unreachable'))
2024-01-30 16:13:03,346 ERROR   wandb-upload_0:1134330 [internal_api.py:upload_file():2767] upload_file request headers: {'User-Agent': 'python-requests/2.23.0', 'Accept-Encoding': 'gzip, deflate', 'Accept': '*/*', 'Connection': 'keep-alive', 'Content-Length': '15551'}
2024-01-30 16:13:03,346 ERROR   wandb-upload_0:1134330 [internal_api.py:upload_file():2769] upload_file response body: 
2024-01-30 16:13:07,572 DEBUG   HandlerThread:1134330 [handler.py:handle_request():146] handle_request: status_report
2024-01-30 16:13:08,237 DEBUG   HandlerThread:1134330 [handler.py:handle_request():146] handle_request: stop_status
2024-01-30 16:13:08,237 DEBUG   SenderThread:1134330 [sender.py:send_request():409] send_request: stop_status
2024-01-30 16:13:08,281 DEBUG   HandlerThread:1134330 [handler.py:handle_request():146] handle_request: internal_messages
2024-01-30 16:13:12,581 DEBUG   HandlerThread:1134330 [handler.py:handle_request():146] handle_request: status_report
2024-01-30 16:13:14,724 DEBUG   SenderThread:1134330 [sender.py:send():382] send: stats
2024-01-30 16:13:17,842 DEBUG   HandlerThread:1134330 [handler.py:handle_request():146] handle_request: status_report
2024-01-30 16:13:22,872 DEBUG   HandlerThread:1134330 [handler.py:handle_request():146] handle_request: status_report
2024-01-30 16:13:23,310 DEBUG   HandlerThread:1134330 [handler.py:handle_request():146] handle_request: stop_status
2024-01-30 16:13:23,310 DEBUG   HandlerThread:1134330 [handler.py:handle_request():146] handle_request: internal_messages
2024-01-30 16:13:23,310 DEBUG   SenderThread:1134330 [sender.py:send_request():409] send_request: stop_status
2024-01-30 16:13:28,659 DEBUG   HandlerThread:1134330 [handler.py:handle_request():146] handle_request: status_report
2024-01-30 16:13:33,743 DEBUG   HandlerThread:1134330 [handler.py:handle_request():146] handle_request: status_report
2024-01-30 16:13:38,237 DEBUG   HandlerThread:1134330 [handler.py:handle_request():146] handle_request: stop_status
2024-01-30 16:13:38,237 DEBUG   SenderThread:1134330 [sender.py:send_request():409] send_request: stop_status
2024-01-30 16:13:38,277 DEBUG   HandlerThread:1134330 [handler.py:handle_request():146] handle_request: internal_messages
2024-01-30 16:13:39,574 DEBUG   HandlerThread:1134330 [handler.py:handle_request():146] handle_request: status_report
2024-01-30 16:13:44,630 DEBUG   HandlerThread:1134330 [handler.py:handle_request():146] handle_request: status_report
2024-01-30 16:13:44,727 DEBUG   SenderThread:1134330 [sender.py:send():382] send: stats
2024-01-30 16:13:49,728 DEBUG   HandlerThread:1134330 [handler.py:handle_request():146] handle_request: status_report
2024-01-30 16:13:53,237 DEBUG   HandlerThread:1134330 [handler.py:handle_request():146] handle_request: stop_status
2024-01-30 16:13:53,237 DEBUG   SenderThread:1134330 [sender.py:send_request():409] send_request: stop_status
2024-01-30 16:13:53,277 DEBUG   HandlerThread:1134330 [handler.py:handle_request():146] handle_request: internal_messages
2024-01-30 16:13:55,575 DEBUG   HandlerThread:1134330 [handler.py:handle_request():146] handle_request: status_report
2024-01-30 16:14:00,578 DEBUG   HandlerThread:1134330 [handler.py:handle_request():146] handle_request: status_report
2024-01-30 16:14:05,578 DEBUG   HandlerThread:1134330 [handler.py:handle_request():146] handle_request: status_report
2024-01-30 16:14:08,237 DEBUG   HandlerThread:1134330 [handler.py:handle_request():146] handle_request: stop_status
2024-01-30 16:14:08,237 DEBUG   SenderThread:1134330 [sender.py:send_request():409] send_request: stop_status
2024-01-30 16:14:08,277 DEBUG   HandlerThread:1134330 [handler.py:handle_request():146] handle_request: internal_messages
2024-01-30 16:14:10,734 DEBUG   HandlerThread:1134330 [handler.py:handle_request():146] handle_request: status_report
2024-01-30 16:14:14,728 DEBUG   SenderThread:1134330 [sender.py:send():382] send: stats
2024-01-30 16:14:15,797 DEBUG   HandlerThread:1134330 [handler.py:handle_request():146] handle_request: status_report
2024-01-30 16:14:20,892 DEBUG   HandlerThread:1134330 [handler.py:handle_request():146] handle_request: status_report
2024-01-30 16:14:23,237 DEBUG   HandlerThread:1134330 [handler.py:handle_request():146] handle_request: stop_status
2024-01-30 16:14:23,237 DEBUG   SenderThread:1134330 [sender.py:send_request():409] send_request: stop_status
2024-01-30 16:14:23,277 DEBUG   HandlerThread:1134330 [handler.py:handle_request():146] handle_request: internal_messages
2024-01-30 16:14:26,636 DEBUG   HandlerThread:1134330 [handler.py:handle_request():146] handle_request: status_report
2024-01-30 16:14:31,636 DEBUG   HandlerThread:1134330 [handler.py:handle_request():146] handle_request: status_report
2024-01-30 16:14:36,666 DEBUG   HandlerThread:1134330 [handler.py:handle_request():146] handle_request: status_report
2024-01-30 16:14:38,327 DEBUG   HandlerThread:1134330 [handler.py:handle_request():146] handle_request: stop_status
2024-01-30 16:14:38,327 DEBUG   HandlerThread:1134330 [handler.py:handle_request():146] handle_request: internal_messages
2024-01-30 16:14:38,327 DEBUG   SenderThread:1134330 [sender.py:send_request():409] send_request: stop_status
2024-01-30 16:14:41,770 DEBUG   HandlerThread:1134330 [handler.py:handle_request():146] handle_request: status_report
2024-01-30 16:14:44,730 DEBUG   SenderThread:1134330 [sender.py:send():382] send: stats
2024-01-30 16:14:47,735 DEBUG   HandlerThread:1134330 [handler.py:handle_request():146] handle_request: status_report
2024-01-30 16:14:52,736 DEBUG   HandlerThread:1134330 [handler.py:handle_request():146] handle_request: status_report
2024-01-30 16:14:53,237 DEBUG   HandlerThread:1134330 [handler.py:handle_request():146] handle_request: stop_status
2024-01-30 16:14:53,237 DEBUG   SenderThread:1134330 [sender.py:send_request():409] send_request: stop_status
2024-01-30 16:14:53,277 DEBUG   HandlerThread:1134330 [handler.py:handle_request():146] handle_request: internal_messages
2024-01-30 16:14:58,531 DEBUG   HandlerThread:1134330 [handler.py:handle_request():146] handle_request: status_report
2024-01-30 16:15:03,532 DEBUG   HandlerThread:1134330 [handler.py:handle_request():146] handle_request: status_report
2024-01-30 16:15:08,237 DEBUG   HandlerThread:1134330 [handler.py:handle_request():146] handle_request: stop_status
2024-01-30 16:15:08,238 DEBUG   SenderThread:1134330 [sender.py:send_request():409] send_request: stop_status
2024-01-30 16:15:08,277 DEBUG   HandlerThread:1134330 [handler.py:handle_request():146] handle_request: internal_messages
2024-01-30 16:15:08,571 DEBUG   HandlerThread:1134330 [handler.py:handle_request():146] handle_request: status_report
2024-01-30 16:15:13,571 DEBUG   HandlerThread:1134330 [handler.py:handle_request():146] handle_request: status_report
2024-01-30 16:15:14,732 DEBUG   SenderThread:1134330 [sender.py:send():382] send: stats
2024-01-30 16:15:18,734 DEBUG   HandlerThread:1134330 [handler.py:handle_request():146] handle_request: status_report
2024-01-30 16:15:23,237 DEBUG   HandlerThread:1134330 [handler.py:handle_request():146] handle_request: stop_status
2024-01-30 16:15:23,238 DEBUG   SenderThread:1134330 [sender.py:send_request():409] send_request: stop_status
2024-01-30 16:15:23,277 DEBUG   HandlerThread:1134330 [handler.py:handle_request():146] handle_request: internal_messages
2024-01-30 16:15:24,552 DEBUG   HandlerThread:1134330 [handler.py:handle_request():146] handle_request: status_report
2024-01-30 16:15:27,899 ERROR   wandb-upload_0:1134330 [internal_api.py:upload_file():2765] upload_file exception https://storage.googleapis.com/wandb-production.appspot.com/dynamic_x/bert_pytorch/87yhbfo2/wandb-metadata.json?Expires=1706688636&GoogleAccessId=gorilla-files-url-signer-man%40wandb-production.iam.gserviceaccount.com&Signature=i6ygl6e%2F1NTaK6CPvF0NXZCkqswXBKlbsIAlDONRJsh%2B3x8JGZM%2F%2F23d4nP224TGJJG%2FCwEhFPdSuwxqSBYHv%2By9Ud6qOPv71v5oMy3xjK95cP8S5aO5KfCrnKtrIOmrXhlAhzuwVq6uvAKGfNqgQD6MEyp8CsvfEfy7pGsDDEXhj40LUnzeh4v3UzcU9ErrNfA3%2Fisa1FmirWu%2FkUcHDNpTeHVwdhLMUqnr5fYBL47fFxTQFwVRLqi9eHGGatIhaAP0mH%2BbS54b2T7CtyGpcXkoRBRSTcKBdvyiBiPDGie7PGw9Xsb6h0zFIIHbjehEtC3Q24GdjVu1TNNGFHYb3w%3D%3D: HTTPSConnectionPool(host='storage.googleapis.com', port=443): Max retries exceeded with url: /wandb-production.appspot.com/dynamic_x/bert_pytorch/87yhbfo2/wandb-metadata.json?Expires=1706688636&GoogleAccessId=gorilla-files-url-signer-man%40wandb-production.iam.gserviceaccount.com&Signature=i6ygl6e%2F1NTaK6CPvF0NXZCkqswXBKlbsIAlDONRJsh%2B3x8JGZM%2F%2F23d4nP224TGJJG%2FCwEhFPdSuwxqSBYHv%2By9Ud6qOPv71v5oMy3xjK95cP8S5aO5KfCrnKtrIOmrXhlAhzuwVq6uvAKGfNqgQD6MEyp8CsvfEfy7pGsDDEXhj40LUnzeh4v3UzcU9ErrNfA3%2Fisa1FmirWu%2FkUcHDNpTeHVwdhLMUqnr5fYBL47fFxTQFwVRLqi9eHGGatIhaAP0mH%2BbS54b2T7CtyGpcXkoRBRSTcKBdvyiBiPDGie7PGw9Xsb6h0zFIIHbjehEtC3Q24GdjVu1TNNGFHYb3w%3D%3D (Caused by NewConnectionError('<urllib3.connection.HTTPSConnection object at 0x7f859815b4f0>: Failed to establish a new connection: [Errno 101] Network is unreachable'))
2024-01-30 16:15:27,899 ERROR   wandb-upload_0:1134330 [internal_api.py:upload_file():2767] upload_file request headers: {'User-Agent': 'python-requests/2.23.0', 'Accept-Encoding': 'gzip, deflate', 'Accept': '*/*', 'Connection': 'keep-alive', 'Content-Length': '15551'}
2024-01-30 16:15:27,899 ERROR   wandb-upload_0:1134330 [internal_api.py:upload_file():2769] upload_file response body: 
2024-01-30 16:15:29,793 DEBUG   HandlerThread:1134330 [handler.py:handle_request():146] handle_request: status_report
2024-01-30 16:15:34,794 DEBUG   HandlerThread:1134330 [handler.py:handle_request():146] handle_request: status_report
2024-01-30 16:15:38,237 DEBUG   HandlerThread:1134330 [handler.py:handle_request():146] handle_request: stop_status
2024-01-30 16:15:38,238 DEBUG   SenderThread:1134330 [sender.py:send_request():409] send_request: stop_status
2024-01-30 16:15:38,281 DEBUG   HandlerThread:1134330 [handler.py:handle_request():146] handle_request: internal_messages
2024-01-30 16:15:40,641 DEBUG   HandlerThread:1134330 [handler.py:handle_request():146] handle_request: status_report
2024-01-30 16:15:44,752 DEBUG   SenderThread:1134330 [sender.py:send():382] send: stats
2024-01-30 16:15:45,753 DEBUG   HandlerThread:1134330 [handler.py:handle_request():146] handle_request: status_report
2024-01-30 16:15:50,753 DEBUG   HandlerThread:1134330 [handler.py:handle_request():146] handle_request: status_report
2024-01-30 16:15:53,238 DEBUG   HandlerThread:1134330 [handler.py:handle_request():146] handle_request: stop_status
2024-01-30 16:15:53,238 DEBUG   SenderThread:1134330 [sender.py:send_request():409] send_request: stop_status
2024-01-30 16:15:53,281 DEBUG   HandlerThread:1134330 [handler.py:handle_request():146] handle_request: internal_messages
2024-01-30 16:15:56,523 DEBUG   HandlerThread:1134330 [handler.py:handle_request():146] handle_request: status_report
2024-01-30 16:16:01,524 DEBUG   HandlerThread:1134330 [handler.py:handle_request():146] handle_request: status_report
2024-01-30 16:16:06,209 INFO    Thread-12 :1134330 [dir_watcher.py:_on_file_modified():288] file/dir modified: /home/yanxindong/mkor/bert/wandb/run-20240130_161012-87yhbfo2/files/output.log
2024-01-30 16:16:06,978 DEBUG   HandlerThread:1134330 [handler.py:handle_request():146] handle_request: status_report
2024-01-30 16:16:07,018 DEBUG   SenderThread:1134330 [sender.py:send():382] send: exit
2024-01-30 16:16:07,018 INFO    SenderThread:1134330 [sender.py:send_exit():589] handling exit code: 1
2024-01-30 16:16:07,018 INFO    SenderThread:1134330 [sender.py:send_exit():591] handling runtime: 352
2024-01-30 16:16:07,019 INFO    SenderThread:1134330 [sender.py:_save_file():1403] saving file wandb-summary.json with policy end
2024-01-30 16:16:07,019 INFO    SenderThread:1134330 [sender.py:send_exit():597] send defer
2024-01-30 16:16:07,019 DEBUG   HandlerThread:1134330 [handler.py:handle_request():146] handle_request: defer
2024-01-30 16:16:07,019 INFO    HandlerThread:1134330 [handler.py:handle_request_defer():172] handle defer: 0
2024-01-30 16:16:07,019 DEBUG   SenderThread:1134330 [sender.py:send_request():409] send_request: defer
2024-01-30 16:16:07,019 INFO    SenderThread:1134330 [sender.py:send_request_defer():613] handle sender defer: 0
2024-01-30 16:16:07,019 INFO    SenderThread:1134330 [sender.py:transition_state():617] send defer: 1
2024-01-30 16:16:07,019 DEBUG   HandlerThread:1134330 [handler.py:handle_request():146] handle_request: defer
2024-01-30 16:16:07,019 INFO    HandlerThread:1134330 [handler.py:handle_request_defer():172] handle defer: 1
2024-01-30 16:16:07,020 DEBUG   SenderThread:1134330 [sender.py:send_request():409] send_request: defer
2024-01-30 16:16:07,020 INFO    SenderThread:1134330 [sender.py:send_request_defer():613] handle sender defer: 1
2024-01-30 16:16:07,020 INFO    SenderThread:1134330 [sender.py:transition_state():617] send defer: 2
2024-01-30 16:16:07,020 DEBUG   HandlerThread:1134330 [handler.py:handle_request():146] handle_request: defer
2024-01-30 16:16:07,020 INFO    HandlerThread:1134330 [handler.py:handle_request_defer():172] handle defer: 2
2024-01-30 16:16:07,020 INFO    HandlerThread:1134330 [system_monitor.py:finish():203] Stopping system monitor
2024-01-30 16:16:07,020 DEBUG   SystemMonitor:1134330 [system_monitor.py:_start():179] Finished system metrics aggregation loop
2024-01-30 16:16:07,020 DEBUG   SystemMonitor:1134330 [system_monitor.py:_start():183] Publishing last batch of metrics
2024-01-30 16:16:07,029 INFO    HandlerThread:1134330 [interfaces.py:finish():202] Joined cpu monitor
2024-01-30 16:16:07,030 INFO    HandlerThread:1134330 [interfaces.py:finish():202] Joined disk monitor
2024-01-30 16:16:07,213 INFO    Thread-12 :1134330 [dir_watcher.py:_on_file_created():271] file/dir created: /home/yanxindong/mkor/bert/wandb/run-20240130_161012-87yhbfo2/files/wandb-summary.json
2024-01-30 16:16:09,214 INFO    Thread-12 :1134330 [dir_watcher.py:_on_file_modified():288] file/dir modified: /home/yanxindong/mkor/bert/wandb/run-20240130_161012-87yhbfo2/files/output.log
2024-01-30 16:16:16,183 INFO    HandlerThread:1134330 [interfaces.py:finish():202] Joined gpu monitor
2024-01-30 16:16:16,183 INFO    HandlerThread:1134330 [interfaces.py:finish():202] Joined memory monitor
2024-01-30 16:16:16,183 INFO    HandlerThread:1134330 [interfaces.py:finish():202] Joined network monitor
2024-01-30 16:16:16,183 DEBUG   HandlerThread:1134330 [handler.py:handle_request():146] handle_request: poll_exit
2024-01-30 16:16:16,183 DEBUG   HandlerThread:1134330 [handler.py:handle_request():146] handle_request: status_report
2024-01-30 16:16:16,183 DEBUG   HandlerThread:1134330 [handler.py:handle_request():146] handle_request: keepalive
2024-01-30 16:16:16,184 DEBUG   SenderThread:1134330 [sender.py:send_request():409] send_request: defer
2024-01-30 16:16:16,184 INFO    SenderThread:1134330 [sender.py:send_request_defer():613] handle sender defer: 2
2024-01-30 16:16:16,184 INFO    SenderThread:1134330 [sender.py:transition_state():617] send defer: 3
2024-01-30 16:16:16,184 DEBUG   SenderThread:1134330 [sender.py:send():382] send: stats
2024-01-30 16:16:16,186 DEBUG   SenderThread:1134330 [sender.py:send_request():409] send_request: poll_exit
2024-01-30 16:16:16,188 DEBUG   HandlerThread:1134330 [handler.py:handle_request():146] handle_request: defer
2024-01-30 16:16:16,188 INFO    HandlerThread:1134330 [handler.py:handle_request_defer():172] handle defer: 3
2024-01-30 16:16:16,188 DEBUG   SenderThread:1134330 [sender.py:send_request():409] send_request: defer
2024-01-30 16:16:16,188 INFO    SenderThread:1134330 [sender.py:send_request_defer():613] handle sender defer: 3
2024-01-30 16:16:16,188 INFO    SenderThread:1134330 [sender.py:transition_state():617] send defer: 4
2024-01-30 16:16:16,189 DEBUG   HandlerThread:1134330 [handler.py:handle_request():146] handle_request: defer
2024-01-30 16:16:16,189 INFO    HandlerThread:1134330 [handler.py:handle_request_defer():172] handle defer: 4
2024-01-30 16:16:16,189 DEBUG   SenderThread:1134330 [sender.py:send_request():409] send_request: defer
2024-01-30 16:16:16,189 INFO    SenderThread:1134330 [sender.py:send_request_defer():613] handle sender defer: 4
2024-01-30 16:16:16,189 INFO    SenderThread:1134330 [sender.py:transition_state():617] send defer: 5
2024-01-30 16:16:16,189 DEBUG   HandlerThread:1134330 [handler.py:handle_request():146] handle_request: defer
2024-01-30 16:16:16,189 INFO    HandlerThread:1134330 [handler.py:handle_request_defer():172] handle defer: 5
2024-01-30 16:16:16,189 DEBUG   SenderThread:1134330 [sender.py:send():382] send: summary
2024-01-30 16:16:16,189 INFO    SenderThread:1134330 [sender.py:_save_file():1403] saving file wandb-summary.json with policy end
2024-01-30 16:16:16,190 DEBUG   SenderThread:1134330 [sender.py:send_request():409] send_request: defer
2024-01-30 16:16:16,190 INFO    SenderThread:1134330 [sender.py:send_request_defer():613] handle sender defer: 5
2024-01-30 16:16:16,190 INFO    SenderThread:1134330 [sender.py:transition_state():617] send defer: 6
2024-01-30 16:16:16,190 DEBUG   HandlerThread:1134330 [handler.py:handle_request():146] handle_request: defer
2024-01-30 16:16:16,190 INFO    HandlerThread:1134330 [handler.py:handle_request_defer():172] handle defer: 6
2024-01-30 16:16:16,190 DEBUG   SenderThread:1134330 [sender.py:send_request():409] send_request: defer
2024-01-30 16:16:16,190 INFO    SenderThread:1134330 [sender.py:send_request_defer():613] handle sender defer: 6
2024-01-30 16:16:16,190 INFO    SenderThread:1134330 [sender.py:transition_state():617] send defer: 7
2024-01-30 16:16:16,190 DEBUG   HandlerThread:1134330 [handler.py:handle_request():146] handle_request: status_report
2024-01-30 16:16:16,190 DEBUG   HandlerThread:1134330 [handler.py:handle_request():146] handle_request: defer
2024-01-30 16:16:16,190 INFO    HandlerThread:1134330 [handler.py:handle_request_defer():172] handle defer: 7
2024-01-30 16:16:16,190 DEBUG   SenderThread:1134330 [sender.py:send_request():409] send_request: defer
2024-01-30 16:16:16,190 INFO    SenderThread:1134330 [sender.py:send_request_defer():613] handle sender defer: 7
2024-01-30 16:16:16,243 INFO    Thread-12 :1134330 [dir_watcher.py:_on_file_modified():288] file/dir modified: /home/yanxindong/mkor/bert/wandb/run-20240130_161012-87yhbfo2/files/wandb-summary.json
2024-01-30 16:16:16,323 INFO    SenderThread:1134330 [sender.py:transition_state():617] send defer: 8
2024-01-30 16:16:16,323 DEBUG   HandlerThread:1134330 [handler.py:handle_request():146] handle_request: defer
2024-01-30 16:16:16,323 INFO    HandlerThread:1134330 [handler.py:handle_request_defer():172] handle defer: 8
2024-01-30 16:16:16,323 DEBUG   SenderThread:1134330 [sender.py:send_request():409] send_request: defer
2024-01-30 16:16:16,323 INFO    SenderThread:1134330 [sender.py:send_request_defer():613] handle sender defer: 8
2024-01-30 16:16:16,324 INFO    SenderThread:1134330 [job_builder.py:build():296] Attempting to build job artifact
2024-01-30 16:16:16,324 INFO    SenderThread:1134330 [job_builder.py:_get_source_type():426] is repo sourced job
2024-01-30 16:16:16,491 INFO    SenderThread:1134330 [job_builder.py:build():402] adding wandb-job metadata file
2024-01-30 16:16:16,494 INFO    SenderThread:1134330 [sender.py:transition_state():617] send defer: 9
2024-01-30 16:16:16,494 DEBUG   HandlerThread:1134330 [handler.py:handle_request():146] handle_request: defer
2024-01-30 16:16:16,494 INFO    HandlerThread:1134330 [handler.py:handle_request_defer():172] handle defer: 9
2024-01-30 16:16:16,494 DEBUG   SenderThread:1134330 [sender.py:send():382] send: artifact
2024-01-30 16:16:17,020 DEBUG   HandlerThread:1134330 [handler.py:handle_request():146] handle_request: poll_exit
2024-01-30 16:16:17,243 INFO    Thread-12 :1134330 [dir_watcher.py:_on_file_modified():288] file/dir modified: /home/yanxindong/mkor/bert/wandb/run-20240130_161012-87yhbfo2/files/output.log
2024-01-30 16:16:18,281 ERROR   wandb-upload_1:1134330 [internal_api.py:upload_file():2765] upload_file exception https://storage.googleapis.com/wandb-artifacts-prod/wandb_artifacts/133981200/707680476/174a3d9bc61fec126cc7d5bdff5c6c5a?Expires=1706688978&GoogleAccessId=gorilla-files-url-signer-man%40wandb-production.iam.gserviceaccount.com&Signature=K7H67UT394ZxkY38h5LLo7qstPxKv9DSLuAIJ%2BawMnvSiLlI76Ar1VipqXQ9pE2svxdbUoX5nmTEq7htyjyogM9hI2e%2BbXLJ3PoZ%2BriOYuitZhYGSJttcVAQw6Vj29UhAQJwY1H8R795pIZVRYna6cwp6vWgd71BUO07graO60iA5ovSG0hXC58DfrZgygvrTFXYZ4iKDeZ57uzYZ4%2B%2FkGEwaXYePNjphjRm5Ev9U7uBwbYTRr7X%2BaGwd5Uz0P5iNB0W1al7TBPBUIvguYcJST90PRLbxcOY3kltbxzaPXOkec3duvGtMxzCsmXn7fHJTvyNNIWDCMGQBex2WaNEng%3D%3D: HTTPSConnectionPool(host='storage.googleapis.com', port=443): Max retries exceeded with url: /wandb-artifacts-prod/wandb_artifacts/133981200/707680476/174a3d9bc61fec126cc7d5bdff5c6c5a?Expires=1706688978&GoogleAccessId=gorilla-files-url-signer-man%40wandb-production.iam.gserviceaccount.com&Signature=K7H67UT394ZxkY38h5LLo7qstPxKv9DSLuAIJ%2BawMnvSiLlI76Ar1VipqXQ9pE2svxdbUoX5nmTEq7htyjyogM9hI2e%2BbXLJ3PoZ%2BriOYuitZhYGSJttcVAQw6Vj29UhAQJwY1H8R795pIZVRYna6cwp6vWgd71BUO07graO60iA5ovSG0hXC58DfrZgygvrTFXYZ4iKDeZ57uzYZ4%2B%2FkGEwaXYePNjphjRm5Ev9U7uBwbYTRr7X%2BaGwd5Uz0P5iNB0W1al7TBPBUIvguYcJST90PRLbxcOY3kltbxzaPXOkec3duvGtMxzCsmXn7fHJTvyNNIWDCMGQBex2WaNEng%3D%3D (Caused by NewConnectionError('<urllib3.connection.HTTPSConnection object at 0x7f859811bf70>: Failed to establish a new connection: [Errno 101] Network is unreachable'))
2024-01-30 16:16:18,281 ERROR   wandb-upload_1:1134330 [internal_api.py:upload_file():2767] upload_file request headers: {'User-Agent': 'python-requests/2.23.0', 'Accept-Encoding': 'gzip, deflate', 'Accept': '*/*', 'Connection': 'keep-alive', 'Content-MD5': 'F0o9m8Yf7BJsx9W9/1xsWg==', 'Content-Type': 'text/plain; charset=utf-8', 'Content-Length': '2179'}
2024-01-30 16:16:18,281 ERROR   wandb-upload_1:1134330 [internal_api.py:upload_file():2769] upload_file response body: 
2024-01-30 16:16:18,869 ERROR   wandb-upload_2:1134330 [internal_api.py:upload_file():2765] upload_file exception https://storage.googleapis.com/wandb-artifacts-prod/wandb_artifacts/133981200/707680476/6873c23a2381d1524249eb1a948a45a5?Expires=1706688978&GoogleAccessId=gorilla-files-url-signer-man%40wandb-production.iam.gserviceaccount.com&Signature=FJbunGpfeOQfbKn542AGPFUBcBVQErMSPGikGCa0aecFeElbpWRcwkiz4wMxZgu6SOi89%2BydcFZipV2Ca52hCBN6z6HQ%2FWNmhJfUfy8OfSxKUOEfnm%2FacOCYZumigHY8XXWV14q%2BIE%2BSXX5UKop3Oygpq2XwB4kUAVTF1xiWGV9J82N5lexioy35TMM0M3fpZVNTLjBkETzKCAah3YICcTldU0r9Cj%2BKrfTDZRT1nd9nHIsEuOMP8GR1dBD958dC5j5Onja4PEXVcvyHXBgveCtHVX7unpWD6GCcrTs2tj5x5W2cpsRNemTkFrzKs%2FQMT3832Dv7Gt5Sw0Hkmzwuvg%3D%3D: HTTPSConnectionPool(host='storage.googleapis.com', port=443): Max retries exceeded with url: /wandb-artifacts-prod/wandb_artifacts/133981200/707680476/6873c23a2381d1524249eb1a948a45a5?Expires=1706688978&GoogleAccessId=gorilla-files-url-signer-man%40wandb-production.iam.gserviceaccount.com&Signature=FJbunGpfeOQfbKn542AGPFUBcBVQErMSPGikGCa0aecFeElbpWRcwkiz4wMxZgu6SOi89%2BydcFZipV2Ca52hCBN6z6HQ%2FWNmhJfUfy8OfSxKUOEfnm%2FacOCYZumigHY8XXWV14q%2BIE%2BSXX5UKop3Oygpq2XwB4kUAVTF1xiWGV9J82N5lexioy35TMM0M3fpZVNTLjBkETzKCAah3YICcTldU0r9Cj%2BKrfTDZRT1nd9nHIsEuOMP8GR1dBD958dC5j5Onja4PEXVcvyHXBgveCtHVX7unpWD6GCcrTs2tj5x5W2cpsRNemTkFrzKs%2FQMT3832Dv7Gt5Sw0Hkmzwuvg%3D%3D (Caused by NewConnectionError('<urllib3.connection.HTTPSConnection object at 0x7f859811bc40>: Failed to establish a new connection: [Errno 101] Network is unreachable'))
2024-01-30 16:16:18,869 ERROR   wandb-upload_2:1134330 [internal_api.py:upload_file():2767] upload_file request headers: {'User-Agent': 'python-requests/2.23.0', 'Accept-Encoding': 'gzip, deflate', 'Accept': '*/*', 'Connection': 'keep-alive', 'Content-MD5': 'aHPCOiOB0VJCSesalIpFpQ==', 'Content-Type': 'application/json', 'Content-Length': '609'}
2024-01-30 16:16:18,869 ERROR   wandb-upload_2:1134330 [internal_api.py:upload_file():2769] upload_file response body: 
2024-01-30 16:16:19,427 ERROR   wandb-upload_1:1134330 [internal_api.py:upload_file():2765] upload_file exception https://storage.googleapis.com/wandb-artifacts-prod/wandb_artifacts/133981200/707680476/174a3d9bc61fec126cc7d5bdff5c6c5a?Expires=1706688978&GoogleAccessId=gorilla-files-url-signer-man%40wandb-production.iam.gserviceaccount.com&Signature=K7H67UT394ZxkY38h5LLo7qstPxKv9DSLuAIJ%2BawMnvSiLlI76Ar1VipqXQ9pE2svxdbUoX5nmTEq7htyjyogM9hI2e%2BbXLJ3PoZ%2BriOYuitZhYGSJttcVAQw6Vj29UhAQJwY1H8R795pIZVRYna6cwp6vWgd71BUO07graO60iA5ovSG0hXC58DfrZgygvrTFXYZ4iKDeZ57uzYZ4%2B%2FkGEwaXYePNjphjRm5Ev9U7uBwbYTRr7X%2BaGwd5Uz0P5iNB0W1al7TBPBUIvguYcJST90PRLbxcOY3kltbxzaPXOkec3duvGtMxzCsmXn7fHJTvyNNIWDCMGQBex2WaNEng%3D%3D: HTTPSConnectionPool(host='storage.googleapis.com', port=443): Max retries exceeded with url: /wandb-artifacts-prod/wandb_artifacts/133981200/707680476/174a3d9bc61fec126cc7d5bdff5c6c5a?Expires=1706688978&GoogleAccessId=gorilla-files-url-signer-man%40wandb-production.iam.gserviceaccount.com&Signature=K7H67UT394ZxkY38h5LLo7qstPxKv9DSLuAIJ%2BawMnvSiLlI76Ar1VipqXQ9pE2svxdbUoX5nmTEq7htyjyogM9hI2e%2BbXLJ3PoZ%2BriOYuitZhYGSJttcVAQw6Vj29UhAQJwY1H8R795pIZVRYna6cwp6vWgd71BUO07graO60iA5ovSG0hXC58DfrZgygvrTFXYZ4iKDeZ57uzYZ4%2B%2FkGEwaXYePNjphjRm5Ev9U7uBwbYTRr7X%2BaGwd5Uz0P5iNB0W1al7TBPBUIvguYcJST90PRLbxcOY3kltbxzaPXOkec3duvGtMxzCsmXn7fHJTvyNNIWDCMGQBex2WaNEng%3D%3D (Caused by NewConnectionError('<urllib3.connection.HTTPSConnection object at 0x7f859815b460>: Failed to establish a new connection: [Errno 101] Network is unreachable'))
2024-01-30 16:16:19,428 ERROR   wandb-upload_1:1134330 [internal_api.py:upload_file():2767] upload_file request headers: {'User-Agent': 'python-requests/2.23.0', 'Accept-Encoding': 'gzip, deflate', 'Accept': '*/*', 'Connection': 'keep-alive', 'Content-MD5': 'F0o9m8Yf7BJsx9W9/1xsWg==', 'Content-Type': 'text/plain; charset=utf-8', 'Content-Length': '2179'}
2024-01-30 16:16:19,428 ERROR   wandb-upload_1:1134330 [internal_api.py:upload_file():2769] upload_file response body: 
2024-01-30 16:16:20,172 ERROR   wandb-upload_2:1134330 [internal_api.py:upload_file():2765] upload_file exception https://storage.googleapis.com/wandb-artifacts-prod/wandb_artifacts/133981200/707680476/6873c23a2381d1524249eb1a948a45a5?Expires=1706688978&GoogleAccessId=gorilla-files-url-signer-man%40wandb-production.iam.gserviceaccount.com&Signature=FJbunGpfeOQfbKn542AGPFUBcBVQErMSPGikGCa0aecFeElbpWRcwkiz4wMxZgu6SOi89%2BydcFZipV2Ca52hCBN6z6HQ%2FWNmhJfUfy8OfSxKUOEfnm%2FacOCYZumigHY8XXWV14q%2BIE%2BSXX5UKop3Oygpq2XwB4kUAVTF1xiWGV9J82N5lexioy35TMM0M3fpZVNTLjBkETzKCAah3YICcTldU0r9Cj%2BKrfTDZRT1nd9nHIsEuOMP8GR1dBD958dC5j5Onja4PEXVcvyHXBgveCtHVX7unpWD6GCcrTs2tj5x5W2cpsRNemTkFrzKs%2FQMT3832Dv7Gt5Sw0Hkmzwuvg%3D%3D: HTTPSConnectionPool(host='storage.googleapis.com', port=443): Max retries exceeded with url: /wandb-artifacts-prod/wandb_artifacts/133981200/707680476/6873c23a2381d1524249eb1a948a45a5?Expires=1706688978&GoogleAccessId=gorilla-files-url-signer-man%40wandb-production.iam.gserviceaccount.com&Signature=FJbunGpfeOQfbKn542AGPFUBcBVQErMSPGikGCa0aecFeElbpWRcwkiz4wMxZgu6SOi89%2BydcFZipV2Ca52hCBN6z6HQ%2FWNmhJfUfy8OfSxKUOEfnm%2FacOCYZumigHY8XXWV14q%2BIE%2BSXX5UKop3Oygpq2XwB4kUAVTF1xiWGV9J82N5lexioy35TMM0M3fpZVNTLjBkETzKCAah3YICcTldU0r9Cj%2BKrfTDZRT1nd9nHIsEuOMP8GR1dBD958dC5j5Onja4PEXVcvyHXBgveCtHVX7unpWD6GCcrTs2tj5x5W2cpsRNemTkFrzKs%2FQMT3832Dv7Gt5Sw0Hkmzwuvg%3D%3D (Caused by NewConnectionError('<urllib3.connection.HTTPSConnection object at 0x7f8598062bb0>: Failed to establish a new connection: [Errno 101] Network is unreachable'))
2024-01-30 16:16:20,172 ERROR   wandb-upload_2:1134330 [internal_api.py:upload_file():2767] upload_file request headers: {'User-Agent': 'python-requests/2.23.0', 'Accept-Encoding': 'gzip, deflate', 'Accept': '*/*', 'Connection': 'keep-alive', 'Content-MD5': 'aHPCOiOB0VJCSesalIpFpQ==', 'Content-Type': 'application/json', 'Content-Length': '609'}
2024-01-30 16:16:20,172 ERROR   wandb-upload_2:1134330 [internal_api.py:upload_file():2769] upload_file response body: 
2024-01-30 16:16:20,172 INFO    wandb-upload_2:1134330 [retry.py:__call__():172] Retry attempt failed:
Traceback (most recent call last):
  File "/home/yanxindong/anaconda/envs/eva/lib/python3.8/site-packages/urllib3/connection.py", line 159, in _new_conn
    conn = connection.create_connection(
  File "/home/yanxindong/anaconda/envs/eva/lib/python3.8/site-packages/urllib3/util/connection.py", line 84, in create_connection
    raise err
  File "/home/yanxindong/anaconda/envs/eva/lib/python3.8/site-packages/urllib3/util/connection.py", line 74, in create_connection
    sock.connect(sa)
OSError: [Errno 101] Network is unreachable

During handling of the above exception, another exception occurred:

Traceback (most recent call last):
  File "/home/yanxindong/anaconda/envs/eva/lib/python3.8/site-packages/urllib3/connectionpool.py", line 670, in urlopen
    httplib_response = self._make_request(
  File "/home/yanxindong/anaconda/envs/eva/lib/python3.8/site-packages/urllib3/connectionpool.py", line 381, in _make_request
    self._validate_conn(conn)
  File "/home/yanxindong/anaconda/envs/eva/lib/python3.8/site-packages/urllib3/connectionpool.py", line 978, in _validate_conn
    conn.connect()
  File "/home/yanxindong/anaconda/envs/eva/lib/python3.8/site-packages/urllib3/connection.py", line 309, in connect
    conn = self._new_conn()
  File "/home/yanxindong/anaconda/envs/eva/lib/python3.8/site-packages/urllib3/connection.py", line 171, in _new_conn
    raise NewConnectionError(
urllib3.exceptions.NewConnectionError: <urllib3.connection.HTTPSConnection object at 0x7f8598062bb0>: Failed to establish a new connection: [Errno 101] Network is unreachable

During handling of the above exception, another exception occurred:

Traceback (most recent call last):
  File "/home/yanxindong/anaconda/envs/eva/lib/python3.8/site-packages/requests/adapters.py", line 439, in send
    resp = conn.urlopen(
  File "/home/yanxindong/anaconda/envs/eva/lib/python3.8/site-packages/urllib3/connectionpool.py", line 726, in urlopen
    retries = retries.increment(
  File "/home/yanxindong/anaconda/envs/eva/lib/python3.8/site-packages/urllib3/util/retry.py", line 446, in increment
    raise MaxRetryError(_pool, url, error or ResponseError(cause))
urllib3.exceptions.MaxRetryError: HTTPSConnectionPool(host='storage.googleapis.com', port=443): Max retries exceeded with url: /wandb-artifacts-prod/wandb_artifacts/133981200/707680476/6873c23a2381d1524249eb1a948a45a5?Expires=1706688978&GoogleAccessId=gorilla-files-url-signer-man%40wandb-production.iam.gserviceaccount.com&Signature=FJbunGpfeOQfbKn542AGPFUBcBVQErMSPGikGCa0aecFeElbpWRcwkiz4wMxZgu6SOi89%2BydcFZipV2Ca52hCBN6z6HQ%2FWNmhJfUfy8OfSxKUOEfnm%2FacOCYZumigHY8XXWV14q%2BIE%2BSXX5UKop3Oygpq2XwB4kUAVTF1xiWGV9J82N5lexioy35TMM0M3fpZVNTLjBkETzKCAah3YICcTldU0r9Cj%2BKrfTDZRT1nd9nHIsEuOMP8GR1dBD958dC5j5Onja4PEXVcvyHXBgveCtHVX7unpWD6GCcrTs2tj5x5W2cpsRNemTkFrzKs%2FQMT3832Dv7Gt5Sw0Hkmzwuvg%3D%3D (Caused by NewConnectionError('<urllib3.connection.HTTPSConnection object at 0x7f8598062bb0>: Failed to establish a new connection: [Errno 101] Network is unreachable'))

During handling of the above exception, another exception occurred:

Traceback (most recent call last):
  File "/home/yanxindong/anaconda/envs/eva/lib/python3.8/site-packages/wandb/sdk/internal/internal_api.py", line 2758, in upload_file
    response = self._upload_file_session.put(
  File "/home/yanxindong/anaconda/envs/eva/lib/python3.8/site-packages/requests/sessions.py", line 590, in put
    return self.request('PUT', url, data=data, **kwargs)
  File "/home/yanxindong/anaconda/envs/eva/lib/python3.8/site-packages/requests/sessions.py", line 530, in request
    resp = self.send(prep, **send_kwargs)
  File "/home/yanxindong/anaconda/envs/eva/lib/python3.8/site-packages/requests/sessions.py", line 643, in send
    r = adapter.send(request, **kwargs)
  File "/home/yanxindong/anaconda/envs/eva/lib/python3.8/site-packages/requests/adapters.py", line 516, in send
    raise ConnectionError(e, request=request)
requests.exceptions.ConnectionError: HTTPSConnectionPool(host='storage.googleapis.com', port=443): Max retries exceeded with url: /wandb-artifacts-prod/wandb_artifacts/133981200/707680476/6873c23a2381d1524249eb1a948a45a5?Expires=1706688978&GoogleAccessId=gorilla-files-url-signer-man%40wandb-production.iam.gserviceaccount.com&Signature=FJbunGpfeOQfbKn542AGPFUBcBVQErMSPGikGCa0aecFeElbpWRcwkiz4wMxZgu6SOi89%2BydcFZipV2Ca52hCBN6z6HQ%2FWNmhJfUfy8OfSxKUOEfnm%2FacOCYZumigHY8XXWV14q%2BIE%2BSXX5UKop3Oygpq2XwB4kUAVTF1xiWGV9J82N5lexioy35TMM0M3fpZVNTLjBkETzKCAah3YICcTldU0r9Cj%2BKrfTDZRT1nd9nHIsEuOMP8GR1dBD958dC5j5Onja4PEXVcvyHXBgveCtHVX7unpWD6GCcrTs2tj5x5W2cpsRNemTkFrzKs%2FQMT3832Dv7Gt5Sw0Hkmzwuvg%3D%3D (Caused by NewConnectionError('<urllib3.connection.HTTPSConnection object at 0x7f8598062bb0>: Failed to establish a new connection: [Errno 101] Network is unreachable'))

During handling of the above exception, another exception occurred:

Traceback (most recent call last):
  File "/home/yanxindong/anaconda/envs/eva/lib/python3.8/site-packages/wandb/sdk/lib/retry.py", line 131, in __call__
    result = self._call_fn(*args, **kwargs)
  File "/home/yanxindong/anaconda/envs/eva/lib/python3.8/site-packages/wandb/sdk/internal/internal_api.py", line 2789, in upload_file
    raise _e.with_traceback(sys.exc_info()[2])
  File "/home/yanxindong/anaconda/envs/eva/lib/python3.8/site-packages/wandb/sdk/internal/internal_api.py", line 2758, in upload_file
    response = self._upload_file_session.put(
  File "/home/yanxindong/anaconda/envs/eva/lib/python3.8/site-packages/requests/sessions.py", line 590, in put
    return self.request('PUT', url, data=data, **kwargs)
  File "/home/yanxindong/anaconda/envs/eva/lib/python3.8/site-packages/requests/sessions.py", line 530, in request
    resp = self.send(prep, **send_kwargs)
  File "/home/yanxindong/anaconda/envs/eva/lib/python3.8/site-packages/requests/sessions.py", line 643, in send
    r = adapter.send(request, **kwargs)
  File "/home/yanxindong/anaconda/envs/eva/lib/python3.8/site-packages/requests/adapters.py", line 516, in send
    raise ConnectionError(e, request=request)
wandb.sdk.lib.retry.TransientError: None
2024-01-30 16:16:21,631 ERROR   wandb-upload_1:1134330 [internal_api.py:upload_file():2765] upload_file exception https://storage.googleapis.com/wandb-artifacts-prod/wandb_artifacts/133981200/707680476/174a3d9bc61fec126cc7d5bdff5c6c5a?Expires=1706688978&GoogleAccessId=gorilla-files-url-signer-man%40wandb-production.iam.gserviceaccount.com&Signature=K7H67UT394ZxkY38h5LLo7qstPxKv9DSLuAIJ%2BawMnvSiLlI76Ar1VipqXQ9pE2svxdbUoX5nmTEq7htyjyogM9hI2e%2BbXLJ3PoZ%2BriOYuitZhYGSJttcVAQw6Vj29UhAQJwY1H8R795pIZVRYna6cwp6vWgd71BUO07graO60iA5ovSG0hXC58DfrZgygvrTFXYZ4iKDeZ57uzYZ4%2B%2FkGEwaXYePNjphjRm5Ev9U7uBwbYTRr7X%2BaGwd5Uz0P5iNB0W1al7TBPBUIvguYcJST90PRLbxcOY3kltbxzaPXOkec3duvGtMxzCsmXn7fHJTvyNNIWDCMGQBex2WaNEng%3D%3D: HTTPSConnectionPool(host='storage.googleapis.com', port=443): Max retries exceeded with url: /wandb-artifacts-prod/wandb_artifacts/133981200/707680476/174a3d9bc61fec126cc7d5bdff5c6c5a?Expires=1706688978&GoogleAccessId=gorilla-files-url-signer-man%40wandb-production.iam.gserviceaccount.com&Signature=K7H67UT394ZxkY38h5LLo7qstPxKv9DSLuAIJ%2BawMnvSiLlI76Ar1VipqXQ9pE2svxdbUoX5nmTEq7htyjyogM9hI2e%2BbXLJ3PoZ%2BriOYuitZhYGSJttcVAQw6Vj29UhAQJwY1H8R795pIZVRYna6cwp6vWgd71BUO07graO60iA5ovSG0hXC58DfrZgygvrTFXYZ4iKDeZ57uzYZ4%2B%2FkGEwaXYePNjphjRm5Ev9U7uBwbYTRr7X%2BaGwd5Uz0P5iNB0W1al7TBPBUIvguYcJST90PRLbxcOY3kltbxzaPXOkec3duvGtMxzCsmXn7fHJTvyNNIWDCMGQBex2WaNEng%3D%3D (Caused by NewConnectionError('<urllib3.connection.HTTPSConnection object at 0x7f85980623a0>: Failed to establish a new connection: [Errno 101] Network is unreachable'))
2024-01-30 16:16:21,632 ERROR   wandb-upload_1:1134330 [internal_api.py:upload_file():2767] upload_file request headers: {'User-Agent': 'python-requests/2.23.0', 'Accept-Encoding': 'gzip, deflate', 'Accept': '*/*', 'Connection': 'keep-alive', 'Content-MD5': 'F0o9m8Yf7BJsx9W9/1xsWg==', 'Content-Type': 'text/plain; charset=utf-8', 'Content-Length': '2179'}
2024-01-30 16:16:21,632 ERROR   wandb-upload_1:1134330 [internal_api.py:upload_file():2769] upload_file response body: 
2024-01-30 16:16:22,022 DEBUG   HandlerThread:1134330 [handler.py:handle_request():146] handle_request: keepalive
2024-01-30 16:16:22,338 ERROR   wandb-upload_2:1134330 [internal_api.py:upload_file():2765] upload_file exception https://storage.googleapis.com/wandb-artifacts-prod/wandb_artifacts/133981200/707680476/6873c23a2381d1524249eb1a948a45a5?Expires=1706688978&GoogleAccessId=gorilla-files-url-signer-man%40wandb-production.iam.gserviceaccount.com&Signature=FJbunGpfeOQfbKn542AGPFUBcBVQErMSPGikGCa0aecFeElbpWRcwkiz4wMxZgu6SOi89%2BydcFZipV2Ca52hCBN6z6HQ%2FWNmhJfUfy8OfSxKUOEfnm%2FacOCYZumigHY8XXWV14q%2BIE%2BSXX5UKop3Oygpq2XwB4kUAVTF1xiWGV9J82N5lexioy35TMM0M3fpZVNTLjBkETzKCAah3YICcTldU0r9Cj%2BKrfTDZRT1nd9nHIsEuOMP8GR1dBD958dC5j5Onja4PEXVcvyHXBgveCtHVX7unpWD6GCcrTs2tj5x5W2cpsRNemTkFrzKs%2FQMT3832Dv7Gt5Sw0Hkmzwuvg%3D%3D: HTTPSConnectionPool(host='storage.googleapis.com', port=443): Max retries exceeded with url: /wandb-artifacts-prod/wandb_artifacts/133981200/707680476/6873c23a2381d1524249eb1a948a45a5?Expires=1706688978&GoogleAccessId=gorilla-files-url-signer-man%40wandb-production.iam.gserviceaccount.com&Signature=FJbunGpfeOQfbKn542AGPFUBcBVQErMSPGikGCa0aecFeElbpWRcwkiz4wMxZgu6SOi89%2BydcFZipV2Ca52hCBN6z6HQ%2FWNmhJfUfy8OfSxKUOEfnm%2FacOCYZumigHY8XXWV14q%2BIE%2BSXX5UKop3Oygpq2XwB4kUAVTF1xiWGV9J82N5lexioy35TMM0M3fpZVNTLjBkETzKCAah3YICcTldU0r9Cj%2BKrfTDZRT1nd9nHIsEuOMP8GR1dBD958dC5j5Onja4PEXVcvyHXBgveCtHVX7unpWD6GCcrTs2tj5x5W2cpsRNemTkFrzKs%2FQMT3832Dv7Gt5Sw0Hkmzwuvg%3D%3D (Caused by NewConnectionError('<urllib3.connection.HTTPSConnection object at 0x7f85980622b0>: Failed to establish a new connection: [Errno 101] Network is unreachable'))
2024-01-30 16:16:22,338 ERROR   wandb-upload_2:1134330 [internal_api.py:upload_file():2767] upload_file request headers: {'User-Agent': 'python-requests/2.23.0', 'Accept-Encoding': 'gzip, deflate', 'Accept': '*/*', 'Connection': 'keep-alive', 'Content-MD5': 'aHPCOiOB0VJCSesalIpFpQ==', 'Content-Type': 'application/json', 'Content-Length': '609'}
2024-01-30 16:16:22,338 ERROR   wandb-upload_2:1134330 [internal_api.py:upload_file():2769] upload_file response body: 
2024-01-30 16:16:26,212 ERROR   wandb-upload_1:1134330 [internal_api.py:upload_file():2765] upload_file exception https://storage.googleapis.com/wandb-artifacts-prod/wandb_artifacts/133981200/707680476/174a3d9bc61fec126cc7d5bdff5c6c5a?Expires=1706688978&GoogleAccessId=gorilla-files-url-signer-man%40wandb-production.iam.gserviceaccount.com&Signature=K7H67UT394ZxkY38h5LLo7qstPxKv9DSLuAIJ%2BawMnvSiLlI76Ar1VipqXQ9pE2svxdbUoX5nmTEq7htyjyogM9hI2e%2BbXLJ3PoZ%2BriOYuitZhYGSJttcVAQw6Vj29UhAQJwY1H8R795pIZVRYna6cwp6vWgd71BUO07graO60iA5ovSG0hXC58DfrZgygvrTFXYZ4iKDeZ57uzYZ4%2B%2FkGEwaXYePNjphjRm5Ev9U7uBwbYTRr7X%2BaGwd5Uz0P5iNB0W1al7TBPBUIvguYcJST90PRLbxcOY3kltbxzaPXOkec3duvGtMxzCsmXn7fHJTvyNNIWDCMGQBex2WaNEng%3D%3D: HTTPSConnectionPool(host='storage.googleapis.com', port=443): Max retries exceeded with url: /wandb-artifacts-prod/wandb_artifacts/133981200/707680476/174a3d9bc61fec126cc7d5bdff5c6c5a?Expires=1706688978&GoogleAccessId=gorilla-files-url-signer-man%40wandb-production.iam.gserviceaccount.com&Signature=K7H67UT394ZxkY38h5LLo7qstPxKv9DSLuAIJ%2BawMnvSiLlI76Ar1VipqXQ9pE2svxdbUoX5nmTEq7htyjyogM9hI2e%2BbXLJ3PoZ%2BriOYuitZhYGSJttcVAQw6Vj29UhAQJwY1H8R795pIZVRYna6cwp6vWgd71BUO07graO60iA5ovSG0hXC58DfrZgygvrTFXYZ4iKDeZ57uzYZ4%2B%2FkGEwaXYePNjphjRm5Ev9U7uBwbYTRr7X%2BaGwd5Uz0P5iNB0W1al7TBPBUIvguYcJST90PRLbxcOY3kltbxzaPXOkec3duvGtMxzCsmXn7fHJTvyNNIWDCMGQBex2WaNEng%3D%3D (Caused by NewConnectionError('<urllib3.connection.HTTPSConnection object at 0x7f859811b760>: Failed to establish a new connection: [Errno 101] Network is unreachable'))
2024-01-30 16:16:26,212 ERROR   wandb-upload_1:1134330 [internal_api.py:upload_file():2767] upload_file request headers: {'User-Agent': 'python-requests/2.23.0', 'Accept-Encoding': 'gzip, deflate', 'Accept': '*/*', 'Connection': 'keep-alive', 'Content-MD5': 'F0o9m8Yf7BJsx9W9/1xsWg==', 'Content-Type': 'text/plain; charset=utf-8', 'Content-Length': '2179'}
2024-01-30 16:16:26,212 ERROR   wandb-upload_1:1134330 [internal_api.py:upload_file():2769] upload_file response body: 
2024-01-30 16:16:26,581 ERROR   wandb-upload_2:1134330 [internal_api.py:upload_file():2765] upload_file exception https://storage.googleapis.com/wandb-artifacts-prod/wandb_artifacts/133981200/707680476/6873c23a2381d1524249eb1a948a45a5?Expires=1706688978&GoogleAccessId=gorilla-files-url-signer-man%40wandb-production.iam.gserviceaccount.com&Signature=FJbunGpfeOQfbKn542AGPFUBcBVQErMSPGikGCa0aecFeElbpWRcwkiz4wMxZgu6SOi89%2BydcFZipV2Ca52hCBN6z6HQ%2FWNmhJfUfy8OfSxKUOEfnm%2FacOCYZumigHY8XXWV14q%2BIE%2BSXX5UKop3Oygpq2XwB4kUAVTF1xiWGV9J82N5lexioy35TMM0M3fpZVNTLjBkETzKCAah3YICcTldU0r9Cj%2BKrfTDZRT1nd9nHIsEuOMP8GR1dBD958dC5j5Onja4PEXVcvyHXBgveCtHVX7unpWD6GCcrTs2tj5x5W2cpsRNemTkFrzKs%2FQMT3832Dv7Gt5Sw0Hkmzwuvg%3D%3D: HTTPSConnectionPool(host='storage.googleapis.com', port=443): Max retries exceeded with url: /wandb-artifacts-prod/wandb_artifacts/133981200/707680476/6873c23a2381d1524249eb1a948a45a5?Expires=1706688978&GoogleAccessId=gorilla-files-url-signer-man%40wandb-production.iam.gserviceaccount.com&Signature=FJbunGpfeOQfbKn542AGPFUBcBVQErMSPGikGCa0aecFeElbpWRcwkiz4wMxZgu6SOi89%2BydcFZipV2Ca52hCBN6z6HQ%2FWNmhJfUfy8OfSxKUOEfnm%2FacOCYZumigHY8XXWV14q%2BIE%2BSXX5UKop3Oygpq2XwB4kUAVTF1xiWGV9J82N5lexioy35TMM0M3fpZVNTLjBkETzKCAah3YICcTldU0r9Cj%2BKrfTDZRT1nd9nHIsEuOMP8GR1dBD958dC5j5Onja4PEXVcvyHXBgveCtHVX7unpWD6GCcrTs2tj5x5W2cpsRNemTkFrzKs%2FQMT3832Dv7Gt5Sw0Hkmzwuvg%3D%3D (Caused by NewConnectionError('<urllib3.connection.HTTPSConnection object at 0x7f859811b700>: Failed to establish a new connection: [Errno 101] Network is unreachable'))
2024-01-30 16:16:26,581 ERROR   wandb-upload_2:1134330 [internal_api.py:upload_file():2767] upload_file request headers: {'User-Agent': 'python-requests/2.23.0', 'Accept-Encoding': 'gzip, deflate', 'Accept': '*/*', 'Connection': 'keep-alive', 'Content-MD5': 'aHPCOiOB0VJCSesalIpFpQ==', 'Content-Type': 'application/json', 'Content-Length': '609'}
2024-01-30 16:16:26,581 ERROR   wandb-upload_2:1134330 [internal_api.py:upload_file():2769] upload_file response body: 
2024-01-30 16:16:27,024 DEBUG   HandlerThread:1134330 [handler.py:handle_request():146] handle_request: keepalive
2024-01-30 16:16:32,026 DEBUG   HandlerThread:1134330 [handler.py:handle_request():146] handle_request: keepalive
2024-01-30 16:16:34,293 ERROR   wandb-upload_1:1134330 [internal_api.py:upload_file():2765] upload_file exception https://storage.googleapis.com/wandb-artifacts-prod/wandb_artifacts/133981200/707680476/174a3d9bc61fec126cc7d5bdff5c6c5a?Expires=1706688978&GoogleAccessId=gorilla-files-url-signer-man%40wandb-production.iam.gserviceaccount.com&Signature=K7H67UT394ZxkY38h5LLo7qstPxKv9DSLuAIJ%2BawMnvSiLlI76Ar1VipqXQ9pE2svxdbUoX5nmTEq7htyjyogM9hI2e%2BbXLJ3PoZ%2BriOYuitZhYGSJttcVAQw6Vj29UhAQJwY1H8R795pIZVRYna6cwp6vWgd71BUO07graO60iA5ovSG0hXC58DfrZgygvrTFXYZ4iKDeZ57uzYZ4%2B%2FkGEwaXYePNjphjRm5Ev9U7uBwbYTRr7X%2BaGwd5Uz0P5iNB0W1al7TBPBUIvguYcJST90PRLbxcOY3kltbxzaPXOkec3duvGtMxzCsmXn7fHJTvyNNIWDCMGQBex2WaNEng%3D%3D: HTTPSConnectionPool(host='storage.googleapis.com', port=443): Max retries exceeded with url: /wandb-artifacts-prod/wandb_artifacts/133981200/707680476/174a3d9bc61fec126cc7d5bdff5c6c5a?Expires=1706688978&GoogleAccessId=gorilla-files-url-signer-man%40wandb-production.iam.gserviceaccount.com&Signature=K7H67UT394ZxkY38h5LLo7qstPxKv9DSLuAIJ%2BawMnvSiLlI76Ar1VipqXQ9pE2svxdbUoX5nmTEq7htyjyogM9hI2e%2BbXLJ3PoZ%2BriOYuitZhYGSJttcVAQw6Vj29UhAQJwY1H8R795pIZVRYna6cwp6vWgd71BUO07graO60iA5ovSG0hXC58DfrZgygvrTFXYZ4iKDeZ57uzYZ4%2B%2FkGEwaXYePNjphjRm5Ev9U7uBwbYTRr7X%2BaGwd5Uz0P5iNB0W1al7TBPBUIvguYcJST90PRLbxcOY3kltbxzaPXOkec3duvGtMxzCsmXn7fHJTvyNNIWDCMGQBex2WaNEng%3D%3D (Caused by NewConnectionError('<urllib3.connection.HTTPSConnection object at 0x7f8598062760>: Failed to establish a new connection: [Errno 101] Network is unreachable'))
2024-01-30 16:16:34,294 ERROR   wandb-upload_1:1134330 [internal_api.py:upload_file():2767] upload_file request headers: {'User-Agent': 'python-requests/2.23.0', 'Accept-Encoding': 'gzip, deflate', 'Accept': '*/*', 'Connection': 'keep-alive', 'Content-MD5': 'F0o9m8Yf7BJsx9W9/1xsWg==', 'Content-Type': 'text/plain; charset=utf-8', 'Content-Length': '2179'}
2024-01-30 16:16:34,294 ERROR   wandb-upload_1:1134330 [internal_api.py:upload_file():2769] upload_file response body: 
2024-01-30 16:16:36,253 ERROR   wandb-upload_2:1134330 [internal_api.py:upload_file():2765] upload_file exception https://storage.googleapis.com/wandb-artifacts-prod/wandb_artifacts/133981200/707680476/6873c23a2381d1524249eb1a948a45a5?Expires=1706688978&GoogleAccessId=gorilla-files-url-signer-man%40wandb-production.iam.gserviceaccount.com&Signature=FJbunGpfeOQfbKn542AGPFUBcBVQErMSPGikGCa0aecFeElbpWRcwkiz4wMxZgu6SOi89%2BydcFZipV2Ca52hCBN6z6HQ%2FWNmhJfUfy8OfSxKUOEfnm%2FacOCYZumigHY8XXWV14q%2BIE%2BSXX5UKop3Oygpq2XwB4kUAVTF1xiWGV9J82N5lexioy35TMM0M3fpZVNTLjBkETzKCAah3YICcTldU0r9Cj%2BKrfTDZRT1nd9nHIsEuOMP8GR1dBD958dC5j5Onja4PEXVcvyHXBgveCtHVX7unpWD6GCcrTs2tj5x5W2cpsRNemTkFrzKs%2FQMT3832Dv7Gt5Sw0Hkmzwuvg%3D%3D: HTTPSConnectionPool(host='storage.googleapis.com', port=443): Max retries exceeded with url: /wandb-artifacts-prod/wandb_artifacts/133981200/707680476/6873c23a2381d1524249eb1a948a45a5?Expires=1706688978&GoogleAccessId=gorilla-files-url-signer-man%40wandb-production.iam.gserviceaccount.com&Signature=FJbunGpfeOQfbKn542AGPFUBcBVQErMSPGikGCa0aecFeElbpWRcwkiz4wMxZgu6SOi89%2BydcFZipV2Ca52hCBN6z6HQ%2FWNmhJfUfy8OfSxKUOEfnm%2FacOCYZumigHY8XXWV14q%2BIE%2BSXX5UKop3Oygpq2XwB4kUAVTF1xiWGV9J82N5lexioy35TMM0M3fpZVNTLjBkETzKCAah3YICcTldU0r9Cj%2BKrfTDZRT1nd9nHIsEuOMP8GR1dBD958dC5j5Onja4PEXVcvyHXBgveCtHVX7unpWD6GCcrTs2tj5x5W2cpsRNemTkFrzKs%2FQMT3832Dv7Gt5Sw0Hkmzwuvg%3D%3D (Caused by NewConnectionError('<urllib3.connection.HTTPSConnection object at 0x7f859801e1c0>: Failed to establish a new connection: [Errno 101] Network is unreachable'))
2024-01-30 16:16:36,253 ERROR   wandb-upload_2:1134330 [internal_api.py:upload_file():2767] upload_file request headers: {'User-Agent': 'python-requests/2.23.0', 'Accept-Encoding': 'gzip, deflate', 'Accept': '*/*', 'Connection': 'keep-alive', 'Content-MD5': 'aHPCOiOB0VJCSesalIpFpQ==', 'Content-Type': 'application/json', 'Content-Length': '609'}
2024-01-30 16:16:36,253 ERROR   wandb-upload_2:1134330 [internal_api.py:upload_file():2769] upload_file response body: 
2024-01-30 16:16:37,029 DEBUG   HandlerThread:1134330 [handler.py:handle_request():146] handle_request: keepalive
2024-01-30 16:16:42,031 DEBUG   HandlerThread:1134330 [handler.py:handle_request():146] handle_request: keepalive
2024-01-30 16:16:47,034 DEBUG   HandlerThread:1134330 [handler.py:handle_request():146] handle_request: keepalive
2024-01-30 16:16:52,037 DEBUG   HandlerThread:1134330 [handler.py:handle_request():146] handle_request: keepalive
2024-01-30 16:16:52,062 ERROR   wandb-upload_1:1134330 [internal_api.py:upload_file():2765] upload_file exception https://storage.googleapis.com/wandb-artifacts-prod/wandb_artifacts/133981200/707680476/174a3d9bc61fec126cc7d5bdff5c6c5a?Expires=1706688978&GoogleAccessId=gorilla-files-url-signer-man%40wandb-production.iam.gserviceaccount.com&Signature=K7H67UT394ZxkY38h5LLo7qstPxKv9DSLuAIJ%2BawMnvSiLlI76Ar1VipqXQ9pE2svxdbUoX5nmTEq7htyjyogM9hI2e%2BbXLJ3PoZ%2BriOYuitZhYGSJttcVAQw6Vj29UhAQJwY1H8R795pIZVRYna6cwp6vWgd71BUO07graO60iA5ovSG0hXC58DfrZgygvrTFXYZ4iKDeZ57uzYZ4%2B%2FkGEwaXYePNjphjRm5Ev9U7uBwbYTRr7X%2BaGwd5Uz0P5iNB0W1al7TBPBUIvguYcJST90PRLbxcOY3kltbxzaPXOkec3duvGtMxzCsmXn7fHJTvyNNIWDCMGQBex2WaNEng%3D%3D: HTTPSConnectionPool(host='storage.googleapis.com', port=443): Max retries exceeded with url: /wandb-artifacts-prod/wandb_artifacts/133981200/707680476/174a3d9bc61fec126cc7d5bdff5c6c5a?Expires=1706688978&GoogleAccessId=gorilla-files-url-signer-man%40wandb-production.iam.gserviceaccount.com&Signature=K7H67UT394ZxkY38h5LLo7qstPxKv9DSLuAIJ%2BawMnvSiLlI76Ar1VipqXQ9pE2svxdbUoX5nmTEq7htyjyogM9hI2e%2BbXLJ3PoZ%2BriOYuitZhYGSJttcVAQw6Vj29UhAQJwY1H8R795pIZVRYna6cwp6vWgd71BUO07graO60iA5ovSG0hXC58DfrZgygvrTFXYZ4iKDeZ57uzYZ4%2B%2FkGEwaXYePNjphjRm5Ev9U7uBwbYTRr7X%2BaGwd5Uz0P5iNB0W1al7TBPBUIvguYcJST90PRLbxcOY3kltbxzaPXOkec3duvGtMxzCsmXn7fHJTvyNNIWDCMGQBex2WaNEng%3D%3D (Caused by NewConnectionError('<urllib3.connection.HTTPSConnection object at 0x7f8578f805e0>: Failed to establish a new connection: [Errno 101] Network is unreachable'))
2024-01-30 16:16:52,062 ERROR   wandb-upload_1:1134330 [internal_api.py:upload_file():2767] upload_file request headers: {'User-Agent': 'python-requests/2.23.0', 'Accept-Encoding': 'gzip, deflate', 'Accept': '*/*', 'Connection': 'keep-alive', 'Content-MD5': 'F0o9m8Yf7BJsx9W9/1xsWg==', 'Content-Type': 'text/plain; charset=utf-8', 'Content-Length': '2179'}
2024-01-30 16:16:52,062 ERROR   wandb-upload_1:1134330 [internal_api.py:upload_file():2769] upload_file response body: 
2024-01-30 16:16:52,653 ERROR   wandb-upload_2:1134330 [internal_api.py:upload_file():2765] upload_file exception https://storage.googleapis.com/wandb-artifacts-prod/wandb_artifacts/133981200/707680476/6873c23a2381d1524249eb1a948a45a5?Expires=1706688978&GoogleAccessId=gorilla-files-url-signer-man%40wandb-production.iam.gserviceaccount.com&Signature=FJbunGpfeOQfbKn542AGPFUBcBVQErMSPGikGCa0aecFeElbpWRcwkiz4wMxZgu6SOi89%2BydcFZipV2Ca52hCBN6z6HQ%2FWNmhJfUfy8OfSxKUOEfnm%2FacOCYZumigHY8XXWV14q%2BIE%2BSXX5UKop3Oygpq2XwB4kUAVTF1xiWGV9J82N5lexioy35TMM0M3fpZVNTLjBkETzKCAah3YICcTldU0r9Cj%2BKrfTDZRT1nd9nHIsEuOMP8GR1dBD958dC5j5Onja4PEXVcvyHXBgveCtHVX7unpWD6GCcrTs2tj5x5W2cpsRNemTkFrzKs%2FQMT3832Dv7Gt5Sw0Hkmzwuvg%3D%3D: HTTPSConnectionPool(host='storage.googleapis.com', port=443): Max retries exceeded with url: /wandb-artifacts-prod/wandb_artifacts/133981200/707680476/6873c23a2381d1524249eb1a948a45a5?Expires=1706688978&GoogleAccessId=gorilla-files-url-signer-man%40wandb-production.iam.gserviceaccount.com&Signature=FJbunGpfeOQfbKn542AGPFUBcBVQErMSPGikGCa0aecFeElbpWRcwkiz4wMxZgu6SOi89%2BydcFZipV2Ca52hCBN6z6HQ%2FWNmhJfUfy8OfSxKUOEfnm%2FacOCYZumigHY8XXWV14q%2BIE%2BSXX5UKop3Oygpq2XwB4kUAVTF1xiWGV9J82N5lexioy35TMM0M3fpZVNTLjBkETzKCAah3YICcTldU0r9Cj%2BKrfTDZRT1nd9nHIsEuOMP8GR1dBD958dC5j5Onja4PEXVcvyHXBgveCtHVX7unpWD6GCcrTs2tj5x5W2cpsRNemTkFrzKs%2FQMT3832Dv7Gt5Sw0Hkmzwuvg%3D%3D (Caused by NewConnectionError('<urllib3.connection.HTTPSConnection object at 0x7f8578f80580>: Failed to establish a new connection: [Errno 101] Network is unreachable'))
2024-01-30 16:16:52,654 ERROR   wandb-upload_2:1134330 [internal_api.py:upload_file():2767] upload_file request headers: {'User-Agent': 'python-requests/2.23.0', 'Accept-Encoding': 'gzip, deflate', 'Accept': '*/*', 'Connection': 'keep-alive', 'Content-MD5': 'aHPCOiOB0VJCSesalIpFpQ==', 'Content-Type': 'application/json', 'Content-Length': '609'}
2024-01-30 16:16:52,654 ERROR   wandb-upload_2:1134330 [internal_api.py:upload_file():2769] upload_file response body: 
2024-01-30 16:16:57,039 DEBUG   HandlerThread:1134330 [handler.py:handle_request():146] handle_request: keepalive
2024-01-30 16:17:02,042 DEBUG   HandlerThread:1134330 [handler.py:handle_request():146] handle_request: keepalive
2024-01-30 16:17:07,044 DEBUG   HandlerThread:1134330 [handler.py:handle_request():146] handle_request: keepalive
2024-01-30 16:17:12,046 DEBUG   HandlerThread:1134330 [handler.py:handle_request():146] handle_request: keepalive
2024-01-30 16:17:17,049 DEBUG   HandlerThread:1134330 [handler.py:handle_request():146] handle_request: keepalive
2024-01-30 16:17:22,051 DEBUG   HandlerThread:1134330 [handler.py:handle_request():146] handle_request: keepalive
2024-01-30 16:17:27,053 DEBUG   HandlerThread:1134330 [handler.py:handle_request():146] handle_request: keepalive
2024-01-30 16:17:28,022 ERROR   wandb-upload_1:1134330 [internal_api.py:upload_file():2765] upload_file exception https://storage.googleapis.com/wandb-artifacts-prod/wandb_artifacts/133981200/707680476/174a3d9bc61fec126cc7d5bdff5c6c5a?Expires=1706688978&GoogleAccessId=gorilla-files-url-signer-man%40wandb-production.iam.gserviceaccount.com&Signature=K7H67UT394ZxkY38h5LLo7qstPxKv9DSLuAIJ%2BawMnvSiLlI76Ar1VipqXQ9pE2svxdbUoX5nmTEq7htyjyogM9hI2e%2BbXLJ3PoZ%2BriOYuitZhYGSJttcVAQw6Vj29UhAQJwY1H8R795pIZVRYna6cwp6vWgd71BUO07graO60iA5ovSG0hXC58DfrZgygvrTFXYZ4iKDeZ57uzYZ4%2B%2FkGEwaXYePNjphjRm5Ev9U7uBwbYTRr7X%2BaGwd5Uz0P5iNB0W1al7TBPBUIvguYcJST90PRLbxcOY3kltbxzaPXOkec3duvGtMxzCsmXn7fHJTvyNNIWDCMGQBex2WaNEng%3D%3D: HTTPSConnectionPool(host='storage.googleapis.com', port=443): Max retries exceeded with url: /wandb-artifacts-prod/wandb_artifacts/133981200/707680476/174a3d9bc61fec126cc7d5bdff5c6c5a?Expires=1706688978&GoogleAccessId=gorilla-files-url-signer-man%40wandb-production.iam.gserviceaccount.com&Signature=K7H67UT394ZxkY38h5LLo7qstPxKv9DSLuAIJ%2BawMnvSiLlI76Ar1VipqXQ9pE2svxdbUoX5nmTEq7htyjyogM9hI2e%2BbXLJ3PoZ%2BriOYuitZhYGSJttcVAQw6Vj29UhAQJwY1H8R795pIZVRYna6cwp6vWgd71BUO07graO60iA5ovSG0hXC58DfrZgygvrTFXYZ4iKDeZ57uzYZ4%2B%2FkGEwaXYePNjphjRm5Ev9U7uBwbYTRr7X%2BaGwd5Uz0P5iNB0W1al7TBPBUIvguYcJST90PRLbxcOY3kltbxzaPXOkec3duvGtMxzCsmXn7fHJTvyNNIWDCMGQBex2WaNEng%3D%3D (Caused by NewConnectionError('<urllib3.connection.HTTPSConnection object at 0x7f8578f91fa0>: Failed to establish a new connection: [Errno 101] Network is unreachable'))
2024-01-30 16:17:28,022 ERROR   wandb-upload_1:1134330 [internal_api.py:upload_file():2767] upload_file request headers: {'User-Agent': 'python-requests/2.23.0', 'Accept-Encoding': 'gzip, deflate', 'Accept': '*/*', 'Connection': 'keep-alive', 'Content-MD5': 'F0o9m8Yf7BJsx9W9/1xsWg==', 'Content-Type': 'text/plain; charset=utf-8', 'Content-Length': '2179'}
2024-01-30 16:17:28,022 ERROR   wandb-upload_1:1134330 [internal_api.py:upload_file():2769] upload_file response body: 
2024-01-30 16:17:31,794 ERROR   wandb-upload_2:1134330 [internal_api.py:upload_file():2765] upload_file exception https://storage.googleapis.com/wandb-artifacts-prod/wandb_artifacts/133981200/707680476/6873c23a2381d1524249eb1a948a45a5?Expires=1706688978&GoogleAccessId=gorilla-files-url-signer-man%40wandb-production.iam.gserviceaccount.com&Signature=FJbunGpfeOQfbKn542AGPFUBcBVQErMSPGikGCa0aecFeElbpWRcwkiz4wMxZgu6SOi89%2BydcFZipV2Ca52hCBN6z6HQ%2FWNmhJfUfy8OfSxKUOEfnm%2FacOCYZumigHY8XXWV14q%2BIE%2BSXX5UKop3Oygpq2XwB4kUAVTF1xiWGV9J82N5lexioy35TMM0M3fpZVNTLjBkETzKCAah3YICcTldU0r9Cj%2BKrfTDZRT1nd9nHIsEuOMP8GR1dBD958dC5j5Onja4PEXVcvyHXBgveCtHVX7unpWD6GCcrTs2tj5x5W2cpsRNemTkFrzKs%2FQMT3832Dv7Gt5Sw0Hkmzwuvg%3D%3D: HTTPSConnectionPool(host='storage.googleapis.com', port=443): Max retries exceeded with url: /wandb-artifacts-prod/wandb_artifacts/133981200/707680476/6873c23a2381d1524249eb1a948a45a5?Expires=1706688978&GoogleAccessId=gorilla-files-url-signer-man%40wandb-production.iam.gserviceaccount.com&Signature=FJbunGpfeOQfbKn542AGPFUBcBVQErMSPGikGCa0aecFeElbpWRcwkiz4wMxZgu6SOi89%2BydcFZipV2Ca52hCBN6z6HQ%2FWNmhJfUfy8OfSxKUOEfnm%2FacOCYZumigHY8XXWV14q%2BIE%2BSXX5UKop3Oygpq2XwB4kUAVTF1xiWGV9J82N5lexioy35TMM0M3fpZVNTLjBkETzKCAah3YICcTldU0r9Cj%2BKrfTDZRT1nd9nHIsEuOMP8GR1dBD958dC5j5Onja4PEXVcvyHXBgveCtHVX7unpWD6GCcrTs2tj5x5W2cpsRNemTkFrzKs%2FQMT3832Dv7Gt5Sw0Hkmzwuvg%3D%3D (Caused by NewConnectionError('<urllib3.connection.HTTPSConnection object at 0x7f8578f807c0>: Failed to establish a new connection: [Errno 101] Network is unreachable'))
2024-01-30 16:17:31,795 ERROR   wandb-upload_2:1134330 [internal_api.py:upload_file():2767] upload_file request headers: {'User-Agent': 'python-requests/2.23.0', 'Accept-Encoding': 'gzip, deflate', 'Accept': '*/*', 'Connection': 'keep-alive', 'Content-MD5': 'aHPCOiOB0VJCSesalIpFpQ==', 'Content-Type': 'application/json', 'Content-Length': '609'}
2024-01-30 16:17:31,795 ERROR   wandb-upload_2:1134330 [internal_api.py:upload_file():2769] upload_file response body: 
2024-01-30 16:17:32,055 DEBUG   HandlerThread:1134330 [handler.py:handle_request():146] handle_request: keepalive
2024-01-30 16:17:37,058 DEBUG   HandlerThread:1134330 [handler.py:handle_request():146] handle_request: keepalive
2024-01-30 16:17:42,060 DEBUG   HandlerThread:1134330 [handler.py:handle_request():146] handle_request: keepalive
2024-01-30 16:17:47,063 DEBUG   HandlerThread:1134330 [handler.py:handle_request():146] handle_request: keepalive
2024-01-30 16:17:52,065 DEBUG   HandlerThread:1134330 [handler.py:handle_request():146] handle_request: keepalive
2024-01-30 16:20:41,768 ERROR   wandb-upload_0:1134330 [internal_api.py:upload_file():2765] upload_file exception https://storage.googleapis.com/wandb-production.appspot.com/dynamic_x/bert_pytorch/87yhbfo2/wandb-metadata.json?Expires=1706688636&GoogleAccessId=gorilla-files-url-signer-man%40wandb-production.iam.gserviceaccount.com&Signature=i6ygl6e%2F1NTaK6CPvF0NXZCkqswXBKlbsIAlDONRJsh%2B3x8JGZM%2F%2F23d4nP224TGJJG%2FCwEhFPdSuwxqSBYHv%2By9Ud6qOPv71v5oMy3xjK95cP8S5aO5KfCrnKtrIOmrXhlAhzuwVq6uvAKGfNqgQD6MEyp8CsvfEfy7pGsDDEXhj40LUnzeh4v3UzcU9ErrNfA3%2Fisa1FmirWu%2FkUcHDNpTeHVwdhLMUqnr5fYBL47fFxTQFwVRLqi9eHGGatIhaAP0mH%2BbS54b2T7CtyGpcXkoRBRSTcKBdvyiBiPDGie7PGw9Xsb6h0zFIIHbjehEtC3Q24GdjVu1TNNGFHYb3w%3D%3D: HTTPSConnectionPool(host='storage.googleapis.com', port=443): Max retries exceeded with url: /wandb-production.appspot.com/dynamic_x/bert_pytorch/87yhbfo2/wandb-metadata.json?Expires=1706688636&GoogleAccessId=gorilla-files-url-signer-man%40wandb-production.iam.gserviceaccount.com&Signature=i6ygl6e%2F1NTaK6CPvF0NXZCkqswXBKlbsIAlDONRJsh%2B3x8JGZM%2F%2F23d4nP224TGJJG%2FCwEhFPdSuwxqSBYHv%2By9Ud6qOPv71v5oMy3xjK95cP8S5aO5KfCrnKtrIOmrXhlAhzuwVq6uvAKGfNqgQD6MEyp8CsvfEfy7pGsDDEXhj40LUnzeh4v3UzcU9ErrNfA3%2Fisa1FmirWu%2FkUcHDNpTeHVwdhLMUqnr5fYBL47fFxTQFwVRLqi9eHGGatIhaAP0mH%2BbS54b2T7CtyGpcXkoRBRSTcKBdvyiBiPDGie7PGw9Xsb6h0zFIIHbjehEtC3Q24GdjVu1TNNGFHYb3w%3D%3D (Caused by NewConnectionError('<urllib3.connection.HTTPSConnection object at 0x7f8578f91400>: Failed to establish a new connection: [Errno 101] Network is unreachable'))
2024-01-30 16:20:41,768 ERROR   wandb-upload_0:1134330 [internal_api.py:upload_file():2767] upload_file request headers: {'User-Agent': 'python-requests/2.23.0', 'Accept-Encoding': 'gzip, deflate', 'Accept': '*/*', 'Connection': 'keep-alive', 'Content-Length': '15551'}
2024-01-30 16:20:41,768 ERROR   wandb-upload_0:1134330 [internal_api.py:upload_file():2769] upload_file response body: 
2024-01-30 16:26:49,695 ERROR   wandb-upload_0:1134330 [internal_api.py:upload_file():2765] upload_file exception https://storage.googleapis.com/wandb-production.appspot.com/dynamic_x/bert_pytorch/87yhbfo2/wandb-metadata.json?Expires=1706688636&GoogleAccessId=gorilla-files-url-signer-man%40wandb-production.iam.gserviceaccount.com&Signature=i6ygl6e%2F1NTaK6CPvF0NXZCkqswXBKlbsIAlDONRJsh%2B3x8JGZM%2F%2F23d4nP224TGJJG%2FCwEhFPdSuwxqSBYHv%2By9Ud6qOPv71v5oMy3xjK95cP8S5aO5KfCrnKtrIOmrXhlAhzuwVq6uvAKGfNqgQD6MEyp8CsvfEfy7pGsDDEXhj40LUnzeh4v3UzcU9ErrNfA3%2Fisa1FmirWu%2FkUcHDNpTeHVwdhLMUqnr5fYBL47fFxTQFwVRLqi9eHGGatIhaAP0mH%2BbS54b2T7CtyGpcXkoRBRSTcKBdvyiBiPDGie7PGw9Xsb6h0zFIIHbjehEtC3Q24GdjVu1TNNGFHYb3w%3D%3D: HTTPSConnectionPool(host='storage.googleapis.com', port=443): Max retries exceeded with url: /wandb-production.appspot.com/dynamic_x/bert_pytorch/87yhbfo2/wandb-metadata.json?Expires=1706688636&GoogleAccessId=gorilla-files-url-signer-man%40wandb-production.iam.gserviceaccount.com&Signature=i6ygl6e%2F1NTaK6CPvF0NXZCkqswXBKlbsIAlDONRJsh%2B3x8JGZM%2F%2F23d4nP224TGJJG%2FCwEhFPdSuwxqSBYHv%2By9Ud6qOPv71v5oMy3xjK95cP8S5aO5KfCrnKtrIOmrXhlAhzuwVq6uvAKGfNqgQD6MEyp8CsvfEfy7pGsDDEXhj40LUnzeh4v3UzcU9ErrNfA3%2Fisa1FmirWu%2FkUcHDNpTeHVwdhLMUqnr5fYBL47fFxTQFwVRLqi9eHGGatIhaAP0mH%2BbS54b2T7CtyGpcXkoRBRSTcKBdvyiBiPDGie7PGw9Xsb6h0zFIIHbjehEtC3Q24GdjVu1TNNGFHYb3w%3D%3D (Caused by NewConnectionError('<urllib3.connection.HTTPSConnection object at 0x7f859801e370>: Failed to establish a new connection: [Errno 111] Connection refused'))
2024-01-30 16:26:49,695 ERROR   wandb-upload_0:1134330 [internal_api.py:upload_file():2767] upload_file request headers: {'User-Agent': 'python-requests/2.23.0', 'Accept-Encoding': 'gzip, deflate', 'Accept': '*/*', 'Connection': 'keep-alive', 'Content-Length': '15551'}
2024-01-30 16:26:49,695 ERROR   wandb-upload_0:1134330 [internal_api.py:upload_file():2769] upload_file response body: 
2024-01-30 16:33:02,018 ERROR   wandb-upload_0:1134330 [internal_api.py:upload_file():2765] upload_file exception https://storage.googleapis.com/wandb-production.appspot.com/dynamic_x/bert_pytorch/87yhbfo2/wandb-metadata.json?Expires=1706688636&GoogleAccessId=gorilla-files-url-signer-man%40wandb-production.iam.gserviceaccount.com&Signature=i6ygl6e%2F1NTaK6CPvF0NXZCkqswXBKlbsIAlDONRJsh%2B3x8JGZM%2F%2F23d4nP224TGJJG%2FCwEhFPdSuwxqSBYHv%2By9Ud6qOPv71v5oMy3xjK95cP8S5aO5KfCrnKtrIOmrXhlAhzuwVq6uvAKGfNqgQD6MEyp8CsvfEfy7pGsDDEXhj40LUnzeh4v3UzcU9ErrNfA3%2Fisa1FmirWu%2FkUcHDNpTeHVwdhLMUqnr5fYBL47fFxTQFwVRLqi9eHGGatIhaAP0mH%2BbS54b2T7CtyGpcXkoRBRSTcKBdvyiBiPDGie7PGw9Xsb6h0zFIIHbjehEtC3Q24GdjVu1TNNGFHYb3w%3D%3D: HTTPSConnectionPool(host='storage.googleapis.com', port=443): Max retries exceeded with url: /wandb-production.appspot.com/dynamic_x/bert_pytorch/87yhbfo2/wandb-metadata.json?Expires=1706688636&GoogleAccessId=gorilla-files-url-signer-man%40wandb-production.iam.gserviceaccount.com&Signature=i6ygl6e%2F1NTaK6CPvF0NXZCkqswXBKlbsIAlDONRJsh%2B3x8JGZM%2F%2F23d4nP224TGJJG%2FCwEhFPdSuwxqSBYHv%2By9Ud6qOPv71v5oMy3xjK95cP8S5aO5KfCrnKtrIOmrXhlAhzuwVq6uvAKGfNqgQD6MEyp8CsvfEfy7pGsDDEXhj40LUnzeh4v3UzcU9ErrNfA3%2Fisa1FmirWu%2FkUcHDNpTeHVwdhLMUqnr5fYBL47fFxTQFwVRLqi9eHGGatIhaAP0mH%2BbS54b2T7CtyGpcXkoRBRSTcKBdvyiBiPDGie7PGw9Xsb6h0zFIIHbjehEtC3Q24GdjVu1TNNGFHYb3w%3D%3D (Caused by NewConnectionError('<urllib3.connection.HTTPSConnection object at 0x7f859815b190>: Failed to establish a new connection: [Errno 111] Connection refused'))
2024-01-30 16:33:02,019 ERROR   wandb-upload_0:1134330 [internal_api.py:upload_file():2767] upload_file request headers: {'User-Agent': 'python-requests/2.23.0', 'Accept-Encoding': 'gzip, deflate', 'Accept': '*/*', 'Connection': 'keep-alive', 'Content-Length': '15551'}
2024-01-30 16:33:02,019 ERROR   wandb-upload_0:1134330 [internal_api.py:upload_file():2769] upload_file response body: 
2024-01-30 16:37:45,404 WARNING StreamThr :1134330 [internal.py:is_dead():414] Internal process exiting, parent pid 1134043 disappeared
2024-01-30 16:37:45,404 ERROR   StreamThr :1134330 [internal.py:wandb_internal():152] Internal process shutdown.
2024-01-30 16:37:46,143 INFO    WriterThread:1134330 [datastore.py:close():296] close: /home/yanxindong/mkor/bert/wandb/run-20240130_161012-87yhbfo2/run-87yhbfo2.wandb
2024-01-30 16:37:46,171 INFO    HandlerThread:1134330 [handler.py:finish():869] shutting down handler
2024-01-30 16:38:54,589 ERROR   wandb-upload_0:1134330 [internal_api.py:upload_file():2765] upload_file exception https://storage.googleapis.com/wandb-production.appspot.com/dynamic_x/bert_pytorch/87yhbfo2/wandb-metadata.json?Expires=1706688636&GoogleAccessId=gorilla-files-url-signer-man%40wandb-production.iam.gserviceaccount.com&Signature=i6ygl6e%2F1NTaK6CPvF0NXZCkqswXBKlbsIAlDONRJsh%2B3x8JGZM%2F%2F23d4nP224TGJJG%2FCwEhFPdSuwxqSBYHv%2By9Ud6qOPv71v5oMy3xjK95cP8S5aO5KfCrnKtrIOmrXhlAhzuwVq6uvAKGfNqgQD6MEyp8CsvfEfy7pGsDDEXhj40LUnzeh4v3UzcU9ErrNfA3%2Fisa1FmirWu%2FkUcHDNpTeHVwdhLMUqnr5fYBL47fFxTQFwVRLqi9eHGGatIhaAP0mH%2BbS54b2T7CtyGpcXkoRBRSTcKBdvyiBiPDGie7PGw9Xsb6h0zFIIHbjehEtC3Q24GdjVu1TNNGFHYb3w%3D%3D: HTTPSConnectionPool(host='storage.googleapis.com', port=443): Max retries exceeded with url: /wandb-production.appspot.com/dynamic_x/bert_pytorch/87yhbfo2/wandb-metadata.json?Expires=1706688636&GoogleAccessId=gorilla-files-url-signer-man%40wandb-production.iam.gserviceaccount.com&Signature=i6ygl6e%2F1NTaK6CPvF0NXZCkqswXBKlbsIAlDONRJsh%2B3x8JGZM%2F%2F23d4nP224TGJJG%2FCwEhFPdSuwxqSBYHv%2By9Ud6qOPv71v5oMy3xjK95cP8S5aO5KfCrnKtrIOmrXhlAhzuwVq6uvAKGfNqgQD6MEyp8CsvfEfy7pGsDDEXhj40LUnzeh4v3UzcU9ErrNfA3%2Fisa1FmirWu%2FkUcHDNpTeHVwdhLMUqnr5fYBL47fFxTQFwVRLqi9eHGGatIhaAP0mH%2BbS54b2T7CtyGpcXkoRBRSTcKBdvyiBiPDGie7PGw9Xsb6h0zFIIHbjehEtC3Q24GdjVu1TNNGFHYb3w%3D%3D (Caused by NewConnectionError('<urllib3.connection.HTTPSConnection object at 0x7f8578f91940>: Failed to establish a new connection: [Errno 111] Connection refused'))
2024-01-30 16:38:54,590 ERROR   wandb-upload_0:1134330 [internal_api.py:upload_file():2767] upload_file request headers: {'User-Agent': 'python-requests/2.23.0', 'Accept-Encoding': 'gzip, deflate', 'Accept': '*/*', 'Connection': 'keep-alive', 'Content-Length': '15551'}
2024-01-30 16:38:54,590 ERROR   wandb-upload_0:1134330 [internal_api.py:upload_file():2769] upload_file response body: 
2024-01-30 16:40:31,478 ERROR   wandb-upload_1:1134330 [internal_api.py:upload_file():2765] upload_file exception https://storage.googleapis.com/wandb-artifacts-prod/wandb_artifacts/133981200/707680476/174a3d9bc61fec126cc7d5bdff5c6c5a?Expires=1706688978&GoogleAccessId=gorilla-files-url-signer-man%40wandb-production.iam.gserviceaccount.com&Signature=K7H67UT394ZxkY38h5LLo7qstPxKv9DSLuAIJ%2BawMnvSiLlI76Ar1VipqXQ9pE2svxdbUoX5nmTEq7htyjyogM9hI2e%2BbXLJ3PoZ%2BriOYuitZhYGSJttcVAQw6Vj29UhAQJwY1H8R795pIZVRYna6cwp6vWgd71BUO07graO60iA5ovSG0hXC58DfrZgygvrTFXYZ4iKDeZ57uzYZ4%2B%2FkGEwaXYePNjphjRm5Ev9U7uBwbYTRr7X%2BaGwd5Uz0P5iNB0W1al7TBPBUIvguYcJST90PRLbxcOY3kltbxzaPXOkec3duvGtMxzCsmXn7fHJTvyNNIWDCMGQBex2WaNEng%3D%3D: HTTPSConnectionPool(host='storage.googleapis.com', port=443): Max retries exceeded with url: /wandb-artifacts-prod/wandb_artifacts/133981200/707680476/174a3d9bc61fec126cc7d5bdff5c6c5a?Expires=1706688978&GoogleAccessId=gorilla-files-url-signer-man%40wandb-production.iam.gserviceaccount.com&Signature=K7H67UT394ZxkY38h5LLo7qstPxKv9DSLuAIJ%2BawMnvSiLlI76Ar1VipqXQ9pE2svxdbUoX5nmTEq7htyjyogM9hI2e%2BbXLJ3PoZ%2BriOYuitZhYGSJttcVAQw6Vj29UhAQJwY1H8R795pIZVRYna6cwp6vWgd71BUO07graO60iA5ovSG0hXC58DfrZgygvrTFXYZ4iKDeZ57uzYZ4%2B%2FkGEwaXYePNjphjRm5Ev9U7uBwbYTRr7X%2BaGwd5Uz0P5iNB0W1al7TBPBUIvguYcJST90PRLbxcOY3kltbxzaPXOkec3duvGtMxzCsmXn7fHJTvyNNIWDCMGQBex2WaNEng%3D%3D (Caused by NewConnectionError('<urllib3.connection.HTTPSConnection object at 0x7f8578f7f520>: Failed to establish a new connection: [Errno 101] Network is unreachable'))
2024-01-30 16:40:31,478 ERROR   wandb-upload_1:1134330 [internal_api.py:upload_file():2767] upload_file request headers: {'User-Agent': 'python-requests/2.23.0', 'Accept-Encoding': 'gzip, deflate', 'Accept': '*/*', 'Connection': 'keep-alive', 'Content-MD5': 'F0o9m8Yf7BJsx9W9/1xsWg==', 'Content-Type': 'text/plain; charset=utf-8', 'Content-Length': '2179'}
2024-01-30 16:40:31,478 ERROR   wandb-upload_1:1134330 [internal_api.py:upload_file():2769] upload_file response body: 
2024-01-30 16:40:39,670 ERROR   wandb-upload_2:1134330 [internal_api.py:upload_file():2765] upload_file exception https://storage.googleapis.com/wandb-artifacts-prod/wandb_artifacts/133981200/707680476/6873c23a2381d1524249eb1a948a45a5?Expires=1706688978&GoogleAccessId=gorilla-files-url-signer-man%40wandb-production.iam.gserviceaccount.com&Signature=FJbunGpfeOQfbKn542AGPFUBcBVQErMSPGikGCa0aecFeElbpWRcwkiz4wMxZgu6SOi89%2BydcFZipV2Ca52hCBN6z6HQ%2FWNmhJfUfy8OfSxKUOEfnm%2FacOCYZumigHY8XXWV14q%2BIE%2BSXX5UKop3Oygpq2XwB4kUAVTF1xiWGV9J82N5lexioy35TMM0M3fpZVNTLjBkETzKCAah3YICcTldU0r9Cj%2BKrfTDZRT1nd9nHIsEuOMP8GR1dBD958dC5j5Onja4PEXVcvyHXBgveCtHVX7unpWD6GCcrTs2tj5x5W2cpsRNemTkFrzKs%2FQMT3832Dv7Gt5Sw0Hkmzwuvg%3D%3D: HTTPSConnectionPool(host='storage.googleapis.com', port=443): Max retries exceeded with url: /wandb-artifacts-prod/wandb_artifacts/133981200/707680476/6873c23a2381d1524249eb1a948a45a5?Expires=1706688978&GoogleAccessId=gorilla-files-url-signer-man%40wandb-production.iam.gserviceaccount.com&Signature=FJbunGpfeOQfbKn542AGPFUBcBVQErMSPGikGCa0aecFeElbpWRcwkiz4wMxZgu6SOi89%2BydcFZipV2Ca52hCBN6z6HQ%2FWNmhJfUfy8OfSxKUOEfnm%2FacOCYZumigHY8XXWV14q%2BIE%2BSXX5UKop3Oygpq2XwB4kUAVTF1xiWGV9J82N5lexioy35TMM0M3fpZVNTLjBkETzKCAah3YICcTldU0r9Cj%2BKrfTDZRT1nd9nHIsEuOMP8GR1dBD958dC5j5Onja4PEXVcvyHXBgveCtHVX7unpWD6GCcrTs2tj5x5W2cpsRNemTkFrzKs%2FQMT3832Dv7Gt5Sw0Hkmzwuvg%3D%3D (Caused by NewConnectionError('<urllib3.connection.HTTPSConnection object at 0x7f8578f7f790>: Failed to establish a new connection: [Errno 101] Network is unreachable'))
2024-01-30 16:40:39,670 ERROR   wandb-upload_2:1134330 [internal_api.py:upload_file():2767] upload_file request headers: {'User-Agent': 'python-requests/2.23.0', 'Accept-Encoding': 'gzip, deflate', 'Accept': '*/*', 'Connection': 'keep-alive', 'Content-MD5': 'aHPCOiOB0VJCSesalIpFpQ==', 'Content-Type': 'application/json', 'Content-Length': '609'}
2024-01-30 16:40:39,670 ERROR   wandb-upload_2:1134330 [internal_api.py:upload_file():2769] upload_file response body: 
2024-01-30 16:42:51,640 ERROR   wandb-upload_1:1134330 [internal_api.py:upload_file():2765] upload_file exception https://storage.googleapis.com/wandb-artifacts-prod/wandb_artifacts/133981200/707680476/174a3d9bc61fec126cc7d5bdff5c6c5a?Expires=1706688978&GoogleAccessId=gorilla-files-url-signer-man%40wandb-production.iam.gserviceaccount.com&Signature=K7H67UT394ZxkY38h5LLo7qstPxKv9DSLuAIJ%2BawMnvSiLlI76Ar1VipqXQ9pE2svxdbUoX5nmTEq7htyjyogM9hI2e%2BbXLJ3PoZ%2BriOYuitZhYGSJttcVAQw6Vj29UhAQJwY1H8R795pIZVRYna6cwp6vWgd71BUO07graO60iA5ovSG0hXC58DfrZgygvrTFXYZ4iKDeZ57uzYZ4%2B%2FkGEwaXYePNjphjRm5Ev9U7uBwbYTRr7X%2BaGwd5Uz0P5iNB0W1al7TBPBUIvguYcJST90PRLbxcOY3kltbxzaPXOkec3duvGtMxzCsmXn7fHJTvyNNIWDCMGQBex2WaNEng%3D%3D: HTTPSConnectionPool(host='storage.googleapis.com', port=443): Max retries exceeded with url: /wandb-artifacts-prod/wandb_artifacts/133981200/707680476/174a3d9bc61fec126cc7d5bdff5c6c5a?Expires=1706688978&GoogleAccessId=gorilla-files-url-signer-man%40wandb-production.iam.gserviceaccount.com&Signature=K7H67UT394ZxkY38h5LLo7qstPxKv9DSLuAIJ%2BawMnvSiLlI76Ar1VipqXQ9pE2svxdbUoX5nmTEq7htyjyogM9hI2e%2BbXLJ3PoZ%2BriOYuitZhYGSJttcVAQw6Vj29UhAQJwY1H8R795pIZVRYna6cwp6vWgd71BUO07graO60iA5ovSG0hXC58DfrZgygvrTFXYZ4iKDeZ57uzYZ4%2B%2FkGEwaXYePNjphjRm5Ev9U7uBwbYTRr7X%2BaGwd5Uz0P5iNB0W1al7TBPBUIvguYcJST90PRLbxcOY3kltbxzaPXOkec3duvGtMxzCsmXn7fHJTvyNNIWDCMGQBex2WaNEng%3D%3D (Caused by NewConnectionError('<urllib3.connection.HTTPSConnection object at 0x7f8578f7d4c0>: Failed to establish a new connection: [Errno 101] Network is unreachable'))
2024-01-30 16:42:51,640 ERROR   wandb-upload_1:1134330 [internal_api.py:upload_file():2767] upload_file request headers: {'User-Agent': 'python-requests/2.23.0', 'Accept-Encoding': 'gzip, deflate', 'Accept': '*/*', 'Connection': 'keep-alive', 'Content-MD5': 'F0o9m8Yf7BJsx9W9/1xsWg==', 'Content-Type': 'text/plain; charset=utf-8', 'Content-Length': '2179'}
2024-01-30 16:42:51,640 ERROR   wandb-upload_1:1134330 [internal_api.py:upload_file():2769] upload_file response body: 
2024-01-30 16:42:54,140 ERROR   wandb-upload_2:1134330 [internal_api.py:upload_file():2765] upload_file exception https://storage.googleapis.com/wandb-artifacts-prod/wandb_artifacts/133981200/707680476/6873c23a2381d1524249eb1a948a45a5?Expires=1706688978&GoogleAccessId=gorilla-files-url-signer-man%40wandb-production.iam.gserviceaccount.com&Signature=FJbunGpfeOQfbKn542AGPFUBcBVQErMSPGikGCa0aecFeElbpWRcwkiz4wMxZgu6SOi89%2BydcFZipV2Ca52hCBN6z6HQ%2FWNmhJfUfy8OfSxKUOEfnm%2FacOCYZumigHY8XXWV14q%2BIE%2BSXX5UKop3Oygpq2XwB4kUAVTF1xiWGV9J82N5lexioy35TMM0M3fpZVNTLjBkETzKCAah3YICcTldU0r9Cj%2BKrfTDZRT1nd9nHIsEuOMP8GR1dBD958dC5j5Onja4PEXVcvyHXBgveCtHVX7unpWD6GCcrTs2tj5x5W2cpsRNemTkFrzKs%2FQMT3832Dv7Gt5Sw0Hkmzwuvg%3D%3D: HTTPSConnectionPool(host='storage.googleapis.com', port=443): Max retries exceeded with url: /wandb-artifacts-prod/wandb_artifacts/133981200/707680476/6873c23a2381d1524249eb1a948a45a5?Expires=1706688978&GoogleAccessId=gorilla-files-url-signer-man%40wandb-production.iam.gserviceaccount.com&Signature=FJbunGpfeOQfbKn542AGPFUBcBVQErMSPGikGCa0aecFeElbpWRcwkiz4wMxZgu6SOi89%2BydcFZipV2Ca52hCBN6z6HQ%2FWNmhJfUfy8OfSxKUOEfnm%2FacOCYZumigHY8XXWV14q%2BIE%2BSXX5UKop3Oygpq2XwB4kUAVTF1xiWGV9J82N5lexioy35TMM0M3fpZVNTLjBkETzKCAah3YICcTldU0r9Cj%2BKrfTDZRT1nd9nHIsEuOMP8GR1dBD958dC5j5Onja4PEXVcvyHXBgveCtHVX7unpWD6GCcrTs2tj5x5W2cpsRNemTkFrzKs%2FQMT3832Dv7Gt5Sw0Hkmzwuvg%3D%3D (Caused by NewConnectionError('<urllib3.connection.HTTPSConnection object at 0x7f8578f7de80>: Failed to establish a new connection: [Errno 101] Network is unreachable'))
2024-01-30 16:42:54,140 ERROR   wandb-upload_2:1134330 [internal_api.py:upload_file():2767] upload_file request headers: {'User-Agent': 'python-requests/2.23.0', 'Accept-Encoding': 'gzip, deflate', 'Accept': '*/*', 'Connection': 'keep-alive', 'Content-MD5': 'aHPCOiOB0VJCSesalIpFpQ==', 'Content-Type': 'application/json', 'Content-Length': '609'}
2024-01-30 16:42:54,141 ERROR   wandb-upload_2:1134330 [internal_api.py:upload_file():2769] upload_file response body: 
2024-01-30 16:44:08,034 ERROR   wandb-upload_0:1134330 [internal_api.py:upload_file():2765] upload_file exception https://storage.googleapis.com/wandb-production.appspot.com/dynamic_x/bert_pytorch/87yhbfo2/wandb-metadata.json?Expires=1706688636&GoogleAccessId=gorilla-files-url-signer-man%40wandb-production.iam.gserviceaccount.com&Signature=i6ygl6e%2F1NTaK6CPvF0NXZCkqswXBKlbsIAlDONRJsh%2B3x8JGZM%2F%2F23d4nP224TGJJG%2FCwEhFPdSuwxqSBYHv%2By9Ud6qOPv71v5oMy3xjK95cP8S5aO5KfCrnKtrIOmrXhlAhzuwVq6uvAKGfNqgQD6MEyp8CsvfEfy7pGsDDEXhj40LUnzeh4v3UzcU9ErrNfA3%2Fisa1FmirWu%2FkUcHDNpTeHVwdhLMUqnr5fYBL47fFxTQFwVRLqi9eHGGatIhaAP0mH%2BbS54b2T7CtyGpcXkoRBRSTcKBdvyiBiPDGie7PGw9Xsb6h0zFIIHbjehEtC3Q24GdjVu1TNNGFHYb3w%3D%3D: HTTPSConnectionPool(host='storage.googleapis.com', port=443): Max retries exceeded with url: /wandb-production.appspot.com/dynamic_x/bert_pytorch/87yhbfo2/wandb-metadata.json?Expires=1706688636&GoogleAccessId=gorilla-files-url-signer-man%40wandb-production.iam.gserviceaccount.com&Signature=i6ygl6e%2F1NTaK6CPvF0NXZCkqswXBKlbsIAlDONRJsh%2B3x8JGZM%2F%2F23d4nP224TGJJG%2FCwEhFPdSuwxqSBYHv%2By9Ud6qOPv71v5oMy3xjK95cP8S5aO5KfCrnKtrIOmrXhlAhzuwVq6uvAKGfNqgQD6MEyp8CsvfEfy7pGsDDEXhj40LUnzeh4v3UzcU9ErrNfA3%2Fisa1FmirWu%2FkUcHDNpTeHVwdhLMUqnr5fYBL47fFxTQFwVRLqi9eHGGatIhaAP0mH%2BbS54b2T7CtyGpcXkoRBRSTcKBdvyiBiPDGie7PGw9Xsb6h0zFIIHbjehEtC3Q24GdjVu1TNNGFHYb3w%3D%3D (Caused by NewConnectionError('<urllib3.connection.HTTPSConnection object at 0x7f859811bf70>: Failed to establish a new connection: [Errno 101] Network is unreachable'))
2024-01-30 16:44:08,035 ERROR   wandb-upload_0:1134330 [internal_api.py:upload_file():2767] upload_file request headers: {'User-Agent': 'python-requests/2.23.0', 'Accept-Encoding': 'gzip, deflate', 'Accept': '*/*', 'Connection': 'keep-alive', 'Content-Length': '15551'}
2024-01-30 16:44:08,035 ERROR   wandb-upload_0:1134330 [internal_api.py:upload_file():2769] upload_file response body: 
2024-01-30 16:49:48,421 ERROR   wandb-upload_0:1134330 [internal_api.py:upload_file():2765] upload_file exception https://storage.googleapis.com/wandb-production.appspot.com/dynamic_x/bert_pytorch/87yhbfo2/wandb-metadata.json?Expires=1706688636&GoogleAccessId=gorilla-files-url-signer-man%40wandb-production.iam.gserviceaccount.com&Signature=i6ygl6e%2F1NTaK6CPvF0NXZCkqswXBKlbsIAlDONRJsh%2B3x8JGZM%2F%2F23d4nP224TGJJG%2FCwEhFPdSuwxqSBYHv%2By9Ud6qOPv71v5oMy3xjK95cP8S5aO5KfCrnKtrIOmrXhlAhzuwVq6uvAKGfNqgQD6MEyp8CsvfEfy7pGsDDEXhj40LUnzeh4v3UzcU9ErrNfA3%2Fisa1FmirWu%2FkUcHDNpTeHVwdhLMUqnr5fYBL47fFxTQFwVRLqi9eHGGatIhaAP0mH%2BbS54b2T7CtyGpcXkoRBRSTcKBdvyiBiPDGie7PGw9Xsb6h0zFIIHbjehEtC3Q24GdjVu1TNNGFHYb3w%3D%3D: HTTPSConnectionPool(host='storage.googleapis.com', port=443): Max retries exceeded with url: /wandb-production.appspot.com/dynamic_x/bert_pytorch/87yhbfo2/wandb-metadata.json?Expires=1706688636&GoogleAccessId=gorilla-files-url-signer-man%40wandb-production.iam.gserviceaccount.com&Signature=i6ygl6e%2F1NTaK6CPvF0NXZCkqswXBKlbsIAlDONRJsh%2B3x8JGZM%2F%2F23d4nP224TGJJG%2FCwEhFPdSuwxqSBYHv%2By9Ud6qOPv71v5oMy3xjK95cP8S5aO5KfCrnKtrIOmrXhlAhzuwVq6uvAKGfNqgQD6MEyp8CsvfEfy7pGsDDEXhj40LUnzeh4v3UzcU9ErrNfA3%2Fisa1FmirWu%2FkUcHDNpTeHVwdhLMUqnr5fYBL47fFxTQFwVRLqi9eHGGatIhaAP0mH%2BbS54b2T7CtyGpcXkoRBRSTcKBdvyiBiPDGie7PGw9Xsb6h0zFIIHbjehEtC3Q24GdjVu1TNNGFHYb3w%3D%3D (Caused by NewConnectionError('<urllib3.connection.HTTPSConnection object at 0x7f8578f7fd60>: Failed to establish a new connection: [Errno 111] Connection refused'))
2024-01-30 16:49:48,421 ERROR   wandb-upload_0:1134330 [internal_api.py:upload_file():2767] upload_file request headers: {'User-Agent': 'python-requests/2.23.0', 'Accept-Encoding': 'gzip, deflate', 'Accept': '*/*', 'Connection': 'keep-alive', 'Content-Length': '15551'}
2024-01-30 16:49:48,421 ERROR   wandb-upload_0:1134330 [internal_api.py:upload_file():2769] upload_file response body: 
2024-01-30 16:55:46,524 ERROR   wandb-upload_0:1134330 [internal_api.py:upload_file():2765] upload_file exception https://storage.googleapis.com/wandb-production.appspot.com/dynamic_x/bert_pytorch/87yhbfo2/wandb-metadata.json?Expires=1706688636&GoogleAccessId=gorilla-files-url-signer-man%40wandb-production.iam.gserviceaccount.com&Signature=i6ygl6e%2F1NTaK6CPvF0NXZCkqswXBKlbsIAlDONRJsh%2B3x8JGZM%2F%2F23d4nP224TGJJG%2FCwEhFPdSuwxqSBYHv%2By9Ud6qOPv71v5oMy3xjK95cP8S5aO5KfCrnKtrIOmrXhlAhzuwVq6uvAKGfNqgQD6MEyp8CsvfEfy7pGsDDEXhj40LUnzeh4v3UzcU9ErrNfA3%2Fisa1FmirWu%2FkUcHDNpTeHVwdhLMUqnr5fYBL47fFxTQFwVRLqi9eHGGatIhaAP0mH%2BbS54b2T7CtyGpcXkoRBRSTcKBdvyiBiPDGie7PGw9Xsb6h0zFIIHbjehEtC3Q24GdjVu1TNNGFHYb3w%3D%3D: HTTPSConnectionPool(host='storage.googleapis.com', port=443): Max retries exceeded with url: /wandb-production.appspot.com/dynamic_x/bert_pytorch/87yhbfo2/wandb-metadata.json?Expires=1706688636&GoogleAccessId=gorilla-files-url-signer-man%40wandb-production.iam.gserviceaccount.com&Signature=i6ygl6e%2F1NTaK6CPvF0NXZCkqswXBKlbsIAlDONRJsh%2B3x8JGZM%2F%2F23d4nP224TGJJG%2FCwEhFPdSuwxqSBYHv%2By9Ud6qOPv71v5oMy3xjK95cP8S5aO5KfCrnKtrIOmrXhlAhzuwVq6uvAKGfNqgQD6MEyp8CsvfEfy7pGsDDEXhj40LUnzeh4v3UzcU9ErrNfA3%2Fisa1FmirWu%2FkUcHDNpTeHVwdhLMUqnr5fYBL47fFxTQFwVRLqi9eHGGatIhaAP0mH%2BbS54b2T7CtyGpcXkoRBRSTcKBdvyiBiPDGie7PGw9Xsb6h0zFIIHbjehEtC3Q24GdjVu1TNNGFHYb3w%3D%3D (Caused by NewConnectionError('<urllib3.connection.HTTPSConnection object at 0x7f8578f923d0>: Failed to establish a new connection: [Errno 111] Connection refused'))
2024-01-30 16:55:46,524 ERROR   wandb-upload_0:1134330 [internal_api.py:upload_file():2767] upload_file request headers: {'User-Agent': 'python-requests/2.23.0', 'Accept-Encoding': 'gzip, deflate', 'Accept': '*/*', 'Connection': 'keep-alive', 'Content-Length': '15551'}
2024-01-30 16:55:46,524 ERROR   wandb-upload_0:1134330 [internal_api.py:upload_file():2769] upload_file response body: 
2024-01-30 17:11:33,110 ERROR   wandb-upload_1:1134330 [internal_api.py:upload_file():2765] upload_file exception https://storage.googleapis.com/wandb-artifacts-prod/wandb_artifacts/133981200/707680476/174a3d9bc61fec126cc7d5bdff5c6c5a?Expires=1706688978&GoogleAccessId=gorilla-files-url-signer-man%40wandb-production.iam.gserviceaccount.com&Signature=K7H67UT394ZxkY38h5LLo7qstPxKv9DSLuAIJ%2BawMnvSiLlI76Ar1VipqXQ9pE2svxdbUoX5nmTEq7htyjyogM9hI2e%2BbXLJ3PoZ%2BriOYuitZhYGSJttcVAQw6Vj29UhAQJwY1H8R795pIZVRYna6cwp6vWgd71BUO07graO60iA5ovSG0hXC58DfrZgygvrTFXYZ4iKDeZ57uzYZ4%2B%2FkGEwaXYePNjphjRm5Ev9U7uBwbYTRr7X%2BaGwd5Uz0P5iNB0W1al7TBPBUIvguYcJST90PRLbxcOY3kltbxzaPXOkec3duvGtMxzCsmXn7fHJTvyNNIWDCMGQBex2WaNEng%3D%3D: HTTPSConnectionPool(host='storage.googleapis.com', port=443): Max retries exceeded with url: /wandb-artifacts-prod/wandb_artifacts/133981200/707680476/174a3d9bc61fec126cc7d5bdff5c6c5a?Expires=1706688978&GoogleAccessId=gorilla-files-url-signer-man%40wandb-production.iam.gserviceaccount.com&Signature=K7H67UT394ZxkY38h5LLo7qstPxKv9DSLuAIJ%2BawMnvSiLlI76Ar1VipqXQ9pE2svxdbUoX5nmTEq7htyjyogM9hI2e%2BbXLJ3PoZ%2BriOYuitZhYGSJttcVAQw6Vj29UhAQJwY1H8R795pIZVRYna6cwp6vWgd71BUO07graO60iA5ovSG0hXC58DfrZgygvrTFXYZ4iKDeZ57uzYZ4%2B%2FkGEwaXYePNjphjRm5Ev9U7uBwbYTRr7X%2BaGwd5Uz0P5iNB0W1al7TBPBUIvguYcJST90PRLbxcOY3kltbxzaPXOkec3duvGtMxzCsmXn7fHJTvyNNIWDCMGQBex2WaNEng%3D%3D (Caused by NewConnectionError('<urllib3.connection.HTTPSConnection object at 0x7f8578f80580>: Failed to establish a new connection: [Errno 110] Connection timed out'))
2024-01-30 17:11:33,110 ERROR   wandb-upload_1:1134330 [internal_api.py:upload_file():2767] upload_file request headers: {'User-Agent': 'python-requests/2.23.0', 'Accept-Encoding': 'gzip, deflate', 'Accept': '*/*', 'Connection': 'keep-alive', 'Content-MD5': 'F0o9m8Yf7BJsx9W9/1xsWg==', 'Content-Type': 'text/plain; charset=utf-8', 'Content-Length': '2179'}
2024-01-30 17:11:33,110 ERROR   wandb-upload_1:1134330 [internal_api.py:upload_file():2769] upload_file response body: 
2024-01-30 17:11:43,350 ERROR   wandb-upload_2:1134330 [internal_api.py:upload_file():2765] upload_file exception https://storage.googleapis.com/wandb-artifacts-prod/wandb_artifacts/133981200/707680476/6873c23a2381d1524249eb1a948a45a5?Expires=1706688978&GoogleAccessId=gorilla-files-url-signer-man%40wandb-production.iam.gserviceaccount.com&Signature=FJbunGpfeOQfbKn542AGPFUBcBVQErMSPGikGCa0aecFeElbpWRcwkiz4wMxZgu6SOi89%2BydcFZipV2Ca52hCBN6z6HQ%2FWNmhJfUfy8OfSxKUOEfnm%2FacOCYZumigHY8XXWV14q%2BIE%2BSXX5UKop3Oygpq2XwB4kUAVTF1xiWGV9J82N5lexioy35TMM0M3fpZVNTLjBkETzKCAah3YICcTldU0r9Cj%2BKrfTDZRT1nd9nHIsEuOMP8GR1dBD958dC5j5Onja4PEXVcvyHXBgveCtHVX7unpWD6GCcrTs2tj5x5W2cpsRNemTkFrzKs%2FQMT3832Dv7Gt5Sw0Hkmzwuvg%3D%3D: HTTPSConnectionPool(host='storage.googleapis.com', port=443): Max retries exceeded with url: /wandb-artifacts-prod/wandb_artifacts/133981200/707680476/6873c23a2381d1524249eb1a948a45a5?Expires=1706688978&GoogleAccessId=gorilla-files-url-signer-man%40wandb-production.iam.gserviceaccount.com&Signature=FJbunGpfeOQfbKn542AGPFUBcBVQErMSPGikGCa0aecFeElbpWRcwkiz4wMxZgu6SOi89%2BydcFZipV2Ca52hCBN6z6HQ%2FWNmhJfUfy8OfSxKUOEfnm%2FacOCYZumigHY8XXWV14q%2BIE%2BSXX5UKop3Oygpq2XwB4kUAVTF1xiWGV9J82N5lexioy35TMM0M3fpZVNTLjBkETzKCAah3YICcTldU0r9Cj%2BKrfTDZRT1nd9nHIsEuOMP8GR1dBD958dC5j5Onja4PEXVcvyHXBgveCtHVX7unpWD6GCcrTs2tj5x5W2cpsRNemTkFrzKs%2FQMT3832Dv7Gt5Sw0Hkmzwuvg%3D%3D (Caused by NewConnectionError('<urllib3.connection.HTTPSConnection object at 0x7f8578f80880>: Failed to establish a new connection: [Errno 110] Connection timed out'))
2024-01-30 17:11:43,350 ERROR   wandb-upload_2:1134330 [internal_api.py:upload_file():2767] upload_file request headers: {'User-Agent': 'python-requests/2.23.0', 'Accept-Encoding': 'gzip, deflate', 'Accept': '*/*', 'Connection': 'keep-alive', 'Content-MD5': 'aHPCOiOB0VJCSesalIpFpQ==', 'Content-Type': 'application/json', 'Content-Length': '609'}
2024-01-30 17:11:43,350 ERROR   wandb-upload_2:1134330 [internal_api.py:upload_file():2769] upload_file response body: 
2024-01-30 17:16:46,070 ERROR   wandb-upload_1:1134330 [internal_api.py:upload_file():2765] upload_file exception https://storage.googleapis.com/wandb-artifacts-prod/wandb_artifacts/133981200/707680476/174a3d9bc61fec126cc7d5bdff5c6c5a?Expires=1706688978&GoogleAccessId=gorilla-files-url-signer-man%40wandb-production.iam.gserviceaccount.com&Signature=K7H67UT394ZxkY38h5LLo7qstPxKv9DSLuAIJ%2BawMnvSiLlI76Ar1VipqXQ9pE2svxdbUoX5nmTEq7htyjyogM9hI2e%2BbXLJ3PoZ%2BriOYuitZhYGSJttcVAQw6Vj29UhAQJwY1H8R795pIZVRYna6cwp6vWgd71BUO07graO60iA5ovSG0hXC58DfrZgygvrTFXYZ4iKDeZ57uzYZ4%2B%2FkGEwaXYePNjphjRm5Ev9U7uBwbYTRr7X%2BaGwd5Uz0P5iNB0W1al7TBPBUIvguYcJST90PRLbxcOY3kltbxzaPXOkec3duvGtMxzCsmXn7fHJTvyNNIWDCMGQBex2WaNEng%3D%3D: HTTPSConnectionPool(host='storage.googleapis.com', port=443): Max retries exceeded with url: /wandb-artifacts-prod/wandb_artifacts/133981200/707680476/174a3d9bc61fec126cc7d5bdff5c6c5a?Expires=1706688978&GoogleAccessId=gorilla-files-url-signer-man%40wandb-production.iam.gserviceaccount.com&Signature=K7H67UT394ZxkY38h5LLo7qstPxKv9DSLuAIJ%2BawMnvSiLlI76Ar1VipqXQ9pE2svxdbUoX5nmTEq7htyjyogM9hI2e%2BbXLJ3PoZ%2BriOYuitZhYGSJttcVAQw6Vj29UhAQJwY1H8R795pIZVRYna6cwp6vWgd71BUO07graO60iA5ovSG0hXC58DfrZgygvrTFXYZ4iKDeZ57uzYZ4%2B%2FkGEwaXYePNjphjRm5Ev9U7uBwbYTRr7X%2BaGwd5Uz0P5iNB0W1al7TBPBUIvguYcJST90PRLbxcOY3kltbxzaPXOkec3duvGtMxzCsmXn7fHJTvyNNIWDCMGQBex2WaNEng%3D%3D (Caused by NewConnectionError('<urllib3.connection.HTTPSConnection object at 0x7f85980621f0>: Failed to establish a new connection: [Errno 101] Network is unreachable'))
2024-01-30 17:16:46,070 ERROR   wandb-upload_1:1134330 [internal_api.py:upload_file():2767] upload_file request headers: {'User-Agent': 'python-requests/2.23.0', 'Accept-Encoding': 'gzip, deflate', 'Accept': '*/*', 'Connection': 'keep-alive', 'Content-MD5': 'F0o9m8Yf7BJsx9W9/1xsWg==', 'Content-Type': 'text/plain; charset=utf-8', 'Content-Length': '2179'}
2024-01-30 17:16:46,071 ERROR   wandb-upload_1:1134330 [internal_api.py:upload_file():2769] upload_file response body: 
2024-01-30 17:17:40,512 ERROR   wandb-upload_2:1134330 [internal_api.py:upload_file():2765] upload_file exception https://storage.googleapis.com/wandb-artifacts-prod/wandb_artifacts/133981200/707680476/6873c23a2381d1524249eb1a948a45a5?Expires=1706688978&GoogleAccessId=gorilla-files-url-signer-man%40wandb-production.iam.gserviceaccount.com&Signature=FJbunGpfeOQfbKn542AGPFUBcBVQErMSPGikGCa0aecFeElbpWRcwkiz4wMxZgu6SOi89%2BydcFZipV2Ca52hCBN6z6HQ%2FWNmhJfUfy8OfSxKUOEfnm%2FacOCYZumigHY8XXWV14q%2BIE%2BSXX5UKop3Oygpq2XwB4kUAVTF1xiWGV9J82N5lexioy35TMM0M3fpZVNTLjBkETzKCAah3YICcTldU0r9Cj%2BKrfTDZRT1nd9nHIsEuOMP8GR1dBD958dC5j5Onja4PEXVcvyHXBgveCtHVX7unpWD6GCcrTs2tj5x5W2cpsRNemTkFrzKs%2FQMT3832Dv7Gt5Sw0Hkmzwuvg%3D%3D: HTTPSConnectionPool(host='storage.googleapis.com', port=443): Max retries exceeded with url: /wandb-artifacts-prod/wandb_artifacts/133981200/707680476/6873c23a2381d1524249eb1a948a45a5?Expires=1706688978&GoogleAccessId=gorilla-files-url-signer-man%40wandb-production.iam.gserviceaccount.com&Signature=FJbunGpfeOQfbKn542AGPFUBcBVQErMSPGikGCa0aecFeElbpWRcwkiz4wMxZgu6SOi89%2BydcFZipV2Ca52hCBN6z6HQ%2FWNmhJfUfy8OfSxKUOEfnm%2FacOCYZumigHY8XXWV14q%2BIE%2BSXX5UKop3Oygpq2XwB4kUAVTF1xiWGV9J82N5lexioy35TMM0M3fpZVNTLjBkETzKCAah3YICcTldU0r9Cj%2BKrfTDZRT1nd9nHIsEuOMP8GR1dBD958dC5j5Onja4PEXVcvyHXBgveCtHVX7unpWD6GCcrTs2tj5x5W2cpsRNemTkFrzKs%2FQMT3832Dv7Gt5Sw0Hkmzwuvg%3D%3D (Caused by NewConnectionError('<urllib3.connection.HTTPSConnection object at 0x7f85980624c0>: Failed to establish a new connection: [Errno 101] Network is unreachable'))
2024-01-30 17:17:40,513 ERROR   wandb-upload_2:1134330 [internal_api.py:upload_file():2767] upload_file request headers: {'User-Agent': 'python-requests/2.23.0', 'Accept-Encoding': 'gzip, deflate', 'Accept': '*/*', 'Connection': 'keep-alive', 'Content-MD5': 'aHPCOiOB0VJCSesalIpFpQ==', 'Content-Type': 'application/json', 'Content-Length': '609'}
2024-01-30 17:17:40,513 ERROR   wandb-upload_2:1134330 [internal_api.py:upload_file():2769] upload_file response body: 
2024-01-30 17:22:13,915 INFO    wandb-upload_1:1134330 [upload_job.py:push():89] Uploaded file /home/yanxindong/.local/share/wandb/artifacts/staging/tmp5yx7cdm5
2024-01-30 17:23:18,425 INFO    wandb-upload_2:1134330 [upload_job.py:push():89] Uploaded file /home/yanxindong/.local/share/wandb/artifacts/staging/tmpy902b3dg
2024-01-30 17:23:21,723 INFO    SenderThread:1134330 [sender.py:send_artifact():1494] sent artifact job-https___github.com_kkkjj-d_mkor.git_bert_run_pretraining.py - {'id': 'QXJ0aWZhY3Q6NzA3NjgwNDc2', 'state': 'PENDING', 'artifactSequence': {'id': 'QXJ0aWZhY3RDb2xsZWN0aW9uOjEzMzk4MTIwMA==', 'latestArtifact': {'id': 'QXJ0aWZhY3Q6NzAzOTc3Mjk3', 'versionIndex': 8}}}
2024-01-30 17:23:21,723 INFO    SenderThread:1134330 [sender.py:finish():1572] shutting down sender
2024-01-30 17:23:21,723 INFO    SenderThread:1134330 [dir_watcher.py:finish():358] shutting down directory watcher
2024-01-30 17:23:22,669 INFO    SenderThread:1134330 [dir_watcher.py:finish():388] scan: /home/yanxindong/mkor/bert/wandb/run-20240130_161012-87yhbfo2/files
2024-01-30 17:23:22,670 INFO    SenderThread:1134330 [dir_watcher.py:finish():402] scan save: /home/yanxindong/mkor/bert/wandb/run-20240130_161012-87yhbfo2/files/wandb-summary.json wandb-summary.json
2024-01-30 17:23:22,670 INFO    SenderThread:1134330 [dir_watcher.py:finish():402] scan save: /home/yanxindong/mkor/bert/wandb/run-20240130_161012-87yhbfo2/files/conda-environment.yaml conda-environment.yaml
2024-01-30 17:23:22,670 INFO    SenderThread:1134330 [dir_watcher.py:finish():402] scan save: /home/yanxindong/mkor/bert/wandb/run-20240130_161012-87yhbfo2/files/wandb-metadata.json wandb-metadata.json
2024-01-30 17:23:22,671 INFO    SenderThread:1134330 [dir_watcher.py:finish():402] scan save: /home/yanxindong/mkor/bert/wandb/run-20240130_161012-87yhbfo2/files/output.log output.log
2024-01-30 17:23:22,680 INFO    SenderThread:1134330 [dir_watcher.py:finish():402] scan save: /home/yanxindong/mkor/bert/wandb/run-20240130_161012-87yhbfo2/files/requirements.txt requirements.txt
2024-01-30 17:23:22,680 INFO    SenderThread:1134330 [dir_watcher.py:finish():402] scan save: /home/yanxindong/mkor/bert/wandb/run-20240130_161012-87yhbfo2/files/config.yaml config.yaml
2024-01-30 17:23:22,680 INFO    SenderThread:1134330 [file_pusher.py:finish():175] shutting down file pusher
2024-01-30 17:23:22,680 INFO    SenderThread:1134330 [file_pusher.py:join():181] waiting for file pusher
2024-01-30 17:23:23,293 INFO    wandb-upload_2:1134330 [upload_job.py:push():131] Uploaded file /home/yanxindong/mkor/bert/wandb/run-20240130_161012-87yhbfo2/files/conda-environment.yaml
2024-01-30 17:23:23,685 INFO    wandb-upload_5:1134330 [upload_job.py:push():131] Uploaded file /home/yanxindong/mkor/bert/wandb/run-20240130_161012-87yhbfo2/files/config.yaml
2024-01-30 17:23:23,693 INFO    wandb-upload_4:1134330 [upload_job.py:push():131] Uploaded file /home/yanxindong/mkor/bert/wandb/run-20240130_161012-87yhbfo2/files/requirements.txt
2024-01-30 17:23:23,696 INFO    wandb-upload_3:1134330 [upload_job.py:push():131] Uploaded file /home/yanxindong/mkor/bert/wandb/run-20240130_161012-87yhbfo2/files/output.log
2024-01-30 17:23:24,485 INFO    wandb-upload_1:1134330 [upload_job.py:push():131] Uploaded file /home/yanxindong/mkor/bert/wandb/run-20240130_161012-87yhbfo2/files/wandb-summary.json
2024-01-30 17:25:04,117 ERROR   wandb-upload_0:1134330 [internal_api.py:upload_file():2765] upload_file exception https://storage.googleapis.com/wandb-production.appspot.com/dynamic_x/bert_pytorch/87yhbfo2/wandb-metadata.json?Expires=1706688636&GoogleAccessId=gorilla-files-url-signer-man%40wandb-production.iam.gserviceaccount.com&Signature=i6ygl6e%2F1NTaK6CPvF0NXZCkqswXBKlbsIAlDONRJsh%2B3x8JGZM%2F%2F23d4nP224TGJJG%2FCwEhFPdSuwxqSBYHv%2By9Ud6qOPv71v5oMy3xjK95cP8S5aO5KfCrnKtrIOmrXhlAhzuwVq6uvAKGfNqgQD6MEyp8CsvfEfy7pGsDDEXhj40LUnzeh4v3UzcU9ErrNfA3%2Fisa1FmirWu%2FkUcHDNpTeHVwdhLMUqnr5fYBL47fFxTQFwVRLqi9eHGGatIhaAP0mH%2BbS54b2T7CtyGpcXkoRBRSTcKBdvyiBiPDGie7PGw9Xsb6h0zFIIHbjehEtC3Q24GdjVu1TNNGFHYb3w%3D%3D: HTTPSConnectionPool(host='storage.googleapis.com', port=443): Max retries exceeded with url: /wandb-production.appspot.com/dynamic_x/bert_pytorch/87yhbfo2/wandb-metadata.json?Expires=1706688636&GoogleAccessId=gorilla-files-url-signer-man%40wandb-production.iam.gserviceaccount.com&Signature=i6ygl6e%2F1NTaK6CPvF0NXZCkqswXBKlbsIAlDONRJsh%2B3x8JGZM%2F%2F23d4nP224TGJJG%2FCwEhFPdSuwxqSBYHv%2By9Ud6qOPv71v5oMy3xjK95cP8S5aO5KfCrnKtrIOmrXhlAhzuwVq6uvAKGfNqgQD6MEyp8CsvfEfy7pGsDDEXhj40LUnzeh4v3UzcU9ErrNfA3%2Fisa1FmirWu%2FkUcHDNpTeHVwdhLMUqnr5fYBL47fFxTQFwVRLqi9eHGGatIhaAP0mH%2BbS54b2T7CtyGpcXkoRBRSTcKBdvyiBiPDGie7PGw9Xsb6h0zFIIHbjehEtC3Q24GdjVu1TNNGFHYb3w%3D%3D (Caused by NewConnectionError('<urllib3.connection.HTTPSConnection object at 0x7f859801e9d0>: Failed to establish a new connection: [Errno 101] Network is unreachable'))
2024-01-30 17:25:04,118 ERROR   wandb-upload_0:1134330 [internal_api.py:upload_file():2767] upload_file request headers: {'User-Agent': 'python-requests/2.23.0', 'Accept-Encoding': 'gzip, deflate', 'Accept': '*/*', 'Connection': 'keep-alive', 'Content-Length': '15551'}
2024-01-30 17:25:04,118 ERROR   wandb-upload_0:1134330 [internal_api.py:upload_file():2769] upload_file response body: 
2024-01-30 17:30:40,163 ERROR   wandb-upload_0:1134330 [internal_api.py:upload_file():2765] upload_file exception https://storage.googleapis.com/wandb-production.appspot.com/dynamic_x/bert_pytorch/87yhbfo2/wandb-metadata.json?Expires=1706688636&GoogleAccessId=gorilla-files-url-signer-man%40wandb-production.iam.gserviceaccount.com&Signature=i6ygl6e%2F1NTaK6CPvF0NXZCkqswXBKlbsIAlDONRJsh%2B3x8JGZM%2F%2F23d4nP224TGJJG%2FCwEhFPdSuwxqSBYHv%2By9Ud6qOPv71v5oMy3xjK95cP8S5aO5KfCrnKtrIOmrXhlAhzuwVq6uvAKGfNqgQD6MEyp8CsvfEfy7pGsDDEXhj40LUnzeh4v3UzcU9ErrNfA3%2Fisa1FmirWu%2FkUcHDNpTeHVwdhLMUqnr5fYBL47fFxTQFwVRLqi9eHGGatIhaAP0mH%2BbS54b2T7CtyGpcXkoRBRSTcKBdvyiBiPDGie7PGw9Xsb6h0zFIIHbjehEtC3Q24GdjVu1TNNGFHYb3w%3D%3D: HTTPSConnectionPool(host='storage.googleapis.com', port=443): Max retries exceeded with url: /wandb-production.appspot.com/dynamic_x/bert_pytorch/87yhbfo2/wandb-metadata.json?Expires=1706688636&GoogleAccessId=gorilla-files-url-signer-man%40wandb-production.iam.gserviceaccount.com&Signature=i6ygl6e%2F1NTaK6CPvF0NXZCkqswXBKlbsIAlDONRJsh%2B3x8JGZM%2F%2F23d4nP224TGJJG%2FCwEhFPdSuwxqSBYHv%2By9Ud6qOPv71v5oMy3xjK95cP8S5aO5KfCrnKtrIOmrXhlAhzuwVq6uvAKGfNqgQD6MEyp8CsvfEfy7pGsDDEXhj40LUnzeh4v3UzcU9ErrNfA3%2Fisa1FmirWu%2FkUcHDNpTeHVwdhLMUqnr5fYBL47fFxTQFwVRLqi9eHGGatIhaAP0mH%2BbS54b2T7CtyGpcXkoRBRSTcKBdvyiBiPDGie7PGw9Xsb6h0zFIIHbjehEtC3Q24GdjVu1TNNGFHYb3w%3D%3D (Caused by NewConnectionError('<urllib3.connection.HTTPSConnection object at 0x7f8598085460>: Failed to establish a new connection: [Errno 101] Network is unreachable'))
2024-01-30 17:30:40,163 ERROR   wandb-upload_0:1134330 [internal_api.py:upload_file():2767] upload_file request headers: {'User-Agent': 'python-requests/2.23.0', 'Accept-Encoding': 'gzip, deflate', 'Accept': '*/*', 'Connection': 'keep-alive', 'Content-Length': '15551'}
2024-01-30 17:30:40,163 ERROR   wandb-upload_0:1134330 [internal_api.py:upload_file():2769] upload_file response body: 
2024-01-30 17:36:10,227 ERROR   wandb-upload_0:1134330 [internal_api.py:upload_file():2765] upload_file exception https://storage.googleapis.com/wandb-production.appspot.com/dynamic_x/bert_pytorch/87yhbfo2/wandb-metadata.json?Expires=1706688636&GoogleAccessId=gorilla-files-url-signer-man%40wandb-production.iam.gserviceaccount.com&Signature=i6ygl6e%2F1NTaK6CPvF0NXZCkqswXBKlbsIAlDONRJsh%2B3x8JGZM%2F%2F23d4nP224TGJJG%2FCwEhFPdSuwxqSBYHv%2By9Ud6qOPv71v5oMy3xjK95cP8S5aO5KfCrnKtrIOmrXhlAhzuwVq6uvAKGfNqgQD6MEyp8CsvfEfy7pGsDDEXhj40LUnzeh4v3UzcU9ErrNfA3%2Fisa1FmirWu%2FkUcHDNpTeHVwdhLMUqnr5fYBL47fFxTQFwVRLqi9eHGGatIhaAP0mH%2BbS54b2T7CtyGpcXkoRBRSTcKBdvyiBiPDGie7PGw9Xsb6h0zFIIHbjehEtC3Q24GdjVu1TNNGFHYb3w%3D%3D: HTTPSConnectionPool(host='storage.googleapis.com', port=443): Max retries exceeded with url: /wandb-production.appspot.com/dynamic_x/bert_pytorch/87yhbfo2/wandb-metadata.json?Expires=1706688636&GoogleAccessId=gorilla-files-url-signer-man%40wandb-production.iam.gserviceaccount.com&Signature=i6ygl6e%2F1NTaK6CPvF0NXZCkqswXBKlbsIAlDONRJsh%2B3x8JGZM%2F%2F23d4nP224TGJJG%2FCwEhFPdSuwxqSBYHv%2By9Ud6qOPv71v5oMy3xjK95cP8S5aO5KfCrnKtrIOmrXhlAhzuwVq6uvAKGfNqgQD6MEyp8CsvfEfy7pGsDDEXhj40LUnzeh4v3UzcU9ErrNfA3%2Fisa1FmirWu%2FkUcHDNpTeHVwdhLMUqnr5fYBL47fFxTQFwVRLqi9eHGGatIhaAP0mH%2BbS54b2T7CtyGpcXkoRBRSTcKBdvyiBiPDGie7PGw9Xsb6h0zFIIHbjehEtC3Q24GdjVu1TNNGFHYb3w%3D%3D (Caused by NewConnectionError('<urllib3.connection.HTTPSConnection object at 0x7f8578f80d90>: Failed to establish a new connection: [Errno 101] Network is unreachable'))
2024-01-30 17:36:10,227 ERROR   wandb-upload_0:1134330 [internal_api.py:upload_file():2767] upload_file request headers: {'User-Agent': 'python-requests/2.23.0', 'Accept-Encoding': 'gzip, deflate', 'Accept': '*/*', 'Connection': 'keep-alive', 'Content-Length': '15551'}
2024-01-30 17:36:10,227 ERROR   wandb-upload_0:1134330 [internal_api.py:upload_file():2769] upload_file response body: 
2024-01-30 17:36:10,228 INFO    wandb-upload_0:1134330 [retry.py:__call__():172] Retry attempt failed:
Traceback (most recent call last):
  File "/home/yanxindong/anaconda/envs/eva/lib/python3.8/site-packages/urllib3/connection.py", line 159, in _new_conn
    conn = connection.create_connection(
  File "/home/yanxindong/anaconda/envs/eva/lib/python3.8/site-packages/urllib3/util/connection.py", line 84, in create_connection
    raise err
  File "/home/yanxindong/anaconda/envs/eva/lib/python3.8/site-packages/urllib3/util/connection.py", line 74, in create_connection
    sock.connect(sa)
OSError: [Errno 101] Network is unreachable

During handling of the above exception, another exception occurred:

Traceback (most recent call last):
  File "/home/yanxindong/anaconda/envs/eva/lib/python3.8/site-packages/urllib3/connectionpool.py", line 670, in urlopen
    httplib_response = self._make_request(
  File "/home/yanxindong/anaconda/envs/eva/lib/python3.8/site-packages/urllib3/connectionpool.py", line 381, in _make_request
    self._validate_conn(conn)
  File "/home/yanxindong/anaconda/envs/eva/lib/python3.8/site-packages/urllib3/connectionpool.py", line 978, in _validate_conn
    conn.connect()
  File "/home/yanxindong/anaconda/envs/eva/lib/python3.8/site-packages/urllib3/connection.py", line 309, in connect
    conn = self._new_conn()
  File "/home/yanxindong/anaconda/envs/eva/lib/python3.8/site-packages/urllib3/connection.py", line 171, in _new_conn
    raise NewConnectionError(
urllib3.exceptions.NewConnectionError: <urllib3.connection.HTTPSConnection object at 0x7f8578f80d90>: Failed to establish a new connection: [Errno 101] Network is unreachable

During handling of the above exception, another exception occurred:

Traceback (most recent call last):
  File "/home/yanxindong/anaconda/envs/eva/lib/python3.8/site-packages/requests/adapters.py", line 439, in send
    resp = conn.urlopen(
  File "/home/yanxindong/anaconda/envs/eva/lib/python3.8/site-packages/urllib3/connectionpool.py", line 726, in urlopen
    retries = retries.increment(
  File "/home/yanxindong/anaconda/envs/eva/lib/python3.8/site-packages/urllib3/util/retry.py", line 446, in increment
    raise MaxRetryError(_pool, url, error or ResponseError(cause))
urllib3.exceptions.MaxRetryError: HTTPSConnectionPool(host='storage.googleapis.com', port=443): Max retries exceeded with url: /wandb-production.appspot.com/dynamic_x/bert_pytorch/87yhbfo2/wandb-metadata.json?Expires=1706688636&GoogleAccessId=gorilla-files-url-signer-man%40wandb-production.iam.gserviceaccount.com&Signature=i6ygl6e%2F1NTaK6CPvF0NXZCkqswXBKlbsIAlDONRJsh%2B3x8JGZM%2F%2F23d4nP224TGJJG%2FCwEhFPdSuwxqSBYHv%2By9Ud6qOPv71v5oMy3xjK95cP8S5aO5KfCrnKtrIOmrXhlAhzuwVq6uvAKGfNqgQD6MEyp8CsvfEfy7pGsDDEXhj40LUnzeh4v3UzcU9ErrNfA3%2Fisa1FmirWu%2FkUcHDNpTeHVwdhLMUqnr5fYBL47fFxTQFwVRLqi9eHGGatIhaAP0mH%2BbS54b2T7CtyGpcXkoRBRSTcKBdvyiBiPDGie7PGw9Xsb6h0zFIIHbjehEtC3Q24GdjVu1TNNGFHYb3w%3D%3D (Caused by NewConnectionError('<urllib3.connection.HTTPSConnection object at 0x7f8578f80d90>: Failed to establish a new connection: [Errno 101] Network is unreachable'))

During handling of the above exception, another exception occurred:

Traceback (most recent call last):
  File "/home/yanxindong/anaconda/envs/eva/lib/python3.8/site-packages/wandb/sdk/internal/internal_api.py", line 2758, in upload_file
    response = self._upload_file_session.put(
  File "/home/yanxindong/anaconda/envs/eva/lib/python3.8/site-packages/requests/sessions.py", line 590, in put
    return self.request('PUT', url, data=data, **kwargs)
  File "/home/yanxindong/anaconda/envs/eva/lib/python3.8/site-packages/requests/sessions.py", line 530, in request
    resp = self.send(prep, **send_kwargs)
  File "/home/yanxindong/anaconda/envs/eva/lib/python3.8/site-packages/requests/sessions.py", line 643, in send
    r = adapter.send(request, **kwargs)
  File "/home/yanxindong/anaconda/envs/eva/lib/python3.8/site-packages/requests/adapters.py", line 516, in send
    raise ConnectionError(e, request=request)
requests.exceptions.ConnectionError: HTTPSConnectionPool(host='storage.googleapis.com', port=443): Max retries exceeded with url: /wandb-production.appspot.com/dynamic_x/bert_pytorch/87yhbfo2/wandb-metadata.json?Expires=1706688636&GoogleAccessId=gorilla-files-url-signer-man%40wandb-production.iam.gserviceaccount.com&Signature=i6ygl6e%2F1NTaK6CPvF0NXZCkqswXBKlbsIAlDONRJsh%2B3x8JGZM%2F%2F23d4nP224TGJJG%2FCwEhFPdSuwxqSBYHv%2By9Ud6qOPv71v5oMy3xjK95cP8S5aO5KfCrnKtrIOmrXhlAhzuwVq6uvAKGfNqgQD6MEyp8CsvfEfy7pGsDDEXhj40LUnzeh4v3UzcU9ErrNfA3%2Fisa1FmirWu%2FkUcHDNpTeHVwdhLMUqnr5fYBL47fFxTQFwVRLqi9eHGGatIhaAP0mH%2BbS54b2T7CtyGpcXkoRBRSTcKBdvyiBiPDGie7PGw9Xsb6h0zFIIHbjehEtC3Q24GdjVu1TNNGFHYb3w%3D%3D (Caused by NewConnectionError('<urllib3.connection.HTTPSConnection object at 0x7f8578f80d90>: Failed to establish a new connection: [Errno 101] Network is unreachable'))

During handling of the above exception, another exception occurred:

Traceback (most recent call last):
  File "/home/yanxindong/anaconda/envs/eva/lib/python3.8/site-packages/wandb/sdk/lib/retry.py", line 131, in __call__
    result = self._call_fn(*args, **kwargs)
  File "/home/yanxindong/anaconda/envs/eva/lib/python3.8/site-packages/wandb/sdk/internal/internal_api.py", line 2789, in upload_file
    raise _e.with_traceback(sys.exc_info()[2])
  File "/home/yanxindong/anaconda/envs/eva/lib/python3.8/site-packages/wandb/sdk/internal/internal_api.py", line 2758, in upload_file
    response = self._upload_file_session.put(
  File "/home/yanxindong/anaconda/envs/eva/lib/python3.8/site-packages/requests/sessions.py", line 590, in put
    return self.request('PUT', url, data=data, **kwargs)
  File "/home/yanxindong/anaconda/envs/eva/lib/python3.8/site-packages/requests/sessions.py", line 530, in request
    resp = self.send(prep, **send_kwargs)
  File "/home/yanxindong/anaconda/envs/eva/lib/python3.8/site-packages/requests/sessions.py", line 643, in send
    r = adapter.send(request, **kwargs)
  File "/home/yanxindong/anaconda/envs/eva/lib/python3.8/site-packages/requests/adapters.py", line 516, in send
    raise ConnectionError(e, request=request)
wandb.sdk.lib.retry.TransientError: None
2024-01-30 17:42:12,052 INFO    wandb-upload_0:1134330 [upload_job.py:push():131] Uploaded file /tmp/tmpr9caoxvlwandb/787532bd-wandb-metadata.json
2024-01-30 17:42:12,401 INFO    SenderThread:1134330 [file_stream.py:finish():595] file stream finish called
2024-01-30 17:42:14,575 INFO    SenderThread:1134330 [file_stream.py:finish():599] file stream finish is done
