2024-01-30 16:10:12,460 INFO    StreamThr :1134320 [internal.py:wandb_internal():86] W&B internal server running at pid: 1134320, started at: 2024-01-30 16:10:12.459836
2024-01-30 16:10:12,463 DEBUG   HandlerThread:1134320 [handler.py:handle_request():146] handle_request: status
2024-01-30 16:10:12,463 INFO    WriterThread:1134320 [datastore.py:open_for_write():87] open: /home/yanxindong/mkor/bert/wandb/run-20240130_161012-wn1qxvno/run-wn1qxvno.wandb
2024-01-30 16:10:12,464 DEBUG   SenderThread:1134320 [sender.py:send():382] send: header
2024-01-30 16:10:12,469 DEBUG   SenderThread:1134320 [sender.py:send():382] send: run
2024-01-30 16:10:13,801 INFO    SenderThread:1134320 [dir_watcher.py:__init__():211] watching files in: /home/yanxindong/mkor/bert/wandb/run-20240130_161012-wn1qxvno/files
2024-01-30 16:10:13,801 INFO    SenderThread:1134320 [sender.py:_start_run_threads():1136] run started: wn1qxvno with start time 1706602212.455771
2024-01-30 16:10:13,805 DEBUG   HandlerThread:1134320 [handler.py:handle_request():146] handle_request: check_version
2024-01-30 16:10:13,805 DEBUG   SenderThread:1134320 [sender.py:send_request():409] send_request: check_version
2024-01-30 16:10:14,702 DEBUG   HandlerThread:1134320 [handler.py:handle_request():146] handle_request: run_start
2024-01-30 16:10:14,730 DEBUG   HandlerThread:1134320 [system_info.py:__init__():27] System info init
2024-01-30 16:10:14,730 DEBUG   HandlerThread:1134320 [system_info.py:__init__():42] System info init done
2024-01-30 16:10:14,731 INFO    HandlerThread:1134320 [system_monitor.py:start():194] Starting system monitor
2024-01-30 16:10:14,731 INFO    SystemMonitor:1134320 [system_monitor.py:_start():158] Starting system asset monitoring threads
2024-01-30 16:10:14,731 INFO    HandlerThread:1134320 [system_monitor.py:probe():214] Collecting system info
2024-01-30 16:10:14,752 INFO    SystemMonitor:1134320 [interfaces.py:start():190] Started cpu monitoring
2024-01-30 16:10:14,756 INFO    SystemMonitor:1134320 [interfaces.py:start():190] Started disk monitoring
2024-01-30 16:10:14,759 INFO    SystemMonitor:1134320 [interfaces.py:start():190] Started gpu monitoring
2024-01-30 16:10:14,775 INFO    SystemMonitor:1134320 [interfaces.py:start():190] Started memory monitoring
2024-01-30 16:10:14,801 INFO    SystemMonitor:1134320 [interfaces.py:start():190] Started network monitoring
2024-01-30 16:10:14,832 DEBUG   HandlerThread:1134320 [system_info.py:probe():151] Probing system
2024-01-30 16:10:14,857 DEBUG   HandlerThread:1134320 [system_info.py:_probe_git():136] Probing git
2024-01-30 16:10:14,970 DEBUG   HandlerThread:1134320 [system_info.py:_probe_git():144] Probing git done
2024-01-30 16:10:14,971 DEBUG   HandlerThread:1134320 [system_info.py:probe():199] Probing system done
2024-01-30 16:10:14,971 DEBUG   HandlerThread:1134320 [system_monitor.py:probe():223] {'os': 'Linux-5.15.0-92-generic-x86_64-with-glibc2.17', 'python': '3.8.17', 'heartbeatAt': '2024-01-30T08:10:14.832533', 'startedAt': '2024-01-30T08:10:12.447666', 'docker': None, 'cuda': None, 'args': ('--local_rank=0', '--config_file', 'config/bert_pretraining_phase2_config.json', '--input_dir', '/home/yanxindong/mkor/bert/data/encoded/sequences_lowercase_max_seq_len_512_next_seq_task_true', '--output_dir', 'results/adam', '--weight_decay', '0.01', '--num_steps_per_checkpoint', '200'), 'state': 'running', 'program': 'run_pretraining.py', 'codePathLocal': 'run_pretraining.py', 'codePath': 'bert/run_pretraining.py', 'git': {'remote': 'https://github.com/kkkjj-d/mkor.git', 'commit': 'efe99e84fef5594780cfb1df6d6a1f61da4ebba0'}, 'email': '1262670315@qq.com', 'root': '/home/yanxindong/mkor', 'host': 'a6000-X640-G40', 'username': 'yanxindong', 'executable': '/home/yanxindong/anaconda/envs/eva/bin/python', 'cpu_count': 64, 'cpu_count_logical': 128, 'cpu_freq': {'current': 849.9999843749999, 'min': 800.0, 'max': 3400.0}, 'cpu_freq_per_core': [{'current': 3299.998, 'min': 800.0, 'max': 3400.0}, {'current': 800.0, 'min': 800.0, 'max': 3400.0}, {'current': 800.0, 'min': 800.0, 'max': 3400.0}, {'current': 800.0, 'min': 800.0, 'max': 3400.0}, {'current': 800.0, 'min': 800.0, 'max': 3400.0}, {'current': 800.0, 'min': 800.0, 'max': 3400.0}, {'current': 800.0, 'min': 800.0, 'max': 3400.0}, {'current': 800.0, 'min': 800.0, 'max': 3400.0}, {'current': 900.0, 'min': 800.0, 'max': 3400.0}, {'current': 800.0, 'min': 800.0, 'max': 3400.0}, {'current': 800.0, 'min': 800.0, 'max': 3400.0}, {'current': 800.0, 'min': 800.0, 'max': 3400.0}, {'current': 800.0, 'min': 800.0, 'max': 3400.0}, {'current': 800.0, 'min': 800.0, 'max': 3400.0}, {'current': 800.0, 'min': 800.0, 'max': 3400.0}, {'current': 800.0, 'min': 800.0, 'max': 3400.0}, {'current': 800.0, 'min': 800.0, 'max': 3400.0}, {'current': 800.0, 'min': 800.0, 'max': 3400.0}, {'current': 800.0, 'min': 800.0, 'max': 3400.0}, {'current': 800.0, 'min': 800.0, 'max': 3400.0}, {'current': 800.0, 'min': 800.0, 'max': 3400.0}, {'current': 800.0, 'min': 800.0, 'max': 3400.0}, {'current': 800.0, 'min': 800.0, 'max': 3400.0}, {'current': 800.0, 'min': 800.0, 'max': 3400.0}, {'current': 800.0, 'min': 800.0, 'max': 3400.0}, {'current': 800.0, 'min': 800.0, 'max': 3400.0}, {'current': 800.0, 'min': 800.0, 'max': 3400.0}, {'current': 800.0, 'min': 800.0, 'max': 3400.0}, {'current': 800.0, 'min': 800.0, 'max': 3400.0}, {'current': 800.0, 'min': 800.0, 'max': 3400.0}, {'current': 800.0, 'min': 800.0, 'max': 3400.0}, {'current': 1300.0, 'min': 800.0, 'max': 3400.0}, {'current': 800.0, 'min': 800.0, 'max': 3400.0}, {'current': 800.0, 'min': 800.0, 'max': 3400.0}, {'current': 1300.0, 'min': 800.0, 'max': 3400.0}, {'current': 800.0, 'min': 800.0, 'max': 3400.0}, {'current': 800.0, 'min': 800.0, 'max': 3400.0}, {'current': 800.0, 'min': 800.0, 'max': 3400.0}, {'current': 800.0, 'min': 800.0, 'max': 3400.0}, {'current': 800.0, 'min': 800.0, 'max': 3400.0}, {'current': 800.0, 'min': 800.0, 'max': 3400.0}, {'current': 800.0, 'min': 800.0, 'max': 3400.0}, {'current': 800.0, 'min': 800.0, 'max': 3400.0}, {'current': 800.0, 'min': 800.0, 'max': 3400.0}, {'current': 800.0, 'min': 800.0, 'max': 3400.0}, {'current': 800.0, 'min': 800.0, 'max': 3400.0}, {'current': 800.0, 'min': 800.0, 'max': 3400.0}, {'current': 800.0, 'min': 800.0, 'max': 3400.0}, {'current': 800.0, 'min': 800.0, 'max': 3400.0}, {'current': 800.0, 'min': 800.0, 'max': 3400.0}, {'current': 800.0, 'min': 800.0, 'max': 3400.0}, {'current': 1000.0, 'min': 800.0, 'max': 3400.0}, {'current': 800.0, 'min': 800.0, 'max': 3400.0}, {'current': 800.0, 'min': 800.0, 'max': 3400.0}, {'current': 800.0, 'min': 800.0, 'max': 3400.0}, {'current': 800.0, 'min': 800.0, 'max': 3400.0}, {'current': 800.0, 'min': 800.0, 'max': 3400.0}, {'current': 800.0, 'min': 800.0, 'max': 3400.0}, {'current': 800.0, 'min': 800.0, 'max': 3400.0}, {'current': 800.0, 'min': 800.0, 'max': 3400.0}, {'current': 800.0, 'min': 800.0, 'max': 3400.0}, {'current': 800.0, 'min': 800.0, 'max': 3400.0}, {'current': 800.0, 'min': 800.0, 'max': 3400.0}, {'current': 800.0, 'min': 800.0, 'max': 3400.0}, {'current': 3300.0, 'min': 800.0, 'max': 3400.0}, {'current': 800.0, 'min': 800.0, 'max': 3400.0}, {'current': 800.0, 'min': 800.0, 'max': 3400.0}, {'current': 800.0, 'min': 800.0, 'max': 3400.0}, {'current': 800.0, 'min': 800.0, 'max': 3400.0}, {'current': 800.0, 'min': 800.0, 'max': 3400.0}, {'current': 800.0, 'min': 800.0, 'max': 3400.0}, {'current': 800.0, 'min': 800.0, 'max': 3400.0}, {'current': 800.0, 'min': 800.0, 'max': 3400.0}, {'current': 800.0, 'min': 800.0, 'max': 3400.0}, {'current': 800.0, 'min': 800.0, 'max': 3400.0}, {'current': 800.0, 'min': 800.0, 'max': 3400.0}, {'current': 800.0, 'min': 800.0, 'max': 3400.0}, {'current': 800.0, 'min': 800.0, 'max': 3400.0}, {'current': 800.0, 'min': 800.0, 'max': 3400.0}, {'current': 800.0, 'min': 800.0, 'max': 3400.0}, {'current': 800.0, 'min': 800.0, 'max': 3400.0}, {'current': 800.0, 'min': 800.0, 'max': 3400.0}, {'current': 800.0, 'min': 800.0, 'max': 3400.0}, {'current': 800.0, 'min': 800.0, 'max': 3400.0}, {'current': 800.0, 'min': 800.0, 'max': 3400.0}, {'current': 800.0, 'min': 800.0, 'max': 3400.0}, {'current': 800.0, 'min': 800.0, 'max': 3400.0}, {'current': 800.0, 'min': 800.0, 'max': 3400.0}, {'current': 800.0, 'min': 800.0, 'max': 3400.0}, {'current': 800.0, 'min': 800.0, 'max': 3400.0}, {'current': 800.0, 'min': 800.0, 'max': 3400.0}, {'current': 800.0, 'min': 800.0, 'max': 3400.0}, {'current': 800.0, 'min': 800.0, 'max': 3400.0}, {'current': 800.0, 'min': 800.0, 'max': 3400.0}, {'current': 800.0, 'min': 800.0, 'max': 3400.0}, {'current': 800.0, 'min': 800.0, 'max': 3400.0}, {'current': 800.0, 'min': 800.0, 'max': 3400.0}, {'current': 800.0, 'min': 800.0, 'max': 3400.0}, {'current': 800.0, 'min': 800.0, 'max': 3400.0}, {'current': 800.0, 'min': 800.0, 'max': 3400.0}, {'current': 800.0, 'min': 800.0, 'max': 3400.0}, {'current': 800.0, 'min': 800.0, 'max': 3400.0}, {'current': 800.0, 'min': 800.0, 'max': 3400.0}, {'current': 800.0, 'min': 800.0, 'max': 3400.0}, {'current': 800.0, 'min': 800.0, 'max': 3400.0}, {'current': 800.0, 'min': 800.0, 'max': 3400.0}, {'current': 800.0, 'min': 800.0, 'max': 3400.0}, {'current': 800.0, 'min': 800.0, 'max': 3400.0}, {'current': 800.0, 'min': 800.0, 'max': 3400.0}, {'current': 800.0, 'min': 800.0, 'max': 3400.0}, {'current': 900.0, 'min': 800.0, 'max': 3400.0}, {'current': 800.0, 'min': 800.0, 'max': 3400.0}, {'current': 800.0, 'min': 800.0, 'max': 3400.0}, {'current': 800.0, 'min': 800.0, 'max': 3400.0}, {'current': 800.0, 'min': 800.0, 'max': 3400.0}, {'current': 800.0, 'min': 800.0, 'max': 3400.0}, {'current': 800.0, 'min': 800.0, 'max': 3400.0}, {'current': 800.0, 'min': 800.0, 'max': 3400.0}, {'current': 800.0, 'min': 800.0, 'max': 3400.0}, {'current': 800.0, 'min': 800.0, 'max': 3400.0}, {'current': 800.0, 'min': 800.0, 'max': 3400.0}, {'current': 800.0, 'min': 800.0, 'max': 3400.0}, {'current': 800.0, 'min': 800.0, 'max': 3400.0}, {'current': 800.0, 'min': 800.0, 'max': 3400.0}, {'current': 800.0, 'min': 800.0, 'max': 3400.0}, {'current': 800.0, 'min': 800.0, 'max': 3400.0}, {'current': 800.0, 'min': 800.0, 'max': 3400.0}, {'current': 800.0, 'min': 800.0, 'max': 3400.0}], 'disk': {'/': {'total': 438.05088806152344, 'used': 30.817367553710938}}, 'gpu': 'NVIDIA RTX A6000', 'gpu_count': 8, 'gpu_devices': [{'name': 'NVIDIA RTX A6000', 'memory_total': 51527024640}, {'name': 'NVIDIA RTX A6000', 'memory_total': 51527024640}, {'name': 'NVIDIA RTX A6000', 'memory_total': 51527024640}, {'name': 'NVIDIA RTX A6000', 'memory_total': 51527024640}, {'name': 'NVIDIA RTX A6000', 'memory_total': 51527024640}, {'name': 'NVIDIA RTX A6000', 'memory_total': 51527024640}, {'name': 'NVIDIA RTX A6000', 'memory_total': 51527024640}, {'name': 'NVIDIA RTX A6000', 'memory_total': 51527024640}], 'memory': {'total': 503.51252365112305}}
2024-01-30 16:10:14,971 INFO    HandlerThread:1134320 [system_monitor.py:probe():224] Finished collecting system info
2024-01-30 16:10:14,971 INFO    HandlerThread:1134320 [system_monitor.py:probe():227] Publishing system info
2024-01-30 16:10:14,971 DEBUG   HandlerThread:1134320 [system_info.py:_save_conda():208] Saving list of conda packages installed into the current environment
2024-01-30 16:10:15,803 INFO    Thread-12 :1134320 [dir_watcher.py:_on_file_created():271] file/dir created: /home/yanxindong/mkor/bert/wandb/run-20240130_161012-wn1qxvno/files/conda-environment.yaml
2024-01-30 16:10:35,805 INFO    Thread-12 :1134320 [dir_watcher.py:_on_file_modified():288] file/dir modified: /home/yanxindong/mkor/bert/wandb/run-20240130_161012-wn1qxvno/files/conda-environment.yaml
2024-01-30 16:10:35,904 DEBUG   HandlerThread:1134320 [system_info.py:_save_conda():220] Saving conda packages done
2024-01-30 16:10:35,906 INFO    HandlerThread:1134320 [system_monitor.py:probe():229] Finished publishing system info
2024-01-30 16:10:35,919 DEBUG   HandlerThread:1134320 [handler.py:handle_request():146] handle_request: status_report
2024-01-30 16:10:35,925 DEBUG   HandlerThread:1134320 [handler.py:handle_request():146] handle_request: keepalive
2024-01-30 16:10:35,925 DEBUG   HandlerThread:1134320 [handler.py:handle_request():146] handle_request: status_report
2024-01-30 16:10:35,925 DEBUG   HandlerThread:1134320 [handler.py:handle_request():146] handle_request: keepalive
2024-01-30 16:10:35,925 DEBUG   HandlerThread:1134320 [handler.py:handle_request():146] handle_request: status_report
2024-01-30 16:10:35,925 DEBUG   HandlerThread:1134320 [handler.py:handle_request():146] handle_request: keepalive
2024-01-30 16:10:35,925 DEBUG   HandlerThread:1134320 [handler.py:handle_request():146] handle_request: status_report
2024-01-30 16:10:35,925 DEBUG   HandlerThread:1134320 [handler.py:handle_request():146] handle_request: keepalive
2024-01-30 16:10:35,926 DEBUG   HandlerThread:1134320 [handler.py:handle_request():146] handle_request: python_packages
2024-01-30 16:10:35,926 DEBUG   SenderThread:1134320 [sender.py:send():382] send: files
2024-01-30 16:10:35,926 INFO    SenderThread:1134320 [sender.py:_save_file():1403] saving file wandb-metadata.json with policy now
2024-01-30 16:10:35,927 DEBUG   SenderThread:1134320 [sender.py:send_request():409] send_request: python_packages
2024-01-30 16:10:35,954 DEBUG   HandlerThread:1134320 [handler.py:handle_request():146] handle_request: stop_status
2024-01-30 16:10:35,954 DEBUG   SenderThread:1134320 [sender.py:send_request():409] send_request: stop_status
2024-01-30 16:10:36,001 DEBUG   HandlerThread:1134320 [handler.py:handle_request():146] handle_request: internal_messages
2024-01-30 16:10:36,468 DEBUG   SenderThread:1134320 [sender.py:send():382] send: telemetry
2024-01-30 16:10:36,502 ERROR   wandb-upload_0:1134320 [internal_api.py:upload_file():2765] upload_file exception https://storage.googleapis.com/wandb-production.appspot.com/dynamic_x/bert_pytorch/wn1qxvno/wandb-metadata.json?Expires=1706688636&GoogleAccessId=gorilla-files-url-signer-man%40wandb-production.iam.gserviceaccount.com&Signature=X2NQsRBPxmFG1jesoKIgaYH%2BEuVtOiN9iCNyn2nXM0cUCfxLAaAA%2Bk3hpaoW2l5axIqryRk6aj9eSNHiDB95u6Hf7uUfIhqHdFIO604O3XU8FxsVDC6sl62BCb5Gv1YZELF0wwnCYUabk5D8%2BySwHmTL5L192XcYTZiRY5RNvkX0XbkI1VhcZpRvVUboO783c0aYk3HaH9AjjVpNUOz6AP7oNYdWa%2BBqjD6KY4lDz4ppjtGJyClpzP%2BXvNyhrL2ChSQrgKLmg7wKvTV5yciTtM7q8830QL9WNkUPXUkfHDQyMFS62jtzEAulOBw9PlxFnSMtX64IMtAkZcBi0zA25A%3D%3D: HTTPSConnectionPool(host='storage.googleapis.com', port=443): Max retries exceeded with url: /wandb-production.appspot.com/dynamic_x/bert_pytorch/wn1qxvno/wandb-metadata.json?Expires=1706688636&GoogleAccessId=gorilla-files-url-signer-man%40wandb-production.iam.gserviceaccount.com&Signature=X2NQsRBPxmFG1jesoKIgaYH%2BEuVtOiN9iCNyn2nXM0cUCfxLAaAA%2Bk3hpaoW2l5axIqryRk6aj9eSNHiDB95u6Hf7uUfIhqHdFIO604O3XU8FxsVDC6sl62BCb5Gv1YZELF0wwnCYUabk5D8%2BySwHmTL5L192XcYTZiRY5RNvkX0XbkI1VhcZpRvVUboO783c0aYk3HaH9AjjVpNUOz6AP7oNYdWa%2BBqjD6KY4lDz4ppjtGJyClpzP%2BXvNyhrL2ChSQrgKLmg7wKvTV5yciTtM7q8830QL9WNkUPXUkfHDQyMFS62jtzEAulOBw9PlxFnSMtX64IMtAkZcBi0zA25A%3D%3D (Caused by NewConnectionError('<urllib3.connection.HTTPSConnection object at 0x7f47d45f8c40>: Failed to establish a new connection: [Errno 111] Connection refused'))
2024-01-30 16:10:36,502 ERROR   wandb-upload_0:1134320 [internal_api.py:upload_file():2767] upload_file request headers: {'User-Agent': 'python-requests/2.23.0', 'Accept-Encoding': 'gzip, deflate', 'Accept': '*/*', 'Connection': 'keep-alive', 'Content-Length': '15553'}
2024-01-30 16:10:36,502 ERROR   wandb-upload_0:1134320 [internal_api.py:upload_file():2769] upload_file response body: 
2024-01-30 16:10:36,806 INFO    Thread-12 :1134320 [dir_watcher.py:_on_file_created():271] file/dir created: /home/yanxindong/mkor/bert/wandb/run-20240130_161012-wn1qxvno/files/wandb-metadata.json
2024-01-30 16:10:36,806 INFO    Thread-12 :1134320 [dir_watcher.py:_on_file_created():271] file/dir created: /home/yanxindong/mkor/bert/wandb/run-20240130_161012-wn1qxvno/files/requirements.txt
2024-01-30 16:10:37,621 ERROR   wandb-upload_0:1134320 [internal_api.py:upload_file():2765] upload_file exception https://storage.googleapis.com/wandb-production.appspot.com/dynamic_x/bert_pytorch/wn1qxvno/wandb-metadata.json?Expires=1706688636&GoogleAccessId=gorilla-files-url-signer-man%40wandb-production.iam.gserviceaccount.com&Signature=X2NQsRBPxmFG1jesoKIgaYH%2BEuVtOiN9iCNyn2nXM0cUCfxLAaAA%2Bk3hpaoW2l5axIqryRk6aj9eSNHiDB95u6Hf7uUfIhqHdFIO604O3XU8FxsVDC6sl62BCb5Gv1YZELF0wwnCYUabk5D8%2BySwHmTL5L192XcYTZiRY5RNvkX0XbkI1VhcZpRvVUboO783c0aYk3HaH9AjjVpNUOz6AP7oNYdWa%2BBqjD6KY4lDz4ppjtGJyClpzP%2BXvNyhrL2ChSQrgKLmg7wKvTV5yciTtM7q8830QL9WNkUPXUkfHDQyMFS62jtzEAulOBw9PlxFnSMtX64IMtAkZcBi0zA25A%3D%3D: HTTPSConnectionPool(host='storage.googleapis.com', port=443): Max retries exceeded with url: /wandb-production.appspot.com/dynamic_x/bert_pytorch/wn1qxvno/wandb-metadata.json?Expires=1706688636&GoogleAccessId=gorilla-files-url-signer-man%40wandb-production.iam.gserviceaccount.com&Signature=X2NQsRBPxmFG1jesoKIgaYH%2BEuVtOiN9iCNyn2nXM0cUCfxLAaAA%2Bk3hpaoW2l5axIqryRk6aj9eSNHiDB95u6Hf7uUfIhqHdFIO604O3XU8FxsVDC6sl62BCb5Gv1YZELF0wwnCYUabk5D8%2BySwHmTL5L192XcYTZiRY5RNvkX0XbkI1VhcZpRvVUboO783c0aYk3HaH9AjjVpNUOz6AP7oNYdWa%2BBqjD6KY4lDz4ppjtGJyClpzP%2BXvNyhrL2ChSQrgKLmg7wKvTV5yciTtM7q8830QL9WNkUPXUkfHDQyMFS62jtzEAulOBw9PlxFnSMtX64IMtAkZcBi0zA25A%3D%3D (Caused by NewConnectionError('<urllib3.connection.HTTPSConnection object at 0x7f47d45f87c0>: Failed to establish a new connection: [Errno 111] Connection refused'))
2024-01-30 16:10:37,621 ERROR   wandb-upload_0:1134320 [internal_api.py:upload_file():2767] upload_file request headers: {'User-Agent': 'python-requests/2.23.0', 'Accept-Encoding': 'gzip, deflate', 'Accept': '*/*', 'Connection': 'keep-alive', 'Content-Length': '15553'}
2024-01-30 16:10:37,621 ERROR   wandb-upload_0:1134320 [internal_api.py:upload_file():2769] upload_file response body: 
2024-01-30 16:10:38,468 DEBUG   HandlerThread:1134320 [handler.py:handle_request():146] handle_request: status_report
2024-01-30 16:10:39,654 ERROR   wandb-upload_0:1134320 [internal_api.py:upload_file():2765] upload_file exception https://storage.googleapis.com/wandb-production.appspot.com/dynamic_x/bert_pytorch/wn1qxvno/wandb-metadata.json?Expires=1706688636&GoogleAccessId=gorilla-files-url-signer-man%40wandb-production.iam.gserviceaccount.com&Signature=X2NQsRBPxmFG1jesoKIgaYH%2BEuVtOiN9iCNyn2nXM0cUCfxLAaAA%2Bk3hpaoW2l5axIqryRk6aj9eSNHiDB95u6Hf7uUfIhqHdFIO604O3XU8FxsVDC6sl62BCb5Gv1YZELF0wwnCYUabk5D8%2BySwHmTL5L192XcYTZiRY5RNvkX0XbkI1VhcZpRvVUboO783c0aYk3HaH9AjjVpNUOz6AP7oNYdWa%2BBqjD6KY4lDz4ppjtGJyClpzP%2BXvNyhrL2ChSQrgKLmg7wKvTV5yciTtM7q8830QL9WNkUPXUkfHDQyMFS62jtzEAulOBw9PlxFnSMtX64IMtAkZcBi0zA25A%3D%3D: HTTPSConnectionPool(host='storage.googleapis.com', port=443): Max retries exceeded with url: /wandb-production.appspot.com/dynamic_x/bert_pytorch/wn1qxvno/wandb-metadata.json?Expires=1706688636&GoogleAccessId=gorilla-files-url-signer-man%40wandb-production.iam.gserviceaccount.com&Signature=X2NQsRBPxmFG1jesoKIgaYH%2BEuVtOiN9iCNyn2nXM0cUCfxLAaAA%2Bk3hpaoW2l5axIqryRk6aj9eSNHiDB95u6Hf7uUfIhqHdFIO604O3XU8FxsVDC6sl62BCb5Gv1YZELF0wwnCYUabk5D8%2BySwHmTL5L192XcYTZiRY5RNvkX0XbkI1VhcZpRvVUboO783c0aYk3HaH9AjjVpNUOz6AP7oNYdWa%2BBqjD6KY4lDz4ppjtGJyClpzP%2BXvNyhrL2ChSQrgKLmg7wKvTV5yciTtM7q8830QL9WNkUPXUkfHDQyMFS62jtzEAulOBw9PlxFnSMtX64IMtAkZcBi0zA25A%3D%3D (Caused by NewConnectionError('<urllib3.connection.HTTPSConnection object at 0x7f47d45f81c0>: Failed to establish a new connection: [Errno 111] Connection refused'))
2024-01-30 16:10:39,654 ERROR   wandb-upload_0:1134320 [internal_api.py:upload_file():2767] upload_file request headers: {'User-Agent': 'python-requests/2.23.0', 'Accept-Encoding': 'gzip, deflate', 'Accept': '*/*', 'Connection': 'keep-alive', 'Content-Length': '15553'}
2024-01-30 16:10:39,654 ERROR   wandb-upload_0:1134320 [internal_api.py:upload_file():2769] upload_file response body: 
2024-01-30 16:10:39,655 INFO    wandb-upload_0:1134320 [retry.py:__call__():172] Retry attempt failed:
Traceback (most recent call last):
  File "/home/yanxindong/anaconda/envs/eva/lib/python3.8/site-packages/urllib3/connection.py", line 159, in _new_conn
    conn = connection.create_connection(
  File "/home/yanxindong/anaconda/envs/eva/lib/python3.8/site-packages/urllib3/util/connection.py", line 84, in create_connection
    raise err
  File "/home/yanxindong/anaconda/envs/eva/lib/python3.8/site-packages/urllib3/util/connection.py", line 74, in create_connection
    sock.connect(sa)
ConnectionRefusedError: [Errno 111] Connection refused

During handling of the above exception, another exception occurred:

Traceback (most recent call last):
  File "/home/yanxindong/anaconda/envs/eva/lib/python3.8/site-packages/urllib3/connectionpool.py", line 670, in urlopen
    httplib_response = self._make_request(
  File "/home/yanxindong/anaconda/envs/eva/lib/python3.8/site-packages/urllib3/connectionpool.py", line 381, in _make_request
    self._validate_conn(conn)
  File "/home/yanxindong/anaconda/envs/eva/lib/python3.8/site-packages/urllib3/connectionpool.py", line 978, in _validate_conn
    conn.connect()
  File "/home/yanxindong/anaconda/envs/eva/lib/python3.8/site-packages/urllib3/connection.py", line 309, in connect
    conn = self._new_conn()
  File "/home/yanxindong/anaconda/envs/eva/lib/python3.8/site-packages/urllib3/connection.py", line 171, in _new_conn
    raise NewConnectionError(
urllib3.exceptions.NewConnectionError: <urllib3.connection.HTTPSConnection object at 0x7f47d45f81c0>: Failed to establish a new connection: [Errno 111] Connection refused

During handling of the above exception, another exception occurred:

Traceback (most recent call last):
  File "/home/yanxindong/anaconda/envs/eva/lib/python3.8/site-packages/requests/adapters.py", line 439, in send
    resp = conn.urlopen(
  File "/home/yanxindong/anaconda/envs/eva/lib/python3.8/site-packages/urllib3/connectionpool.py", line 726, in urlopen
    retries = retries.increment(
  File "/home/yanxindong/anaconda/envs/eva/lib/python3.8/site-packages/urllib3/util/retry.py", line 446, in increment
    raise MaxRetryError(_pool, url, error or ResponseError(cause))
urllib3.exceptions.MaxRetryError: HTTPSConnectionPool(host='storage.googleapis.com', port=443): Max retries exceeded with url: /wandb-production.appspot.com/dynamic_x/bert_pytorch/wn1qxvno/wandb-metadata.json?Expires=1706688636&GoogleAccessId=gorilla-files-url-signer-man%40wandb-production.iam.gserviceaccount.com&Signature=X2NQsRBPxmFG1jesoKIgaYH%2BEuVtOiN9iCNyn2nXM0cUCfxLAaAA%2Bk3hpaoW2l5axIqryRk6aj9eSNHiDB95u6Hf7uUfIhqHdFIO604O3XU8FxsVDC6sl62BCb5Gv1YZELF0wwnCYUabk5D8%2BySwHmTL5L192XcYTZiRY5RNvkX0XbkI1VhcZpRvVUboO783c0aYk3HaH9AjjVpNUOz6AP7oNYdWa%2BBqjD6KY4lDz4ppjtGJyClpzP%2BXvNyhrL2ChSQrgKLmg7wKvTV5yciTtM7q8830QL9WNkUPXUkfHDQyMFS62jtzEAulOBw9PlxFnSMtX64IMtAkZcBi0zA25A%3D%3D (Caused by NewConnectionError('<urllib3.connection.HTTPSConnection object at 0x7f47d45f81c0>: Failed to establish a new connection: [Errno 111] Connection refused'))

During handling of the above exception, another exception occurred:

Traceback (most recent call last):
  File "/home/yanxindong/anaconda/envs/eva/lib/python3.8/site-packages/wandb/sdk/internal/internal_api.py", line 2758, in upload_file
    response = self._upload_file_session.put(
  File "/home/yanxindong/anaconda/envs/eva/lib/python3.8/site-packages/requests/sessions.py", line 590, in put
    return self.request('PUT', url, data=data, **kwargs)
  File "/home/yanxindong/anaconda/envs/eva/lib/python3.8/site-packages/requests/sessions.py", line 530, in request
    resp = self.send(prep, **send_kwargs)
  File "/home/yanxindong/anaconda/envs/eva/lib/python3.8/site-packages/requests/sessions.py", line 643, in send
    r = adapter.send(request, **kwargs)
  File "/home/yanxindong/anaconda/envs/eva/lib/python3.8/site-packages/requests/adapters.py", line 516, in send
    raise ConnectionError(e, request=request)
requests.exceptions.ConnectionError: HTTPSConnectionPool(host='storage.googleapis.com', port=443): Max retries exceeded with url: /wandb-production.appspot.com/dynamic_x/bert_pytorch/wn1qxvno/wandb-metadata.json?Expires=1706688636&GoogleAccessId=gorilla-files-url-signer-man%40wandb-production.iam.gserviceaccount.com&Signature=X2NQsRBPxmFG1jesoKIgaYH%2BEuVtOiN9iCNyn2nXM0cUCfxLAaAA%2Bk3hpaoW2l5axIqryRk6aj9eSNHiDB95u6Hf7uUfIhqHdFIO604O3XU8FxsVDC6sl62BCb5Gv1YZELF0wwnCYUabk5D8%2BySwHmTL5L192XcYTZiRY5RNvkX0XbkI1VhcZpRvVUboO783c0aYk3HaH9AjjVpNUOz6AP7oNYdWa%2BBqjD6KY4lDz4ppjtGJyClpzP%2BXvNyhrL2ChSQrgKLmg7wKvTV5yciTtM7q8830QL9WNkUPXUkfHDQyMFS62jtzEAulOBw9PlxFnSMtX64IMtAkZcBi0zA25A%3D%3D (Caused by NewConnectionError('<urllib3.connection.HTTPSConnection object at 0x7f47d45f81c0>: Failed to establish a new connection: [Errno 111] Connection refused'))

During handling of the above exception, another exception occurred:

Traceback (most recent call last):
  File "/home/yanxindong/anaconda/envs/eva/lib/python3.8/site-packages/wandb/sdk/lib/retry.py", line 131, in __call__
    result = self._call_fn(*args, **kwargs)
  File "/home/yanxindong/anaconda/envs/eva/lib/python3.8/site-packages/wandb/sdk/internal/internal_api.py", line 2789, in upload_file
    raise _e.with_traceback(sys.exc_info()[2])
  File "/home/yanxindong/anaconda/envs/eva/lib/python3.8/site-packages/wandb/sdk/internal/internal_api.py", line 2758, in upload_file
    response = self._upload_file_session.put(
  File "/home/yanxindong/anaconda/envs/eva/lib/python3.8/site-packages/requests/sessions.py", line 590, in put
    return self.request('PUT', url, data=data, **kwargs)
  File "/home/yanxindong/anaconda/envs/eva/lib/python3.8/site-packages/requests/sessions.py", line 530, in request
    resp = self.send(prep, **send_kwargs)
  File "/home/yanxindong/anaconda/envs/eva/lib/python3.8/site-packages/requests/sessions.py", line 643, in send
    r = adapter.send(request, **kwargs)
  File "/home/yanxindong/anaconda/envs/eva/lib/python3.8/site-packages/requests/adapters.py", line 516, in send
    raise ConnectionError(e, request=request)
wandb.sdk.lib.retry.TransientError: None
2024-01-30 16:10:43,474 DEBUG   HandlerThread:1134320 [handler.py:handle_request():146] handle_request: status_report
2024-01-30 16:10:44,510 ERROR   wandb-upload_0:1134320 [internal_api.py:upload_file():2765] upload_file exception https://storage.googleapis.com/wandb-production.appspot.com/dynamic_x/bert_pytorch/wn1qxvno/wandb-metadata.json?Expires=1706688636&GoogleAccessId=gorilla-files-url-signer-man%40wandb-production.iam.gserviceaccount.com&Signature=X2NQsRBPxmFG1jesoKIgaYH%2BEuVtOiN9iCNyn2nXM0cUCfxLAaAA%2Bk3hpaoW2l5axIqryRk6aj9eSNHiDB95u6Hf7uUfIhqHdFIO604O3XU8FxsVDC6sl62BCb5Gv1YZELF0wwnCYUabk5D8%2BySwHmTL5L192XcYTZiRY5RNvkX0XbkI1VhcZpRvVUboO783c0aYk3HaH9AjjVpNUOz6AP7oNYdWa%2BBqjD6KY4lDz4ppjtGJyClpzP%2BXvNyhrL2ChSQrgKLmg7wKvTV5yciTtM7q8830QL9WNkUPXUkfHDQyMFS62jtzEAulOBw9PlxFnSMtX64IMtAkZcBi0zA25A%3D%3D: HTTPSConnectionPool(host='storage.googleapis.com', port=443): Max retries exceeded with url: /wandb-production.appspot.com/dynamic_x/bert_pytorch/wn1qxvno/wandb-metadata.json?Expires=1706688636&GoogleAccessId=gorilla-files-url-signer-man%40wandb-production.iam.gserviceaccount.com&Signature=X2NQsRBPxmFG1jesoKIgaYH%2BEuVtOiN9iCNyn2nXM0cUCfxLAaAA%2Bk3hpaoW2l5axIqryRk6aj9eSNHiDB95u6Hf7uUfIhqHdFIO604O3XU8FxsVDC6sl62BCb5Gv1YZELF0wwnCYUabk5D8%2BySwHmTL5L192XcYTZiRY5RNvkX0XbkI1VhcZpRvVUboO783c0aYk3HaH9AjjVpNUOz6AP7oNYdWa%2BBqjD6KY4lDz4ppjtGJyClpzP%2BXvNyhrL2ChSQrgKLmg7wKvTV5yciTtM7q8830QL9WNkUPXUkfHDQyMFS62jtzEAulOBw9PlxFnSMtX64IMtAkZcBi0zA25A%3D%3D (Caused by NewConnectionError('<urllib3.connection.HTTPSConnection object at 0x7f47d45ff100>: Failed to establish a new connection: [Errno 111] Connection refused'))
2024-01-30 16:10:44,510 ERROR   wandb-upload_0:1134320 [internal_api.py:upload_file():2767] upload_file request headers: {'User-Agent': 'python-requests/2.23.0', 'Accept-Encoding': 'gzip, deflate', 'Accept': '*/*', 'Connection': 'keep-alive', 'Content-Length': '15553'}
2024-01-30 16:10:44,510 ERROR   wandb-upload_0:1134320 [internal_api.py:upload_file():2769] upload_file response body: 
2024-01-30 16:10:44,807 INFO    Thread-12 :1134320 [dir_watcher.py:_on_file_modified():288] file/dir modified: /home/yanxindong/mkor/bert/wandb/run-20240130_161012-wn1qxvno/files/config.yaml
2024-01-30 16:10:49,417 DEBUG   HandlerThread:1134320 [handler.py:handle_request():146] handle_request: status_report
2024-01-30 16:10:50,954 DEBUG   HandlerThread:1134320 [handler.py:handle_request():146] handle_request: stop_status
2024-01-30 16:10:50,954 DEBUG   SenderThread:1134320 [sender.py:send_request():409] send_request: stop_status
2024-01-30 16:10:50,995 DEBUG   HandlerThread:1134320 [handler.py:handle_request():146] handle_request: internal_messages
2024-01-30 16:10:54,006 ERROR   wandb-upload_0:1134320 [internal_api.py:upload_file():2765] upload_file exception https://storage.googleapis.com/wandb-production.appspot.com/dynamic_x/bert_pytorch/wn1qxvno/wandb-metadata.json?Expires=1706688636&GoogleAccessId=gorilla-files-url-signer-man%40wandb-production.iam.gserviceaccount.com&Signature=X2NQsRBPxmFG1jesoKIgaYH%2BEuVtOiN9iCNyn2nXM0cUCfxLAaAA%2Bk3hpaoW2l5axIqryRk6aj9eSNHiDB95u6Hf7uUfIhqHdFIO604O3XU8FxsVDC6sl62BCb5Gv1YZELF0wwnCYUabk5D8%2BySwHmTL5L192XcYTZiRY5RNvkX0XbkI1VhcZpRvVUboO783c0aYk3HaH9AjjVpNUOz6AP7oNYdWa%2BBqjD6KY4lDz4ppjtGJyClpzP%2BXvNyhrL2ChSQrgKLmg7wKvTV5yciTtM7q8830QL9WNkUPXUkfHDQyMFS62jtzEAulOBw9PlxFnSMtX64IMtAkZcBi0zA25A%3D%3D: HTTPSConnectionPool(host='storage.googleapis.com', port=443): Max retries exceeded with url: /wandb-production.appspot.com/dynamic_x/bert_pytorch/wn1qxvno/wandb-metadata.json?Expires=1706688636&GoogleAccessId=gorilla-files-url-signer-man%40wandb-production.iam.gserviceaccount.com&Signature=X2NQsRBPxmFG1jesoKIgaYH%2BEuVtOiN9iCNyn2nXM0cUCfxLAaAA%2Bk3hpaoW2l5axIqryRk6aj9eSNHiDB95u6Hf7uUfIhqHdFIO604O3XU8FxsVDC6sl62BCb5Gv1YZELF0wwnCYUabk5D8%2BySwHmTL5L192XcYTZiRY5RNvkX0XbkI1VhcZpRvVUboO783c0aYk3HaH9AjjVpNUOz6AP7oNYdWa%2BBqjD6KY4lDz4ppjtGJyClpzP%2BXvNyhrL2ChSQrgKLmg7wKvTV5yciTtM7q8830QL9WNkUPXUkfHDQyMFS62jtzEAulOBw9PlxFnSMtX64IMtAkZcBi0zA25A%3D%3D (Caused by NewConnectionError('<urllib3.connection.HTTPSConnection object at 0x7f47d45f8490>: Failed to establish a new connection: [Errno 111] Connection refused'))
2024-01-30 16:10:54,006 ERROR   wandb-upload_0:1134320 [internal_api.py:upload_file():2767] upload_file request headers: {'User-Agent': 'python-requests/2.23.0', 'Accept-Encoding': 'gzip, deflate', 'Accept': '*/*', 'Connection': 'keep-alive', 'Content-Length': '15553'}
2024-01-30 16:10:54,006 ERROR   wandb-upload_0:1134320 [internal_api.py:upload_file():2769] upload_file response body: 
2024-01-30 16:10:55,347 DEBUG   HandlerThread:1134320 [handler.py:handle_request():146] handle_request: status_report
2024-01-30 16:11:00,348 DEBUG   HandlerThread:1134320 [handler.py:handle_request():146] handle_request: status_report
2024-01-30 16:11:05,348 DEBUG   HandlerThread:1134320 [handler.py:handle_request():146] handle_request: status_report
2024-01-30 16:11:05,954 DEBUG   HandlerThread:1134320 [handler.py:handle_request():146] handle_request: stop_status
2024-01-30 16:11:05,954 DEBUG   SenderThread:1134320 [sender.py:send_request():409] send_request: stop_status
2024-01-30 16:11:05,997 DEBUG   HandlerThread:1134320 [handler.py:handle_request():146] handle_request: internal_messages
2024-01-30 16:11:11,035 ERROR   wandb-upload_0:1134320 [internal_api.py:upload_file():2765] upload_file exception https://storage.googleapis.com/wandb-production.appspot.com/dynamic_x/bert_pytorch/wn1qxvno/wandb-metadata.json?Expires=1706688636&GoogleAccessId=gorilla-files-url-signer-man%40wandb-production.iam.gserviceaccount.com&Signature=X2NQsRBPxmFG1jesoKIgaYH%2BEuVtOiN9iCNyn2nXM0cUCfxLAaAA%2Bk3hpaoW2l5axIqryRk6aj9eSNHiDB95u6Hf7uUfIhqHdFIO604O3XU8FxsVDC6sl62BCb5Gv1YZELF0wwnCYUabk5D8%2BySwHmTL5L192XcYTZiRY5RNvkX0XbkI1VhcZpRvVUboO783c0aYk3HaH9AjjVpNUOz6AP7oNYdWa%2BBqjD6KY4lDz4ppjtGJyClpzP%2BXvNyhrL2ChSQrgKLmg7wKvTV5yciTtM7q8830QL9WNkUPXUkfHDQyMFS62jtzEAulOBw9PlxFnSMtX64IMtAkZcBi0zA25A%3D%3D: HTTPSConnectionPool(host='storage.googleapis.com', port=443): Max retries exceeded with url: /wandb-production.appspot.com/dynamic_x/bert_pytorch/wn1qxvno/wandb-metadata.json?Expires=1706688636&GoogleAccessId=gorilla-files-url-signer-man%40wandb-production.iam.gserviceaccount.com&Signature=X2NQsRBPxmFG1jesoKIgaYH%2BEuVtOiN9iCNyn2nXM0cUCfxLAaAA%2Bk3hpaoW2l5axIqryRk6aj9eSNHiDB95u6Hf7uUfIhqHdFIO604O3XU8FxsVDC6sl62BCb5Gv1YZELF0wwnCYUabk5D8%2BySwHmTL5L192XcYTZiRY5RNvkX0XbkI1VhcZpRvVUboO783c0aYk3HaH9AjjVpNUOz6AP7oNYdWa%2BBqjD6KY4lDz4ppjtGJyClpzP%2BXvNyhrL2ChSQrgKLmg7wKvTV5yciTtM7q8830QL9WNkUPXUkfHDQyMFS62jtzEAulOBw9PlxFnSMtX64IMtAkZcBi0zA25A%3D%3D (Caused by NewConnectionError('<urllib3.connection.HTTPSConnection object at 0x7f47d463c7c0>: Failed to establish a new connection: [Errno 111] Connection refused'))
2024-01-30 16:11:11,035 ERROR   wandb-upload_0:1134320 [internal_api.py:upload_file():2767] upload_file request headers: {'User-Agent': 'python-requests/2.23.0', 'Accept-Encoding': 'gzip, deflate', 'Accept': '*/*', 'Connection': 'keep-alive', 'Content-Length': '15553'}
2024-01-30 16:11:11,035 ERROR   wandb-upload_0:1134320 [internal_api.py:upload_file():2769] upload_file response body: 
2024-01-30 16:11:11,262 DEBUG   HandlerThread:1134320 [handler.py:handle_request():146] handle_request: status_report
2024-01-30 16:11:14,801 DEBUG   SystemMonitor:1134320 [system_monitor.py:_start():172] Starting system metrics aggregation loop
2024-01-30 16:11:14,805 DEBUG   SenderThread:1134320 [sender.py:send():382] send: stats
2024-01-30 16:11:16,806 DEBUG   HandlerThread:1134320 [handler.py:handle_request():146] handle_request: status_report
2024-01-30 16:11:20,954 DEBUG   HandlerThread:1134320 [handler.py:handle_request():146] handle_request: stop_status
2024-01-30 16:11:20,955 DEBUG   SenderThread:1134320 [sender.py:send_request():409] send_request: stop_status
2024-01-30 16:11:20,997 DEBUG   HandlerThread:1134320 [handler.py:handle_request():146] handle_request: internal_messages
2024-01-30 16:11:22,293 DEBUG   HandlerThread:1134320 [handler.py:handle_request():146] handle_request: status_report
2024-01-30 16:11:27,310 DEBUG   HandlerThread:1134320 [handler.py:handle_request():146] handle_request: status_report
2024-01-30 16:11:32,416 DEBUG   HandlerThread:1134320 [handler.py:handle_request():146] handle_request: status_report
2024-01-30 16:11:35,954 DEBUG   HandlerThread:1134320 [handler.py:handle_request():146] handle_request: stop_status
2024-01-30 16:11:35,955 DEBUG   SenderThread:1134320 [sender.py:send_request():409] send_request: stop_status
2024-01-30 16:11:36,025 DEBUG   HandlerThread:1134320 [handler.py:handle_request():146] handle_request: internal_messages
2024-01-30 16:11:38,305 DEBUG   HandlerThread:1134320 [handler.py:handle_request():146] handle_request: status_report
2024-01-30 16:11:43,306 DEBUG   HandlerThread:1134320 [handler.py:handle_request():146] handle_request: status_report
2024-01-30 16:11:44,808 DEBUG   SenderThread:1134320 [sender.py:send():382] send: stats
2024-01-30 16:11:48,809 DEBUG   HandlerThread:1134320 [handler.py:handle_request():146] handle_request: status_report
2024-01-30 16:11:49,182 ERROR   wandb-upload_0:1134320 [internal_api.py:upload_file():2765] upload_file exception https://storage.googleapis.com/wandb-production.appspot.com/dynamic_x/bert_pytorch/wn1qxvno/wandb-metadata.json?Expires=1706688636&GoogleAccessId=gorilla-files-url-signer-man%40wandb-production.iam.gserviceaccount.com&Signature=X2NQsRBPxmFG1jesoKIgaYH%2BEuVtOiN9iCNyn2nXM0cUCfxLAaAA%2Bk3hpaoW2l5axIqryRk6aj9eSNHiDB95u6Hf7uUfIhqHdFIO604O3XU8FxsVDC6sl62BCb5Gv1YZELF0wwnCYUabk5D8%2BySwHmTL5L192XcYTZiRY5RNvkX0XbkI1VhcZpRvVUboO783c0aYk3HaH9AjjVpNUOz6AP7oNYdWa%2BBqjD6KY4lDz4ppjtGJyClpzP%2BXvNyhrL2ChSQrgKLmg7wKvTV5yciTtM7q8830QL9WNkUPXUkfHDQyMFS62jtzEAulOBw9PlxFnSMtX64IMtAkZcBi0zA25A%3D%3D: HTTPSConnectionPool(host='storage.googleapis.com', port=443): Max retries exceeded with url: /wandb-production.appspot.com/dynamic_x/bert_pytorch/wn1qxvno/wandb-metadata.json?Expires=1706688636&GoogleAccessId=gorilla-files-url-signer-man%40wandb-production.iam.gserviceaccount.com&Signature=X2NQsRBPxmFG1jesoKIgaYH%2BEuVtOiN9iCNyn2nXM0cUCfxLAaAA%2Bk3hpaoW2l5axIqryRk6aj9eSNHiDB95u6Hf7uUfIhqHdFIO604O3XU8FxsVDC6sl62BCb5Gv1YZELF0wwnCYUabk5D8%2BySwHmTL5L192XcYTZiRY5RNvkX0XbkI1VhcZpRvVUboO783c0aYk3HaH9AjjVpNUOz6AP7oNYdWa%2BBqjD6KY4lDz4ppjtGJyClpzP%2BXvNyhrL2ChSQrgKLmg7wKvTV5yciTtM7q8830QL9WNkUPXUkfHDQyMFS62jtzEAulOBw9PlxFnSMtX64IMtAkZcBi0zA25A%3D%3D (Caused by NewConnectionError('<urllib3.connection.HTTPSConnection object at 0x7f47d45f8280>: Failed to establish a new connection: [Errno 101] Network is unreachable'))
2024-01-30 16:11:49,182 ERROR   wandb-upload_0:1134320 [internal_api.py:upload_file():2767] upload_file request headers: {'User-Agent': 'python-requests/2.23.0', 'Accept-Encoding': 'gzip, deflate', 'Accept': '*/*', 'Connection': 'keep-alive', 'Content-Length': '15553'}
2024-01-30 16:11:49,182 ERROR   wandb-upload_0:1134320 [internal_api.py:upload_file():2769] upload_file response body: 
2024-01-30 16:11:50,955 DEBUG   HandlerThread:1134320 [handler.py:handle_request():146] handle_request: stop_status
2024-01-30 16:11:50,955 DEBUG   SenderThread:1134320 [sender.py:send_request():409] send_request: stop_status
2024-01-30 16:11:50,997 DEBUG   HandlerThread:1134320 [handler.py:handle_request():146] handle_request: internal_messages
2024-01-30 16:11:54,247 DEBUG   HandlerThread:1134320 [handler.py:handle_request():146] handle_request: status_report
2024-01-30 16:11:55,985 INFO    Thread-12 :1134320 [dir_watcher.py:_on_file_created():271] file/dir created: /home/yanxindong/mkor/bert/wandb/run-20240130_161012-wn1qxvno/files/output.log
2024-01-30 16:11:57,985 INFO    Thread-12 :1134320 [dir_watcher.py:_on_file_modified():288] file/dir modified: /home/yanxindong/mkor/bert/wandb/run-20240130_161012-wn1qxvno/files/output.log
2024-01-30 16:12:00,236 DEBUG   HandlerThread:1134320 [handler.py:handle_request():146] handle_request: status_report
2024-01-30 16:12:05,236 DEBUG   HandlerThread:1134320 [handler.py:handle_request():146] handle_request: status_report
2024-01-30 16:12:09,878 DEBUG   HandlerThread:1134320 [handler.py:handle_request():146] handle_request: stop_status
2024-01-30 16:12:09,878 DEBUG   SenderThread:1134320 [sender.py:send_request():409] send_request: stop_status
2024-01-30 16:12:09,881 DEBUG   HandlerThread:1134320 [handler.py:handle_request():146] handle_request: internal_messages
2024-01-30 16:12:10,310 DEBUG   HandlerThread:1134320 [handler.py:handle_request():146] handle_request: status_report
2024-01-30 16:12:14,810 DEBUG   SenderThread:1134320 [sender.py:send():382] send: stats
2024-01-30 16:12:15,899 DEBUG   HandlerThread:1134320 [handler.py:handle_request():146] handle_request: status_report
2024-01-30 16:12:21,118 DEBUG   HandlerThread:1134320 [handler.py:handle_request():146] handle_request: status_report
2024-01-30 16:12:24,878 DEBUG   HandlerThread:1134320 [handler.py:handle_request():146] handle_request: internal_messages
2024-01-30 16:12:24,878 DEBUG   HandlerThread:1134320 [handler.py:handle_request():146] handle_request: stop_status
2024-01-30 16:12:24,878 DEBUG   SenderThread:1134320 [sender.py:send_request():409] send_request: stop_status
2024-01-30 16:12:26,222 DEBUG   HandlerThread:1134320 [handler.py:handle_request():146] handle_request: status_report
2024-01-30 16:12:31,282 DEBUG   HandlerThread:1134320 [handler.py:handle_request():146] handle_request: status_report
2024-01-30 16:12:36,443 DEBUG   HandlerThread:1134320 [handler.py:handle_request():146] handle_request: status_report
2024-01-30 16:12:39,878 DEBUG   HandlerThread:1134320 [handler.py:handle_request():146] handle_request: internal_messages
2024-01-30 16:12:39,878 DEBUG   HandlerThread:1134320 [handler.py:handle_request():146] handle_request: stop_status
2024-01-30 16:12:39,878 DEBUG   SenderThread:1134320 [sender.py:send_request():409] send_request: stop_status
2024-01-30 16:12:42,245 DEBUG   HandlerThread:1134320 [handler.py:handle_request():146] handle_request: status_report
2024-01-30 16:12:44,812 DEBUG   SenderThread:1134320 [sender.py:send():382] send: stats
2024-01-30 16:12:47,814 DEBUG   HandlerThread:1134320 [handler.py:handle_request():146] handle_request: status_report
2024-01-30 16:12:53,443 DEBUG   HandlerThread:1134320 [handler.py:handle_request():146] handle_request: status_report
2024-01-30 16:12:54,878 DEBUG   HandlerThread:1134320 [handler.py:handle_request():146] handle_request: internal_messages
2024-01-30 16:12:54,878 DEBUG   HandlerThread:1134320 [handler.py:handle_request():146] handle_request: stop_status
2024-01-30 16:12:54,879 DEBUG   SenderThread:1134320 [sender.py:send_request():409] send_request: stop_status
2024-01-30 16:12:56,578 ERROR   wandb-upload_0:1134320 [internal_api.py:upload_file():2765] upload_file exception https://storage.googleapis.com/wandb-production.appspot.com/dynamic_x/bert_pytorch/wn1qxvno/wandb-metadata.json?Expires=1706688636&GoogleAccessId=gorilla-files-url-signer-man%40wandb-production.iam.gserviceaccount.com&Signature=X2NQsRBPxmFG1jesoKIgaYH%2BEuVtOiN9iCNyn2nXM0cUCfxLAaAA%2Bk3hpaoW2l5axIqryRk6aj9eSNHiDB95u6Hf7uUfIhqHdFIO604O3XU8FxsVDC6sl62BCb5Gv1YZELF0wwnCYUabk5D8%2BySwHmTL5L192XcYTZiRY5RNvkX0XbkI1VhcZpRvVUboO783c0aYk3HaH9AjjVpNUOz6AP7oNYdWa%2BBqjD6KY4lDz4ppjtGJyClpzP%2BXvNyhrL2ChSQrgKLmg7wKvTV5yciTtM7q8830QL9WNkUPXUkfHDQyMFS62jtzEAulOBw9PlxFnSMtX64IMtAkZcBi0zA25A%3D%3D: HTTPSConnectionPool(host='storage.googleapis.com', port=443): Max retries exceeded with url: /wandb-production.appspot.com/dynamic_x/bert_pytorch/wn1qxvno/wandb-metadata.json?Expires=1706688636&GoogleAccessId=gorilla-files-url-signer-man%40wandb-production.iam.gserviceaccount.com&Signature=X2NQsRBPxmFG1jesoKIgaYH%2BEuVtOiN9iCNyn2nXM0cUCfxLAaAA%2Bk3hpaoW2l5axIqryRk6aj9eSNHiDB95u6Hf7uUfIhqHdFIO604O3XU8FxsVDC6sl62BCb5Gv1YZELF0wwnCYUabk5D8%2BySwHmTL5L192XcYTZiRY5RNvkX0XbkI1VhcZpRvVUboO783c0aYk3HaH9AjjVpNUOz6AP7oNYdWa%2BBqjD6KY4lDz4ppjtGJyClpzP%2BXvNyhrL2ChSQrgKLmg7wKvTV5yciTtM7q8830QL9WNkUPXUkfHDQyMFS62jtzEAulOBw9PlxFnSMtX64IMtAkZcBi0zA25A%3D%3D (Caused by NewConnectionError('<urllib3.connection.HTTPSConnection object at 0x7f47d4479b20>: Failed to establish a new connection: [Errno 101] Network is unreachable'))
2024-01-30 16:12:56,578 ERROR   wandb-upload_0:1134320 [internal_api.py:upload_file():2767] upload_file request headers: {'User-Agent': 'python-requests/2.23.0', 'Accept-Encoding': 'gzip, deflate', 'Accept': '*/*', 'Connection': 'keep-alive', 'Content-Length': '15553'}
2024-01-30 16:12:56,578 ERROR   wandb-upload_0:1134320 [internal_api.py:upload_file():2769] upload_file response body: 
2024-01-30 16:12:59,169 DEBUG   HandlerThread:1134320 [handler.py:handle_request():146] handle_request: status_report
2024-01-30 16:13:04,170 DEBUG   HandlerThread:1134320 [handler.py:handle_request():146] handle_request: status_report
2024-01-30 16:13:09,443 DEBUG   HandlerThread:1134320 [handler.py:handle_request():146] handle_request: status_report
2024-01-30 16:13:09,878 DEBUG   HandlerThread:1134320 [handler.py:handle_request():146] handle_request: internal_messages
2024-01-30 16:13:09,879 DEBUG   HandlerThread:1134320 [handler.py:handle_request():146] handle_request: stop_status
2024-01-30 16:13:09,879 DEBUG   SenderThread:1134320 [sender.py:send_request():409] send_request: stop_status
2024-01-30 16:13:14,836 DEBUG   SenderThread:1134320 [sender.py:send():382] send: stats
2024-01-30 16:13:14,838 DEBUG   HandlerThread:1134320 [handler.py:handle_request():146] handle_request: status_report
2024-01-30 16:13:19,909 DEBUG   HandlerThread:1134320 [handler.py:handle_request():146] handle_request: status_report
2024-01-30 16:13:24,945 DEBUG   HandlerThread:1134320 [handler.py:handle_request():146] handle_request: internal_messages
2024-01-30 16:13:24,946 DEBUG   HandlerThread:1134320 [handler.py:handle_request():146] handle_request: stop_status
2024-01-30 16:13:24,946 DEBUG   SenderThread:1134320 [sender.py:send_request():409] send_request: stop_status
2024-01-30 16:13:25,221 DEBUG   HandlerThread:1134320 [handler.py:handle_request():146] handle_request: status_report
2024-01-30 16:13:30,278 DEBUG   HandlerThread:1134320 [handler.py:handle_request():146] handle_request: status_report
2024-01-30 16:13:35,387 DEBUG   HandlerThread:1134320 [handler.py:handle_request():146] handle_request: status_report
2024-01-30 16:13:39,905 DEBUG   HandlerThread:1134320 [handler.py:handle_request():146] handle_request: internal_messages
2024-01-30 16:13:39,906 DEBUG   HandlerThread:1134320 [handler.py:handle_request():146] handle_request: stop_status
2024-01-30 16:13:39,906 DEBUG   SenderThread:1134320 [sender.py:send_request():409] send_request: stop_status
2024-01-30 16:13:41,259 DEBUG   HandlerThread:1134320 [handler.py:handle_request():146] handle_request: status_report
2024-01-30 16:13:44,838 DEBUG   SenderThread:1134320 [sender.py:send():382] send: stats
2024-01-30 16:13:46,840 DEBUG   HandlerThread:1134320 [handler.py:handle_request():146] handle_request: status_report
2024-01-30 16:13:52,444 DEBUG   HandlerThread:1134320 [handler.py:handle_request():146] handle_request: status_report
2024-01-30 16:13:54,878 DEBUG   HandlerThread:1134320 [handler.py:handle_request():146] handle_request: internal_messages
2024-01-30 16:13:54,879 DEBUG   HandlerThread:1134320 [handler.py:handle_request():146] handle_request: stop_status
2024-01-30 16:13:54,879 DEBUG   SenderThread:1134320 [sender.py:send_request():409] send_request: stop_status
2024-01-30 16:13:58,230 DEBUG   HandlerThread:1134320 [handler.py:handle_request():146] handle_request: status_report
2024-01-30 16:14:03,230 DEBUG   HandlerThread:1134320 [handler.py:handle_request():146] handle_request: status_report
2024-01-30 16:14:08,444 DEBUG   HandlerThread:1134320 [handler.py:handle_request():146] handle_request: status_report
2024-01-30 16:14:09,878 DEBUG   HandlerThread:1134320 [handler.py:handle_request():146] handle_request: internal_messages
2024-01-30 16:14:09,879 DEBUG   HandlerThread:1134320 [handler.py:handle_request():146] handle_request: stop_status
2024-01-30 16:14:09,879 DEBUG   SenderThread:1134320 [sender.py:send_request():409] send_request: stop_status
2024-01-30 16:14:14,137 DEBUG   HandlerThread:1134320 [handler.py:handle_request():146] handle_request: status_report
2024-01-30 16:14:14,840 DEBUG   SenderThread:1134320 [sender.py:send():382] send: stats
2024-01-30 16:14:19,938 DEBUG   HandlerThread:1134320 [handler.py:handle_request():146] handle_request: status_report
2024-01-30 16:14:24,878 DEBUG   HandlerThread:1134320 [handler.py:handle_request():146] handle_request: internal_messages
2024-01-30 16:14:24,879 DEBUG   HandlerThread:1134320 [handler.py:handle_request():146] handle_request: stop_status
2024-01-30 16:14:24,879 DEBUG   SenderThread:1134320 [sender.py:send_request():409] send_request: stop_status
2024-01-30 16:14:25,161 DEBUG   HandlerThread:1134320 [handler.py:handle_request():146] handle_request: status_report
2024-01-30 16:14:30,229 DEBUG   HandlerThread:1134320 [handler.py:handle_request():146] handle_request: status_report
2024-01-30 16:14:35,289 DEBUG   HandlerThread:1134320 [handler.py:handle_request():146] handle_request: status_report
2024-01-30 16:14:39,953 DEBUG   HandlerThread:1134320 [handler.py:handle_request():146] handle_request: internal_messages
2024-01-30 16:14:39,953 DEBUG   HandlerThread:1134320 [handler.py:handle_request():146] handle_request: stop_status
2024-01-30 16:14:39,953 DEBUG   SenderThread:1134320 [sender.py:send_request():409] send_request: stop_status
2024-01-30 16:14:41,293 DEBUG   HandlerThread:1134320 [handler.py:handle_request():146] handle_request: status_report
2024-01-30 16:14:44,842 DEBUG   SenderThread:1134320 [sender.py:send():382] send: stats
2024-01-30 16:14:46,843 DEBUG   HandlerThread:1134320 [handler.py:handle_request():146] handle_request: status_report
2024-01-30 16:14:52,444 DEBUG   HandlerThread:1134320 [handler.py:handle_request():146] handle_request: status_report
2024-01-30 16:14:54,878 DEBUG   HandlerThread:1134320 [handler.py:handle_request():146] handle_request: internal_messages
2024-01-30 16:14:54,879 DEBUG   HandlerThread:1134320 [handler.py:handle_request():146] handle_request: stop_status
2024-01-30 16:14:54,879 DEBUG   SenderThread:1134320 [sender.py:send_request():409] send_request: stop_status
2024-01-30 16:14:58,254 DEBUG   HandlerThread:1134320 [handler.py:handle_request():146] handle_request: status_report
2024-01-30 16:15:03,255 DEBUG   HandlerThread:1134320 [handler.py:handle_request():146] handle_request: status_report
2024-01-30 16:15:08,444 DEBUG   HandlerThread:1134320 [handler.py:handle_request():146] handle_request: status_report
2024-01-30 16:15:09,878 DEBUG   HandlerThread:1134320 [handler.py:handle_request():146] handle_request: internal_messages
2024-01-30 16:15:09,879 DEBUG   HandlerThread:1134320 [handler.py:handle_request():146] handle_request: stop_status
2024-01-30 16:15:09,879 DEBUG   SenderThread:1134320 [sender.py:send_request():409] send_request: stop_status
2024-01-30 16:15:10,982 ERROR   wandb-upload_0:1134320 [internal_api.py:upload_file():2765] upload_file exception https://storage.googleapis.com/wandb-production.appspot.com/dynamic_x/bert_pytorch/wn1qxvno/wandb-metadata.json?Expires=1706688636&GoogleAccessId=gorilla-files-url-signer-man%40wandb-production.iam.gserviceaccount.com&Signature=X2NQsRBPxmFG1jesoKIgaYH%2BEuVtOiN9iCNyn2nXM0cUCfxLAaAA%2Bk3hpaoW2l5axIqryRk6aj9eSNHiDB95u6Hf7uUfIhqHdFIO604O3XU8FxsVDC6sl62BCb5Gv1YZELF0wwnCYUabk5D8%2BySwHmTL5L192XcYTZiRY5RNvkX0XbkI1VhcZpRvVUboO783c0aYk3HaH9AjjVpNUOz6AP7oNYdWa%2BBqjD6KY4lDz4ppjtGJyClpzP%2BXvNyhrL2ChSQrgKLmg7wKvTV5yciTtM7q8830QL9WNkUPXUkfHDQyMFS62jtzEAulOBw9PlxFnSMtX64IMtAkZcBi0zA25A%3D%3D: HTTPSConnectionPool(host='storage.googleapis.com', port=443): Max retries exceeded with url: /wandb-production.appspot.com/dynamic_x/bert_pytorch/wn1qxvno/wandb-metadata.json?Expires=1706688636&GoogleAccessId=gorilla-files-url-signer-man%40wandb-production.iam.gserviceaccount.com&Signature=X2NQsRBPxmFG1jesoKIgaYH%2BEuVtOiN9iCNyn2nXM0cUCfxLAaAA%2Bk3hpaoW2l5axIqryRk6aj9eSNHiDB95u6Hf7uUfIhqHdFIO604O3XU8FxsVDC6sl62BCb5Gv1YZELF0wwnCYUabk5D8%2BySwHmTL5L192XcYTZiRY5RNvkX0XbkI1VhcZpRvVUboO783c0aYk3HaH9AjjVpNUOz6AP7oNYdWa%2BBqjD6KY4lDz4ppjtGJyClpzP%2BXvNyhrL2ChSQrgKLmg7wKvTV5yciTtM7q8830QL9WNkUPXUkfHDQyMFS62jtzEAulOBw9PlxFnSMtX64IMtAkZcBi0zA25A%3D%3D (Caused by NewConnectionError('<urllib3.connection.HTTPSConnection object at 0x7f47d45f89d0>: Failed to establish a new connection: [Errno 101] Network is unreachable'))
2024-01-30 16:15:10,983 ERROR   wandb-upload_0:1134320 [internal_api.py:upload_file():2767] upload_file request headers: {'User-Agent': 'python-requests/2.23.0', 'Accept-Encoding': 'gzip, deflate', 'Accept': '*/*', 'Connection': 'keep-alive', 'Content-Length': '15553'}
2024-01-30 16:15:10,983 ERROR   wandb-upload_0:1134320 [internal_api.py:upload_file():2769] upload_file response body: 
2024-01-30 16:15:14,306 DEBUG   HandlerThread:1134320 [handler.py:handle_request():146] handle_request: status_report
2024-01-30 16:15:14,845 DEBUG   SenderThread:1134320 [sender.py:send():382] send: stats
2024-01-30 16:15:19,846 DEBUG   HandlerThread:1134320 [handler.py:handle_request():146] handle_request: status_report
2024-01-30 16:15:24,879 DEBUG   HandlerThread:1134320 [handler.py:handle_request():146] handle_request: internal_messages
2024-01-30 16:15:24,879 DEBUG   HandlerThread:1134320 [handler.py:handle_request():146] handle_request: stop_status
2024-01-30 16:15:24,879 DEBUG   SenderThread:1134320 [sender.py:send_request():409] send_request: stop_status
2024-01-30 16:15:25,210 DEBUG   HandlerThread:1134320 [handler.py:handle_request():146] handle_request: status_report
2024-01-30 16:15:30,315 DEBUG   HandlerThread:1134320 [handler.py:handle_request():146] handle_request: status_report
2024-01-30 16:15:35,346 DEBUG   HandlerThread:1134320 [handler.py:handle_request():146] handle_request: status_report
2024-01-30 16:15:37,793 DEBUG   SenderThread:1134320 [sender.py:send():382] send: exit
2024-01-30 16:15:37,794 INFO    SenderThread:1134320 [sender.py:send_exit():589] handling exit code: 1
2024-01-30 16:15:37,794 INFO    SenderThread:1134320 [sender.py:send_exit():591] handling runtime: 323
2024-01-30 16:15:37,794 INFO    SenderThread:1134320 [sender.py:_save_file():1403] saving file wandb-summary.json with policy end
2024-01-30 16:15:37,794 INFO    SenderThread:1134320 [sender.py:send_exit():597] send defer
2024-01-30 16:15:37,795 DEBUG   HandlerThread:1134320 [handler.py:handle_request():146] handle_request: defer
2024-01-30 16:15:37,795 INFO    HandlerThread:1134320 [handler.py:handle_request_defer():172] handle defer: 0
2024-01-30 16:15:37,795 DEBUG   SenderThread:1134320 [sender.py:send_request():409] send_request: defer
2024-01-30 16:15:37,795 INFO    SenderThread:1134320 [sender.py:send_request_defer():613] handle sender defer: 0
2024-01-30 16:15:37,795 INFO    SenderThread:1134320 [sender.py:transition_state():617] send defer: 1
2024-01-30 16:15:37,795 DEBUG   HandlerThread:1134320 [handler.py:handle_request():146] handle_request: defer
2024-01-30 16:15:37,795 INFO    HandlerThread:1134320 [handler.py:handle_request_defer():172] handle defer: 1
2024-01-30 16:15:37,795 DEBUG   SenderThread:1134320 [sender.py:send_request():409] send_request: defer
2024-01-30 16:15:37,795 INFO    SenderThread:1134320 [sender.py:send_request_defer():613] handle sender defer: 1
2024-01-30 16:15:37,795 INFO    SenderThread:1134320 [sender.py:transition_state():617] send defer: 2
2024-01-30 16:15:37,795 DEBUG   HandlerThread:1134320 [handler.py:handle_request():146] handle_request: defer
2024-01-30 16:15:37,795 INFO    HandlerThread:1134320 [handler.py:handle_request_defer():172] handle defer: 2
2024-01-30 16:15:37,795 INFO    HandlerThread:1134320 [system_monitor.py:finish():203] Stopping system monitor
2024-01-30 16:15:37,796 DEBUG   SystemMonitor:1134320 [system_monitor.py:_start():179] Finished system metrics aggregation loop
2024-01-30 16:15:37,796 DEBUG   SystemMonitor:1134320 [system_monitor.py:_start():183] Publishing last batch of metrics
2024-01-30 16:15:37,798 INFO    HandlerThread:1134320 [interfaces.py:finish():202] Joined cpu monitor
2024-01-30 16:15:37,805 INFO    HandlerThread:1134320 [interfaces.py:finish():202] Joined disk monitor
2024-01-30 16:15:38,682 INFO    Thread-12 :1134320 [dir_watcher.py:_on_file_created():271] file/dir created: /home/yanxindong/mkor/bert/wandb/run-20240130_161012-wn1qxvno/files/wandb-summary.json
2024-01-30 16:15:40,806 INFO    Thread-12 :1134320 [dir_watcher.py:_on_file_modified():288] file/dir modified: /home/yanxindong/mkor/bert/wandb/run-20240130_161012-wn1qxvno/files/output.log
2024-01-30 16:15:45,388 INFO    HandlerThread:1134320 [interfaces.py:finish():202] Joined gpu monitor
2024-01-30 16:15:45,388 INFO    HandlerThread:1134320 [interfaces.py:finish():202] Joined memory monitor
2024-01-30 16:15:45,388 INFO    HandlerThread:1134320 [interfaces.py:finish():202] Joined network monitor
2024-01-30 16:15:45,388 DEBUG   HandlerThread:1134320 [handler.py:handle_request():146] handle_request: poll_exit
2024-01-30 16:15:45,388 DEBUG   HandlerThread:1134320 [handler.py:handle_request():146] handle_request: status_report
2024-01-30 16:15:45,388 DEBUG   HandlerThread:1134320 [handler.py:handle_request():146] handle_request: keepalive
2024-01-30 16:15:45,389 DEBUG   SenderThread:1134320 [sender.py:send_request():409] send_request: defer
2024-01-30 16:15:45,389 INFO    SenderThread:1134320 [sender.py:send_request_defer():613] handle sender defer: 2
2024-01-30 16:15:45,389 INFO    SenderThread:1134320 [sender.py:transition_state():617] send defer: 3
2024-01-30 16:15:45,389 DEBUG   SenderThread:1134320 [sender.py:send():382] send: stats
2024-01-30 16:15:45,390 DEBUG   SenderThread:1134320 [sender.py:send_request():409] send_request: poll_exit
2024-01-30 16:15:45,393 DEBUG   HandlerThread:1134320 [handler.py:handle_request():146] handle_request: defer
2024-01-30 16:15:45,393 INFO    HandlerThread:1134320 [handler.py:handle_request_defer():172] handle defer: 3
2024-01-30 16:15:45,393 DEBUG   SenderThread:1134320 [sender.py:send_request():409] send_request: defer
2024-01-30 16:15:45,393 INFO    SenderThread:1134320 [sender.py:send_request_defer():613] handle sender defer: 3
2024-01-30 16:15:45,393 INFO    SenderThread:1134320 [sender.py:transition_state():617] send defer: 4
2024-01-30 16:15:45,394 DEBUG   HandlerThread:1134320 [handler.py:handle_request():146] handle_request: defer
2024-01-30 16:15:45,394 INFO    HandlerThread:1134320 [handler.py:handle_request_defer():172] handle defer: 4
2024-01-30 16:15:45,394 DEBUG   SenderThread:1134320 [sender.py:send_request():409] send_request: defer
2024-01-30 16:15:45,394 INFO    SenderThread:1134320 [sender.py:send_request_defer():613] handle sender defer: 4
2024-01-30 16:15:45,394 INFO    SenderThread:1134320 [sender.py:transition_state():617] send defer: 5
2024-01-30 16:15:45,394 DEBUG   HandlerThread:1134320 [handler.py:handle_request():146] handle_request: defer
2024-01-30 16:15:45,394 INFO    HandlerThread:1134320 [handler.py:handle_request_defer():172] handle defer: 5
2024-01-30 16:15:45,394 DEBUG   SenderThread:1134320 [sender.py:send():382] send: summary
2024-01-30 16:15:45,394 INFO    SenderThread:1134320 [sender.py:_save_file():1403] saving file wandb-summary.json with policy end
2024-01-30 16:15:45,395 DEBUG   SenderThread:1134320 [sender.py:send_request():409] send_request: defer
2024-01-30 16:15:45,395 INFO    SenderThread:1134320 [sender.py:send_request_defer():613] handle sender defer: 5
2024-01-30 16:15:45,395 INFO    SenderThread:1134320 [sender.py:transition_state():617] send defer: 6
2024-01-30 16:15:45,395 DEBUG   HandlerThread:1134320 [handler.py:handle_request():146] handle_request: defer
2024-01-30 16:15:45,395 INFO    HandlerThread:1134320 [handler.py:handle_request_defer():172] handle defer: 6
2024-01-30 16:15:45,395 DEBUG   SenderThread:1134320 [sender.py:send_request():409] send_request: defer
2024-01-30 16:15:45,395 INFO    SenderThread:1134320 [sender.py:send_request_defer():613] handle sender defer: 6
2024-01-30 16:15:45,395 INFO    SenderThread:1134320 [sender.py:transition_state():617] send defer: 7
2024-01-30 16:15:45,395 DEBUG   HandlerThread:1134320 [handler.py:handle_request():146] handle_request: status_report
2024-01-30 16:15:45,395 DEBUG   HandlerThread:1134320 [handler.py:handle_request():146] handle_request: defer
2024-01-30 16:15:45,395 INFO    HandlerThread:1134320 [handler.py:handle_request_defer():172] handle defer: 7
2024-01-30 16:15:45,395 DEBUG   SenderThread:1134320 [sender.py:send_request():409] send_request: defer
2024-01-30 16:15:45,395 INFO    SenderThread:1134320 [sender.py:send_request_defer():613] handle sender defer: 7
2024-01-30 16:15:45,917 INFO    Thread-12 :1134320 [dir_watcher.py:_on_file_modified():288] file/dir modified: /home/yanxindong/mkor/bert/wandb/run-20240130_161012-wn1qxvno/files/wandb-summary.json
2024-01-30 16:15:45,918 DEBUG   HandlerThread:1134320 [handler.py:handle_request():146] handle_request: poll_exit
2024-01-30 16:15:45,948 INFO    SenderThread:1134320 [sender.py:transition_state():617] send defer: 8
2024-01-30 16:15:45,948 DEBUG   SenderThread:1134320 [sender.py:send_request():409] send_request: poll_exit
2024-01-30 16:15:45,948 DEBUG   HandlerThread:1134320 [handler.py:handle_request():146] handle_request: defer
2024-01-30 16:15:45,949 INFO    HandlerThread:1134320 [handler.py:handle_request_defer():172] handle defer: 8
2024-01-30 16:15:45,949 DEBUG   SenderThread:1134320 [sender.py:send_request():409] send_request: defer
2024-01-30 16:15:45,949 INFO    SenderThread:1134320 [sender.py:send_request_defer():613] handle sender defer: 8
2024-01-30 16:15:45,949 INFO    SenderThread:1134320 [job_builder.py:build():296] Attempting to build job artifact
2024-01-30 16:15:45,949 INFO    SenderThread:1134320 [job_builder.py:_get_source_type():426] is repo sourced job
2024-01-30 16:15:46,294 INFO    SenderThread:1134320 [job_builder.py:build():402] adding wandb-job metadata file
2024-01-30 16:15:46,297 INFO    SenderThread:1134320 [sender.py:transition_state():617] send defer: 9
2024-01-30 16:15:46,297 DEBUG   HandlerThread:1134320 [handler.py:handle_request():146] handle_request: defer
2024-01-30 16:15:46,297 INFO    HandlerThread:1134320 [handler.py:handle_request_defer():172] handle defer: 9
2024-01-30 16:15:46,298 DEBUG   SenderThread:1134320 [sender.py:send():382] send: artifact
2024-01-30 16:15:46,917 INFO    Thread-12 :1134320 [dir_watcher.py:_on_file_modified():288] file/dir modified: /home/yanxindong/mkor/bert/wandb/run-20240130_161012-wn1qxvno/files/output.log
2024-01-30 16:15:46,918 DEBUG   HandlerThread:1134320 [handler.py:handle_request():146] handle_request: poll_exit
2024-01-30 16:15:48,430 ERROR   wandb-upload_1:1134320 [internal_api.py:upload_file():2765] upload_file exception https://storage.googleapis.com/wandb-artifacts-prod/wandb_artifacts/133981200/707679828/174a3d9bc61fec126cc7d5bdff5c6c5a?Expires=1706688948&GoogleAccessId=gorilla-files-url-signer-man%40wandb-production.iam.gserviceaccount.com&Signature=kbovuOHqx1zQ01k2JLv3vSDaYbHItTycqeq2YURNlbD5XRGkUvQrNZxJrbM6osH%2FENF6HvfcT%2BENYNpNC%2BL5OqLe%2FmpPae6eDy6NexFC7Zbbbn9d3G2XLZG9goE9iklwKX4KW1pd0VzWFfTel%2BLXIkIaFS0dWCAz2jiQuMLH7iAEoy5QbiMBP8lhXU9g1jMABHn8GXPrq1BY6Mv11K9TRqNDr05oEvZxddTyDwSBtZ5ywPejT5hE7v2D%2Blbt7shbB8A4xXrB2OflVHzyHKV74RagasqYRZZu0H7uvoCd5JAmTCIIMoiKQTdW3oHWTL%2F1Ja7qj52XwR7z51GvxZVvhg%3D%3D: HTTPSConnectionPool(host='storage.googleapis.com', port=443): Max retries exceeded with url: /wandb-artifacts-prod/wandb_artifacts/133981200/707679828/174a3d9bc61fec126cc7d5bdff5c6c5a?Expires=1706688948&GoogleAccessId=gorilla-files-url-signer-man%40wandb-production.iam.gserviceaccount.com&Signature=kbovuOHqx1zQ01k2JLv3vSDaYbHItTycqeq2YURNlbD5XRGkUvQrNZxJrbM6osH%2FENF6HvfcT%2BENYNpNC%2BL5OqLe%2FmpPae6eDy6NexFC7Zbbbn9d3G2XLZG9goE9iklwKX4KW1pd0VzWFfTel%2BLXIkIaFS0dWCAz2jiQuMLH7iAEoy5QbiMBP8lhXU9g1jMABHn8GXPrq1BY6Mv11K9TRqNDr05oEvZxddTyDwSBtZ5ywPejT5hE7v2D%2Blbt7shbB8A4xXrB2OflVHzyHKV74RagasqYRZZu0H7uvoCd5JAmTCIIMoiKQTdW3oHWTL%2F1Ja7qj52XwR7z51GvxZVvhg%3D%3D (Caused by NewConnectionError('<urllib3.connection.HTTPSConnection object at 0x7f47d46531c0>: Failed to establish a new connection: [Errno 101] Network is unreachable'))
2024-01-30 16:15:48,430 ERROR   wandb-upload_1:1134320 [internal_api.py:upload_file():2767] upload_file request headers: {'User-Agent': 'python-requests/2.23.0', 'Accept-Encoding': 'gzip, deflate', 'Accept': '*/*', 'Connection': 'keep-alive', 'Content-MD5': 'F0o9m8Yf7BJsx9W9/1xsWg==', 'Content-Type': 'text/plain; charset=utf-8', 'Content-Length': '2179'}
2024-01-30 16:15:48,430 ERROR   wandb-upload_1:1134320 [internal_api.py:upload_file():2769] upload_file response body: 
2024-01-30 16:15:49,046 ERROR   wandb-upload_2:1134320 [internal_api.py:upload_file():2765] upload_file exception https://storage.googleapis.com/wandb-artifacts-prod/wandb_artifacts/133981200/707679828/6873c23a2381d1524249eb1a948a45a5?Expires=1706688948&GoogleAccessId=gorilla-files-url-signer-man%40wandb-production.iam.gserviceaccount.com&Signature=c4l7issmW7JLxt%2F5iscJknq14hvYZvtF2GxzULmZuZuFAJ%2F9XDgpKYtL0M4ID77UMZgvwjxdjv6iO1HPm2i%2Fu6ogy7h5xHLRe4rQDX3k94rmTIhO%2FUHArMuR8wQR9%2FNUP2Z9TYpq0bGocaYm5xB2yEK%2BFAAF7JHHKdmu4clQQkzMPRoPoRQbpo1LvqvTBYfG%2F3BaewVmOiLE44F0S9TtUNZHVpHFx0OJyzH54n%2BLCqC4BBokBnRXGMVspDfurrfZTTaqS4bo4Gd113ehd9TNzRIawroe89EdL186rqaseJc6YZuiUYJD8lMZW3j%2Fdcyy%2Fop22jcv9B3fOEsjLcfxfQ%3D%3D: HTTPSConnectionPool(host='storage.googleapis.com', port=443): Max retries exceeded with url: /wandb-artifacts-prod/wandb_artifacts/133981200/707679828/6873c23a2381d1524249eb1a948a45a5?Expires=1706688948&GoogleAccessId=gorilla-files-url-signer-man%40wandb-production.iam.gserviceaccount.com&Signature=c4l7issmW7JLxt%2F5iscJknq14hvYZvtF2GxzULmZuZuFAJ%2F9XDgpKYtL0M4ID77UMZgvwjxdjv6iO1HPm2i%2Fu6ogy7h5xHLRe4rQDX3k94rmTIhO%2FUHArMuR8wQR9%2FNUP2Z9TYpq0bGocaYm5xB2yEK%2BFAAF7JHHKdmu4clQQkzMPRoPoRQbpo1LvqvTBYfG%2F3BaewVmOiLE44F0S9TtUNZHVpHFx0OJyzH54n%2BLCqC4BBokBnRXGMVspDfurrfZTTaqS4bo4Gd113ehd9TNzRIawroe89EdL186rqaseJc6YZuiUYJD8lMZW3j%2Fdcyy%2Fop22jcv9B3fOEsjLcfxfQ%3D%3D (Caused by NewConnectionError('<urllib3.connection.HTTPSConnection object at 0x7f47d4653d30>: Failed to establish a new connection: [Errno 101] Network is unreachable'))
2024-01-30 16:15:49,046 ERROR   wandb-upload_2:1134320 [internal_api.py:upload_file():2767] upload_file request headers: {'User-Agent': 'python-requests/2.23.0', 'Accept-Encoding': 'gzip, deflate', 'Accept': '*/*', 'Connection': 'keep-alive', 'Content-MD5': 'aHPCOiOB0VJCSesalIpFpQ==', 'Content-Type': 'application/json', 'Content-Length': '609'}
2024-01-30 16:15:49,047 ERROR   wandb-upload_2:1134320 [internal_api.py:upload_file():2769] upload_file response body: 
2024-01-30 16:15:49,472 ERROR   wandb-upload_1:1134320 [internal_api.py:upload_file():2765] upload_file exception https://storage.googleapis.com/wandb-artifacts-prod/wandb_artifacts/133981200/707679828/174a3d9bc61fec126cc7d5bdff5c6c5a?Expires=1706688948&GoogleAccessId=gorilla-files-url-signer-man%40wandb-production.iam.gserviceaccount.com&Signature=kbovuOHqx1zQ01k2JLv3vSDaYbHItTycqeq2YURNlbD5XRGkUvQrNZxJrbM6osH%2FENF6HvfcT%2BENYNpNC%2BL5OqLe%2FmpPae6eDy6NexFC7Zbbbn9d3G2XLZG9goE9iklwKX4KW1pd0VzWFfTel%2BLXIkIaFS0dWCAz2jiQuMLH7iAEoy5QbiMBP8lhXU9g1jMABHn8GXPrq1BY6Mv11K9TRqNDr05oEvZxddTyDwSBtZ5ywPejT5hE7v2D%2Blbt7shbB8A4xXrB2OflVHzyHKV74RagasqYRZZu0H7uvoCd5JAmTCIIMoiKQTdW3oHWTL%2F1Ja7qj52XwR7z51GvxZVvhg%3D%3D: HTTPSConnectionPool(host='storage.googleapis.com', port=443): Max retries exceeded with url: /wandb-artifacts-prod/wandb_artifacts/133981200/707679828/174a3d9bc61fec126cc7d5bdff5c6c5a?Expires=1706688948&GoogleAccessId=gorilla-files-url-signer-man%40wandb-production.iam.gserviceaccount.com&Signature=kbovuOHqx1zQ01k2JLv3vSDaYbHItTycqeq2YURNlbD5XRGkUvQrNZxJrbM6osH%2FENF6HvfcT%2BENYNpNC%2BL5OqLe%2FmpPae6eDy6NexFC7Zbbbn9d3G2XLZG9goE9iklwKX4KW1pd0VzWFfTel%2BLXIkIaFS0dWCAz2jiQuMLH7iAEoy5QbiMBP8lhXU9g1jMABHn8GXPrq1BY6Mv11K9TRqNDr05oEvZxddTyDwSBtZ5ywPejT5hE7v2D%2Blbt7shbB8A4xXrB2OflVHzyHKV74RagasqYRZZu0H7uvoCd5JAmTCIIMoiKQTdW3oHWTL%2F1Ja7qj52XwR7z51GvxZVvhg%3D%3D (Caused by NewConnectionError('<urllib3.connection.HTTPSConnection object at 0x7f47d46536a0>: Failed to establish a new connection: [Errno 101] Network is unreachable'))
2024-01-30 16:15:49,472 ERROR   wandb-upload_1:1134320 [internal_api.py:upload_file():2767] upload_file request headers: {'User-Agent': 'python-requests/2.23.0', 'Accept-Encoding': 'gzip, deflate', 'Accept': '*/*', 'Connection': 'keep-alive', 'Content-MD5': 'F0o9m8Yf7BJsx9W9/1xsWg==', 'Content-Type': 'text/plain; charset=utf-8', 'Content-Length': '2179'}
2024-01-30 16:15:49,472 ERROR   wandb-upload_1:1134320 [internal_api.py:upload_file():2769] upload_file response body: 
2024-01-30 16:15:50,246 ERROR   wandb-upload_2:1134320 [internal_api.py:upload_file():2765] upload_file exception https://storage.googleapis.com/wandb-artifacts-prod/wandb_artifacts/133981200/707679828/6873c23a2381d1524249eb1a948a45a5?Expires=1706688948&GoogleAccessId=gorilla-files-url-signer-man%40wandb-production.iam.gserviceaccount.com&Signature=c4l7issmW7JLxt%2F5iscJknq14hvYZvtF2GxzULmZuZuFAJ%2F9XDgpKYtL0M4ID77UMZgvwjxdjv6iO1HPm2i%2Fu6ogy7h5xHLRe4rQDX3k94rmTIhO%2FUHArMuR8wQR9%2FNUP2Z9TYpq0bGocaYm5xB2yEK%2BFAAF7JHHKdmu4clQQkzMPRoPoRQbpo1LvqvTBYfG%2F3BaewVmOiLE44F0S9TtUNZHVpHFx0OJyzH54n%2BLCqC4BBokBnRXGMVspDfurrfZTTaqS4bo4Gd113ehd9TNzRIawroe89EdL186rqaseJc6YZuiUYJD8lMZW3j%2Fdcyy%2Fop22jcv9B3fOEsjLcfxfQ%3D%3D: HTTPSConnectionPool(host='storage.googleapis.com', port=443): Max retries exceeded with url: /wandb-artifacts-prod/wandb_artifacts/133981200/707679828/6873c23a2381d1524249eb1a948a45a5?Expires=1706688948&GoogleAccessId=gorilla-files-url-signer-man%40wandb-production.iam.gserviceaccount.com&Signature=c4l7issmW7JLxt%2F5iscJknq14hvYZvtF2GxzULmZuZuFAJ%2F9XDgpKYtL0M4ID77UMZgvwjxdjv6iO1HPm2i%2Fu6ogy7h5xHLRe4rQDX3k94rmTIhO%2FUHArMuR8wQR9%2FNUP2Z9TYpq0bGocaYm5xB2yEK%2BFAAF7JHHKdmu4clQQkzMPRoPoRQbpo1LvqvTBYfG%2F3BaewVmOiLE44F0S9TtUNZHVpHFx0OJyzH54n%2BLCqC4BBokBnRXGMVspDfurrfZTTaqS4bo4Gd113ehd9TNzRIawroe89EdL186rqaseJc6YZuiUYJD8lMZW3j%2Fdcyy%2Fop22jcv9B3fOEsjLcfxfQ%3D%3D (Caused by NewConnectionError('<urllib3.connection.HTTPSConnection object at 0x7f47d460afa0>: Failed to establish a new connection: [Errno 101] Network is unreachable'))
2024-01-30 16:15:50,246 ERROR   wandb-upload_2:1134320 [internal_api.py:upload_file():2767] upload_file request headers: {'User-Agent': 'python-requests/2.23.0', 'Accept-Encoding': 'gzip, deflate', 'Accept': '*/*', 'Connection': 'keep-alive', 'Content-MD5': 'aHPCOiOB0VJCSesalIpFpQ==', 'Content-Type': 'application/json', 'Content-Length': '609'}
2024-01-30 16:15:50,246 ERROR   wandb-upload_2:1134320 [internal_api.py:upload_file():2769] upload_file response body: 
2024-01-30 16:15:50,246 INFO    wandb-upload_2:1134320 [retry.py:__call__():172] Retry attempt failed:
Traceback (most recent call last):
  File "/home/yanxindong/anaconda/envs/eva/lib/python3.8/site-packages/urllib3/connection.py", line 159, in _new_conn
    conn = connection.create_connection(
  File "/home/yanxindong/anaconda/envs/eva/lib/python3.8/site-packages/urllib3/util/connection.py", line 84, in create_connection
    raise err
  File "/home/yanxindong/anaconda/envs/eva/lib/python3.8/site-packages/urllib3/util/connection.py", line 74, in create_connection
    sock.connect(sa)
OSError: [Errno 101] Network is unreachable

During handling of the above exception, another exception occurred:

Traceback (most recent call last):
  File "/home/yanxindong/anaconda/envs/eva/lib/python3.8/site-packages/urllib3/connectionpool.py", line 670, in urlopen
    httplib_response = self._make_request(
  File "/home/yanxindong/anaconda/envs/eva/lib/python3.8/site-packages/urllib3/connectionpool.py", line 381, in _make_request
    self._validate_conn(conn)
  File "/home/yanxindong/anaconda/envs/eva/lib/python3.8/site-packages/urllib3/connectionpool.py", line 978, in _validate_conn
    conn.connect()
  File "/home/yanxindong/anaconda/envs/eva/lib/python3.8/site-packages/urllib3/connection.py", line 309, in connect
    conn = self._new_conn()
  File "/home/yanxindong/anaconda/envs/eva/lib/python3.8/site-packages/urllib3/connection.py", line 171, in _new_conn
    raise NewConnectionError(
urllib3.exceptions.NewConnectionError: <urllib3.connection.HTTPSConnection object at 0x7f47d460afa0>: Failed to establish a new connection: [Errno 101] Network is unreachable

During handling of the above exception, another exception occurred:

Traceback (most recent call last):
  File "/home/yanxindong/anaconda/envs/eva/lib/python3.8/site-packages/requests/adapters.py", line 439, in send
    resp = conn.urlopen(
  File "/home/yanxindong/anaconda/envs/eva/lib/python3.8/site-packages/urllib3/connectionpool.py", line 726, in urlopen
    retries = retries.increment(
  File "/home/yanxindong/anaconda/envs/eva/lib/python3.8/site-packages/urllib3/util/retry.py", line 446, in increment
    raise MaxRetryError(_pool, url, error or ResponseError(cause))
urllib3.exceptions.MaxRetryError: HTTPSConnectionPool(host='storage.googleapis.com', port=443): Max retries exceeded with url: /wandb-artifacts-prod/wandb_artifacts/133981200/707679828/6873c23a2381d1524249eb1a948a45a5?Expires=1706688948&GoogleAccessId=gorilla-files-url-signer-man%40wandb-production.iam.gserviceaccount.com&Signature=c4l7issmW7JLxt%2F5iscJknq14hvYZvtF2GxzULmZuZuFAJ%2F9XDgpKYtL0M4ID77UMZgvwjxdjv6iO1HPm2i%2Fu6ogy7h5xHLRe4rQDX3k94rmTIhO%2FUHArMuR8wQR9%2FNUP2Z9TYpq0bGocaYm5xB2yEK%2BFAAF7JHHKdmu4clQQkzMPRoPoRQbpo1LvqvTBYfG%2F3BaewVmOiLE44F0S9TtUNZHVpHFx0OJyzH54n%2BLCqC4BBokBnRXGMVspDfurrfZTTaqS4bo4Gd113ehd9TNzRIawroe89EdL186rqaseJc6YZuiUYJD8lMZW3j%2Fdcyy%2Fop22jcv9B3fOEsjLcfxfQ%3D%3D (Caused by NewConnectionError('<urllib3.connection.HTTPSConnection object at 0x7f47d460afa0>: Failed to establish a new connection: [Errno 101] Network is unreachable'))

During handling of the above exception, another exception occurred:

Traceback (most recent call last):
  File "/home/yanxindong/anaconda/envs/eva/lib/python3.8/site-packages/wandb/sdk/internal/internal_api.py", line 2758, in upload_file
    response = self._upload_file_session.put(
  File "/home/yanxindong/anaconda/envs/eva/lib/python3.8/site-packages/requests/sessions.py", line 590, in put
    return self.request('PUT', url, data=data, **kwargs)
  File "/home/yanxindong/anaconda/envs/eva/lib/python3.8/site-packages/requests/sessions.py", line 530, in request
    resp = self.send(prep, **send_kwargs)
  File "/home/yanxindong/anaconda/envs/eva/lib/python3.8/site-packages/requests/sessions.py", line 643, in send
    r = adapter.send(request, **kwargs)
  File "/home/yanxindong/anaconda/envs/eva/lib/python3.8/site-packages/requests/adapters.py", line 516, in send
    raise ConnectionError(e, request=request)
requests.exceptions.ConnectionError: HTTPSConnectionPool(host='storage.googleapis.com', port=443): Max retries exceeded with url: /wandb-artifacts-prod/wandb_artifacts/133981200/707679828/6873c23a2381d1524249eb1a948a45a5?Expires=1706688948&GoogleAccessId=gorilla-files-url-signer-man%40wandb-production.iam.gserviceaccount.com&Signature=c4l7issmW7JLxt%2F5iscJknq14hvYZvtF2GxzULmZuZuFAJ%2F9XDgpKYtL0M4ID77UMZgvwjxdjv6iO1HPm2i%2Fu6ogy7h5xHLRe4rQDX3k94rmTIhO%2FUHArMuR8wQR9%2FNUP2Z9TYpq0bGocaYm5xB2yEK%2BFAAF7JHHKdmu4clQQkzMPRoPoRQbpo1LvqvTBYfG%2F3BaewVmOiLE44F0S9TtUNZHVpHFx0OJyzH54n%2BLCqC4BBokBnRXGMVspDfurrfZTTaqS4bo4Gd113ehd9TNzRIawroe89EdL186rqaseJc6YZuiUYJD8lMZW3j%2Fdcyy%2Fop22jcv9B3fOEsjLcfxfQ%3D%3D (Caused by NewConnectionError('<urllib3.connection.HTTPSConnection object at 0x7f47d460afa0>: Failed to establish a new connection: [Errno 101] Network is unreachable'))

During handling of the above exception, another exception occurred:

Traceback (most recent call last):
  File "/home/yanxindong/anaconda/envs/eva/lib/python3.8/site-packages/wandb/sdk/lib/retry.py", line 131, in __call__
    result = self._call_fn(*args, **kwargs)
  File "/home/yanxindong/anaconda/envs/eva/lib/python3.8/site-packages/wandb/sdk/internal/internal_api.py", line 2789, in upload_file
    raise _e.with_traceback(sys.exc_info()[2])
  File "/home/yanxindong/anaconda/envs/eva/lib/python3.8/site-packages/wandb/sdk/internal/internal_api.py", line 2758, in upload_file
    response = self._upload_file_session.put(
  File "/home/yanxindong/anaconda/envs/eva/lib/python3.8/site-packages/requests/sessions.py", line 590, in put
    return self.request('PUT', url, data=data, **kwargs)
  File "/home/yanxindong/anaconda/envs/eva/lib/python3.8/site-packages/requests/sessions.py", line 530, in request
    resp = self.send(prep, **send_kwargs)
  File "/home/yanxindong/anaconda/envs/eva/lib/python3.8/site-packages/requests/sessions.py", line 643, in send
    r = adapter.send(request, **kwargs)
  File "/home/yanxindong/anaconda/envs/eva/lib/python3.8/site-packages/requests/adapters.py", line 516, in send
    raise ConnectionError(e, request=request)
wandb.sdk.lib.retry.TransientError: None
2024-01-30 16:15:51,726 ERROR   wandb-upload_1:1134320 [internal_api.py:upload_file():2765] upload_file exception https://storage.googleapis.com/wandb-artifacts-prod/wandb_artifacts/133981200/707679828/174a3d9bc61fec126cc7d5bdff5c6c5a?Expires=1706688948&GoogleAccessId=gorilla-files-url-signer-man%40wandb-production.iam.gserviceaccount.com&Signature=kbovuOHqx1zQ01k2JLv3vSDaYbHItTycqeq2YURNlbD5XRGkUvQrNZxJrbM6osH%2FENF6HvfcT%2BENYNpNC%2BL5OqLe%2FmpPae6eDy6NexFC7Zbbbn9d3G2XLZG9goE9iklwKX4KW1pd0VzWFfTel%2BLXIkIaFS0dWCAz2jiQuMLH7iAEoy5QbiMBP8lhXU9g1jMABHn8GXPrq1BY6Mv11K9TRqNDr05oEvZxddTyDwSBtZ5ywPejT5hE7v2D%2Blbt7shbB8A4xXrB2OflVHzyHKV74RagasqYRZZu0H7uvoCd5JAmTCIIMoiKQTdW3oHWTL%2F1Ja7qj52XwR7z51GvxZVvhg%3D%3D: HTTPSConnectionPool(host='storage.googleapis.com', port=443): Max retries exceeded with url: /wandb-artifacts-prod/wandb_artifacts/133981200/707679828/174a3d9bc61fec126cc7d5bdff5c6c5a?Expires=1706688948&GoogleAccessId=gorilla-files-url-signer-man%40wandb-production.iam.gserviceaccount.com&Signature=kbovuOHqx1zQ01k2JLv3vSDaYbHItTycqeq2YURNlbD5XRGkUvQrNZxJrbM6osH%2FENF6HvfcT%2BENYNpNC%2BL5OqLe%2FmpPae6eDy6NexFC7Zbbbn9d3G2XLZG9goE9iklwKX4KW1pd0VzWFfTel%2BLXIkIaFS0dWCAz2jiQuMLH7iAEoy5QbiMBP8lhXU9g1jMABHn8GXPrq1BY6Mv11K9TRqNDr05oEvZxddTyDwSBtZ5ywPejT5hE7v2D%2Blbt7shbB8A4xXrB2OflVHzyHKV74RagasqYRZZu0H7uvoCd5JAmTCIIMoiKQTdW3oHWTL%2F1Ja7qj52XwR7z51GvxZVvhg%3D%3D (Caused by NewConnectionError('<urllib3.connection.HTTPSConnection object at 0x7f47d45ffbe0>: Failed to establish a new connection: [Errno 101] Network is unreachable'))
2024-01-30 16:15:51,726 ERROR   wandb-upload_1:1134320 [internal_api.py:upload_file():2767] upload_file request headers: {'User-Agent': 'python-requests/2.23.0', 'Accept-Encoding': 'gzip, deflate', 'Accept': '*/*', 'Connection': 'keep-alive', 'Content-MD5': 'F0o9m8Yf7BJsx9W9/1xsWg==', 'Content-Type': 'text/plain; charset=utf-8', 'Content-Length': '2179'}
2024-01-30 16:15:51,726 ERROR   wandb-upload_1:1134320 [internal_api.py:upload_file():2769] upload_file response body: 
2024-01-30 16:15:51,920 DEBUG   HandlerThread:1134320 [handler.py:handle_request():146] handle_request: keepalive
2024-01-30 16:15:52,598 ERROR   wandb-upload_2:1134320 [internal_api.py:upload_file():2765] upload_file exception https://storage.googleapis.com/wandb-artifacts-prod/wandb_artifacts/133981200/707679828/6873c23a2381d1524249eb1a948a45a5?Expires=1706688948&GoogleAccessId=gorilla-files-url-signer-man%40wandb-production.iam.gserviceaccount.com&Signature=c4l7issmW7JLxt%2F5iscJknq14hvYZvtF2GxzULmZuZuFAJ%2F9XDgpKYtL0M4ID77UMZgvwjxdjv6iO1HPm2i%2Fu6ogy7h5xHLRe4rQDX3k94rmTIhO%2FUHArMuR8wQR9%2FNUP2Z9TYpq0bGocaYm5xB2yEK%2BFAAF7JHHKdmu4clQQkzMPRoPoRQbpo1LvqvTBYfG%2F3BaewVmOiLE44F0S9TtUNZHVpHFx0OJyzH54n%2BLCqC4BBokBnRXGMVspDfurrfZTTaqS4bo4Gd113ehd9TNzRIawroe89EdL186rqaseJc6YZuiUYJD8lMZW3j%2Fdcyy%2Fop22jcv9B3fOEsjLcfxfQ%3D%3D: HTTPSConnectionPool(host='storage.googleapis.com', port=443): Max retries exceeded with url: /wandb-artifacts-prod/wandb_artifacts/133981200/707679828/6873c23a2381d1524249eb1a948a45a5?Expires=1706688948&GoogleAccessId=gorilla-files-url-signer-man%40wandb-production.iam.gserviceaccount.com&Signature=c4l7issmW7JLxt%2F5iscJknq14hvYZvtF2GxzULmZuZuFAJ%2F9XDgpKYtL0M4ID77UMZgvwjxdjv6iO1HPm2i%2Fu6ogy7h5xHLRe4rQDX3k94rmTIhO%2FUHArMuR8wQR9%2FNUP2Z9TYpq0bGocaYm5xB2yEK%2BFAAF7JHHKdmu4clQQkzMPRoPoRQbpo1LvqvTBYfG%2F3BaewVmOiLE44F0S9TtUNZHVpHFx0OJyzH54n%2BLCqC4BBokBnRXGMVspDfurrfZTTaqS4bo4Gd113ehd9TNzRIawroe89EdL186rqaseJc6YZuiUYJD8lMZW3j%2Fdcyy%2Fop22jcv9B3fOEsjLcfxfQ%3D%3D (Caused by NewConnectionError('<urllib3.connection.HTTPSConnection object at 0x7f47d460ab80>: Failed to establish a new connection: [Errno 101] Network is unreachable'))
2024-01-30 16:15:52,599 ERROR   wandb-upload_2:1134320 [internal_api.py:upload_file():2767] upload_file request headers: {'User-Agent': 'python-requests/2.23.0', 'Accept-Encoding': 'gzip, deflate', 'Accept': '*/*', 'Connection': 'keep-alive', 'Content-MD5': 'aHPCOiOB0VJCSesalIpFpQ==', 'Content-Type': 'application/json', 'Content-Length': '609'}
2024-01-30 16:15:52,599 ERROR   wandb-upload_2:1134320 [internal_api.py:upload_file():2769] upload_file response body: 
2024-01-30 16:15:55,782 ERROR   wandb-upload_1:1134320 [internal_api.py:upload_file():2765] upload_file exception https://storage.googleapis.com/wandb-artifacts-prod/wandb_artifacts/133981200/707679828/174a3d9bc61fec126cc7d5bdff5c6c5a?Expires=1706688948&GoogleAccessId=gorilla-files-url-signer-man%40wandb-production.iam.gserviceaccount.com&Signature=kbovuOHqx1zQ01k2JLv3vSDaYbHItTycqeq2YURNlbD5XRGkUvQrNZxJrbM6osH%2FENF6HvfcT%2BENYNpNC%2BL5OqLe%2FmpPae6eDy6NexFC7Zbbbn9d3G2XLZG9goE9iklwKX4KW1pd0VzWFfTel%2BLXIkIaFS0dWCAz2jiQuMLH7iAEoy5QbiMBP8lhXU9g1jMABHn8GXPrq1BY6Mv11K9TRqNDr05oEvZxddTyDwSBtZ5ywPejT5hE7v2D%2Blbt7shbB8A4xXrB2OflVHzyHKV74RagasqYRZZu0H7uvoCd5JAmTCIIMoiKQTdW3oHWTL%2F1Ja7qj52XwR7z51GvxZVvhg%3D%3D: HTTPSConnectionPool(host='storage.googleapis.com', port=443): Max retries exceeded with url: /wandb-artifacts-prod/wandb_artifacts/133981200/707679828/174a3d9bc61fec126cc7d5bdff5c6c5a?Expires=1706688948&GoogleAccessId=gorilla-files-url-signer-man%40wandb-production.iam.gserviceaccount.com&Signature=kbovuOHqx1zQ01k2JLv3vSDaYbHItTycqeq2YURNlbD5XRGkUvQrNZxJrbM6osH%2FENF6HvfcT%2BENYNpNC%2BL5OqLe%2FmpPae6eDy6NexFC7Zbbbn9d3G2XLZG9goE9iklwKX4KW1pd0VzWFfTel%2BLXIkIaFS0dWCAz2jiQuMLH7iAEoy5QbiMBP8lhXU9g1jMABHn8GXPrq1BY6Mv11K9TRqNDr05oEvZxddTyDwSBtZ5ywPejT5hE7v2D%2Blbt7shbB8A4xXrB2OflVHzyHKV74RagasqYRZZu0H7uvoCd5JAmTCIIMoiKQTdW3oHWTL%2F1Ja7qj52XwR7z51GvxZVvhg%3D%3D (Caused by NewConnectionError('<urllib3.connection.HTTPSConnection object at 0x7f47d4653640>: Failed to establish a new connection: [Errno 101] Network is unreachable'))
2024-01-30 16:15:55,782 ERROR   wandb-upload_1:1134320 [internal_api.py:upload_file():2767] upload_file request headers: {'User-Agent': 'python-requests/2.23.0', 'Accept-Encoding': 'gzip, deflate', 'Accept': '*/*', 'Connection': 'keep-alive', 'Content-MD5': 'F0o9m8Yf7BJsx9W9/1xsWg==', 'Content-Type': 'text/plain; charset=utf-8', 'Content-Length': '2179'}
2024-01-30 16:15:55,782 ERROR   wandb-upload_1:1134320 [internal_api.py:upload_file():2769] upload_file response body: 
2024-01-30 16:15:56,696 ERROR   wandb-upload_2:1134320 [internal_api.py:upload_file():2765] upload_file exception https://storage.googleapis.com/wandb-artifacts-prod/wandb_artifacts/133981200/707679828/6873c23a2381d1524249eb1a948a45a5?Expires=1706688948&GoogleAccessId=gorilla-files-url-signer-man%40wandb-production.iam.gserviceaccount.com&Signature=c4l7issmW7JLxt%2F5iscJknq14hvYZvtF2GxzULmZuZuFAJ%2F9XDgpKYtL0M4ID77UMZgvwjxdjv6iO1HPm2i%2Fu6ogy7h5xHLRe4rQDX3k94rmTIhO%2FUHArMuR8wQR9%2FNUP2Z9TYpq0bGocaYm5xB2yEK%2BFAAF7JHHKdmu4clQQkzMPRoPoRQbpo1LvqvTBYfG%2F3BaewVmOiLE44F0S9TtUNZHVpHFx0OJyzH54n%2BLCqC4BBokBnRXGMVspDfurrfZTTaqS4bo4Gd113ehd9TNzRIawroe89EdL186rqaseJc6YZuiUYJD8lMZW3j%2Fdcyy%2Fop22jcv9B3fOEsjLcfxfQ%3D%3D: HTTPSConnectionPool(host='storage.googleapis.com', port=443): Max retries exceeded with url: /wandb-artifacts-prod/wandb_artifacts/133981200/707679828/6873c23a2381d1524249eb1a948a45a5?Expires=1706688948&GoogleAccessId=gorilla-files-url-signer-man%40wandb-production.iam.gserviceaccount.com&Signature=c4l7issmW7JLxt%2F5iscJknq14hvYZvtF2GxzULmZuZuFAJ%2F9XDgpKYtL0M4ID77UMZgvwjxdjv6iO1HPm2i%2Fu6ogy7h5xHLRe4rQDX3k94rmTIhO%2FUHArMuR8wQR9%2FNUP2Z9TYpq0bGocaYm5xB2yEK%2BFAAF7JHHKdmu4clQQkzMPRoPoRQbpo1LvqvTBYfG%2F3BaewVmOiLE44F0S9TtUNZHVpHFx0OJyzH54n%2BLCqC4BBokBnRXGMVspDfurrfZTTaqS4bo4Gd113ehd9TNzRIawroe89EdL186rqaseJc6YZuiUYJD8lMZW3j%2Fdcyy%2Fop22jcv9B3fOEsjLcfxfQ%3D%3D (Caused by NewConnectionError('<urllib3.connection.HTTPSConnection object at 0x7f47d4653d30>: Failed to establish a new connection: [Errno 101] Network is unreachable'))
2024-01-30 16:15:56,696 ERROR   wandb-upload_2:1134320 [internal_api.py:upload_file():2767] upload_file request headers: {'User-Agent': 'python-requests/2.23.0', 'Accept-Encoding': 'gzip, deflate', 'Accept': '*/*', 'Connection': 'keep-alive', 'Content-MD5': 'aHPCOiOB0VJCSesalIpFpQ==', 'Content-Type': 'application/json', 'Content-Length': '609'}
2024-01-30 16:15:56,696 ERROR   wandb-upload_2:1134320 [internal_api.py:upload_file():2769] upload_file response body: 
2024-01-30 16:15:56,922 DEBUG   HandlerThread:1134320 [handler.py:handle_request():146] handle_request: keepalive
2024-01-30 16:16:01,923 DEBUG   HandlerThread:1134320 [handler.py:handle_request():146] handle_request: keepalive
2024-01-30 16:16:04,212 ERROR   wandb-upload_1:1134320 [internal_api.py:upload_file():2765] upload_file exception https://storage.googleapis.com/wandb-artifacts-prod/wandb_artifacts/133981200/707679828/174a3d9bc61fec126cc7d5bdff5c6c5a?Expires=1706688948&GoogleAccessId=gorilla-files-url-signer-man%40wandb-production.iam.gserviceaccount.com&Signature=kbovuOHqx1zQ01k2JLv3vSDaYbHItTycqeq2YURNlbD5XRGkUvQrNZxJrbM6osH%2FENF6HvfcT%2BENYNpNC%2BL5OqLe%2FmpPae6eDy6NexFC7Zbbbn9d3G2XLZG9goE9iklwKX4KW1pd0VzWFfTel%2BLXIkIaFS0dWCAz2jiQuMLH7iAEoy5QbiMBP8lhXU9g1jMABHn8GXPrq1BY6Mv11K9TRqNDr05oEvZxddTyDwSBtZ5ywPejT5hE7v2D%2Blbt7shbB8A4xXrB2OflVHzyHKV74RagasqYRZZu0H7uvoCd5JAmTCIIMoiKQTdW3oHWTL%2F1Ja7qj52XwR7z51GvxZVvhg%3D%3D: HTTPSConnectionPool(host='storage.googleapis.com', port=443): Max retries exceeded with url: /wandb-artifacts-prod/wandb_artifacts/133981200/707679828/174a3d9bc61fec126cc7d5bdff5c6c5a?Expires=1706688948&GoogleAccessId=gorilla-files-url-signer-man%40wandb-production.iam.gserviceaccount.com&Signature=kbovuOHqx1zQ01k2JLv3vSDaYbHItTycqeq2YURNlbD5XRGkUvQrNZxJrbM6osH%2FENF6HvfcT%2BENYNpNC%2BL5OqLe%2FmpPae6eDy6NexFC7Zbbbn9d3G2XLZG9goE9iklwKX4KW1pd0VzWFfTel%2BLXIkIaFS0dWCAz2jiQuMLH7iAEoy5QbiMBP8lhXU9g1jMABHn8GXPrq1BY6Mv11K9TRqNDr05oEvZxddTyDwSBtZ5ywPejT5hE7v2D%2Blbt7shbB8A4xXrB2OflVHzyHKV74RagasqYRZZu0H7uvoCd5JAmTCIIMoiKQTdW3oHWTL%2F1Ja7qj52XwR7z51GvxZVvhg%3D%3D (Caused by NewConnectionError('<urllib3.connection.HTTPSConnection object at 0x7f47d460a2b0>: Failed to establish a new connection: [Errno 101] Network is unreachable'))
2024-01-30 16:16:04,212 ERROR   wandb-upload_1:1134320 [internal_api.py:upload_file():2767] upload_file request headers: {'User-Agent': 'python-requests/2.23.0', 'Accept-Encoding': 'gzip, deflate', 'Accept': '*/*', 'Connection': 'keep-alive', 'Content-MD5': 'F0o9m8Yf7BJsx9W9/1xsWg==', 'Content-Type': 'text/plain; charset=utf-8', 'Content-Length': '2179'}
2024-01-30 16:16:04,213 ERROR   wandb-upload_1:1134320 [internal_api.py:upload_file():2769] upload_file response body: 
2024-01-30 16:16:04,802 ERROR   wandb-upload_2:1134320 [internal_api.py:upload_file():2765] upload_file exception https://storage.googleapis.com/wandb-artifacts-prod/wandb_artifacts/133981200/707679828/6873c23a2381d1524249eb1a948a45a5?Expires=1706688948&GoogleAccessId=gorilla-files-url-signer-man%40wandb-production.iam.gserviceaccount.com&Signature=c4l7issmW7JLxt%2F5iscJknq14hvYZvtF2GxzULmZuZuFAJ%2F9XDgpKYtL0M4ID77UMZgvwjxdjv6iO1HPm2i%2Fu6ogy7h5xHLRe4rQDX3k94rmTIhO%2FUHArMuR8wQR9%2FNUP2Z9TYpq0bGocaYm5xB2yEK%2BFAAF7JHHKdmu4clQQkzMPRoPoRQbpo1LvqvTBYfG%2F3BaewVmOiLE44F0S9TtUNZHVpHFx0OJyzH54n%2BLCqC4BBokBnRXGMVspDfurrfZTTaqS4bo4Gd113ehd9TNzRIawroe89EdL186rqaseJc6YZuiUYJD8lMZW3j%2Fdcyy%2Fop22jcv9B3fOEsjLcfxfQ%3D%3D: HTTPSConnectionPool(host='storage.googleapis.com', port=443): Max retries exceeded with url: /wandb-artifacts-prod/wandb_artifacts/133981200/707679828/6873c23a2381d1524249eb1a948a45a5?Expires=1706688948&GoogleAccessId=gorilla-files-url-signer-man%40wandb-production.iam.gserviceaccount.com&Signature=c4l7issmW7JLxt%2F5iscJknq14hvYZvtF2GxzULmZuZuFAJ%2F9XDgpKYtL0M4ID77UMZgvwjxdjv6iO1HPm2i%2Fu6ogy7h5xHLRe4rQDX3k94rmTIhO%2FUHArMuR8wQR9%2FNUP2Z9TYpq0bGocaYm5xB2yEK%2BFAAF7JHHKdmu4clQQkzMPRoPoRQbpo1LvqvTBYfG%2F3BaewVmOiLE44F0S9TtUNZHVpHFx0OJyzH54n%2BLCqC4BBokBnRXGMVspDfurrfZTTaqS4bo4Gd113ehd9TNzRIawroe89EdL186rqaseJc6YZuiUYJD8lMZW3j%2Fdcyy%2Fop22jcv9B3fOEsjLcfxfQ%3D%3D (Caused by NewConnectionError('<urllib3.connection.HTTPSConnection object at 0x7f47d445a3d0>: Failed to establish a new connection: [Errno 101] Network is unreachable'))
2024-01-30 16:16:04,802 ERROR   wandb-upload_2:1134320 [internal_api.py:upload_file():2767] upload_file request headers: {'User-Agent': 'python-requests/2.23.0', 'Accept-Encoding': 'gzip, deflate', 'Accept': '*/*', 'Connection': 'keep-alive', 'Content-MD5': 'aHPCOiOB0VJCSesalIpFpQ==', 'Content-Type': 'application/json', 'Content-Length': '609'}
2024-01-30 16:16:04,802 ERROR   wandb-upload_2:1134320 [internal_api.py:upload_file():2769] upload_file response body: 
2024-01-30 16:16:06,925 DEBUG   HandlerThread:1134320 [handler.py:handle_request():146] handle_request: keepalive
2024-01-30 16:16:11,926 DEBUG   HandlerThread:1134320 [handler.py:handle_request():146] handle_request: keepalive
2024-01-30 16:16:16,928 DEBUG   HandlerThread:1134320 [handler.py:handle_request():146] handle_request: keepalive
2024-01-30 16:16:21,929 DEBUG   HandlerThread:1134320 [handler.py:handle_request():146] handle_request: keepalive
2024-01-30 16:16:23,278 ERROR   wandb-upload_1:1134320 [internal_api.py:upload_file():2765] upload_file exception https://storage.googleapis.com/wandb-artifacts-prod/wandb_artifacts/133981200/707679828/174a3d9bc61fec126cc7d5bdff5c6c5a?Expires=1706688948&GoogleAccessId=gorilla-files-url-signer-man%40wandb-production.iam.gserviceaccount.com&Signature=kbovuOHqx1zQ01k2JLv3vSDaYbHItTycqeq2YURNlbD5XRGkUvQrNZxJrbM6osH%2FENF6HvfcT%2BENYNpNC%2BL5OqLe%2FmpPae6eDy6NexFC7Zbbbn9d3G2XLZG9goE9iklwKX4KW1pd0VzWFfTel%2BLXIkIaFS0dWCAz2jiQuMLH7iAEoy5QbiMBP8lhXU9g1jMABHn8GXPrq1BY6Mv11K9TRqNDr05oEvZxddTyDwSBtZ5ywPejT5hE7v2D%2Blbt7shbB8A4xXrB2OflVHzyHKV74RagasqYRZZu0H7uvoCd5JAmTCIIMoiKQTdW3oHWTL%2F1Ja7qj52XwR7z51GvxZVvhg%3D%3D: HTTPSConnectionPool(host='storage.googleapis.com', port=443): Max retries exceeded with url: /wandb-artifacts-prod/wandb_artifacts/133981200/707679828/174a3d9bc61fec126cc7d5bdff5c6c5a?Expires=1706688948&GoogleAccessId=gorilla-files-url-signer-man%40wandb-production.iam.gserviceaccount.com&Signature=kbovuOHqx1zQ01k2JLv3vSDaYbHItTycqeq2YURNlbD5XRGkUvQrNZxJrbM6osH%2FENF6HvfcT%2BENYNpNC%2BL5OqLe%2FmpPae6eDy6NexFC7Zbbbn9d3G2XLZG9goE9iklwKX4KW1pd0VzWFfTel%2BLXIkIaFS0dWCAz2jiQuMLH7iAEoy5QbiMBP8lhXU9g1jMABHn8GXPrq1BY6Mv11K9TRqNDr05oEvZxddTyDwSBtZ5ywPejT5hE7v2D%2Blbt7shbB8A4xXrB2OflVHzyHKV74RagasqYRZZu0H7uvoCd5JAmTCIIMoiKQTdW3oHWTL%2F1Ja7qj52XwR7z51GvxZVvhg%3D%3D (Caused by NewConnectionError('<urllib3.connection.HTTPSConnection object at 0x7f47d44570a0>: Failed to establish a new connection: [Errno 101] Network is unreachable'))
2024-01-30 16:16:23,278 ERROR   wandb-upload_1:1134320 [internal_api.py:upload_file():2767] upload_file request headers: {'User-Agent': 'python-requests/2.23.0', 'Accept-Encoding': 'gzip, deflate', 'Accept': '*/*', 'Connection': 'keep-alive', 'Content-MD5': 'F0o9m8Yf7BJsx9W9/1xsWg==', 'Content-Type': 'text/plain; charset=utf-8', 'Content-Length': '2179'}
2024-01-30 16:16:23,278 ERROR   wandb-upload_1:1134320 [internal_api.py:upload_file():2769] upload_file response body: 
2024-01-30 16:16:24,399 ERROR   wandb-upload_2:1134320 [internal_api.py:upload_file():2765] upload_file exception https://storage.googleapis.com/wandb-artifacts-prod/wandb_artifacts/133981200/707679828/6873c23a2381d1524249eb1a948a45a5?Expires=1706688948&GoogleAccessId=gorilla-files-url-signer-man%40wandb-production.iam.gserviceaccount.com&Signature=c4l7issmW7JLxt%2F5iscJknq14hvYZvtF2GxzULmZuZuFAJ%2F9XDgpKYtL0M4ID77UMZgvwjxdjv6iO1HPm2i%2Fu6ogy7h5xHLRe4rQDX3k94rmTIhO%2FUHArMuR8wQR9%2FNUP2Z9TYpq0bGocaYm5xB2yEK%2BFAAF7JHHKdmu4clQQkzMPRoPoRQbpo1LvqvTBYfG%2F3BaewVmOiLE44F0S9TtUNZHVpHFx0OJyzH54n%2BLCqC4BBokBnRXGMVspDfurrfZTTaqS4bo4Gd113ehd9TNzRIawroe89EdL186rqaseJc6YZuiUYJD8lMZW3j%2Fdcyy%2Fop22jcv9B3fOEsjLcfxfQ%3D%3D: HTTPSConnectionPool(host='storage.googleapis.com', port=443): Max retries exceeded with url: /wandb-artifacts-prod/wandb_artifacts/133981200/707679828/6873c23a2381d1524249eb1a948a45a5?Expires=1706688948&GoogleAccessId=gorilla-files-url-signer-man%40wandb-production.iam.gserviceaccount.com&Signature=c4l7issmW7JLxt%2F5iscJknq14hvYZvtF2GxzULmZuZuFAJ%2F9XDgpKYtL0M4ID77UMZgvwjxdjv6iO1HPm2i%2Fu6ogy7h5xHLRe4rQDX3k94rmTIhO%2FUHArMuR8wQR9%2FNUP2Z9TYpq0bGocaYm5xB2yEK%2BFAAF7JHHKdmu4clQQkzMPRoPoRQbpo1LvqvTBYfG%2F3BaewVmOiLE44F0S9TtUNZHVpHFx0OJyzH54n%2BLCqC4BBokBnRXGMVspDfurrfZTTaqS4bo4Gd113ehd9TNzRIawroe89EdL186rqaseJc6YZuiUYJD8lMZW3j%2Fdcyy%2Fop22jcv9B3fOEsjLcfxfQ%3D%3D (Caused by NewConnectionError('<urllib3.connection.HTTPSConnection object at 0x7f47d44577c0>: Failed to establish a new connection: [Errno 101] Network is unreachable'))
2024-01-30 16:16:24,399 ERROR   wandb-upload_2:1134320 [internal_api.py:upload_file():2767] upload_file request headers: {'User-Agent': 'python-requests/2.23.0', 'Accept-Encoding': 'gzip, deflate', 'Accept': '*/*', 'Connection': 'keep-alive', 'Content-MD5': 'aHPCOiOB0VJCSesalIpFpQ==', 'Content-Type': 'application/json', 'Content-Length': '609'}
2024-01-30 16:16:24,400 ERROR   wandb-upload_2:1134320 [internal_api.py:upload_file():2769] upload_file response body: 
2024-01-30 16:16:26,931 DEBUG   HandlerThread:1134320 [handler.py:handle_request():146] handle_request: keepalive
2024-01-30 16:16:31,934 DEBUG   HandlerThread:1134320 [handler.py:handle_request():146] handle_request: keepalive
2024-01-30 16:16:36,936 DEBUG   HandlerThread:1134320 [handler.py:handle_request():146] handle_request: keepalive
2024-01-30 16:16:41,938 DEBUG   HandlerThread:1134320 [handler.py:handle_request():146] handle_request: keepalive
2024-01-30 16:16:46,940 DEBUG   HandlerThread:1134320 [handler.py:handle_request():146] handle_request: keepalive
2024-01-30 16:16:51,943 DEBUG   HandlerThread:1134320 [handler.py:handle_request():146] handle_request: keepalive
2024-01-30 16:16:56,945 DEBUG   HandlerThread:1134320 [handler.py:handle_request():146] handle_request: keepalive
2024-01-30 16:16:57,548 ERROR   wandb-upload_2:1134320 [internal_api.py:upload_file():2765] upload_file exception https://storage.googleapis.com/wandb-artifacts-prod/wandb_artifacts/133981200/707679828/6873c23a2381d1524249eb1a948a45a5?Expires=1706688948&GoogleAccessId=gorilla-files-url-signer-man%40wandb-production.iam.gserviceaccount.com&Signature=c4l7issmW7JLxt%2F5iscJknq14hvYZvtF2GxzULmZuZuFAJ%2F9XDgpKYtL0M4ID77UMZgvwjxdjv6iO1HPm2i%2Fu6ogy7h5xHLRe4rQDX3k94rmTIhO%2FUHArMuR8wQR9%2FNUP2Z9TYpq0bGocaYm5xB2yEK%2BFAAF7JHHKdmu4clQQkzMPRoPoRQbpo1LvqvTBYfG%2F3BaewVmOiLE44F0S9TtUNZHVpHFx0OJyzH54n%2BLCqC4BBokBnRXGMVspDfurrfZTTaqS4bo4Gd113ehd9TNzRIawroe89EdL186rqaseJc6YZuiUYJD8lMZW3j%2Fdcyy%2Fop22jcv9B3fOEsjLcfxfQ%3D%3D: HTTPSConnectionPool(host='storage.googleapis.com', port=443): Max retries exceeded with url: /wandb-artifacts-prod/wandb_artifacts/133981200/707679828/6873c23a2381d1524249eb1a948a45a5?Expires=1706688948&GoogleAccessId=gorilla-files-url-signer-man%40wandb-production.iam.gserviceaccount.com&Signature=c4l7issmW7JLxt%2F5iscJknq14hvYZvtF2GxzULmZuZuFAJ%2F9XDgpKYtL0M4ID77UMZgvwjxdjv6iO1HPm2i%2Fu6ogy7h5xHLRe4rQDX3k94rmTIhO%2FUHArMuR8wQR9%2FNUP2Z9TYpq0bGocaYm5xB2yEK%2BFAAF7JHHKdmu4clQQkzMPRoPoRQbpo1LvqvTBYfG%2F3BaewVmOiLE44F0S9TtUNZHVpHFx0OJyzH54n%2BLCqC4BBokBnRXGMVspDfurrfZTTaqS4bo4Gd113ehd9TNzRIawroe89EdL186rqaseJc6YZuiUYJD8lMZW3j%2Fdcyy%2Fop22jcv9B3fOEsjLcfxfQ%3D%3D (Caused by NewConnectionError('<urllib3.connection.HTTPSConnection object at 0x7f47d444f6d0>: Failed to establish a new connection: [Errno 101] Network is unreachable'))
2024-01-30 16:16:57,549 ERROR   wandb-upload_2:1134320 [internal_api.py:upload_file():2767] upload_file request headers: {'User-Agent': 'python-requests/2.23.0', 'Accept-Encoding': 'gzip, deflate', 'Accept': '*/*', 'Connection': 'keep-alive', 'Content-MD5': 'aHPCOiOB0VJCSesalIpFpQ==', 'Content-Type': 'application/json', 'Content-Length': '609'}
2024-01-30 16:16:57,549 ERROR   wandb-upload_2:1134320 [internal_api.py:upload_file():2769] upload_file response body: 
2024-01-30 16:17:00,022 ERROR   wandb-upload_1:1134320 [internal_api.py:upload_file():2765] upload_file exception https://storage.googleapis.com/wandb-artifacts-prod/wandb_artifacts/133981200/707679828/174a3d9bc61fec126cc7d5bdff5c6c5a?Expires=1706688948&GoogleAccessId=gorilla-files-url-signer-man%40wandb-production.iam.gserviceaccount.com&Signature=kbovuOHqx1zQ01k2JLv3vSDaYbHItTycqeq2YURNlbD5XRGkUvQrNZxJrbM6osH%2FENF6HvfcT%2BENYNpNC%2BL5OqLe%2FmpPae6eDy6NexFC7Zbbbn9d3G2XLZG9goE9iklwKX4KW1pd0VzWFfTel%2BLXIkIaFS0dWCAz2jiQuMLH7iAEoy5QbiMBP8lhXU9g1jMABHn8GXPrq1BY6Mv11K9TRqNDr05oEvZxddTyDwSBtZ5ywPejT5hE7v2D%2Blbt7shbB8A4xXrB2OflVHzyHKV74RagasqYRZZu0H7uvoCd5JAmTCIIMoiKQTdW3oHWTL%2F1Ja7qj52XwR7z51GvxZVvhg%3D%3D: HTTPSConnectionPool(host='storage.googleapis.com', port=443): Max retries exceeded with url: /wandb-artifacts-prod/wandb_artifacts/133981200/707679828/174a3d9bc61fec126cc7d5bdff5c6c5a?Expires=1706688948&GoogleAccessId=gorilla-files-url-signer-man%40wandb-production.iam.gserviceaccount.com&Signature=kbovuOHqx1zQ01k2JLv3vSDaYbHItTycqeq2YURNlbD5XRGkUvQrNZxJrbM6osH%2FENF6HvfcT%2BENYNpNC%2BL5OqLe%2FmpPae6eDy6NexFC7Zbbbn9d3G2XLZG9goE9iklwKX4KW1pd0VzWFfTel%2BLXIkIaFS0dWCAz2jiQuMLH7iAEoy5QbiMBP8lhXU9g1jMABHn8GXPrq1BY6Mv11K9TRqNDr05oEvZxddTyDwSBtZ5ywPejT5hE7v2D%2Blbt7shbB8A4xXrB2OflVHzyHKV74RagasqYRZZu0H7uvoCd5JAmTCIIMoiKQTdW3oHWTL%2F1Ja7qj52XwR7z51GvxZVvhg%3D%3D (Caused by NewConnectionError('<urllib3.connection.HTTPSConnection object at 0x7f47d4457a90>: Failed to establish a new connection: [Errno 101] Network is unreachable'))
2024-01-30 16:17:00,022 ERROR   wandb-upload_1:1134320 [internal_api.py:upload_file():2767] upload_file request headers: {'User-Agent': 'python-requests/2.23.0', 'Accept-Encoding': 'gzip, deflate', 'Accept': '*/*', 'Connection': 'keep-alive', 'Content-MD5': 'F0o9m8Yf7BJsx9W9/1xsWg==', 'Content-Type': 'text/plain; charset=utf-8', 'Content-Length': '2179'}
2024-01-30 16:17:00,022 ERROR   wandb-upload_1:1134320 [internal_api.py:upload_file():2769] upload_file response body: 
2024-01-30 16:17:01,947 DEBUG   HandlerThread:1134320 [handler.py:handle_request():146] handle_request: keepalive
2024-01-30 16:17:06,949 DEBUG   HandlerThread:1134320 [handler.py:handle_request():146] handle_request: keepalive
2024-01-30 16:17:11,952 DEBUG   HandlerThread:1134320 [handler.py:handle_request():146] handle_request: keepalive
2024-01-30 16:17:16,954 DEBUG   HandlerThread:1134320 [handler.py:handle_request():146] handle_request: keepalive
2024-01-30 16:17:21,957 DEBUG   HandlerThread:1134320 [handler.py:handle_request():146] handle_request: keepalive
2024-01-30 16:17:26,958 DEBUG   HandlerThread:1134320 [handler.py:handle_request():146] handle_request: keepalive
2024-01-30 16:17:31,961 DEBUG   HandlerThread:1134320 [handler.py:handle_request():146] handle_request: keepalive
2024-01-30 16:17:36,963 DEBUG   HandlerThread:1134320 [handler.py:handle_request():146] handle_request: keepalive
2024-01-30 16:17:41,966 DEBUG   HandlerThread:1134320 [handler.py:handle_request():146] handle_request: keepalive
2024-01-30 16:17:46,968 DEBUG   HandlerThread:1134320 [handler.py:handle_request():146] handle_request: keepalive
2024-01-30 16:17:51,971 DEBUG   HandlerThread:1134320 [handler.py:handle_request():146] handle_request: keepalive
2024-01-30 16:18:05,926 ERROR   wandb-upload_2:1134320 [internal_api.py:upload_file():2765] upload_file exception https://storage.googleapis.com/wandb-artifacts-prod/wandb_artifacts/133981200/707679828/6873c23a2381d1524249eb1a948a45a5?Expires=1706688948&GoogleAccessId=gorilla-files-url-signer-man%40wandb-production.iam.gserviceaccount.com&Signature=c4l7issmW7JLxt%2F5iscJknq14hvYZvtF2GxzULmZuZuFAJ%2F9XDgpKYtL0M4ID77UMZgvwjxdjv6iO1HPm2i%2Fu6ogy7h5xHLRe4rQDX3k94rmTIhO%2FUHArMuR8wQR9%2FNUP2Z9TYpq0bGocaYm5xB2yEK%2BFAAF7JHHKdmu4clQQkzMPRoPoRQbpo1LvqvTBYfG%2F3BaewVmOiLE44F0S9TtUNZHVpHFx0OJyzH54n%2BLCqC4BBokBnRXGMVspDfurrfZTTaqS4bo4Gd113ehd9TNzRIawroe89EdL186rqaseJc6YZuiUYJD8lMZW3j%2Fdcyy%2Fop22jcv9B3fOEsjLcfxfQ%3D%3D: HTTPSConnectionPool(host='storage.googleapis.com', port=443): Max retries exceeded with url: /wandb-artifacts-prod/wandb_artifacts/133981200/707679828/6873c23a2381d1524249eb1a948a45a5?Expires=1706688948&GoogleAccessId=gorilla-files-url-signer-man%40wandb-production.iam.gserviceaccount.com&Signature=c4l7issmW7JLxt%2F5iscJknq14hvYZvtF2GxzULmZuZuFAJ%2F9XDgpKYtL0M4ID77UMZgvwjxdjv6iO1HPm2i%2Fu6ogy7h5xHLRe4rQDX3k94rmTIhO%2FUHArMuR8wQR9%2FNUP2Z9TYpq0bGocaYm5xB2yEK%2BFAAF7JHHKdmu4clQQkzMPRoPoRQbpo1LvqvTBYfG%2F3BaewVmOiLE44F0S9TtUNZHVpHFx0OJyzH54n%2BLCqC4BBokBnRXGMVspDfurrfZTTaqS4bo4Gd113ehd9TNzRIawroe89EdL186rqaseJc6YZuiUYJD8lMZW3j%2Fdcyy%2Fop22jcv9B3fOEsjLcfxfQ%3D%3D (Caused by NewConnectionError('<urllib3.connection.HTTPSConnection object at 0x7f47d460a520>: Failed to establish a new connection: [Errno 101] Network is unreachable'))
2024-01-30 16:18:05,926 ERROR   wandb-upload_2:1134320 [internal_api.py:upload_file():2767] upload_file request headers: {'User-Agent': 'python-requests/2.23.0', 'Accept-Encoding': 'gzip, deflate', 'Accept': '*/*', 'Connection': 'keep-alive', 'Content-MD5': 'aHPCOiOB0VJCSesalIpFpQ==', 'Content-Type': 'application/json', 'Content-Length': '609'}
2024-01-30 16:18:05,926 ERROR   wandb-upload_2:1134320 [internal_api.py:upload_file():2769] upload_file response body: 
2024-01-30 16:18:10,669 ERROR   wandb-upload_1:1134320 [internal_api.py:upload_file():2765] upload_file exception https://storage.googleapis.com/wandb-artifacts-prod/wandb_artifacts/133981200/707679828/174a3d9bc61fec126cc7d5bdff5c6c5a?Expires=1706688948&GoogleAccessId=gorilla-files-url-signer-man%40wandb-production.iam.gserviceaccount.com&Signature=kbovuOHqx1zQ01k2JLv3vSDaYbHItTycqeq2YURNlbD5XRGkUvQrNZxJrbM6osH%2FENF6HvfcT%2BENYNpNC%2BL5OqLe%2FmpPae6eDy6NexFC7Zbbbn9d3G2XLZG9goE9iklwKX4KW1pd0VzWFfTel%2BLXIkIaFS0dWCAz2jiQuMLH7iAEoy5QbiMBP8lhXU9g1jMABHn8GXPrq1BY6Mv11K9TRqNDr05oEvZxddTyDwSBtZ5ywPejT5hE7v2D%2Blbt7shbB8A4xXrB2OflVHzyHKV74RagasqYRZZu0H7uvoCd5JAmTCIIMoiKQTdW3oHWTL%2F1Ja7qj52XwR7z51GvxZVvhg%3D%3D: HTTPSConnectionPool(host='storage.googleapis.com', port=443): Max retries exceeded with url: /wandb-artifacts-prod/wandb_artifacts/133981200/707679828/174a3d9bc61fec126cc7d5bdff5c6c5a?Expires=1706688948&GoogleAccessId=gorilla-files-url-signer-man%40wandb-production.iam.gserviceaccount.com&Signature=kbovuOHqx1zQ01k2JLv3vSDaYbHItTycqeq2YURNlbD5XRGkUvQrNZxJrbM6osH%2FENF6HvfcT%2BENYNpNC%2BL5OqLe%2FmpPae6eDy6NexFC7Zbbbn9d3G2XLZG9goE9iklwKX4KW1pd0VzWFfTel%2BLXIkIaFS0dWCAz2jiQuMLH7iAEoy5QbiMBP8lhXU9g1jMABHn8GXPrq1BY6Mv11K9TRqNDr05oEvZxddTyDwSBtZ5ywPejT5hE7v2D%2Blbt7shbB8A4xXrB2OflVHzyHKV74RagasqYRZZu0H7uvoCd5JAmTCIIMoiKQTdW3oHWTL%2F1Ja7qj52XwR7z51GvxZVvhg%3D%3D (Caused by NewConnectionError('<urllib3.connection.HTTPSConnection object at 0x7f47d4456850>: Failed to establish a new connection: [Errno 101] Network is unreachable'))
2024-01-30 16:18:10,669 ERROR   wandb-upload_1:1134320 [internal_api.py:upload_file():2767] upload_file request headers: {'User-Agent': 'python-requests/2.23.0', 'Accept-Encoding': 'gzip, deflate', 'Accept': '*/*', 'Connection': 'keep-alive', 'Content-MD5': 'F0o9m8Yf7BJsx9W9/1xsWg==', 'Content-Type': 'text/plain; charset=utf-8', 'Content-Length': '2179'}
2024-01-30 16:18:10,669 ERROR   wandb-upload_1:1134320 [internal_api.py:upload_file():2769] upload_file response body: 
2024-01-30 16:19:46,161 ERROR   wandb-upload_0:1134320 [internal_api.py:upload_file():2765] upload_file exception https://storage.googleapis.com/wandb-production.appspot.com/dynamic_x/bert_pytorch/wn1qxvno/wandb-metadata.json?Expires=1706688636&GoogleAccessId=gorilla-files-url-signer-man%40wandb-production.iam.gserviceaccount.com&Signature=X2NQsRBPxmFG1jesoKIgaYH%2BEuVtOiN9iCNyn2nXM0cUCfxLAaAA%2Bk3hpaoW2l5axIqryRk6aj9eSNHiDB95u6Hf7uUfIhqHdFIO604O3XU8FxsVDC6sl62BCb5Gv1YZELF0wwnCYUabk5D8%2BySwHmTL5L192XcYTZiRY5RNvkX0XbkI1VhcZpRvVUboO783c0aYk3HaH9AjjVpNUOz6AP7oNYdWa%2BBqjD6KY4lDz4ppjtGJyClpzP%2BXvNyhrL2ChSQrgKLmg7wKvTV5yciTtM7q8830QL9WNkUPXUkfHDQyMFS62jtzEAulOBw9PlxFnSMtX64IMtAkZcBi0zA25A%3D%3D: HTTPSConnectionPool(host='storage.googleapis.com', port=443): Max retries exceeded with url: /wandb-production.appspot.com/dynamic_x/bert_pytorch/wn1qxvno/wandb-metadata.json?Expires=1706688636&GoogleAccessId=gorilla-files-url-signer-man%40wandb-production.iam.gserviceaccount.com&Signature=X2NQsRBPxmFG1jesoKIgaYH%2BEuVtOiN9iCNyn2nXM0cUCfxLAaAA%2Bk3hpaoW2l5axIqryRk6aj9eSNHiDB95u6Hf7uUfIhqHdFIO604O3XU8FxsVDC6sl62BCb5Gv1YZELF0wwnCYUabk5D8%2BySwHmTL5L192XcYTZiRY5RNvkX0XbkI1VhcZpRvVUboO783c0aYk3HaH9AjjVpNUOz6AP7oNYdWa%2BBqjD6KY4lDz4ppjtGJyClpzP%2BXvNyhrL2ChSQrgKLmg7wKvTV5yciTtM7q8830QL9WNkUPXUkfHDQyMFS62jtzEAulOBw9PlxFnSMtX64IMtAkZcBi0zA25A%3D%3D (Caused by NewConnectionError('<urllib3.connection.HTTPSConnection object at 0x7f47d44569d0>: Failed to establish a new connection: [Errno 111] Connection refused'))
2024-01-30 16:19:46,162 ERROR   wandb-upload_0:1134320 [internal_api.py:upload_file():2767] upload_file request headers: {'User-Agent': 'python-requests/2.23.0', 'Accept-Encoding': 'gzip, deflate', 'Accept': '*/*', 'Connection': 'keep-alive', 'Content-Length': '15553'}
2024-01-30 16:19:46,162 ERROR   wandb-upload_0:1134320 [internal_api.py:upload_file():2769] upload_file response body: 
2024-01-30 16:20:31,489 ERROR   wandb-upload_1:1134320 [internal_api.py:upload_file():2765] upload_file exception https://storage.googleapis.com/wandb-artifacts-prod/wandb_artifacts/133981200/707679828/174a3d9bc61fec126cc7d5bdff5c6c5a?Expires=1706688948&GoogleAccessId=gorilla-files-url-signer-man%40wandb-production.iam.gserviceaccount.com&Signature=kbovuOHqx1zQ01k2JLv3vSDaYbHItTycqeq2YURNlbD5XRGkUvQrNZxJrbM6osH%2FENF6HvfcT%2BENYNpNC%2BL5OqLe%2FmpPae6eDy6NexFC7Zbbbn9d3G2XLZG9goE9iklwKX4KW1pd0VzWFfTel%2BLXIkIaFS0dWCAz2jiQuMLH7iAEoy5QbiMBP8lhXU9g1jMABHn8GXPrq1BY6Mv11K9TRqNDr05oEvZxddTyDwSBtZ5ywPejT5hE7v2D%2Blbt7shbB8A4xXrB2OflVHzyHKV74RagasqYRZZu0H7uvoCd5JAmTCIIMoiKQTdW3oHWTL%2F1Ja7qj52XwR7z51GvxZVvhg%3D%3D: HTTPSConnectionPool(host='storage.googleapis.com', port=443): Max retries exceeded with url: /wandb-artifacts-prod/wandb_artifacts/133981200/707679828/174a3d9bc61fec126cc7d5bdff5c6c5a?Expires=1706688948&GoogleAccessId=gorilla-files-url-signer-man%40wandb-production.iam.gserviceaccount.com&Signature=kbovuOHqx1zQ01k2JLv3vSDaYbHItTycqeq2YURNlbD5XRGkUvQrNZxJrbM6osH%2FENF6HvfcT%2BENYNpNC%2BL5OqLe%2FmpPae6eDy6NexFC7Zbbbn9d3G2XLZG9goE9iklwKX4KW1pd0VzWFfTel%2BLXIkIaFS0dWCAz2jiQuMLH7iAEoy5QbiMBP8lhXU9g1jMABHn8GXPrq1BY6Mv11K9TRqNDr05oEvZxddTyDwSBtZ5ywPejT5hE7v2D%2Blbt7shbB8A4xXrB2OflVHzyHKV74RagasqYRZZu0H7uvoCd5JAmTCIIMoiKQTdW3oHWTL%2F1Ja7qj52XwR7z51GvxZVvhg%3D%3D (Caused by NewConnectionError('<urllib3.connection.HTTPSConnection object at 0x7f47d44562b0>: Failed to establish a new connection: [Errno 111] Connection refused'))
2024-01-30 16:20:31,489 ERROR   wandb-upload_1:1134320 [internal_api.py:upload_file():2767] upload_file request headers: {'User-Agent': 'python-requests/2.23.0', 'Accept-Encoding': 'gzip, deflate', 'Accept': '*/*', 'Connection': 'keep-alive', 'Content-MD5': 'F0o9m8Yf7BJsx9W9/1xsWg==', 'Content-Type': 'text/plain; charset=utf-8', 'Content-Length': '2179'}
2024-01-30 16:20:31,489 ERROR   wandb-upload_1:1134320 [internal_api.py:upload_file():2769] upload_file response body: 
2024-01-30 16:20:32,741 ERROR   wandb-upload_2:1134320 [internal_api.py:upload_file():2765] upload_file exception https://storage.googleapis.com/wandb-artifacts-prod/wandb_artifacts/133981200/707679828/6873c23a2381d1524249eb1a948a45a5?Expires=1706688948&GoogleAccessId=gorilla-files-url-signer-man%40wandb-production.iam.gserviceaccount.com&Signature=c4l7issmW7JLxt%2F5iscJknq14hvYZvtF2GxzULmZuZuFAJ%2F9XDgpKYtL0M4ID77UMZgvwjxdjv6iO1HPm2i%2Fu6ogy7h5xHLRe4rQDX3k94rmTIhO%2FUHArMuR8wQR9%2FNUP2Z9TYpq0bGocaYm5xB2yEK%2BFAAF7JHHKdmu4clQQkzMPRoPoRQbpo1LvqvTBYfG%2F3BaewVmOiLE44F0S9TtUNZHVpHFx0OJyzH54n%2BLCqC4BBokBnRXGMVspDfurrfZTTaqS4bo4Gd113ehd9TNzRIawroe89EdL186rqaseJc6YZuiUYJD8lMZW3j%2Fdcyy%2Fop22jcv9B3fOEsjLcfxfQ%3D%3D: HTTPSConnectionPool(host='storage.googleapis.com', port=443): Max retries exceeded with url: /wandb-artifacts-prod/wandb_artifacts/133981200/707679828/6873c23a2381d1524249eb1a948a45a5?Expires=1706688948&GoogleAccessId=gorilla-files-url-signer-man%40wandb-production.iam.gserviceaccount.com&Signature=c4l7issmW7JLxt%2F5iscJknq14hvYZvtF2GxzULmZuZuFAJ%2F9XDgpKYtL0M4ID77UMZgvwjxdjv6iO1HPm2i%2Fu6ogy7h5xHLRe4rQDX3k94rmTIhO%2FUHArMuR8wQR9%2FNUP2Z9TYpq0bGocaYm5xB2yEK%2BFAAF7JHHKdmu4clQQkzMPRoPoRQbpo1LvqvTBYfG%2F3BaewVmOiLE44F0S9TtUNZHVpHFx0OJyzH54n%2BLCqC4BBokBnRXGMVspDfurrfZTTaqS4bo4Gd113ehd9TNzRIawroe89EdL186rqaseJc6YZuiUYJD8lMZW3j%2Fdcyy%2Fop22jcv9B3fOEsjLcfxfQ%3D%3D (Caused by NewConnectionError('<urllib3.connection.HTTPSConnection object at 0x7f47d4456460>: Failed to establish a new connection: [Errno 111] Connection refused'))
2024-01-30 16:20:32,742 ERROR   wandb-upload_2:1134320 [internal_api.py:upload_file():2767] upload_file request headers: {'User-Agent': 'python-requests/2.23.0', 'Accept-Encoding': 'gzip, deflate', 'Accept': '*/*', 'Connection': 'keep-alive', 'Content-MD5': 'aHPCOiOB0VJCSesalIpFpQ==', 'Content-Type': 'application/json', 'Content-Length': '609'}
2024-01-30 16:20:32,742 ERROR   wandb-upload_2:1134320 [internal_api.py:upload_file():2769] upload_file response body: 
2024-01-30 16:25:00,352 ERROR   wandb-upload_2:1134320 [internal_api.py:upload_file():2765] upload_file exception https://storage.googleapis.com/wandb-artifacts-prod/wandb_artifacts/133981200/707679828/6873c23a2381d1524249eb1a948a45a5?Expires=1706688948&GoogleAccessId=gorilla-files-url-signer-man%40wandb-production.iam.gserviceaccount.com&Signature=c4l7issmW7JLxt%2F5iscJknq14hvYZvtF2GxzULmZuZuFAJ%2F9XDgpKYtL0M4ID77UMZgvwjxdjv6iO1HPm2i%2Fu6ogy7h5xHLRe4rQDX3k94rmTIhO%2FUHArMuR8wQR9%2FNUP2Z9TYpq0bGocaYm5xB2yEK%2BFAAF7JHHKdmu4clQQkzMPRoPoRQbpo1LvqvTBYfG%2F3BaewVmOiLE44F0S9TtUNZHVpHFx0OJyzH54n%2BLCqC4BBokBnRXGMVspDfurrfZTTaqS4bo4Gd113ehd9TNzRIawroe89EdL186rqaseJc6YZuiUYJD8lMZW3j%2Fdcyy%2Fop22jcv9B3fOEsjLcfxfQ%3D%3D: HTTPSConnectionPool(host='storage.googleapis.com', port=443): Max retries exceeded with url: /wandb-artifacts-prod/wandb_artifacts/133981200/707679828/6873c23a2381d1524249eb1a948a45a5?Expires=1706688948&GoogleAccessId=gorilla-files-url-signer-man%40wandb-production.iam.gserviceaccount.com&Signature=c4l7issmW7JLxt%2F5iscJknq14hvYZvtF2GxzULmZuZuFAJ%2F9XDgpKYtL0M4ID77UMZgvwjxdjv6iO1HPm2i%2Fu6ogy7h5xHLRe4rQDX3k94rmTIhO%2FUHArMuR8wQR9%2FNUP2Z9TYpq0bGocaYm5xB2yEK%2BFAAF7JHHKdmu4clQQkzMPRoPoRQbpo1LvqvTBYfG%2F3BaewVmOiLE44F0S9TtUNZHVpHFx0OJyzH54n%2BLCqC4BBokBnRXGMVspDfurrfZTTaqS4bo4Gd113ehd9TNzRIawroe89EdL186rqaseJc6YZuiUYJD8lMZW3j%2Fdcyy%2Fop22jcv9B3fOEsjLcfxfQ%3D%3D (Caused by NewConnectionError('<urllib3.connection.HTTPSConnection object at 0x7f47d4457280>: Failed to establish a new connection: [Errno 111] Connection refused'))
2024-01-30 16:25:00,352 ERROR   wandb-upload_2:1134320 [internal_api.py:upload_file():2767] upload_file request headers: {'User-Agent': 'python-requests/2.23.0', 'Accept-Encoding': 'gzip, deflate', 'Accept': '*/*', 'Connection': 'keep-alive', 'Content-MD5': 'aHPCOiOB0VJCSesalIpFpQ==', 'Content-Type': 'application/json', 'Content-Length': '609'}
2024-01-30 16:25:00,352 ERROR   wandb-upload_2:1134320 [internal_api.py:upload_file():2769] upload_file response body: 
2024-01-30 16:25:39,718 ERROR   wandb-upload_1:1134320 [internal_api.py:upload_file():2765] upload_file exception https://storage.googleapis.com/wandb-artifacts-prod/wandb_artifacts/133981200/707679828/174a3d9bc61fec126cc7d5bdff5c6c5a?Expires=1706688948&GoogleAccessId=gorilla-files-url-signer-man%40wandb-production.iam.gserviceaccount.com&Signature=kbovuOHqx1zQ01k2JLv3vSDaYbHItTycqeq2YURNlbD5XRGkUvQrNZxJrbM6osH%2FENF6HvfcT%2BENYNpNC%2BL5OqLe%2FmpPae6eDy6NexFC7Zbbbn9d3G2XLZG9goE9iklwKX4KW1pd0VzWFfTel%2BLXIkIaFS0dWCAz2jiQuMLH7iAEoy5QbiMBP8lhXU9g1jMABHn8GXPrq1BY6Mv11K9TRqNDr05oEvZxddTyDwSBtZ5ywPejT5hE7v2D%2Blbt7shbB8A4xXrB2OflVHzyHKV74RagasqYRZZu0H7uvoCd5JAmTCIIMoiKQTdW3oHWTL%2F1Ja7qj52XwR7z51GvxZVvhg%3D%3D: HTTPSConnectionPool(host='storage.googleapis.com', port=443): Max retries exceeded with url: /wandb-artifacts-prod/wandb_artifacts/133981200/707679828/174a3d9bc61fec126cc7d5bdff5c6c5a?Expires=1706688948&GoogleAccessId=gorilla-files-url-signer-man%40wandb-production.iam.gserviceaccount.com&Signature=kbovuOHqx1zQ01k2JLv3vSDaYbHItTycqeq2YURNlbD5XRGkUvQrNZxJrbM6osH%2FENF6HvfcT%2BENYNpNC%2BL5OqLe%2FmpPae6eDy6NexFC7Zbbbn9d3G2XLZG9goE9iklwKX4KW1pd0VzWFfTel%2BLXIkIaFS0dWCAz2jiQuMLH7iAEoy5QbiMBP8lhXU9g1jMABHn8GXPrq1BY6Mv11K9TRqNDr05oEvZxddTyDwSBtZ5ywPejT5hE7v2D%2Blbt7shbB8A4xXrB2OflVHzyHKV74RagasqYRZZu0H7uvoCd5JAmTCIIMoiKQTdW3oHWTL%2F1Ja7qj52XwR7z51GvxZVvhg%3D%3D (Caused by NewConnectionError('<urllib3.connection.HTTPSConnection object at 0x7f47d4653130>: Failed to establish a new connection: [Errno 111] Connection refused'))
2024-01-30 16:25:39,718 ERROR   wandb-upload_1:1134320 [internal_api.py:upload_file():2767] upload_file request headers: {'User-Agent': 'python-requests/2.23.0', 'Accept-Encoding': 'gzip, deflate', 'Accept': '*/*', 'Connection': 'keep-alive', 'Content-MD5': 'F0o9m8Yf7BJsx9W9/1xsWg==', 'Content-Type': 'text/plain; charset=utf-8', 'Content-Length': '2179'}
2024-01-30 16:25:39,718 ERROR   wandb-upload_1:1134320 [internal_api.py:upload_file():2769] upload_file response body: 
2024-01-30 16:25:58,602 ERROR   wandb-upload_0:1134320 [internal_api.py:upload_file():2765] upload_file exception https://storage.googleapis.com/wandb-production.appspot.com/dynamic_x/bert_pytorch/wn1qxvno/wandb-metadata.json?Expires=1706688636&GoogleAccessId=gorilla-files-url-signer-man%40wandb-production.iam.gserviceaccount.com&Signature=X2NQsRBPxmFG1jesoKIgaYH%2BEuVtOiN9iCNyn2nXM0cUCfxLAaAA%2Bk3hpaoW2l5axIqryRk6aj9eSNHiDB95u6Hf7uUfIhqHdFIO604O3XU8FxsVDC6sl62BCb5Gv1YZELF0wwnCYUabk5D8%2BySwHmTL5L192XcYTZiRY5RNvkX0XbkI1VhcZpRvVUboO783c0aYk3HaH9AjjVpNUOz6AP7oNYdWa%2BBqjD6KY4lDz4ppjtGJyClpzP%2BXvNyhrL2ChSQrgKLmg7wKvTV5yciTtM7q8830QL9WNkUPXUkfHDQyMFS62jtzEAulOBw9PlxFnSMtX64IMtAkZcBi0zA25A%3D%3D: HTTPSConnectionPool(host='storage.googleapis.com', port=443): Max retries exceeded with url: /wandb-production.appspot.com/dynamic_x/bert_pytorch/wn1qxvno/wandb-metadata.json?Expires=1706688636&GoogleAccessId=gorilla-files-url-signer-man%40wandb-production.iam.gserviceaccount.com&Signature=X2NQsRBPxmFG1jesoKIgaYH%2BEuVtOiN9iCNyn2nXM0cUCfxLAaAA%2Bk3hpaoW2l5axIqryRk6aj9eSNHiDB95u6Hf7uUfIhqHdFIO604O3XU8FxsVDC6sl62BCb5Gv1YZELF0wwnCYUabk5D8%2BySwHmTL5L192XcYTZiRY5RNvkX0XbkI1VhcZpRvVUboO783c0aYk3HaH9AjjVpNUOz6AP7oNYdWa%2BBqjD6KY4lDz4ppjtGJyClpzP%2BXvNyhrL2ChSQrgKLmg7wKvTV5yciTtM7q8830QL9WNkUPXUkfHDQyMFS62jtzEAulOBw9PlxFnSMtX64IMtAkZcBi0zA25A%3D%3D (Caused by NewConnectionError('<urllib3.connection.HTTPSConnection object at 0x7f47d460a790>: Failed to establish a new connection: [Errno 111] Connection refused'))
2024-01-30 16:25:58,603 ERROR   wandb-upload_0:1134320 [internal_api.py:upload_file():2767] upload_file request headers: {'User-Agent': 'python-requests/2.23.0', 'Accept-Encoding': 'gzip, deflate', 'Accept': '*/*', 'Connection': 'keep-alive', 'Content-Length': '15553'}
2024-01-30 16:25:58,603 ERROR   wandb-upload_0:1134320 [internal_api.py:upload_file():2769] upload_file response body: 
2024-01-30 16:30:17,430 ERROR   wandb-upload_2:1134320 [internal_api.py:upload_file():2765] upload_file exception https://storage.googleapis.com/wandb-artifacts-prod/wandb_artifacts/133981200/707679828/6873c23a2381d1524249eb1a948a45a5?Expires=1706688948&GoogleAccessId=gorilla-files-url-signer-man%40wandb-production.iam.gserviceaccount.com&Signature=c4l7issmW7JLxt%2F5iscJknq14hvYZvtF2GxzULmZuZuFAJ%2F9XDgpKYtL0M4ID77UMZgvwjxdjv6iO1HPm2i%2Fu6ogy7h5xHLRe4rQDX3k94rmTIhO%2FUHArMuR8wQR9%2FNUP2Z9TYpq0bGocaYm5xB2yEK%2BFAAF7JHHKdmu4clQQkzMPRoPoRQbpo1LvqvTBYfG%2F3BaewVmOiLE44F0S9TtUNZHVpHFx0OJyzH54n%2BLCqC4BBokBnRXGMVspDfurrfZTTaqS4bo4Gd113ehd9TNzRIawroe89EdL186rqaseJc6YZuiUYJD8lMZW3j%2Fdcyy%2Fop22jcv9B3fOEsjLcfxfQ%3D%3D: HTTPSConnectionPool(host='storage.googleapis.com', port=443): Max retries exceeded with url: /wandb-artifacts-prod/wandb_artifacts/133981200/707679828/6873c23a2381d1524249eb1a948a45a5?Expires=1706688948&GoogleAccessId=gorilla-files-url-signer-man%40wandb-production.iam.gserviceaccount.com&Signature=c4l7issmW7JLxt%2F5iscJknq14hvYZvtF2GxzULmZuZuFAJ%2F9XDgpKYtL0M4ID77UMZgvwjxdjv6iO1HPm2i%2Fu6ogy7h5xHLRe4rQDX3k94rmTIhO%2FUHArMuR8wQR9%2FNUP2Z9TYpq0bGocaYm5xB2yEK%2BFAAF7JHHKdmu4clQQkzMPRoPoRQbpo1LvqvTBYfG%2F3BaewVmOiLE44F0S9TtUNZHVpHFx0OJyzH54n%2BLCqC4BBokBnRXGMVspDfurrfZTTaqS4bo4Gd113ehd9TNzRIawroe89EdL186rqaseJc6YZuiUYJD8lMZW3j%2Fdcyy%2Fop22jcv9B3fOEsjLcfxfQ%3D%3D (Caused by NewConnectionError('<urllib3.connection.HTTPSConnection object at 0x7f47d444d640>: Failed to establish a new connection: [Errno 111] Connection refused'))
2024-01-30 16:30:17,431 ERROR   wandb-upload_2:1134320 [internal_api.py:upload_file():2767] upload_file request headers: {'User-Agent': 'python-requests/2.23.0', 'Accept-Encoding': 'gzip, deflate', 'Accept': '*/*', 'Connection': 'keep-alive', 'Content-MD5': 'aHPCOiOB0VJCSesalIpFpQ==', 'Content-Type': 'application/json', 'Content-Length': '609'}
2024-01-30 16:30:17,431 ERROR   wandb-upload_2:1134320 [internal_api.py:upload_file():2769] upload_file response body: 
2024-01-30 16:31:51,471 ERROR   wandb-upload_1:1134320 [internal_api.py:upload_file():2765] upload_file exception https://storage.googleapis.com/wandb-artifacts-prod/wandb_artifacts/133981200/707679828/174a3d9bc61fec126cc7d5bdff5c6c5a?Expires=1706688948&GoogleAccessId=gorilla-files-url-signer-man%40wandb-production.iam.gserviceaccount.com&Signature=kbovuOHqx1zQ01k2JLv3vSDaYbHItTycqeq2YURNlbD5XRGkUvQrNZxJrbM6osH%2FENF6HvfcT%2BENYNpNC%2BL5OqLe%2FmpPae6eDy6NexFC7Zbbbn9d3G2XLZG9goE9iklwKX4KW1pd0VzWFfTel%2BLXIkIaFS0dWCAz2jiQuMLH7iAEoy5QbiMBP8lhXU9g1jMABHn8GXPrq1BY6Mv11K9TRqNDr05oEvZxddTyDwSBtZ5ywPejT5hE7v2D%2Blbt7shbB8A4xXrB2OflVHzyHKV74RagasqYRZZu0H7uvoCd5JAmTCIIMoiKQTdW3oHWTL%2F1Ja7qj52XwR7z51GvxZVvhg%3D%3D: HTTPSConnectionPool(host='storage.googleapis.com', port=443): Max retries exceeded with url: /wandb-artifacts-prod/wandb_artifacts/133981200/707679828/174a3d9bc61fec126cc7d5bdff5c6c5a?Expires=1706688948&GoogleAccessId=gorilla-files-url-signer-man%40wandb-production.iam.gserviceaccount.com&Signature=kbovuOHqx1zQ01k2JLv3vSDaYbHItTycqeq2YURNlbD5XRGkUvQrNZxJrbM6osH%2FENF6HvfcT%2BENYNpNC%2BL5OqLe%2FmpPae6eDy6NexFC7Zbbbn9d3G2XLZG9goE9iklwKX4KW1pd0VzWFfTel%2BLXIkIaFS0dWCAz2jiQuMLH7iAEoy5QbiMBP8lhXU9g1jMABHn8GXPrq1BY6Mv11K9TRqNDr05oEvZxddTyDwSBtZ5ywPejT5hE7v2D%2Blbt7shbB8A4xXrB2OflVHzyHKV74RagasqYRZZu0H7uvoCd5JAmTCIIMoiKQTdW3oHWTL%2F1Ja7qj52XwR7z51GvxZVvhg%3D%3D (Caused by NewConnectionError('<urllib3.connection.HTTPSConnection object at 0x7f47d445a400>: Failed to establish a new connection: [Errno 111] Connection refused'))
2024-01-30 16:31:51,471 ERROR   wandb-upload_1:1134320 [internal_api.py:upload_file():2767] upload_file request headers: {'User-Agent': 'python-requests/2.23.0', 'Accept-Encoding': 'gzip, deflate', 'Accept': '*/*', 'Connection': 'keep-alive', 'Content-MD5': 'F0o9m8Yf7BJsx9W9/1xsWg==', 'Content-Type': 'text/plain; charset=utf-8', 'Content-Length': '2179'}
2024-01-30 16:31:51,471 ERROR   wandb-upload_1:1134320 [internal_api.py:upload_file():2769] upload_file response body: 
2024-01-30 16:32:13,599 ERROR   wandb-upload_0:1134320 [internal_api.py:upload_file():2765] upload_file exception https://storage.googleapis.com/wandb-production.appspot.com/dynamic_x/bert_pytorch/wn1qxvno/wandb-metadata.json?Expires=1706688636&GoogleAccessId=gorilla-files-url-signer-man%40wandb-production.iam.gserviceaccount.com&Signature=X2NQsRBPxmFG1jesoKIgaYH%2BEuVtOiN9iCNyn2nXM0cUCfxLAaAA%2Bk3hpaoW2l5axIqryRk6aj9eSNHiDB95u6Hf7uUfIhqHdFIO604O3XU8FxsVDC6sl62BCb5Gv1YZELF0wwnCYUabk5D8%2BySwHmTL5L192XcYTZiRY5RNvkX0XbkI1VhcZpRvVUboO783c0aYk3HaH9AjjVpNUOz6AP7oNYdWa%2BBqjD6KY4lDz4ppjtGJyClpzP%2BXvNyhrL2ChSQrgKLmg7wKvTV5yciTtM7q8830QL9WNkUPXUkfHDQyMFS62jtzEAulOBw9PlxFnSMtX64IMtAkZcBi0zA25A%3D%3D: HTTPSConnectionPool(host='storage.googleapis.com', port=443): Max retries exceeded with url: /wandb-production.appspot.com/dynamic_x/bert_pytorch/wn1qxvno/wandb-metadata.json?Expires=1706688636&GoogleAccessId=gorilla-files-url-signer-man%40wandb-production.iam.gserviceaccount.com&Signature=X2NQsRBPxmFG1jesoKIgaYH%2BEuVtOiN9iCNyn2nXM0cUCfxLAaAA%2Bk3hpaoW2l5axIqryRk6aj9eSNHiDB95u6Hf7uUfIhqHdFIO604O3XU8FxsVDC6sl62BCb5Gv1YZELF0wwnCYUabk5D8%2BySwHmTL5L192XcYTZiRY5RNvkX0XbkI1VhcZpRvVUboO783c0aYk3HaH9AjjVpNUOz6AP7oNYdWa%2BBqjD6KY4lDz4ppjtGJyClpzP%2BXvNyhrL2ChSQrgKLmg7wKvTV5yciTtM7q8830QL9WNkUPXUkfHDQyMFS62jtzEAulOBw9PlxFnSMtX64IMtAkZcBi0zA25A%3D%3D (Caused by NewConnectionError('<urllib3.connection.HTTPSConnection object at 0x7f47d4457fd0>: Failed to establish a new connection: [Errno 111] Connection refused'))
2024-01-30 16:32:13,599 ERROR   wandb-upload_0:1134320 [internal_api.py:upload_file():2767] upload_file request headers: {'User-Agent': 'python-requests/2.23.0', 'Accept-Encoding': 'gzip, deflate', 'Accept': '*/*', 'Connection': 'keep-alive', 'Content-Length': '15553'}
2024-01-30 16:32:13,599 ERROR   wandb-upload_0:1134320 [internal_api.py:upload_file():2769] upload_file response body: 
2024-01-30 16:36:30,092 ERROR   wandb-upload_2:1134320 [internal_api.py:upload_file():2765] upload_file exception https://storage.googleapis.com/wandb-artifacts-prod/wandb_artifacts/133981200/707679828/6873c23a2381d1524249eb1a948a45a5?Expires=1706688948&GoogleAccessId=gorilla-files-url-signer-man%40wandb-production.iam.gserviceaccount.com&Signature=c4l7issmW7JLxt%2F5iscJknq14hvYZvtF2GxzULmZuZuFAJ%2F9XDgpKYtL0M4ID77UMZgvwjxdjv6iO1HPm2i%2Fu6ogy7h5xHLRe4rQDX3k94rmTIhO%2FUHArMuR8wQR9%2FNUP2Z9TYpq0bGocaYm5xB2yEK%2BFAAF7JHHKdmu4clQQkzMPRoPoRQbpo1LvqvTBYfG%2F3BaewVmOiLE44F0S9TtUNZHVpHFx0OJyzH54n%2BLCqC4BBokBnRXGMVspDfurrfZTTaqS4bo4Gd113ehd9TNzRIawroe89EdL186rqaseJc6YZuiUYJD8lMZW3j%2Fdcyy%2Fop22jcv9B3fOEsjLcfxfQ%3D%3D: HTTPSConnectionPool(host='storage.googleapis.com', port=443): Max retries exceeded with url: /wandb-artifacts-prod/wandb_artifacts/133981200/707679828/6873c23a2381d1524249eb1a948a45a5?Expires=1706688948&GoogleAccessId=gorilla-files-url-signer-man%40wandb-production.iam.gserviceaccount.com&Signature=c4l7issmW7JLxt%2F5iscJknq14hvYZvtF2GxzULmZuZuFAJ%2F9XDgpKYtL0M4ID77UMZgvwjxdjv6iO1HPm2i%2Fu6ogy7h5xHLRe4rQDX3k94rmTIhO%2FUHArMuR8wQR9%2FNUP2Z9TYpq0bGocaYm5xB2yEK%2BFAAF7JHHKdmu4clQQkzMPRoPoRQbpo1LvqvTBYfG%2F3BaewVmOiLE44F0S9TtUNZHVpHFx0OJyzH54n%2BLCqC4BBokBnRXGMVspDfurrfZTTaqS4bo4Gd113ehd9TNzRIawroe89EdL186rqaseJc6YZuiUYJD8lMZW3j%2Fdcyy%2Fop22jcv9B3fOEsjLcfxfQ%3D%3D (Caused by NewConnectionError('<urllib3.connection.HTTPSConnection object at 0x7f47d445a490>: Failed to establish a new connection: [Errno 111] Connection refused'))
2024-01-30 16:36:30,092 ERROR   wandb-upload_2:1134320 [internal_api.py:upload_file():2767] upload_file request headers: {'User-Agent': 'python-requests/2.23.0', 'Accept-Encoding': 'gzip, deflate', 'Accept': '*/*', 'Connection': 'keep-alive', 'Content-MD5': 'aHPCOiOB0VJCSesalIpFpQ==', 'Content-Type': 'application/json', 'Content-Length': '609'}
2024-01-30 16:36:30,092 ERROR   wandb-upload_2:1134320 [internal_api.py:upload_file():2769] upload_file response body: 
2024-01-30 16:37:43,626 ERROR   wandb-upload_1:1134320 [internal_api.py:upload_file():2765] upload_file exception https://storage.googleapis.com/wandb-artifacts-prod/wandb_artifacts/133981200/707679828/174a3d9bc61fec126cc7d5bdff5c6c5a?Expires=1706688948&GoogleAccessId=gorilla-files-url-signer-man%40wandb-production.iam.gserviceaccount.com&Signature=kbovuOHqx1zQ01k2JLv3vSDaYbHItTycqeq2YURNlbD5XRGkUvQrNZxJrbM6osH%2FENF6HvfcT%2BENYNpNC%2BL5OqLe%2FmpPae6eDy6NexFC7Zbbbn9d3G2XLZG9goE9iklwKX4KW1pd0VzWFfTel%2BLXIkIaFS0dWCAz2jiQuMLH7iAEoy5QbiMBP8lhXU9g1jMABHn8GXPrq1BY6Mv11K9TRqNDr05oEvZxddTyDwSBtZ5ywPejT5hE7v2D%2Blbt7shbB8A4xXrB2OflVHzyHKV74RagasqYRZZu0H7uvoCd5JAmTCIIMoiKQTdW3oHWTL%2F1Ja7qj52XwR7z51GvxZVvhg%3D%3D: HTTPSConnectionPool(host='storage.googleapis.com', port=443): Max retries exceeded with url: /wandb-artifacts-prod/wandb_artifacts/133981200/707679828/174a3d9bc61fec126cc7d5bdff5c6c5a?Expires=1706688948&GoogleAccessId=gorilla-files-url-signer-man%40wandb-production.iam.gserviceaccount.com&Signature=kbovuOHqx1zQ01k2JLv3vSDaYbHItTycqeq2YURNlbD5XRGkUvQrNZxJrbM6osH%2FENF6HvfcT%2BENYNpNC%2BL5OqLe%2FmpPae6eDy6NexFC7Zbbbn9d3G2XLZG9goE9iklwKX4KW1pd0VzWFfTel%2BLXIkIaFS0dWCAz2jiQuMLH7iAEoy5QbiMBP8lhXU9g1jMABHn8GXPrq1BY6Mv11K9TRqNDr05oEvZxddTyDwSBtZ5ywPejT5hE7v2D%2Blbt7shbB8A4xXrB2OflVHzyHKV74RagasqYRZZu0H7uvoCd5JAmTCIIMoiKQTdW3oHWTL%2F1Ja7qj52XwR7z51GvxZVvhg%3D%3D (Caused by NewConnectionError('<urllib3.connection.HTTPSConnection object at 0x7f47d445ab50>: Failed to establish a new connection: [Errno 111] Connection refused'))
2024-01-30 16:37:43,627 ERROR   wandb-upload_1:1134320 [internal_api.py:upload_file():2767] upload_file request headers: {'User-Agent': 'python-requests/2.23.0', 'Accept-Encoding': 'gzip, deflate', 'Accept': '*/*', 'Connection': 'keep-alive', 'Content-MD5': 'F0o9m8Yf7BJsx9W9/1xsWg==', 'Content-Type': 'text/plain; charset=utf-8', 'Content-Length': '2179'}
2024-01-30 16:37:43,627 ERROR   wandb-upload_1:1134320 [internal_api.py:upload_file():2769] upload_file response body: 
2024-01-30 16:37:46,110 WARNING StreamThr :1134320 [internal.py:is_dead():414] Internal process exiting, parent pid 1134039 disappeared
2024-01-30 16:37:46,110 ERROR   StreamThr :1134320 [internal.py:wandb_internal():152] Internal process shutdown.
2024-01-30 16:37:47,050 INFO    WriterThread:1134320 [datastore.py:close():296] close: /home/yanxindong/mkor/bert/wandb/run-20240130_161012-wn1qxvno/run-wn1qxvno.wandb
2024-01-30 16:37:47,066 INFO    HandlerThread:1134320 [handler.py:finish():869] shutting down handler
2024-01-30 16:38:23,275 ERROR   wandb-upload_0:1134320 [internal_api.py:upload_file():2765] upload_file exception https://storage.googleapis.com/wandb-production.appspot.com/dynamic_x/bert_pytorch/wn1qxvno/wandb-metadata.json?Expires=1706688636&GoogleAccessId=gorilla-files-url-signer-man%40wandb-production.iam.gserviceaccount.com&Signature=X2NQsRBPxmFG1jesoKIgaYH%2BEuVtOiN9iCNyn2nXM0cUCfxLAaAA%2Bk3hpaoW2l5axIqryRk6aj9eSNHiDB95u6Hf7uUfIhqHdFIO604O3XU8FxsVDC6sl62BCb5Gv1YZELF0wwnCYUabk5D8%2BySwHmTL5L192XcYTZiRY5RNvkX0XbkI1VhcZpRvVUboO783c0aYk3HaH9AjjVpNUOz6AP7oNYdWa%2BBqjD6KY4lDz4ppjtGJyClpzP%2BXvNyhrL2ChSQrgKLmg7wKvTV5yciTtM7q8830QL9WNkUPXUkfHDQyMFS62jtzEAulOBw9PlxFnSMtX64IMtAkZcBi0zA25A%3D%3D: HTTPSConnectionPool(host='storage.googleapis.com', port=443): Max retries exceeded with url: /wandb-production.appspot.com/dynamic_x/bert_pytorch/wn1qxvno/wandb-metadata.json?Expires=1706688636&GoogleAccessId=gorilla-files-url-signer-man%40wandb-production.iam.gserviceaccount.com&Signature=X2NQsRBPxmFG1jesoKIgaYH%2BEuVtOiN9iCNyn2nXM0cUCfxLAaAA%2Bk3hpaoW2l5axIqryRk6aj9eSNHiDB95u6Hf7uUfIhqHdFIO604O3XU8FxsVDC6sl62BCb5Gv1YZELF0wwnCYUabk5D8%2BySwHmTL5L192XcYTZiRY5RNvkX0XbkI1VhcZpRvVUboO783c0aYk3HaH9AjjVpNUOz6AP7oNYdWa%2BBqjD6KY4lDz4ppjtGJyClpzP%2BXvNyhrL2ChSQrgKLmg7wKvTV5yciTtM7q8830QL9WNkUPXUkfHDQyMFS62jtzEAulOBw9PlxFnSMtX64IMtAkZcBi0zA25A%3D%3D (Caused by NewConnectionError('<urllib3.connection.HTTPSConnection object at 0x7f47d44504f0>: Failed to establish a new connection: [Errno 111] Connection refused'))
2024-01-30 16:38:23,275 ERROR   wandb-upload_0:1134320 [internal_api.py:upload_file():2767] upload_file request headers: {'User-Agent': 'python-requests/2.23.0', 'Accept-Encoding': 'gzip, deflate', 'Accept': '*/*', 'Connection': 'keep-alive', 'Content-Length': '15553'}
2024-01-30 16:38:23,275 ERROR   wandb-upload_0:1134320 [internal_api.py:upload_file():2769] upload_file response body: 
2024-01-30 16:41:46,953 ERROR   wandb-upload_2:1134320 [internal_api.py:upload_file():2765] upload_file exception https://storage.googleapis.com/wandb-artifacts-prod/wandb_artifacts/133981200/707679828/6873c23a2381d1524249eb1a948a45a5?Expires=1706688948&GoogleAccessId=gorilla-files-url-signer-man%40wandb-production.iam.gserviceaccount.com&Signature=c4l7issmW7JLxt%2F5iscJknq14hvYZvtF2GxzULmZuZuFAJ%2F9XDgpKYtL0M4ID77UMZgvwjxdjv6iO1HPm2i%2Fu6ogy7h5xHLRe4rQDX3k94rmTIhO%2FUHArMuR8wQR9%2FNUP2Z9TYpq0bGocaYm5xB2yEK%2BFAAF7JHHKdmu4clQQkzMPRoPoRQbpo1LvqvTBYfG%2F3BaewVmOiLE44F0S9TtUNZHVpHFx0OJyzH54n%2BLCqC4BBokBnRXGMVspDfurrfZTTaqS4bo4Gd113ehd9TNzRIawroe89EdL186rqaseJc6YZuiUYJD8lMZW3j%2Fdcyy%2Fop22jcv9B3fOEsjLcfxfQ%3D%3D: HTTPSConnectionPool(host='storage.googleapis.com', port=443): Max retries exceeded with url: /wandb-artifacts-prod/wandb_artifacts/133981200/707679828/6873c23a2381d1524249eb1a948a45a5?Expires=1706688948&GoogleAccessId=gorilla-files-url-signer-man%40wandb-production.iam.gserviceaccount.com&Signature=c4l7issmW7JLxt%2F5iscJknq14hvYZvtF2GxzULmZuZuFAJ%2F9XDgpKYtL0M4ID77UMZgvwjxdjv6iO1HPm2i%2Fu6ogy7h5xHLRe4rQDX3k94rmTIhO%2FUHArMuR8wQR9%2FNUP2Z9TYpq0bGocaYm5xB2yEK%2BFAAF7JHHKdmu4clQQkzMPRoPoRQbpo1LvqvTBYfG%2F3BaewVmOiLE44F0S9TtUNZHVpHFx0OJyzH54n%2BLCqC4BBokBnRXGMVspDfurrfZTTaqS4bo4Gd113ehd9TNzRIawroe89EdL186rqaseJc6YZuiUYJD8lMZW3j%2Fdcyy%2Fop22jcv9B3fOEsjLcfxfQ%3D%3D (Caused by NewConnectionError('<urllib3.connection.HTTPSConnection object at 0x7f47d445a5b0>: Failed to establish a new connection: [Errno 101] Network is unreachable'))
2024-01-30 16:41:46,953 ERROR   wandb-upload_2:1134320 [internal_api.py:upload_file():2767] upload_file request headers: {'User-Agent': 'python-requests/2.23.0', 'Accept-Encoding': 'gzip, deflate', 'Accept': '*/*', 'Connection': 'keep-alive', 'Content-MD5': 'aHPCOiOB0VJCSesalIpFpQ==', 'Content-Type': 'application/json', 'Content-Length': '609'}
2024-01-30 16:41:46,953 ERROR   wandb-upload_2:1134320 [internal_api.py:upload_file():2769] upload_file response body: 
2024-01-30 16:42:49,306 ERROR   wandb-upload_1:1134320 [internal_api.py:upload_file():2765] upload_file exception https://storage.googleapis.com/wandb-artifacts-prod/wandb_artifacts/133981200/707679828/174a3d9bc61fec126cc7d5bdff5c6c5a?Expires=1706688948&GoogleAccessId=gorilla-files-url-signer-man%40wandb-production.iam.gserviceaccount.com&Signature=kbovuOHqx1zQ01k2JLv3vSDaYbHItTycqeq2YURNlbD5XRGkUvQrNZxJrbM6osH%2FENF6HvfcT%2BENYNpNC%2BL5OqLe%2FmpPae6eDy6NexFC7Zbbbn9d3G2XLZG9goE9iklwKX4KW1pd0VzWFfTel%2BLXIkIaFS0dWCAz2jiQuMLH7iAEoy5QbiMBP8lhXU9g1jMABHn8GXPrq1BY6Mv11K9TRqNDr05oEvZxddTyDwSBtZ5ywPejT5hE7v2D%2Blbt7shbB8A4xXrB2OflVHzyHKV74RagasqYRZZu0H7uvoCd5JAmTCIIMoiKQTdW3oHWTL%2F1Ja7qj52XwR7z51GvxZVvhg%3D%3D: HTTPSConnectionPool(host='storage.googleapis.com', port=443): Max retries exceeded with url: /wandb-artifacts-prod/wandb_artifacts/133981200/707679828/174a3d9bc61fec126cc7d5bdff5c6c5a?Expires=1706688948&GoogleAccessId=gorilla-files-url-signer-man%40wandb-production.iam.gserviceaccount.com&Signature=kbovuOHqx1zQ01k2JLv3vSDaYbHItTycqeq2YURNlbD5XRGkUvQrNZxJrbM6osH%2FENF6HvfcT%2BENYNpNC%2BL5OqLe%2FmpPae6eDy6NexFC7Zbbbn9d3G2XLZG9goE9iklwKX4KW1pd0VzWFfTel%2BLXIkIaFS0dWCAz2jiQuMLH7iAEoy5QbiMBP8lhXU9g1jMABHn8GXPrq1BY6Mv11K9TRqNDr05oEvZxddTyDwSBtZ5ywPejT5hE7v2D%2Blbt7shbB8A4xXrB2OflVHzyHKV74RagasqYRZZu0H7uvoCd5JAmTCIIMoiKQTdW3oHWTL%2F1Ja7qj52XwR7z51GvxZVvhg%3D%3D (Caused by NewConnectionError('<urllib3.connection.HTTPSConnection object at 0x7f47d444f550>: Failed to establish a new connection: [Errno 101] Network is unreachable'))
2024-01-30 16:42:49,306 ERROR   wandb-upload_1:1134320 [internal_api.py:upload_file():2767] upload_file request headers: {'User-Agent': 'python-requests/2.23.0', 'Accept-Encoding': 'gzip, deflate', 'Accept': '*/*', 'Connection': 'keep-alive', 'Content-MD5': 'F0o9m8Yf7BJsx9W9/1xsWg==', 'Content-Type': 'text/plain; charset=utf-8', 'Content-Length': '2179'}
2024-01-30 16:42:49,307 ERROR   wandb-upload_1:1134320 [internal_api.py:upload_file():2769] upload_file response body: 
2024-01-30 16:43:32,223 ERROR   wandb-upload_0:1134320 [internal_api.py:upload_file():2765] upload_file exception https://storage.googleapis.com/wandb-production.appspot.com/dynamic_x/bert_pytorch/wn1qxvno/wandb-metadata.json?Expires=1706688636&GoogleAccessId=gorilla-files-url-signer-man%40wandb-production.iam.gserviceaccount.com&Signature=X2NQsRBPxmFG1jesoKIgaYH%2BEuVtOiN9iCNyn2nXM0cUCfxLAaAA%2Bk3hpaoW2l5axIqryRk6aj9eSNHiDB95u6Hf7uUfIhqHdFIO604O3XU8FxsVDC6sl62BCb5Gv1YZELF0wwnCYUabk5D8%2BySwHmTL5L192XcYTZiRY5RNvkX0XbkI1VhcZpRvVUboO783c0aYk3HaH9AjjVpNUOz6AP7oNYdWa%2BBqjD6KY4lDz4ppjtGJyClpzP%2BXvNyhrL2ChSQrgKLmg7wKvTV5yciTtM7q8830QL9WNkUPXUkfHDQyMFS62jtzEAulOBw9PlxFnSMtX64IMtAkZcBi0zA25A%3D%3D: HTTPSConnectionPool(host='storage.googleapis.com', port=443): Max retries exceeded with url: /wandb-production.appspot.com/dynamic_x/bert_pytorch/wn1qxvno/wandb-metadata.json?Expires=1706688636&GoogleAccessId=gorilla-files-url-signer-man%40wandb-production.iam.gserviceaccount.com&Signature=X2NQsRBPxmFG1jesoKIgaYH%2BEuVtOiN9iCNyn2nXM0cUCfxLAaAA%2Bk3hpaoW2l5axIqryRk6aj9eSNHiDB95u6Hf7uUfIhqHdFIO604O3XU8FxsVDC6sl62BCb5Gv1YZELF0wwnCYUabk5D8%2BySwHmTL5L192XcYTZiRY5RNvkX0XbkI1VhcZpRvVUboO783c0aYk3HaH9AjjVpNUOz6AP7oNYdWa%2BBqjD6KY4lDz4ppjtGJyClpzP%2BXvNyhrL2ChSQrgKLmg7wKvTV5yciTtM7q8830QL9WNkUPXUkfHDQyMFS62jtzEAulOBw9PlxFnSMtX64IMtAkZcBi0zA25A%3D%3D (Caused by NewConnectionError('<urllib3.connection.HTTPSConnection object at 0x7f47d4450310>: Failed to establish a new connection: [Errno 101] Network is unreachable'))
2024-01-30 16:43:32,224 ERROR   wandb-upload_0:1134320 [internal_api.py:upload_file():2767] upload_file request headers: {'User-Agent': 'python-requests/2.23.0', 'Accept-Encoding': 'gzip, deflate', 'Accept': '*/*', 'Connection': 'keep-alive', 'Content-Length': '15553'}
2024-01-30 16:43:32,224 ERROR   wandb-upload_0:1134320 [internal_api.py:upload_file():2769] upload_file response body: 
2024-01-30 17:11:53,590 ERROR   wandb-upload_2:1134320 [internal_api.py:upload_file():2765] upload_file exception https://storage.googleapis.com/wandb-artifacts-prod/wandb_artifacts/133981200/707679828/6873c23a2381d1524249eb1a948a45a5?Expires=1706688948&GoogleAccessId=gorilla-files-url-signer-man%40wandb-production.iam.gserviceaccount.com&Signature=c4l7issmW7JLxt%2F5iscJknq14hvYZvtF2GxzULmZuZuFAJ%2F9XDgpKYtL0M4ID77UMZgvwjxdjv6iO1HPm2i%2Fu6ogy7h5xHLRe4rQDX3k94rmTIhO%2FUHArMuR8wQR9%2FNUP2Z9TYpq0bGocaYm5xB2yEK%2BFAAF7JHHKdmu4clQQkzMPRoPoRQbpo1LvqvTBYfG%2F3BaewVmOiLE44F0S9TtUNZHVpHFx0OJyzH54n%2BLCqC4BBokBnRXGMVspDfurrfZTTaqS4bo4Gd113ehd9TNzRIawroe89EdL186rqaseJc6YZuiUYJD8lMZW3j%2Fdcyy%2Fop22jcv9B3fOEsjLcfxfQ%3D%3D: HTTPSConnectionPool(host='storage.googleapis.com', port=443): Max retries exceeded with url: /wandb-artifacts-prod/wandb_artifacts/133981200/707679828/6873c23a2381d1524249eb1a948a45a5?Expires=1706688948&GoogleAccessId=gorilla-files-url-signer-man%40wandb-production.iam.gserviceaccount.com&Signature=c4l7issmW7JLxt%2F5iscJknq14hvYZvtF2GxzULmZuZuFAJ%2F9XDgpKYtL0M4ID77UMZgvwjxdjv6iO1HPm2i%2Fu6ogy7h5xHLRe4rQDX3k94rmTIhO%2FUHArMuR8wQR9%2FNUP2Z9TYpq0bGocaYm5xB2yEK%2BFAAF7JHHKdmu4clQQkzMPRoPoRQbpo1LvqvTBYfG%2F3BaewVmOiLE44F0S9TtUNZHVpHFx0OJyzH54n%2BLCqC4BBokBnRXGMVspDfurrfZTTaqS4bo4Gd113ehd9TNzRIawroe89EdL186rqaseJc6YZuiUYJD8lMZW3j%2Fdcyy%2Fop22jcv9B3fOEsjLcfxfQ%3D%3D (Caused by NewConnectionError('<urllib3.connection.HTTPSConnection object at 0x7f47d4450eb0>: Failed to establish a new connection: [Errno 110] Connection timed out'))
2024-01-30 17:11:53,590 ERROR   wandb-upload_2:1134320 [internal_api.py:upload_file():2767] upload_file request headers: {'User-Agent': 'python-requests/2.23.0', 'Accept-Encoding': 'gzip, deflate', 'Accept': '*/*', 'Connection': 'keep-alive', 'Content-MD5': 'aHPCOiOB0VJCSesalIpFpQ==', 'Content-Type': 'application/json', 'Content-Length': '609'}
2024-01-30 17:11:53,590 ERROR   wandb-upload_2:1134320 [internal_api.py:upload_file():2769] upload_file response body: 
2024-01-30 17:12:22,262 ERROR   wandb-upload_1:1134320 [internal_api.py:upload_file():2765] upload_file exception https://storage.googleapis.com/wandb-artifacts-prod/wandb_artifacts/133981200/707679828/174a3d9bc61fec126cc7d5bdff5c6c5a?Expires=1706688948&GoogleAccessId=gorilla-files-url-signer-man%40wandb-production.iam.gserviceaccount.com&Signature=kbovuOHqx1zQ01k2JLv3vSDaYbHItTycqeq2YURNlbD5XRGkUvQrNZxJrbM6osH%2FENF6HvfcT%2BENYNpNC%2BL5OqLe%2FmpPae6eDy6NexFC7Zbbbn9d3G2XLZG9goE9iklwKX4KW1pd0VzWFfTel%2BLXIkIaFS0dWCAz2jiQuMLH7iAEoy5QbiMBP8lhXU9g1jMABHn8GXPrq1BY6Mv11K9TRqNDr05oEvZxddTyDwSBtZ5ywPejT5hE7v2D%2Blbt7shbB8A4xXrB2OflVHzyHKV74RagasqYRZZu0H7uvoCd5JAmTCIIMoiKQTdW3oHWTL%2F1Ja7qj52XwR7z51GvxZVvhg%3D%3D: HTTPSConnectionPool(host='storage.googleapis.com', port=443): Max retries exceeded with url: /wandb-artifacts-prod/wandb_artifacts/133981200/707679828/174a3d9bc61fec126cc7d5bdff5c6c5a?Expires=1706688948&GoogleAccessId=gorilla-files-url-signer-man%40wandb-production.iam.gserviceaccount.com&Signature=kbovuOHqx1zQ01k2JLv3vSDaYbHItTycqeq2YURNlbD5XRGkUvQrNZxJrbM6osH%2FENF6HvfcT%2BENYNpNC%2BL5OqLe%2FmpPae6eDy6NexFC7Zbbbn9d3G2XLZG9goE9iklwKX4KW1pd0VzWFfTel%2BLXIkIaFS0dWCAz2jiQuMLH7iAEoy5QbiMBP8lhXU9g1jMABHn8GXPrq1BY6Mv11K9TRqNDr05oEvZxddTyDwSBtZ5ywPejT5hE7v2D%2Blbt7shbB8A4xXrB2OflVHzyHKV74RagasqYRZZu0H7uvoCd5JAmTCIIMoiKQTdW3oHWTL%2F1Ja7qj52XwR7z51GvxZVvhg%3D%3D (Caused by NewConnectionError('<urllib3.connection.HTTPSConnection object at 0x7f47d460a460>: Failed to establish a new connection: [Errno 110] Connection timed out'))
2024-01-30 17:12:22,262 ERROR   wandb-upload_1:1134320 [internal_api.py:upload_file():2767] upload_file request headers: {'User-Agent': 'python-requests/2.23.0', 'Accept-Encoding': 'gzip, deflate', 'Accept': '*/*', 'Connection': 'keep-alive', 'Content-MD5': 'F0o9m8Yf7BJsx9W9/1xsWg==', 'Content-Type': 'text/plain; charset=utf-8', 'Content-Length': '2179'}
2024-01-30 17:12:22,262 ERROR   wandb-upload_1:1134320 [internal_api.py:upload_file():2769] upload_file response body: 
2024-01-30 17:12:42,742 ERROR   wandb-upload_0:1134320 [internal_api.py:upload_file():2765] upload_file exception https://storage.googleapis.com/wandb-production.appspot.com/dynamic_x/bert_pytorch/wn1qxvno/wandb-metadata.json?Expires=1706688636&GoogleAccessId=gorilla-files-url-signer-man%40wandb-production.iam.gserviceaccount.com&Signature=X2NQsRBPxmFG1jesoKIgaYH%2BEuVtOiN9iCNyn2nXM0cUCfxLAaAA%2Bk3hpaoW2l5axIqryRk6aj9eSNHiDB95u6Hf7uUfIhqHdFIO604O3XU8FxsVDC6sl62BCb5Gv1YZELF0wwnCYUabk5D8%2BySwHmTL5L192XcYTZiRY5RNvkX0XbkI1VhcZpRvVUboO783c0aYk3HaH9AjjVpNUOz6AP7oNYdWa%2BBqjD6KY4lDz4ppjtGJyClpzP%2BXvNyhrL2ChSQrgKLmg7wKvTV5yciTtM7q8830QL9WNkUPXUkfHDQyMFS62jtzEAulOBw9PlxFnSMtX64IMtAkZcBi0zA25A%3D%3D: HTTPSConnectionPool(host='storage.googleapis.com', port=443): Max retries exceeded with url: /wandb-production.appspot.com/dynamic_x/bert_pytorch/wn1qxvno/wandb-metadata.json?Expires=1706688636&GoogleAccessId=gorilla-files-url-signer-man%40wandb-production.iam.gserviceaccount.com&Signature=X2NQsRBPxmFG1jesoKIgaYH%2BEuVtOiN9iCNyn2nXM0cUCfxLAaAA%2Bk3hpaoW2l5axIqryRk6aj9eSNHiDB95u6Hf7uUfIhqHdFIO604O3XU8FxsVDC6sl62BCb5Gv1YZELF0wwnCYUabk5D8%2BySwHmTL5L192XcYTZiRY5RNvkX0XbkI1VhcZpRvVUboO783c0aYk3HaH9AjjVpNUOz6AP7oNYdWa%2BBqjD6KY4lDz4ppjtGJyClpzP%2BXvNyhrL2ChSQrgKLmg7wKvTV5yciTtM7q8830QL9WNkUPXUkfHDQyMFS62jtzEAulOBw9PlxFnSMtX64IMtAkZcBi0zA25A%3D%3D (Caused by NewConnectionError('<urllib3.connection.HTTPSConnection object at 0x7f47d4653d60>: Failed to establish a new connection: [Errno 110] Connection timed out'))
2024-01-30 17:12:42,742 ERROR   wandb-upload_0:1134320 [internal_api.py:upload_file():2767] upload_file request headers: {'User-Agent': 'python-requests/2.23.0', 'Accept-Encoding': 'gzip, deflate', 'Accept': '*/*', 'Connection': 'keep-alive', 'Content-Length': '15553'}
2024-01-30 17:12:42,742 ERROR   wandb-upload_0:1134320 [internal_api.py:upload_file():2769] upload_file response body: 
2024-01-30 17:17:59,924 ERROR   wandb-upload_2:1134320 [internal_api.py:upload_file():2765] upload_file exception https://storage.googleapis.com/wandb-artifacts-prod/wandb_artifacts/133981200/707679828/6873c23a2381d1524249eb1a948a45a5?Expires=1706688948&GoogleAccessId=gorilla-files-url-signer-man%40wandb-production.iam.gserviceaccount.com&Signature=c4l7issmW7JLxt%2F5iscJknq14hvYZvtF2GxzULmZuZuFAJ%2F9XDgpKYtL0M4ID77UMZgvwjxdjv6iO1HPm2i%2Fu6ogy7h5xHLRe4rQDX3k94rmTIhO%2FUHArMuR8wQR9%2FNUP2Z9TYpq0bGocaYm5xB2yEK%2BFAAF7JHHKdmu4clQQkzMPRoPoRQbpo1LvqvTBYfG%2F3BaewVmOiLE44F0S9TtUNZHVpHFx0OJyzH54n%2BLCqC4BBokBnRXGMVspDfurrfZTTaqS4bo4Gd113ehd9TNzRIawroe89EdL186rqaseJc6YZuiUYJD8lMZW3j%2Fdcyy%2Fop22jcv9B3fOEsjLcfxfQ%3D%3D: HTTPSConnectionPool(host='storage.googleapis.com', port=443): Max retries exceeded with url: /wandb-artifacts-prod/wandb_artifacts/133981200/707679828/6873c23a2381d1524249eb1a948a45a5?Expires=1706688948&GoogleAccessId=gorilla-files-url-signer-man%40wandb-production.iam.gserviceaccount.com&Signature=c4l7issmW7JLxt%2F5iscJknq14hvYZvtF2GxzULmZuZuFAJ%2F9XDgpKYtL0M4ID77UMZgvwjxdjv6iO1HPm2i%2Fu6ogy7h5xHLRe4rQDX3k94rmTIhO%2FUHArMuR8wQR9%2FNUP2Z9TYpq0bGocaYm5xB2yEK%2BFAAF7JHHKdmu4clQQkzMPRoPoRQbpo1LvqvTBYfG%2F3BaewVmOiLE44F0S9TtUNZHVpHFx0OJyzH54n%2BLCqC4BBokBnRXGMVspDfurrfZTTaqS4bo4Gd113ehd9TNzRIawroe89EdL186rqaseJc6YZuiUYJD8lMZW3j%2Fdcyy%2Fop22jcv9B3fOEsjLcfxfQ%3D%3D (Caused by NewConnectionError('<urllib3.connection.HTTPSConnection object at 0x7f47d44594c0>: Failed to establish a new connection: [Errno 101] Network is unreachable'))
2024-01-30 17:17:59,924 ERROR   wandb-upload_2:1134320 [internal_api.py:upload_file():2767] upload_file request headers: {'User-Agent': 'python-requests/2.23.0', 'Accept-Encoding': 'gzip, deflate', 'Accept': '*/*', 'Connection': 'keep-alive', 'Content-MD5': 'aHPCOiOB0VJCSesalIpFpQ==', 'Content-Type': 'application/json', 'Content-Length': '609'}
2024-01-30 17:17:59,924 ERROR   wandb-upload_2:1134320 [internal_api.py:upload_file():2769] upload_file response body: 
2024-01-30 17:18:17,609 ERROR   wandb-upload_1:1134320 [internal_api.py:upload_file():2765] upload_file exception https://storage.googleapis.com/wandb-artifacts-prod/wandb_artifacts/133981200/707679828/174a3d9bc61fec126cc7d5bdff5c6c5a?Expires=1706688948&GoogleAccessId=gorilla-files-url-signer-man%40wandb-production.iam.gserviceaccount.com&Signature=kbovuOHqx1zQ01k2JLv3vSDaYbHItTycqeq2YURNlbD5XRGkUvQrNZxJrbM6osH%2FENF6HvfcT%2BENYNpNC%2BL5OqLe%2FmpPae6eDy6NexFC7Zbbbn9d3G2XLZG9goE9iklwKX4KW1pd0VzWFfTel%2BLXIkIaFS0dWCAz2jiQuMLH7iAEoy5QbiMBP8lhXU9g1jMABHn8GXPrq1BY6Mv11K9TRqNDr05oEvZxddTyDwSBtZ5ywPejT5hE7v2D%2Blbt7shbB8A4xXrB2OflVHzyHKV74RagasqYRZZu0H7uvoCd5JAmTCIIMoiKQTdW3oHWTL%2F1Ja7qj52XwR7z51GvxZVvhg%3D%3D: HTTPSConnectionPool(host='storage.googleapis.com', port=443): Max retries exceeded with url: /wandb-artifacts-prod/wandb_artifacts/133981200/707679828/174a3d9bc61fec126cc7d5bdff5c6c5a?Expires=1706688948&GoogleAccessId=gorilla-files-url-signer-man%40wandb-production.iam.gserviceaccount.com&Signature=kbovuOHqx1zQ01k2JLv3vSDaYbHItTycqeq2YURNlbD5XRGkUvQrNZxJrbM6osH%2FENF6HvfcT%2BENYNpNC%2BL5OqLe%2FmpPae6eDy6NexFC7Zbbbn9d3G2XLZG9goE9iklwKX4KW1pd0VzWFfTel%2BLXIkIaFS0dWCAz2jiQuMLH7iAEoy5QbiMBP8lhXU9g1jMABHn8GXPrq1BY6Mv11K9TRqNDr05oEvZxddTyDwSBtZ5ywPejT5hE7v2D%2Blbt7shbB8A4xXrB2OflVHzyHKV74RagasqYRZZu0H7uvoCd5JAmTCIIMoiKQTdW3oHWTL%2F1Ja7qj52XwR7z51GvxZVvhg%3D%3D (Caused by NewConnectionError('<urllib3.connection.HTTPSConnection object at 0x7f47d4457b80>: Failed to establish a new connection: [Errno 101] Network is unreachable'))
2024-01-30 17:18:17,609 ERROR   wandb-upload_1:1134320 [internal_api.py:upload_file():2767] upload_file request headers: {'User-Agent': 'python-requests/2.23.0', 'Accept-Encoding': 'gzip, deflate', 'Accept': '*/*', 'Connection': 'keep-alive', 'Content-MD5': 'F0o9m8Yf7BJsx9W9/1xsWg==', 'Content-Type': 'text/plain; charset=utf-8', 'Content-Length': '2179'}
2024-01-30 17:18:17,610 ERROR   wandb-upload_1:1134320 [internal_api.py:upload_file():2769] upload_file response body: 
2024-01-30 17:18:52,351 ERROR   wandb-upload_0:1134320 [internal_api.py:upload_file():2765] upload_file exception https://storage.googleapis.com/wandb-production.appspot.com/dynamic_x/bert_pytorch/wn1qxvno/wandb-metadata.json?Expires=1706688636&GoogleAccessId=gorilla-files-url-signer-man%40wandb-production.iam.gserviceaccount.com&Signature=X2NQsRBPxmFG1jesoKIgaYH%2BEuVtOiN9iCNyn2nXM0cUCfxLAaAA%2Bk3hpaoW2l5axIqryRk6aj9eSNHiDB95u6Hf7uUfIhqHdFIO604O3XU8FxsVDC6sl62BCb5Gv1YZELF0wwnCYUabk5D8%2BySwHmTL5L192XcYTZiRY5RNvkX0XbkI1VhcZpRvVUboO783c0aYk3HaH9AjjVpNUOz6AP7oNYdWa%2BBqjD6KY4lDz4ppjtGJyClpzP%2BXvNyhrL2ChSQrgKLmg7wKvTV5yciTtM7q8830QL9WNkUPXUkfHDQyMFS62jtzEAulOBw9PlxFnSMtX64IMtAkZcBi0zA25A%3D%3D: HTTPSConnectionPool(host='storage.googleapis.com', port=443): Max retries exceeded with url: /wandb-production.appspot.com/dynamic_x/bert_pytorch/wn1qxvno/wandb-metadata.json?Expires=1706688636&GoogleAccessId=gorilla-files-url-signer-man%40wandb-production.iam.gserviceaccount.com&Signature=X2NQsRBPxmFG1jesoKIgaYH%2BEuVtOiN9iCNyn2nXM0cUCfxLAaAA%2Bk3hpaoW2l5axIqryRk6aj9eSNHiDB95u6Hf7uUfIhqHdFIO604O3XU8FxsVDC6sl62BCb5Gv1YZELF0wwnCYUabk5D8%2BySwHmTL5L192XcYTZiRY5RNvkX0XbkI1VhcZpRvVUboO783c0aYk3HaH9AjjVpNUOz6AP7oNYdWa%2BBqjD6KY4lDz4ppjtGJyClpzP%2BXvNyhrL2ChSQrgKLmg7wKvTV5yciTtM7q8830QL9WNkUPXUkfHDQyMFS62jtzEAulOBw9PlxFnSMtX64IMtAkZcBi0zA25A%3D%3D (Caused by NewConnectionError('<urllib3.connection.HTTPSConnection object at 0x7f47d4450a30>: Failed to establish a new connection: [Errno 111] Connection refused'))
2024-01-30 17:18:52,351 ERROR   wandb-upload_0:1134320 [internal_api.py:upload_file():2767] upload_file request headers: {'User-Agent': 'python-requests/2.23.0', 'Accept-Encoding': 'gzip, deflate', 'Accept': '*/*', 'Connection': 'keep-alive', 'Content-Length': '15553'}
2024-01-30 17:18:52,351 ERROR   wandb-upload_0:1134320 [internal_api.py:upload_file():2769] upload_file response body: 
2024-01-30 17:23:19,271 INFO    wandb-upload_2:1134320 [upload_job.py:push():89] Uploaded file /home/yanxindong/.local/share/wandb/artifacts/staging/tmppebjot51
2024-01-30 17:24:13,249 INFO    wandb-upload_1:1134320 [upload_job.py:push():89] Uploaded file /home/yanxindong/.local/share/wandb/artifacts/staging/tmp6h83xrvn
2024-01-30 17:24:16,635 INFO    SenderThread:1134320 [sender.py:send_artifact():1494] sent artifact job-https___github.com_kkkjj-d_mkor.git_bert_run_pretraining.py - {'id': 'QXJ0aWZhY3Q6NzA3Njc5ODI4', 'state': 'PENDING', 'artifactSequence': {'id': 'QXJ0aWZhY3RDb2xsZWN0aW9uOjEzMzk4MTIwMA==', 'latestArtifact': {'id': 'QXJ0aWZhY3Q6NzAzOTc3Mjk3', 'versionIndex': 8}}}
2024-01-30 17:24:16,636 INFO    SenderThread:1134320 [sender.py:finish():1572] shutting down sender
2024-01-30 17:24:16,637 INFO    SenderThread:1134320 [dir_watcher.py:finish():358] shutting down directory watcher
2024-01-30 17:24:17,385 INFO    SenderThread:1134320 [dir_watcher.py:finish():388] scan: /home/yanxindong/mkor/bert/wandb/run-20240130_161012-wn1qxvno/files
2024-01-30 17:24:17,385 INFO    SenderThread:1134320 [dir_watcher.py:finish():402] scan save: /home/yanxindong/mkor/bert/wandb/run-20240130_161012-wn1qxvno/files/wandb-summary.json wandb-summary.json
2024-01-30 17:24:17,386 INFO    SenderThread:1134320 [dir_watcher.py:finish():402] scan save: /home/yanxindong/mkor/bert/wandb/run-20240130_161012-wn1qxvno/files/conda-environment.yaml conda-environment.yaml
2024-01-30 17:24:17,386 INFO    SenderThread:1134320 [dir_watcher.py:finish():402] scan save: /home/yanxindong/mkor/bert/wandb/run-20240130_161012-wn1qxvno/files/wandb-metadata.json wandb-metadata.json
2024-01-30 17:24:17,386 INFO    SenderThread:1134320 [dir_watcher.py:finish():402] scan save: /home/yanxindong/mkor/bert/wandb/run-20240130_161012-wn1qxvno/files/output.log output.log
2024-01-30 17:24:17,387 INFO    SenderThread:1134320 [dir_watcher.py:finish():402] scan save: /home/yanxindong/mkor/bert/wandb/run-20240130_161012-wn1qxvno/files/requirements.txt requirements.txt
2024-01-30 17:24:17,391 INFO    SenderThread:1134320 [dir_watcher.py:finish():402] scan save: /home/yanxindong/mkor/bert/wandb/run-20240130_161012-wn1qxvno/files/config.yaml config.yaml
2024-01-30 17:24:17,392 INFO    SenderThread:1134320 [file_pusher.py:finish():175] shutting down file pusher
2024-01-30 17:24:17,392 INFO    SenderThread:1134320 [file_pusher.py:join():181] waiting for file pusher
2024-01-30 17:24:18,013 INFO    wandb-upload_3:1134320 [upload_job.py:push():131] Uploaded file /home/yanxindong/mkor/bert/wandb/run-20240130_161012-wn1qxvno/files/wandb-summary.json
2024-01-30 17:24:18,409 INFO    wandb-upload_5:1134320 [upload_job.py:push():131] Uploaded file /home/yanxindong/mkor/bert/wandb/run-20240130_161012-wn1qxvno/files/config.yaml
2024-01-30 17:24:18,410 INFO    wandb-upload_4:1134320 [upload_job.py:push():131] Uploaded file /home/yanxindong/mkor/bert/wandb/run-20240130_161012-wn1qxvno/files/requirements.txt
2024-01-30 17:24:18,414 INFO    wandb-upload_1:1134320 [upload_job.py:push():131] Uploaded file /home/yanxindong/mkor/bert/wandb/run-20240130_161012-wn1qxvno/files/output.log
2024-01-30 17:24:19,276 INFO    wandb-upload_2:1134320 [upload_job.py:push():131] Uploaded file /home/yanxindong/mkor/bert/wandb/run-20240130_161012-wn1qxvno/files/conda-environment.yaml
2024-01-30 17:24:24,481 INFO    wandb-upload_0:1134320 [upload_job.py:push():131] Uploaded file /tmp/tmp1hi0u8gywandb/51d0748p-wandb-metadata.json
2024-01-30 17:24:24,903 INFO    SenderThread:1134320 [file_stream.py:finish():595] file stream finish called
2024-01-30 17:24:25,323 INFO    SenderThread:1134320 [file_stream.py:finish():599] file stream finish is done
