2024-01-30 16:10:12,524 INFO    StreamThr :1134334 [internal.py:wandb_internal():86] W&B internal server running at pid: 1134334, started at: 2024-01-30 16:10:12.524116
2024-01-30 16:10:12,535 DEBUG   HandlerThread:1134334 [handler.py:handle_request():146] handle_request: status
2024-01-30 16:10:12,569 INFO    WriterThread:1134334 [datastore.py:open_for_write():87] open: /home/yanxindong/mkor/bert/wandb/run-20240130_161012-hv2wnz37/run-hv2wnz37.wandb
2024-01-30 16:10:12,570 DEBUG   SenderThread:1134334 [sender.py:send():382] send: header
2024-01-30 16:10:12,598 DEBUG   SenderThread:1134334 [sender.py:send():382] send: run
2024-01-30 16:10:14,002 INFO    SenderThread:1134334 [dir_watcher.py:__init__():211] watching files in: /home/yanxindong/mkor/bert/wandb/run-20240130_161012-hv2wnz37/files
2024-01-30 16:10:14,002 INFO    SenderThread:1134334 [sender.py:_start_run_threads():1136] run started: hv2wnz37 with start time 1706602212.52393
2024-01-30 16:10:14,007 DEBUG   HandlerThread:1134334 [handler.py:handle_request():146] handle_request: check_version
2024-01-30 16:10:14,007 DEBUG   SenderThread:1134334 [sender.py:send_request():409] send_request: check_version
2024-01-30 16:10:14,935 DEBUG   HandlerThread:1134334 [handler.py:handle_request():146] handle_request: run_start
2024-01-30 16:10:14,944 DEBUG   HandlerThread:1134334 [system_info.py:__init__():27] System info init
2024-01-30 16:10:14,944 DEBUG   HandlerThread:1134334 [system_info.py:__init__():42] System info init done
2024-01-30 16:10:14,945 INFO    HandlerThread:1134334 [system_monitor.py:start():194] Starting system monitor
2024-01-30 16:10:14,958 INFO    SystemMonitor:1134334 [system_monitor.py:_start():158] Starting system asset monitoring threads
2024-01-30 16:10:14,958 INFO    HandlerThread:1134334 [system_monitor.py:probe():214] Collecting system info
2024-01-30 16:10:14,990 INFO    SystemMonitor:1134334 [interfaces.py:start():190] Started cpu monitoring
2024-01-30 16:10:15,006 INFO    SystemMonitor:1134334 [interfaces.py:start():190] Started disk monitoring
2024-01-30 16:10:15,037 INFO    SystemMonitor:1134334 [interfaces.py:start():190] Started gpu monitoring
2024-01-30 16:10:15,082 INFO    SystemMonitor:1134334 [interfaces.py:start():190] Started memory monitoring
2024-01-30 16:10:15,111 INFO    SystemMonitor:1134334 [interfaces.py:start():190] Started network monitoring
2024-01-30 16:10:15,137 DEBUG   HandlerThread:1134334 [system_info.py:probe():151] Probing system
2024-01-30 16:10:15,166 DEBUG   HandlerThread:1134334 [system_info.py:_probe_git():136] Probing git
2024-01-30 16:10:15,249 DEBUG   HandlerThread:1134334 [system_info.py:_probe_git():144] Probing git done
2024-01-30 16:10:15,250 DEBUG   HandlerThread:1134334 [system_info.py:probe():199] Probing system done
2024-01-30 16:10:15,250 DEBUG   HandlerThread:1134334 [system_monitor.py:probe():223] {'os': 'Linux-5.15.0-92-generic-x86_64-with-glibc2.17', 'python': '3.8.17', 'heartbeatAt': '2024-01-30T08:10:15.137160', 'startedAt': '2024-01-30T08:10:12.516959', 'docker': None, 'cuda': None, 'args': ('--local_rank=7', '--config_file', 'config/bert_pretraining_phase2_config.json', '--input_dir', '/home/yanxindong/mkor/bert/data/encoded/sequences_lowercase_max_seq_len_512_next_seq_task_true', '--output_dir', 'results/adam', '--weight_decay', '0.01', '--num_steps_per_checkpoint', '200'), 'state': 'running', 'program': 'run_pretraining.py', 'codePathLocal': 'run_pretraining.py', 'codePath': 'bert/run_pretraining.py', 'git': {'remote': 'https://github.com/kkkjj-d/mkor.git', 'commit': 'efe99e84fef5594780cfb1df6d6a1f61da4ebba0'}, 'email': '1262670315@qq.com', 'root': '/home/yanxindong/mkor', 'host': 'a6000-X640-G40', 'username': 'yanxindong', 'executable': '/home/yanxindong/anaconda/envs/eva/bin/python', 'cpu_count': 64, 'cpu_count_logical': 128, 'cpu_freq': {'current': 846.875, 'min': 800.0, 'max': 3400.0}, 'cpu_freq_per_core': [{'current': 3300.0, 'min': 800.0, 'max': 3400.0}, {'current': 900.0, 'min': 800.0, 'max': 3400.0}, {'current': 800.0, 'min': 800.0, 'max': 3400.0}, {'current': 800.0, 'min': 800.0, 'max': 3400.0}, {'current': 900.0, 'min': 800.0, 'max': 3400.0}, {'current': 800.0, 'min': 800.0, 'max': 3400.0}, {'current': 800.0, 'min': 800.0, 'max': 3400.0}, {'current': 800.0, 'min': 800.0, 'max': 3400.0}, {'current': 900.0, 'min': 800.0, 'max': 3400.0}, {'current': 800.0, 'min': 800.0, 'max': 3400.0}, {'current': 800.0, 'min': 800.0, 'max': 3400.0}, {'current': 800.0, 'min': 800.0, 'max': 3400.0}, {'current': 800.0, 'min': 800.0, 'max': 3400.0}, {'current': 800.0, 'min': 800.0, 'max': 3400.0}, {'current': 800.0, 'min': 800.0, 'max': 3400.0}, {'current': 800.0, 'min': 800.0, 'max': 3400.0}, {'current': 800.0, 'min': 800.0, 'max': 3400.0}, {'current': 800.0, 'min': 800.0, 'max': 3400.0}, {'current': 800.0, 'min': 800.0, 'max': 3400.0}, {'current': 800.0, 'min': 800.0, 'max': 3400.0}, {'current': 800.0, 'min': 800.0, 'max': 3400.0}, {'current': 800.0, 'min': 800.0, 'max': 3400.0}, {'current': 800.0, 'min': 800.0, 'max': 3400.0}, {'current': 800.0, 'min': 800.0, 'max': 3400.0}, {'current': 800.0, 'min': 800.0, 'max': 3400.0}, {'current': 800.0, 'min': 800.0, 'max': 3400.0}, {'current': 800.0, 'min': 800.0, 'max': 3400.0}, {'current': 800.0, 'min': 800.0, 'max': 3400.0}, {'current': 800.0, 'min': 800.0, 'max': 3400.0}, {'current': 800.0, 'min': 800.0, 'max': 3400.0}, {'current': 800.0, 'min': 800.0, 'max': 3400.0}, {'current': 800.0, 'min': 800.0, 'max': 3400.0}, {'current': 800.0, 'min': 800.0, 'max': 3400.0}, {'current': 800.0, 'min': 800.0, 'max': 3400.0}, {'current': 1300.0, 'min': 800.0, 'max': 3400.0}, {'current': 800.0, 'min': 800.0, 'max': 3400.0}, {'current': 800.0, 'min': 800.0, 'max': 3400.0}, {'current': 800.0, 'min': 800.0, 'max': 3400.0}, {'current': 800.0, 'min': 800.0, 'max': 3400.0}, {'current': 800.0, 'min': 800.0, 'max': 3400.0}, {'current': 800.0, 'min': 800.0, 'max': 3400.0}, {'current': 800.0, 'min': 800.0, 'max': 3400.0}, {'current': 800.0, 'min': 800.0, 'max': 3400.0}, {'current': 800.0, 'min': 800.0, 'max': 3400.0}, {'current': 800.0, 'min': 800.0, 'max': 3400.0}, {'current': 800.0, 'min': 800.0, 'max': 3400.0}, {'current': 800.0, 'min': 800.0, 'max': 3400.0}, {'current': 800.0, 'min': 800.0, 'max': 3400.0}, {'current': 800.0, 'min': 800.0, 'max': 3400.0}, {'current': 800.0, 'min': 800.0, 'max': 3400.0}, {'current': 800.0, 'min': 800.0, 'max': 3400.0}, {'current': 1000.0, 'min': 800.0, 'max': 3400.0}, {'current': 800.0, 'min': 800.0, 'max': 3400.0}, {'current': 800.0, 'min': 800.0, 'max': 3400.0}, {'current': 800.0, 'min': 800.0, 'max': 3400.0}, {'current': 800.0, 'min': 800.0, 'max': 3400.0}, {'current': 800.0, 'min': 800.0, 'max': 3400.0}, {'current': 800.0, 'min': 800.0, 'max': 3400.0}, {'current': 800.0, 'min': 800.0, 'max': 3400.0}, {'current': 800.0, 'min': 800.0, 'max': 3400.0}, {'current': 800.0, 'min': 800.0, 'max': 3400.0}, {'current': 800.0, 'min': 800.0, 'max': 3400.0}, {'current': 800.0, 'min': 800.0, 'max': 3400.0}, {'current': 800.0, 'min': 800.0, 'max': 3400.0}, {'current': 3300.0, 'min': 800.0, 'max': 3400.0}, {'current': 800.0, 'min': 800.0, 'max': 3400.0}, {'current': 800.0, 'min': 800.0, 'max': 3400.0}, {'current': 800.0, 'min': 800.0, 'max': 3400.0}, {'current': 800.0, 'min': 800.0, 'max': 3400.0}, {'current': 800.0, 'min': 800.0, 'max': 3400.0}, {'current': 800.0, 'min': 800.0, 'max': 3400.0}, {'current': 800.0, 'min': 800.0, 'max': 3400.0}, {'current': 800.0, 'min': 800.0, 'max': 3400.0}, {'current': 800.0, 'min': 800.0, 'max': 3400.0}, {'current': 800.0, 'min': 800.0, 'max': 3400.0}, {'current': 800.0, 'min': 800.0, 'max': 3400.0}, {'current': 800.0, 'min': 800.0, 'max': 3400.0}, {'current': 800.0, 'min': 800.0, 'max': 3400.0}, {'current': 800.0, 'min': 800.0, 'max': 3400.0}, {'current': 800.0, 'min': 800.0, 'max': 3400.0}, {'current': 800.0, 'min': 800.0, 'max': 3400.0}, {'current': 800.0, 'min': 800.0, 'max': 3400.0}, {'current': 800.0, 'min': 800.0, 'max': 3400.0}, {'current': 800.0, 'min': 800.0, 'max': 3400.0}, {'current': 800.0, 'min': 800.0, 'max': 3400.0}, {'current': 800.0, 'min': 800.0, 'max': 3400.0}, {'current': 800.0, 'min': 800.0, 'max': 3400.0}, {'current': 800.0, 'min': 800.0, 'max': 3400.0}, {'current': 800.0, 'min': 800.0, 'max': 3400.0}, {'current': 800.0, 'min': 800.0, 'max': 3400.0}, {'current': 800.0, 'min': 800.0, 'max': 3400.0}, {'current': 800.0, 'min': 800.0, 'max': 3400.0}, {'current': 800.0, 'min': 800.0, 'max': 3400.0}, {'current': 800.0, 'min': 800.0, 'max': 3400.0}, {'current': 800.0, 'min': 800.0, 'max': 3400.0}, {'current': 800.0, 'min': 800.0, 'max': 3400.0}, {'current': 800.0, 'min': 800.0, 'max': 3400.0}, {'current': 800.0, 'min': 800.0, 'max': 3400.0}, {'current': 800.0, 'min': 800.0, 'max': 3400.0}, {'current': 800.0, 'min': 800.0, 'max': 3400.0}, {'current': 800.0, 'min': 800.0, 'max': 3400.0}, {'current': 800.0, 'min': 800.0, 'max': 3400.0}, {'current': 800.0, 'min': 800.0, 'max': 3400.0}, {'current': 800.0, 'min': 800.0, 'max': 3400.0}, {'current': 800.0, 'min': 800.0, 'max': 3400.0}, {'current': 800.0, 'min': 800.0, 'max': 3400.0}, {'current': 800.0, 'min': 800.0, 'max': 3400.0}, {'current': 800.0, 'min': 800.0, 'max': 3400.0}, {'current': 800.0, 'min': 800.0, 'max': 3400.0}, {'current': 800.0, 'min': 800.0, 'max': 3400.0}, {'current': 900.0, 'min': 800.0, 'max': 3400.0}, {'current': 800.0, 'min': 800.0, 'max': 3400.0}, {'current': 800.0, 'min': 800.0, 'max': 3400.0}, {'current': 800.0, 'min': 800.0, 'max': 3400.0}, {'current': 800.0, 'min': 800.0, 'max': 3400.0}, {'current': 800.0, 'min': 800.0, 'max': 3400.0}, {'current': 800.0, 'min': 800.0, 'max': 3400.0}, {'current': 800.0, 'min': 800.0, 'max': 3400.0}, {'current': 800.0, 'min': 800.0, 'max': 3400.0}, {'current': 800.0, 'min': 800.0, 'max': 3400.0}, {'current': 800.0, 'min': 800.0, 'max': 3400.0}, {'current': 800.0, 'min': 800.0, 'max': 3400.0}, {'current': 800.0, 'min': 800.0, 'max': 3400.0}, {'current': 800.0, 'min': 800.0, 'max': 3400.0}, {'current': 800.0, 'min': 800.0, 'max': 3400.0}, {'current': 800.0, 'min': 800.0, 'max': 3400.0}, {'current': 800.0, 'min': 800.0, 'max': 3400.0}, {'current': 800.0, 'min': 800.0, 'max': 3400.0}], 'disk': {'/': {'total': 438.05088806152344, 'used': 30.817367553710938}}, 'gpu': 'NVIDIA RTX A6000', 'gpu_count': 8, 'gpu_devices': [{'name': 'NVIDIA RTX A6000', 'memory_total': 51527024640}, {'name': 'NVIDIA RTX A6000', 'memory_total': 51527024640}, {'name': 'NVIDIA RTX A6000', 'memory_total': 51527024640}, {'name': 'NVIDIA RTX A6000', 'memory_total': 51527024640}, {'name': 'NVIDIA RTX A6000', 'memory_total': 51527024640}, {'name': 'NVIDIA RTX A6000', 'memory_total': 51527024640}, {'name': 'NVIDIA RTX A6000', 'memory_total': 51527024640}, {'name': 'NVIDIA RTX A6000', 'memory_total': 51527024640}], 'memory': {'total': 503.51252365112305}}
2024-01-30 16:10:15,250 INFO    HandlerThread:1134334 [system_monitor.py:probe():224] Finished collecting system info
2024-01-30 16:10:15,250 INFO    HandlerThread:1134334 [system_monitor.py:probe():227] Publishing system info
2024-01-30 16:10:15,250 DEBUG   HandlerThread:1134334 [system_info.py:_save_conda():208] Saving list of conda packages installed into the current environment
2024-01-30 16:10:16,004 INFO    Thread-12 :1134334 [dir_watcher.py:_on_file_created():271] file/dir created: /home/yanxindong/mkor/bert/wandb/run-20240130_161012-hv2wnz37/files/conda-environment.yaml
2024-01-30 16:10:35,995 DEBUG   HandlerThread:1134334 [system_info.py:_save_conda():220] Saving conda packages done
2024-01-30 16:10:35,996 INFO    HandlerThread:1134334 [system_monitor.py:probe():229] Finished publishing system info
2024-01-30 16:10:36,014 DEBUG   HandlerThread:1134334 [handler.py:handle_request():146] handle_request: status_report
2024-01-30 16:10:36,019 DEBUG   HandlerThread:1134334 [handler.py:handle_request():146] handle_request: keepalive
2024-01-30 16:10:36,020 DEBUG   HandlerThread:1134334 [handler.py:handle_request():146] handle_request: status_report
2024-01-30 16:10:36,020 DEBUG   HandlerThread:1134334 [handler.py:handle_request():146] handle_request: keepalive
2024-01-30 16:10:36,020 INFO    Thread-12 :1134334 [dir_watcher.py:_on_file_modified():288] file/dir modified: /home/yanxindong/mkor/bert/wandb/run-20240130_161012-hv2wnz37/files/conda-environment.yaml
2024-01-30 16:10:36,020 INFO    Thread-12 :1134334 [dir_watcher.py:_on_file_created():271] file/dir created: /home/yanxindong/mkor/bert/wandb/run-20240130_161012-hv2wnz37/files/wandb-metadata.json
2024-01-30 16:10:36,020 DEBUG   HandlerThread:1134334 [handler.py:handle_request():146] handle_request: status_report
2024-01-30 16:10:36,020 DEBUG   HandlerThread:1134334 [handler.py:handle_request():146] handle_request: keepalive
2024-01-30 16:10:36,021 DEBUG   HandlerThread:1134334 [handler.py:handle_request():146] handle_request: status_report
2024-01-30 16:10:36,021 DEBUG   HandlerThread:1134334 [handler.py:handle_request():146] handle_request: keepalive
2024-01-30 16:10:36,021 DEBUG   HandlerThread:1134334 [handler.py:handle_request():146] handle_request: python_packages
2024-01-30 16:10:36,025 DEBUG   SenderThread:1134334 [sender.py:send():382] send: files
2024-01-30 16:10:36,025 INFO    SenderThread:1134334 [sender.py:_save_file():1403] saving file wandb-metadata.json with policy now
2024-01-30 16:10:36,026 DEBUG   SenderThread:1134334 [sender.py:send_request():409] send_request: python_packages
2024-01-30 16:10:36,042 DEBUG   HandlerThread:1134334 [handler.py:handle_request():146] handle_request: stop_status
2024-01-30 16:10:36,042 DEBUG   SenderThread:1134334 [sender.py:send_request():409] send_request: stop_status
2024-01-30 16:10:36,082 DEBUG   HandlerThread:1134334 [handler.py:handle_request():146] handle_request: internal_messages
2024-01-30 16:10:36,371 DEBUG   SenderThread:1134334 [sender.py:send():382] send: telemetry
2024-01-30 16:10:36,779 ERROR   wandb-upload_0:1134334 [internal_api.py:upload_file():2765] upload_file exception https://storage.googleapis.com/wandb-production.appspot.com/dynamic_x/bert_pytorch/hv2wnz37/wandb-metadata.json?Expires=1706688636&GoogleAccessId=gorilla-files-url-signer-man%40wandb-production.iam.gserviceaccount.com&Signature=QD%2Fxf%2FivbWxQBUtR0j4IlcF8Tgh1I7K6m3cwuwolO0Az06CVc4CZE2LzhOI7bvPGsZWRdfPmB%2BJ6qQ1o1LiSGQ5AuV2RbiuGmSMvLXlHYHloPBVmqEyAleKhDMLEvMwU3bGclBUpaCiKKN%2B%2BvKetTMs4P2ueBW278aYZNVvua1m1VITnI5grj0fV1MBx7VtDom7VTQyyD8nYkEwoqnkJ0GlCsH%2FSCZEyWfq%2F0A%2BVP72tolvso6nYheXNGUTk8vdKfUGQ8cc%2FMnadC3qfPKm9yvPUeF2NC%2FCVU3IW7WDu1TPGibbS5Slwv4lHWNU%2BLdHIr6cT2Rav%2BBfK1tcvT4044w%3D%3D: HTTPSConnectionPool(host='storage.googleapis.com', port=443): Max retries exceeded with url: /wandb-production.appspot.com/dynamic_x/bert_pytorch/hv2wnz37/wandb-metadata.json?Expires=1706688636&GoogleAccessId=gorilla-files-url-signer-man%40wandb-production.iam.gserviceaccount.com&Signature=QD%2Fxf%2FivbWxQBUtR0j4IlcF8Tgh1I7K6m3cwuwolO0Az06CVc4CZE2LzhOI7bvPGsZWRdfPmB%2BJ6qQ1o1LiSGQ5AuV2RbiuGmSMvLXlHYHloPBVmqEyAleKhDMLEvMwU3bGclBUpaCiKKN%2B%2BvKetTMs4P2ueBW278aYZNVvua1m1VITnI5grj0fV1MBx7VtDom7VTQyyD8nYkEwoqnkJ0GlCsH%2FSCZEyWfq%2F0A%2BVP72tolvso6nYheXNGUTk8vdKfUGQ8cc%2FMnadC3qfPKm9yvPUeF2NC%2FCVU3IW7WDu1TPGibbS5Slwv4lHWNU%2BLdHIr6cT2Rav%2BBfK1tcvT4044w%3D%3D (Caused by NewConnectionError('<urllib3.connection.HTTPSConnection object at 0x7f819c69a850>: Failed to establish a new connection: [Errno 111] Connection refused'))
2024-01-30 16:10:36,779 ERROR   wandb-upload_0:1134334 [internal_api.py:upload_file():2767] upload_file request headers: {'User-Agent': 'python-requests/2.23.0', 'Accept-Encoding': 'gzip, deflate', 'Accept': '*/*', 'Connection': 'keep-alive', 'Content-Length': '15540'}
2024-01-30 16:10:36,779 ERROR   wandb-upload_0:1134334 [internal_api.py:upload_file():2769] upload_file response body: 
2024-01-30 16:10:37,022 INFO    Thread-12 :1134334 [dir_watcher.py:_on_file_created():271] file/dir created: /home/yanxindong/mkor/bert/wandb/run-20240130_161012-hv2wnz37/files/requirements.txt
2024-01-30 16:10:37,871 ERROR   wandb-upload_0:1134334 [internal_api.py:upload_file():2765] upload_file exception https://storage.googleapis.com/wandb-production.appspot.com/dynamic_x/bert_pytorch/hv2wnz37/wandb-metadata.json?Expires=1706688636&GoogleAccessId=gorilla-files-url-signer-man%40wandb-production.iam.gserviceaccount.com&Signature=QD%2Fxf%2FivbWxQBUtR0j4IlcF8Tgh1I7K6m3cwuwolO0Az06CVc4CZE2LzhOI7bvPGsZWRdfPmB%2BJ6qQ1o1LiSGQ5AuV2RbiuGmSMvLXlHYHloPBVmqEyAleKhDMLEvMwU3bGclBUpaCiKKN%2B%2BvKetTMs4P2ueBW278aYZNVvua1m1VITnI5grj0fV1MBx7VtDom7VTQyyD8nYkEwoqnkJ0GlCsH%2FSCZEyWfq%2F0A%2BVP72tolvso6nYheXNGUTk8vdKfUGQ8cc%2FMnadC3qfPKm9yvPUeF2NC%2FCVU3IW7WDu1TPGibbS5Slwv4lHWNU%2BLdHIr6cT2Rav%2BBfK1tcvT4044w%3D%3D: HTTPSConnectionPool(host='storage.googleapis.com', port=443): Max retries exceeded with url: /wandb-production.appspot.com/dynamic_x/bert_pytorch/hv2wnz37/wandb-metadata.json?Expires=1706688636&GoogleAccessId=gorilla-files-url-signer-man%40wandb-production.iam.gserviceaccount.com&Signature=QD%2Fxf%2FivbWxQBUtR0j4IlcF8Tgh1I7K6m3cwuwolO0Az06CVc4CZE2LzhOI7bvPGsZWRdfPmB%2BJ6qQ1o1LiSGQ5AuV2RbiuGmSMvLXlHYHloPBVmqEyAleKhDMLEvMwU3bGclBUpaCiKKN%2B%2BvKetTMs4P2ueBW278aYZNVvua1m1VITnI5grj0fV1MBx7VtDom7VTQyyD8nYkEwoqnkJ0GlCsH%2FSCZEyWfq%2F0A%2BVP72tolvso6nYheXNGUTk8vdKfUGQ8cc%2FMnadC3qfPKm9yvPUeF2NC%2FCVU3IW7WDu1TPGibbS5Slwv4lHWNU%2BLdHIr6cT2Rav%2BBfK1tcvT4044w%3D%3D (Caused by NewConnectionError('<urllib3.connection.HTTPSConnection object at 0x7f819c69a040>: Failed to establish a new connection: [Errno 111] Connection refused'))
2024-01-30 16:10:37,871 ERROR   wandb-upload_0:1134334 [internal_api.py:upload_file():2767] upload_file request headers: {'User-Agent': 'python-requests/2.23.0', 'Accept-Encoding': 'gzip, deflate', 'Accept': '*/*', 'Connection': 'keep-alive', 'Content-Length': '15540'}
2024-01-30 16:10:37,871 ERROR   wandb-upload_0:1134334 [internal_api.py:upload_file():2769] upload_file response body: 
2024-01-30 16:10:38,372 DEBUG   HandlerThread:1134334 [handler.py:handle_request():146] handle_request: status_report
2024-01-30 16:10:40,314 ERROR   wandb-upload_0:1134334 [internal_api.py:upload_file():2765] upload_file exception https://storage.googleapis.com/wandb-production.appspot.com/dynamic_x/bert_pytorch/hv2wnz37/wandb-metadata.json?Expires=1706688636&GoogleAccessId=gorilla-files-url-signer-man%40wandb-production.iam.gserviceaccount.com&Signature=QD%2Fxf%2FivbWxQBUtR0j4IlcF8Tgh1I7K6m3cwuwolO0Az06CVc4CZE2LzhOI7bvPGsZWRdfPmB%2BJ6qQ1o1LiSGQ5AuV2RbiuGmSMvLXlHYHloPBVmqEyAleKhDMLEvMwU3bGclBUpaCiKKN%2B%2BvKetTMs4P2ueBW278aYZNVvua1m1VITnI5grj0fV1MBx7VtDom7VTQyyD8nYkEwoqnkJ0GlCsH%2FSCZEyWfq%2F0A%2BVP72tolvso6nYheXNGUTk8vdKfUGQ8cc%2FMnadC3qfPKm9yvPUeF2NC%2FCVU3IW7WDu1TPGibbS5Slwv4lHWNU%2BLdHIr6cT2Rav%2BBfK1tcvT4044w%3D%3D: HTTPSConnectionPool(host='storage.googleapis.com', port=443): Max retries exceeded with url: /wandb-production.appspot.com/dynamic_x/bert_pytorch/hv2wnz37/wandb-metadata.json?Expires=1706688636&GoogleAccessId=gorilla-files-url-signer-man%40wandb-production.iam.gserviceaccount.com&Signature=QD%2Fxf%2FivbWxQBUtR0j4IlcF8Tgh1I7K6m3cwuwolO0Az06CVc4CZE2LzhOI7bvPGsZWRdfPmB%2BJ6qQ1o1LiSGQ5AuV2RbiuGmSMvLXlHYHloPBVmqEyAleKhDMLEvMwU3bGclBUpaCiKKN%2B%2BvKetTMs4P2ueBW278aYZNVvua1m1VITnI5grj0fV1MBx7VtDom7VTQyyD8nYkEwoqnkJ0GlCsH%2FSCZEyWfq%2F0A%2BVP72tolvso6nYheXNGUTk8vdKfUGQ8cc%2FMnadC3qfPKm9yvPUeF2NC%2FCVU3IW7WDu1TPGibbS5Slwv4lHWNU%2BLdHIr6cT2Rav%2BBfK1tcvT4044w%3D%3D (Caused by NewConnectionError('<urllib3.connection.HTTPSConnection object at 0x7f819c69a610>: Failed to establish a new connection: [Errno 111] Connection refused'))
2024-01-30 16:10:40,314 ERROR   wandb-upload_0:1134334 [internal_api.py:upload_file():2767] upload_file request headers: {'User-Agent': 'python-requests/2.23.0', 'Accept-Encoding': 'gzip, deflate', 'Accept': '*/*', 'Connection': 'keep-alive', 'Content-Length': '15540'}
2024-01-30 16:10:40,314 ERROR   wandb-upload_0:1134334 [internal_api.py:upload_file():2769] upload_file response body: 
2024-01-30 16:10:40,314 INFO    wandb-upload_0:1134334 [retry.py:__call__():172] Retry attempt failed:
Traceback (most recent call last):
  File "/home/yanxindong/anaconda/envs/eva/lib/python3.8/site-packages/urllib3/connection.py", line 159, in _new_conn
    conn = connection.create_connection(
  File "/home/yanxindong/anaconda/envs/eva/lib/python3.8/site-packages/urllib3/util/connection.py", line 84, in create_connection
    raise err
  File "/home/yanxindong/anaconda/envs/eva/lib/python3.8/site-packages/urllib3/util/connection.py", line 74, in create_connection
    sock.connect(sa)
ConnectionRefusedError: [Errno 111] Connection refused

During handling of the above exception, another exception occurred:

Traceback (most recent call last):
  File "/home/yanxindong/anaconda/envs/eva/lib/python3.8/site-packages/urllib3/connectionpool.py", line 670, in urlopen
    httplib_response = self._make_request(
  File "/home/yanxindong/anaconda/envs/eva/lib/python3.8/site-packages/urllib3/connectionpool.py", line 381, in _make_request
    self._validate_conn(conn)
  File "/home/yanxindong/anaconda/envs/eva/lib/python3.8/site-packages/urllib3/connectionpool.py", line 978, in _validate_conn
    conn.connect()
  File "/home/yanxindong/anaconda/envs/eva/lib/python3.8/site-packages/urllib3/connection.py", line 309, in connect
    conn = self._new_conn()
  File "/home/yanxindong/anaconda/envs/eva/lib/python3.8/site-packages/urllib3/connection.py", line 171, in _new_conn
    raise NewConnectionError(
urllib3.exceptions.NewConnectionError: <urllib3.connection.HTTPSConnection object at 0x7f819c69a610>: Failed to establish a new connection: [Errno 111] Connection refused

During handling of the above exception, another exception occurred:

Traceback (most recent call last):
  File "/home/yanxindong/anaconda/envs/eva/lib/python3.8/site-packages/requests/adapters.py", line 439, in send
    resp = conn.urlopen(
  File "/home/yanxindong/anaconda/envs/eva/lib/python3.8/site-packages/urllib3/connectionpool.py", line 726, in urlopen
    retries = retries.increment(
  File "/home/yanxindong/anaconda/envs/eva/lib/python3.8/site-packages/urllib3/util/retry.py", line 446, in increment
    raise MaxRetryError(_pool, url, error or ResponseError(cause))
urllib3.exceptions.MaxRetryError: HTTPSConnectionPool(host='storage.googleapis.com', port=443): Max retries exceeded with url: /wandb-production.appspot.com/dynamic_x/bert_pytorch/hv2wnz37/wandb-metadata.json?Expires=1706688636&GoogleAccessId=gorilla-files-url-signer-man%40wandb-production.iam.gserviceaccount.com&Signature=QD%2Fxf%2FivbWxQBUtR0j4IlcF8Tgh1I7K6m3cwuwolO0Az06CVc4CZE2LzhOI7bvPGsZWRdfPmB%2BJ6qQ1o1LiSGQ5AuV2RbiuGmSMvLXlHYHloPBVmqEyAleKhDMLEvMwU3bGclBUpaCiKKN%2B%2BvKetTMs4P2ueBW278aYZNVvua1m1VITnI5grj0fV1MBx7VtDom7VTQyyD8nYkEwoqnkJ0GlCsH%2FSCZEyWfq%2F0A%2BVP72tolvso6nYheXNGUTk8vdKfUGQ8cc%2FMnadC3qfPKm9yvPUeF2NC%2FCVU3IW7WDu1TPGibbS5Slwv4lHWNU%2BLdHIr6cT2Rav%2BBfK1tcvT4044w%3D%3D (Caused by NewConnectionError('<urllib3.connection.HTTPSConnection object at 0x7f819c69a610>: Failed to establish a new connection: [Errno 111] Connection refused'))

During handling of the above exception, another exception occurred:

Traceback (most recent call last):
  File "/home/yanxindong/anaconda/envs/eva/lib/python3.8/site-packages/wandb/sdk/internal/internal_api.py", line 2758, in upload_file
    response = self._upload_file_session.put(
  File "/home/yanxindong/anaconda/envs/eva/lib/python3.8/site-packages/requests/sessions.py", line 590, in put
    return self.request('PUT', url, data=data, **kwargs)
  File "/home/yanxindong/anaconda/envs/eva/lib/python3.8/site-packages/requests/sessions.py", line 530, in request
    resp = self.send(prep, **send_kwargs)
  File "/home/yanxindong/anaconda/envs/eva/lib/python3.8/site-packages/requests/sessions.py", line 643, in send
    r = adapter.send(request, **kwargs)
  File "/home/yanxindong/anaconda/envs/eva/lib/python3.8/site-packages/requests/adapters.py", line 516, in send
    raise ConnectionError(e, request=request)
requests.exceptions.ConnectionError: HTTPSConnectionPool(host='storage.googleapis.com', port=443): Max retries exceeded with url: /wandb-production.appspot.com/dynamic_x/bert_pytorch/hv2wnz37/wandb-metadata.json?Expires=1706688636&GoogleAccessId=gorilla-files-url-signer-man%40wandb-production.iam.gserviceaccount.com&Signature=QD%2Fxf%2FivbWxQBUtR0j4IlcF8Tgh1I7K6m3cwuwolO0Az06CVc4CZE2LzhOI7bvPGsZWRdfPmB%2BJ6qQ1o1LiSGQ5AuV2RbiuGmSMvLXlHYHloPBVmqEyAleKhDMLEvMwU3bGclBUpaCiKKN%2B%2BvKetTMs4P2ueBW278aYZNVvua1m1VITnI5grj0fV1MBx7VtDom7VTQyyD8nYkEwoqnkJ0GlCsH%2FSCZEyWfq%2F0A%2BVP72tolvso6nYheXNGUTk8vdKfUGQ8cc%2FMnadC3qfPKm9yvPUeF2NC%2FCVU3IW7WDu1TPGibbS5Slwv4lHWNU%2BLdHIr6cT2Rav%2BBfK1tcvT4044w%3D%3D (Caused by NewConnectionError('<urllib3.connection.HTTPSConnection object at 0x7f819c69a610>: Failed to establish a new connection: [Errno 111] Connection refused'))

During handling of the above exception, another exception occurred:

Traceback (most recent call last):
  File "/home/yanxindong/anaconda/envs/eva/lib/python3.8/site-packages/wandb/sdk/lib/retry.py", line 131, in __call__
    result = self._call_fn(*args, **kwargs)
  File "/home/yanxindong/anaconda/envs/eva/lib/python3.8/site-packages/wandb/sdk/internal/internal_api.py", line 2789, in upload_file
    raise _e.with_traceback(sys.exc_info()[2])
  File "/home/yanxindong/anaconda/envs/eva/lib/python3.8/site-packages/wandb/sdk/internal/internal_api.py", line 2758, in upload_file
    response = self._upload_file_session.put(
  File "/home/yanxindong/anaconda/envs/eva/lib/python3.8/site-packages/requests/sessions.py", line 590, in put
    return self.request('PUT', url, data=data, **kwargs)
  File "/home/yanxindong/anaconda/envs/eva/lib/python3.8/site-packages/requests/sessions.py", line 530, in request
    resp = self.send(prep, **send_kwargs)
  File "/home/yanxindong/anaconda/envs/eva/lib/python3.8/site-packages/requests/sessions.py", line 643, in send
    r = adapter.send(request, **kwargs)
  File "/home/yanxindong/anaconda/envs/eva/lib/python3.8/site-packages/requests/adapters.py", line 516, in send
    raise ConnectionError(e, request=request)
wandb.sdk.lib.retry.TransientError: None
2024-01-30 16:10:43,377 DEBUG   HandlerThread:1134334 [handler.py:handle_request():146] handle_request: status_report
2024-01-30 16:10:45,032 INFO    Thread-12 :1134334 [dir_watcher.py:_on_file_modified():288] file/dir modified: /home/yanxindong/mkor/bert/wandb/run-20240130_161012-hv2wnz37/files/config.yaml
2024-01-30 16:10:45,102 ERROR   wandb-upload_0:1134334 [internal_api.py:upload_file():2765] upload_file exception https://storage.googleapis.com/wandb-production.appspot.com/dynamic_x/bert_pytorch/hv2wnz37/wandb-metadata.json?Expires=1706688636&GoogleAccessId=gorilla-files-url-signer-man%40wandb-production.iam.gserviceaccount.com&Signature=QD%2Fxf%2FivbWxQBUtR0j4IlcF8Tgh1I7K6m3cwuwolO0Az06CVc4CZE2LzhOI7bvPGsZWRdfPmB%2BJ6qQ1o1LiSGQ5AuV2RbiuGmSMvLXlHYHloPBVmqEyAleKhDMLEvMwU3bGclBUpaCiKKN%2B%2BvKetTMs4P2ueBW278aYZNVvua1m1VITnI5grj0fV1MBx7VtDom7VTQyyD8nYkEwoqnkJ0GlCsH%2FSCZEyWfq%2F0A%2BVP72tolvso6nYheXNGUTk8vdKfUGQ8cc%2FMnadC3qfPKm9yvPUeF2NC%2FCVU3IW7WDu1TPGibbS5Slwv4lHWNU%2BLdHIr6cT2Rav%2BBfK1tcvT4044w%3D%3D: HTTPSConnectionPool(host='storage.googleapis.com', port=443): Max retries exceeded with url: /wandb-production.appspot.com/dynamic_x/bert_pytorch/hv2wnz37/wandb-metadata.json?Expires=1706688636&GoogleAccessId=gorilla-files-url-signer-man%40wandb-production.iam.gserviceaccount.com&Signature=QD%2Fxf%2FivbWxQBUtR0j4IlcF8Tgh1I7K6m3cwuwolO0Az06CVc4CZE2LzhOI7bvPGsZWRdfPmB%2BJ6qQ1o1LiSGQ5AuV2RbiuGmSMvLXlHYHloPBVmqEyAleKhDMLEvMwU3bGclBUpaCiKKN%2B%2BvKetTMs4P2ueBW278aYZNVvua1m1VITnI5grj0fV1MBx7VtDom7VTQyyD8nYkEwoqnkJ0GlCsH%2FSCZEyWfq%2F0A%2BVP72tolvso6nYheXNGUTk8vdKfUGQ8cc%2FMnadC3qfPKm9yvPUeF2NC%2FCVU3IW7WDu1TPGibbS5Slwv4lHWNU%2BLdHIr6cT2Rav%2BBfK1tcvT4044w%3D%3D (Caused by NewConnectionError('<urllib3.connection.HTTPSConnection object at 0x7f819c69a220>: Failed to establish a new connection: [Errno 111] Connection refused'))
2024-01-30 16:10:45,103 ERROR   wandb-upload_0:1134334 [internal_api.py:upload_file():2767] upload_file request headers: {'User-Agent': 'python-requests/2.23.0', 'Accept-Encoding': 'gzip, deflate', 'Accept': '*/*', 'Connection': 'keep-alive', 'Content-Length': '15540'}
2024-01-30 16:10:45,103 ERROR   wandb-upload_0:1134334 [internal_api.py:upload_file():2769] upload_file response body: 
2024-01-30 16:10:49,390 DEBUG   HandlerThread:1134334 [handler.py:handle_request():146] handle_request: status_report
2024-01-30 16:10:51,042 DEBUG   HandlerThread:1134334 [handler.py:handle_request():146] handle_request: stop_status
2024-01-30 16:10:51,042 DEBUG   SenderThread:1134334 [sender.py:send_request():409] send_request: stop_status
2024-01-30 16:10:51,106 DEBUG   HandlerThread:1134334 [handler.py:handle_request():146] handle_request: internal_messages
2024-01-30 16:10:54,700 ERROR   wandb-upload_0:1134334 [internal_api.py:upload_file():2765] upload_file exception https://storage.googleapis.com/wandb-production.appspot.com/dynamic_x/bert_pytorch/hv2wnz37/wandb-metadata.json?Expires=1706688636&GoogleAccessId=gorilla-files-url-signer-man%40wandb-production.iam.gserviceaccount.com&Signature=QD%2Fxf%2FivbWxQBUtR0j4IlcF8Tgh1I7K6m3cwuwolO0Az06CVc4CZE2LzhOI7bvPGsZWRdfPmB%2BJ6qQ1o1LiSGQ5AuV2RbiuGmSMvLXlHYHloPBVmqEyAleKhDMLEvMwU3bGclBUpaCiKKN%2B%2BvKetTMs4P2ueBW278aYZNVvua1m1VITnI5grj0fV1MBx7VtDom7VTQyyD8nYkEwoqnkJ0GlCsH%2FSCZEyWfq%2F0A%2BVP72tolvso6nYheXNGUTk8vdKfUGQ8cc%2FMnadC3qfPKm9yvPUeF2NC%2FCVU3IW7WDu1TPGibbS5Slwv4lHWNU%2BLdHIr6cT2Rav%2BBfK1tcvT4044w%3D%3D: HTTPSConnectionPool(host='storage.googleapis.com', port=443): Max retries exceeded with url: /wandb-production.appspot.com/dynamic_x/bert_pytorch/hv2wnz37/wandb-metadata.json?Expires=1706688636&GoogleAccessId=gorilla-files-url-signer-man%40wandb-production.iam.gserviceaccount.com&Signature=QD%2Fxf%2FivbWxQBUtR0j4IlcF8Tgh1I7K6m3cwuwolO0Az06CVc4CZE2LzhOI7bvPGsZWRdfPmB%2BJ6qQ1o1LiSGQ5AuV2RbiuGmSMvLXlHYHloPBVmqEyAleKhDMLEvMwU3bGclBUpaCiKKN%2B%2BvKetTMs4P2ueBW278aYZNVvua1m1VITnI5grj0fV1MBx7VtDom7VTQyyD8nYkEwoqnkJ0GlCsH%2FSCZEyWfq%2F0A%2BVP72tolvso6nYheXNGUTk8vdKfUGQ8cc%2FMnadC3qfPKm9yvPUeF2NC%2FCVU3IW7WDu1TPGibbS5Slwv4lHWNU%2BLdHIr6cT2Rav%2BBfK1tcvT4044w%3D%3D (Caused by NewConnectionError('<urllib3.connection.HTTPSConnection object at 0x7f819c5d8520>: Failed to establish a new connection: [Errno 111] Connection refused'))
2024-01-30 16:10:54,700 ERROR   wandb-upload_0:1134334 [internal_api.py:upload_file():2767] upload_file request headers: {'User-Agent': 'python-requests/2.23.0', 'Accept-Encoding': 'gzip, deflate', 'Accept': '*/*', 'Connection': 'keep-alive', 'Content-Length': '15540'}
2024-01-30 16:10:54,700 ERROR   wandb-upload_0:1134334 [internal_api.py:upload_file():2769] upload_file response body: 
2024-01-30 16:10:55,335 DEBUG   HandlerThread:1134334 [handler.py:handle_request():146] handle_request: status_report
2024-01-30 16:11:00,335 DEBUG   HandlerThread:1134334 [handler.py:handle_request():146] handle_request: status_report
2024-01-30 16:11:05,336 DEBUG   HandlerThread:1134334 [handler.py:handle_request():146] handle_request: status_report
2024-01-30 16:11:06,042 DEBUG   HandlerThread:1134334 [handler.py:handle_request():146] handle_request: stop_status
2024-01-30 16:11:06,042 DEBUG   SenderThread:1134334 [sender.py:send_request():409] send_request: stop_status
2024-01-30 16:11:06,089 DEBUG   HandlerThread:1134334 [handler.py:handle_request():146] handle_request: internal_messages
2024-01-30 16:11:10,389 DEBUG   HandlerThread:1134334 [handler.py:handle_request():146] handle_request: status_report
2024-01-30 16:11:13,455 ERROR   wandb-upload_0:1134334 [internal_api.py:upload_file():2765] upload_file exception https://storage.googleapis.com/wandb-production.appspot.com/dynamic_x/bert_pytorch/hv2wnz37/wandb-metadata.json?Expires=1706688636&GoogleAccessId=gorilla-files-url-signer-man%40wandb-production.iam.gserviceaccount.com&Signature=QD%2Fxf%2FivbWxQBUtR0j4IlcF8Tgh1I7K6m3cwuwolO0Az06CVc4CZE2LzhOI7bvPGsZWRdfPmB%2BJ6qQ1o1LiSGQ5AuV2RbiuGmSMvLXlHYHloPBVmqEyAleKhDMLEvMwU3bGclBUpaCiKKN%2B%2BvKetTMs4P2ueBW278aYZNVvua1m1VITnI5grj0fV1MBx7VtDom7VTQyyD8nYkEwoqnkJ0GlCsH%2FSCZEyWfq%2F0A%2BVP72tolvso6nYheXNGUTk8vdKfUGQ8cc%2FMnadC3qfPKm9yvPUeF2NC%2FCVU3IW7WDu1TPGibbS5Slwv4lHWNU%2BLdHIr6cT2Rav%2BBfK1tcvT4044w%3D%3D: HTTPSConnectionPool(host='storage.googleapis.com', port=443): Max retries exceeded with url: /wandb-production.appspot.com/dynamic_x/bert_pytorch/hv2wnz37/wandb-metadata.json?Expires=1706688636&GoogleAccessId=gorilla-files-url-signer-man%40wandb-production.iam.gserviceaccount.com&Signature=QD%2Fxf%2FivbWxQBUtR0j4IlcF8Tgh1I7K6m3cwuwolO0Az06CVc4CZE2LzhOI7bvPGsZWRdfPmB%2BJ6qQ1o1LiSGQ5AuV2RbiuGmSMvLXlHYHloPBVmqEyAleKhDMLEvMwU3bGclBUpaCiKKN%2B%2BvKetTMs4P2ueBW278aYZNVvua1m1VITnI5grj0fV1MBx7VtDom7VTQyyD8nYkEwoqnkJ0GlCsH%2FSCZEyWfq%2F0A%2BVP72tolvso6nYheXNGUTk8vdKfUGQ8cc%2FMnadC3qfPKm9yvPUeF2NC%2FCVU3IW7WDu1TPGibbS5Slwv4lHWNU%2BLdHIr6cT2Rav%2BBfK1tcvT4044w%3D%3D (Caused by NewConnectionError('<urllib3.connection.HTTPSConnection object at 0x7f819c6a3700>: Failed to establish a new connection: [Errno 111] Connection refused'))
2024-01-30 16:11:13,455 ERROR   wandb-upload_0:1134334 [internal_api.py:upload_file():2767] upload_file request headers: {'User-Agent': 'python-requests/2.23.0', 'Accept-Encoding': 'gzip, deflate', 'Accept': '*/*', 'Connection': 'keep-alive', 'Content-Length': '15540'}
2024-01-30 16:11:13,455 ERROR   wandb-upload_0:1134334 [internal_api.py:upload_file():2769] upload_file response body: 
2024-01-30 16:11:15,111 DEBUG   SystemMonitor:1134334 [system_monitor.py:_start():172] Starting system metrics aggregation loop
2024-01-30 16:11:15,114 DEBUG   SenderThread:1134334 [sender.py:send():382] send: stats
2024-01-30 16:11:16,116 DEBUG   HandlerThread:1134334 [handler.py:handle_request():146] handle_request: status_report
2024-01-30 16:11:21,042 DEBUG   HandlerThread:1134334 [handler.py:handle_request():146] handle_request: stop_status
2024-01-30 16:11:21,043 DEBUG   SenderThread:1134334 [sender.py:send_request():409] send_request: stop_status
2024-01-30 16:11:21,085 DEBUG   HandlerThread:1134334 [handler.py:handle_request():146] handle_request: internal_messages
2024-01-30 16:11:21,386 DEBUG   HandlerThread:1134334 [handler.py:handle_request():146] handle_request: status_report
2024-01-30 16:11:26,386 DEBUG   HandlerThread:1134334 [handler.py:handle_request():146] handle_request: status_report
2024-01-30 16:11:31,442 DEBUG   HandlerThread:1134334 [handler.py:handle_request():146] handle_request: status_report
2024-01-30 16:11:36,042 DEBUG   HandlerThread:1134334 [handler.py:handle_request():146] handle_request: stop_status
2024-01-30 16:11:36,042 DEBUG   SenderThread:1134334 [sender.py:send_request():409] send_request: stop_status
2024-01-30 16:11:36,086 DEBUG   HandlerThread:1134334 [handler.py:handle_request():146] handle_request: internal_messages
2024-01-30 16:11:37,347 DEBUG   HandlerThread:1134334 [handler.py:handle_request():146] handle_request: status_report
2024-01-30 16:11:42,348 DEBUG   HandlerThread:1134334 [handler.py:handle_request():146] handle_request: status_report
2024-01-30 16:11:45,116 DEBUG   SenderThread:1134334 [sender.py:send():382] send: stats
2024-01-30 16:11:48,117 DEBUG   HandlerThread:1134334 [handler.py:handle_request():146] handle_request: status_report
2024-01-30 16:11:49,894 ERROR   wandb-upload_0:1134334 [internal_api.py:upload_file():2765] upload_file exception https://storage.googleapis.com/wandb-production.appspot.com/dynamic_x/bert_pytorch/hv2wnz37/wandb-metadata.json?Expires=1706688636&GoogleAccessId=gorilla-files-url-signer-man%40wandb-production.iam.gserviceaccount.com&Signature=QD%2Fxf%2FivbWxQBUtR0j4IlcF8Tgh1I7K6m3cwuwolO0Az06CVc4CZE2LzhOI7bvPGsZWRdfPmB%2BJ6qQ1o1LiSGQ5AuV2RbiuGmSMvLXlHYHloPBVmqEyAleKhDMLEvMwU3bGclBUpaCiKKN%2B%2BvKetTMs4P2ueBW278aYZNVvua1m1VITnI5grj0fV1MBx7VtDom7VTQyyD8nYkEwoqnkJ0GlCsH%2FSCZEyWfq%2F0A%2BVP72tolvso6nYheXNGUTk8vdKfUGQ8cc%2FMnadC3qfPKm9yvPUeF2NC%2FCVU3IW7WDu1TPGibbS5Slwv4lHWNU%2BLdHIr6cT2Rav%2BBfK1tcvT4044w%3D%3D: HTTPSConnectionPool(host='storage.googleapis.com', port=443): Max retries exceeded with url: /wandb-production.appspot.com/dynamic_x/bert_pytorch/hv2wnz37/wandb-metadata.json?Expires=1706688636&GoogleAccessId=gorilla-files-url-signer-man%40wandb-production.iam.gserviceaccount.com&Signature=QD%2Fxf%2FivbWxQBUtR0j4IlcF8Tgh1I7K6m3cwuwolO0Az06CVc4CZE2LzhOI7bvPGsZWRdfPmB%2BJ6qQ1o1LiSGQ5AuV2RbiuGmSMvLXlHYHloPBVmqEyAleKhDMLEvMwU3bGclBUpaCiKKN%2B%2BvKetTMs4P2ueBW278aYZNVvua1m1VITnI5grj0fV1MBx7VtDom7VTQyyD8nYkEwoqnkJ0GlCsH%2FSCZEyWfq%2F0A%2BVP72tolvso6nYheXNGUTk8vdKfUGQ8cc%2FMnadC3qfPKm9yvPUeF2NC%2FCVU3IW7WDu1TPGibbS5Slwv4lHWNU%2BLdHIr6cT2Rav%2BBfK1tcvT4044w%3D%3D (Caused by NewConnectionError('<urllib3.connection.HTTPSConnection object at 0x7f819c6a3dc0>: Failed to establish a new connection: [Errno 101] Network is unreachable'))
2024-01-30 16:11:49,894 ERROR   wandb-upload_0:1134334 [internal_api.py:upload_file():2767] upload_file request headers: {'User-Agent': 'python-requests/2.23.0', 'Accept-Encoding': 'gzip, deflate', 'Accept': '*/*', 'Connection': 'keep-alive', 'Content-Length': '15540'}
2024-01-30 16:11:49,894 ERROR   wandb-upload_0:1134334 [internal_api.py:upload_file():2769] upload_file response body: 
2024-01-30 16:11:51,042 DEBUG   HandlerThread:1134334 [handler.py:handle_request():146] handle_request: stop_status
2024-01-30 16:11:51,043 DEBUG   SenderThread:1134334 [sender.py:send_request():409] send_request: stop_status
2024-01-30 16:11:51,085 DEBUG   HandlerThread:1134334 [handler.py:handle_request():146] handle_request: internal_messages
2024-01-30 16:11:53,341 DEBUG   HandlerThread:1134334 [handler.py:handle_request():146] handle_request: status_report
2024-01-30 16:11:55,243 INFO    Thread-12 :1134334 [dir_watcher.py:_on_file_created():271] file/dir created: /home/yanxindong/mkor/bert/wandb/run-20240130_161012-hv2wnz37/files/output.log
2024-01-30 16:11:57,245 INFO    Thread-12 :1134334 [dir_watcher.py:_on_file_modified():288] file/dir modified: /home/yanxindong/mkor/bert/wandb/run-20240130_161012-hv2wnz37/files/output.log
2024-01-30 16:11:59,239 DEBUG   HandlerThread:1134334 [handler.py:handle_request():146] handle_request: status_report
2024-01-30 16:12:04,240 DEBUG   HandlerThread:1134334 [handler.py:handle_request():146] handle_request: status_report
2024-01-30 16:12:07,254 DEBUG   HandlerThread:1134334 [handler.py:handle_request():146] handle_request: stop_status
2024-01-30 16:12:07,255 DEBUG   SenderThread:1134334 [sender.py:send_request():409] send_request: stop_status
2024-01-30 16:12:10,191 DEBUG   HandlerThread:1134334 [handler.py:handle_request():146] handle_request: status_report
2024-01-30 16:12:10,768 DEBUG   HandlerThread:1134334 [handler.py:handle_request():146] handle_request: internal_messages
2024-01-30 16:12:15,128 DEBUG   SenderThread:1134334 [sender.py:send():382] send: stats
2024-01-30 16:12:16,132 DEBUG   HandlerThread:1134334 [handler.py:handle_request():146] handle_request: status_report
2024-01-30 16:12:21,257 DEBUG   HandlerThread:1134334 [handler.py:handle_request():146] handle_request: status_report
2024-01-30 16:12:22,326 DEBUG   HandlerThread:1134334 [handler.py:handle_request():146] handle_request: stop_status
2024-01-30 16:12:22,326 DEBUG   HandlerThread:1134334 [handler.py:handle_request():146] handle_request: internal_messages
2024-01-30 16:12:22,326 DEBUG   SenderThread:1134334 [sender.py:send_request():409] send_request: stop_status
2024-01-30 16:12:26,713 DEBUG   HandlerThread:1134334 [handler.py:handle_request():146] handle_request: status_report
2024-01-30 16:12:31,852 DEBUG   HandlerThread:1134334 [handler.py:handle_request():146] handle_request: status_report
2024-01-30 16:12:36,933 DEBUG   HandlerThread:1134334 [handler.py:handle_request():146] handle_request: status_report
2024-01-30 16:12:37,261 DEBUG   HandlerThread:1134334 [handler.py:handle_request():146] handle_request: stop_status
2024-01-30 16:12:37,262 DEBUG   SenderThread:1134334 [sender.py:send_request():409] send_request: stop_status
2024-01-30 16:12:37,297 DEBUG   HandlerThread:1134334 [handler.py:handle_request():146] handle_request: internal_messages
2024-01-30 16:12:42,650 DEBUG   HandlerThread:1134334 [handler.py:handle_request():146] handle_request: status_report
2024-01-30 16:12:45,130 DEBUG   SenderThread:1134334 [sender.py:send():382] send: stats
2024-01-30 16:12:48,132 DEBUG   HandlerThread:1134334 [handler.py:handle_request():146] handle_request: status_report
2024-01-30 16:12:52,254 DEBUG   HandlerThread:1134334 [handler.py:handle_request():146] handle_request: stop_status
2024-01-30 16:12:52,255 DEBUG   SenderThread:1134334 [sender.py:send_request():409] send_request: stop_status
2024-01-30 16:12:52,297 DEBUG   HandlerThread:1134334 [handler.py:handle_request():146] handle_request: internal_messages
2024-01-30 16:12:53,596 DEBUG   HandlerThread:1134334 [handler.py:handle_request():146] handle_request: status_report
2024-01-30 16:12:58,597 DEBUG   HandlerThread:1134334 [handler.py:handle_request():146] handle_request: status_report
2024-01-30 16:13:03,598 DEBUG   HandlerThread:1134334 [handler.py:handle_request():146] handle_request: status_report
2024-01-30 16:13:07,254 DEBUG   HandlerThread:1134334 [handler.py:handle_request():146] handle_request: stop_status
2024-01-30 16:13:07,255 DEBUG   SenderThread:1134334 [sender.py:send_request():409] send_request: stop_status
2024-01-30 16:13:07,297 DEBUG   HandlerThread:1134334 [handler.py:handle_request():146] handle_request: internal_messages
2024-01-30 16:13:07,914 ERROR   wandb-upload_0:1134334 [internal_api.py:upload_file():2765] upload_file exception https://storage.googleapis.com/wandb-production.appspot.com/dynamic_x/bert_pytorch/hv2wnz37/wandb-metadata.json?Expires=1706688636&GoogleAccessId=gorilla-files-url-signer-man%40wandb-production.iam.gserviceaccount.com&Signature=QD%2Fxf%2FivbWxQBUtR0j4IlcF8Tgh1I7K6m3cwuwolO0Az06CVc4CZE2LzhOI7bvPGsZWRdfPmB%2BJ6qQ1o1LiSGQ5AuV2RbiuGmSMvLXlHYHloPBVmqEyAleKhDMLEvMwU3bGclBUpaCiKKN%2B%2BvKetTMs4P2ueBW278aYZNVvua1m1VITnI5grj0fV1MBx7VtDom7VTQyyD8nYkEwoqnkJ0GlCsH%2FSCZEyWfq%2F0A%2BVP72tolvso6nYheXNGUTk8vdKfUGQ8cc%2FMnadC3qfPKm9yvPUeF2NC%2FCVU3IW7WDu1TPGibbS5Slwv4lHWNU%2BLdHIr6cT2Rav%2BBfK1tcvT4044w%3D%3D: HTTPSConnectionPool(host='storage.googleapis.com', port=443): Max retries exceeded with url: /wandb-production.appspot.com/dynamic_x/bert_pytorch/hv2wnz37/wandb-metadata.json?Expires=1706688636&GoogleAccessId=gorilla-files-url-signer-man%40wandb-production.iam.gserviceaccount.com&Signature=QD%2Fxf%2FivbWxQBUtR0j4IlcF8Tgh1I7K6m3cwuwolO0Az06CVc4CZE2LzhOI7bvPGsZWRdfPmB%2BJ6qQ1o1LiSGQ5AuV2RbiuGmSMvLXlHYHloPBVmqEyAleKhDMLEvMwU3bGclBUpaCiKKN%2B%2BvKetTMs4P2ueBW278aYZNVvua1m1VITnI5grj0fV1MBx7VtDom7VTQyyD8nYkEwoqnkJ0GlCsH%2FSCZEyWfq%2F0A%2BVP72tolvso6nYheXNGUTk8vdKfUGQ8cc%2FMnadC3qfPKm9yvPUeF2NC%2FCVU3IW7WDu1TPGibbS5Slwv4lHWNU%2BLdHIr6cT2Rav%2BBfK1tcvT4044w%3D%3D (Caused by NewConnectionError('<urllib3.connection.HTTPSConnection object at 0x7f819c533a60>: Failed to establish a new connection: [Errno 101] Network is unreachable'))
2024-01-30 16:13:07,914 ERROR   wandb-upload_0:1134334 [internal_api.py:upload_file():2767] upload_file request headers: {'User-Agent': 'python-requests/2.23.0', 'Accept-Encoding': 'gzip, deflate', 'Accept': '*/*', 'Connection': 'keep-alive', 'Content-Length': '15540'}
2024-01-30 16:13:07,914 ERROR   wandb-upload_0:1134334 [internal_api.py:upload_file():2769] upload_file response body: 
2024-01-30 16:13:08,627 DEBUG   HandlerThread:1134334 [handler.py:handle_request():146] handle_request: status_report
2024-01-30 16:13:13,628 DEBUG   HandlerThread:1134334 [handler.py:handle_request():146] handle_request: status_report
2024-01-30 16:13:15,223 DEBUG   SenderThread:1134334 [sender.py:send():382] send: stats
2024-01-30 16:13:19,306 DEBUG   HandlerThread:1134334 [handler.py:handle_request():146] handle_request: status_report
2024-01-30 16:13:22,254 DEBUG   HandlerThread:1134334 [handler.py:handle_request():146] handle_request: stop_status
2024-01-30 16:13:22,255 DEBUG   SenderThread:1134334 [sender.py:send_request():409] send_request: stop_status
2024-01-30 16:13:22,297 DEBUG   HandlerThread:1134334 [handler.py:handle_request():146] handle_request: internal_messages
2024-01-30 16:13:24,631 DEBUG   HandlerThread:1134334 [handler.py:handle_request():146] handle_request: status_report
2024-01-30 16:13:29,744 DEBUG   HandlerThread:1134334 [handler.py:handle_request():146] handle_request: status_report
2024-01-30 16:13:34,902 DEBUG   HandlerThread:1134334 [handler.py:handle_request():146] handle_request: status_report
2024-01-30 16:13:37,361 DEBUG   HandlerThread:1134334 [handler.py:handle_request():146] handle_request: stop_status
2024-01-30 16:13:37,361 DEBUG   HandlerThread:1134334 [handler.py:handle_request():146] handle_request: internal_messages
2024-01-30 16:13:37,362 DEBUG   SenderThread:1134334 [sender.py:send_request():409] send_request: stop_status
2024-01-30 16:13:40,678 DEBUG   HandlerThread:1134334 [handler.py:handle_request():146] handle_request: status_report
2024-01-30 16:13:45,226 DEBUG   SenderThread:1134334 [sender.py:send():382] send: stats
2024-01-30 16:13:46,227 DEBUG   HandlerThread:1134334 [handler.py:handle_request():146] handle_request: status_report
2024-01-30 16:13:51,227 DEBUG   HandlerThread:1134334 [handler.py:handle_request():146] handle_request: status_report
2024-01-30 16:13:52,255 DEBUG   HandlerThread:1134334 [handler.py:handle_request():146] handle_request: stop_status
2024-01-30 16:13:52,255 DEBUG   SenderThread:1134334 [sender.py:send_request():409] send_request: stop_status
2024-01-30 16:13:52,258 DEBUG   HandlerThread:1134334 [handler.py:handle_request():146] handle_request: internal_messages
2024-01-30 16:13:56,558 DEBUG   HandlerThread:1134334 [handler.py:handle_request():146] handle_request: status_report
2024-01-30 16:14:01,558 DEBUG   HandlerThread:1134334 [handler.py:handle_request():146] handle_request: status_report
2024-01-30 16:14:06,559 DEBUG   HandlerThread:1134334 [handler.py:handle_request():146] handle_request: status_report
2024-01-30 16:14:07,255 DEBUG   HandlerThread:1134334 [handler.py:handle_request():146] handle_request: stop_status
2024-01-30 16:14:07,255 DEBUG   SenderThread:1134334 [sender.py:send_request():409] send_request: stop_status
2024-01-30 16:14:07,297 DEBUG   HandlerThread:1134334 [handler.py:handle_request():146] handle_request: internal_messages
2024-01-30 16:14:12,541 DEBUG   HandlerThread:1134334 [handler.py:handle_request():146] handle_request: status_report
2024-01-30 16:14:15,228 DEBUG   SenderThread:1134334 [sender.py:send():382] send: stats
2024-01-30 16:14:18,262 DEBUG   HandlerThread:1134334 [handler.py:handle_request():146] handle_request: status_report
2024-01-30 16:14:22,290 DEBUG   HandlerThread:1134334 [handler.py:handle_request():146] handle_request: stop_status
2024-01-30 16:14:22,290 DEBUG   SenderThread:1134334 [sender.py:send_request():409] send_request: stop_status
2024-01-30 16:14:22,297 DEBUG   HandlerThread:1134334 [handler.py:handle_request():146] handle_request: internal_messages
2024-01-30 16:14:23,597 DEBUG   HandlerThread:1134334 [handler.py:handle_request():146] handle_request: status_report
2024-01-30 16:14:28,621 DEBUG   HandlerThread:1134334 [handler.py:handle_request():146] handle_request: status_report
2024-01-30 16:14:33,781 DEBUG   HandlerThread:1134334 [handler.py:handle_request():146] handle_request: status_report
2024-01-30 16:14:37,256 DEBUG   HandlerThread:1134334 [handler.py:handle_request():146] handle_request: stop_status
2024-01-30 16:14:37,256 DEBUG   SenderThread:1134334 [sender.py:send_request():409] send_request: stop_status
2024-01-30 16:14:37,298 DEBUG   HandlerThread:1134334 [handler.py:handle_request():146] handle_request: internal_messages
2024-01-30 16:14:39,570 DEBUG   HandlerThread:1134334 [handler.py:handle_request():146] handle_request: status_report
2024-01-30 16:14:44,646 DEBUG   HandlerThread:1134334 [handler.py:handle_request():146] handle_request: status_report
2024-01-30 16:14:45,232 DEBUG   SenderThread:1134334 [sender.py:send():382] send: stats
2024-01-30 16:14:50,306 DEBUG   HandlerThread:1134334 [handler.py:handle_request():146] handle_request: status_report
2024-01-30 16:14:52,256 DEBUG   HandlerThread:1134334 [handler.py:handle_request():146] handle_request: stop_status
2024-01-30 16:14:52,256 DEBUG   SenderThread:1134334 [sender.py:send_request():409] send_request: stop_status
2024-01-30 16:14:52,301 DEBUG   HandlerThread:1134334 [handler.py:handle_request():146] handle_request: internal_messages
2024-01-30 16:14:55,554 DEBUG   HandlerThread:1134334 [handler.py:handle_request():146] handle_request: status_report
2024-01-30 16:15:00,555 DEBUG   HandlerThread:1134334 [handler.py:handle_request():146] handle_request: status_report
2024-01-30 16:15:05,555 DEBUG   HandlerThread:1134334 [handler.py:handle_request():146] handle_request: status_report
2024-01-30 16:15:07,256 DEBUG   HandlerThread:1134334 [handler.py:handle_request():146] handle_request: stop_status
2024-01-30 16:15:07,256 DEBUG   SenderThread:1134334 [sender.py:send_request():409] send_request: stop_status
2024-01-30 16:15:07,297 DEBUG   HandlerThread:1134334 [handler.py:handle_request():146] handle_request: internal_messages
2024-01-30 16:15:10,563 DEBUG   HandlerThread:1134334 [handler.py:handle_request():146] handle_request: status_report
2024-01-30 16:15:15,232 DEBUG   SenderThread:1134334 [sender.py:send():382] send: stats
2024-01-30 16:15:16,234 DEBUG   HandlerThread:1134334 [handler.py:handle_request():146] handle_request: status_report
2024-01-30 16:15:20,435 ERROR   wandb-upload_0:1134334 [internal_api.py:upload_file():2765] upload_file exception https://storage.googleapis.com/wandb-production.appspot.com/dynamic_x/bert_pytorch/hv2wnz37/wandb-metadata.json?Expires=1706688636&GoogleAccessId=gorilla-files-url-signer-man%40wandb-production.iam.gserviceaccount.com&Signature=QD%2Fxf%2FivbWxQBUtR0j4IlcF8Tgh1I7K6m3cwuwolO0Az06CVc4CZE2LzhOI7bvPGsZWRdfPmB%2BJ6qQ1o1LiSGQ5AuV2RbiuGmSMvLXlHYHloPBVmqEyAleKhDMLEvMwU3bGclBUpaCiKKN%2B%2BvKetTMs4P2ueBW278aYZNVvua1m1VITnI5grj0fV1MBx7VtDom7VTQyyD8nYkEwoqnkJ0GlCsH%2FSCZEyWfq%2F0A%2BVP72tolvso6nYheXNGUTk8vdKfUGQ8cc%2FMnadC3qfPKm9yvPUeF2NC%2FCVU3IW7WDu1TPGibbS5Slwv4lHWNU%2BLdHIr6cT2Rav%2BBfK1tcvT4044w%3D%3D: HTTPSConnectionPool(host='storage.googleapis.com', port=443): Max retries exceeded with url: /wandb-production.appspot.com/dynamic_x/bert_pytorch/hv2wnz37/wandb-metadata.json?Expires=1706688636&GoogleAccessId=gorilla-files-url-signer-man%40wandb-production.iam.gserviceaccount.com&Signature=QD%2Fxf%2FivbWxQBUtR0j4IlcF8Tgh1I7K6m3cwuwolO0Az06CVc4CZE2LzhOI7bvPGsZWRdfPmB%2BJ6qQ1o1LiSGQ5AuV2RbiuGmSMvLXlHYHloPBVmqEyAleKhDMLEvMwU3bGclBUpaCiKKN%2B%2BvKetTMs4P2ueBW278aYZNVvua1m1VITnI5grj0fV1MBx7VtDom7VTQyyD8nYkEwoqnkJ0GlCsH%2FSCZEyWfq%2F0A%2BVP72tolvso6nYheXNGUTk8vdKfUGQ8cc%2FMnadC3qfPKm9yvPUeF2NC%2FCVU3IW7WDu1TPGibbS5Slwv4lHWNU%2BLdHIr6cT2Rav%2BBfK1tcvT4044w%3D%3D (Caused by NewConnectionError('<urllib3.connection.HTTPSConnection object at 0x7f819c6a3cd0>: Failed to establish a new connection: [Errno 101] Network is unreachable'))
2024-01-30 16:15:20,435 ERROR   wandb-upload_0:1134334 [internal_api.py:upload_file():2767] upload_file request headers: {'User-Agent': 'python-requests/2.23.0', 'Accept-Encoding': 'gzip, deflate', 'Accept': '*/*', 'Connection': 'keep-alive', 'Content-Length': '15540'}
2024-01-30 16:15:20,435 ERROR   wandb-upload_0:1134334 [internal_api.py:upload_file():2769] upload_file response body: 
2024-01-30 16:15:21,285 DEBUG   HandlerThread:1134334 [handler.py:handle_request():146] handle_request: status_report
2024-01-30 16:15:22,256 DEBUG   HandlerThread:1134334 [handler.py:handle_request():146] handle_request: stop_status
2024-01-30 16:15:22,257 DEBUG   SenderThread:1134334 [sender.py:send_request():409] send_request: stop_status
2024-01-30 16:15:22,357 DEBUG   HandlerThread:1134334 [handler.py:handle_request():146] handle_request: internal_messages
2024-01-30 16:15:26,600 DEBUG   HandlerThread:1134334 [handler.py:handle_request():146] handle_request: status_report
2024-01-30 16:15:31,714 DEBUG   HandlerThread:1134334 [handler.py:handle_request():146] handle_request: status_report
2024-01-30 16:15:36,818 DEBUG   HandlerThread:1134334 [handler.py:handle_request():146] handle_request: status_report
2024-01-30 16:15:37,256 DEBUG   HandlerThread:1134334 [handler.py:handle_request():146] handle_request: stop_status
2024-01-30 16:15:37,257 DEBUG   SenderThread:1134334 [sender.py:send_request():409] send_request: stop_status
2024-01-30 16:15:37,261 DEBUG   HandlerThread:1134334 [handler.py:handle_request():146] handle_request: internal_messages
2024-01-30 16:15:42,722 DEBUG   HandlerThread:1134334 [handler.py:handle_request():146] handle_request: status_report
2024-01-30 16:15:45,235 DEBUG   SenderThread:1134334 [sender.py:send():382] send: stats
2024-01-30 16:15:48,236 DEBUG   HandlerThread:1134334 [handler.py:handle_request():146] handle_request: status_report
2024-01-30 16:15:52,256 DEBUG   HandlerThread:1134334 [handler.py:handle_request():146] handle_request: stop_status
2024-01-30 16:15:52,257 DEBUG   SenderThread:1134334 [sender.py:send_request():409] send_request: stop_status
2024-01-30 16:15:52,297 DEBUG   HandlerThread:1134334 [handler.py:handle_request():146] handle_request: internal_messages
2024-01-30 16:15:53,626 DEBUG   HandlerThread:1134334 [handler.py:handle_request():146] handle_request: status_report
2024-01-30 16:15:58,627 DEBUG   HandlerThread:1134334 [handler.py:handle_request():146] handle_request: status_report
2024-01-30 16:16:03,402 INFO    Thread-12 :1134334 [dir_watcher.py:_on_file_modified():288] file/dir modified: /home/yanxindong/mkor/bert/wandb/run-20240130_161012-hv2wnz37/files/output.log
2024-01-30 16:16:04,523 DEBUG   HandlerThread:1134334 [handler.py:handle_request():146] handle_request: status_report
2024-01-30 16:16:07,256 DEBUG   HandlerThread:1134334 [handler.py:handle_request():146] handle_request: stop_status
2024-01-30 16:16:07,257 DEBUG   SenderThread:1134334 [sender.py:send_request():409] send_request: stop_status
2024-01-30 16:16:07,260 DEBUG   HandlerThread:1134334 [handler.py:handle_request():146] handle_request: internal_messages
2024-01-30 16:16:09,596 DEBUG   HandlerThread:1134334 [handler.py:handle_request():146] handle_request: status_report
2024-01-30 16:16:14,599 DEBUG   HandlerThread:1134334 [handler.py:handle_request():146] handle_request: status_report
2024-01-30 16:16:15,237 DEBUG   SenderThread:1134334 [sender.py:send():382] send: stats
2024-01-30 16:16:20,258 DEBUG   HandlerThread:1134334 [handler.py:handle_request():146] handle_request: status_report
2024-01-30 16:16:22,258 DEBUG   HandlerThread:1134334 [handler.py:handle_request():146] handle_request: stop_status
2024-01-30 16:16:22,259 DEBUG   SenderThread:1134334 [sender.py:send_request():409] send_request: stop_status
2024-01-30 16:16:22,297 DEBUG   HandlerThread:1134334 [handler.py:handle_request():146] handle_request: internal_messages
2024-01-30 16:16:22,547 DEBUG   SenderThread:1134334 [sender.py:send():382] send: exit
2024-01-30 16:16:22,547 INFO    SenderThread:1134334 [sender.py:send_exit():589] handling exit code: 1
2024-01-30 16:16:22,547 INFO    SenderThread:1134334 [sender.py:send_exit():591] handling runtime: 367
2024-01-30 16:16:22,547 INFO    SenderThread:1134334 [sender.py:_save_file():1403] saving file wandb-summary.json with policy end
2024-01-30 16:16:22,548 INFO    SenderThread:1134334 [sender.py:send_exit():597] send defer
2024-01-30 16:16:22,548 DEBUG   HandlerThread:1134334 [handler.py:handle_request():146] handle_request: defer
2024-01-30 16:16:22,548 INFO    HandlerThread:1134334 [handler.py:handle_request_defer():172] handle defer: 0
2024-01-30 16:16:22,548 DEBUG   SenderThread:1134334 [sender.py:send_request():409] send_request: defer
2024-01-30 16:16:22,548 INFO    SenderThread:1134334 [sender.py:send_request_defer():613] handle sender defer: 0
2024-01-30 16:16:22,548 INFO    SenderThread:1134334 [sender.py:transition_state():617] send defer: 1
2024-01-30 16:16:22,549 DEBUG   HandlerThread:1134334 [handler.py:handle_request():146] handle_request: defer
2024-01-30 16:16:22,549 INFO    HandlerThread:1134334 [handler.py:handle_request_defer():172] handle defer: 1
2024-01-30 16:16:22,549 DEBUG   SenderThread:1134334 [sender.py:send_request():409] send_request: defer
2024-01-30 16:16:22,549 INFO    SenderThread:1134334 [sender.py:send_request_defer():613] handle sender defer: 1
2024-01-30 16:16:22,549 INFO    SenderThread:1134334 [sender.py:transition_state():617] send defer: 2
2024-01-30 16:16:22,549 DEBUG   HandlerThread:1134334 [handler.py:handle_request():146] handle_request: defer
2024-01-30 16:16:22,549 INFO    HandlerThread:1134334 [handler.py:handle_request_defer():172] handle defer: 2
2024-01-30 16:16:22,549 INFO    HandlerThread:1134334 [system_monitor.py:finish():203] Stopping system monitor
2024-01-30 16:16:22,549 DEBUG   SystemMonitor:1134334 [system_monitor.py:_start():179] Finished system metrics aggregation loop
2024-01-30 16:16:22,549 DEBUG   SystemMonitor:1134334 [system_monitor.py:_start():183] Publishing last batch of metrics
2024-01-30 16:16:22,551 INFO    HandlerThread:1134334 [interfaces.py:finish():202] Joined cpu monitor
2024-01-30 16:16:22,552 INFO    HandlerThread:1134334 [interfaces.py:finish():202] Joined disk monitor
2024-01-30 16:16:23,480 INFO    Thread-12 :1134334 [dir_watcher.py:_on_file_modified():288] file/dir modified: /home/yanxindong/mkor/bert/wandb/run-20240130_161012-hv2wnz37/files/output.log
2024-01-30 16:16:23,481 INFO    Thread-12 :1134334 [dir_watcher.py:_on_file_created():271] file/dir created: /home/yanxindong/mkor/bert/wandb/run-20240130_161012-hv2wnz37/files/wandb-summary.json
2024-01-30 16:16:24,047 INFO    HandlerThread:1134334 [interfaces.py:finish():202] Joined gpu monitor
2024-01-30 16:16:24,047 INFO    HandlerThread:1134334 [interfaces.py:finish():202] Joined memory monitor
2024-01-30 16:16:24,047 INFO    HandlerThread:1134334 [interfaces.py:finish():202] Joined network monitor
2024-01-30 16:16:24,048 DEBUG   HandlerThread:1134334 [handler.py:handle_request():146] handle_request: poll_exit
2024-01-30 16:16:24,048 DEBUG   SenderThread:1134334 [sender.py:send_request():409] send_request: defer
2024-01-30 16:16:24,048 INFO    SenderThread:1134334 [sender.py:send_request_defer():613] handle sender defer: 2
2024-01-30 16:16:24,048 INFO    SenderThread:1134334 [sender.py:transition_state():617] send defer: 3
2024-01-30 16:16:24,048 DEBUG   HandlerThread:1134334 [handler.py:handle_request():146] handle_request: defer
2024-01-30 16:16:24,048 INFO    HandlerThread:1134334 [handler.py:handle_request_defer():172] handle defer: 3
2024-01-30 16:16:24,048 DEBUG   SenderThread:1134334 [sender.py:send():382] send: stats
2024-01-30 16:16:24,049 DEBUG   SenderThread:1134334 [sender.py:send_request():409] send_request: poll_exit
2024-01-30 16:16:24,049 DEBUG   SenderThread:1134334 [sender.py:send_request():409] send_request: defer
2024-01-30 16:16:24,049 INFO    SenderThread:1134334 [sender.py:send_request_defer():613] handle sender defer: 3
2024-01-30 16:16:24,049 INFO    SenderThread:1134334 [sender.py:transition_state():617] send defer: 4
2024-01-30 16:16:24,049 DEBUG   HandlerThread:1134334 [handler.py:handle_request():146] handle_request: defer
2024-01-30 16:16:24,049 INFO    HandlerThread:1134334 [handler.py:handle_request_defer():172] handle defer: 4
2024-01-30 16:16:24,049 DEBUG   SenderThread:1134334 [sender.py:send_request():409] send_request: defer
2024-01-30 16:16:24,049 INFO    SenderThread:1134334 [sender.py:send_request_defer():613] handle sender defer: 4
2024-01-30 16:16:24,049 INFO    SenderThread:1134334 [sender.py:transition_state():617] send defer: 5
2024-01-30 16:16:24,049 DEBUG   HandlerThread:1134334 [handler.py:handle_request():146] handle_request: defer
2024-01-30 16:16:24,049 INFO    HandlerThread:1134334 [handler.py:handle_request_defer():172] handle defer: 5
2024-01-30 16:16:24,050 DEBUG   SenderThread:1134334 [sender.py:send():382] send: summary
2024-01-30 16:16:24,050 INFO    SenderThread:1134334 [sender.py:_save_file():1403] saving file wandb-summary.json with policy end
2024-01-30 16:16:24,050 DEBUG   SenderThread:1134334 [sender.py:send_request():409] send_request: defer
2024-01-30 16:16:24,050 INFO    SenderThread:1134334 [sender.py:send_request_defer():613] handle sender defer: 5
2024-01-30 16:16:24,050 INFO    SenderThread:1134334 [sender.py:transition_state():617] send defer: 6
2024-01-30 16:16:24,050 DEBUG   HandlerThread:1134334 [handler.py:handle_request():146] handle_request: defer
2024-01-30 16:16:24,050 INFO    HandlerThread:1134334 [handler.py:handle_request_defer():172] handle defer: 6
2024-01-30 16:16:24,050 DEBUG   SenderThread:1134334 [sender.py:send_request():409] send_request: defer
2024-01-30 16:16:24,050 INFO    SenderThread:1134334 [sender.py:send_request_defer():613] handle sender defer: 6
2024-01-30 16:16:24,050 INFO    SenderThread:1134334 [sender.py:transition_state():617] send defer: 7
2024-01-30 16:16:24,050 DEBUG   HandlerThread:1134334 [handler.py:handle_request():146] handle_request: status_report
2024-01-30 16:16:24,050 DEBUG   HandlerThread:1134334 [handler.py:handle_request():146] handle_request: defer
2024-01-30 16:16:24,051 INFO    HandlerThread:1134334 [handler.py:handle_request_defer():172] handle defer: 7
2024-01-30 16:16:24,051 DEBUG   SenderThread:1134334 [sender.py:send_request():409] send_request: defer
2024-01-30 16:16:24,051 INFO    SenderThread:1134334 [sender.py:send_request_defer():613] handle sender defer: 7
2024-01-30 16:16:24,481 INFO    Thread-12 :1134334 [dir_watcher.py:_on_file_modified():288] file/dir modified: /home/yanxindong/mkor/bert/wandb/run-20240130_161012-hv2wnz37/files/wandb-summary.json
2024-01-30 16:16:24,520 DEBUG   HandlerThread:1134334 [handler.py:handle_request():146] handle_request: poll_exit
2024-01-30 16:16:24,974 INFO    SenderThread:1134334 [sender.py:transition_state():617] send defer: 8
2024-01-30 16:16:24,975 DEBUG   SenderThread:1134334 [sender.py:send_request():409] send_request: poll_exit
2024-01-30 16:16:24,975 DEBUG   HandlerThread:1134334 [handler.py:handle_request():146] handle_request: defer
2024-01-30 16:16:24,975 INFO    HandlerThread:1134334 [handler.py:handle_request_defer():172] handle defer: 8
2024-01-30 16:16:24,976 DEBUG   SenderThread:1134334 [sender.py:send_request():409] send_request: defer
2024-01-30 16:16:24,976 INFO    SenderThread:1134334 [sender.py:send_request_defer():613] handle sender defer: 8
2024-01-30 16:16:24,976 INFO    SenderThread:1134334 [job_builder.py:build():296] Attempting to build job artifact
2024-01-30 16:16:24,977 INFO    SenderThread:1134334 [job_builder.py:_get_source_type():426] is repo sourced job
2024-01-30 16:16:25,002 INFO    SenderThread:1134334 [job_builder.py:build():402] adding wandb-job metadata file
2024-01-30 16:16:25,004 INFO    SenderThread:1134334 [sender.py:transition_state():617] send defer: 9
2024-01-30 16:16:25,004 DEBUG   HandlerThread:1134334 [handler.py:handle_request():146] handle_request: defer
2024-01-30 16:16:25,004 INFO    HandlerThread:1134334 [handler.py:handle_request_defer():172] handle defer: 9
2024-01-30 16:16:25,004 DEBUG   SenderThread:1134334 [sender.py:send():382] send: artifact
2024-01-30 16:16:25,482 INFO    Thread-12 :1134334 [dir_watcher.py:_on_file_modified():288] file/dir modified: /home/yanxindong/mkor/bert/wandb/run-20240130_161012-hv2wnz37/files/output.log
2024-01-30 16:16:25,521 DEBUG   HandlerThread:1134334 [handler.py:handle_request():146] handle_request: poll_exit
2024-01-30 16:16:26,882 ERROR   wandb-upload_2:1134334 [internal_api.py:upload_file():2765] upload_file exception https://storage.googleapis.com/wandb-artifacts-prod/wandb_artifacts/133981200/707680667/6873c23a2381d1524249eb1a948a45a5?Expires=1706688986&GoogleAccessId=gorilla-files-url-signer-man%40wandb-production.iam.gserviceaccount.com&Signature=pLutHOvvYkhLFMVsvj%2FcNFhiXUQKpdneKu7HDHSRpFEFSGDh%2BVG7u5XzbniWCqqTmQUukmavF5ze5HK1dc082gHQo6RDma53MJ%2B1vq9GscskVPAp5FsLcxYNZX%2FajraXUjrDpqiX0ogRu%2FfxbcP1rSNC9VJQsF6cf7IyTY%2F5hYJRhpzn8epgFzbCPPRt%2FJYvUEAzC2kcfjHnRL4t9h5W9JUUYArxxBD%2BGE16g%2Bx4NP9kHFtMcEYthU06bgAmz%2F3npvAc%2FPg%2F5JUaEbiOtQJFHLrqgyeN4%2Fazv%2BuSUMfdkLPNSx2LjuhrOHA6Y6sI%2BWOpfaLy8kJuryWhcmOzbK4iAw%3D%3D: HTTPSConnectionPool(host='storage.googleapis.com', port=443): Max retries exceeded with url: /wandb-artifacts-prod/wandb_artifacts/133981200/707680667/6873c23a2381d1524249eb1a948a45a5?Expires=1706688986&GoogleAccessId=gorilla-files-url-signer-man%40wandb-production.iam.gserviceaccount.com&Signature=pLutHOvvYkhLFMVsvj%2FcNFhiXUQKpdneKu7HDHSRpFEFSGDh%2BVG7u5XzbniWCqqTmQUukmavF5ze5HK1dc082gHQo6RDma53MJ%2B1vq9GscskVPAp5FsLcxYNZX%2FajraXUjrDpqiX0ogRu%2FfxbcP1rSNC9VJQsF6cf7IyTY%2F5hYJRhpzn8epgFzbCPPRt%2FJYvUEAzC2kcfjHnRL4t9h5W9JUUYArxxBD%2BGE16g%2Bx4NP9kHFtMcEYthU06bgAmz%2F3npvAc%2FPg%2F5JUaEbiOtQJFHLrqgyeN4%2Fazv%2BuSUMfdkLPNSx2LjuhrOHA6Y6sI%2BWOpfaLy8kJuryWhcmOzbK4iAw%3D%3D (Caused by NewConnectionError('<urllib3.connection.HTTPSConnection object at 0x7f819c5fbc40>: Failed to establish a new connection: [Errno 101] Network is unreachable'))
2024-01-30 16:16:26,882 ERROR   wandb-upload_2:1134334 [internal_api.py:upload_file():2767] upload_file request headers: {'User-Agent': 'python-requests/2.23.0', 'Accept-Encoding': 'gzip, deflate', 'Accept': '*/*', 'Connection': 'keep-alive', 'Content-MD5': 'aHPCOiOB0VJCSesalIpFpQ==', 'Content-Type': 'application/json', 'Content-Length': '609'}
2024-01-30 16:16:26,882 ERROR   wandb-upload_2:1134334 [internal_api.py:upload_file():2769] upload_file response body: 
2024-01-30 16:16:26,882 ERROR   wandb-upload_1:1134334 [internal_api.py:upload_file():2765] upload_file exception https://storage.googleapis.com/wandb-artifacts-prod/wandb_artifacts/133981200/707680667/174a3d9bc61fec126cc7d5bdff5c6c5a?Expires=1706688986&GoogleAccessId=gorilla-files-url-signer-man%40wandb-production.iam.gserviceaccount.com&Signature=Lq7TDpgKSjA328uscGOaP30h0mbWcZnWwy4q5CObxZHdnesfBC3LQoKtCvxmyPolY5tqbEFCgVQf11egXygH2iW9XyvCWyb5BJOCZsFdLihQesybNPQe3IgvScDnJr6z2aljpg9TFvS7O8l3Vl0ogWCQnTER0ZUJP5NDzlDmerkvhg10FJifuxIoNgGvLyTDT%2FXk5xNV8EyVJ%2B%2F41HKCIZx5fcLEEIW09B991ppq5knLWxV3rMRsIQf3suZ5eaa2f0T57I3cQIRpj3yewO%2BlmLo%2Fn33rpQV5L8eyJmlIuvt5mcSe4p4znC5ptLIXe6ohnQ9HlyCiaNEQ3n7CWQ1TjA%3D%3D: HTTPSConnectionPool(host='storage.googleapis.com', port=443): Max retries exceeded with url: /wandb-artifacts-prod/wandb_artifacts/133981200/707680667/174a3d9bc61fec126cc7d5bdff5c6c5a?Expires=1706688986&GoogleAccessId=gorilla-files-url-signer-man%40wandb-production.iam.gserviceaccount.com&Signature=Lq7TDpgKSjA328uscGOaP30h0mbWcZnWwy4q5CObxZHdnesfBC3LQoKtCvxmyPolY5tqbEFCgVQf11egXygH2iW9XyvCWyb5BJOCZsFdLihQesybNPQe3IgvScDnJr6z2aljpg9TFvS7O8l3Vl0ogWCQnTER0ZUJP5NDzlDmerkvhg10FJifuxIoNgGvLyTDT%2FXk5xNV8EyVJ%2B%2F41HKCIZx5fcLEEIW09B991ppq5knLWxV3rMRsIQf3suZ5eaa2f0T57I3cQIRpj3yewO%2BlmLo%2Fn33rpQV5L8eyJmlIuvt5mcSe4p4znC5ptLIXe6ohnQ9HlyCiaNEQ3n7CWQ1TjA%3D%3D (Caused by NewConnectionError('<urllib3.connection.HTTPSConnection object at 0x7f819c511f10>: Failed to establish a new connection: [Errno 101] Network is unreachable'))
2024-01-30 16:16:26,883 ERROR   wandb-upload_1:1134334 [internal_api.py:upload_file():2767] upload_file request headers: {'User-Agent': 'python-requests/2.23.0', 'Accept-Encoding': 'gzip, deflate', 'Accept': '*/*', 'Connection': 'keep-alive', 'Content-MD5': 'F0o9m8Yf7BJsx9W9/1xsWg==', 'Content-Type': 'text/plain; charset=utf-8', 'Content-Length': '2179'}
2024-01-30 16:16:26,883 ERROR   wandb-upload_1:1134334 [internal_api.py:upload_file():2769] upload_file response body: 
2024-01-30 16:16:27,960 ERROR   wandb-upload_1:1134334 [internal_api.py:upload_file():2765] upload_file exception https://storage.googleapis.com/wandb-artifacts-prod/wandb_artifacts/133981200/707680667/174a3d9bc61fec126cc7d5bdff5c6c5a?Expires=1706688986&GoogleAccessId=gorilla-files-url-signer-man%40wandb-production.iam.gserviceaccount.com&Signature=Lq7TDpgKSjA328uscGOaP30h0mbWcZnWwy4q5CObxZHdnesfBC3LQoKtCvxmyPolY5tqbEFCgVQf11egXygH2iW9XyvCWyb5BJOCZsFdLihQesybNPQe3IgvScDnJr6z2aljpg9TFvS7O8l3Vl0ogWCQnTER0ZUJP5NDzlDmerkvhg10FJifuxIoNgGvLyTDT%2FXk5xNV8EyVJ%2B%2F41HKCIZx5fcLEEIW09B991ppq5knLWxV3rMRsIQf3suZ5eaa2f0T57I3cQIRpj3yewO%2BlmLo%2Fn33rpQV5L8eyJmlIuvt5mcSe4p4znC5ptLIXe6ohnQ9HlyCiaNEQ3n7CWQ1TjA%3D%3D: HTTPSConnectionPool(host='storage.googleapis.com', port=443): Max retries exceeded with url: /wandb-artifacts-prod/wandb_artifacts/133981200/707680667/174a3d9bc61fec126cc7d5bdff5c6c5a?Expires=1706688986&GoogleAccessId=gorilla-files-url-signer-man%40wandb-production.iam.gserviceaccount.com&Signature=Lq7TDpgKSjA328uscGOaP30h0mbWcZnWwy4q5CObxZHdnesfBC3LQoKtCvxmyPolY5tqbEFCgVQf11egXygH2iW9XyvCWyb5BJOCZsFdLihQesybNPQe3IgvScDnJr6z2aljpg9TFvS7O8l3Vl0ogWCQnTER0ZUJP5NDzlDmerkvhg10FJifuxIoNgGvLyTDT%2FXk5xNV8EyVJ%2B%2F41HKCIZx5fcLEEIW09B991ppq5knLWxV3rMRsIQf3suZ5eaa2f0T57I3cQIRpj3yewO%2BlmLo%2Fn33rpQV5L8eyJmlIuvt5mcSe4p4znC5ptLIXe6ohnQ9HlyCiaNEQ3n7CWQ1TjA%3D%3D (Caused by NewConnectionError('<urllib3.connection.HTTPSConnection object at 0x7f819c5fb190>: Failed to establish a new connection: [Errno 101] Network is unreachable'))
2024-01-30 16:16:27,960 ERROR   wandb-upload_1:1134334 [internal_api.py:upload_file():2767] upload_file request headers: {'User-Agent': 'python-requests/2.23.0', 'Accept-Encoding': 'gzip, deflate', 'Accept': '*/*', 'Connection': 'keep-alive', 'Content-MD5': 'F0o9m8Yf7BJsx9W9/1xsWg==', 'Content-Type': 'text/plain; charset=utf-8', 'Content-Length': '2179'}
2024-01-30 16:16:27,960 ERROR   wandb-upload_1:1134334 [internal_api.py:upload_file():2769] upload_file response body: 
2024-01-30 16:16:28,067 ERROR   wandb-upload_2:1134334 [internal_api.py:upload_file():2765] upload_file exception https://storage.googleapis.com/wandb-artifacts-prod/wandb_artifacts/133981200/707680667/6873c23a2381d1524249eb1a948a45a5?Expires=1706688986&GoogleAccessId=gorilla-files-url-signer-man%40wandb-production.iam.gserviceaccount.com&Signature=pLutHOvvYkhLFMVsvj%2FcNFhiXUQKpdneKu7HDHSRpFEFSGDh%2BVG7u5XzbniWCqqTmQUukmavF5ze5HK1dc082gHQo6RDma53MJ%2B1vq9GscskVPAp5FsLcxYNZX%2FajraXUjrDpqiX0ogRu%2FfxbcP1rSNC9VJQsF6cf7IyTY%2F5hYJRhpzn8epgFzbCPPRt%2FJYvUEAzC2kcfjHnRL4t9h5W9JUUYArxxBD%2BGE16g%2Bx4NP9kHFtMcEYthU06bgAmz%2F3npvAc%2FPg%2F5JUaEbiOtQJFHLrqgyeN4%2Fazv%2BuSUMfdkLPNSx2LjuhrOHA6Y6sI%2BWOpfaLy8kJuryWhcmOzbK4iAw%3D%3D: HTTPSConnectionPool(host='storage.googleapis.com', port=443): Max retries exceeded with url: /wandb-artifacts-prod/wandb_artifacts/133981200/707680667/6873c23a2381d1524249eb1a948a45a5?Expires=1706688986&GoogleAccessId=gorilla-files-url-signer-man%40wandb-production.iam.gserviceaccount.com&Signature=pLutHOvvYkhLFMVsvj%2FcNFhiXUQKpdneKu7HDHSRpFEFSGDh%2BVG7u5XzbniWCqqTmQUukmavF5ze5HK1dc082gHQo6RDma53MJ%2B1vq9GscskVPAp5FsLcxYNZX%2FajraXUjrDpqiX0ogRu%2FfxbcP1rSNC9VJQsF6cf7IyTY%2F5hYJRhpzn8epgFzbCPPRt%2FJYvUEAzC2kcfjHnRL4t9h5W9JUUYArxxBD%2BGE16g%2Bx4NP9kHFtMcEYthU06bgAmz%2F3npvAc%2FPg%2F5JUaEbiOtQJFHLrqgyeN4%2Fazv%2BuSUMfdkLPNSx2LjuhrOHA6Y6sI%2BWOpfaLy8kJuryWhcmOzbK4iAw%3D%3D (Caused by NewConnectionError('<urllib3.connection.HTTPSConnection object at 0x7f819c511f70>: Failed to establish a new connection: [Errno 101] Network is unreachable'))
2024-01-30 16:16:28,068 ERROR   wandb-upload_2:1134334 [internal_api.py:upload_file():2767] upload_file request headers: {'User-Agent': 'python-requests/2.23.0', 'Accept-Encoding': 'gzip, deflate', 'Accept': '*/*', 'Connection': 'keep-alive', 'Content-MD5': 'aHPCOiOB0VJCSesalIpFpQ==', 'Content-Type': 'application/json', 'Content-Length': '609'}
2024-01-30 16:16:28,068 ERROR   wandb-upload_2:1134334 [internal_api.py:upload_file():2769] upload_file response body: 
2024-01-30 16:16:30,011 ERROR   wandb-upload_1:1134334 [internal_api.py:upload_file():2765] upload_file exception https://storage.googleapis.com/wandb-artifacts-prod/wandb_artifacts/133981200/707680667/174a3d9bc61fec126cc7d5bdff5c6c5a?Expires=1706688986&GoogleAccessId=gorilla-files-url-signer-man%40wandb-production.iam.gserviceaccount.com&Signature=Lq7TDpgKSjA328uscGOaP30h0mbWcZnWwy4q5CObxZHdnesfBC3LQoKtCvxmyPolY5tqbEFCgVQf11egXygH2iW9XyvCWyb5BJOCZsFdLihQesybNPQe3IgvScDnJr6z2aljpg9TFvS7O8l3Vl0ogWCQnTER0ZUJP5NDzlDmerkvhg10FJifuxIoNgGvLyTDT%2FXk5xNV8EyVJ%2B%2F41HKCIZx5fcLEEIW09B991ppq5knLWxV3rMRsIQf3suZ5eaa2f0T57I3cQIRpj3yewO%2BlmLo%2Fn33rpQV5L8eyJmlIuvt5mcSe4p4znC5ptLIXe6ohnQ9HlyCiaNEQ3n7CWQ1TjA%3D%3D: HTTPSConnectionPool(host='storage.googleapis.com', port=443): Max retries exceeded with url: /wandb-artifacts-prod/wandb_artifacts/133981200/707680667/174a3d9bc61fec126cc7d5bdff5c6c5a?Expires=1706688986&GoogleAccessId=gorilla-files-url-signer-man%40wandb-production.iam.gserviceaccount.com&Signature=Lq7TDpgKSjA328uscGOaP30h0mbWcZnWwy4q5CObxZHdnesfBC3LQoKtCvxmyPolY5tqbEFCgVQf11egXygH2iW9XyvCWyb5BJOCZsFdLihQesybNPQe3IgvScDnJr6z2aljpg9TFvS7O8l3Vl0ogWCQnTER0ZUJP5NDzlDmerkvhg10FJifuxIoNgGvLyTDT%2FXk5xNV8EyVJ%2B%2F41HKCIZx5fcLEEIW09B991ppq5knLWxV3rMRsIQf3suZ5eaa2f0T57I3cQIRpj3yewO%2BlmLo%2Fn33rpQV5L8eyJmlIuvt5mcSe4p4znC5ptLIXe6ohnQ9HlyCiaNEQ3n7CWQ1TjA%3D%3D (Caused by NewConnectionError('<urllib3.connection.HTTPSConnection object at 0x7f819c503220>: Failed to establish a new connection: [Errno 101] Network is unreachable'))
2024-01-30 16:16:30,012 ERROR   wandb-upload_1:1134334 [internal_api.py:upload_file():2767] upload_file request headers: {'User-Agent': 'python-requests/2.23.0', 'Accept-Encoding': 'gzip, deflate', 'Accept': '*/*', 'Connection': 'keep-alive', 'Content-MD5': 'F0o9m8Yf7BJsx9W9/1xsWg==', 'Content-Type': 'text/plain; charset=utf-8', 'Content-Length': '2179'}
2024-01-30 16:16:30,012 ERROR   wandb-upload_1:1134334 [internal_api.py:upload_file():2769] upload_file response body: 
2024-01-30 16:16:30,012 INFO    wandb-upload_1:1134334 [retry.py:__call__():172] Retry attempt failed:
Traceback (most recent call last):
  File "/home/yanxindong/anaconda/envs/eva/lib/python3.8/site-packages/urllib3/connection.py", line 159, in _new_conn
    conn = connection.create_connection(
  File "/home/yanxindong/anaconda/envs/eva/lib/python3.8/site-packages/urllib3/util/connection.py", line 84, in create_connection
    raise err
  File "/home/yanxindong/anaconda/envs/eva/lib/python3.8/site-packages/urllib3/util/connection.py", line 74, in create_connection
    sock.connect(sa)
OSError: [Errno 101] Network is unreachable

During handling of the above exception, another exception occurred:

Traceback (most recent call last):
  File "/home/yanxindong/anaconda/envs/eva/lib/python3.8/site-packages/urllib3/connectionpool.py", line 670, in urlopen
    httplib_response = self._make_request(
  File "/home/yanxindong/anaconda/envs/eva/lib/python3.8/site-packages/urllib3/connectionpool.py", line 381, in _make_request
    self._validate_conn(conn)
  File "/home/yanxindong/anaconda/envs/eva/lib/python3.8/site-packages/urllib3/connectionpool.py", line 978, in _validate_conn
    conn.connect()
  File "/home/yanxindong/anaconda/envs/eva/lib/python3.8/site-packages/urllib3/connection.py", line 309, in connect
    conn = self._new_conn()
  File "/home/yanxindong/anaconda/envs/eva/lib/python3.8/site-packages/urllib3/connection.py", line 171, in _new_conn
    raise NewConnectionError(
urllib3.exceptions.NewConnectionError: <urllib3.connection.HTTPSConnection object at 0x7f819c503220>: Failed to establish a new connection: [Errno 101] Network is unreachable

During handling of the above exception, another exception occurred:

Traceback (most recent call last):
  File "/home/yanxindong/anaconda/envs/eva/lib/python3.8/site-packages/requests/adapters.py", line 439, in send
    resp = conn.urlopen(
  File "/home/yanxindong/anaconda/envs/eva/lib/python3.8/site-packages/urllib3/connectionpool.py", line 726, in urlopen
    retries = retries.increment(
  File "/home/yanxindong/anaconda/envs/eva/lib/python3.8/site-packages/urllib3/util/retry.py", line 446, in increment
    raise MaxRetryError(_pool, url, error or ResponseError(cause))
urllib3.exceptions.MaxRetryError: HTTPSConnectionPool(host='storage.googleapis.com', port=443): Max retries exceeded with url: /wandb-artifacts-prod/wandb_artifacts/133981200/707680667/174a3d9bc61fec126cc7d5bdff5c6c5a?Expires=1706688986&GoogleAccessId=gorilla-files-url-signer-man%40wandb-production.iam.gserviceaccount.com&Signature=Lq7TDpgKSjA328uscGOaP30h0mbWcZnWwy4q5CObxZHdnesfBC3LQoKtCvxmyPolY5tqbEFCgVQf11egXygH2iW9XyvCWyb5BJOCZsFdLihQesybNPQe3IgvScDnJr6z2aljpg9TFvS7O8l3Vl0ogWCQnTER0ZUJP5NDzlDmerkvhg10FJifuxIoNgGvLyTDT%2FXk5xNV8EyVJ%2B%2F41HKCIZx5fcLEEIW09B991ppq5knLWxV3rMRsIQf3suZ5eaa2f0T57I3cQIRpj3yewO%2BlmLo%2Fn33rpQV5L8eyJmlIuvt5mcSe4p4znC5ptLIXe6ohnQ9HlyCiaNEQ3n7CWQ1TjA%3D%3D (Caused by NewConnectionError('<urllib3.connection.HTTPSConnection object at 0x7f819c503220>: Failed to establish a new connection: [Errno 101] Network is unreachable'))

During handling of the above exception, another exception occurred:

Traceback (most recent call last):
  File "/home/yanxindong/anaconda/envs/eva/lib/python3.8/site-packages/wandb/sdk/internal/internal_api.py", line 2758, in upload_file
    response = self._upload_file_session.put(
  File "/home/yanxindong/anaconda/envs/eva/lib/python3.8/site-packages/requests/sessions.py", line 590, in put
    return self.request('PUT', url, data=data, **kwargs)
  File "/home/yanxindong/anaconda/envs/eva/lib/python3.8/site-packages/requests/sessions.py", line 530, in request
    resp = self.send(prep, **send_kwargs)
  File "/home/yanxindong/anaconda/envs/eva/lib/python3.8/site-packages/requests/sessions.py", line 643, in send
    r = adapter.send(request, **kwargs)
  File "/home/yanxindong/anaconda/envs/eva/lib/python3.8/site-packages/requests/adapters.py", line 516, in send
    raise ConnectionError(e, request=request)
requests.exceptions.ConnectionError: HTTPSConnectionPool(host='storage.googleapis.com', port=443): Max retries exceeded with url: /wandb-artifacts-prod/wandb_artifacts/133981200/707680667/174a3d9bc61fec126cc7d5bdff5c6c5a?Expires=1706688986&GoogleAccessId=gorilla-files-url-signer-man%40wandb-production.iam.gserviceaccount.com&Signature=Lq7TDpgKSjA328uscGOaP30h0mbWcZnWwy4q5CObxZHdnesfBC3LQoKtCvxmyPolY5tqbEFCgVQf11egXygH2iW9XyvCWyb5BJOCZsFdLihQesybNPQe3IgvScDnJr6z2aljpg9TFvS7O8l3Vl0ogWCQnTER0ZUJP5NDzlDmerkvhg10FJifuxIoNgGvLyTDT%2FXk5xNV8EyVJ%2B%2F41HKCIZx5fcLEEIW09B991ppq5knLWxV3rMRsIQf3suZ5eaa2f0T57I3cQIRpj3yewO%2BlmLo%2Fn33rpQV5L8eyJmlIuvt5mcSe4p4znC5ptLIXe6ohnQ9HlyCiaNEQ3n7CWQ1TjA%3D%3D (Caused by NewConnectionError('<urllib3.connection.HTTPSConnection object at 0x7f819c503220>: Failed to establish a new connection: [Errno 101] Network is unreachable'))

During handling of the above exception, another exception occurred:

Traceback (most recent call last):
  File "/home/yanxindong/anaconda/envs/eva/lib/python3.8/site-packages/wandb/sdk/lib/retry.py", line 131, in __call__
    result = self._call_fn(*args, **kwargs)
  File "/home/yanxindong/anaconda/envs/eva/lib/python3.8/site-packages/wandb/sdk/internal/internal_api.py", line 2789, in upload_file
    raise _e.with_traceback(sys.exc_info()[2])
  File "/home/yanxindong/anaconda/envs/eva/lib/python3.8/site-packages/wandb/sdk/internal/internal_api.py", line 2758, in upload_file
    response = self._upload_file_session.put(
  File "/home/yanxindong/anaconda/envs/eva/lib/python3.8/site-packages/requests/sessions.py", line 590, in put
    return self.request('PUT', url, data=data, **kwargs)
  File "/home/yanxindong/anaconda/envs/eva/lib/python3.8/site-packages/requests/sessions.py", line 530, in request
    resp = self.send(prep, **send_kwargs)
  File "/home/yanxindong/anaconda/envs/eva/lib/python3.8/site-packages/requests/sessions.py", line 643, in send
    r = adapter.send(request, **kwargs)
  File "/home/yanxindong/anaconda/envs/eva/lib/python3.8/site-packages/requests/adapters.py", line 516, in send
    raise ConnectionError(e, request=request)
wandb.sdk.lib.retry.TransientError: None
2024-01-30 16:16:30,324 ERROR   wandb-upload_2:1134334 [internal_api.py:upload_file():2765] upload_file exception https://storage.googleapis.com/wandb-artifacts-prod/wandb_artifacts/133981200/707680667/6873c23a2381d1524249eb1a948a45a5?Expires=1706688986&GoogleAccessId=gorilla-files-url-signer-man%40wandb-production.iam.gserviceaccount.com&Signature=pLutHOvvYkhLFMVsvj%2FcNFhiXUQKpdneKu7HDHSRpFEFSGDh%2BVG7u5XzbniWCqqTmQUukmavF5ze5HK1dc082gHQo6RDma53MJ%2B1vq9GscskVPAp5FsLcxYNZX%2FajraXUjrDpqiX0ogRu%2FfxbcP1rSNC9VJQsF6cf7IyTY%2F5hYJRhpzn8epgFzbCPPRt%2FJYvUEAzC2kcfjHnRL4t9h5W9JUUYArxxBD%2BGE16g%2Bx4NP9kHFtMcEYthU06bgAmz%2F3npvAc%2FPg%2F5JUaEbiOtQJFHLrqgyeN4%2Fazv%2BuSUMfdkLPNSx2LjuhrOHA6Y6sI%2BWOpfaLy8kJuryWhcmOzbK4iAw%3D%3D: HTTPSConnectionPool(host='storage.googleapis.com', port=443): Max retries exceeded with url: /wandb-artifacts-prod/wandb_artifacts/133981200/707680667/6873c23a2381d1524249eb1a948a45a5?Expires=1706688986&GoogleAccessId=gorilla-files-url-signer-man%40wandb-production.iam.gserviceaccount.com&Signature=pLutHOvvYkhLFMVsvj%2FcNFhiXUQKpdneKu7HDHSRpFEFSGDh%2BVG7u5XzbniWCqqTmQUukmavF5ze5HK1dc082gHQo6RDma53MJ%2B1vq9GscskVPAp5FsLcxYNZX%2FajraXUjrDpqiX0ogRu%2FfxbcP1rSNC9VJQsF6cf7IyTY%2F5hYJRhpzn8epgFzbCPPRt%2FJYvUEAzC2kcfjHnRL4t9h5W9JUUYArxxBD%2BGE16g%2Bx4NP9kHFtMcEYthU06bgAmz%2F3npvAc%2FPg%2F5JUaEbiOtQJFHLrqgyeN4%2Fazv%2BuSUMfdkLPNSx2LjuhrOHA6Y6sI%2BWOpfaLy8kJuryWhcmOzbK4iAw%3D%3D (Caused by NewConnectionError('<urllib3.connection.HTTPSConnection object at 0x7f819c503be0>: Failed to establish a new connection: [Errno 101] Network is unreachable'))
2024-01-30 16:16:30,325 ERROR   wandb-upload_2:1134334 [internal_api.py:upload_file():2767] upload_file request headers: {'User-Agent': 'python-requests/2.23.0', 'Accept-Encoding': 'gzip, deflate', 'Accept': '*/*', 'Connection': 'keep-alive', 'Content-MD5': 'aHPCOiOB0VJCSesalIpFpQ==', 'Content-Type': 'application/json', 'Content-Length': '609'}
2024-01-30 16:16:30,325 ERROR   wandb-upload_2:1134334 [internal_api.py:upload_file():2769] upload_file response body: 
2024-01-30 16:16:30,325 INFO    wandb-upload_2:1134334 [retry.py:__call__():172] Retry attempt failed:
Traceback (most recent call last):
  File "/home/yanxindong/anaconda/envs/eva/lib/python3.8/site-packages/urllib3/connection.py", line 159, in _new_conn
    conn = connection.create_connection(
  File "/home/yanxindong/anaconda/envs/eva/lib/python3.8/site-packages/urllib3/util/connection.py", line 84, in create_connection
    raise err
  File "/home/yanxindong/anaconda/envs/eva/lib/python3.8/site-packages/urllib3/util/connection.py", line 74, in create_connection
    sock.connect(sa)
OSError: [Errno 101] Network is unreachable

During handling of the above exception, another exception occurred:

Traceback (most recent call last):
  File "/home/yanxindong/anaconda/envs/eva/lib/python3.8/site-packages/urllib3/connectionpool.py", line 670, in urlopen
    httplib_response = self._make_request(
  File "/home/yanxindong/anaconda/envs/eva/lib/python3.8/site-packages/urllib3/connectionpool.py", line 381, in _make_request
    self._validate_conn(conn)
  File "/home/yanxindong/anaconda/envs/eva/lib/python3.8/site-packages/urllib3/connectionpool.py", line 978, in _validate_conn
    conn.connect()
  File "/home/yanxindong/anaconda/envs/eva/lib/python3.8/site-packages/urllib3/connection.py", line 309, in connect
    conn = self._new_conn()
  File "/home/yanxindong/anaconda/envs/eva/lib/python3.8/site-packages/urllib3/connection.py", line 171, in _new_conn
    raise NewConnectionError(
urllib3.exceptions.NewConnectionError: <urllib3.connection.HTTPSConnection object at 0x7f819c503be0>: Failed to establish a new connection: [Errno 101] Network is unreachable

During handling of the above exception, another exception occurred:

Traceback (most recent call last):
  File "/home/yanxindong/anaconda/envs/eva/lib/python3.8/site-packages/requests/adapters.py", line 439, in send
    resp = conn.urlopen(
  File "/home/yanxindong/anaconda/envs/eva/lib/python3.8/site-packages/urllib3/connectionpool.py", line 726, in urlopen
    retries = retries.increment(
  File "/home/yanxindong/anaconda/envs/eva/lib/python3.8/site-packages/urllib3/util/retry.py", line 446, in increment
    raise MaxRetryError(_pool, url, error or ResponseError(cause))
urllib3.exceptions.MaxRetryError: HTTPSConnectionPool(host='storage.googleapis.com', port=443): Max retries exceeded with url: /wandb-artifacts-prod/wandb_artifacts/133981200/707680667/6873c23a2381d1524249eb1a948a45a5?Expires=1706688986&GoogleAccessId=gorilla-files-url-signer-man%40wandb-production.iam.gserviceaccount.com&Signature=pLutHOvvYkhLFMVsvj%2FcNFhiXUQKpdneKu7HDHSRpFEFSGDh%2BVG7u5XzbniWCqqTmQUukmavF5ze5HK1dc082gHQo6RDma53MJ%2B1vq9GscskVPAp5FsLcxYNZX%2FajraXUjrDpqiX0ogRu%2FfxbcP1rSNC9VJQsF6cf7IyTY%2F5hYJRhpzn8epgFzbCPPRt%2FJYvUEAzC2kcfjHnRL4t9h5W9JUUYArxxBD%2BGE16g%2Bx4NP9kHFtMcEYthU06bgAmz%2F3npvAc%2FPg%2F5JUaEbiOtQJFHLrqgyeN4%2Fazv%2BuSUMfdkLPNSx2LjuhrOHA6Y6sI%2BWOpfaLy8kJuryWhcmOzbK4iAw%3D%3D (Caused by NewConnectionError('<urllib3.connection.HTTPSConnection object at 0x7f819c503be0>: Failed to establish a new connection: [Errno 101] Network is unreachable'))

During handling of the above exception, another exception occurred:

Traceback (most recent call last):
  File "/home/yanxindong/anaconda/envs/eva/lib/python3.8/site-packages/wandb/sdk/internal/internal_api.py", line 2758, in upload_file
    response = self._upload_file_session.put(
  File "/home/yanxindong/anaconda/envs/eva/lib/python3.8/site-packages/requests/sessions.py", line 590, in put
    return self.request('PUT', url, data=data, **kwargs)
  File "/home/yanxindong/anaconda/envs/eva/lib/python3.8/site-packages/requests/sessions.py", line 530, in request
    resp = self.send(prep, **send_kwargs)
  File "/home/yanxindong/anaconda/envs/eva/lib/python3.8/site-packages/requests/sessions.py", line 643, in send
    r = adapter.send(request, **kwargs)
  File "/home/yanxindong/anaconda/envs/eva/lib/python3.8/site-packages/requests/adapters.py", line 516, in send
    raise ConnectionError(e, request=request)
requests.exceptions.ConnectionError: HTTPSConnectionPool(host='storage.googleapis.com', port=443): Max retries exceeded with url: /wandb-artifacts-prod/wandb_artifacts/133981200/707680667/6873c23a2381d1524249eb1a948a45a5?Expires=1706688986&GoogleAccessId=gorilla-files-url-signer-man%40wandb-production.iam.gserviceaccount.com&Signature=pLutHOvvYkhLFMVsvj%2FcNFhiXUQKpdneKu7HDHSRpFEFSGDh%2BVG7u5XzbniWCqqTmQUukmavF5ze5HK1dc082gHQo6RDma53MJ%2B1vq9GscskVPAp5FsLcxYNZX%2FajraXUjrDpqiX0ogRu%2FfxbcP1rSNC9VJQsF6cf7IyTY%2F5hYJRhpzn8epgFzbCPPRt%2FJYvUEAzC2kcfjHnRL4t9h5W9JUUYArxxBD%2BGE16g%2Bx4NP9kHFtMcEYthU06bgAmz%2F3npvAc%2FPg%2F5JUaEbiOtQJFHLrqgyeN4%2Fazv%2BuSUMfdkLPNSx2LjuhrOHA6Y6sI%2BWOpfaLy8kJuryWhcmOzbK4iAw%3D%3D (Caused by NewConnectionError('<urllib3.connection.HTTPSConnection object at 0x7f819c503be0>: Failed to establish a new connection: [Errno 101] Network is unreachable'))

During handling of the above exception, another exception occurred:

Traceback (most recent call last):
  File "/home/yanxindong/anaconda/envs/eva/lib/python3.8/site-packages/wandb/sdk/lib/retry.py", line 131, in __call__
    result = self._call_fn(*args, **kwargs)
  File "/home/yanxindong/anaconda/envs/eva/lib/python3.8/site-packages/wandb/sdk/internal/internal_api.py", line 2789, in upload_file
    raise _e.with_traceback(sys.exc_info()[2])
  File "/home/yanxindong/anaconda/envs/eva/lib/python3.8/site-packages/wandb/sdk/internal/internal_api.py", line 2758, in upload_file
    response = self._upload_file_session.put(
  File "/home/yanxindong/anaconda/envs/eva/lib/python3.8/site-packages/requests/sessions.py", line 590, in put
    return self.request('PUT', url, data=data, **kwargs)
  File "/home/yanxindong/anaconda/envs/eva/lib/python3.8/site-packages/requests/sessions.py", line 530, in request
    resp = self.send(prep, **send_kwargs)
  File "/home/yanxindong/anaconda/envs/eva/lib/python3.8/site-packages/requests/sessions.py", line 643, in send
    r = adapter.send(request, **kwargs)
  File "/home/yanxindong/anaconda/envs/eva/lib/python3.8/site-packages/requests/adapters.py", line 516, in send
    raise ConnectionError(e, request=request)
wandb.sdk.lib.retry.TransientError: None
2024-01-30 16:16:30,523 DEBUG   HandlerThread:1134334 [handler.py:handle_request():146] handle_request: keepalive
2024-01-30 16:16:34,592 ERROR   wandb-upload_1:1134334 [internal_api.py:upload_file():2765] upload_file exception https://storage.googleapis.com/wandb-artifacts-prod/wandb_artifacts/133981200/707680667/174a3d9bc61fec126cc7d5bdff5c6c5a?Expires=1706688986&GoogleAccessId=gorilla-files-url-signer-man%40wandb-production.iam.gserviceaccount.com&Signature=Lq7TDpgKSjA328uscGOaP30h0mbWcZnWwy4q5CObxZHdnesfBC3LQoKtCvxmyPolY5tqbEFCgVQf11egXygH2iW9XyvCWyb5BJOCZsFdLihQesybNPQe3IgvScDnJr6z2aljpg9TFvS7O8l3Vl0ogWCQnTER0ZUJP5NDzlDmerkvhg10FJifuxIoNgGvLyTDT%2FXk5xNV8EyVJ%2B%2F41HKCIZx5fcLEEIW09B991ppq5knLWxV3rMRsIQf3suZ5eaa2f0T57I3cQIRpj3yewO%2BlmLo%2Fn33rpQV5L8eyJmlIuvt5mcSe4p4znC5ptLIXe6ohnQ9HlyCiaNEQ3n7CWQ1TjA%3D%3D: HTTPSConnectionPool(host='storage.googleapis.com', port=443): Max retries exceeded with url: /wandb-artifacts-prod/wandb_artifacts/133981200/707680667/174a3d9bc61fec126cc7d5bdff5c6c5a?Expires=1706688986&GoogleAccessId=gorilla-files-url-signer-man%40wandb-production.iam.gserviceaccount.com&Signature=Lq7TDpgKSjA328uscGOaP30h0mbWcZnWwy4q5CObxZHdnesfBC3LQoKtCvxmyPolY5tqbEFCgVQf11egXygH2iW9XyvCWyb5BJOCZsFdLihQesybNPQe3IgvScDnJr6z2aljpg9TFvS7O8l3Vl0ogWCQnTER0ZUJP5NDzlDmerkvhg10FJifuxIoNgGvLyTDT%2FXk5xNV8EyVJ%2B%2F41HKCIZx5fcLEEIW09B991ppq5knLWxV3rMRsIQf3suZ5eaa2f0T57I3cQIRpj3yewO%2BlmLo%2Fn33rpQV5L8eyJmlIuvt5mcSe4p4znC5ptLIXe6ohnQ9HlyCiaNEQ3n7CWQ1TjA%3D%3D (Caused by NewConnectionError('<urllib3.connection.HTTPSConnection object at 0x7f819c5022e0>: Failed to establish a new connection: [Errno 101] Network is unreachable'))
2024-01-30 16:16:34,592 ERROR   wandb-upload_1:1134334 [internal_api.py:upload_file():2767] upload_file request headers: {'User-Agent': 'python-requests/2.23.0', 'Accept-Encoding': 'gzip, deflate', 'Accept': '*/*', 'Connection': 'keep-alive', 'Content-MD5': 'F0o9m8Yf7BJsx9W9/1xsWg==', 'Content-Type': 'text/plain; charset=utf-8', 'Content-Length': '2179'}
2024-01-30 16:16:34,593 ERROR   wandb-upload_1:1134334 [internal_api.py:upload_file():2769] upload_file response body: 
2024-01-30 16:16:34,694 ERROR   wandb-upload_2:1134334 [internal_api.py:upload_file():2765] upload_file exception https://storage.googleapis.com/wandb-artifacts-prod/wandb_artifacts/133981200/707680667/6873c23a2381d1524249eb1a948a45a5?Expires=1706688986&GoogleAccessId=gorilla-files-url-signer-man%40wandb-production.iam.gserviceaccount.com&Signature=pLutHOvvYkhLFMVsvj%2FcNFhiXUQKpdneKu7HDHSRpFEFSGDh%2BVG7u5XzbniWCqqTmQUukmavF5ze5HK1dc082gHQo6RDma53MJ%2B1vq9GscskVPAp5FsLcxYNZX%2FajraXUjrDpqiX0ogRu%2FfxbcP1rSNC9VJQsF6cf7IyTY%2F5hYJRhpzn8epgFzbCPPRt%2FJYvUEAzC2kcfjHnRL4t9h5W9JUUYArxxBD%2BGE16g%2Bx4NP9kHFtMcEYthU06bgAmz%2F3npvAc%2FPg%2F5JUaEbiOtQJFHLrqgyeN4%2Fazv%2BuSUMfdkLPNSx2LjuhrOHA6Y6sI%2BWOpfaLy8kJuryWhcmOzbK4iAw%3D%3D: HTTPSConnectionPool(host='storage.googleapis.com', port=443): Max retries exceeded with url: /wandb-artifacts-prod/wandb_artifacts/133981200/707680667/6873c23a2381d1524249eb1a948a45a5?Expires=1706688986&GoogleAccessId=gorilla-files-url-signer-man%40wandb-production.iam.gserviceaccount.com&Signature=pLutHOvvYkhLFMVsvj%2FcNFhiXUQKpdneKu7HDHSRpFEFSGDh%2BVG7u5XzbniWCqqTmQUukmavF5ze5HK1dc082gHQo6RDma53MJ%2B1vq9GscskVPAp5FsLcxYNZX%2FajraXUjrDpqiX0ogRu%2FfxbcP1rSNC9VJQsF6cf7IyTY%2F5hYJRhpzn8epgFzbCPPRt%2FJYvUEAzC2kcfjHnRL4t9h5W9JUUYArxxBD%2BGE16g%2Bx4NP9kHFtMcEYthU06bgAmz%2F3npvAc%2FPg%2F5JUaEbiOtQJFHLrqgyeN4%2Fazv%2BuSUMfdkLPNSx2LjuhrOHA6Y6sI%2BWOpfaLy8kJuryWhcmOzbK4iAw%3D%3D (Caused by NewConnectionError('<urllib3.connection.HTTPSConnection object at 0x7f819c502a00>: Failed to establish a new connection: [Errno 101] Network is unreachable'))
2024-01-30 16:16:34,694 ERROR   wandb-upload_2:1134334 [internal_api.py:upload_file():2767] upload_file request headers: {'User-Agent': 'python-requests/2.23.0', 'Accept-Encoding': 'gzip, deflate', 'Accept': '*/*', 'Connection': 'keep-alive', 'Content-MD5': 'aHPCOiOB0VJCSesalIpFpQ==', 'Content-Type': 'application/json', 'Content-Length': '609'}
2024-01-30 16:16:34,694 ERROR   wandb-upload_2:1134334 [internal_api.py:upload_file():2769] upload_file response body: 
2024-01-30 16:16:35,526 DEBUG   HandlerThread:1134334 [handler.py:handle_request():146] handle_request: keepalive
2024-01-30 16:16:40,528 DEBUG   HandlerThread:1134334 [handler.py:handle_request():146] handle_request: keepalive
2024-01-30 16:16:43,232 ERROR   wandb-upload_1:1134334 [internal_api.py:upload_file():2765] upload_file exception https://storage.googleapis.com/wandb-artifacts-prod/wandb_artifacts/133981200/707680667/174a3d9bc61fec126cc7d5bdff5c6c5a?Expires=1706688986&GoogleAccessId=gorilla-files-url-signer-man%40wandb-production.iam.gserviceaccount.com&Signature=Lq7TDpgKSjA328uscGOaP30h0mbWcZnWwy4q5CObxZHdnesfBC3LQoKtCvxmyPolY5tqbEFCgVQf11egXygH2iW9XyvCWyb5BJOCZsFdLihQesybNPQe3IgvScDnJr6z2aljpg9TFvS7O8l3Vl0ogWCQnTER0ZUJP5NDzlDmerkvhg10FJifuxIoNgGvLyTDT%2FXk5xNV8EyVJ%2B%2F41HKCIZx5fcLEEIW09B991ppq5knLWxV3rMRsIQf3suZ5eaa2f0T57I3cQIRpj3yewO%2BlmLo%2Fn33rpQV5L8eyJmlIuvt5mcSe4p4znC5ptLIXe6ohnQ9HlyCiaNEQ3n7CWQ1TjA%3D%3D: HTTPSConnectionPool(host='storage.googleapis.com', port=443): Max retries exceeded with url: /wandb-artifacts-prod/wandb_artifacts/133981200/707680667/174a3d9bc61fec126cc7d5bdff5c6c5a?Expires=1706688986&GoogleAccessId=gorilla-files-url-signer-man%40wandb-production.iam.gserviceaccount.com&Signature=Lq7TDpgKSjA328uscGOaP30h0mbWcZnWwy4q5CObxZHdnesfBC3LQoKtCvxmyPolY5tqbEFCgVQf11egXygH2iW9XyvCWyb5BJOCZsFdLihQesybNPQe3IgvScDnJr6z2aljpg9TFvS7O8l3Vl0ogWCQnTER0ZUJP5NDzlDmerkvhg10FJifuxIoNgGvLyTDT%2FXk5xNV8EyVJ%2B%2F41HKCIZx5fcLEEIW09B991ppq5knLWxV3rMRsIQf3suZ5eaa2f0T57I3cQIRpj3yewO%2BlmLo%2Fn33rpQV5L8eyJmlIuvt5mcSe4p4znC5ptLIXe6ohnQ9HlyCiaNEQ3n7CWQ1TjA%3D%3D (Caused by NewConnectionError('<urllib3.connection.HTTPSConnection object at 0x7f819c4f9070>: Failed to establish a new connection: [Errno 101] Network is unreachable'))
2024-01-30 16:16:43,232 ERROR   wandb-upload_1:1134334 [internal_api.py:upload_file():2767] upload_file request headers: {'User-Agent': 'python-requests/2.23.0', 'Accept-Encoding': 'gzip, deflate', 'Accept': '*/*', 'Connection': 'keep-alive', 'Content-MD5': 'F0o9m8Yf7BJsx9W9/1xsWg==', 'Content-Type': 'text/plain; charset=utf-8', 'Content-Length': '2179'}
2024-01-30 16:16:43,232 ERROR   wandb-upload_1:1134334 [internal_api.py:upload_file():2769] upload_file response body: 
2024-01-30 16:16:43,630 ERROR   wandb-upload_2:1134334 [internal_api.py:upload_file():2765] upload_file exception https://storage.googleapis.com/wandb-artifacts-prod/wandb_artifacts/133981200/707680667/6873c23a2381d1524249eb1a948a45a5?Expires=1706688986&GoogleAccessId=gorilla-files-url-signer-man%40wandb-production.iam.gserviceaccount.com&Signature=pLutHOvvYkhLFMVsvj%2FcNFhiXUQKpdneKu7HDHSRpFEFSGDh%2BVG7u5XzbniWCqqTmQUukmavF5ze5HK1dc082gHQo6RDma53MJ%2B1vq9GscskVPAp5FsLcxYNZX%2FajraXUjrDpqiX0ogRu%2FfxbcP1rSNC9VJQsF6cf7IyTY%2F5hYJRhpzn8epgFzbCPPRt%2FJYvUEAzC2kcfjHnRL4t9h5W9JUUYArxxBD%2BGE16g%2Bx4NP9kHFtMcEYthU06bgAmz%2F3npvAc%2FPg%2F5JUaEbiOtQJFHLrqgyeN4%2Fazv%2BuSUMfdkLPNSx2LjuhrOHA6Y6sI%2BWOpfaLy8kJuryWhcmOzbK4iAw%3D%3D: HTTPSConnectionPool(host='storage.googleapis.com', port=443): Max retries exceeded with url: /wandb-artifacts-prod/wandb_artifacts/133981200/707680667/6873c23a2381d1524249eb1a948a45a5?Expires=1706688986&GoogleAccessId=gorilla-files-url-signer-man%40wandb-production.iam.gserviceaccount.com&Signature=pLutHOvvYkhLFMVsvj%2FcNFhiXUQKpdneKu7HDHSRpFEFSGDh%2BVG7u5XzbniWCqqTmQUukmavF5ze5HK1dc082gHQo6RDma53MJ%2B1vq9GscskVPAp5FsLcxYNZX%2FajraXUjrDpqiX0ogRu%2FfxbcP1rSNC9VJQsF6cf7IyTY%2F5hYJRhpzn8epgFzbCPPRt%2FJYvUEAzC2kcfjHnRL4t9h5W9JUUYArxxBD%2BGE16g%2Bx4NP9kHFtMcEYthU06bgAmz%2F3npvAc%2FPg%2F5JUaEbiOtQJFHLrqgyeN4%2Fazv%2BuSUMfdkLPNSx2LjuhrOHA6Y6sI%2BWOpfaLy8kJuryWhcmOzbK4iAw%3D%3D (Caused by NewConnectionError('<urllib3.connection.HTTPSConnection object at 0x7f819c4f9220>: Failed to establish a new connection: [Errno 101] Network is unreachable'))
2024-01-30 16:16:43,630 ERROR   wandb-upload_2:1134334 [internal_api.py:upload_file():2767] upload_file request headers: {'User-Agent': 'python-requests/2.23.0', 'Accept-Encoding': 'gzip, deflate', 'Accept': '*/*', 'Connection': 'keep-alive', 'Content-MD5': 'aHPCOiOB0VJCSesalIpFpQ==', 'Content-Type': 'application/json', 'Content-Length': '609'}
2024-01-30 16:16:43,630 ERROR   wandb-upload_2:1134334 [internal_api.py:upload_file():2769] upload_file response body: 
2024-01-30 16:16:45,530 DEBUG   HandlerThread:1134334 [handler.py:handle_request():146] handle_request: keepalive
2024-01-30 16:16:50,533 DEBUG   HandlerThread:1134334 [handler.py:handle_request():146] handle_request: keepalive
2024-01-30 16:16:55,535 DEBUG   HandlerThread:1134334 [handler.py:handle_request():146] handle_request: keepalive
2024-01-30 16:17:00,537 DEBUG   HandlerThread:1134334 [handler.py:handle_request():146] handle_request: keepalive
2024-01-30 16:17:00,788 ERROR   wandb-upload_1:1134334 [internal_api.py:upload_file():2765] upload_file exception https://storage.googleapis.com/wandb-artifacts-prod/wandb_artifacts/133981200/707680667/174a3d9bc61fec126cc7d5bdff5c6c5a?Expires=1706688986&GoogleAccessId=gorilla-files-url-signer-man%40wandb-production.iam.gserviceaccount.com&Signature=Lq7TDpgKSjA328uscGOaP30h0mbWcZnWwy4q5CObxZHdnesfBC3LQoKtCvxmyPolY5tqbEFCgVQf11egXygH2iW9XyvCWyb5BJOCZsFdLihQesybNPQe3IgvScDnJr6z2aljpg9TFvS7O8l3Vl0ogWCQnTER0ZUJP5NDzlDmerkvhg10FJifuxIoNgGvLyTDT%2FXk5xNV8EyVJ%2B%2F41HKCIZx5fcLEEIW09B991ppq5knLWxV3rMRsIQf3suZ5eaa2f0T57I3cQIRpj3yewO%2BlmLo%2Fn33rpQV5L8eyJmlIuvt5mcSe4p4znC5ptLIXe6ohnQ9HlyCiaNEQ3n7CWQ1TjA%3D%3D: HTTPSConnectionPool(host='storage.googleapis.com', port=443): Max retries exceeded with url: /wandb-artifacts-prod/wandb_artifacts/133981200/707680667/174a3d9bc61fec126cc7d5bdff5c6c5a?Expires=1706688986&GoogleAccessId=gorilla-files-url-signer-man%40wandb-production.iam.gserviceaccount.com&Signature=Lq7TDpgKSjA328uscGOaP30h0mbWcZnWwy4q5CObxZHdnesfBC3LQoKtCvxmyPolY5tqbEFCgVQf11egXygH2iW9XyvCWyb5BJOCZsFdLihQesybNPQe3IgvScDnJr6z2aljpg9TFvS7O8l3Vl0ogWCQnTER0ZUJP5NDzlDmerkvhg10FJifuxIoNgGvLyTDT%2FXk5xNV8EyVJ%2B%2F41HKCIZx5fcLEEIW09B991ppq5knLWxV3rMRsIQf3suZ5eaa2f0T57I3cQIRpj3yewO%2BlmLo%2Fn33rpQV5L8eyJmlIuvt5mcSe4p4znC5ptLIXe6ohnQ9HlyCiaNEQ3n7CWQ1TjA%3D%3D (Caused by NewConnectionError('<urllib3.connection.HTTPSConnection object at 0x7f819c4f9fa0>: Failed to establish a new connection: [Errno 101] Network is unreachable'))
2024-01-30 16:17:00,788 ERROR   wandb-upload_1:1134334 [internal_api.py:upload_file():2767] upload_file request headers: {'User-Agent': 'python-requests/2.23.0', 'Accept-Encoding': 'gzip, deflate', 'Accept': '*/*', 'Connection': 'keep-alive', 'Content-MD5': 'F0o9m8Yf7BJsx9W9/1xsWg==', 'Content-Type': 'text/plain; charset=utf-8', 'Content-Length': '2179'}
2024-01-30 16:17:00,788 ERROR   wandb-upload_1:1134334 [internal_api.py:upload_file():2769] upload_file response body: 
2024-01-30 16:17:02,904 ERROR   wandb-upload_2:1134334 [internal_api.py:upload_file():2765] upload_file exception https://storage.googleapis.com/wandb-artifacts-prod/wandb_artifacts/133981200/707680667/6873c23a2381d1524249eb1a948a45a5?Expires=1706688986&GoogleAccessId=gorilla-files-url-signer-man%40wandb-production.iam.gserviceaccount.com&Signature=pLutHOvvYkhLFMVsvj%2FcNFhiXUQKpdneKu7HDHSRpFEFSGDh%2BVG7u5XzbniWCqqTmQUukmavF5ze5HK1dc082gHQo6RDma53MJ%2B1vq9GscskVPAp5FsLcxYNZX%2FajraXUjrDpqiX0ogRu%2FfxbcP1rSNC9VJQsF6cf7IyTY%2F5hYJRhpzn8epgFzbCPPRt%2FJYvUEAzC2kcfjHnRL4t9h5W9JUUYArxxBD%2BGE16g%2Bx4NP9kHFtMcEYthU06bgAmz%2F3npvAc%2FPg%2F5JUaEbiOtQJFHLrqgyeN4%2Fazv%2BuSUMfdkLPNSx2LjuhrOHA6Y6sI%2BWOpfaLy8kJuryWhcmOzbK4iAw%3D%3D: HTTPSConnectionPool(host='storage.googleapis.com', port=443): Max retries exceeded with url: /wandb-artifacts-prod/wandb_artifacts/133981200/707680667/6873c23a2381d1524249eb1a948a45a5?Expires=1706688986&GoogleAccessId=gorilla-files-url-signer-man%40wandb-production.iam.gserviceaccount.com&Signature=pLutHOvvYkhLFMVsvj%2FcNFhiXUQKpdneKu7HDHSRpFEFSGDh%2BVG7u5XzbniWCqqTmQUukmavF5ze5HK1dc082gHQo6RDma53MJ%2B1vq9GscskVPAp5FsLcxYNZX%2FajraXUjrDpqiX0ogRu%2FfxbcP1rSNC9VJQsF6cf7IyTY%2F5hYJRhpzn8epgFzbCPPRt%2FJYvUEAzC2kcfjHnRL4t9h5W9JUUYArxxBD%2BGE16g%2Bx4NP9kHFtMcEYthU06bgAmz%2F3npvAc%2FPg%2F5JUaEbiOtQJFHLrqgyeN4%2Fazv%2BuSUMfdkLPNSx2LjuhrOHA6Y6sI%2BWOpfaLy8kJuryWhcmOzbK4iAw%3D%3D (Caused by NewConnectionError('<urllib3.connection.HTTPSConnection object at 0x7f819c5029d0>: Failed to establish a new connection: [Errno 101] Network is unreachable'))
2024-01-30 16:17:02,905 ERROR   wandb-upload_2:1134334 [internal_api.py:upload_file():2767] upload_file request headers: {'User-Agent': 'python-requests/2.23.0', 'Accept-Encoding': 'gzip, deflate', 'Accept': '*/*', 'Connection': 'keep-alive', 'Content-MD5': 'aHPCOiOB0VJCSesalIpFpQ==', 'Content-Type': 'application/json', 'Content-Length': '609'}
2024-01-30 16:17:02,905 ERROR   wandb-upload_2:1134334 [internal_api.py:upload_file():2769] upload_file response body: 
2024-01-30 16:17:05,540 DEBUG   HandlerThread:1134334 [handler.py:handle_request():146] handle_request: keepalive
2024-01-30 16:17:10,542 DEBUG   HandlerThread:1134334 [handler.py:handle_request():146] handle_request: keepalive
2024-01-30 16:17:15,544 DEBUG   HandlerThread:1134334 [handler.py:handle_request():146] handle_request: keepalive
2024-01-30 16:17:20,546 DEBUG   HandlerThread:1134334 [handler.py:handle_request():146] handle_request: keepalive
2024-01-30 16:17:25,552 DEBUG   HandlerThread:1134334 [handler.py:handle_request():146] handle_request: keepalive
2024-01-30 16:17:30,554 DEBUG   HandlerThread:1134334 [handler.py:handle_request():146] handle_request: keepalive
2024-01-30 16:17:35,308 ERROR   wandb-upload_1:1134334 [internal_api.py:upload_file():2765] upload_file exception https://storage.googleapis.com/wandb-artifacts-prod/wandb_artifacts/133981200/707680667/174a3d9bc61fec126cc7d5bdff5c6c5a?Expires=1706688986&GoogleAccessId=gorilla-files-url-signer-man%40wandb-production.iam.gserviceaccount.com&Signature=Lq7TDpgKSjA328uscGOaP30h0mbWcZnWwy4q5CObxZHdnesfBC3LQoKtCvxmyPolY5tqbEFCgVQf11egXygH2iW9XyvCWyb5BJOCZsFdLihQesybNPQe3IgvScDnJr6z2aljpg9TFvS7O8l3Vl0ogWCQnTER0ZUJP5NDzlDmerkvhg10FJifuxIoNgGvLyTDT%2FXk5xNV8EyVJ%2B%2F41HKCIZx5fcLEEIW09B991ppq5knLWxV3rMRsIQf3suZ5eaa2f0T57I3cQIRpj3yewO%2BlmLo%2Fn33rpQV5L8eyJmlIuvt5mcSe4p4znC5ptLIXe6ohnQ9HlyCiaNEQ3n7CWQ1TjA%3D%3D: HTTPSConnectionPool(host='storage.googleapis.com', port=443): Max retries exceeded with url: /wandb-artifacts-prod/wandb_artifacts/133981200/707680667/174a3d9bc61fec126cc7d5bdff5c6c5a?Expires=1706688986&GoogleAccessId=gorilla-files-url-signer-man%40wandb-production.iam.gserviceaccount.com&Signature=Lq7TDpgKSjA328uscGOaP30h0mbWcZnWwy4q5CObxZHdnesfBC3LQoKtCvxmyPolY5tqbEFCgVQf11egXygH2iW9XyvCWyb5BJOCZsFdLihQesybNPQe3IgvScDnJr6z2aljpg9TFvS7O8l3Vl0ogWCQnTER0ZUJP5NDzlDmerkvhg10FJifuxIoNgGvLyTDT%2FXk5xNV8EyVJ%2B%2F41HKCIZx5fcLEEIW09B991ppq5knLWxV3rMRsIQf3suZ5eaa2f0T57I3cQIRpj3yewO%2BlmLo%2Fn33rpQV5L8eyJmlIuvt5mcSe4p4znC5ptLIXe6ohnQ9HlyCiaNEQ3n7CWQ1TjA%3D%3D (Caused by NewConnectionError('<urllib3.connection.HTTPSConnection object at 0x7f819c511eb0>: Failed to establish a new connection: [Errno 101] Network is unreachable'))
2024-01-30 16:17:35,308 ERROR   wandb-upload_1:1134334 [internal_api.py:upload_file():2767] upload_file request headers: {'User-Agent': 'python-requests/2.23.0', 'Accept-Encoding': 'gzip, deflate', 'Accept': '*/*', 'Connection': 'keep-alive', 'Content-MD5': 'F0o9m8Yf7BJsx9W9/1xsWg==', 'Content-Type': 'text/plain; charset=utf-8', 'Content-Length': '2179'}
2024-01-30 16:17:35,308 ERROR   wandb-upload_1:1134334 [internal_api.py:upload_file():2769] upload_file response body: 
2024-01-30 16:17:35,556 DEBUG   HandlerThread:1134334 [handler.py:handle_request():146] handle_request: keepalive
2024-01-30 16:17:40,388 ERROR   wandb-upload_2:1134334 [internal_api.py:upload_file():2765] upload_file exception https://storage.googleapis.com/wandb-artifacts-prod/wandb_artifacts/133981200/707680667/6873c23a2381d1524249eb1a948a45a5?Expires=1706688986&GoogleAccessId=gorilla-files-url-signer-man%40wandb-production.iam.gserviceaccount.com&Signature=pLutHOvvYkhLFMVsvj%2FcNFhiXUQKpdneKu7HDHSRpFEFSGDh%2BVG7u5XzbniWCqqTmQUukmavF5ze5HK1dc082gHQo6RDma53MJ%2B1vq9GscskVPAp5FsLcxYNZX%2FajraXUjrDpqiX0ogRu%2FfxbcP1rSNC9VJQsF6cf7IyTY%2F5hYJRhpzn8epgFzbCPPRt%2FJYvUEAzC2kcfjHnRL4t9h5W9JUUYArxxBD%2BGE16g%2Bx4NP9kHFtMcEYthU06bgAmz%2F3npvAc%2FPg%2F5JUaEbiOtQJFHLrqgyeN4%2Fazv%2BuSUMfdkLPNSx2LjuhrOHA6Y6sI%2BWOpfaLy8kJuryWhcmOzbK4iAw%3D%3D: HTTPSConnectionPool(host='storage.googleapis.com', port=443): Max retries exceeded with url: /wandb-artifacts-prod/wandb_artifacts/133981200/707680667/6873c23a2381d1524249eb1a948a45a5?Expires=1706688986&GoogleAccessId=gorilla-files-url-signer-man%40wandb-production.iam.gserviceaccount.com&Signature=pLutHOvvYkhLFMVsvj%2FcNFhiXUQKpdneKu7HDHSRpFEFSGDh%2BVG7u5XzbniWCqqTmQUukmavF5ze5HK1dc082gHQo6RDma53MJ%2B1vq9GscskVPAp5FsLcxYNZX%2FajraXUjrDpqiX0ogRu%2FfxbcP1rSNC9VJQsF6cf7IyTY%2F5hYJRhpzn8epgFzbCPPRt%2FJYvUEAzC2kcfjHnRL4t9h5W9JUUYArxxBD%2BGE16g%2Bx4NP9kHFtMcEYthU06bgAmz%2F3npvAc%2FPg%2F5JUaEbiOtQJFHLrqgyeN4%2Fazv%2BuSUMfdkLPNSx2LjuhrOHA6Y6sI%2BWOpfaLy8kJuryWhcmOzbK4iAw%3D%3D (Caused by NewConnectionError('<urllib3.connection.HTTPSConnection object at 0x7f819c4ee9a0>: Failed to establish a new connection: [Errno 101] Network is unreachable'))
2024-01-30 16:17:40,388 ERROR   wandb-upload_2:1134334 [internal_api.py:upload_file():2767] upload_file request headers: {'User-Agent': 'python-requests/2.23.0', 'Accept-Encoding': 'gzip, deflate', 'Accept': '*/*', 'Connection': 'keep-alive', 'Content-MD5': 'aHPCOiOB0VJCSesalIpFpQ==', 'Content-Type': 'application/json', 'Content-Length': '609'}
2024-01-30 16:17:40,388 ERROR   wandb-upload_2:1134334 [internal_api.py:upload_file():2769] upload_file response body: 
2024-01-30 16:17:40,559 DEBUG   HandlerThread:1134334 [handler.py:handle_request():146] handle_request: keepalive
2024-01-30 16:17:45,561 DEBUG   HandlerThread:1134334 [handler.py:handle_request():146] handle_request: keepalive
2024-01-30 16:17:50,564 DEBUG   HandlerThread:1134334 [handler.py:handle_request():146] handle_request: keepalive
2024-01-30 16:17:55,566 DEBUG   HandlerThread:1134334 [handler.py:handle_request():146] handle_request: keepalive
2024-01-30 16:19:58,550 ERROR   wandb-upload_0:1134334 [internal_api.py:upload_file():2765] upload_file exception https://storage.googleapis.com/wandb-production.appspot.com/dynamic_x/bert_pytorch/hv2wnz37/wandb-metadata.json?Expires=1706688636&GoogleAccessId=gorilla-files-url-signer-man%40wandb-production.iam.gserviceaccount.com&Signature=QD%2Fxf%2FivbWxQBUtR0j4IlcF8Tgh1I7K6m3cwuwolO0Az06CVc4CZE2LzhOI7bvPGsZWRdfPmB%2BJ6qQ1o1LiSGQ5AuV2RbiuGmSMvLXlHYHloPBVmqEyAleKhDMLEvMwU3bGclBUpaCiKKN%2B%2BvKetTMs4P2ueBW278aYZNVvua1m1VITnI5grj0fV1MBx7VtDom7VTQyyD8nYkEwoqnkJ0GlCsH%2FSCZEyWfq%2F0A%2BVP72tolvso6nYheXNGUTk8vdKfUGQ8cc%2FMnadC3qfPKm9yvPUeF2NC%2FCVU3IW7WDu1TPGibbS5Slwv4lHWNU%2BLdHIr6cT2Rav%2BBfK1tcvT4044w%3D%3D: HTTPSConnectionPool(host='storage.googleapis.com', port=443): Max retries exceeded with url: /wandb-production.appspot.com/dynamic_x/bert_pytorch/hv2wnz37/wandb-metadata.json?Expires=1706688636&GoogleAccessId=gorilla-files-url-signer-man%40wandb-production.iam.gserviceaccount.com&Signature=QD%2Fxf%2FivbWxQBUtR0j4IlcF8Tgh1I7K6m3cwuwolO0Az06CVc4CZE2LzhOI7bvPGsZWRdfPmB%2BJ6qQ1o1LiSGQ5AuV2RbiuGmSMvLXlHYHloPBVmqEyAleKhDMLEvMwU3bGclBUpaCiKKN%2B%2BvKetTMs4P2ueBW278aYZNVvua1m1VITnI5grj0fV1MBx7VtDom7VTQyyD8nYkEwoqnkJ0GlCsH%2FSCZEyWfq%2F0A%2BVP72tolvso6nYheXNGUTk8vdKfUGQ8cc%2FMnadC3qfPKm9yvPUeF2NC%2FCVU3IW7WDu1TPGibbS5Slwv4lHWNU%2BLdHIr6cT2Rav%2BBfK1tcvT4044w%3D%3D (Caused by NewConnectionError('<urllib3.connection.HTTPSConnection object at 0x7f819c4f9070>: Failed to establish a new connection: [Errno 111] Connection refused'))
2024-01-30 16:19:58,550 ERROR   wandb-upload_0:1134334 [internal_api.py:upload_file():2767] upload_file request headers: {'User-Agent': 'python-requests/2.23.0', 'Accept-Encoding': 'gzip, deflate', 'Accept': '*/*', 'Connection': 'keep-alive', 'Content-Length': '15540'}
2024-01-30 16:19:58,550 ERROR   wandb-upload_0:1134334 [internal_api.py:upload_file():2769] upload_file response body: 
2024-01-30 16:26:08,935 ERROR   wandb-upload_0:1134334 [internal_api.py:upload_file():2765] upload_file exception https://storage.googleapis.com/wandb-production.appspot.com/dynamic_x/bert_pytorch/hv2wnz37/wandb-metadata.json?Expires=1706688636&GoogleAccessId=gorilla-files-url-signer-man%40wandb-production.iam.gserviceaccount.com&Signature=QD%2Fxf%2FivbWxQBUtR0j4IlcF8Tgh1I7K6m3cwuwolO0Az06CVc4CZE2LzhOI7bvPGsZWRdfPmB%2BJ6qQ1o1LiSGQ5AuV2RbiuGmSMvLXlHYHloPBVmqEyAleKhDMLEvMwU3bGclBUpaCiKKN%2B%2BvKetTMs4P2ueBW278aYZNVvua1m1VITnI5grj0fV1MBx7VtDom7VTQyyD8nYkEwoqnkJ0GlCsH%2FSCZEyWfq%2F0A%2BVP72tolvso6nYheXNGUTk8vdKfUGQ8cc%2FMnadC3qfPKm9yvPUeF2NC%2FCVU3IW7WDu1TPGibbS5Slwv4lHWNU%2BLdHIr6cT2Rav%2BBfK1tcvT4044w%3D%3D: HTTPSConnectionPool(host='storage.googleapis.com', port=443): Max retries exceeded with url: /wandb-production.appspot.com/dynamic_x/bert_pytorch/hv2wnz37/wandb-metadata.json?Expires=1706688636&GoogleAccessId=gorilla-files-url-signer-man%40wandb-production.iam.gserviceaccount.com&Signature=QD%2Fxf%2FivbWxQBUtR0j4IlcF8Tgh1I7K6m3cwuwolO0Az06CVc4CZE2LzhOI7bvPGsZWRdfPmB%2BJ6qQ1o1LiSGQ5AuV2RbiuGmSMvLXlHYHloPBVmqEyAleKhDMLEvMwU3bGclBUpaCiKKN%2B%2BvKetTMs4P2ueBW278aYZNVvua1m1VITnI5grj0fV1MBx7VtDom7VTQyyD8nYkEwoqnkJ0GlCsH%2FSCZEyWfq%2F0A%2BVP72tolvso6nYheXNGUTk8vdKfUGQ8cc%2FMnadC3qfPKm9yvPUeF2NC%2FCVU3IW7WDu1TPGibbS5Slwv4lHWNU%2BLdHIr6cT2Rav%2BBfK1tcvT4044w%3D%3D (Caused by NewConnectionError('<urllib3.connection.HTTPSConnection object at 0x7f819c503640>: Failed to establish a new connection: [Errno 111] Connection refused'))
2024-01-30 16:26:08,935 ERROR   wandb-upload_0:1134334 [internal_api.py:upload_file():2767] upload_file request headers: {'User-Agent': 'python-requests/2.23.0', 'Accept-Encoding': 'gzip, deflate', 'Accept': '*/*', 'Connection': 'keep-alive', 'Content-Length': '15540'}
2024-01-30 16:26:08,935 ERROR   wandb-upload_0:1134334 [internal_api.py:upload_file():2769] upload_file response body: 
2024-01-30 16:32:20,107 ERROR   wandb-upload_0:1134334 [internal_api.py:upload_file():2765] upload_file exception https://storage.googleapis.com/wandb-production.appspot.com/dynamic_x/bert_pytorch/hv2wnz37/wandb-metadata.json?Expires=1706688636&GoogleAccessId=gorilla-files-url-signer-man%40wandb-production.iam.gserviceaccount.com&Signature=QD%2Fxf%2FivbWxQBUtR0j4IlcF8Tgh1I7K6m3cwuwolO0Az06CVc4CZE2LzhOI7bvPGsZWRdfPmB%2BJ6qQ1o1LiSGQ5AuV2RbiuGmSMvLXlHYHloPBVmqEyAleKhDMLEvMwU3bGclBUpaCiKKN%2B%2BvKetTMs4P2ueBW278aYZNVvua1m1VITnI5grj0fV1MBx7VtDom7VTQyyD8nYkEwoqnkJ0GlCsH%2FSCZEyWfq%2F0A%2BVP72tolvso6nYheXNGUTk8vdKfUGQ8cc%2FMnadC3qfPKm9yvPUeF2NC%2FCVU3IW7WDu1TPGibbS5Slwv4lHWNU%2BLdHIr6cT2Rav%2BBfK1tcvT4044w%3D%3D: HTTPSConnectionPool(host='storage.googleapis.com', port=443): Max retries exceeded with url: /wandb-production.appspot.com/dynamic_x/bert_pytorch/hv2wnz37/wandb-metadata.json?Expires=1706688636&GoogleAccessId=gorilla-files-url-signer-man%40wandb-production.iam.gserviceaccount.com&Signature=QD%2Fxf%2FivbWxQBUtR0j4IlcF8Tgh1I7K6m3cwuwolO0Az06CVc4CZE2LzhOI7bvPGsZWRdfPmB%2BJ6qQ1o1LiSGQ5AuV2RbiuGmSMvLXlHYHloPBVmqEyAleKhDMLEvMwU3bGclBUpaCiKKN%2B%2BvKetTMs4P2ueBW278aYZNVvua1m1VITnI5grj0fV1MBx7VtDom7VTQyyD8nYkEwoqnkJ0GlCsH%2FSCZEyWfq%2F0A%2BVP72tolvso6nYheXNGUTk8vdKfUGQ8cc%2FMnadC3qfPKm9yvPUeF2NC%2FCVU3IW7WDu1TPGibbS5Slwv4lHWNU%2BLdHIr6cT2Rav%2BBfK1tcvT4044w%3D%3D (Caused by NewConnectionError('<urllib3.connection.HTTPSConnection object at 0x7f819c4f9ac0>: Failed to establish a new connection: [Errno 111] Connection refused'))
2024-01-30 16:32:20,107 ERROR   wandb-upload_0:1134334 [internal_api.py:upload_file():2767] upload_file request headers: {'User-Agent': 'python-requests/2.23.0', 'Accept-Encoding': 'gzip, deflate', 'Accept': '*/*', 'Connection': 'keep-alive', 'Content-Length': '15540'}
2024-01-30 16:32:20,107 ERROR   wandb-upload_0:1134334 [internal_api.py:upload_file():2769] upload_file response body: 
2024-01-30 16:37:45,664 WARNING StreamThr :1134334 [internal.py:is_dead():414] Internal process exiting, parent pid 1134046 disappeared
2024-01-30 16:37:45,664 ERROR   StreamThr :1134334 [internal.py:wandb_internal():152] Internal process shutdown.
2024-01-30 16:37:46,638 INFO    WriterThread:1134334 [datastore.py:close():296] close: /home/yanxindong/mkor/bert/wandb/run-20240130_161012-hv2wnz37/run-hv2wnz37.wandb
2024-01-30 16:37:46,661 INFO    HandlerThread:1134334 [handler.py:finish():869] shutting down handler
2024-01-30 16:38:02,351 ERROR   wandb-upload_0:1134334 [internal_api.py:upload_file():2765] upload_file exception https://storage.googleapis.com/wandb-production.appspot.com/dynamic_x/bert_pytorch/hv2wnz37/wandb-metadata.json?Expires=1706688636&GoogleAccessId=gorilla-files-url-signer-man%40wandb-production.iam.gserviceaccount.com&Signature=QD%2Fxf%2FivbWxQBUtR0j4IlcF8Tgh1I7K6m3cwuwolO0Az06CVc4CZE2LzhOI7bvPGsZWRdfPmB%2BJ6qQ1o1LiSGQ5AuV2RbiuGmSMvLXlHYHloPBVmqEyAleKhDMLEvMwU3bGclBUpaCiKKN%2B%2BvKetTMs4P2ueBW278aYZNVvua1m1VITnI5grj0fV1MBx7VtDom7VTQyyD8nYkEwoqnkJ0GlCsH%2FSCZEyWfq%2F0A%2BVP72tolvso6nYheXNGUTk8vdKfUGQ8cc%2FMnadC3qfPKm9yvPUeF2NC%2FCVU3IW7WDu1TPGibbS5Slwv4lHWNU%2BLdHIr6cT2Rav%2BBfK1tcvT4044w%3D%3D: HTTPSConnectionPool(host='storage.googleapis.com', port=443): Max retries exceeded with url: /wandb-production.appspot.com/dynamic_x/bert_pytorch/hv2wnz37/wandb-metadata.json?Expires=1706688636&GoogleAccessId=gorilla-files-url-signer-man%40wandb-production.iam.gserviceaccount.com&Signature=QD%2Fxf%2FivbWxQBUtR0j4IlcF8Tgh1I7K6m3cwuwolO0Az06CVc4CZE2LzhOI7bvPGsZWRdfPmB%2BJ6qQ1o1LiSGQ5AuV2RbiuGmSMvLXlHYHloPBVmqEyAleKhDMLEvMwU3bGclBUpaCiKKN%2B%2BvKetTMs4P2ueBW278aYZNVvua1m1VITnI5grj0fV1MBx7VtDom7VTQyyD8nYkEwoqnkJ0GlCsH%2FSCZEyWfq%2F0A%2BVP72tolvso6nYheXNGUTk8vdKfUGQ8cc%2FMnadC3qfPKm9yvPUeF2NC%2FCVU3IW7WDu1TPGibbS5Slwv4lHWNU%2BLdHIr6cT2Rav%2BBfK1tcvT4044w%3D%3D (Caused by NewConnectionError('<urllib3.connection.HTTPSConnection object at 0x7f819c511e80>: Failed to establish a new connection: [Errno 111] Connection refused'))
2024-01-30 16:38:02,351 ERROR   wandb-upload_0:1134334 [internal_api.py:upload_file():2767] upload_file request headers: {'User-Agent': 'python-requests/2.23.0', 'Accept-Encoding': 'gzip, deflate', 'Accept': '*/*', 'Connection': 'keep-alive', 'Content-Length': '15540'}
2024-01-30 16:38:02,351 ERROR   wandb-upload_0:1134334 [internal_api.py:upload_file():2769] upload_file response body: 
2024-01-30 16:40:39,670 ERROR   wandb-upload_2:1134334 [internal_api.py:upload_file():2765] upload_file exception https://storage.googleapis.com/wandb-artifacts-prod/wandb_artifacts/133981200/707680667/6873c23a2381d1524249eb1a948a45a5?Expires=1706688986&GoogleAccessId=gorilla-files-url-signer-man%40wandb-production.iam.gserviceaccount.com&Signature=pLutHOvvYkhLFMVsvj%2FcNFhiXUQKpdneKu7HDHSRpFEFSGDh%2BVG7u5XzbniWCqqTmQUukmavF5ze5HK1dc082gHQo6RDma53MJ%2B1vq9GscskVPAp5FsLcxYNZX%2FajraXUjrDpqiX0ogRu%2FfxbcP1rSNC9VJQsF6cf7IyTY%2F5hYJRhpzn8epgFzbCPPRt%2FJYvUEAzC2kcfjHnRL4t9h5W9JUUYArxxBD%2BGE16g%2Bx4NP9kHFtMcEYthU06bgAmz%2F3npvAc%2FPg%2F5JUaEbiOtQJFHLrqgyeN4%2Fazv%2BuSUMfdkLPNSx2LjuhrOHA6Y6sI%2BWOpfaLy8kJuryWhcmOzbK4iAw%3D%3D: HTTPSConnectionPool(host='storage.googleapis.com', port=443): Max retries exceeded with url: /wandb-artifacts-prod/wandb_artifacts/133981200/707680667/6873c23a2381d1524249eb1a948a45a5?Expires=1706688986&GoogleAccessId=gorilla-files-url-signer-man%40wandb-production.iam.gserviceaccount.com&Signature=pLutHOvvYkhLFMVsvj%2FcNFhiXUQKpdneKu7HDHSRpFEFSGDh%2BVG7u5XzbniWCqqTmQUukmavF5ze5HK1dc082gHQo6RDma53MJ%2B1vq9GscskVPAp5FsLcxYNZX%2FajraXUjrDpqiX0ogRu%2FfxbcP1rSNC9VJQsF6cf7IyTY%2F5hYJRhpzn8epgFzbCPPRt%2FJYvUEAzC2kcfjHnRL4t9h5W9JUUYArxxBD%2BGE16g%2Bx4NP9kHFtMcEYthU06bgAmz%2F3npvAc%2FPg%2F5JUaEbiOtQJFHLrqgyeN4%2Fazv%2BuSUMfdkLPNSx2LjuhrOHA6Y6sI%2BWOpfaLy8kJuryWhcmOzbK4iAw%3D%3D (Caused by NewConnectionError('<urllib3.connection.HTTPSConnection object at 0x7f819c4ee670>: Failed to establish a new connection: [Errno 101] Network is unreachable'))
2024-01-30 16:40:39,670 ERROR   wandb-upload_2:1134334 [internal_api.py:upload_file():2767] upload_file request headers: {'User-Agent': 'python-requests/2.23.0', 'Accept-Encoding': 'gzip, deflate', 'Accept': '*/*', 'Connection': 'keep-alive', 'Content-MD5': 'aHPCOiOB0VJCSesalIpFpQ==', 'Content-Type': 'application/json', 'Content-Length': '609'}
2024-01-30 16:40:39,670 ERROR   wandb-upload_2:1134334 [internal_api.py:upload_file():2769] upload_file response body: 
2024-01-30 16:40:39,671 ERROR   wandb-upload_1:1134334 [internal_api.py:upload_file():2765] upload_file exception https://storage.googleapis.com/wandb-artifacts-prod/wandb_artifacts/133981200/707680667/174a3d9bc61fec126cc7d5bdff5c6c5a?Expires=1706688986&GoogleAccessId=gorilla-files-url-signer-man%40wandb-production.iam.gserviceaccount.com&Signature=Lq7TDpgKSjA328uscGOaP30h0mbWcZnWwy4q5CObxZHdnesfBC3LQoKtCvxmyPolY5tqbEFCgVQf11egXygH2iW9XyvCWyb5BJOCZsFdLihQesybNPQe3IgvScDnJr6z2aljpg9TFvS7O8l3Vl0ogWCQnTER0ZUJP5NDzlDmerkvhg10FJifuxIoNgGvLyTDT%2FXk5xNV8EyVJ%2B%2F41HKCIZx5fcLEEIW09B991ppq5knLWxV3rMRsIQf3suZ5eaa2f0T57I3cQIRpj3yewO%2BlmLo%2Fn33rpQV5L8eyJmlIuvt5mcSe4p4znC5ptLIXe6ohnQ9HlyCiaNEQ3n7CWQ1TjA%3D%3D: HTTPSConnectionPool(host='storage.googleapis.com', port=443): Max retries exceeded with url: /wandb-artifacts-prod/wandb_artifacts/133981200/707680667/174a3d9bc61fec126cc7d5bdff5c6c5a?Expires=1706688986&GoogleAccessId=gorilla-files-url-signer-man%40wandb-production.iam.gserviceaccount.com&Signature=Lq7TDpgKSjA328uscGOaP30h0mbWcZnWwy4q5CObxZHdnesfBC3LQoKtCvxmyPolY5tqbEFCgVQf11egXygH2iW9XyvCWyb5BJOCZsFdLihQesybNPQe3IgvScDnJr6z2aljpg9TFvS7O8l3Vl0ogWCQnTER0ZUJP5NDzlDmerkvhg10FJifuxIoNgGvLyTDT%2FXk5xNV8EyVJ%2B%2F41HKCIZx5fcLEEIW09B991ppq5knLWxV3rMRsIQf3suZ5eaa2f0T57I3cQIRpj3yewO%2BlmLo%2Fn33rpQV5L8eyJmlIuvt5mcSe4p4znC5ptLIXe6ohnQ9HlyCiaNEQ3n7CWQ1TjA%3D%3D (Caused by NewConnectionError('<urllib3.connection.HTTPSConnection object at 0x7f819c4ee610>: Failed to establish a new connection: [Errno 101] Network is unreachable'))
2024-01-30 16:40:39,671 ERROR   wandb-upload_1:1134334 [internal_api.py:upload_file():2767] upload_file request headers: {'User-Agent': 'python-requests/2.23.0', 'Accept-Encoding': 'gzip, deflate', 'Accept': '*/*', 'Connection': 'keep-alive', 'Content-MD5': 'F0o9m8Yf7BJsx9W9/1xsWg==', 'Content-Type': 'text/plain; charset=utf-8', 'Content-Length': '2179'}
2024-01-30 16:40:39,672 ERROR   wandb-upload_1:1134334 [internal_api.py:upload_file():2769] upload_file response body: 
2024-01-30 16:42:58,557 ERROR   wandb-upload_1:1134334 [internal_api.py:upload_file():2765] upload_file exception https://storage.googleapis.com/wandb-artifacts-prod/wandb_artifacts/133981200/707680667/174a3d9bc61fec126cc7d5bdff5c6c5a?Expires=1706688986&GoogleAccessId=gorilla-files-url-signer-man%40wandb-production.iam.gserviceaccount.com&Signature=Lq7TDpgKSjA328uscGOaP30h0mbWcZnWwy4q5CObxZHdnesfBC3LQoKtCvxmyPolY5tqbEFCgVQf11egXygH2iW9XyvCWyb5BJOCZsFdLihQesybNPQe3IgvScDnJr6z2aljpg9TFvS7O8l3Vl0ogWCQnTER0ZUJP5NDzlDmerkvhg10FJifuxIoNgGvLyTDT%2FXk5xNV8EyVJ%2B%2F41HKCIZx5fcLEEIW09B991ppq5knLWxV3rMRsIQf3suZ5eaa2f0T57I3cQIRpj3yewO%2BlmLo%2Fn33rpQV5L8eyJmlIuvt5mcSe4p4znC5ptLIXe6ohnQ9HlyCiaNEQ3n7CWQ1TjA%3D%3D: HTTPSConnectionPool(host='storage.googleapis.com', port=443): Max retries exceeded with url: /wandb-artifacts-prod/wandb_artifacts/133981200/707680667/174a3d9bc61fec126cc7d5bdff5c6c5a?Expires=1706688986&GoogleAccessId=gorilla-files-url-signer-man%40wandb-production.iam.gserviceaccount.com&Signature=Lq7TDpgKSjA328uscGOaP30h0mbWcZnWwy4q5CObxZHdnesfBC3LQoKtCvxmyPolY5tqbEFCgVQf11egXygH2iW9XyvCWyb5BJOCZsFdLihQesybNPQe3IgvScDnJr6z2aljpg9TFvS7O8l3Vl0ogWCQnTER0ZUJP5NDzlDmerkvhg10FJifuxIoNgGvLyTDT%2FXk5xNV8EyVJ%2B%2F41HKCIZx5fcLEEIW09B991ppq5knLWxV3rMRsIQf3suZ5eaa2f0T57I3cQIRpj3yewO%2BlmLo%2Fn33rpQV5L8eyJmlIuvt5mcSe4p4znC5ptLIXe6ohnQ9HlyCiaNEQ3n7CWQ1TjA%3D%3D (Caused by NewConnectionError('<urllib3.connection.HTTPSConnection object at 0x7f819c4f9220>: Failed to establish a new connection: [Errno 101] Network is unreachable'))
2024-01-30 16:42:58,557 ERROR   wandb-upload_1:1134334 [internal_api.py:upload_file():2767] upload_file request headers: {'User-Agent': 'python-requests/2.23.0', 'Accept-Encoding': 'gzip, deflate', 'Accept': '*/*', 'Connection': 'keep-alive', 'Content-MD5': 'F0o9m8Yf7BJsx9W9/1xsWg==', 'Content-Type': 'text/plain; charset=utf-8', 'Content-Length': '2179'}
2024-01-30 16:42:58,557 ERROR   wandb-upload_1:1134334 [internal_api.py:upload_file():2769] upload_file response body: 
2024-01-30 16:43:05,420 ERROR   wandb-upload_2:1134334 [internal_api.py:upload_file():2765] upload_file exception https://storage.googleapis.com/wandb-artifacts-prod/wandb_artifacts/133981200/707680667/6873c23a2381d1524249eb1a948a45a5?Expires=1706688986&GoogleAccessId=gorilla-files-url-signer-man%40wandb-production.iam.gserviceaccount.com&Signature=pLutHOvvYkhLFMVsvj%2FcNFhiXUQKpdneKu7HDHSRpFEFSGDh%2BVG7u5XzbniWCqqTmQUukmavF5ze5HK1dc082gHQo6RDma53MJ%2B1vq9GscskVPAp5FsLcxYNZX%2FajraXUjrDpqiX0ogRu%2FfxbcP1rSNC9VJQsF6cf7IyTY%2F5hYJRhpzn8epgFzbCPPRt%2FJYvUEAzC2kcfjHnRL4t9h5W9JUUYArxxBD%2BGE16g%2Bx4NP9kHFtMcEYthU06bgAmz%2F3npvAc%2FPg%2F5JUaEbiOtQJFHLrqgyeN4%2Fazv%2BuSUMfdkLPNSx2LjuhrOHA6Y6sI%2BWOpfaLy8kJuryWhcmOzbK4iAw%3D%3D: HTTPSConnectionPool(host='storage.googleapis.com', port=443): Max retries exceeded with url: /wandb-artifacts-prod/wandb_artifacts/133981200/707680667/6873c23a2381d1524249eb1a948a45a5?Expires=1706688986&GoogleAccessId=gorilla-files-url-signer-man%40wandb-production.iam.gserviceaccount.com&Signature=pLutHOvvYkhLFMVsvj%2FcNFhiXUQKpdneKu7HDHSRpFEFSGDh%2BVG7u5XzbniWCqqTmQUukmavF5ze5HK1dc082gHQo6RDma53MJ%2B1vq9GscskVPAp5FsLcxYNZX%2FajraXUjrDpqiX0ogRu%2FfxbcP1rSNC9VJQsF6cf7IyTY%2F5hYJRhpzn8epgFzbCPPRt%2FJYvUEAzC2kcfjHnRL4t9h5W9JUUYArxxBD%2BGE16g%2Bx4NP9kHFtMcEYthU06bgAmz%2F3npvAc%2FPg%2F5JUaEbiOtQJFHLrqgyeN4%2Fazv%2BuSUMfdkLPNSx2LjuhrOHA6Y6sI%2BWOpfaLy8kJuryWhcmOzbK4iAw%3D%3D (Caused by NewConnectionError('<urllib3.connection.HTTPSConnection object at 0x7f819c502190>: Failed to establish a new connection: [Errno 101] Network is unreachable'))
2024-01-30 16:43:05,420 ERROR   wandb-upload_2:1134334 [internal_api.py:upload_file():2767] upload_file request headers: {'User-Agent': 'python-requests/2.23.0', 'Accept-Encoding': 'gzip, deflate', 'Accept': '*/*', 'Connection': 'keep-alive', 'Content-MD5': 'aHPCOiOB0VJCSesalIpFpQ==', 'Content-Type': 'application/json', 'Content-Length': '609'}
2024-01-30 16:43:05,420 ERROR   wandb-upload_2:1134334 [internal_api.py:upload_file():2769] upload_file response body: 
2024-01-30 16:43:28,223 ERROR   wandb-upload_0:1134334 [internal_api.py:upload_file():2765] upload_file exception https://storage.googleapis.com/wandb-production.appspot.com/dynamic_x/bert_pytorch/hv2wnz37/wandb-metadata.json?Expires=1706688636&GoogleAccessId=gorilla-files-url-signer-man%40wandb-production.iam.gserviceaccount.com&Signature=QD%2Fxf%2FivbWxQBUtR0j4IlcF8Tgh1I7K6m3cwuwolO0Az06CVc4CZE2LzhOI7bvPGsZWRdfPmB%2BJ6qQ1o1LiSGQ5AuV2RbiuGmSMvLXlHYHloPBVmqEyAleKhDMLEvMwU3bGclBUpaCiKKN%2B%2BvKetTMs4P2ueBW278aYZNVvua1m1VITnI5grj0fV1MBx7VtDom7VTQyyD8nYkEwoqnkJ0GlCsH%2FSCZEyWfq%2F0A%2BVP72tolvso6nYheXNGUTk8vdKfUGQ8cc%2FMnadC3qfPKm9yvPUeF2NC%2FCVU3IW7WDu1TPGibbS5Slwv4lHWNU%2BLdHIr6cT2Rav%2BBfK1tcvT4044w%3D%3D: HTTPSConnectionPool(host='storage.googleapis.com', port=443): Max retries exceeded with url: /wandb-production.appspot.com/dynamic_x/bert_pytorch/hv2wnz37/wandb-metadata.json?Expires=1706688636&GoogleAccessId=gorilla-files-url-signer-man%40wandb-production.iam.gserviceaccount.com&Signature=QD%2Fxf%2FivbWxQBUtR0j4IlcF8Tgh1I7K6m3cwuwolO0Az06CVc4CZE2LzhOI7bvPGsZWRdfPmB%2BJ6qQ1o1LiSGQ5AuV2RbiuGmSMvLXlHYHloPBVmqEyAleKhDMLEvMwU3bGclBUpaCiKKN%2B%2BvKetTMs4P2ueBW278aYZNVvua1m1VITnI5grj0fV1MBx7VtDom7VTQyyD8nYkEwoqnkJ0GlCsH%2FSCZEyWfq%2F0A%2BVP72tolvso6nYheXNGUTk8vdKfUGQ8cc%2FMnadC3qfPKm9yvPUeF2NC%2FCVU3IW7WDu1TPGibbS5Slwv4lHWNU%2BLdHIr6cT2Rav%2BBfK1tcvT4044w%3D%3D (Caused by NewConnectionError('<urllib3.connection.HTTPSConnection object at 0x7f819c503b50>: Failed to establish a new connection: [Errno 101] Network is unreachable'))
2024-01-30 16:43:28,223 ERROR   wandb-upload_0:1134334 [internal_api.py:upload_file():2767] upload_file request headers: {'User-Agent': 'python-requests/2.23.0', 'Accept-Encoding': 'gzip, deflate', 'Accept': '*/*', 'Connection': 'keep-alive', 'Content-Length': '15540'}
2024-01-30 16:43:28,223 ERROR   wandb-upload_0:1134334 [internal_api.py:upload_file():2769] upload_file response body: 
2024-01-30 17:11:41,301 ERROR   wandb-upload_2:1134334 [internal_api.py:upload_file():2765] upload_file exception https://storage.googleapis.com/wandb-artifacts-prod/wandb_artifacts/133981200/707680667/6873c23a2381d1524249eb1a948a45a5?Expires=1706688986&GoogleAccessId=gorilla-files-url-signer-man%40wandb-production.iam.gserviceaccount.com&Signature=pLutHOvvYkhLFMVsvj%2FcNFhiXUQKpdneKu7HDHSRpFEFSGDh%2BVG7u5XzbniWCqqTmQUukmavF5ze5HK1dc082gHQo6RDma53MJ%2B1vq9GscskVPAp5FsLcxYNZX%2FajraXUjrDpqiX0ogRu%2FfxbcP1rSNC9VJQsF6cf7IyTY%2F5hYJRhpzn8epgFzbCPPRt%2FJYvUEAzC2kcfjHnRL4t9h5W9JUUYArxxBD%2BGE16g%2Bx4NP9kHFtMcEYthU06bgAmz%2F3npvAc%2FPg%2F5JUaEbiOtQJFHLrqgyeN4%2Fazv%2BuSUMfdkLPNSx2LjuhrOHA6Y6sI%2BWOpfaLy8kJuryWhcmOzbK4iAw%3D%3D: HTTPSConnectionPool(host='storage.googleapis.com', port=443): Max retries exceeded with url: /wandb-artifacts-prod/wandb_artifacts/133981200/707680667/6873c23a2381d1524249eb1a948a45a5?Expires=1706688986&GoogleAccessId=gorilla-files-url-signer-man%40wandb-production.iam.gserviceaccount.com&Signature=pLutHOvvYkhLFMVsvj%2FcNFhiXUQKpdneKu7HDHSRpFEFSGDh%2BVG7u5XzbniWCqqTmQUukmavF5ze5HK1dc082gHQo6RDma53MJ%2B1vq9GscskVPAp5FsLcxYNZX%2FajraXUjrDpqiX0ogRu%2FfxbcP1rSNC9VJQsF6cf7IyTY%2F5hYJRhpzn8epgFzbCPPRt%2FJYvUEAzC2kcfjHnRL4t9h5W9JUUYArxxBD%2BGE16g%2Bx4NP9kHFtMcEYthU06bgAmz%2F3npvAc%2FPg%2F5JUaEbiOtQJFHLrqgyeN4%2Fazv%2BuSUMfdkLPNSx2LjuhrOHA6Y6sI%2BWOpfaLy8kJuryWhcmOzbK4iAw%3D%3D (Caused by NewConnectionError('<urllib3.connection.HTTPSConnection object at 0x7f819c502a30>: Failed to establish a new connection: [Errno 110] Connection timed out'))
2024-01-30 17:11:41,302 ERROR   wandb-upload_2:1134334 [internal_api.py:upload_file():2767] upload_file request headers: {'User-Agent': 'python-requests/2.23.0', 'Accept-Encoding': 'gzip, deflate', 'Accept': '*/*', 'Connection': 'keep-alive', 'Content-MD5': 'aHPCOiOB0VJCSesalIpFpQ==', 'Content-Type': 'application/json', 'Content-Length': '609'}
2024-01-30 17:11:41,302 ERROR   wandb-upload_2:1134334 [internal_api.py:upload_file():2769] upload_file response body: 
2024-01-30 17:11:55,638 ERROR   wandb-upload_1:1134334 [internal_api.py:upload_file():2765] upload_file exception https://storage.googleapis.com/wandb-artifacts-prod/wandb_artifacts/133981200/707680667/174a3d9bc61fec126cc7d5bdff5c6c5a?Expires=1706688986&GoogleAccessId=gorilla-files-url-signer-man%40wandb-production.iam.gserviceaccount.com&Signature=Lq7TDpgKSjA328uscGOaP30h0mbWcZnWwy4q5CObxZHdnesfBC3LQoKtCvxmyPolY5tqbEFCgVQf11egXygH2iW9XyvCWyb5BJOCZsFdLihQesybNPQe3IgvScDnJr6z2aljpg9TFvS7O8l3Vl0ogWCQnTER0ZUJP5NDzlDmerkvhg10FJifuxIoNgGvLyTDT%2FXk5xNV8EyVJ%2B%2F41HKCIZx5fcLEEIW09B991ppq5knLWxV3rMRsIQf3suZ5eaa2f0T57I3cQIRpj3yewO%2BlmLo%2Fn33rpQV5L8eyJmlIuvt5mcSe4p4znC5ptLIXe6ohnQ9HlyCiaNEQ3n7CWQ1TjA%3D%3D: HTTPSConnectionPool(host='storage.googleapis.com', port=443): Max retries exceeded with url: /wandb-artifacts-prod/wandb_artifacts/133981200/707680667/174a3d9bc61fec126cc7d5bdff5c6c5a?Expires=1706688986&GoogleAccessId=gorilla-files-url-signer-man%40wandb-production.iam.gserviceaccount.com&Signature=Lq7TDpgKSjA328uscGOaP30h0mbWcZnWwy4q5CObxZHdnesfBC3LQoKtCvxmyPolY5tqbEFCgVQf11egXygH2iW9XyvCWyb5BJOCZsFdLihQesybNPQe3IgvScDnJr6z2aljpg9TFvS7O8l3Vl0ogWCQnTER0ZUJP5NDzlDmerkvhg10FJifuxIoNgGvLyTDT%2FXk5xNV8EyVJ%2B%2F41HKCIZx5fcLEEIW09B991ppq5knLWxV3rMRsIQf3suZ5eaa2f0T57I3cQIRpj3yewO%2BlmLo%2Fn33rpQV5L8eyJmlIuvt5mcSe4p4znC5ptLIXe6ohnQ9HlyCiaNEQ3n7CWQ1TjA%3D%3D (Caused by NewConnectionError('<urllib3.connection.HTTPSConnection object at 0x7f819c503e20>: Failed to establish a new connection: [Errno 110] Connection timed out'))
2024-01-30 17:11:55,638 ERROR   wandb-upload_1:1134334 [internal_api.py:upload_file():2767] upload_file request headers: {'User-Agent': 'python-requests/2.23.0', 'Accept-Encoding': 'gzip, deflate', 'Accept': '*/*', 'Connection': 'keep-alive', 'Content-MD5': 'F0o9m8Yf7BJsx9W9/1xsWg==', 'Content-Type': 'text/plain; charset=utf-8', 'Content-Length': '2179'}
2024-01-30 17:11:55,638 ERROR   wandb-upload_1:1134334 [internal_api.py:upload_file():2769] upload_file response body: 
2024-01-30 17:13:09,366 ERROR   wandb-upload_0:1134334 [internal_api.py:upload_file():2765] upload_file exception https://storage.googleapis.com/wandb-production.appspot.com/dynamic_x/bert_pytorch/hv2wnz37/wandb-metadata.json?Expires=1706688636&GoogleAccessId=gorilla-files-url-signer-man%40wandb-production.iam.gserviceaccount.com&Signature=QD%2Fxf%2FivbWxQBUtR0j4IlcF8Tgh1I7K6m3cwuwolO0Az06CVc4CZE2LzhOI7bvPGsZWRdfPmB%2BJ6qQ1o1LiSGQ5AuV2RbiuGmSMvLXlHYHloPBVmqEyAleKhDMLEvMwU3bGclBUpaCiKKN%2B%2BvKetTMs4P2ueBW278aYZNVvua1m1VITnI5grj0fV1MBx7VtDom7VTQyyD8nYkEwoqnkJ0GlCsH%2FSCZEyWfq%2F0A%2BVP72tolvso6nYheXNGUTk8vdKfUGQ8cc%2FMnadC3qfPKm9yvPUeF2NC%2FCVU3IW7WDu1TPGibbS5Slwv4lHWNU%2BLdHIr6cT2Rav%2BBfK1tcvT4044w%3D%3D: HTTPSConnectionPool(host='storage.googleapis.com', port=443): Max retries exceeded with url: /wandb-production.appspot.com/dynamic_x/bert_pytorch/hv2wnz37/wandb-metadata.json?Expires=1706688636&GoogleAccessId=gorilla-files-url-signer-man%40wandb-production.iam.gserviceaccount.com&Signature=QD%2Fxf%2FivbWxQBUtR0j4IlcF8Tgh1I7K6m3cwuwolO0Az06CVc4CZE2LzhOI7bvPGsZWRdfPmB%2BJ6qQ1o1LiSGQ5AuV2RbiuGmSMvLXlHYHloPBVmqEyAleKhDMLEvMwU3bGclBUpaCiKKN%2B%2BvKetTMs4P2ueBW278aYZNVvua1m1VITnI5grj0fV1MBx7VtDom7VTQyyD8nYkEwoqnkJ0GlCsH%2FSCZEyWfq%2F0A%2BVP72tolvso6nYheXNGUTk8vdKfUGQ8cc%2FMnadC3qfPKm9yvPUeF2NC%2FCVU3IW7WDu1TPGibbS5Slwv4lHWNU%2BLdHIr6cT2Rav%2BBfK1tcvT4044w%3D%3D (Caused by NewConnectionError('<urllib3.connection.HTTPSConnection object at 0x7f819c4f9580>: Failed to establish a new connection: [Errno 110] Connection timed out'))
2024-01-30 17:13:09,366 ERROR   wandb-upload_0:1134334 [internal_api.py:upload_file():2767] upload_file request headers: {'User-Agent': 'python-requests/2.23.0', 'Accept-Encoding': 'gzip, deflate', 'Accept': '*/*', 'Connection': 'keep-alive', 'Content-Length': '15540'}
2024-01-30 17:13:09,366 ERROR   wandb-upload_0:1134334 [internal_api.py:upload_file():2769] upload_file response body: 
2024-01-30 17:17:15,876 ERROR   wandb-upload_2:1134334 [internal_api.py:upload_file():2765] upload_file exception https://storage.googleapis.com/wandb-artifacts-prod/wandb_artifacts/133981200/707680667/6873c23a2381d1524249eb1a948a45a5?Expires=1706688986&GoogleAccessId=gorilla-files-url-signer-man%40wandb-production.iam.gserviceaccount.com&Signature=pLutHOvvYkhLFMVsvj%2FcNFhiXUQKpdneKu7HDHSRpFEFSGDh%2BVG7u5XzbniWCqqTmQUukmavF5ze5HK1dc082gHQo6RDma53MJ%2B1vq9GscskVPAp5FsLcxYNZX%2FajraXUjrDpqiX0ogRu%2FfxbcP1rSNC9VJQsF6cf7IyTY%2F5hYJRhpzn8epgFzbCPPRt%2FJYvUEAzC2kcfjHnRL4t9h5W9JUUYArxxBD%2BGE16g%2Bx4NP9kHFtMcEYthU06bgAmz%2F3npvAc%2FPg%2F5JUaEbiOtQJFHLrqgyeN4%2Fazv%2BuSUMfdkLPNSx2LjuhrOHA6Y6sI%2BWOpfaLy8kJuryWhcmOzbK4iAw%3D%3D: HTTPSConnectionPool(host='storage.googleapis.com', port=443): Max retries exceeded with url: /wandb-artifacts-prod/wandb_artifacts/133981200/707680667/6873c23a2381d1524249eb1a948a45a5?Expires=1706688986&GoogleAccessId=gorilla-files-url-signer-man%40wandb-production.iam.gserviceaccount.com&Signature=pLutHOvvYkhLFMVsvj%2FcNFhiXUQKpdneKu7HDHSRpFEFSGDh%2BVG7u5XzbniWCqqTmQUukmavF5ze5HK1dc082gHQo6RDma53MJ%2B1vq9GscskVPAp5FsLcxYNZX%2FajraXUjrDpqiX0ogRu%2FfxbcP1rSNC9VJQsF6cf7IyTY%2F5hYJRhpzn8epgFzbCPPRt%2FJYvUEAzC2kcfjHnRL4t9h5W9JUUYArxxBD%2BGE16g%2Bx4NP9kHFtMcEYthU06bgAmz%2F3npvAc%2FPg%2F5JUaEbiOtQJFHLrqgyeN4%2Fazv%2BuSUMfdkLPNSx2LjuhrOHA6Y6sI%2BWOpfaLy8kJuryWhcmOzbK4iAw%3D%3D (Caused by NewConnectionError('<urllib3.connection.HTTPSConnection object at 0x7f819c4edd00>: Failed to establish a new connection: [Errno 101] Network is unreachable'))
2024-01-30 17:17:15,877 ERROR   wandb-upload_2:1134334 [internal_api.py:upload_file():2767] upload_file request headers: {'User-Agent': 'python-requests/2.23.0', 'Accept-Encoding': 'gzip, deflate', 'Accept': '*/*', 'Connection': 'keep-alive', 'Content-MD5': 'aHPCOiOB0VJCSesalIpFpQ==', 'Content-Type': 'application/json', 'Content-Length': '609'}
2024-01-30 17:17:15,877 ERROR   wandb-upload_2:1134334 [internal_api.py:upload_file():2769] upload_file response body: 
2024-01-30 17:18:02,111 ERROR   wandb-upload_1:1134334 [internal_api.py:upload_file():2765] upload_file exception https://storage.googleapis.com/wandb-artifacts-prod/wandb_artifacts/133981200/707680667/174a3d9bc61fec126cc7d5bdff5c6c5a?Expires=1706688986&GoogleAccessId=gorilla-files-url-signer-man%40wandb-production.iam.gserviceaccount.com&Signature=Lq7TDpgKSjA328uscGOaP30h0mbWcZnWwy4q5CObxZHdnesfBC3LQoKtCvxmyPolY5tqbEFCgVQf11egXygH2iW9XyvCWyb5BJOCZsFdLihQesybNPQe3IgvScDnJr6z2aljpg9TFvS7O8l3Vl0ogWCQnTER0ZUJP5NDzlDmerkvhg10FJifuxIoNgGvLyTDT%2FXk5xNV8EyVJ%2B%2F41HKCIZx5fcLEEIW09B991ppq5knLWxV3rMRsIQf3suZ5eaa2f0T57I3cQIRpj3yewO%2BlmLo%2Fn33rpQV5L8eyJmlIuvt5mcSe4p4znC5ptLIXe6ohnQ9HlyCiaNEQ3n7CWQ1TjA%3D%3D: HTTPSConnectionPool(host='storage.googleapis.com', port=443): Max retries exceeded with url: /wandb-artifacts-prod/wandb_artifacts/133981200/707680667/174a3d9bc61fec126cc7d5bdff5c6c5a?Expires=1706688986&GoogleAccessId=gorilla-files-url-signer-man%40wandb-production.iam.gserviceaccount.com&Signature=Lq7TDpgKSjA328uscGOaP30h0mbWcZnWwy4q5CObxZHdnesfBC3LQoKtCvxmyPolY5tqbEFCgVQf11egXygH2iW9XyvCWyb5BJOCZsFdLihQesybNPQe3IgvScDnJr6z2aljpg9TFvS7O8l3Vl0ogWCQnTER0ZUJP5NDzlDmerkvhg10FJifuxIoNgGvLyTDT%2FXk5xNV8EyVJ%2B%2F41HKCIZx5fcLEEIW09B991ppq5knLWxV3rMRsIQf3suZ5eaa2f0T57I3cQIRpj3yewO%2BlmLo%2Fn33rpQV5L8eyJmlIuvt5mcSe4p4znC5ptLIXe6ohnQ9HlyCiaNEQ3n7CWQ1TjA%3D%3D (Caused by NewConnectionError('<urllib3.connection.HTTPSConnection object at 0x7f819c4ecaf0>: Failed to establish a new connection: [Errno 101] Network is unreachable'))
2024-01-30 17:18:02,112 ERROR   wandb-upload_1:1134334 [internal_api.py:upload_file():2767] upload_file request headers: {'User-Agent': 'python-requests/2.23.0', 'Accept-Encoding': 'gzip, deflate', 'Accept': '*/*', 'Connection': 'keep-alive', 'Content-MD5': 'F0o9m8Yf7BJsx9W9/1xsWg==', 'Content-Type': 'text/plain; charset=utf-8', 'Content-Length': '2179'}
2024-01-30 17:18:02,112 ERROR   wandb-upload_1:1134334 [internal_api.py:upload_file():2769] upload_file response body: 
2024-01-30 17:18:42,117 ERROR   wandb-upload_0:1134334 [internal_api.py:upload_file():2765] upload_file exception https://storage.googleapis.com/wandb-production.appspot.com/dynamic_x/bert_pytorch/hv2wnz37/wandb-metadata.json?Expires=1706688636&GoogleAccessId=gorilla-files-url-signer-man%40wandb-production.iam.gserviceaccount.com&Signature=QD%2Fxf%2FivbWxQBUtR0j4IlcF8Tgh1I7K6m3cwuwolO0Az06CVc4CZE2LzhOI7bvPGsZWRdfPmB%2BJ6qQ1o1LiSGQ5AuV2RbiuGmSMvLXlHYHloPBVmqEyAleKhDMLEvMwU3bGclBUpaCiKKN%2B%2BvKetTMs4P2ueBW278aYZNVvua1m1VITnI5grj0fV1MBx7VtDom7VTQyyD8nYkEwoqnkJ0GlCsH%2FSCZEyWfq%2F0A%2BVP72tolvso6nYheXNGUTk8vdKfUGQ8cc%2FMnadC3qfPKm9yvPUeF2NC%2FCVU3IW7WDu1TPGibbS5Slwv4lHWNU%2BLdHIr6cT2Rav%2BBfK1tcvT4044w%3D%3D: HTTPSConnectionPool(host='storage.googleapis.com', port=443): Max retries exceeded with url: /wandb-production.appspot.com/dynamic_x/bert_pytorch/hv2wnz37/wandb-metadata.json?Expires=1706688636&GoogleAccessId=gorilla-files-url-signer-man%40wandb-production.iam.gserviceaccount.com&Signature=QD%2Fxf%2FivbWxQBUtR0j4IlcF8Tgh1I7K6m3cwuwolO0Az06CVc4CZE2LzhOI7bvPGsZWRdfPmB%2BJ6qQ1o1LiSGQ5AuV2RbiuGmSMvLXlHYHloPBVmqEyAleKhDMLEvMwU3bGclBUpaCiKKN%2B%2BvKetTMs4P2ueBW278aYZNVvua1m1VITnI5grj0fV1MBx7VtDom7VTQyyD8nYkEwoqnkJ0GlCsH%2FSCZEyWfq%2F0A%2BVP72tolvso6nYheXNGUTk8vdKfUGQ8cc%2FMnadC3qfPKm9yvPUeF2NC%2FCVU3IW7WDu1TPGibbS5Slwv4lHWNU%2BLdHIr6cT2Rav%2BBfK1tcvT4044w%3D%3D (Caused by NewConnectionError('<urllib3.connection.HTTPSConnection object at 0x7f819c4eccd0>: Failed to establish a new connection: [Errno 111] Connection refused'))
2024-01-30 17:18:42,117 ERROR   wandb-upload_0:1134334 [internal_api.py:upload_file():2767] upload_file request headers: {'User-Agent': 'python-requests/2.23.0', 'Accept-Encoding': 'gzip, deflate', 'Accept': '*/*', 'Connection': 'keep-alive', 'Content-Length': '15540'}
2024-01-30 17:18:42,117 ERROR   wandb-upload_0:1134334 [internal_api.py:upload_file():2769] upload_file response body: 
2024-01-30 17:23:05,444 INFO    wandb-upload_2:1134334 [upload_job.py:push():89] Uploaded file /home/yanxindong/.local/share/wandb/artifacts/staging/tmprt_2pts7
2024-01-30 17:23:22,200 INFO    wandb-upload_1:1134334 [upload_job.py:push():89] Uploaded file /home/yanxindong/.local/share/wandb/artifacts/staging/tmpyht6xl3o
2024-01-30 17:23:25,281 INFO    SenderThread:1134334 [sender.py:send_artifact():1494] sent artifact job-https___github.com_kkkjj-d_mkor.git_bert_run_pretraining.py - {'id': 'QXJ0aWZhY3Q6NzA3NjgwNjY3', 'state': 'PENDING', 'artifactSequence': {'id': 'QXJ0aWZhY3RDb2xsZWN0aW9uOjEzMzk4MTIwMA==', 'latestArtifact': {'id': 'QXJ0aWZhY3Q6NzAzOTc3Mjk3', 'versionIndex': 8}}}
2024-01-30 17:23:25,281 INFO    SenderThread:1134334 [sender.py:finish():1572] shutting down sender
2024-01-30 17:23:25,282 INFO    SenderThread:1134334 [dir_watcher.py:finish():358] shutting down directory watcher
2024-01-30 17:23:25,949 INFO    SenderThread:1134334 [dir_watcher.py:finish():388] scan: /home/yanxindong/mkor/bert/wandb/run-20240130_161012-hv2wnz37/files
2024-01-30 17:23:25,949 INFO    SenderThread:1134334 [dir_watcher.py:finish():402] scan save: /home/yanxindong/mkor/bert/wandb/run-20240130_161012-hv2wnz37/files/wandb-summary.json wandb-summary.json
2024-01-30 17:23:25,950 INFO    SenderThread:1134334 [dir_watcher.py:finish():402] scan save: /home/yanxindong/mkor/bert/wandb/run-20240130_161012-hv2wnz37/files/conda-environment.yaml conda-environment.yaml
2024-01-30 17:23:25,950 INFO    SenderThread:1134334 [dir_watcher.py:finish():402] scan save: /home/yanxindong/mkor/bert/wandb/run-20240130_161012-hv2wnz37/files/wandb-metadata.json wandb-metadata.json
2024-01-30 17:23:25,950 INFO    SenderThread:1134334 [dir_watcher.py:finish():402] scan save: /home/yanxindong/mkor/bert/wandb/run-20240130_161012-hv2wnz37/files/output.log output.log
2024-01-30 17:23:25,951 INFO    SenderThread:1134334 [dir_watcher.py:finish():402] scan save: /home/yanxindong/mkor/bert/wandb/run-20240130_161012-hv2wnz37/files/requirements.txt requirements.txt
2024-01-30 17:23:25,959 INFO    SenderThread:1134334 [dir_watcher.py:finish():402] scan save: /home/yanxindong/mkor/bert/wandb/run-20240130_161012-hv2wnz37/files/config.yaml config.yaml
2024-01-30 17:23:25,959 INFO    SenderThread:1134334 [file_pusher.py:finish():175] shutting down file pusher
2024-01-30 17:23:25,959 INFO    SenderThread:1134334 [file_pusher.py:join():181] waiting for file pusher
2024-01-30 17:23:26,561 INFO    wandb-upload_2:1134334 [upload_job.py:push():131] Uploaded file /home/yanxindong/mkor/bert/wandb/run-20240130_161012-hv2wnz37/files/wandb-summary.json
2024-01-30 17:23:26,948 INFO    wandb-upload_5:1134334 [upload_job.py:push():131] Uploaded file /home/yanxindong/mkor/bert/wandb/run-20240130_161012-hv2wnz37/files/config.yaml
2024-01-30 17:23:26,979 INFO    wandb-upload_4:1134334 [upload_job.py:push():131] Uploaded file /home/yanxindong/mkor/bert/wandb/run-20240130_161012-hv2wnz37/files/requirements.txt
2024-01-30 17:23:26,986 INFO    wandb-upload_1:1134334 [upload_job.py:push():131] Uploaded file /home/yanxindong/mkor/bert/wandb/run-20240130_161012-hv2wnz37/files/conda-environment.yaml
2024-01-30 17:23:27,900 INFO    wandb-upload_3:1134334 [upload_job.py:push():131] Uploaded file /home/yanxindong/mkor/bert/wandb/run-20240130_161012-hv2wnz37/files/output.log
2024-01-30 17:24:14,050 INFO    wandb-upload_0:1134334 [upload_job.py:push():131] Uploaded file /tmp/tmpvnv1xohewandb/oodxgvjt-wandb-metadata.json
2024-01-30 17:24:14,512 INFO    SenderThread:1134334 [file_stream.py:finish():595] file stream finish called
2024-01-30 17:24:14,844 INFO    SenderThread:1134334 [file_stream.py:finish():599] file stream finish is done
